{"data":{"id":1722049035075590,"id_str":"1722049035075590","order_type":1,"datetime":"1709257102","microtimestamp":"1709257102362000","amount":0.48910835,"amount_str":"0.48910835","amount_traded":"0","amount_at_create":"0.48910835","price":61337,"price_str":"61337"},"channel":"live_orders_btcusd","event":"order_created"}
{"data":{"id":1722049035079681,"id_str":"1722049035079681","order_type":0,"datetime":"1709257102","microtimestamp":"1709257102363000","amount":0.01630682,"amount_str":"0.01630682","amount_traded":"0","amount_at_create":"0.01630682","price":61324,"price_str":"61324"},"channel":"live_orders_btcusd","event":"order_created"}
{"data":{"id":1722049035079682,"id_str":"1722049035079682","order_type":1,"datetime":"1709257102","microtimestamp":"1709257102363000","amount":0.01630417,"amount_str":"0.01630417","amount_traded":"0","amount_at_create":"0.01630417","price":61334,"price_str":"61334"},"channel":"live_orders_btcusd","event":"order_created"}
{"data":{"id":1722049035087872,"id_str":"1722049035087872","order_type":0,"datetime":"1709257102","microtimestamp":"1709257102364000","amount":0.16332658,"amount_str":"0.16332658","amount_traded":"0","amount_at_create":"0.16332658","price":61227,"price_str":"61227"},"channel":"live_orders_btcusd","event":"order_created"}
{"data":{"id":1722049035100160,"id_str":"1722049035100160","order_type":1,"datetime":"1709257102","microtimestamp":"1709257102367000","amount":0.48907675,"amount_str":"0.48907675","amount_traded":"0","amount_at_create":"0.48907675","price":61341,"price_str":"61341"},"channel":"live_orders_btcusd","event":"order_created"}
{"data":{"id":1722049035079681,"id_str":"1722049035079681","order_type":0,"datetime":"1709257102","microtimestamp":"1709257102382000","amount":0.01630682,"amount_str":"0.01630682","amount_traded":"0","amount_at_create":"0.01630682","price":61324,"price_str":"61324"},"channel":"live_orders_btcusd","event":"order_deleted"}
{"data":{"id":1722049035075590,"id_str":"1722049035075590","order_type":1,"datetime":"1709257102","microtimestamp":"1709257102404000","amount":0.48910835,"amount_str":"0.48910835","amount_traded":"0","amount_at_create":"0.48910835","price":61337,"price_str":"61337"},"channel":"live_orders_btcusd","event":"order_deleted"}
{"data":{"id":1722049035079682,"id_str":"1722049035079682","order_type":1,"datetime":"1709257102","microtimestamp":"1709257102405000","amount":0.01630417,"amount_str":"0.01630417","amount_traded":"0","amount_at_create":"0.01630417","price":61334,"price_str":"61334"},"channel":"live_orders_btcusd","event":"order_deleted"}
{"data":{"id":1722049035100160,"id_str":"1722049035100160","order_type":1,"datetime":"1709257102","microtimestamp":"1709257102405000","amount":0.48907675,"amount_str":"0.48907675","amount_traded":"0","amount_at_create":"0.48907675","price":61341,"price_str":"61341"},"channel":"live_orders_btcusd","event":"order_deleted"}
{"data":{"id":1722049033236480,"id_str":"1722049033236480","order_type":0,"datetime":"1709257102","microtimestamp":"1709257102429000","amount":0.00815301,"amount_str":"0.00815301","amount_traded":"0","amount_at_create":"0.00815301","price":61321,"price_str":"61321"},"channel":"live_orders_btcusd","event":"order_deleted"}
{"data":{"id":1722049034117120,"id_str":"1722049034117120","order_type":0,"datetime":"1709257102","microtimestamp":"1709257102441000","amount":0.00093264,"amount_str":"0.00093264","amount_traded":"0","amount_at_create":"0.00093264","price":61322,"price_str":"61322"},"channel":"live_orders_btcusd","event":"order_deleted"}
{"data":{"id":1722049035436041,"id_str":"1722049035436041","order_type":1,"datetime":"1709257102","microtimestamp":"1709257102450000","amount":0.02000807,"amount_str":"0.02000807","amount_traded":"0","amount_at_create":"0.02000807","price":61351,"price_str":"61351"},"channel":"live_orders_btcusd","event":"order_created"}
{"data":{"id":1722049035440132,"id_str":"1722049035440132","order_type":0,"datetime":"1709257102","microtimestamp":"1709257102451000","amount":0.48923488,"amount_str":"0.48923488","amount_traded":"0","amount_at_create":"0.48923488","price":61320,"price_str":"61320"},"channel":"live_orders_btcusd","event":"order_created"}
{"data":{"id":1722049032851457,"id_str":"1722049032851457","order_type":0,"datetime":"1709257102","microtimestamp":"1709257102458000","amount":0.00040756,"amount_str":"0.00040756","amount_traded":"0","amount_at_create":"0.00040756","price":61317,"price_str":"61317"},"channel":"live_orders_btcusd","event":"order_deleted"}
{"data":{"id":1722049035558914,"id_str":"1722049035558914","order_type":0,"datetime":"1709257102","microtimestamp":"1709257102480000","amount":0.00815268,"amount_str":"0.00815268","amount_traded":"0","amount_at_create":"0.00815268","price":61326,"price_str":"61326"},"channel":"live_orders_btcusd","event":"order_created"}
{"data":{"id":1722049035616257,"id_str":"1722049035616257","order_type":1,"datetime":"1709257102","microtimestamp":"1709257102493000","amount":0.01630448,"amount_str":"0.01630448","amount_traded":"0","amount_at_create":"0.01630448","price":61333,"price_str":"61333"},"channel":"live_orders_btcusd","event":"order_created"}
{"data":{"id":1722049035628545,"id_str":"1722049035628545","order_type":0,"datetime":"1709257102","microtimestamp":"1709257102496000","amount":0.01630626,"amount_str":"0.01630626","amount_traded":"0","amount_at_create":"0.01630626","price":61326,"price_str":"61326"},"channel":"live_orders_btcusd","event":"order_created"}
{"data":{"id":1722049035075586,"id_str":"1722049035075586","order_type":0,"datetime":"1709257103","microtimestamp":"1709257102503000","amount":0.48919478,"amount_str":"0.48919478","amount_traded":"0","amount_at_create":"0.48919478","price":61325,"price_str":"61325"},"channel":"live_orders_btcusd","event":"order_deleted"}
{"data":{"id":1722049035616257,"id_str":"1722049035616257","order_type":1,"datetime":"1709257103","microtimestamp":"1709257102511000","amount":0.01630448,"amount_str":"0.01630448","amount_traded":"0","amount_at_create":"0.01630448","price":61333,"price_str":"61333"},"channel":"live_orders_btcusd","event":"order_deleted"}
{"data":{"id":1722049035710464,"id_str":"1722049035710464","order_type":1,"datetime":"1709257103","microtimestamp":"1709257102516000","amount":0.03718287,"amount_str":"0.03718287","amount_traded":"0","amount_at_create":"0.03718287","price":61349,"price_str":"61349"},"channel":"live_orders_btcusd","event":"order_created"}
{"data":{"id":1722049035759616,"id_str":"1722049035759616","order_type":0,"datetime":"1709257103","microtimestamp":"1709257102529000","amount":0.00093245,"amount_str":"0.00093245","amount_traded":"0","amount_at_create":"0.00093245","price":61326,"price_str":"61326"},"channel":"live_orders_btcusd","event":"order_created"}
{"data":{"id":1722049035878401,"id_str":"1722049035878401","order_type":0,"datetime":"1709257103","microtimestamp":"1709257102557000","amount":0.00040756,"amount_str":"0.00040756","amount_traded":"0","amount_at_create":"0.00040756","price":61316,"price_str":"61316"},"channel":"live_orders_btcusd","event":"order_created"}
{"data":{"id":1722048992481280,"id_str":"1722048992481280","order_type":1,"datetime":"1709257103","microtimestamp":"1709257102632000","amount":0.00272853,"amount_str":"0.00272853","amount_traded":"0","amount_at_create":"0.00272853","price":61536,"price_str":"61536"},"channel":"live_orders_btcusd","event":"order_deleted"}
{"data":{"id":1722049035878401,"id_str":"1722049035878401","order_type":0,"datetime":"1709257103","microtimestamp":"1709257102661000","amount":0.00040756,"amount_str":"0.00040756","amount_traded":"0","amount_at_create":"0.00040756","price":61316,"price_str":"61316"},"channel":"live_orders_btcusd","event":"order_deleted"}
{"data":{"id":1722049036455936,"id_str":"1722049036455936","order_type":0,"datetime":"1709257103","microtimestamp":"1709257102699000","amount":0.00040756,"amount_str":"0.00040756","amount_traded":"0","amount_at_create":"0.00040756","price":61317,"price_str":"61317"},"channel":"live_orders_btcusd","event":"order_created"}
{"data":{"id":1722049032744961,"id_str":"1722049032744961","order_type":1,"datetime":"1709257103","microtimestamp":"1709257102705000","amount":0.40767339,"amount_str":"0.40767339","amount_traded":"0","amount_at_create":"0.40767339","price":61342,"price_str":"61342"},"channel":"live_orders_btcusd","event":"order_deleted"}
{"data":{"id":1722049031757826,"id_str":"1722049031757826","order_type":1,"datetime":"1709257103","microtimestamp":"1709257102705000","amount":0.40767339,"amount_str":"0.40767339","amount_traded":"0","amount_at_create":"0.40767339","price":61341,"price_str":"61341"},"channel":"live_orders_btcusd","event":"order_deleted"}
{"data":{"id":1722049036455936,"id_str":"1722049036455936","order_type":0,"datetime":"1709257103","microtimestamp":"1709257102709000","amount":0.00040756,"amount_str":"0.00040756","amount_traded":"0","amount_at_create":"0.00040756","price":61317,"price_str":"61317"},"channel":"live_orders_btcusd","event":"order_deleted"}
{"data":{"id":1722049036619776,"id_str":"1722049036619776","order_type":0,"datetime":"1709257103","microtimestamp":"1709257102738000","amount":0.00040756,"amount_str":"0.00040756","amount_traded":"0","amount_at_create":"0.00040756","price":61316,"price_str":"61316"},"channel":"live_orders_btcusd","event":"order_created"}
{"data":{"id":1722049036668928,"id_str":"1722049036668928","order_type":0,"datetime":"1709257103","microtimestamp":"1709257102750000","amount":0.40767339,"amount_str":"0.40767339","amount_traded":"0","amount_at_create":"0.40767339","price":61117,"price_str":"61117"},"channel":"live_orders_btcusd","event":"order_created"}
{"data":{"id":1722049035436041,"id_str":"1722049035436041","order_type":1,"datetime":"1709257103","microtimestamp":"1709257102763000","amount":0.02000807,"amount_str":"0.02000807","amount_traded":"0","amount_at_create":"0.02000807","price":61351,"price_str":"61351"},"channel":"live_orders_btcusd","event":"order_deleted"}
{"data":{"id":1722049036668928,"id_str":"1722049036668928","order_type":0,"datetime":"1709257103","microtimestamp":"1709257102765000","amount":0.40767339,"amount_str":"0.40767339","amount_traded":"0","amount_at_create":"0.40767339","price":61117,"price_str":"61117"},"channel":"live_orders_btcusd","event":"order_deleted"}
{"data":{"id":1722049036734466,"id_str":"1722049036734466","order_type":1,"datetime":"1709257103","microtimestamp":"1709257102766000","amount":0.00272853,"amount_str":"0.00272853","amount_traded":"0","amount_at_create":"0.00272853","price":61586,"price_str":"61586"},"channel":"live_orders_btcusd","event":"order_created"}
{"data":{"id":1722049037111297,"id_str":"1722049037111297","order_type":1,"datetime":"1709257103","microtimestamp":"1709257102859000","amount":0.02177815,"amount_str":"0.02177815","amount_traded":"0","amount_at_create":"0.02177815","price":61433,"price_str":"61433"},"channel":"live_orders_btcusd","event":"order_created"}
{"data":{"id":1722049036619776,"id_str":"1722049036619776","order_type":0,"datetime":"1709257103","microtimestamp":"1709257102864000","amount":0.00040756,"amount_str":"0.00040756","amount_traded":"0","amount_at_create":"0.00040756","price":61316,"price_str":"61316"},"channel":"live_orders_btcusd","event":"order_deleted"}
{"data":{"id":1722049037160448,"id_str":"1722049037160448","order_type":0,"datetime":"1709257103","microtimestamp":"1709257102870000","amount":0.48920969,"amount_str":"0.48920969","amount_traded":"0","amount_at_create":"0.48920969","price":61323,"price_str":"61323"},"channel":"live_orders_btcusd","event":"order_created"}
{"data":{"id":1722049037160449,"id_str":"1722049037160449","order_type":1,"datetime":"1709257103","microtimestamp":"1709257102870000","amount":0.48905335,"amount_str":"0.48905335","amount_traded":"0","amount_at_create":"0.48905335","price":61343,"price_str":"61343"},"channel":"live_orders_btcusd","event":"order_created"}
{"data":{"id":1722049037160450,"id_str":"1722049037160450","order_type":1,"datetime":"1709257103","microtimestamp":"1709257102871000","amount":0.01630473,"amount_str":"0.01630473","amount_traded":"0","amount_at_create":"0.01630473","price":61332,"price_str":"61332"},"channel":"live_orders_btcusd","event":"order_created"}
{"data":{"id":1722049037164544,"id_str":"1722049037164544","order_type":1,"datetime":"1709257103","microtimestamp":"1709257102871000","amount":0.48905335,"amount_str":"0.48905335","amount_traded":"0","amount_at_create":"0.48905335","price":61343,"price_str":"61343"},"channel":"live_orders_btcusd","event":"order_created"}
{"data":{"id":1722049037201409,"id_str":"1722049037201409","order_type":0,"datetime":"1709257103","microtimestamp":"1709257102881000","amount":0.40767339,"amount_str":"0.40767339","amount_traded":"0","amount_at_create":"0.40767339","price":61117,"price_str":"61117"},"channel":"live_orders_btcusd","event":"order_created"}
{"data":{"id":1722049037201409,"id_str":"1722049037201409","order_type":0,"datetime":"1709257103","microtimestamp":"1709257102894000","amount":0.40767339,"amount_str":"0.40767339","amount_traded":"0","amount_at_create":"0.40767339","price":61117,"price_str":"61117"},"channel":"live_orders_btcusd","event":"order_deleted"}
{"data":{"id":1722049037279232,"id_str":"1722049037279232","order_type":0,"datetime":"1709257103","microtimestamp":"1709257102899000","amount":0.00040756,"amount_str":"0.00040756","amount_traded":"0","amount_at_create":"0.00040756","price":61317,"price_str":"61317"},"channel":"live_orders_btcusd","event":"order_created"}
{"data":{"id":1722049037111297,"id_str":"1722049037111297","order_type":1,"datetime":"1709257103","microtimestamp":"1709257102904000","amount":0.02177815,"amount_str":"0.02177815","amount_traded":"0","amount_at_create":"0.02177815","price":61433,"price_str":"61433"},"channel":"live_orders_btcusd","event":"order_deleted"}
{"data":{"id":1722049037160449,"id_str":"1722049037160449","order_type":1,"datetime":"1709257103","microtimestamp":"1709257102906000","amount":0.48905335,"amount_str":"0.48905335","amount_traded":"0","amount_at_create":"0.48905335","price":61343,"price_str":"61343"},"channel":"live_orders_btcusd","event":"order_deleted"}
{"data":{"id":1722049037422593,"id_str":"1722049037422593","order_type":1,"datetime":"1709257103","microtimestamp":"1709257102934000","amount":0.059,"amount_str":"0.05900000","amount_traded":"0","amount_at_create":"0.05900000","price":61342,"price_str":"61342"},"channel":"live_orders_btcusd","event":"order_created"}
{"data":{"id":1722049037463553,"id_str":"1722049037463553","order_type":1,"datetime":"1709257103","microtimestamp":"1709257102945000","amount":0.00487252,"amount_str":"0.00487252","amount_traded":"0","amount_at_create":"0.00487252","price":61341,"price_str":"61341"},"channel":"live_orders_btcusd","event":"order_created"}
{"data":{"id":1722049037279232,"id_str":"1722049037279232","order_type":0,"datetime":"1709257103","microtimestamp":"1709257102952000","amount":0.00040756,"amount_str":"0.00040756","amount_traded":"0","amount_at_create":"0.00040756","price":61317,"price_str":"61317"},"channel":"live_orders_btcusd","event":"order_deleted"}
{"data":{"id":1722049037422593,"id_str":"1722049037422593","order_type":1,"datetime":"1709257103","microtimestamp":"1709257102963000","amount":0.059,"amount_str":"0.05900000","amount_traded":"0","amount_at_create":"0.05900000","price":61342,"price_str":"61342"},"channel":"live_orders_btcusd","event":"order_deleted"}
{"data":{"id":1722049037701120,"id_str":"1722049037701120","order_type":0,"datetime":"1709257103","microtimestamp":"1709257103002000","amount":0.00040756,"amount_str":"0.00040756","amount_traded":"0","amount_at_create":"0.00040756","price":61316,"price_str":"61316"},"channel":"live_orders_btcusd","event":"order_created"}
{"data":{"id":1722049035558914,"id_str":"1722049035558914","order_type":0,"datetime":"1709257103","microtimestamp":"1709257103023000","amount":0.00815268,"amount_str":"0.00815268","amount_traded":"0","amount_at_create":"0.00815268","price":61326,"price_str":"61326"},"channel":"live_orders_btcusd","event":"order_deleted"}
{"data":{"id":1722049035628545,"id_str":"1722049035628545","order_type":0,"datetime":"1709257103","microtimestamp":"1709257103033000","amount":0.01630626,"amount_str":"0.01630626","amount_traded":"0","amount_at_create":"0.01630626","price":61326,"price_str":"61326"},"channel":"live_orders_btcusd","event":"order_deleted"}
{"data":{"id":1722049037160450,"id_str":"1722049037160450","order_type":1,"datetime":"1709257103","microtimestamp":"1709257103040000","amount":0.01630473,"amount_str":"0.01630473","amount_traded":"0","amount_at_create":"0.01630473","price":61332,"price_str":"61332"},"channel":"live_orders_btcusd","event":"order_deleted"}
{"data":{"id":1722049035440132,"id_str":"1722049035440132","order_type":0,"datetime":"1709257103","microtimestamp":"1709257103041000","amount":0.48923488,"amount_str":"0.48923488","amount_traded":"0","amount_at_create":"0.48923488","price":61320,"price_str":"61320"},"channel":"live_orders_btcusd","event":"order_deleted"}
{"data":{"id":1722049037160448,"id_str":"1722049037160448","order_type":0,"datetime":"1709257103","microtimestamp":"1709257103042000","amount":0.48920969,"amount_str":"0.48920969","amount_traded":"0","amount_at_create":"0.48920969","price":61323,"price_str":"61323"},"channel":"live_orders_btcusd","event":"order_deleted"}
{"data":{"id":1722049034993667,"id_str":"1722049034993667","order_type":1,"datetime":"1709257103","microtimestamp":"1709257103043000","amount":0.00487272,"amount_str":"0.00487272","amount_traded":"0","amount_at_create":"0.00487272","price":61344,"price_str":"61344"},"channel":"live_orders_btcusd","event":"order_deleted"}
{"data":{"id":1722049030610947,"id_str":"1722049030610947","order_type":0,"datetime":"1709257103","microtimestamp":"1709257103050000","amount":0.48929945,"amount_str":"0.48929945","amount_traded":"0","amount_at_create":"0.48929945","price":61312,"price_str":"61312"},"channel":"live_orders_btcusd","event":"order_deleted"}
{"data":{"id":1722049035710464,"id_str":"1722049035710464","order_type":1,"datetime":"1709257103","microtimestamp":"1709257103053000","amount":0.03718287,"amount_str":"0.03718287","amount_traded":"0","amount_at_create":"0.03718287","price":61349,"price_str":"61349"},"channel":"live_orders_btcusd","event":"order_deleted"}
{"data":{"id":1722049037955076,"id_str":"1722049037955076","order_type":1,"datetime":"1709257103","microtimestamp":"1709257103064000","amount":0.03718287,"amount_str":"0.03718287","amount_traded":"0","amount_at_create":"0.03718287","price":61347,"price_str":"61347"},"channel":"live_orders_btcusd","event":"order_created"}
{"data":{"id":1722049037967360,"id_str":"1722049037967360","order_type":0,"datetime":"1709257103","microtimestamp":"1709257103067000","amount":0.00093259,"amount_str":"0.00093259","amount_traded":"0","amount_at_create":"0.00093259","price":61327,"price_str":"61327"},"channel":"live_orders_btcusd","event":"order_created"}
{"data":{"id":1722049030602753,"id_str":"1722049030602753","order_type":1,"datetime":"1709257103","microtimestamp":"1709257103083000","amount":0.48893364,"amount_str":"0.48893364","amount_traded":"0","amount_at_create":"0.48893364","price":61359,"price_str":"61359"},"channel":"live_orders_btcusd","event":"order_deleted"}
{"data":{"id":1722049038036992,"id_str":"1722049038036992","order_type":1,"datetime":"1709257103","microtimestamp":"1709257103084000","amount":0.00487252,"amount_str":"0.00487252","amount_traded":"0","amount_at_create":"0.00487252","price":61339,"price_str":"61339"},"channel":"live_orders_btcusd","event":"order_created"}
{"data":{"id":1722049038065666,"id_str":"1722049038065666","order_type":1,"datetime":"1709257103","microtimestamp":"1709257103091000","amount":0.02456633,"amount_str":"0.02456633","amount_traded":"0","amount_at_create":"0.02456633","price":61426,"price_str":"61426"},"channel":"live_orders_btcusd","event":"order_created"}
{"data":{"id":1722049038082048,"id_str":"1722049038082048","order_type":1,"datetime":"1709257103","microtimestamp":"1709257103095000","amount":0.0163058,"amount_str":"0.01630580","amount_traded":"0","amount_at_create":"0.01630580","price":61328,"price_str":"61328"},"channel":"live_orders_btcusd","event":"order_created"}
{"data":{"id":1722049038090242,"id_str":"1722049038090242","order_type":1,"datetime":"1709257103","microtimestamp":"1709257103097000","amount":0.48914904,"amount_str":"0.48914904","amount_traded":"0","amount_at_create":"0.48914904","price":61331,"price_str":"61331"},"channel":"live_orders_btcusd","event":"order_created"}
{"data":{"id":1722049038090243,"id_str":"1722049038090243","order_type":1,"datetime":"1709257103","microtimestamp":"1709257103097000","amount":0.1875,"amount_str":"0.18750000","amount_traded":"0","amount_at_create":"0.18750000","price":61341,"price_str":"61341"},"channel":"live_orders_btcusd","event":"order_created"}
{"data":{"id":1722049038090245,"id_str":"1722049038090245","order_type":0,"datetime":"1709257103","microtimestamp":"1709257103098000","amount":0.40767339,"amount_str":"0.40767339","amount_traded":"0","amount_at_create":"0.40767339","price":61117,"price_str":"61117"},"channel":"live_orders_btcusd","event":"order_created"}
{"data":{"id":1722049038094337,"id_str":"1722049038094337","order_type":0,"datetime":"1709257103","microtimestamp":"1709257103098000","amount":0.4893269,"amount_str":"0.48932690","amount_traded":"0","amount_at_create":"0.48932690","price":61308,"price_str":"61308"},"channel":"live_orders_btcusd","event":"order_created"}
{"data":{"id":1722049038094339,"id_str":"1722049038094339","order_type":0,"datetime":"1709257103","microtimestamp":"1709257103098000","amount":0.48924024,"amount_str":"0.48924024","amount_traded":"0","amount_at_create":"0.48924024","price":61319,"price_str":"61319"},"channel":"live_orders_btcusd","event":"order_created"}
{"data":{"id":1722049038094340,"id_str":"1722049038094340","order_type":0,"datetime":"1709257103","microtimestamp":"1709257103099000","amount":0.01630715,"amount_str":"0.01630715","amount_traded":"0","amount_at_create":"0.01630715","price":61322,"price_str":"61322"},"channel":"live_orders_btcusd","event":"order_created"}
{"data":{"id":1722049038094341,"id_str":"1722049038094341","order_type":0,"datetime":"1709257103","microtimestamp":"1709257103099000","amount":0.48925305,"amount_str":"0.48925305","amount_traded":"0","amount_at_create":"0.48925305","price":61317,"price_str":"61317"},"channel":"live_orders_btcusd","event":"order_created"}
{"data":{"id":1722049037967360,"id_str":"1722049037967360","order_type":0,"datetime":"1709257103","microtimestamp":"1709257103104000","amount":0.00093259,"amount_str":"0.00093259","amount_traded":"0","amount_at_create":"0.00093259","price":61327,"price_str":"61327"},"channel":"live_orders_btcusd","event":"order_deleted"}
{"data":{"id":1722049035759616,"id_str":"1722049035759616","order_type":0,"datetime":"1709257103","microtimestamp":"1709257103105000","amount":0.00093245,"amount_str":"0.00093245","amount_traded":"0","amount_at_create":"0.00093245","price":61326,"price_str":"61326"},"channel":"live_orders_btcusd","event":"order_deleted"}
{"data":{"id":1722049038065666,"id_str":"1722049038065666","order_type":1,"datetime":"1709257103","microtimestamp":"1709257103105000","amount":0.02456633,"amount_str":"0.02456633","amount_traded":"0","amount_at_create":"0.02456633","price":61426,"price_str":"61426"},"channel":"live_orders_btcusd","event":"order_deleted"}
{"data":{"id":1722049038090245,"id_str":"1722049038090245","order_type":0,"datetime":"1709257103","microtimestamp":"1709257103111000","amount":0.40767339,"amount_str":"0.40767339","amount_traded":"0","amount_at_create":"0.40767339","price":61117,"price_str":"61117"},"channel":"live_orders_btcusd","event":"order_deleted"}
{"data":{"id":1722049038094341,"id_str":"1722049038094341","order_type":0,"datetime":"1709257103","microtimestamp":"1709257103115000","amount":0.48925305,"amount_str":"0.48925305","amount_traded":"0","amount_at_create":"0.48925305","price":61317,"price_str":"61317"},"channel":"live_orders_btcusd","event":"order_deleted"}
{"data":{"id":1722049038090242,"id_str":"1722049038090242","order_type":1,"datetime":"1709257103","microtimestamp":"1709257103117000","amount":0.48914904,"amount_str":"0.48914904","amount_traded":"0","amount_at_create":"0.48914904","price":61331,"price_str":"61331"},"channel":"live_orders_btcusd","event":"order_deleted"}
{"data":{"id":1722049038090243,"id_str":"1722049038090243","order_type":1,"datetime":"1709257103","microtimestamp":"1709257103126000","amount":0.1875,"amount_str":"0.18750000","amount_traded":"0","amount_at_create":"0.18750000","price":61341,"price_str":"61341"},"channel":"live_orders_btcusd","event":"order_deleted"}
{"data":{"id":1722049038352384,"id_str":"1722049038352384","order_type":1,"datetime":"1709257103","microtimestamp":"1709257103161000","amount":0.48860607,"amount_str":"0.48860607","amount_traded":"0","amount_at_create":"0.48860607","price":61400,"price_str":"61400"},"channel":"live_orders_btcusd","event":"order_created"}
{"data":{"id":1722048981225472,"id_str":"1722048981225472","order_type":0,"datetime":"1709257103","microtimestamp":"1709257103173000","amount":3.06757844,"amount_str":"3.06757844","amount_traded":"0","amount_at_create":"3.06757844","price":61315,"price_str":"61315"},"channel":"live_orders_btcusd","event":"order_deleted"}
{"data":{"id":1722049037701120,"id_str":"1722049037701120","order_type":0,"datetime":"1709257103","microtimestamp":"1709257103177000","amount":0.00040756,"amount_str":"0.00040756","amount_traded":"0","amount_at_create":"0.00040756","price":61316,"price_str":"61316"},"channel":"live_orders_btcusd","event":"order_deleted"}
{"data":{"id":1722049038094340,"id_str":"1722049038094340","order_type":0,"datetime":"1709257103","microtimestamp":"1709257103190000","amount":0.01630715,"amount_str":"0.01630715","amount_traded":"0","amount_at_create":"0.01630715","price":61322,"price_str":"61322"},"channel":"live_orders_btcusd","event":"order_deleted"}
{"data":{"id":1722049038471168,"id_str":"1722049038471168","order_type":0,"datetime":"1709257103","microtimestamp":"1709257103190000","amount":0.5,"amount_str":"0.50000000","amount_traded":"0","amount_at_create":"0.50000000","price":61256,"price_str":"61256"},"channel":"live_orders_btcusd","event":"order_created"}
{"data":{"id":1722049038577664,"id_str":"1722049038577664","order_type":0,"datetime":"1709257103","microtimestamp":"1709257103216000","amount":3.06762847,"amount_str":"3.06762847","amount_traded":"0","amount_at_create":"3.06762847","price":61314,"price_str":"61314"},"channel":"live_orders_btcusd","event":"order_created"}
{"data":{"id":1722049034887169,"id_str":"1722049034887169","order_type":0,"datetime":"1709257103","microtimestamp":"1709257103222000","amount":0.00815314,"amount_str":"0.00815314","amount_traded":"0","amount_at_create":"0.00815314","price":61324,"price_str":"61324"},"channel":"live_orders_btcusd","event":"order_deleted"}
{"data":{"id":1722049038602241,"id_str":"1722049038602241","order_type":0,"datetime":"1709257103","microtimestamp":"1709257103222000","amount":0.00040756,"amount_str":"0.00040756","amount_traded":"0","amount_at_create":"0.00040756","price":61316,"price_str":"61316"},"channel":"live_orders_btcusd","event":"order_created"}
{"data":{"id":1722049037955076,"id_str":"1722049037955076","order_type":1,"datetime":"1709257103","microtimestamp":"1709257103228000","amount":0.03718287,"amount_str":"0.03718287","amount_traded":"0","amount_at_create":"0.03718287","price":61347,"price_str":"61347"},"channel":"live_orders_btcusd","event":"order_deleted"}
{"data":{"id":1722049038651397,"id_str":"1722049038651397","order_type":0,"datetime":"1709257103","microtimestamp":"1709257103234000","amount":0.01630765,"amount_str":"0.01630765","amount_traded":"0","amount_at_create":"0.01630765","price":61320,"price_str":"61320"},"channel":"live_orders_btcusd","event":"order_created"}
{"data":{"id":1722049038082048,"id_str":"1722049038082048","order_type":1,"datetime":"1709257103","microtimestamp":"1709257103239000","amount":0.0163058,"amount_str":"0.01630580","amount_traded":"0","amount_at_create":"0.01630580","price":61328,"price_str":"61328"},"channel":"live_orders_btcusd","event":"order_deleted"}
{"data":{"id":1722048403918851,"id_str":"1722048403918851","order_type":1,"datetime":"1709257103","microtimestamp":"1709257103240000","amount":3.476,"amount_str":"3.47600000","amount_traded":"0","amount_at_create":"3.47600000","price":61537,"price_str":"61537"},"channel":"live_orders_btcusd","event":"order_deleted"}
{"data":{"id":1722049038094339,"id_str":"1722049038094339","order_type":0,"datetime":"1709257103","microtimestamp":"1709257103241000","amount":0.48924024,"amount_str":"0.48924024","amount_traded":"0","amount_at_create":"0.48924024","price":61319,"price_str":"61319"},"channel":"live_orders_btcusd","event":"order_deleted"}
{"data":{"id":1722049038688259,"id_str":"1722049038688259","order_type":1,"datetime":"1709257103","microtimestamp":"1709257103243000","amount":0.03718287,"amount_str":"0.03718287","amount_traded":"0","amount_at_create":"0.03718287","price":61343,"price_str":"61343"},"channel":"live_orders_btcusd","event":"order_created"}
{"data":{"id":1722049037164544,"id_str":"1722049037164544","order_type":1,"datetime":"1709257103","microtimestamp":"1709257103244000","amount":0.48905335,"amount_str":"0.48905335","amount_traded":"0","amount_at_create":"0.48905335","price":61343,"price_str":"61343"},"channel":"live_orders_btcusd","event":"order_deleted"}
{"data":{"id":1722049038712832,"id_str":"1722049038712832","order_type":1,"datetime":"1709257103","microtimestamp":"1709257103249000","amount":0.02234706,"amount_str":"0.02234706","amount_traded":"0","amount_at_create":"0.02234706","price":61423,"price_str":"61423"},"channel":"live_orders_btcusd","event":"order_created"}
{"data":{"id":1722049038602241,"id_str":"1722049038602241","order_type":0,"datetime":"1709257103","microtimestamp":"1709257103250000","amount":0.00040756,"amount_str":"0.00040756","amount_traded":"0","amount_at_create":"0.00040756","price":61316,"price_str":"61316"},"channel":"live_orders_btcusd","event":"order_deleted"}
{"data":{"id":1722049038737408,"id_str":"1722049038737408","order_type":0,"datetime":"1709257103","microtimestamp":"1709257103255000","amount":0.00815314,"amount_str":"0.00815314","amount_traded":"0","amount_at_create":"0.00815314","price":61321,"price_str":"61321"},"channel":"live_orders_btcusd","event":"order_created"}
{"data":{"id":1722049035087872,"id_str":"1722049035087872","order_type":0,"datetime":"1709257103","microtimestamp":"1709257103259000","amount":0.16332658,"amount_str":"0.16332658","amount_traded":"0","amount_at_create":"0.16332658","price":61227,"price_str":"61227"},"channel":"live_orders_btcusd","event":"order_deleted"}
{"data":{"id":1722049030610948,"id_str":"1722049030610948","order_type":0,"datetime":"1709257103","microtimestamp":"1709257103260000","amount":0.48951925,"amount_str":"0.48951925","amount_traded":"0","amount_at_create":"0.48951925","price":61284,"price_str":"61284"},"channel":"live_orders_btcusd","event":"order_deleted"}
{"data":{"id":1722049038712832,"id_str":"1722049038712832","order_type":1,"datetime":"1709257103","microtimestamp":"1709257103277000","amount":0.02234706,"amount_str":"0.02234706","amount_traded":"0","amount_at_create":"0.02234706","price":61423,"price_str":"61423"},"channel":"live_orders_btcusd","event":"order_deleted"}
{"data":{"id":1722049038352384,"id_str":"1722049038352384","order_type":1,"datetime":"1709257103","microtimestamp":"1709257103295000","amount":0.48860607,"amount_str":"0.48860607","amount_traded":"0","amount_at_create":"0.48860607","price":61400,"price_str":"61400"},"channel":"live_orders_btcusd","event":"order_deleted"}
{"data":{"id":1722049038737408,"id_str":"1722049038737408","order_type":0,"datetime":"1709257103","microtimestamp":"1709257103299000","amount":0.00815314,"amount_str":"0.00815314","amount_traded":"0","amount_at_create":"0.00815314","price":61321,"price_str":"61321"},"channel":"live_orders_btcusd","event":"order_deleted"}
{"data":{"id":1722049030873090,"id_str":"1722049030873090","order_type":0,"datetime":"1709257103","microtimestamp":"1709257103307000","amount":0.16306297,"amount_str":"0.16306297","amount_traded":"0","amount_at_create":"0.16306297","price":61306,"price_str":"61306"},"channel":"live_orders_btcusd","event":"order_deleted"}
{"data":{"id":1722049038954498,"id_str":"1722049038954498","order_type":0,"datetime":"1709257103","microtimestamp":"1709257103308000","amount":0.48943787,"amount_str":"0.48943787","amount_traded":"0","amount_at_create":"0.48943787","price":61294,"price_str":"61294"},"channel":"live_orders_btcusd","event":"order_created"}
{"data":{"id":1722049038958595,"id_str":"1722049038958595","order_type":1,"datetime":"1709257103","microtimestamp":"1709257103309000","amount":0.4890806,"amount_str":"0.48908060","amount_traded":"0","amount_at_create":"0.48908060","price":61340,"price_str":"61340"},"channel":"live_orders_btcusd","event":"order_created"}
{"data":{"id":1722049038962689,"id_str":"1722049038962689","order_type":0,"datetime":"1709257103","microtimestamp":"1709257103310000","amount":0.48925511,"amount_str":"0.48925511","amount_traded":"0","amount_at_create":"0.48925511","price":61317,"price_str":"61317"},"channel":"live_orders_btcusd","event":"order_created"}
{"data":{"id":1722049038966786,"id_str":"1722049038966786","order_type":1,"datetime":"1709257103","microtimestamp":"1709257103311000","amount":0.48895758,"amount_str":"0.48895758","amount_traded":"0","amount_at_create":"0.48895758","price":61356,"price_str":"61356"},"channel":"live_orders_btcusd","event":"order_created"}
{"data":{"id":1722049038970880,"id_str":"1722049038970880","order_type":1,"datetime":"1709257103","microtimestamp":"1709257103312000","amount":0.0163063,"amount_str":"0.01630630","amount_traded":"0","amount_at_create":"0.01630630","price":61326,"price_str":"61326"},"channel":"live_orders_btcusd","event":"order_created"}
{"data":{"id":1722049038974976,"id_str":"1722049038974976","order_type":1,"datetime":"1709257103","microtimestamp":"1709257103313000","amount":0.48917411,"amount_str":"0.48917411","amount_traded":"0","amount_at_create":"0.48917411","price":61328,"price_str":"61328"},"channel":"live_orders_btcusd","event":"order_created"}
{"data":{"id":1722049038974978,"id_str":"1722049038974978","order_type":1,"datetime":"1709257103","microtimestamp":"1709257103313000","amount":3.52,"amount_str":"3.52000000","amount_traded":"0","amount_at_create":"3.52000000","price":61529,"price_str":"61529"},"channel":"live_orders_btcusd","event":"order_created"}
{"data":{"id":1722049037463553,"id_str":"1722049037463553","order_type":1,"datetime":"1709257103","microtimestamp":"1709257103315000","amount":0.00487252,"amount_str":"0.00487252","amount_traded":"0","amount_at_create":"0.00487252","price":61341,"price_str":"61341"},"channel":"live_orders_btcusd","event":"order_deleted"}
{"data":{"id":1722049039024131,"id_str":"1722049039024131","order_type":1,"datetime":"1709257103","microtimestamp":"1709257103326000","amount":0.02223123,"amount_str":"0.02223123","amount_traded":"0","amount_at_create":"0.02223123","price":61347,"price_str":"61347"},"channel":"live_orders_btcusd","event":"order_created"}
{"data":{"id":1722049038974976,"id_str":"1722049038974976","order_type":1,"datetime":"1709257103","microtimestamp":"1709257103329000","amount":0.48917411,"amount_str":"0.48917411","amount_traded":"0","amount_at_create":"0.48917411","price":61328,"price_str":"61328"},"channel":"live_orders_btcusd","event":"order_deleted"}
{"data":{"id":1722049038970880,"id_str":"1722049038970880","order_type":1,"datetime":"1709257103","microtimestamp":"1709257103329000","amount":0.0163063,"amount_str":"0.01630630","amount_traded":"0","amount_at_create":"0.01630630","price":61326,"price_str":"61326"},"channel":"live_orders_btcusd","event":"order_deleted"}
{"data":{"id":1722049039052801,"id_str":"1722049039052801","order_type":1,"datetime":"1709257103","microtimestamp":"1709257103332000","amount":0.00487275,"amount_str":"0.00487275","amount_traded":"0","amount_at_create":"0.00487275","price":61336,"price_str":"61336"},"channel":"live_orders_btcusd","event":"order_created"}
{"data":{"id":1722049039130626,"id_str":"1722049039130626","order_type":0,"datetime":"1709257103","microtimestamp":"1709257103351000","amount":0.00815314,"amount_str":"0.00815314","amount_traded":"0","amount_at_create":"0.00815314","price":61319,"price_str":"61319"},"channel":"live_orders_btcusd","event":"order_created"}
{"data":{"id":1722049039151108,"id_str":"1722049039151108","order_type":0,"datetime":"1709257103","microtimestamp":"1709257103356000","amount":0.00040756,"amount_str":"0.00040756","amount_traded":"0","amount_at_create":"0.00040756","price":61311,"price_str":"61311"},"channel":"live_orders_btcusd","event":"order_created"}
{"data":{"id":1722049039208448,"id_str":"1722049039208448","order_type":0,"datetime":"1709257103","microtimestamp":"1709257103370000","amount":0.16306297,"amount_str":"0.16306297","amount_traded":"0","amount_at_create":"0.16306297","price":61300,"price_str":"61300"},"channel":"live_orders_btcusd","event":"order_created"}
{"data":{"id":1722049039212545,"id_str":"1722049039212545","order_type":1,"datetime":"1709257103","microtimestamp":"1709257103371000","amount":0.1875,"amount_str":"0.18750000","amount_traded":"0","amount_at_create":"0.18750000","price":61522,"price_str":"61522"},"channel":"live_orders_btcusd","event":"order_created"}
{"data":{"id":1722049030946819,"id_str":"1722049030946819","order_type":1,"datetime":"1709257103","microtimestamp":"1709257103376000","amount":0.09745519,"amount_str":"0.09745519","amount_traded":"0","amount_at_create":"0.09745519","price":61360,"price_str":"61360"},"channel":"live_orders_btcusd","event":"order_deleted"}
{"data":{"id":1722049039253504,"id_str":"1722049039253504","order_type":1,"datetime":"1709257103","microtimestamp":"1709257103381000","amount":0.48914009,"amount_str":"0.48914009","amount_traded":"0","amount_at_create":"0.48914009","price":61333,"price_str":"61333"},"channel":"live_orders_btcusd","event":"order_created"}
{"data":{"id":1722049039269888,"id_str":"1722049039269888","order_type":1,"datetime":"1709257103","microtimestamp":"1709257103385000","amount":0.1875,"amount_str":"0.18750000","amount_traded":"0","amount_at_create":"0.18750000","price":61343,"price_str":"61343"},"channel":"live_orders_btcusd","event":"order_created"}
{"data":{"id":1722049039310848,"id_str":"1722049039310848","order_type":1,"datetime":"1709257103","microtimestamp":"1709257103395000","amount":0.09744884,"amount_str":"0.09744884","amount_traded":"0","amount_at_create":"0.09744884","price":61355,"price_str":"61355"},"channel":"live_orders_btcusd","event":"order_created"}
{"data":{"id":1722049039425541,"id_str":"1722049039425541","order_type":1,"datetime":"1709257103","microtimestamp":"1709257103424000","amount":0.01630628,"amount_str":"0.01630628","amount_traded":"0","amount_at_create":"0.01630628","price":61327,"price_str":"61327"},"channel":"live_orders_btcusd","event":"order_created"}
{"data":{"id":1722048996503552,"id_str":"1722048996503552","order_type":1,"datetime":"1709257103","microtimestamp":"1709257103433000","amount":0.93147957,"amount_str":"0.93147957","amount_traded":"0","amount_at_create":"0.93147957","price":61375,"price_str":"61375"},"channel":"live_orders_btcusd","event":"order_deleted"}
{"data":{"id":1722049039024131,"id_str":"1722049039024131","order_type":1,"datetime":"1709257103","microtimestamp":"1709257103456000","amount":0.02223123,"amount_str":"0.02223123","amount_traded":"0","amount_at_create":"0.02223123","price":61347,"price_str":"61347"},"channel":"live_orders_btcusd","event":"order_deleted"}
{"data":{"id":1722049039151108,"id_str":"1722049039151108","order_type":0,"datetime":"1709257103","microtimestamp":"1709257103471000","amount":0.00040756,"amount_str":"0.00040756","amount_traded":"0","amount_at_create":"0.00040756","price":61311,"price_str":"61311"},"channel":"live_orders_btcusd","event":"order_deleted"}
{"data":{"id":1722049039634434,"id_str":"1722049039634434","order_type":1,"datetime":"1709257103","microtimestamp":"1709257103474000","amount":0.9314933,"amount_str":"0.93149330","amount_traded":"0","amount_at_create":"0.93149330","price":61374,"price_str":"61374"},"channel":"live_orders_btcusd","event":"order_created"}
{"data":{"id":1722049039671296,"id_str":"1722049039671296","order_type":0,"datetime":"1709257103","microtimestamp":"1709257103483000","amount":0.40767339,"amount_str":"0.40767339","amount_traded":"0","amount_at_create":"0.40767339","price":61115,"price_str":"61115"},"channel":"live_orders_btcusd","event":"order_created"}
{"data":{"id":1722049039671296,"id_str":"1722049039671296","order_type":0,"datetime":"1709257103","microtimestamp":"1709257103497000","amount":0.40767339,"amount_str":"0.40767339","amount_traded":"0","amount_at_create":"0.40767339","price":61115,"price_str":"61115"},"channel":"live_orders_btcusd","event":"order_deleted"}
{"data":{"id":1722049039425541,"id_str":"1722049039425541","order_type":1,"datetime":"1709257103","microtimestamp":"1709257103498000","amount":0.01630628,"amount_str":"0.01630628","amount_traded":"0","amount_at_create":"0.01630628","price":61327,"price_str":"61327"},"channel":"live_orders_btcusd","event":"order_deleted"}
{"data":{"id":1722049038036992,"id_str":"1722049038036992","order_type":1,"datetime":"1709257104","microtimestamp":"1709257103501000","amount":0.00487252,"amount_str":"0.00487252","amount_traded":"0","amount_at_create":"0.00487252","price":61339,"price_str":"61339"},"channel":"live_orders_btcusd","event":"order_deleted"}
{"data":{"id":1722049039757313,"id_str":"1722049039757313","order_type":1,"datetime":"1709257104","microtimestamp":"1709257103504000","amount":0.48914106,"amount_str":"0.48914106","amount_traded":"0","amount_at_create":"0.48914106","price":61332,"price_str":"61332"},"channel":"live_orders_btcusd","event":"order_created"}
{"data":{"id":1722049039253504,"id_str":"1722049039253504","order_type":1,"datetime":"1709257104","microtimestamp":"1709257103505000","amount":0.48914009,"amount_str":"0.48914009","amount_traded":"0","amount_at_create":"0.48914009","price":61333,"price_str":"61333"},"channel":"live_orders_btcusd","event":"order_deleted"}
{"data":{"id":1722049039826945,"id_str":"1722049039826945","order_type":0,"datetime":"1709257104","microtimestamp":"1709257103522000","amount":0.00040756,"amount_str":"0.00040756","amount_traded":"0","amount_at_create":"0.00040756","price":61315,"price_str":"61315"},"channel":"live_orders_btcusd","event":"order_created"}
{"data":{"id":1722049039847424,"id_str":"1722049039847424","order_type":1,"datetime":"1709257104","microtimestamp":"1709257103527000","amount":0.02090217,"amount_str":"0.02090217","amount_traded":"0","amount_at_create":"0.02090217","price":61345,"price_str":"61345"},"channel":"live_orders_btcusd","event":"order_created"}
{"data":{"id":1722049039859712,"id_str":"1722049039859712","order_type":1,"datetime":"1709257104","microtimestamp":"1709257103529000","amount":0.00487295,"amount_str":"0.00487295","amount_traded":"0","amount_at_create":"0.00487295","price":61334,"price_str":"61334"},"channel":"live_orders_btcusd","event":"order_created"}
{"data":{"id":1722049039933440,"id_str":"1722049039933440","order_type":1,"datetime":"1709257104","microtimestamp":"1709257103548000","amount":0.0163063,"amount_str":"0.01630630","amount_traded":"0","amount_at_create":"0.01630630","price":61326,"price_str":"61326"},"channel":"live_orders_btcusd","event":"order_created"}
{"data":{"id":1722049040158721,"id_str":"1722049040158721","order_type":0,"datetime":"1709257104","microtimestamp":"1709257103603000","amount":0.48929215,"amount_str":"0.48929215","amount_traded":"0","amount_at_create":"0.48929215","price":61313,"price_str":"61313"},"channel":"live_orders_btcusd","event":"order_created"}
{"data":{"id":1722049009606657,"id_str":"1722049009606657","order_type":0,"datetime":"1709257104","microtimestamp":"1709257103616000","amount":0.06519874,"amount_str":"0.06519874","amount_traded":"0","amount_at_create":"0.06519874","price":61307,"price_str":"61307"},"channel":"live_orders_btcusd","event":"order_deleted"}
{"data":{"id":1722049039826945,"id_str":"1722049039826945","order_type":0,"datetime":"1709257104","microtimestamp":"1709257103678000","amount":0.00040756,"amount_str":"0.00040756","amount_traded":"0","amount_at_create":"0.00040756","price":61315,"price_str":"61315"},"channel":"live_orders_btcusd","event":"order_deleted"}
{"data":{"id":1722048603226115,"id_str":"1722048603226115","order_type":1,"datetime":"1709257104","microtimestamp":"1709257103731000","amount":4.0234,"amount_str":"4.02340000","amount_traded":"0","amount_at_create":"4.02340000","price":61474,"price_str":"61474"},"channel":"live_orders_btcusd","event":"order_deleted"}
{"data":{"id":1722049040744448,"id_str":"1722049040744448","order_type":0,"datetime":"1709257104","microtimestamp":"1709257103745000","amount":0.00040756,"amount_str":"0.00040756","amount_traded":"0","amount_at_create":"0.00040756","price":61316,"price_str":"61316"},"channel":"live_orders_btcusd","event":"order_created"}
{"data":{"id":1722049040777216,"id_str":"1722049040777216","order_type":1,"datetime":"1709257104","microtimestamp":"1709257103753000","amount":3.8714,"amount_str":"3.87140000","amount_traded":"0","amount_at_create":"3.87140000","price":61435,"price_str":"61435"},"channel":"live_orders_btcusd","event":"order_created"}
{"data":{"id":1722049040744448,"id_str":"1722049040744448","order_type":0,"datetime":"1709257104","microtimestamp":"1709257103755000","amount":0.00040756,"amount_str":"0.00040756","amount_traded":"0","amount_at_create":"0.00040756","price":61316,"price_str":"61316"},"channel":"live_orders_btcusd","event":"order_deleted"}
{"data":{"id":1722048603217921,"id_str":"1722048603217921","order_type":0,"datetime":"1709257104","microtimestamp":"1709257103775000","amount":4.0575,"amount_str":"4.05750000","amount_traded":"0","amount_at_create":"4.05750000","price":61166,"price_str":"61166"},"channel":"live_orders_btcusd","event":"order_deleted"}
{"data":{"id":1722049040920576,"id_str":"1722049040920576","order_type":0,"datetime":"1709257104","microtimestamp":"1709257103788000","amount":0.00040756,"amount_str":"0.00040756","amount_traded":"0","amount_at_create":"0.00040756","price":61315,"price_str":"61315"},"channel":"live_orders_btcusd","event":"order_created"}
{"data":{"id":1722049040949248,"id_str":"1722049040949248","order_type":0,"datetime":"1709257104","microtimestamp":"1709257103796000","amount":3.8525,"amount_str":"3.85250000","amount_traded":"0","amount_at_create":"3.85250000","price":61127,"price_str":"61127"},"channel":"live_orders_btcusd","event":"order_created"}
{"data":{"id":1722049040920576,"id_str":"1722049040920576","order_type":0,"datetime":"1709257104","microtimestamp":"1709257103818000","amount":0.00040756,"amount_str":"0.00040756","amount_traded":"0","amount_at_create":"0.00040756","price":61315,"price_str":"61315"},"channel":"live_orders_btcusd","event":"order_deleted"}
{"data":{"id":1722049041137665,"id_str":"1722049041137665","order_type":0,"datetime":"1709257104","microtimestamp":"1709257103842000","amount":0.1875,"amount_str":"0.18750000","amount_traded":"0","amount_at_create":"0.18750000","price":61145,"price_str":"61145"},"channel":"live_orders_btcusd","event":"order_created"}
{"data":{"id":1722049041289216,"id_str":"1722049041289216","order_type":0,"datetime":"1709257104","microtimestamp":"1709257103878000","amount":0.00040756,"amount_str":"0.00040756","amount_traded":"0","amount_at_create":"0.00040756","price":61316,"price_str":"61316"},"channel":"live_orders_btcusd","event":"order_created"}
{"data":{"id":1722049039859712,"id_str":"1722049039859712","order_type":1,"datetime":"1709257104","microtimestamp":"1709257103909000","amount":0.00487295,"amount_str":"0.00487295","amount_traded":"0","amount_at_create":"0.00487295","price":61334,"price_str":"61334"},"channel":"live_orders_btcusd","event":"order_deleted"}
{"data":{"id":1722049041563651,"id_str":"1722049041563651","order_type":0,"datetime":"1709257104","microtimestamp":"1709257103946000","amount":0.00815354,"amount_str":"0.00815354","amount_traded":"0","amount_at_create":"0.00815354","price":61321,"price_str":"61321"},"channel":"live_orders_btcusd","event":"order_created"}
{"data":{"id":1722049041575939,"id_str":"1722049041575939","order_type":0,"datetime":"1709257104","microtimestamp":"1709257103948000","amount":0.40767339,"amount_str":"0.40767339","amount_traded":"0","amount_at_create":"0.40767339","price":61115,"price_str":"61115"},"channel":"live_orders_btcusd","event":"order_created"}
{"data":{"id":1722049041575939,"id_str":"1722049041575939","order_type":0,"datetime":"1709257104","microtimestamp":"1709257103963000","amount":0.40767339,"amount_str":"0.40767339","amount_traded":"0","amount_at_create":"0.40767339","price":61115,"price_str":"61115"},"channel":"live_orders_btcusd","event":"order_deleted"}
{"data":{"id":1722049039269888,"id_str":"1722049039269888","order_type":1,"datetime":"1709257104","microtimestamp":"1709257103978000","amount":0.1875,"amount_str":"0.18750000","amount_traded":"0","amount_at_create":"0.18750000","price":61343,"price_str":"61343"},"channel":"live_orders_btcusd","event":"order_deleted"}
{"data":{"id":1722049041289216,"id_str":"1722049041289216","order_type":0,"datetime":"1709257104","microtimestamp":"1709257103980000","amount":0.00040756,"amount_str":"0.00040756","amount_traded":"0","amount_at_create":"0.00040756","price":61316,"price_str":"61316"},"channel":"live_orders_btcusd","event":"order_deleted"}
{"data":{"id":1722049038962689,"id_str":"1722049038962689","order_type":0,"datetime":"1709257104","microtimestamp":"1709257104009000","amount":0.48925511,"amount_str":"0.48925511","amount_traded":"0","amount_at_create":"0.48925511","price":61317,"price_str":"61317"},"channel":"live_orders_btcusd","event":"order_deleted"}
{"data":{"id":1722049039933440,"id_str":"1722049039933440","order_type":1,"datetime":"1709257104","microtimestamp":"1709257104009000","amount":0.0163063,"amount_str":"0.01630630","amount_traded":"0","amount_at_create":"0.01630630","price":61326,"price_str":"61326"},"channel":"live_orders_btcusd","event":"order_deleted"}
{"data":{"id":1722049042001922,"id_str":"1722049042001922","order_type":0,"datetime":"1709257104","microtimestamp":"1709257104053000","amount":0.48924908,"amount_str":"0.48924908","amount_traded":"0","amount_at_create":"0.48924908","price":61318,"price_str":"61318"},"channel":"live_orders_btcusd","event":"order_created"}
{"data":{"id":1722049042014209,"id_str":"1722049042014209","order_type":1,"datetime":"1709257104","microtimestamp":"1709257104055000","amount":0.01630601,"amount_str":"0.01630601","amount_traded":"0","amount_at_create":"0.01630601","price":61328,"price_str":"61328"},"channel":"live_orders_btcusd","event":"order_created"}
{"data":{"id":1722049042014211,"id_str":"1722049042014211","order_type":1,"datetime":"1709257104","microtimestamp":"1709257104056000","amount":0.48917218,"amount_str":"0.48917218","amount_traded":"0","amount_at_create":"0.48917218","price":61329,"price_str":"61329"},"channel":"live_orders_btcusd","event":"order_created"}
{"data":{"id":1722049042022400,"id_str":"1722049042022400","order_type":0,"datetime":"1709257104","microtimestamp":"1709257104057000","amount":0.00040756,"amount_str":"0.00040756","amount_traded":"0","amount_at_create":"0.00040756","price":61315,"price_str":"61315"},"channel":"live_orders_btcusd","event":"order_created"}
{"data":{"id":1722048994168832,"id_str":"1722048994168832","order_type":0,"datetime":"1709257104","microtimestamp":"1709257104076000","amount":0.1875,"amount_str":"0.18750000","amount_traded":"0","amount_at_create":"0.18750000","price":61282,"price_str":"61282"},"channel":"live_orders_btcusd","event":"order_deleted"}
{"data":{"id":1722049038651397,"id_str":"1722049038651397","order_type":0,"datetime":"1709257104","microtimestamp":"1709257104100000","amount":0.01630765,"amount_str":"0.01630765","amount_traded":"0","amount_at_create":"0.01630765","price":61320,"price_str":"61320"},"channel":"live_orders_btcusd","event":"order_deleted"}
{"data":{"id":1722049040158721,"id_str":"1722049040158721","order_type":0,"datetime":"1709257104","microtimestamp":"1709257104101000","amount":0.48929215,"amount_str":"0.48929215","amount_traded":"0","amount_at_create":"0.48929215","price":61313,"price_str":"61313"},"channel":"live_orders_btcusd","event":"order_deleted"}
{"data":{"id":1722049042022400,"id_str":"1722049042022400","order_type":0,"datetime":"1709257104","microtimestamp":"1709257104120000","amount":0.00040756,"amount_str":"0.00040756","amount_traded":"0","amount_at_create":"0.00040756","price":61315,"price_str":"61315"},"channel":"live_orders_btcusd","event":"order_deleted"}
{"data":{"id":1722049042378752,"id_str":"1722049042378752","order_type":0,"datetime":"1709257104","microtimestamp":"1709257104144000","amount":0.48927678,"amount_str":"0.48927678","amount_traded":"0","amount_at_create":"0.48927678","price":61314,"price_str":"61314"},"channel":"live_orders_btcusd","event":"order_created"}
{"data":{"id":1722049042382850,"id_str":"1722049042382850","order_type":0,"datetime":"1709257104","microtimestamp":"1709257104145000","amount":0.0163076,"amount_str":"0.01630760","amount_traded":"0","amount_at_create":"0.01630760","price":61321,"price_str":"61321"},"channel":"live_orders_btcusd","event":"order_created"}
{"data":{"id":1722049042563072,"id_str":"1722049042563072","order_type":0,"datetime":"1709257104","microtimestamp":"1709257104189000","amount":0.00040756,"amount_str":"0.00040756","amount_traded":"0","amount_at_create":"0.00040756","price":61316,"price_str":"61316"},"channel":"live_orders_btcusd","event":"order_created"}
{"data":{"id":1722049039757313,"id_str":"1722049039757313","order_type":1,"datetime":"1709257104","microtimestamp":"1709257104200000","amount":0.48914106,"amount_str":"0.48914106","amount_traded":"0","amount_at_create":"0.48914106","price":61332,"price_str":"61332"},"channel":"live_orders_btcusd","event":"order_deleted"}
{"data":{"id":1722049042001922,"id_str":"1722049042001922","order_type":0,"datetime":"1709257104","microtimestamp":"1709257104201000","amount":0.48924908,"amount_str":"0.48924908","amount_traded":"0","amount_at_create":"0.48924908","price":61318,"price_str":"61318"},"channel":"live_orders_btcusd","event":"order_deleted"}
{"data":{"id":1722049042014211,"id_str":"1722049042014211","order_type":1,"datetime":"1709257104","microtimestamp":"1709257104202000","amount":0.48917218,"amount_str":"0.48917218","amount_traded":"0","amount_at_create":"0.48917218","price":61329,"price_str":"61329"},"channel":"live_orders_btcusd","event":"order_deleted"}
{"data":{"id":1722049042792448,"id_str":"1722049042792448","order_type":1,"datetime":"1709257104","microtimestamp":"1709257104245000","amount":0.48912458,"amount_str":"0.48912458","amount_traded":"0","amount_at_create":"0.48912458","price":61335,"price_str":"61335"},"channel":"live_orders_btcusd","event":"order_created"}
{"data":{"id":1722049042563072,"id_str":"1722049042563072","order_type":0,"datetime":"1709257104","microtimestamp":"1709257104254000","amount":0.00040756,"amount_str":"0.00040756","amount_traded":"0","amount_at_create":"0.00040756","price":61316,"price_str":"61316"},"channel":"live_orders_btcusd","event":"order_deleted"}
{"data":{"id":1722049042964480,"id_str":"1722049042964480","order_type":1,"datetime":"1709257104","microtimestamp":"1709257104287000","amount":0.48915614,"amount_str":"0.48915614","amount_traded":"0","amount_at_create":"0.48915614","price":61331,"price_str":"61331"},"channel":"live_orders_btcusd","event":"order_created"}
{"data":{"id":1722049042976770,"id_str":"1722049042976770","order_type":0,"datetime":"1709257104","microtimestamp":"1709257104290000","amount":0.48924169,"amount_str":"0.48924169","amount_traded":"0","amount_at_create":"0.48924169","price":61319,"price_str":"61319"},"channel":"live_orders_btcusd","event":"order_created"}
{"data":{"id":1722049042980864,"id_str":"1722049042980864","order_type":0,"datetime":"1709257104","microtimestamp":"1709257104291000","amount":0.48957028,"amount_str":"0.48957028","amount_traded":"0","amount_at_create":"0.48957028","price":61278,"price_str":"61278"},"channel":"live_orders_btcusd","event":"order_created"}
{"data":{"id":1722049042964480,"id_str":"1722049042964480","order_type":1,"datetime":"1709257104","microtimestamp":"1709257104306000","amount":0.48915614,"amount_str":"0.48915614","amount_traded":"0","amount_at_create":"0.48915614","price":61331,"price_str":"61331"},"channel":"live_orders_btcusd","event":"order_deleted"}
{"data":{"id":1722049043181569,"id_str":"1722049043181569","order_type":0,"datetime":"1709257104","microtimestamp":"1709257104340000","amount":0.1875,"amount_str":"0.18750000","amount_traded":"0","amount_at_create":"0.18750000","price":61279,"price_str":"61279"},"channel":"live_orders_btcusd","event":"order_created"}
{"data":{"id":1722049043210240,"id_str":"1722049043210240","order_type":0,"datetime":"1709257104","microtimestamp":"1709257104347000","amount":0.00040756,"amount_str":"0.00040756","amount_traded":"0","amount_at_create":"0.00040756","price":61315,"price_str":"61315"},"channel":"live_orders_btcusd","event":"order_created"}
{"data":{"id":1722049043247104,"id_str":"1722049043247104","order_type":0,"datetime":"1709257104","microtimestamp":"1709257104356000","amount":0.06519916,"amount_str":"0.06519916","amount_traded":"0","amount_at_create":"0.06519916","price":61307,"price_str":"61307"},"channel":"live_orders_btcusd","event":"order_created"}
{"data":{"id":1722048913600517,"id_str":"1722048913600517","order_type":1,"datetime":"1709257104","microtimestamp":"1709257104378000","amount":0.473,"amount_str":"0.47300000","amount_traded":"0","amount_at_create":"0.47300000","price":61387,"price_str":"61387"},"channel":"live_orders_btcusd","event":"order_deleted"}
{"data":{"id":1722048955486208,"id_str":"1722048955486208","order_type":0,"datetime":"1709257104","microtimestamp":"1709257104379000","amount":0.839,"amount_str":"0.83900000","amount_traded":"0","amount_at_create":"0.83900000","price":61288,"price_str":"61288"},"channel":"live_orders_btcusd","event":"order_deleted"}
{"data":{"id":1722048913612805,"id_str":"1722048913612805","order_type":0,"datetime":"1709257104","microtimestamp":"1709257104380000","amount":0.784,"amount_str":"0.78400000","amount_traded":"0","amount_at_create":"0.78400000","price":61304,"price_str":"61304"},"channel":"live_orders_btcusd","event":"order_deleted"}
{"data":{"id":1722048955482115,"id_str":"1722048955482115","order_type":1,"datetime":"1709257104","microtimestamp":"1709257104380000","amount":0.515,"amount_str":"0.51500000","amount_traded":"0","amount_at_create":"0.51500000","price":61371,"price_str":"61371"},"channel":"live_orders_btcusd","event":"order_deleted"}
{"data":{"id":1722049043468288,"id_str":"1722049043468288","order_type":0,"datetime":"1709257104","microtimestamp":"1709257104410000","amount":0.791,"amount_str":"0.79100000","amount_traded":"0","amount_at_create":"0.79100000","price":61274,"price_str":"61274"},"channel":"live_orders_btcusd","event":"order_created"}
{"data":{"id":1722049043472384,"id_str":"1722049043472384","order_type":0,"datetime":"1709257104","microtimestamp":"1709257104411000","amount":0.758,"amount_str":"0.75800000","amount_traded":"0","amount_at_create":"0.75800000","price":61290,"price_str":"61290"},"channel":"live_orders_btcusd","event":"order_created"}
{"data":{"id":1722049043472385,"id_str":"1722049043472385","order_type":1,"datetime":"1709257104","microtimestamp":"1709257104411000","amount":0.665,"amount_str":"0.66500000","amount_traded":"0","amount_at_create":"0.66500000","price":61357,"price_str":"61357"},"channel":"live_orders_btcusd","event":"order_created"}
{"data":{"id":1722049041563651,"id_str":"1722049041563651","order_type":0,"datetime":"1709257104","microtimestamp":"1709257104425000","amount":0.00815354,"amount_str":"0.00815354","amount_traded":"0","amount_at_create":"0.00815354","price":61321,"price_str":"61321"},"channel":"live_orders_btcusd","event":"order_deleted"}
{"data":{"id":1722049043210240,"id_str":"1722049043210240","order_type":0,"datetime":"1709257104","microtimestamp":"1709257104453000","amount":0.00040756,"amount_str":"0.00040756","amount_traded":"0","amount_at_create":"0.00040756","price":61315,"price_str":"61315"},"channel":"live_orders_btcusd","event":"order_deleted"}
{"data":{"id":1722049043681280,"id_str":"1722049043681280","order_type":1,"datetime":"1709257104","microtimestamp":"1709257104462000","amount":0.842,"amount_str":"0.84200000","amount_traded":"0","amount_at_create":"0.84200000","price":61373,"price_str":"61373"},"channel":"live_orders_btcusd","event":"order_created"}
{"data":{"id":1722049043759106,"id_str":"1722049043759106","order_type":0,"datetime":"1709257104","microtimestamp":"1709257104481000","amount":0.40767339,"amount_str":"0.40767339","amount_traded":"0","amount_at_create":"0.40767339","price":61114,"price_str":"61114"},"channel":"live_orders_btcusd","event":"order_created"}
{"data":{"id":1722049043759106,"id_str":"1722049043759106","order_type":0,"datetime":"1709257104","microtimestamp":"1709257104496000","amount":0.40767339,"amount_str":"0.40767339","amount_traded":"0","amount_at_create":"0.40767339","price":61114,"price_str":"61114"},"channel":"live_orders_btcusd","event":"order_deleted"}
{"data":{"id":1722049044103168,"id_str":"1722049044103168","order_type":0,"datetime":"1709257105","microtimestamp":"1709257104565000","amount":0.00040756,"amount_str":"0.00040756","amount_traded":"0","amount_at_create":"0.00040756","price":61316,"price_str":"61316"},"channel":"live_orders_btcusd","event":"order_created"}
{"data":{"id":1722049044344832,"id_str":"1722049044344832","order_type":1,"datetime":"1709257105","microtimestamp":"1709257104624000","amount":0.48915995,"amount_str":"0.48915995","amount_traded":"0","amount_at_create":"0.48915995","price":61330,"price_str":"61330"},"channel":"live_orders_btcusd","event":"order_created"}
{"data":{"id":1722049044103168,"id_str":"1722049044103168","order_type":0,"datetime":"1709257105","microtimestamp":"1709257104670000","amount":0.00040756,"amount_str":"0.00040756","amount_traded":"0","amount_at_create":"0.00040756","price":61316,"price_str":"61316"},"channel":"live_orders_btcusd","event":"order_deleted"}
{"data":{"id":1722049004191746,"id_str":"1722049004191746","order_type":1,"datetime":"1709257105","microtimestamp":"1709257104757000","amount":0.00033,"amount_str":"0.00033000","amount_traded":"0","amount_at_create":"0.00033000","price":61394,"price_str":"61394"},"channel":"live_orders_btcusd","event":"order_deleted"}
{"data":{"id":1722049044926464,"id_str":"1722049044926464","order_type":0,"datetime":"1709257105","microtimestamp":"1709257104766000","amount":0.00040756,"amount_str":"0.00040756","amount_traded":"0","amount_at_create":"0.00040756","price":61315,"price_str":"61315"},"channel":"live_orders_btcusd","event":"order_created"}
{"data":{"id":1722049043247104,"id_str":"1722049043247104","order_type":0,"datetime":"1709257105","microtimestamp":"1709257104828000","amount":0.06519916,"amount_str":"0.06519916","amount_traded":"0","amount_at_create":"0.06519916","price":61307,"price_str":"61307"},"channel":"live_orders_btcusd","event":"order_deleted"}
{"data":{"id":1722049045200897,"id_str":"1722049045200897","order_type":1,"datetime":"1709257105","microtimestamp":"1709257104834000","amount":0.00033,"amount_str":"0.00033000","amount_traded":"0","amount_at_create":"0.00033000","price":61393,"price_str":"61393"},"channel":"live_orders_btcusd","event":"order_created"}
{"data":{"id":1722049044926464,"id_str":"1722049044926464","order_type":0,"datetime":"1709257105","microtimestamp":"1709257104856000","amount":0.00040756,"amount_str":"0.00040756","amount_traded":"0","amount_at_create":"0.00040756","price":61315,"price_str":"61315"},"channel":"live_orders_btcusd","event":"order_deleted"}
{"data":{"id":1722049045512192,"id_str":"1722049045512192","order_type":0,"datetime":"1709257105","microtimestamp":"1709257104909000","amount":0.00040756,"amount_str":"0.00040756","amount_traded":"0","amount_at_create":"0.00040756","price":61316,"price_str":"61316"},"channel":"live_orders_btcusd","event":"order_created"}
{"data":{"id":1722049045692416,"id_str":"1722049045692416","order_type":0,"datetime":"1709257105","microtimestamp":"1709257104953000","amount":0.40766874,"amount_str":"0.40766874","amount_traded":"0","amount_at_create":"0.40766874","price":61114,"price_str":"61114"},"channel":"live_orders_btcusd","event":"order_created"}
{"data":{"id":1722049045692416,"id_str":"1722049045692416","order_type":0,"datetime":"1709257105","microtimestamp":"1709257104967000","amount":0.40766874,"amount_str":"0.40766874","amount_traded":"0","amount_at_create":"0.40766874","price":61114,"price_str":"61114"},"channel":"live_orders_btcusd","event":"order_deleted"}
{"data":{"id":1722049045512192,"id_str":"1722049045512192","order_type":0,"datetime":"1709257105","microtimestamp":"1709257104999000","amount":0.00040756,"amount_str":"0.00040756","amount_traded":"0","amount_at_create":"0.00040756","price":61316,"price_str":"61316"},"channel":"live_orders_btcusd","event":"order_deleted"}
{"data":{"id":1722049046048771,"id_str":"1722049046048771","order_type":0,"datetime":"1709257105","microtimestamp":"1709257105041000","amount":0.00040756,"amount_str":"0.00040756","amount_traded":"0","amount_at_create":"0.00040756","price":61315,"price_str":"61315"},"channel":"live_orders_btcusd","event":"order_created"}
{"data":{"id":1722049046048771,"id_str":"1722049046048771","order_type":0,"datetime":"1709257105","microtimestamp":"1709257105168000","amount":0.00040756,"amount_str":"0.00040756","amount_traded":"0","amount_at_create":"0.00040756","price":61315,"price_str":"61315"},"channel":"live_orders_btcusd","event":"order_deleted"}
{"data":{"id":1722049046654976,"id_str":"1722049046654976","order_type":0,"datetime":"1709257105","microtimestamp":"1709257105188000","amount":0.06519904,"amount_str":"0.06519904","amount_traded":"0","amount_at_create":"0.06519904","price":61306,"price_str":"61306"},"channel":"live_orders_btcusd","event":"order_created"}
{"data":{"id":1722049042382850,"id_str":"1722049042382850","order_type":0,"datetime":"1709257105","microtimestamp":"1709257105204000","amount":0.0163076,"amount_str":"0.01630760","amount_traded":"0","amount_at_create":"0.01630760","price":61321,"price_str":"61321"},"channel":"live_orders_btcusd","event":"order_deleted"}
{"data":{"id":1722049042378752,"id_str":"1722049042378752","order_type":0,"datetime":"1709257105","microtimestamp":"1709257105204000","amount":0.48927678,"amount_str":"0.48927678","amount_traded":"0","amount_at_create":"0.48927678","price":61314,"price_str":"61314"},"channel":"live_orders_btcusd","event":"order_deleted"}
{"data":{"id":1722049042014209,"id_str":"1722049042014209","order_type":1,"datetime":"1709257105","microtimestamp":"1709257105204000","amount":0.01630601,"amount_str":"0.01630601","amount_traded":"0","amount_at_create":"0.01630601","price":61328,"price_str":"61328"},"channel":"live_orders_btcusd","event":"order_deleted"}
{"data":{"id":1722049044344832,"id_str":"1722049044344832","order_type":1,"datetime":"1709257105","microtimestamp":"1709257105204000","amount":0.48915995,"amount_str":"0.48915995","amount_traded":"0","amount_at_create":"0.48915995","price":61330,"price_str":"61330"},"channel":"live_orders_btcusd","event":"order_deleted"}
{"data":{"id":1722049042976770,"id_str":"1722049042976770","order_type":0,"datetime":"1709257105","microtimestamp":"1709257105205000","amount":0.48924169,"amount_str":"0.48924169","amount_traded":"0","amount_at_create":"0.48924169","price":61319,"price_str":"61319"},"channel":"live_orders_btcusd","event":"order_deleted"}
{"data":{"id":1722049046917120,"id_str":"1722049046917120","order_type":1,"datetime":"1709257105","microtimestamp":"1709257105252000","amount":0.01630545,"amount_str":"0.01630545","amount_traded":"0","amount_at_create":"0.01630545","price":61330,"price_str":"61330"},"channel":"live_orders_btcusd","event":"order_created"}
{"data":{"id":1722049046917124,"id_str":"1722049046917124","order_type":0,"datetime":"1709257105","microtimestamp":"1709257105253000","amount":0.4892629,"amount_str":"0.48926290","amount_traded":"0","amount_at_create":"0.48926290","price":61316,"price_str":"61316"},"channel":"live_orders_btcusd","event":"order_created"}
{"data":{"id":1722049046925314,"id_str":"1722049046925314","order_type":0,"datetime":"1709257105","microtimestamp":"1709257105255000","amount":0.01630714,"amount_str":"0.01630714","amount_traded":"0","amount_at_create":"0.01630714","price":61322,"price_str":"61322"},"channel":"live_orders_btcusd","event":"order_created"}
{"data":{"id":1722049046929411,"id_str":"1722049046929411","order_type":1,"datetime":"1709257105","microtimestamp":"1709257105256000","amount":0.48914658,"amount_str":"0.48914658","amount_traded":"0","amount_at_create":"0.48914658","price":61332,"price_str":"61332"},"channel":"live_orders_btcusd","event":"order_created"}
{"data":{"id":1722049046945793,"id_str":"1722049046945793","order_type":0,"datetime":"1709257105","microtimestamp":"1709257105259000","amount":0.48923134,"amount_str":"0.48923134","amount_traded":"0","amount_at_create":"0.48923134","price":61320,"price_str":"61320"},"channel":"live_orders_btcusd","event":"order_created"}
{"data":{"id":1722049047007234,"id_str":"1722049047007234","order_type":1,"datetime":"1709257105","microtimestamp":"1709257105275000","amount":0.032,"amount_str":"0.03200000","amount_traded":"0","amount_at_create":"0.03200000","price":61334,"price_str":"61334"},"channel":"live_orders_btcusd","event":"order_created"}
{"data":{"id":1722049046929411,"id_str":"1722049046929411","order_type":1,"datetime":"1709257105","microtimestamp":"1709257105275000","amount":0.48914658,"amount_str":"0.48914658","amount_traded":"0","amount_at_create":"0.48914658","price":61332,"price_str":"61332"},"channel":"live_orders_btcusd","event":"order_deleted"}
{"data":{"id":1722049046925314,"id_str":"1722049046925314","order_type":0,"datetime":"1709257105","microtimestamp":"1709257105275000","amount":0.01630714,"amount_str":"0.01630714","amount_traded":"0","amount_at_create":"0.01630714","price":61322,"price_str":"61322"},"channel":"live_orders_btcusd","event":"order_deleted"}
{"data":{"id":1722049047064577,"id_str":"1722049047064577","order_type":0,"datetime":"1709257105","microtimestamp":"1709257105288000","amount":0.00040756,"amount_str":"0.00040756","amount_traded":"0","amount_at_create":"0.00040756","price":61316,"price_str":"61316"},"channel":"live_orders_btcusd","event":"order_created"}
{"data":{"id":1722049047007234,"id_str":"1722049047007234","order_type":1,"datetime":"1709257105","microtimestamp":"1709257105304000","amount":0.032,"amount_str":"0.03200000","amount_traded":"0","amount_at_create":"0.03200000","price":61334,"price_str":"61334"},"channel":"live_orders_btcusd","event":"order_deleted"}
{"data":{"id":1722049046945793,"id_str":"1722049046945793","order_type":0,"datetime":"1709257105","microtimestamp":"1709257105307000","amount":0.48923134,"amount_str":"0.48923134","amount_traded":"0","amount_at_create":"0.48923134","price":61320,"price_str":"61320"},"channel":"live_orders_btcusd","event":"order_deleted"}
{"data":{"id":1722049047322626,"id_str":"1722049047322626","order_type":0,"datetime":"1709257105","microtimestamp":"1709257105352000","amount":0.01630705,"amount_str":"0.01630705","amount_traded":"0","amount_at_create":"0.01630705","price":61323,"price_str":"61323"},"channel":"live_orders_btcusd","event":"order_created"}
{"data":{"id":1722049047064577,"id_str":"1722049047064577","order_type":0,"datetime":"1709257105","microtimestamp":"1709257105358000","amount":0.00040756,"amount_str":"0.00040756","amount_traded":"0","amount_at_create":"0.00040756","price":61316,"price_str":"61316"},"channel":"live_orders_btcusd","event":"order_deleted"}
{"data":{"id":1722049038958595,"id_str":"1722049038958595","order_type":1,"datetime":"1709257105","microtimestamp":"1709257105406000","amount":0.4890806,"amount_str":"0.48908060","amount_traded":"0","amount_at_create":"0.48908060","price":61340,"price_str":"61340"},"channel":"live_orders_btcusd","event":"order_deleted"}
{"data":{"id":1722049046917124,"id_str":"1722049046917124","order_type":0,"datetime":"1709257105","microtimestamp":"1709257105407000","amount":0.4892629,"amount_str":"0.48926290","amount_traded":"0","amount_at_create":"0.48926290","price":61316,"price_str":"61316"},"channel":"live_orders_btcusd","event":"order_deleted"}
{"data":{"id":1722049047695362,"id_str":"1722049047695362","order_type":0,"datetime":"1709257105","microtimestamp":"1709257105443000","amount":0.40766874,"amount_str":"0.40766874","amount_traded":"0","amount_at_create":"0.40766874","price":61114,"price_str":"61114"},"channel":"live_orders_btcusd","event":"order_created"}
{"data":{"id":1722049047715841,"id_str":"1722049047715841","order_type":1,"datetime":"1709257105","microtimestamp":"1709257105447000","amount":0.48914303,"amount_str":"0.48914303","amount_traded":"0","amount_at_create":"0.48914303","price":61332,"price_str":"61332"},"channel":"live_orders_btcusd","event":"order_created"}
{"data":{"id":1722049047728130,"id_str":"1722049047728130","order_type":1,"datetime":"1709257105","microtimestamp":"1709257105450000","amount":0.48904808,"amount_str":"0.48904808","amount_traded":"0","amount_at_create":"0.48904808","price":61344,"price_str":"61344"},"channel":"live_orders_btcusd","event":"order_created"}
{"data":{"id":1722049047732228,"id_str":"1722049047732228","order_type":0,"datetime":"1709257105","microtimestamp":"1709257105452000","amount":0.48922881,"amount_str":"0.48922881","amount_traded":"0","amount_at_create":"0.48922881","price":61321,"price_str":"61321"},"channel":"live_orders_btcusd","event":"order_created"}
{"data":{"id":1722049047695362,"id_str":"1722049047695362","order_type":0,"datetime":"1709257105","microtimestamp":"1709257105459000","amount":0.40766874,"amount_str":"0.40766874","amount_traded":"0","amount_at_create":"0.40766874","price":61114,"price_str":"61114"},"channel":"live_orders_btcusd","event":"order_deleted"}
{"data":{"id":1722049048006656,"id_str":"1722049048006656","order_type":0,"datetime":"1709257106","microtimestamp":"1709257105518000","amount":0.00040756,"amount_str":"0.00040756","amount_traded":"0","amount_at_create":"0.00040756","price":61315,"price_str":"61315"},"channel":"live_orders_btcusd","event":"order_created"}
{"data":{"id":1722049047322626,"id_str":"1722049047322626","order_type":0,"datetime":"1709257106","microtimestamp":"1709257105531000","amount":0.01630705,"amount_str":"0.01630705","amount_traded":"0","amount_at_create":"0.01630705","price":61323,"price_str":"61323"},"channel":"live_orders_btcusd","event":"order_deleted"}
{"data":{"id":1722049047732228,"id_str":"1722049047732228","order_type":0,"datetime":"1709257106","microtimestamp":"1709257105532000","amount":0.48922881,"amount_str":"0.48922881","amount_traded":"0","amount_at_create":"0.48922881","price":61321,"price_str":"61321"},"channel":"live_orders_btcusd","event":"order_deleted"}
{"data":{"id":1722049048244224,"id_str":"1722049048244224","order_type":0,"datetime":"1709257106","microtimestamp":"1709257105576000","amount":0.01630677,"amount_str":"0.01630677","amount_traded":"0","amount_at_create":"0.01630677","price":61324,"price_str":"61324"},"channel":"live_orders_btcusd","event":"order_created"}
{"data":{"id":1722049048809474,"id_str":"1722049048809474","order_type":1,"datetime":"1709257106","microtimestamp":"1709257105715000","amount":0.00487268,"amount_str":"0.00487268","amount_traded":"0","amount_at_create":"0.00487268","price":61334,"price_str":"61334"},"channel":"live_orders_btcusd","event":"order_created"}
{"data":{"id":1722049048006656,"id_str":"1722049048006656","order_type":0,"datetime":"1709257106","microtimestamp":"1709257105778000","amount":0.00040756,"amount_str":"0.00040756","amount_traded":"0","amount_at_create":"0.00040756","price":61315,"price_str":"61315"},"channel":"live_orders_btcusd","event":"order_deleted"}
{"data":{"id":1722049049518081,"id_str":"1722049049518081","order_type":0,"datetime":"1709257106","microtimestamp":"1709257105887000","amount":0.40766874,"amount_str":"0.40766874","amount_traded":"0","amount_at_create":"0.40766874","price":61115,"price_str":"61115"},"channel":"live_orders_btcusd","event":"order_created"}
{"data":{"id":1722049049518081,"id_str":"1722049049518081","order_type":0,"datetime":"1709257106","microtimestamp":"1709257105901000","amount":0.40766874,"amount_str":"0.40766874","amount_traded":"0","amount_at_create":"0.40766874","price":61115,"price_str":"61115"},"channel":"live_orders_btcusd","event":"order_deleted"}
{"data":{"id":1722049049714692,"id_str":"1722049049714692","order_type":0,"datetime":"1709257106","microtimestamp":"1709257105936000","amount":0.00040756,"amount_str":"0.00040756","amount_traded":"0","amount_at_create":"0.00040756","price":61316,"price_str":"61316"},"channel":"live_orders_btcusd","event":"order_created"}
{"data":{"id":1722049049714692,"id_str":"1722049049714692","order_type":0,"datetime":"1709257106","microtimestamp":"1709257105989000","amount":0.00040756,"amount_str":"0.00040756","amount_traded":"0","amount_at_create":"0.00040756","price":61316,"price_str":"61316"},"channel":"live_orders_btcusd","event":"order_deleted"}
{"data":{"id":1722049048809474,"id_str":"1722049048809474","order_type":1,"datetime":"1709257106","microtimestamp":"1709257106029000","amount":0.00487268,"amount_str":"0.00487268","amount_traded":"0","amount_at_create":"0.00487268","price":61334,"price_str":"61334"},"channel":"live_orders_btcusd","event":"order_deleted"}
{"data":{"id":1722049050312704,"id_str":"1722049050312704","order_type":0,"datetime":"1709257106","microtimestamp":"1709257106081000","amount":0.00040756,"amount_str":"0.00040756","amount_traded":"0","amount_at_create":"0.00040756","price":61315,"price_str":"61315"},"channel":"live_orders_btcusd","event":"order_created"}
{"data":{"id":1722049050312704,"id_str":"1722049050312704","order_type":0,"datetime":"1709257106","microtimestamp":"1709257106127000","amount":0.00040756,"amount_str":"0.00040756","amount_traded":"0","amount_at_create":"0.00040756","price":61315,"price_str":"61315"},"channel":"live_orders_btcusd","event":"order_deleted"}
{"data":{"id":1722049050861568,"id_str":"1722049050861568","order_type":0,"datetime":"1709257106","microtimestamp":"1709257106215000","amount":0.00040756,"amount_str":"0.00040756","amount_traded":"0","amount_at_create":"0.00040756","price":61316,"price_str":"61316"},"channel":"live_orders_btcusd","event":"order_created"}
{"data":{"id":1722049050861568,"id_str":"1722049050861568","order_type":0,"datetime":"1709257106","microtimestamp":"1709257106246000","amount":0.00040756,"amount_str":"0.00040756","amount_traded":"0","amount_at_create":"0.00040756","price":61316,"price_str":"61316"},"channel":"live_orders_btcusd","event":"order_deleted"}
{"data":{"id":1722049051209728,"id_str":"1722049051209728","order_type":0,"datetime":"1709257106","microtimestamp":"1709257106300000","amount":0.00040756,"amount_str":"0.00040756","amount_traded":"0","amount_at_create":"0.00040756","price":61315,"price_str":"61315"},"channel":"live_orders_btcusd","event":"order_created"}
{"data":{"id":1722049048244224,"id_str":"1722049048244224","order_type":0,"datetime":"1709257106","microtimestamp":"1709257106302000","amount":0.01630677,"amount_str":"0.01630677","amount_traded":"0","amount_at_create":"0.01630677","price":61324,"price_str":"61324"},"channel":"live_orders_btcusd","event":"order_deleted"}
{"data":{"id":1722049051402243,"id_str":"1722049051402243","order_type":0,"datetime":"1709257106","microtimestamp":"1709257106348000","amount":0.48923139,"amount_str":"0.48923139","amount_traded":"0","amount_at_create":"0.48923139","price":61320,"price_str":"61320"},"channel":"live_orders_btcusd","event":"order_created"}
{"data":{"id":1722049051402244,"id_str":"1722049051402244","order_type":0,"datetime":"1709257106","microtimestamp":"1709257106348000","amount":0.48925399,"amount_str":"0.48925399","amount_traded":"0","amount_at_create":"0.48925399","price":61317,"price_str":"61317"},"channel":"live_orders_btcusd","event":"order_created"}
{"data":{"id":1722049051414528,"id_str":"1722049051414528","order_type":0,"datetime":"1709257106","microtimestamp":"1709257106351000","amount":0.01630714,"amount_str":"0.01630714","amount_traded":"0","amount_at_create":"0.01630714","price":61322,"price_str":"61322"},"channel":"live_orders_btcusd","event":"order_created"}
{"data":{"id":1722049051402243,"id_str":"1722049051402243","order_type":0,"datetime":"1709257106","microtimestamp":"1709257106402000","amount":0.48923139,"amount_str":"0.48923139","amount_traded":"0","amount_at_create":"0.48923139","price":61320,"price_str":"61320"},"channel":"live_orders_btcusd","event":"order_deleted"}
{"data":{"id":1722049051414528,"id_str":"1722049051414528","order_type":0,"datetime":"1709257106","microtimestamp":"1709257106403000","amount":0.01630714,"amount_str":"0.01630714","amount_traded":"0","amount_at_create":"0.01630714","price":61322,"price_str":"61322"},"channel":"live_orders_btcusd","event":"order_deleted"}
{"data":{"id":1722049051209728,"id_str":"1722049051209728","order_type":0,"datetime":"1709257106","microtimestamp":"1709257106439000","amount":0.00040756,"amount_str":"0.00040756","amount_traded":"0","amount_at_create":"0.00040756","price":61315,"price_str":"61315"},"channel":"live_orders_btcusd","event":"order_deleted"}
{"data":{"id":1722049051803648,"id_str":"1722049051803648","order_type":0,"datetime":"1709257106","microtimestamp":"1709257106445000","amount":0.40766874,"amount_str":"0.40766874","amount_traded":"0","amount_at_create":"0.40766874","price":61115,"price_str":"61115"},"channel":"live_orders_btcusd","event":"order_created"}
{"data":{"id":1722049051811840,"id_str":"1722049051811840","order_type":0,"datetime":"1709257106","microtimestamp":"1709257106447000","amount":0.01630701,"amount_str":"0.01630701","amount_traded":"0","amount_at_create":"0.01630701","price":61323,"price_str":"61323"},"channel":"live_orders_btcusd","event":"order_created"}
{"data":{"id":1722049051803648,"id_str":"1722049051803648","order_type":0,"datetime":"1709257106","microtimestamp":"1709257106460000","amount":0.40766874,"amount_str":"0.40766874","amount_traded":"0","amount_at_create":"0.40766874","price":61115,"price_str":"61115"},"channel":"live_orders_btcusd","event":"order_deleted"}
{"data":{"id":1722049039847424,"id_str":"1722049039847424","order_type":1,"datetime":"1709257106","microtimestamp":"1709257106471000","amount":0.02090217,"amount_str":"0.02090217","amount_traded":"0","amount_at_create":"0.02090217","price":61345,"price_str":"61345"},"channel":"live_orders_btcusd","event":"order_deleted"}
{"data":{"id":1722049038688259,"id_str":"1722049038688259","order_type":1,"datetime":"1709257106","microtimestamp":"1709257106479000","amount":0.03718287,"amount_str":"0.03718287","amount_traded":"0","amount_at_create":"0.03718287","price":61343,"price_str":"61343"},"channel":"live_orders_btcusd","event":"order_deleted"}
{"data":{"id":1722049051811840,"id_str":"1722049051811840","order_type":0,"datetime":"1709257106","microtimestamp":"1709257106480000","amount":0.01630701,"amount_str":"0.01630701","amount_traded":"0","amount_at_create":"0.01630701","price":61323,"price_str":"61323"},"channel":"live_orders_btcusd","event":"order_deleted"}
{"data":{"id":1722049051951104,"id_str":"1722049051951104","order_type":0,"datetime":"1709257106","microtimestamp":"1709257106481000","amount":0.00815314,"amount_str":"0.00815314","amount_traded":"0","amount_at_create":"0.00815314","price":61321,"price_str":"61321"},"channel":"live_orders_btcusd","event":"order_created"}
{"data":{"id":1722049038954498,"id_str":"1722049038954498","order_type":0,"datetime":"1709257106","microtimestamp":"1709257106487000","amount":0.48943787,"amount_str":"0.48943787","amount_traded":"0","amount_at_create":"0.48943787","price":61294,"price_str":"61294"},"channel":"live_orders_btcusd","event":"order_deleted"}
{"data":{"id":1722049046917120,"id_str":"1722049046917120","order_type":1,"datetime":"1709257106","microtimestamp":"1709257106487000","amount":0.01630545,"amount_str":"0.01630545","amount_traded":"0","amount_at_create":"0.01630545","price":61330,"price_str":"61330"},"channel":"live_orders_btcusd","event":"order_deleted"}
{"data":{"id":1722049051402244,"id_str":"1722049051402244","order_type":0,"datetime":"1709257106","microtimestamp":"1709257106487000","amount":0.48925399,"amount_str":"0.48925399","amount_traded":"0","amount_at_create":"0.48925399","price":61317,"price_str":"61317"},"channel":"live_orders_btcusd","event":"order_deleted"}
{"data":{"id":1722049047715841,"id_str":"1722049047715841","order_type":1,"datetime":"1709257106","microtimestamp":"1709257106488000","amount":0.48914303,"amount_str":"0.48914303","amount_traded":"0","amount_at_create":"0.48914303","price":61332,"price_str":"61332"},"channel":"live_orders_btcusd","event":"order_deleted"}
{"data":{"id":1722049042980864,"id_str":"1722049042980864","order_type":0,"datetime":"1709257106","microtimestamp":"1709257106488000","amount":0.48957028,"amount_str":"0.48957028","amount_traded":"0","amount_at_create":"0.48957028","price":61278,"price_str":"61278"},"channel":"live_orders_btcusd","event":"order_deleted"}
{"data":{"id":1722049038094337,"id_str":"1722049038094337","order_type":0,"datetime":"1709257106","microtimestamp":"1709257106489000","amount":0.4893269,"amount_str":"0.48932690","amount_traded":"0","amount_at_create":"0.48932690","price":61308,"price_str":"61308"},"channel":"live_orders_btcusd","event":"order_deleted"}
{"data":{"id":1722049039052801,"id_str":"1722049039052801","order_type":1,"datetime":"1709257106","microtimestamp":"1709257106490000","amount":0.00487275,"amount_str":"0.00487275","amount_traded":"0","amount_at_create":"0.00487275","price":61336,"price_str":"61336"},"channel":"live_orders_btcusd","event":"order_deleted"}
{"data":{"id":1722049038966786,"id_str":"1722049038966786","order_type":1,"datetime":"1709257106","microtimestamp":"1709257106494000","amount":0.48895758,"amount_str":"0.48895758","amount_traded":"0","amount_at_create":"0.48895758","price":61356,"price_str":"61356"},"channel":"live_orders_btcusd","event":"order_deleted"}
{"data":{"id":1722049052069888,"id_str":"1722049052069888","order_type":1,"datetime":"1709257107","microtimestamp":"1709257106510000","amount":0.00487275,"amount_str":"0.00487275","amount_traded":"0","amount_at_create":"0.00487275","price":61338,"price_str":"61338"},"channel":"live_orders_btcusd","event":"order_created"}
{"data":{"id":1722049052102657,"id_str":"1722049052102657","order_type":0,"datetime":"1709257107","microtimestamp":"1709257106518000","amount":0.00040756,"amount_str":"0.00040756","amount_traded":"0","amount_at_create":"0.00040756","price":61316,"price_str":"61316"},"channel":"live_orders_btcusd","event":"order_created"}
{"data":{"id":1722049052139525,"id_str":"1722049052139525","order_type":1,"datetime":"1709257107","microtimestamp":"1709257106528000","amount":0.02022787,"amount_str":"0.02022787","amount_traded":"0","amount_at_create":"0.02022787","price":61347,"price_str":"61347"},"channel":"live_orders_btcusd","event":"order_created"}
{"data":{"id":1722049052139525,"id_str":"1722049052139525","order_type":1,"datetime":"1709257107","microtimestamp":"1709257106540000","amount":0.02022787,"amount_str":"0.02022787","amount_traded":"0","amount_at_create":"0.02022787","price":61347,"price_str":"61347"},"channel":"live_orders_btcusd","event":"order_deleted"}
{"data":{"id":1722049052221444,"id_str":"1722049052221444","order_type":0,"datetime":"1709257107","microtimestamp":"1709257106547000","amount":0.48929374,"amount_str":"0.48929374","amount_traded":"0","amount_at_create":"0.48929374","price":61312,"price_str":"61312"},"channel":"live_orders_btcusd","event":"order_created"}
{"data":{"id":1722049052229638,"id_str":"1722049052229638","order_type":1,"datetime":"1709257107","microtimestamp":"1709257106549000","amount":0.01630417,"amount_str":"0.01630417","amount_traded":"0","amount_at_create":"0.01630417","price":61334,"price_str":"61334"},"channel":"live_orders_btcusd","event":"order_created"}
{"data":{"id":1722049052237826,"id_str":"1722049052237826","order_type":0,"datetime":"1709257107","microtimestamp":"1709257106552000","amount":0.48940569,"amount_str":"0.48940569","amount_traded":"0","amount_at_create":"0.48940569","price":61298,"price_str":"61298"},"channel":"live_orders_btcusd","event":"order_created"}
{"data":{"id":1722049052241924,"id_str":"1722049052241924","order_type":1,"datetime":"1709257107","microtimestamp":"1709257106552000","amount":0.48891231,"amount_str":"0.48891231","amount_traded":"0","amount_at_create":"0.48891231","price":61361,"price_str":"61361"},"channel":"live_orders_btcusd","event":"order_created"}
{"data":{"id":1722049052254208,"id_str":"1722049052254208","order_type":1,"datetime":"1709257107","microtimestamp":"1709257106555000","amount":0.48908974,"amount_str":"0.48908974","amount_traded":"0","amount_at_create":"0.48908974","price":61339,"price_str":"61339"},"channel":"live_orders_btcusd","event":"order_created"}
{"data":{"id":1722049052229638,"id_str":"1722049052229638","order_type":1,"datetime":"1709257107","microtimestamp":"1709257106572000","amount":0.01630417,"amount_str":"0.01630417","amount_traded":"0","amount_at_create":"0.01630417","price":61334,"price_str":"61334"},"channel":"live_orders_btcusd","event":"order_deleted"}
{"data":{"id":1722049052102657,"id_str":"1722049052102657","order_type":0,"datetime":"1709257107","microtimestamp":"1709257106579000","amount":0.00040756,"amount_str":"0.00040756","amount_traded":"0","amount_at_create":"0.00040756","price":61316,"price_str":"61316"},"channel":"live_orders_btcusd","event":"order_deleted"}
{"data":{"id":1722049052516354,"id_str":"1722049052516354","order_type":0,"datetime":"1709257107","microtimestamp":"1709257106619000","amount":0.01630613,"amount_str":"0.01630613","amount_traded":"0","amount_at_create":"0.01630613","price":61326,"price_str":"61326"},"channel":"live_orders_btcusd","event":"order_created"}
{"data":{"id":1722049052528644,"id_str":"1722049052528644","order_type":0,"datetime":"1709257107","microtimestamp":"1709257106623000","amount":0.48922083,"amount_str":"0.48922083","amount_traded":"0","amount_at_create":"0.48922083","price":61322,"price_str":"61322"},"channel":"live_orders_btcusd","event":"order_created"}
{"data":{"id":1722049052516354,"id_str":"1722049052516354","order_type":0,"datetime":"1709257107","microtimestamp":"1709257106638000","amount":0.01630613,"amount_str":"0.01630613","amount_traded":"0","amount_at_create":"0.01630613","price":61326,"price_str":"61326"},"channel":"live_orders_btcusd","event":"order_deleted"}
{"data":{"id":1722049052618754,"id_str":"1722049052618754","order_type":0,"datetime":"1709257107","microtimestamp":"1709257106644000","amount":0.00040756,"amount_str":"0.00040756","amount_traded":"0","amount_at_create":"0.00040756","price":61315,"price_str":"61315"},"channel":"live_orders_btcusd","event":"order_created"}
{"data":{"id":1722049052635138,"id_str":"1722049052635138","order_type":1,"datetime":"1709257107","microtimestamp":"1709257106648000","amount":0.0241837,"amount_str":"0.02418370","amount_traded":"0","amount_at_create":"0.02418370","price":61349,"price_str":"61349"},"channel":"live_orders_btcusd","event":"order_created"}
{"data":{"id":1722049052528644,"id_str":"1722049052528644","order_type":0,"datetime":"1709257107","microtimestamp":"1709257106657000","amount":0.48922083,"amount_str":"0.48922083","amount_traded":"0","amount_at_create":"0.48922083","price":61322,"price_str":"61322"},"channel":"live_orders_btcusd","event":"order_deleted"}
{"data":{"id":1722049052798976,"id_str":"1722049052798976","order_type":1,"datetime":"1709257107","microtimestamp":"1709257106688000","amount":0.01630471,"amount_str":"0.01630471","amount_traded":"0","amount_at_create":"0.01630471","price":61332,"price_str":"61332"},"channel":"live_orders_btcusd","event":"order_created"}
{"data":{"id":1722049042792448,"id_str":"1722049042792448","order_type":1,"datetime":"1709257107","microtimestamp":"1709257106698000","amount":0.48912458,"amount_str":"0.48912458","amount_traded":"0","amount_at_create":"0.48912458","price":61335,"price_str":"61335"},"channel":"live_orders_btcusd","event":"order_deleted"}
{"data":{"id":1722049052901376,"id_str":"1722049052901376","order_type":1,"datetime":"1709257107","microtimestamp":"1709257106713000","amount":0.03718287,"amount_str":"0.03718287","amount_traded":"0","amount_at_create":"0.03718287","price":61346,"price_str":"61346"},"channel":"live_orders_btcusd","event":"order_created"}
{"data":{"id":1722049053024256,"id_str":"1722049053024256","order_type":0,"datetime":"1709257107","microtimestamp":"1709257106743000","amount":0.01630638,"amount_str":"0.01630638","amount_traded":"0","amount_at_create":"0.01630638","price":61325,"price_str":"61325"},"channel":"live_orders_btcusd","event":"order_created"}
{"data":{"id":1722049053028352,"id_str":"1722049053028352","order_type":1,"datetime":"1709257107","microtimestamp":"1709257106744000","amount":0.48912511,"amount_str":"0.48912511","amount_traded":"0","amount_at_create":"0.48912511","price":61334,"price_str":"61334"},"channel":"live_orders_btcusd","event":"order_created"}
{"data":{"id":1722049052618754,"id_str":"1722049052618754","order_type":0,"datetime":"1709257107","microtimestamp":"1709257106779000","amount":0.00040756,"amount_str":"0.00040756","amount_traded":"0","amount_at_create":"0.00040756","price":61315,"price_str":"61315"},"channel":"live_orders_btcusd","event":"order_deleted"}
{"data":{"id":1722049053388802,"id_str":"1722049053388802","order_type":0,"datetime":"1709257107","microtimestamp":"1709257106832000","amount":0.48920833,"amount_str":"0.48920833","amount_traded":"0","amount_at_create":"0.48920833","price":61323,"price_str":"61323"},"channel":"live_orders_btcusd","event":"order_created"}
{"data":{"id":1722049053618177,"id_str":"1722049053618177","order_type":0,"datetime":"1709257107","microtimestamp":"1709257106889000","amount":0.40766874,"amount_str":"0.40766874","amount_traded":"0","amount_at_create":"0.40766874","price":61115,"price_str":"61115"},"channel":"live_orders_btcusd","event":"order_created"}
{"data":{"id":1722049053618177,"id_str":"1722049053618177","order_type":0,"datetime":"1709257107","microtimestamp":"1709257106902000","amount":0.40766874,"amount_str":"0.40766874","amount_traded":"0","amount_at_create":"0.40766874","price":61115,"price_str":"61115"},"channel":"live_orders_btcusd","event":"order_deleted"}
{"data":{"id":1722049053896704,"id_str":"1722049053896704","order_type":0,"datetime":"1709257107","microtimestamp":"1709257106956000","amount":0.00040756,"amount_str":"0.00040756","amount_traded":"0","amount_at_create":"0.00040756","price":61316,"price_str":"61316"},"channel":"live_orders_btcusd","event":"order_created"}
{"data":{"id":1722049053896704,"id_str":"1722049053896704","order_type":0,"datetime":"1709257107","microtimestamp":"1709257106997000","amount":0.00040756,"amount_str":"0.00040756","amount_traded":"0","amount_at_create":"0.00040756","price":61316,"price_str":"61316"},"channel":"live_orders_btcusd","event":"order_deleted"}
{"data":{"id":1722049053024256,"id_str":"1722049053024256","order_type":0,"datetime":"1709257107","microtimestamp":"1709257107097000","amount":0.01630638,"amount_str":"0.01630638","amount_traded":"0","amount_at_create":"0.01630638","price":61325,"price_str":"61325"},"channel":"live_orders_btcusd","event":"order_deleted"}
{"data":{"id":1722049054642176,"id_str":"1722049054642176","order_type":0,"datetime":"1709257107","microtimestamp":"1709257107138000","amount":0.00040756,"amount_str":"0.00040756","amount_traded":"0","amount_at_create":"0.00040756","price":61315,"price_str":"61315"},"channel":"live_orders_btcusd","event":"order_created"}
{"data":{"id":1722049054650368,"id_str":"1722049054650368","order_type":0,"datetime":"1709257107","microtimestamp":"1709257107140000","amount":0.48922743,"amount_str":"0.48922743","amount_traded":"0","amount_at_create":"0.48922743","price":61321,"price_str":"61321"},"channel":"live_orders_btcusd","event":"order_created"}
{"data":{"id":1722049054658560,"id_str":"1722049054658560","order_type":0,"datetime":"1709257107","microtimestamp":"1709257107143000","amount":0.01630629,"amount_str":"0.01630629","amount_traded":"0","amount_at_create":"0.01630629","price":61326,"price_str":"61326"},"channel":"live_orders_btcusd","event":"order_created"}
{"data":{"id":1722049054642176,"id_str":"1722049054642176","order_type":0,"datetime":"1709257107","microtimestamp":"1709257107307000","amount":0.00040756,"amount_str":"0.00040756","amount_traded":"0","amount_at_create":"0.00040756","price":61315,"price_str":"61315"},"channel":"live_orders_btcusd","event":"order_deleted"}
{"data":{"id":1722049055494145,"id_str":"1722049055494145","order_type":0,"datetime":"1709257107","microtimestamp":"1709257107347000","amount":0.00031838,"amount_str":"0.00031838","amount_traded":"0","amount_at_create":"0.00031838","price":999999999,"price_str":"999999999"},"channel":"live_orders_btcusd","event":"order_created"}
{"data":{"id":1722049055494145,"id_str":"1722049055494145","order_type":0,"datetime":"1709257107","microtimestamp":"1709257107347000","amount":0,"amount_str":"0","amount_traded":"0.00031838","amount_at_create":"0.00031838","price":61332,"price_str":"61332"},"channel":"live_orders_btcusd","event":"order_deleted"}
{"data":{"id":1722049052798976,"id_str":"1722049052798976","order_type":1,"datetime":"1709257107","microtimestamp":"1709257107347000","amount":0.01598633,"amount_str":"0.01598633","amount_traded":"0.00031838","amount_at_create":"0.01630471","price":61332,"price_str":"61332"},"channel":"live_orders_btcusd","event":"order_changed"}
{"data":{"id":1722049052798976,"id_str":"1722049052798976","order_type":1,"datetime":"1709257107","microtimestamp":"1709257107393000","amount":0.01598633,"amount_str":"0.01598633","amount_traded":"0","amount_at_create":"0.01630471","price":61332,"price_str":"61332"},"channel":"live_orders_btcusd","event":"order_deleted"}
{"data":{"id":1722049053028352,"id_str":"1722049053028352","order_type":1,"datetime":"1709257107","microtimestamp":"1709257107398000","amount":0.48912511,"amount_str":"0.48912511","amount_traded":"0","amount_at_create":"0.48912511","price":61334,"price_str":"61334"},"channel":"live_orders_btcusd","event":"order_deleted"}
{"data":{"id":1722049055707137,"id_str":"1722049055707137","order_type":0,"datetime":"1709257107","microtimestamp":"1709257107398000","amount":0.00040756,"amount_str":"0.00040756","amount_traded":"0","amount_at_create":"0.00040756","price":61316,"price_str":"61316"},"channel":"live_orders_btcusd","event":"order_created"}
{"data":{"id":1722049053388802,"id_str":"1722049053388802","order_type":0,"datetime":"1709257107","microtimestamp":"1709257107399000","amount":0.48920833,"amount_str":"0.48920833","amount_traded":"0","amount_at_create":"0.48920833","price":61323,"price_str":"61323"},"channel":"live_orders_btcusd","event":"order_deleted"}
{"data":{"id":1722049055903746,"id_str":"1722049055903746","order_type":0,"datetime":"1709257107","microtimestamp":"1709257107447000","amount":0.48951297,"amount_str":"0.48951297","amount_traded":"0","amount_at_create":"0.48951297","price":61285,"price_str":"61285"},"channel":"live_orders_btcusd","event":"order_created"}
{"data":{"id":1722049055903747,"id_str":"1722049055903747","order_type":1,"datetime":"1709257107","microtimestamp":"1709257107447000","amount":0.48911665,"amount_str":"0.48911665","amount_traded":"0","amount_at_create":"0.48911665","price":61336,"price_str":"61336"},"channel":"live_orders_btcusd","event":"order_created"}
{"data":{"id":1722049055907841,"id_str":"1722049055907841","order_type":0,"datetime":"1709257107","microtimestamp":"1709257107447000","amount":0.48920009,"amount_str":"0.48920009","amount_traded":"0","amount_at_create":"0.48920009","price":61324,"price_str":"61324"},"channel":"live_orders_btcusd","event":"order_created"}
{"data":{"id":1722049055911936,"id_str":"1722049055911936","order_type":1,"datetime":"1709257107","microtimestamp":"1709257107448000","amount":0.40766874,"amount_str":"0.40766874","amount_traded":"0","amount_at_create":"0.40766874","price":61343,"price_str":"61343"},"channel":"live_orders_btcusd","event":"order_created"}
{"data":{"id":1722049039130626,"id_str":"1722049039130626","order_type":0,"datetime":"1709257108","microtimestamp":"1709257107503000","amount":0.00815314,"amount_str":"0.00815314","amount_traded":"0","amount_at_create":"0.00815314","price":61319,"price_str":"61319"},"channel":"live_orders_btcusd","event":"order_deleted"}
{"data":{"id":1722049055907841,"id_str":"1722049055907841","order_type":0,"datetime":"1709257108","microtimestamp":"1709257107508000","amount":0.48920009,"amount_str":"0.48920009","amount_traded":"0","amount_at_create":"0.48920009","price":61324,"price_str":"61324"},"channel":"live_orders_btcusd","event":"order_deleted"}
{"data":{"id":1722048832622593,"id_str":"1722048832622593","order_type":1,"datetime":"1709257108","microtimestamp":"1709257107508000","amount":0.1875,"amount_str":"0.18750000","amount_traded":"0","amount_at_create":"0.18750000","price":61383,"price_str":"61383"},"channel":"live_orders_btcusd","event":"order_deleted"}
{"data":{"id":1722049054658560,"id_str":"1722049054658560","order_type":0,"datetime":"1709257108","microtimestamp":"1709257107508000","amount":0.01630629,"amount_str":"0.01630629","amount_traded":"0","amount_at_create":"0.01630629","price":61326,"price_str":"61326"},"channel":"live_orders_btcusd","event":"order_deleted"}
{"data":{"id":1722049055707137,"id_str":"1722049055707137","order_type":0,"datetime":"1709257108","microtimestamp":"1709257107523000","amount":0.00040756,"amount_str":"0.00040756","amount_traded":"0","amount_at_create":"0.00040756","price":61316,"price_str":"61316"},"channel":"live_orders_btcusd","event":"order_deleted"}
{"data":{"id":1722049056256000,"id_str":"1722049056256000","order_type":0,"datetime":"1709257108","microtimestamp":"1709257107533000","amount":0.00815248,"amount_str":"0.00815248","amount_traded":"0","amount_at_create":"0.00815248","price":61323,"price_str":"61323"},"channel":"live_orders_btcusd","event":"order_created"}
{"data":{"id":1722049056346113,"id_str":"1722049056346113","order_type":1,"datetime":"1709257108","microtimestamp":"1709257107555000","amount":0.01630438,"amount_str":"0.01630438","amount_traded":"0","amount_at_create":"0.01630438","price":61334,"price_str":"61334"},"channel":"live_orders_btcusd","event":"order_created"}
{"data":{"id":1722049056358400,"id_str":"1722049056358400","order_type":0,"datetime":"1709257108","microtimestamp":"1709257107557000","amount":0.01630591,"amount_str":"0.01630591","amount_traded":"0","amount_at_create":"0.01630591","price":61327,"price_str":"61327"},"channel":"live_orders_btcusd","event":"order_created"}
{"data":{"id":1722049056718849,"id_str":"1722049056718849","order_type":0,"datetime":"1709257108","microtimestamp":"1709257107645000","amount":0.00040756,"amount_str":"0.00040756","amount_traded":"0","amount_at_create":"0.00040756","price":61315,"price_str":"61315"},"channel":"live_orders_btcusd","event":"order_created"}
{"data":{"id":1722049056800768,"id_str":"1722049056800768","order_type":0,"datetime":"1709257108","microtimestamp":"1709257107666000","amount":0.48919443,"amount_str":"0.48919443","amount_traded":"0","amount_at_create":"0.48919443","price":61325,"price_str":"61325"},"channel":"live_orders_btcusd","event":"order_created"}
{"data":{"id":1722049056346113,"id_str":"1722049056346113","order_type":1,"datetime":"1709257108","microtimestamp":"1709257107699000","amount":0.01630438,"amount_str":"0.01630438","amount_traded":"0","amount_at_create":"0.01630438","price":61334,"price_str":"61334"},"channel":"live_orders_btcusd","event":"order_deleted"}
{"data":{"id":1722049055903747,"id_str":"1722049055903747","order_type":1,"datetime":"1709257108","microtimestamp":"1709257107699000","amount":0.48911665,"amount_str":"0.48911665","amount_traded":"0","amount_at_create":"0.48911665","price":61336,"price_str":"61336"},"channel":"live_orders_btcusd","event":"order_deleted"}
{"data":{"id":1722049056718849,"id_str":"1722049056718849","order_type":0,"datetime":"1709257108","microtimestamp":"1709257107736000","amount":0.00040756,"amount_str":"0.00040756","amount_traded":"0","amount_at_create":"0.00040756","price":61315,"price_str":"61315"},"channel":"live_orders_btcusd","event":"order_deleted"}
{"data":{"id":1722049057112064,"id_str":"1722049057112064","order_type":1,"datetime":"1709257108","microtimestamp":"1709257107741000","amount":0.48911766,"amount_str":"0.48911766","amount_traded":"0","amount_at_create":"0.48911766","price":61335,"price_str":"61335"},"channel":"live_orders_btcusd","event":"order_created"}
{"data":{"id":1722049057120261,"id_str":"1722049057120261","order_type":1,"datetime":"1709257108","microtimestamp":"1709257107744000","amount":0.01630448,"amount_str":"0.01630448","amount_traded":"0","amount_at_create":"0.01630448","price":61333,"price_str":"61333"},"channel":"live_orders_btcusd","event":"order_created"}
{"data":{"id":1722049057456129,"id_str":"1722049057456129","order_type":0,"datetime":"1709257108","microtimestamp":"1709257107826000","amount":0.00040756,"amount_str":"0.00040756","amount_traded":"0","amount_at_create":"0.00040756","price":61316,"price_str":"61316"},"channel":"live_orders_btcusd","event":"order_created"}
{"data":{"id":1722049057456129,"id_str":"1722049057456129","order_type":0,"datetime":"1709257108","microtimestamp":"1709257107869000","amount":0.00040756,"amount_str":"0.00040756","amount_traded":"0","amount_at_create":"0.00040756","price":61316,"price_str":"61316"},"channel":"live_orders_btcusd","event":"order_deleted"}
{"data":{"id":1722049052069888,"id_str":"1722049052069888","order_type":1,"datetime":"1709257108","microtimestamp":"1709257107871000","amount":0.00487275,"amount_str":"0.00487275","amount_traded":"0","amount_at_create":"0.00487275","price":61338,"price_str":"61338"},"channel":"live_orders_btcusd","event":"order_deleted"}
{"data":{"id":1722049057767424,"id_str":"1722049057767424","order_type":1,"datetime":"1709257108","microtimestamp":"1709257107901000","amount":0.00487244,"amount_str":"0.00487244","amount_traded":"0","amount_at_create":"0.00487244","price":61340,"price_str":"61340"},"channel":"live_orders_btcusd","event":"order_created"}
{"data":{"id":1722049057959936,"id_str":"1722049057959936","order_type":0,"datetime":"1709257108","microtimestamp":"1709257107948000","amount":0.00040756,"amount_str":"0.00040756","amount_traded":"0","amount_at_create":"0.00040756","price":61315,"price_str":"61315"},"channel":"live_orders_btcusd","event":"order_created"}
{"data":{"id":1722049057959936,"id_str":"1722049057959936","order_type":0,"datetime":"1709257108","microtimestamp":"1709257108055000","amount":0.00040756,"amount_str":"0.00040756","amount_traded":"0","amount_at_create":"0.00040756","price":61315,"price_str":"61315"},"channel":"live_orders_btcusd","event":"order_deleted"}
{"data":{"id":1722049058816000,"id_str":"1722049058816000","order_type":0,"datetime":"1709257108","microtimestamp":"1709257108158000","amount":0.00040756,"amount_str":"0.00040756","amount_traded":"0","amount_at_create":"0.00040756","price":61316,"price_str":"61316"},"channel":"live_orders_btcusd","event":"order_created"}
{"data":{"id":1722049055911936,"id_str":"1722049055911936","order_type":1,"datetime":"1709257108","microtimestamp":"1709257108207000","amount":0.40766874,"amount_str":"0.40766874","amount_traded":"0","amount_at_create":"0.40766874","price":61343,"price_str":"61343"},"channel":"live_orders_btcusd","event":"order_deleted"}
{"data":{"id":1722049059213314,"id_str":"1722049059213314","order_type":0,"datetime":"1709257108","microtimestamp":"1709257108254000","amount":0.40766874,"amount_str":"0.40766874","amount_traded":"0","amount_at_create":"0.40766874","price":61117,"price_str":"61117"},"channel":"live_orders_btcusd","event":"order_created"}
{"data":{"id":1722049059237889,"id_str":"1722049059237889","order_type":1,"datetime":"1709257108","microtimestamp":"1709257108261000","amount":0.00487244,"amount_str":"0.00487244","amount_traded":"0","amount_at_create":"0.00487244","price":61338,"price_str":"61338"},"channel":"live_orders_btcusd","event":"order_created"}
{"data":{"id":1722049059213314,"id_str":"1722049059213314","order_type":0,"datetime":"1709257108","microtimestamp":"1709257108269000","amount":0.40766874,"amount_str":"0.40766874","amount_traded":"0","amount_at_create":"0.40766874","price":61117,"price_str":"61117"},"channel":"live_orders_btcusd","event":"order_deleted"}
{"data":{"id":1722049058816000,"id_str":"1722049058816000","order_type":0,"datetime":"1709257108","microtimestamp":"1709257108276000","amount":0.00040756,"amount_str":"0.00040756","amount_traded":"0","amount_at_create":"0.00040756","price":61316,"price_str":"61316"},"channel":"live_orders_btcusd","event":"order_deleted"}
{"data":{"id":1722049054650368,"id_str":"1722049054650368","order_type":0,"datetime":"1709257108","microtimestamp":"1709257108303000","amount":0.48922743,"amount_str":"0.48922743","amount_traded":"0","amount_at_create":"0.48922743","price":61321,"price_str":"61321"},"channel":"live_orders_btcusd","event":"order_deleted"}
{"data":{"id":1722049057112064,"id_str":"1722049057112064","order_type":1,"datetime":"1709257108","microtimestamp":"1709257108304000","amount":0.48911766,"amount_str":"0.48911766","amount_traded":"0","amount_at_create":"0.48911766","price":61335,"price_str":"61335"},"channel":"live_orders_btcusd","event":"order_deleted"}
{"data":{"id":1722049056800768,"id_str":"1722049056800768","order_type":0,"datetime":"1709257108","microtimestamp":"1709257108304000","amount":0.48919443,"amount_str":"0.48919443","amount_traded":"0","amount_at_create":"0.48919443","price":61325,"price_str":"61325"},"channel":"live_orders_btcusd","event":"order_deleted"}
{"data":{"id":1722049056358400,"id_str":"1722049056358400","order_type":0,"datetime":"1709257108","microtimestamp":"1709257108304000","amount":0.01630591,"amount_str":"0.01630591","amount_traded":"0","amount_at_create":"0.01630591","price":61327,"price_str":"61327"},"channel":"live_orders_btcusd","event":"order_deleted"}
{"data":{"id":1722049057120261,"id_str":"1722049057120261","order_type":1,"datetime":"1709257108","microtimestamp":"1709257108304000","amount":0.01630448,"amount_str":"0.01630448","amount_traded":"0","amount_at_create":"0.01630448","price":61333,"price_str":"61333"},"channel":"live_orders_btcusd","event":"order_deleted"}
{"data":{"id":1722049059479554,"id_str":"1722049059479554","order_type":0,"datetime":"1709257108","microtimestamp":"1709257108319000","amount":0.00040756,"amount_str":"0.00040756","amount_traded":"0","amount_at_create":"0.00040756","price":61315,"price_str":"61315"},"channel":"live_orders_btcusd","event":"order_created"}
{"data":{"id":1722049052254208,"id_str":"1722049052254208","order_type":1,"datetime":"1709257108","microtimestamp":"1709257108350000","amount":0.48908974,"amount_str":"0.48908974","amount_traded":"0","amount_at_create":"0.48908974","price":61339,"price_str":"61339"},"channel":"live_orders_btcusd","event":"order_deleted"}
{"data":{"id":1722049059610626,"id_str":"1722049059610626","order_type":1,"datetime":"1709257108","microtimestamp":"1709257108351000","amount":0.48913092,"amount_str":"0.48913092","amount_traded":"0","amount_at_create":"0.48913092","price":61334,"price_str":"61334"},"channel":"live_orders_btcusd","event":"order_created"}
{"data":{"id":1722049059610628,"id_str":"1722049059610628","order_type":1,"datetime":"1709257108","microtimestamp":"1709257108351000","amount":0.48859561,"amount_str":"0.48859561","amount_traded":"0","amount_at_create":"0.48859561","price":61401,"price_str":"61401"},"channel":"live_orders_btcusd","event":"order_created"}
{"data":{"id":1722049059614723,"id_str":"1722049059614723","order_type":0,"datetime":"1709257108","microtimestamp":"1709257108353000","amount":0.48921425,"amount_str":"0.48921425","amount_traded":"0","amount_at_create":"0.48921425","price":61322,"price_str":"61322"},"channel":"live_orders_btcusd","event":"order_created"}
{"data":{"id":1722049059618818,"id_str":"1722049059618818","order_type":1,"datetime":"1709257108","microtimestamp":"1709257108353000","amount":0.01630492,"amount_str":"0.01630492","amount_traded":"0","amount_at_create":"0.01630492","price":61332,"price_str":"61332"},"channel":"live_orders_btcusd","event":"order_created"}
{"data":{"id":1722049059622913,"id_str":"1722049059622913","order_type":0,"datetime":"1709257108","microtimestamp":"1709257108354000","amount":0.01630657,"amount_str":"0.01630657","amount_traded":"0","amount_at_create":"0.01630657","price":61324,"price_str":"61324"},"channel":"live_orders_btcusd","event":"order_created"}
{"data":{"id":1722049059622912,"id_str":"1722049059622912","order_type":0,"datetime":"1709257108","microtimestamp":"1709257108354000","amount":0.4892457,"amount_str":"0.48924570","amount_traded":"0","amount_at_create":"0.48924570","price":61318,"price_str":"61318"},"channel":"live_orders_btcusd","event":"order_created"}
{"data":{"id":1722049059618818,"id_str":"1722049059618818","order_type":1,"datetime":"1709257108","microtimestamp":"1709257108369000","amount":0.01630492,"amount_str":"0.01630492","amount_traded":"0","amount_at_create":"0.01630492","price":61332,"price_str":"61332"},"channel":"live_orders_btcusd","event":"order_deleted"}
{"data":{"id":1722049059610626,"id_str":"1722049059610626","order_type":1,"datetime":"1709257108","microtimestamp":"1709257108401000","amount":0.48913092,"amount_str":"0.48913092","amount_traded":"0","amount_at_create":"0.48913092","price":61334,"price_str":"61334"},"channel":"live_orders_btcusd","event":"order_deleted"}
{"data":{"id":1722049059856386,"id_str":"1722049059856386","order_type":1,"datetime":"1709257108","microtimestamp":"1709257108412000","amount":0.48910076,"amount_str":"0.48910076","amount_traded":"0","amount_at_create":"0.48910076","price":61338,"price_str":"61338"},"channel":"live_orders_btcusd","event":"order_created"}
{"data":{"id":1722049059856386,"id_str":"1722049059856386","order_type":1,"datetime":"1709257108","microtimestamp":"1709257108426000","amount":0.48910076,"amount_str":"0.48910076","amount_traded":"0","amount_at_create":"0.48910076","price":61338,"price_str":"61338"},"channel":"live_orders_btcusd","event":"order_deleted"}
{"data":{"id":1722049059479554,"id_str":"1722049059479554","order_type":0,"datetime":"1709257108","microtimestamp":"1709257108464000","amount":0.00040756,"amount_str":"0.00040756","amount_traded":"0","amount_at_create":"0.00040756","price":61315,"price_str":"61315"},"channel":"live_orders_btcusd","event":"order_deleted"}
{"data":{"id":1722049060102144,"id_str":"1722049060102144","order_type":1,"datetime":"1709257108","microtimestamp":"1709257108471000","amount":0.01630521,"amount_str":"0.01630521","amount_traded":"0","amount_at_create":"0.01630521","price":61331,"price_str":"61331"},"channel":"live_orders_btcusd","event":"order_created"}
{"data":{"id":1722049060130818,"id_str":"1722049060130818","order_type":0,"datetime":"1709257108","microtimestamp":"1709257108478000","amount":0.40766874,"amount_str":"0.40766874","amount_traded":"0","amount_at_create":"0.40766874","price":61117,"price_str":"61117"},"channel":"live_orders_btcusd","event":"order_created"}
{"data":{"id":1722049060130818,"id_str":"1722049060130818","order_type":0,"datetime":"1709257108","microtimestamp":"1709257108492000","amount":0.40766874,"amount_str":"0.40766874","amount_traded":"0","amount_at_create":"0.40766874","price":61117,"price_str":"61117"},"channel":"live_orders_btcusd","event":"order_deleted"}
{"data":{"id":1722049052901376,"id_str":"1722049052901376","order_type":1,"datetime":"1709257109","microtimestamp":"1709257108503000","amount":0.03718287,"amount_str":"0.03718287","amount_traded":"0","amount_at_create":"0.03718287","price":61346,"price_str":"61346"},"channel":"live_orders_btcusd","event":"order_deleted"}
{"data":{"id":1722049060282368,"id_str":"1722049060282368","order_type":1,"datetime":"1709257109","microtimestamp":"1709257108515000","amount":0.03718287,"amount_str":"0.03718287","amount_traded":"0","amount_at_create":"0.03718287","price":61347,"price_str":"61347"},"channel":"live_orders_btcusd","event":"order_created"}
{"data":{"id":1722049060356096,"id_str":"1722049060356096","order_type":0,"datetime":"1709257109","microtimestamp":"1709257108533000","amount":0.00040756,"amount_str":"0.00040756","amount_traded":"0","amount_at_create":"0.00040756","price":61316,"price_str":"61316"},"channel":"live_orders_btcusd","event":"order_created"}
{"data":{"id":1722049060356096,"id_str":"1722049060356096","order_type":0,"datetime":"1709257109","microtimestamp":"1709257108560000","amount":0.00040756,"amount_str":"0.00040756","amount_traded":"0","amount_at_create":"0.00040756","price":61316,"price_str":"61316"},"channel":"live_orders_btcusd","event":"order_deleted"}
{"data":{"id":1722049060593664,"id_str":"1722049060593664","order_type":0,"datetime":"1709257109","microtimestamp":"1709257108591000","amount":0.00040756,"amount_str":"0.00040756","amount_traded":"0","amount_at_create":"0.00040756","price":61315,"price_str":"61315"},"channel":"live_orders_btcusd","event":"order_created"}
{"data":{"id":1722049060593664,"id_str":"1722049060593664","order_type":0,"datetime":"1709257109","microtimestamp":"1709257108627000","amount":0.00040756,"amount_str":"0.00040756","amount_traded":"0","amount_at_create":"0.00040756","price":61315,"price_str":"61315"},"channel":"live_orders_btcusd","event":"order_deleted"}
{"data":{"id":1722049060978688,"id_str":"1722049060978688","order_type":0,"datetime":"1709257109","microtimestamp":"1709257108685000","amount":0.00040756,"amount_str":"0.00040756","amount_traded":"0","amount_at_create":"0.00040756","price":61316,"price_str":"61316"},"channel":"live_orders_btcusd","event":"order_created"}
{"data":{"id":1722049060978688,"id_str":"1722049060978688","order_type":0,"datetime":"1709257109","microtimestamp":"1709257108743000","amount":0.00040756,"amount_str":"0.00040756","amount_traded":"0","amount_at_create":"0.00040756","price":61316,"price_str":"61316"},"channel":"live_orders_btcusd","event":"order_deleted"}
{"data":{"id":1722049061388289,"id_str":"1722049061388289","order_type":0,"datetime":"1709257109","microtimestamp":"1709257108785000","amount":0.00040756,"amount_str":"0.00040756","amount_traded":"0","amount_at_create":"0.00040756","price":61315,"price_str":"61315"},"channel":"live_orders_btcusd","event":"order_created"}
{"data":{"id":1722049061388289,"id_str":"1722049061388289","order_type":0,"datetime":"1709257109","microtimestamp":"1709257108872000","amount":0.00040756,"amount_str":"0.00040756","amount_traded":"0","amount_at_create":"0.00040756","price":61315,"price_str":"61315"},"channel":"live_orders_btcusd","event":"order_deleted"}
{"data":{"id":1722049062019072,"id_str":"1722049062019072","order_type":0,"datetime":"1709257109","microtimestamp":"1709257108939000","amount":0.00040756,"amount_str":"0.00040756","amount_traded":"0","amount_at_create":"0.00040756","price":61316,"price_str":"61316"},"channel":"live_orders_btcusd","event":"order_created"}
{"data":{"id":1722049062064129,"id_str":"1722049062064129","order_type":0,"datetime":"1709257109","microtimestamp":"1709257108951000","amount":0.40766874,"amount_str":"0.40766874","amount_traded":"0","amount_at_create":"0.40766874","price":61117,"price_str":"61117"},"channel":"live_orders_btcusd","event":"order_created"}
{"data":{"id":1722049062064129,"id_str":"1722049062064129","order_type":0,"datetime":"1709257109","microtimestamp":"1709257108965000","amount":0.40766874,"amount_str":"0.40766874","amount_traded":"0","amount_at_create":"0.40766874","price":61117,"price_str":"61117"},"channel":"live_orders_btcusd","event":"order_deleted"}
{"data":{"id":1722049062019072,"id_str":"1722049062019072","order_type":0,"datetime":"1709257109","microtimestamp":"1709257108966000","amount":0.00040756,"amount_str":"0.00040756","amount_traded":"0","amount_at_create":"0.00040756","price":61316,"price_str":"61316"},"channel":"live_orders_btcusd","event":"order_deleted"}
{"data":{"id":1722049062256640,"id_str":"1722049062256640","order_type":0,"datetime":"1709257109","microtimestamp":"1709257108997000","amount":0.00040756,"amount_str":"0.00040756","amount_traded":"0","amount_at_create":"0.00040756","price":61315,"price_str":"61315"},"channel":"live_orders_btcusd","event":"order_created"}
{"data":{"id":1722049062256640,"id_str":"1722049062256640","order_type":0,"datetime":"1709257109","microtimestamp":"1709257109104000","amount":0.00040756,"amount_str":"0.00040756","amount_traded":"0","amount_at_create":"0.00040756","price":61315,"price_str":"61315"},"channel":"live_orders_btcusd","event":"order_deleted"}
{"data":{"id":1722049062895618,"id_str":"1722049062895618","order_type":0,"datetime":"1709257109","microtimestamp":"1709257109154000","amount":0.00040756,"amount_str":"0.00040756","amount_traded":"0","amount_at_create":"0.00040756","price":61316,"price_str":"61316"},"channel":"live_orders_btcusd","event":"order_created"}
{"data":{"id":1722049062895618,"id_str":"1722049062895618","order_type":0,"datetime":"1709257109","microtimestamp":"1709257109239000","amount":0.00040756,"amount_str":"0.00040756","amount_traded":"0","amount_at_create":"0.00040756","price":61316,"price_str":"61316"},"channel":"live_orders_btcusd","event":"order_deleted"}
{"data":{"id":1722049063473153,"id_str":"1722049063473153","order_type":0,"datetime":"1709257109","microtimestamp":"1709257109295000","amount":0.00040756,"amount_str":"0.00040756","amount_traded":"0","amount_at_create":"0.00040756","price":61315,"price_str":"61315"},"channel":"live_orders_btcusd","event":"order_created"}
{"data":{"id":1722049063829504,"id_str":"1722049063829504","order_type":1,"datetime":"1709257109","microtimestamp":"1709257109381000","amount":0.4891081,"amount_str":"0.48910810","amount_traded":"0","amount_at_create":"0.48910810","price":61337,"price_str":"61337"},"channel":"live_orders_btcusd","event":"order_created"}
{"data":{"id":1722049063829505,"id_str":"1722049063829505","order_type":1,"datetime":"1709257109","microtimestamp":"1709257109382000","amount":0.48913954,"amount_str":"0.48913954","amount_traded":"0","amount_at_create":"0.48913954","price":61333,"price_str":"61333"},"channel":"live_orders_btcusd","event":"order_created"}
{"data":{"id":1722049063841792,"id_str":"1722049063841792","order_type":0,"datetime":"1709257109","microtimestamp":"1709257109384000","amount":0.16332709,"amount_str":"0.16332709","amount_traded":"0","amount_at_create":"0.16332709","price":61226,"price_str":"61226"},"channel":"live_orders_btcusd","event":"order_created"}
{"data":{"id":1722049064005632,"id_str":"1722049064005632","order_type":1,"datetime":"1709257109","microtimestamp":"1709257109424000","amount":0.40766874,"amount_str":"0.40766874","amount_traded":"0","amount_at_create":"0.40766874","price":61343,"price_str":"61343"},"channel":"live_orders_btcusd","event":"order_created"}
{"data":{"id":1722049063473153,"id_str":"1722049063473153","order_type":0,"datetime":"1709257109","microtimestamp":"1709257109434000","amount":0.00040756,"amount_str":"0.00040756","amount_traded":"0","amount_at_create":"0.00040756","price":61315,"price_str":"61315"},"channel":"live_orders_btcusd","event":"order_deleted"}
{"data":{"id":1722049064288256,"id_str":"1722049064288256","order_type":0,"datetime":"1709257109","microtimestamp":"1709257109493000","amount":0.00040756,"amount_str":"0.00040756","amount_traded":"0","amount_at_create":"0.00040756","price":61316,"price_str":"61316"},"channel":"live_orders_btcusd","event":"order_created"}
{"data":{"id":1722049064288256,"id_str":"1722049064288256","order_type":0,"datetime":"1709257110","microtimestamp":"1709257109541000","amount":0.00040756,"amount_str":"0.00040756","amount_traded":"0","amount_at_create":"0.00040756","price":61316,"price_str":"61316"},"channel":"live_orders_btcusd","event":"order_deleted"}
{"data":{"id":1722049064603648,"id_str":"1722049064603648","order_type":0,"datetime":"1709257110","microtimestamp":"1709257109570000","amount":0.00040756,"amount_str":"0.00040756","amount_traded":"0","amount_at_create":"0.00040756","price":61315,"price_str":"61315"},"channel":"live_orders_btcusd","event":"order_created"}
{"data":{"id":1722049052241924,"id_str":"1722049052241924","order_type":1,"datetime":"1709257110","microtimestamp":"1709257109614000","amount":0.48891231,"amount_str":"0.48891231","amount_traded":"0","amount_at_create":"0.48891231","price":61361,"price_str":"61361"},"channel":"live_orders_btcusd","event":"order_deleted"}
{"data":{"id":1722049060102144,"id_str":"1722049060102144","order_type":1,"datetime":"1709257110","microtimestamp":"1709257109615000","amount":0.01630521,"amount_str":"0.01630521","amount_traded":"0","amount_at_create":"0.01630521","price":61331,"price_str":"61331"},"channel":"live_orders_btcusd","event":"order_deleted"}
{"data":{"id":1722049063829505,"id_str":"1722049063829505","order_type":1,"datetime":"1709257110","microtimestamp":"1709257109615000","amount":0.48913954,"amount_str":"0.48913954","amount_traded":"0","amount_at_create":"0.48913954","price":61333,"price_str":"61333"},"channel":"live_orders_btcusd","event":"order_deleted"}
{"data":{"id":1722049064603648,"id_str":"1722049064603648","order_type":0,"datetime":"1709257110","microtimestamp":"1709257109622000","amount":0.00040756,"amount_str":"0.00040756","amount_traded":"0","amount_at_create":"0.00040756","price":61315,"price_str":"61315"},"channel":"live_orders_btcusd","event":"order_deleted"}
{"data":{"id":1722049064976385,"id_str":"1722049064976385","order_type":1,"datetime":"1709257110","microtimestamp":"1709257109661000","amount":0.01630531,"amount_str":"0.01630531","amount_traded":"0","amount_at_create":"0.01630531","price":61330,"price_str":"61330"},"channel":"live_orders_btcusd","event":"order_created"}
{"data":{"id":1722049064980480,"id_str":"1722049064980480","order_type":1,"datetime":"1709257110","microtimestamp":"1709257109662000","amount":0.48914243,"amount_str":"0.48914243","amount_traded":"0","amount_at_create":"0.48914243","price":61332,"price_str":"61332"},"channel":"live_orders_btcusd","event":"order_created"}
{"data":{"id":1722049064980481,"id_str":"1722049064980481","order_type":1,"datetime":"1709257110","microtimestamp":"1709257109662000","amount":0.48894099,"amount_str":"0.48894099","amount_traded":"0","amount_at_create":"0.48894099","price":61358,"price_str":"61358"},"channel":"live_orders_btcusd","event":"order_created"}
{"data":{"id":1722049065013248,"id_str":"1722049065013248","order_type":0,"datetime":"1709257110","microtimestamp":"1709257109670000","amount":0.00040756,"amount_str":"0.00040756","amount_traded":"0","amount_at_create":"0.00040756","price":61316,"price_str":"61316"},"channel":"live_orders_btcusd","event":"order_created"}
{"data":{"id":1722049059614723,"id_str":"1722049059614723","order_type":0,"datetime":"1709257110","microtimestamp":"1709257109763000","amount":0.48921425,"amount_str":"0.48921425","amount_traded":"0","amount_at_create":"0.48921425","price":61322,"price_str":"61322"},"channel":"live_orders_btcusd","event":"order_deleted"}
{"data":{"id":1722049065013248,"id_str":"1722049065013248","order_type":0,"datetime":"1709257110","microtimestamp":"1709257109766000","amount":0.00040756,"amount_str":"0.00040756","amount_traded":"0","amount_at_create":"0.00040756","price":61316,"price_str":"61316"},"channel":"live_orders_btcusd","event":"order_deleted"}
{"data":{"id":1722049065529348,"id_str":"1722049065529348","order_type":0,"datetime":"1709257110","microtimestamp":"1709257109797000","amount":0.00040756,"amount_str":"0.00040756","amount_traded":"0","amount_at_create":"0.00040756","price":61315,"price_str":"61315"},"channel":"live_orders_btcusd","event":"order_created"}
{"data":{"id":1722049065582593,"id_str":"1722049065582593","order_type":0,"datetime":"1709257110","microtimestamp":"1709257109809000","amount":0.4892292,"amount_str":"0.48922920","amount_traded":"0","amount_at_create":"0.48922920","price":61320,"price_str":"61320"},"channel":"live_orders_btcusd","event":"order_created"}
{"data":{"id":1722049064005632,"id_str":"1722049064005632","order_type":1,"datetime":"1709257110","microtimestamp":"1709257109906000","amount":0.40766874,"amount_str":"0.40766874","amount_traded":"0","amount_at_create":"0.40766874","price":61343,"price_str":"61343"},"channel":"live_orders_btcusd","event":"order_deleted"}
{"data":{"id":1722049065529348,"id_str":"1722049065529348","order_type":0,"datetime":"1709257110","microtimestamp":"1709257109929000","amount":0.00040756,"amount_str":"0.00040756","amount_traded":"0","amount_at_create":"0.00040756","price":61315,"price_str":"61315"},"channel":"live_orders_btcusd","event":"order_deleted"}
{"data":{"id":1722049066164225,"id_str":"1722049066164225","order_type":0,"datetime":"1709257110","microtimestamp":"1709257109952000","amount":0.40766874,"amount_str":"0.40766874","amount_traded":"0","amount_at_create":"0.40766874","price":61117,"price_str":"61117"},"channel":"live_orders_btcusd","event":"order_created"}
{"data":{"id":1722049066192896,"id_str":"1722049066192896","order_type":0,"datetime":"1709257110","microtimestamp":"1709257109958000","amount":0.00040756,"amount_str":"0.00040756","amount_traded":"0","amount_at_create":"0.00040756","price":61316,"price_str":"61316"},"channel":"live_orders_btcusd","event":"order_created"}
{"data":{"id":1722049066164225,"id_str":"1722049066164225","order_type":0,"datetime":"1709257110","microtimestamp":"1709257109966000","amount":0.40766874,"amount_str":"0.40766874","amount_traded":"0","amount_at_create":"0.40766874","price":61117,"price_str":"61117"},"channel":"live_orders_btcusd","event":"order_deleted"}
{"data":{"id":1722049059622913,"id_str":"1722049059622913","order_type":0,"datetime":"1709257110","microtimestamp":"1709257109993000","amount":0.01630657,"amount_str":"0.01630657","amount_traded":"0","amount_at_create":"0.01630657","price":61324,"price_str":"61324"},"channel":"live_orders_btcusd","event":"order_deleted"}
{"data":{"id":1722049066516480,"id_str":"1722049066516480","order_type":0,"datetime":"1709257110","microtimestamp":"1709257110037000","amount":0.01630708,"amount_str":"0.01630708","amount_traded":"0","amount_at_create":"0.01630708","price":61323,"price_str":"61323"},"channel":"live_orders_btcusd","event":"order_created"}
{"data":{"id":1722049066192896,"id_str":"1722049066192896","order_type":0,"datetime":"1709257110","microtimestamp":"1709257110041000","amount":0.00040756,"amount_str":"0.00040756","amount_traded":"0","amount_at_create":"0.00040756","price":61316,"price_str":"61316"},"channel":"live_orders_btcusd","event":"order_deleted"}
{"data":{"id":1722049066913793,"id_str":"1722049066913793","order_type":0,"datetime":"1709257110","microtimestamp":"1709257110135000","amount":0.00040756,"amount_str":"0.00040756","amount_traded":"0","amount_at_create":"0.00040756","price":61315,"price_str":"61315"},"channel":"live_orders_btcusd","event":"order_created"}
{"data":{"id":1722049067163648,"id_str":"1722049067163648","order_type":0,"datetime":"1709257110","microtimestamp":"1709257110195000","amount":0.03114,"amount_str":"0.03114000","amount_traded":"0","amount_at_create":"0.03114000","price":999999999,"price_str":"999999999"},"channel":"live_orders_btcusd","event":"order_created"}
{"data":{"id":1722049067163648,"id_str":"1722049067163648","order_type":0,"datetime":"1709257110","microtimestamp":"1709257110195000","amount":0.01483469,"amount_str":"0.01483469","amount_traded":"0.01630531","amount_at_create":"0.03114000","price":61330,"price_str":"61330"},"channel":"live_orders_btcusd","event":"order_changed"}
{"data":{"id":1722049064976385,"id_str":"1722049064976385","order_type":1,"datetime":"1709257110","microtimestamp":"1709257110195000","amount":0,"amount_str":"0","amount_traded":"0.01630531","amount_at_create":"0.01630531","price":61330,"price_str":"61330"},"channel":"live_orders_btcusd","event":"order_deleted"}
{"data":{"id":1722049067163648,"id_str":"1722049067163648","order_type":0,"datetime":"1709257110","microtimestamp":"1709257110195000","amount":0,"amount_str":"0","amount_traded":"0.01483469","amount_at_create":"0.03114000","price":61332,"price_str":"61332"},"channel":"live_orders_btcusd","event":"order_deleted"}
{"data":{"id":1722049064980480,"id_str":"1722049064980480","order_type":1,"datetime":"1709257110","microtimestamp":"1709257110195000","amount":0.47430774,"amount_str":"0.47430774","amount_traded":"0.01483469","amount_at_create":"0.48914243","price":61332,"price_str":"61332"},"channel":"live_orders_btcusd","event":"order_changed"}
{"data":{"id":1722049065582593,"id_str":"1722049065582593","order_type":0,"datetime":"1709257110","microtimestamp":"1709257110198000","amount":0.4892292,"amount_str":"0.48922920","amount_traded":"0","amount_at_create":"0.48922920","price":61320,"price_str":"61320"},"channel":"live_orders_btcusd","event":"order_deleted"}
{"data":{"id":1722049064980480,"id_str":"1722049064980480","order_type":1,"datetime":"1709257110","microtimestamp":"1709257110231000","amount":0.47430774,"amount_str":"0.47430774","amount_traded":"0","amount_at_create":"0.48914243","price":61332,"price_str":"61332"},"channel":"live_orders_btcusd","event":"order_deleted"}
{"data":{"id":1722049038577664,"id_str":"1722049038577664","order_type":0,"datetime":"1709257110","microtimestamp":"1709257110243000","amount":3.06762847,"amount_str":"3.06762847","amount_traded":"0","amount_at_create":"3.06762847","price":61314,"price_str":"61314"},"channel":"live_orders_btcusd","event":"order_deleted"}
{"data":{"id":1722049067376642,"id_str":"1722049067376642","order_type":0,"datetime":"1709257110","microtimestamp":"1709257110247000","amount":0.48922824,"amount_str":"0.48922824","amount_traded":"0","amount_at_create":"0.48922824","price":61321,"price_str":"61321"},"channel":"live_orders_btcusd","event":"order_created"}
{"data":{"id":1722049059622912,"id_str":"1722049059622912","order_type":0,"datetime":"1709257110","microtimestamp":"1709257110255000","amount":0.4892457,"amount_str":"0.48924570","amount_traded":"0","amount_at_create":"0.48924570","price":61318,"price_str":"61318"},"channel":"live_orders_btcusd","event":"order_deleted"}
{"data":{"id":1722049052221444,"id_str":"1722049052221444","order_type":0,"datetime":"1709257110","microtimestamp":"1709257110255000","amount":0.48929374,"amount_str":"0.48929374","amount_traded":"0","amount_at_create":"0.48929374","price":61312,"price_str":"61312"},"channel":"live_orders_btcusd","event":"order_deleted"}
{"data":{"id":1722049066516480,"id_str":"1722049066516480","order_type":0,"datetime":"1709257110","microtimestamp":"1709257110256000","amount":0.01630708,"amount_str":"0.01630708","amount_traded":"0","amount_at_create":"0.01630708","price":61323,"price_str":"61323"},"channel":"live_orders_btcusd","event":"order_deleted"}
{"data":{"id":1722049063829504,"id_str":"1722049063829504","order_type":1,"datetime":"1709257110","microtimestamp":"1709257110258000","amount":0.4891081,"amount_str":"0.48910810","amount_traded":"0","amount_at_create":"0.48910810","price":61337,"price_str":"61337"},"channel":"live_orders_btcusd","event":"order_deleted"}
{"data":{"id":1722049052237826,"id_str":"1722049052237826","order_type":0,"datetime":"1709257110","microtimestamp":"1709257110260000","amount":0.48940569,"amount_str":"0.48940569","amount_traded":"0","amount_at_create":"0.48940569","price":61298,"price_str":"61298"},"channel":"live_orders_btcusd","event":"order_deleted"}
{"data":{"id":1722049056256000,"id_str":"1722049056256000","order_type":0,"datetime":"1709257110","microtimestamp":"1709257110262000","amount":0.00815248,"amount_str":"0.00815248","amount_traded":"0","amount_at_create":"0.00815248","price":61323,"price_str":"61323"},"channel":"live_orders_btcusd","event":"order_deleted"}
{"data":{"id":1722049067376642,"id_str":"1722049067376642","order_type":0,"datetime":"1709257110","microtimestamp":"1709257110263000","amount":0.48922824,"amount_str":"0.48922824","amount_traded":"0","amount_at_create":"0.48922824","price":61321,"price_str":"61321"},"channel":"live_orders_btcusd","event":"order_deleted"}
{"data":{"id":1722049052635138,"id_str":"1722049052635138","order_type":1,"datetime":"1709257110","microtimestamp":"1709257110265000","amount":0.0241837,"amount_str":"0.02418370","amount_traded":"0","amount_at_create":"0.02418370","price":61349,"price_str":"61349"},"channel":"live_orders_btcusd","event":"order_deleted"}
{"data":{"id":1722049066913793,"id_str":"1722049066913793","order_type":0,"datetime":"1709257110","microtimestamp":"1709257110278000","amount":0.00040756,"amount_str":"0.00040756","amount_traded":"0","amount_at_create":"0.00040756","price":61315,"price_str":"61315"},"channel":"live_orders_btcusd","event":"order_deleted"}
{"data":{"id":1722049039634434,"id_str":"1722049039634434","order_type":1,"datetime":"1709257110","microtimestamp":"1709257110279000","amount":0.9314933,"amount_str":"0.93149330","amount_traded":"0","amount_at_create":"0.93149330","price":61374,"price_str":"61374"},"channel":"live_orders_btcusd","event":"order_deleted"}
{"data":{"id":1722049001275392,"id_str":"1722049001275392","order_type":0,"datetime":"1709257110","microtimestamp":"1709257110283000","amount":0.1875,"amount_str":"0.18750000","amount_traded":"0","amount_at_create":"0.18750000","price":61310,"price_str":"61310"},"channel":"live_orders_btcusd","event":"order_deleted"}
{"data":{"id":1722049067532288,"id_str":"1722049067532288","order_type":1,"datetime":"1709257110","microtimestamp":"1709257110285000","amount":0.1875,"amount_str":"0.18750000","amount_traded":"0","amount_at_create":"0.18750000","price":61339,"price_str":"61339"},"channel":"live_orders_btcusd","event":"order_created"}
{"data":{"id":1722049067606024,"id_str":"1722049067606024","order_type":0,"datetime":"1709257110","microtimestamp":"1709257110304000","amount":3.06811088,"amount_str":"3.06811088","amount_traded":"0","amount_at_create":"3.06811088","price":61311,"price_str":"61311"},"channel":"live_orders_btcusd","event":"order_created"}
{"data":{"id":1722049060282368,"id_str":"1722049060282368","order_type":1,"datetime":"1709257110","microtimestamp":"1709257110305000","amount":0.03718287,"amount_str":"0.03718287","amount_traded":"0","amount_at_create":"0.03718287","price":61347,"price_str":"61347"},"channel":"live_orders_btcusd","event":"order_deleted"}
{"data":{"id":1722049057767424,"id_str":"1722049057767424","order_type":1,"datetime":"1709257110","microtimestamp":"1709257110317000","amount":0.00487244,"amount_str":"0.00487244","amount_traded":"0","amount_at_create":"0.00487244","price":61340,"price_str":"61340"},"channel":"live_orders_btcusd","event":"order_deleted"}
{"data":{"id":1722049067606024,"id_str":"1722049067606024","order_type":0,"datetime":"1709257110","microtimestamp":"1709257110317000","amount":3.06811088,"amount_str":"3.06811088","amount_traded":"0","amount_at_create":"3.06811088","price":61311,"price_str":"61311"},"channel":"live_orders_btcusd","event":"order_deleted"}
{"data":{"id":1722049067671554,"id_str":"1722049067671554","order_type":1,"datetime":"1709257110","microtimestamp":"1709257110319000","amount":0.03718287,"amount_str":"0.03718287","amount_traded":"0","amount_at_create":"0.03718287","price":61343,"price_str":"61343"},"channel":"live_orders_btcusd","event":"order_created"}
{"data":{"id":1722049067679747,"id_str":"1722049067679747","order_type":1,"datetime":"1709257110","microtimestamp":"1709257110321000","amount":0.02409072,"amount_str":"0.02409072","amount_traded":"0","amount_at_create":"0.02409072","price":61345,"price_str":"61345"},"channel":"live_orders_btcusd","event":"order_created"}
{"data":{"id":1722049067679747,"id_str":"1722049067679747","order_type":1,"datetime":"1709257110","microtimestamp":"1709257110334000","amount":0.02409072,"amount_str":"0.02409072","amount_traded":"0","amount_at_create":"0.02409072","price":61345,"price_str":"61345"},"channel":"live_orders_btcusd","event":"order_deleted"}
{"data":{"id":1722049067737088,"id_str":"1722049067737088","order_type":1,"datetime":"1709257110","microtimestamp":"1709257110335000","amount":0.00487272,"amount_str":"0.00487272","amount_traded":"0","amount_at_create":"0.00487272","price":61336,"price_str":"61336"},"channel":"live_orders_btcusd","event":"order_created"}
{"data":{"id":1722049004187649,"id_str":"1722049004187649","order_type":0,"datetime":"1709257110","microtimestamp":"1709257110337000","amount":0.04875518,"amount_str":"0.04875518","amount_traded":"0","amount_at_create":"0.04875518","price":61299,"price_str":"61299"},"channel":"live_orders_btcusd","event":"order_deleted"}
{"data":{"id":1722049067769856,"id_str":"1722049067769856","order_type":1,"datetime":"1709257110","microtimestamp":"1709257110343000","amount":0.93156573,"amount_str":"0.93156573","amount_traded":"0","amount_at_create":"0.93156573","price":61369,"price_str":"61369"},"channel":"live_orders_btcusd","event":"order_created"}
{"data":{"id":1722049051951104,"id_str":"1722049051951104","order_type":0,"datetime":"1709257110","microtimestamp":"1709257110344000","amount":0.00815314,"amount_str":"0.00815314","amount_traded":"0","amount_at_create":"0.00815314","price":61321,"price_str":"61321"},"channel":"live_orders_btcusd","event":"order_deleted"}
{"data":{"id":1722049067851776,"id_str":"1722049067851776","order_type":0,"datetime":"1709257110","microtimestamp":"1709257110363000","amount":3.06821096,"amount_str":"3.06821096","amount_traded":"0","amount_at_create":"3.06821096","price":61309,"price_str":"61309"},"channel":"live_orders_btcusd","event":"order_created"}
{"data":{"id":1722049067855872,"id_str":"1722049067855872","order_type":0,"datetime":"1709257110","microtimestamp":"1709257110364000","amount":0.00815308,"amount_str":"0.00815308","amount_traded":"0","amount_at_create":"0.00815308","price":61319,"price_str":"61319"},"channel":"live_orders_btcusd","event":"order_created"}
{"data":{"id":1722049046654976,"id_str":"1722049046654976","order_type":0,"datetime":"1709257110","microtimestamp":"1709257110368000","amount":0.06519904,"amount_str":"0.06519904","amount_traded":"0","amount_at_create":"0.06519904","price":61306,"price_str":"61306"},"channel":"live_orders_btcusd","event":"order_deleted"}
{"data":{"id":1722049067978753,"id_str":"1722049067978753","order_type":0,"datetime":"1709257110","microtimestamp":"1709257110394000","amount":0.04875518,"amount_str":"0.04875518","amount_traded":"0","amount_at_create":"0.04875518","price":61291,"price_str":"61291"},"channel":"live_orders_btcusd","event":"order_created"}
{"data":{"id":1722049059610628,"id_str":"1722049059610628","order_type":1,"datetime":"1709257110","microtimestamp":"1709257110406000","amount":0.48859561,"amount_str":"0.48859561","amount_traded":"0","amount_at_create":"0.48859561","price":61401,"price_str":"61401"},"channel":"live_orders_btcusd","event":"order_deleted"}
{"data":{"id":1722049064980481,"id_str":"1722049064980481","order_type":1,"datetime":"1709257110","microtimestamp":"1709257110406000","amount":0.48894099,"amount_str":"0.48894099","amount_traded":"0","amount_at_create":"0.48894099","price":61358,"price_str":"61358"},"channel":"live_orders_btcusd","event":"order_deleted"}
{"data":{"id":1722049055903746,"id_str":"1722049055903746","order_type":0,"datetime":"1709257110","microtimestamp":"1709257110407000","amount":0.48951297,"amount_str":"0.48951297","amount_traded":"0","amount_at_create":"0.48951297","price":61285,"price_str":"61285"},"channel":"live_orders_btcusd","event":"order_deleted"}
{"data":{"id":1722049047728130,"id_str":"1722049047728130","order_type":1,"datetime":"1709257110","microtimestamp":"1709257110407000","amount":0.48904808,"amount_str":"0.48904808","amount_traded":"0","amount_at_create":"0.48904808","price":61344,"price_str":"61344"},"channel":"live_orders_btcusd","event":"order_deleted"}
{"data":{"id":1722049059237889,"id_str":"1722049059237889","order_type":1,"datetime":"1709257110","microtimestamp":"1709257110420000","amount":0.00487244,"amount_str":"0.00487244","amount_traded":"0","amount_at_create":"0.00487244","price":61338,"price_str":"61338"},"channel":"live_orders_btcusd","event":"order_deleted"}
{"data":{"id":1722049068113921,"id_str":"1722049068113921","order_type":0,"datetime":"1709257110","microtimestamp":"1709257110427000","amount":0.09,"amount_str":"0.09000000","amount_traded":"0","amount_at_create":"0.09000000","price":61307,"price_str":"61307"},"channel":"live_orders_btcusd","event":"order_created"}
{"data":{"id":1722049068167169,"id_str":"1722049068167169","order_type":1,"datetime":"1709257110","microtimestamp":"1709257110440000","amount":0.00487272,"amount_str":"0.00487272","amount_traded":"0","amount_at_create":"0.00487272","price":61334,"price_str":"61334"},"channel":"live_orders_btcusd","event":"order_created"}
{"data":{"id":1722049068212230,"id_str":"1722049068212230","order_type":0,"datetime":"1709257110","microtimestamp":"1709257110452000","amount":0.48932724,"amount_str":"0.48932724","amount_traded":"0","amount_at_create":"0.48932724","price":61308,"price_str":"61308"},"channel":"live_orders_btcusd","event":"order_created"}
{"data":{"id":1722049068224513,"id_str":"1722049068224513","order_type":0,"datetime":"1709257110","microtimestamp":"1709257110454000","amount":0.48929361,"amount_str":"0.48929361","amount_traded":"0","amount_at_create":"0.48929361","price":61312,"price_str":"61312"},"channel":"live_orders_btcusd","event":"order_created"}
{"data":{"id":1722049068113921,"id_str":"1722049068113921","order_type":0,"datetime":"1709257110","microtimestamp":"1709257110454000","amount":0.09,"amount_str":"0.09000000","amount_traded":"0","amount_at_create":"0.09000000","price":61307,"price_str":"61307"},"channel":"live_orders_btcusd","event":"order_deleted"}
{"data":{"id":1722049068228611,"id_str":"1722049068228611","order_type":0,"datetime":"1709257110","microtimestamp":"1709257110455000","amount":0.0163081,"amount_str":"0.01630810","amount_traded":"0","amount_at_create":"0.01630810","price":61319,"price_str":"61319"},"channel":"live_orders_btcusd","event":"order_created"}
{"data":{"id":1722049068232705,"id_str":"1722049068232705","order_type":1,"datetime":"1709257110","microtimestamp":"1709257110456000","amount":0.48908868,"amount_str":"0.48908868","amount_traded":"0","amount_at_create":"0.48908868","price":61339,"price_str":"61339"},"channel":"live_orders_btcusd","event":"order_created"}
{"data":{"id":1722049068236801,"id_str":"1722049068236801","order_type":0,"datetime":"1709257110","microtimestamp":"1709257110457000","amount":0.48944347,"amount_str":"0.48944347","amount_traded":"0","amount_at_create":"0.48944347","price":61294,"price_str":"61294"},"channel":"live_orders_btcusd","event":"order_created"}
{"data":{"id":1722049068236804,"id_str":"1722049068236804","order_type":0,"datetime":"1709257110","microtimestamp":"1709257110457000","amount":0.489571,"amount_str":"0.48957100","amount_traded":"0","amount_at_create":"0.48957100","price":61278,"price_str":"61278"},"channel":"live_orders_btcusd","event":"order_created"}
{"data":{"id":1722049068236805,"id_str":"1722049068236805","order_type":1,"datetime":"1709257110","microtimestamp":"1709257110458000","amount":0.01630658,"amount_str":"0.01630658","amount_traded":"0","amount_at_create":"0.01630658","price":61325,"price_str":"61325"},"channel":"live_orders_btcusd","event":"order_created"}
{"data":{"id":1722049068244995,"id_str":"1722049068244995","order_type":1,"datetime":"1709257110","microtimestamp":"1709257110459000","amount":0.48910119,"amount_str":"0.48910119","amount_traded":"0","amount_at_create":"0.48910119","price":61337,"price_str":"61337"},"channel":"live_orders_btcusd","event":"order_created"}
{"data":{"id":1722049068249090,"id_str":"1722049068249090","order_type":0,"datetime":"1709257110","microtimestamp":"1709257110460000","amount":0.00815308,"amount_str":"0.00815308","amount_traded":"0","amount_at_create":"0.00815308","price":61317,"price_str":"61317"},"channel":"live_orders_btcusd","event":"order_created"}
{"data":{"id":1722049068244995,"id_str":"1722049068244995","order_type":1,"datetime":"1709257110","microtimestamp":"1709257110476000","amount":0.48910119,"amount_str":"0.48910119","amount_traded":"0","amount_at_create":"0.48910119","price":61337,"price_str":"61337"},"channel":"live_orders_btcusd","event":"order_deleted"}
{"data":{"id":1722049068326917,"id_str":"1722049068326917","order_type":0,"datetime":"1709257110","microtimestamp":"1709257110480000","amount":0.00040756,"amount_str":"0.00040756","amount_traded":"0","amount_at_create":"0.00040756","price":61307,"price_str":"61307"},"channel":"live_orders_btcusd","event":"order_created"}
{"data":{"id":1722049068380160,"id_str":"1722049068380160","order_type":1,"datetime":"1709257110","microtimestamp":"1709257110492000","amount":0.02299694,"amount_str":"0.02299694","amount_traded":"0","amount_at_create":"0.02299694","price":61345,"price_str":"61345"},"channel":"live_orders_btcusd","event":"order_created"}
{"data":{"id":1722049068384256,"id_str":"1722049068384256","order_type":0,"datetime":"1709257110","microtimestamp":"1709257110493000","amount":0.40766874,"amount_str":"0.40766874","amount_traded":"0","amount_at_create":"0.40766874","price":61114,"price_str":"61114"},"channel":"live_orders_btcusd","event":"order_created"}
{"data":{"id":1722049067532288,"id_str":"1722049067532288","order_type":1,"datetime":"1709257111","microtimestamp":"1709257110503000","amount":0.1875,"amount_str":"0.18750000","amount_traded":"0","amount_at_create":"0.18750000","price":61339,"price_str":"61339"},"channel":"live_orders_btcusd","event":"order_deleted"}
{"data":{"id":1722049068384256,"id_str":"1722049068384256","order_type":0,"datetime":"1709257111","microtimestamp":"1709257110509000","amount":0.40766874,"amount_str":"0.40766874","amount_traded":"0","amount_at_create":"0.40766874","price":61114,"price_str":"61114"},"channel":"live_orders_btcusd","event":"order_deleted"}
{"data":{"id":1722049068507139,"id_str":"1722049068507139","order_type":0,"datetime":"1709257111","microtimestamp":"1709257110524000","amount":0.48926014,"amount_str":"0.48926014","amount_traded":"0","amount_at_create":"0.48926014","price":61317,"price_str":"61317"},"channel":"live_orders_btcusd","event":"order_created"}
{"data":{"id":1722049068515328,"id_str":"1722049068515328","order_type":1,"datetime":"1709257111","microtimestamp":"1709257110525000","amount":0.48911714,"amount_str":"0.48911714","amount_traded":"0","amount_at_create":"0.48911714","price":61335,"price_str":"61335"},"channel":"live_orders_btcusd","event":"order_created"}
{"data":{"id":1722049068515328,"id_str":"1722049068515328","order_type":1,"datetime":"1709257111","microtimestamp":"1709257110541000","amount":0.48911714,"amount_str":"0.48911714","amount_traded":"0","amount_at_create":"0.48911714","price":61335,"price_str":"61335"},"channel":"live_orders_btcusd","event":"order_deleted"}
{"data":{"id":1722049038471168,"id_str":"1722049038471168","order_type":0,"datetime":"1709257111","microtimestamp":"1709257110543000","amount":0.5,"amount_str":"0.50000000","amount_traded":"0","amount_at_create":"0.50000000","price":61256,"price_str":"61256"},"channel":"live_orders_btcusd","event":"order_deleted"}
{"data":{"id":1722049067855872,"id_str":"1722049067855872","order_type":0,"datetime":"1709257111","microtimestamp":"1709257110576000","amount":0.00815308,"amount_str":"0.00815308","amount_traded":"0","amount_at_create":"0.00815308","price":61319,"price_str":"61319"},"channel":"live_orders_btcusd","event":"order_deleted"}
{"data":{"id":1722049068326917,"id_str":"1722049068326917","order_type":0,"datetime":"1709257111","microtimestamp":"1709257110650000","amount":0.00040756,"amount_str":"0.00040756","amount_traded":"0","amount_at_create":"0.00040756","price":61307,"price_str":"61307"},"channel":"live_orders_btcusd","event":"order_deleted"}
{"data":{"id":1722049069809669,"id_str":"1722049069809669","order_type":0,"datetime":"1709257111","microtimestamp":"1709257110842000","amount":0.00040756,"amount_str":"0.00040756","amount_traded":"0","amount_at_create":"0.00040756","price":61310,"price_str":"61310"},"channel":"live_orders_btcusd","event":"order_created"}
{"data":{"id":1722049070260224,"id_str":"1722049070260224","order_type":0,"datetime":"1709257111","microtimestamp":"1709257110951000","amount":0.40766874,"amount_str":"0.40766874","amount_traded":"0","amount_at_create":"0.40766874","price":61112,"price_str":"61112"},"channel":"live_orders_btcusd","event":"order_created"}
{"data":{"id":1722049070260224,"id_str":"1722049070260224","order_type":0,"datetime":"1709257111","microtimestamp":"1709257110965000","amount":0.40766874,"amount_str":"0.40766874","amount_traded":"0","amount_at_create":"0.40766874","price":61112,"price_str":"61112"},"channel":"live_orders_btcusd","event":"order_deleted"}
{"data":{"id":1722049069809669,"id_str":"1722049069809669","order_type":0,"datetime":"1709257111","microtimestamp":"1709257111078000","amount":0.00040756,"amount_str":"0.00040756","amount_traded":"0","amount_at_create":"0.00040756","price":61310,"price_str":"61310"},"channel":"live_orders_btcusd","event":"order_deleted"}
{"data":{"id":1722049071222785,"id_str":"1722049071222785","order_type":0,"datetime":"1709257111","microtimestamp":"1709257111186000","amount":0.00040756,"amount_str":"0.00040756","amount_traded":"0","amount_at_create":"0.00040756","price":61311,"price_str":"61311"},"channel":"live_orders_btcusd","event":"order_created"}
{"data":{"id":1722049071476736,"id_str":"1722049071476736","order_type":0,"datetime":"1709257111","microtimestamp":"1709257111248000","amount":0.01630658,"amount_str":"0.01630658","amount_traded":"0","amount_at_create":"0.01630658","price":61306,"price_str":"61306"},"channel":"live_orders_btcusd","event":"order_created"}
{"data":{"id":1722049071222785,"id_str":"1722049071222785","order_type":0,"datetime":"1709257111","microtimestamp":"1709257111281000","amount":0.00040756,"amount_str":"0.00040756","amount_traded":"0","amount_at_create":"0.00040756","price":61311,"price_str":"61311"},"channel":"live_orders_btcusd","event":"order_deleted"}
{"data":{"id":1722049071689728,"id_str":"1722049071689728","order_type":1,"datetime":"1709257111","microtimestamp":"1709257111301000","amount":0.48918145,"amount_str":"0.48918145","amount_traded":"0","amount_at_create":"0.48918145","price":61327,"price_str":"61327"},"channel":"live_orders_btcusd","event":"order_created"}
{"data":{"id":1722049071693825,"id_str":"1722049071693825","order_type":1,"datetime":"1709257111","microtimestamp":"1709257111302000","amount":0.48914753,"amount_str":"0.48914753","amount_traded":"0","amount_at_create":"0.48914753","price":61332,"price_str":"61332"},"channel":"live_orders_btcusd","event":"order_created"}
{"data":{"id":1722049071763456,"id_str":"1722049071763456","order_type":0,"datetime":"1709257111","microtimestamp":"1709257111318000","amount":0.00040756,"amount_str":"0.00040756","amount_traded":"0","amount_at_create":"0.00040756","price":61312,"price_str":"61312"},"channel":"live_orders_btcusd","event":"order_created"}
{"data":{"id":1722049071763456,"id_str":"1722049071763456","order_type":0,"datetime":"1709257111","microtimestamp":"1709257111345000","amount":0.00040756,"amount_str":"0.00040756","amount_traded":"0","amount_at_create":"0.00040756","price":61312,"price_str":"61312"},"channel":"live_orders_btcusd","event":"order_deleted"}
{"data":{"id":1722049072058368,"id_str":"1722049072058368","order_type":0,"datetime":"1709257111","microtimestamp":"1709257111390000","amount":0.00040756,"amount_str":"0.00040756","amount_traded":"0","amount_at_create":"0.00040756","price":61310,"price_str":"61310"},"channel":"live_orders_btcusd","event":"order_created"}
{"data":{"id":1722049072300033,"id_str":"1722049072300033","order_type":0,"datetime":"1709257111","microtimestamp":"1709257111449000","amount":0.40769201,"amount_str":"0.40769201","amount_traded":"0","amount_at_create":"0.40769201","price":61112,"price_str":"61112"},"channel":"live_orders_btcusd","event":"order_created"}
{"data":{"id":1722049072058368,"id_str":"1722049072058368","order_type":0,"datetime":"1709257111","microtimestamp":"1709257111459000","amount":0.00040756,"amount_str":"0.00040756","amount_traded":"0","amount_at_create":"0.00040756","price":61310,"price_str":"61310"},"channel":"live_orders_btcusd","event":"order_deleted"}
{"data":{"id":1722049072300033,"id_str":"1722049072300033","order_type":0,"datetime":"1709257111","microtimestamp":"1709257111463000","amount":0.40769201,"amount_str":"0.40769201","amount_traded":"0","amount_at_create":"0.40769201","price":61112,"price_str":"61112"},"channel":"live_orders_btcusd","event":"order_deleted"}
{"data":{"id":1722049072787456,"id_str":"1722049072787456","order_type":0,"datetime":"1709257112","microtimestamp":"1709257111568000","amount":0.00040756,"amount_str":"0.00040756","amount_traded":"0","amount_at_create":"0.00040756","price":61311,"price_str":"61311"},"channel":"live_orders_btcusd","event":"order_created"}
{"data":{"id":1722049072787456,"id_str":"1722049072787456","order_type":0,"datetime":"1709257112","microtimestamp":"1709257111615000","amount":0.00040756,"amount_str":"0.00040756","amount_traded":"0","amount_at_create":"0.00040756","price":61311,"price_str":"61311"},"channel":"live_orders_btcusd","event":"order_deleted"}
{"data":{"id":1722049073102849,"id_str":"1722049073102849","order_type":0,"datetime":"1709257112","microtimestamp":"1709257111646000","amount":0.00040756,"amount_str":"0.00040756","amount_traded":"0","amount_at_create":"0.00040756","price":61310,"price_str":"61310"},"channel":"live_orders_btcusd","event":"order_created"}
{"data":{"id":1722049073102849,"id_str":"1722049073102849","order_type":0,"datetime":"1709257112","microtimestamp":"1709257111689000","amount":0.00040756,"amount_str":"0.00040756","amount_traded":"0","amount_at_create":"0.00040756","price":61310,"price_str":"61310"},"channel":"live_orders_btcusd","event":"order_deleted"}
{"data":{"id":1722049071693825,"id_str":"1722049071693825","order_type":1,"datetime":"1709257112","microtimestamp":"1709257111698000","amount":0.48914753,"amount_str":"0.48914753","amount_traded":"0","amount_at_create":"0.48914753","price":61332,"price_str":"61332"},"channel":"live_orders_btcusd","event":"order_deleted"}
{"data":{"id":1722049071689728,"id_str":"1722049071689728","order_type":1,"datetime":"1709257112","microtimestamp":"1709257111698000","amount":0.48918145,"amount_str":"0.48918145","amount_traded":"0","amount_at_create":"0.48918145","price":61327,"price_str":"61327"},"channel":"live_orders_btcusd","event":"order_deleted"}
{"data":{"id":1722049068236805,"id_str":"1722049068236805","order_type":1,"datetime":"1709257112","microtimestamp":"1709257111699000","amount":0.01630658,"amount_str":"0.01630658","amount_traded":"0","amount_at_create":"0.01630658","price":61325,"price_str":"61325"},"channel":"live_orders_btcusd","event":"order_deleted"}
{"data":{"id":1722049073504256,"id_str":"1722049073504256","order_type":1,"datetime":"1709257112","microtimestamp":"1709257111743000","amount":0.48891956,"amount_str":"0.48891956","amount_traded":"0","amount_at_create":"0.48891956","price":61360,"price_str":"61360"},"channel":"live_orders_btcusd","event":"order_created"}
{"data":{"id":1722049073508352,"id_str":"1722049073508352","order_type":1,"datetime":"1709257112","microtimestamp":"1709257111744000","amount":0.48912154,"amount_str":"0.48912154","amount_traded":"0","amount_at_create":"0.48912154","price":61335,"price_str":"61335"},"channel":"live_orders_btcusd","event":"order_created"}
{"data":{"id":1722049073512448,"id_str":"1722049073512448","order_type":1,"datetime":"1709257112","microtimestamp":"1709257111745000","amount":0.01630461,"amount_str":"0.01630461","amount_traded":"0","amount_at_create":"0.01630461","price":61333,"price_str":"61333"},"channel":"live_orders_btcusd","event":"order_created"}
{"data":{"id":1722049073512449,"id_str":"1722049073512449","order_type":1,"datetime":"1709257112","microtimestamp":"1709257111745000","amount":0.48903158,"amount_str":"0.48903158","amount_traded":"0","amount_at_create":"0.48903158","price":61346,"price_str":"61346"},"channel":"live_orders_btcusd","event":"order_created"}
{"data":{"id":1722049073512450,"id_str":"1722049073512450","order_type":1,"datetime":"1709257112","microtimestamp":"1709257111746000","amount":0.1875,"amount_str":"0.18750000","amount_traded":"0","amount_at_create":"0.18750000","price":61341,"price_str":"61341"},"channel":"live_orders_btcusd","event":"order_created"}
{"data":{"id":1722049073786882,"id_str":"1722049073786882","order_type":0,"datetime":"1709257112","microtimestamp":"1709257111813000","amount":0.00040756,"amount_str":"0.00040756","amount_traded":"0","amount_at_create":"0.00040756","price":61311,"price_str":"61311"},"channel":"live_orders_btcusd","event":"order_created"}
{"data":{"id":1722049073786882,"id_str":"1722049073786882","order_type":0,"datetime":"1709257112","microtimestamp":"1709257111830000","amount":0.00040756,"amount_str":"0.00040756","amount_traded":"0","amount_at_create":"0.00040756","price":61311,"price_str":"61311"},"channel":"live_orders_btcusd","event":"order_deleted"}
{"data":{"id":1722049073872899,"id_str":"1722049073872899","order_type":0,"datetime":"1709257112","microtimestamp":"1709257111834000","amount":0.00815314,"amount_str":"0.00815314","amount_traded":"0","amount_at_create":"0.00815314","price":61319,"price_str":"61319"},"channel":"live_orders_btcusd","event":"order_created"}
{"data":{"id":1722049074073600,"id_str":"1722049074073600","order_type":0,"datetime":"1709257112","microtimestamp":"1709257111882000","amount":0.00040756,"amount_str":"0.00040756","amount_traded":"0","amount_at_create":"0.00040756","price":61310,"price_str":"61310"},"channel":"live_orders_btcusd","event":"order_created"}
{"data":{"id":1722049074073600,"id_str":"1722049074073600","order_type":0,"datetime":"1709257112","microtimestamp":"1709257111910000","amount":0.00040756,"amount_str":"0.00040756","amount_traded":"0","amount_at_create":"0.00040756","price":61310,"price_str":"61310"},"channel":"live_orders_btcusd","event":"order_deleted"}
{"data":{"id":1722049074360320,"id_str":"1722049074360320","order_type":1,"datetime":"1709257112","microtimestamp":"1709257111952000","amount":0.40769201,"amount_str":"0.40769201","amount_traded":"0","amount_at_create":"0.40769201","price":61338,"price_str":"61338"},"channel":"live_orders_btcusd","event":"order_created"}
{"data":{"id":1722049074368512,"id_str":"1722049074368512","order_type":0,"datetime":"1709257112","microtimestamp":"1709257111954000","amount":0.00040756,"amount_str":"0.00040756","amount_traded":"0","amount_at_create":"0.00040756","price":61311,"price_str":"61311"},"channel":"live_orders_btcusd","event":"order_created"}
{"data":{"id":1722049074368512,"id_str":"1722049074368512","order_type":0,"datetime":"1709257112","microtimestamp":"1709257112057000","amount":0.00040756,"amount_str":"0.00040756","amount_traded":"0","amount_at_create":"0.00040756","price":61311,"price_str":"61311"},"channel":"live_orders_btcusd","event":"order_deleted"}
{"data":{"id":1722049075298307,"id_str":"1722049075298307","order_type":0,"datetime":"1709257112","microtimestamp":"1709257112181000","amount":0.00040756,"amount_str":"0.00040756","amount_traded":"0","amount_at_create":"0.00040756","price":61312,"price_str":"61312"},"channel":"live_orders_btcusd","event":"order_created"}
{"data":{"id":1722049063841792,"id_str":"1722049063841792","order_type":0,"datetime":"1709257112","microtimestamp":"1709257112196000","amount":0.16332709,"amount_str":"0.16332709","amount_traded":"0","amount_at_create":"0.16332709","price":61226,"price_str":"61226"},"channel":"live_orders_btcusd","event":"order_deleted"}
{"data":{"id":1722049068224513,"id_str":"1722049068224513","order_type":0,"datetime":"1709257112","microtimestamp":"1709257112208000","amount":0.48929361,"amount_str":"0.48929361","amount_traded":"0","amount_at_create":"0.48929361","price":61312,"price_str":"61312"},"channel":"live_orders_btcusd","event":"order_deleted"}
{"data":{"id":1722049068228611,"id_str":"1722049068228611","order_type":0,"datetime":"1709257112","microtimestamp":"1709257112209000","amount":0.0163081,"amount_str":"0.01630810","amount_traded":"0","amount_at_create":"0.01630810","price":61319,"price_str":"61319"},"channel":"live_orders_btcusd","event":"order_deleted"}
{"data":{"id":1722049073512448,"id_str":"1722049073512448","order_type":1,"datetime":"1709257112","microtimestamp":"1709257112213000","amount":0.01630461,"amount_str":"0.01630461","amount_traded":"0","amount_at_create":"0.01630461","price":61333,"price_str":"61333"},"channel":"live_orders_btcusd","event":"order_deleted"}
{"data":{"id":1722049075298307,"id_str":"1722049075298307","order_type":0,"datetime":"1709257112","microtimestamp":"1709257112239000","amount":0.00040756,"amount_str":"0.00040756","amount_traded":"0","amount_at_create":"0.00040756","price":61312,"price_str":"61312"},"channel":"live_orders_btcusd","event":"order_deleted"}
{"data":{"id":1722049073872899,"id_str":"1722049073872899","order_type":0,"datetime":"1709257112","microtimestamp":"1709257112244000","amount":0.00815314,"amount_str":"0.00815314","amount_traded":"0","amount_at_create":"0.00815314","price":61319,"price_str":"61319"},"channel":"live_orders_btcusd","event":"order_deleted"}
{"data":{"id":1722049075613698,"id_str":"1722049075613698","order_type":1,"datetime":"1709257112","microtimestamp":"1709257112259000","amount":0.01630474,"amount_str":"0.01630474","amount_traded":"0","amount_at_create":"0.01630474","price":61332,"price_str":"61332"},"channel":"live_orders_btcusd","event":"order_created"}
{"data":{"id":1722049075625986,"id_str":"1722049075625986","order_type":0,"datetime":"1709257112","microtimestamp":"1709257112261000","amount":0.48928549,"amount_str":"0.48928549","amount_traded":"0","amount_at_create":"0.48928549","price":61313,"price_str":"61313"},"channel":"live_orders_btcusd","event":"order_created"}
{"data":{"id":1722049075634179,"id_str":"1722049075634179","order_type":0,"datetime":"1709257112","microtimestamp":"1709257112263000","amount":0.01630788,"amount_str":"0.01630788","amount_traded":"0","amount_at_create":"0.01630788","price":61320,"price_str":"61320"},"channel":"live_orders_btcusd","event":"order_created"}
{"data":{"id":1722049068380160,"id_str":"1722049068380160","order_type":1,"datetime":"1709257112","microtimestamp":"1709257112313000","amount":0.02299694,"amount_str":"0.02299694","amount_traded":"0","amount_at_create":"0.02299694","price":61345,"price_str":"61345"},"channel":"live_orders_btcusd","event":"order_deleted"}
{"data":{"id":1722049075847170,"id_str":"1722049075847170","order_type":0,"datetime":"1709257112","microtimestamp":"1709257112316000","amount":0.00040756,"amount_str":"0.00040756","amount_traded":"0","amount_at_create":"0.00040756","price":61310,"price_str":"61310"},"channel":"live_orders_btcusd","event":"order_created"}
{"data":{"id":1722049073508352,"id_str":"1722049073508352","order_type":1,"datetime":"1709257112","microtimestamp":"1709257112317000","amount":0.48912154,"amount_str":"0.48912154","amount_traded":"0","amount_at_create":"0.48912154","price":61335,"price_str":"61335"},"channel":"live_orders_btcusd","event":"order_deleted"}
{"data":{"id":1722049076027392,"id_str":"1722049076027392","order_type":1,"datetime":"1709257112","microtimestamp":"1709257112360000","amount":0.48912699,"amount_str":"0.48912699","amount_traded":"0","amount_at_create":"0.48912699","price":61334,"price_str":"61334"},"channel":"live_orders_btcusd","event":"order_created"}
{"data":{"id":1722048956407808,"id_str":"1722048956407808","order_type":0,"datetime":"1709257112","microtimestamp":"1709257112401000","amount":1,"amount_str":"1.00000000","amount_traded":"0","amount_at_create":"1.00000000","price":61256,"price_str":"61256"},"channel":"live_orders_btcusd","event":"order_deleted"}
{"data":{"id":1722048833040398,"id_str":"1722048833040398","order_type":0,"datetime":"1709257112","microtimestamp":"1709257112402000","amount":0.5,"amount_str":"0.50000000","amount_traded":"0","amount_at_create":"0.50000000","price":61287,"price_str":"61287"},"channel":"live_orders_btcusd","event":"order_deleted"}
{"data":{"id":1722048980045825,"id_str":"1722048980045825","order_type":0,"datetime":"1709257112","microtimestamp":"1709257112402000","amount":0.5,"amount_str":"0.50000000","amount_traded":"0","amount_at_create":"0.50000000","price":61303,"price_str":"61303"},"channel":"live_orders_btcusd","event":"order_deleted"}
{"data":{"id":1722049076314113,"id_str":"1722049076314113","order_type":0,"datetime":"1709257112","microtimestamp":"1709257112429000","amount":0.5,"amount_str":"0.50000000","amount_traded":"0","amount_at_create":"0.50000000","price":61256,"price_str":"61256"},"channel":"live_orders_btcusd","event":"order_created"}
{"data":{"id":1722049076318208,"id_str":"1722049076318208","order_type":0,"datetime":"1709257112","microtimestamp":"1709257112430000","amount":1,"amount_str":"1.00000000","amount_traded":"0","amount_at_create":"1.00000000","price":61225,"price_str":"61225"},"channel":"live_orders_btcusd","event":"order_created"}
{"data":{"id":1722049076322304,"id_str":"1722049076322304","order_type":0,"datetime":"1709257112","microtimestamp":"1709257112431000","amount":0.5,"amount_str":"0.50000000","amount_traded":"0","amount_at_create":"0.50000000","price":61194,"price_str":"61194"},"channel":"live_orders_btcusd","event":"order_created"}
{"data":{"id":1722049074360320,"id_str":"1722049074360320","order_type":1,"datetime":"1709257112","microtimestamp":"1709257112448000","amount":0.40769201,"amount_str":"0.40769201","amount_traded":"0","amount_at_create":"0.40769201","price":61338,"price_str":"61338"},"channel":"live_orders_btcusd","event":"order_deleted"}
{"data":{"id":1722049076559873,"id_str":"1722049076559873","order_type":1,"datetime":"1709257112","microtimestamp":"1709257112489000","amount":0.02237146,"amount_str":"0.02237146","amount_traded":"0","amount_at_create":"0.02237146","price":61344,"price_str":"61344"},"channel":"live_orders_btcusd","event":"order_created"}
{"data":{"id":1722049076576256,"id_str":"1722049076576256","order_type":0,"datetime":"1709257112","microtimestamp":"1709257112493000","amount":0.40769201,"amount_str":"0.40769201","amount_traded":"0","amount_at_create":"0.40769201","price":61112,"price_str":"61112"},"channel":"live_orders_btcusd","event":"order_created"}
{"data":{"id":1722049076629504,"id_str":"1722049076629504","order_type":0,"datetime":"1709257113","microtimestamp":"1709257112506000","amount":0.00815314,"amount_str":"0.00815314","amount_traded":"0","amount_at_create":"0.00815314","price":61319,"price_str":"61319"},"channel":"live_orders_btcusd","event":"order_created"}
{"data":{"id":1722049076576256,"id_str":"1722049076576256","order_type":0,"datetime":"1709257113","microtimestamp":"1709257112507000","amount":0.40769201,"amount_str":"0.40769201","amount_traded":"0","amount_at_create":"0.40769201","price":61112,"price_str":"61112"},"channel":"live_orders_btcusd","event":"order_deleted"}
{"data":{"id":1722049076744194,"id_str":"1722049076744194","order_type":0,"datetime":"1709257113","microtimestamp":"1709257112534000","amount":0.5,"amount_str":"0.50000000","amount_traded":"0","amount_at_create":"0.50000000","price":61095,"price_str":"61095"},"channel":"live_orders_btcusd","event":"order_created"}
{"data":{"id":1722049075847170,"id_str":"1722049075847170","order_type":0,"datetime":"1709257113","microtimestamp":"1709257112558000","amount":0.00040756,"amount_str":"0.00040756","amount_traded":"0","amount_at_create":"0.00040756","price":61310,"price_str":"61310"},"channel":"live_orders_btcusd","event":"order_deleted"}
{"data":{"id":1722049077276673,"id_str":"1722049077276673","order_type":0,"datetime":"1709257113","microtimestamp":"1709257112665000","amount":0.00040756,"amount_str":"0.00040756","amount_traded":"0","amount_at_create":"0.00040756","price":61311,"price_str":"61311"},"channel":"live_orders_btcusd","event":"order_created"}
{"data":{"id":1722049077276673,"id_str":"1722049077276673","order_type":0,"datetime":"1709257113","microtimestamp":"1709257112761000","amount":0.00040756,"amount_str":"0.00040756","amount_traded":"0","amount_at_create":"0.00040756","price":61311,"price_str":"61311"},"channel":"live_orders_btcusd","event":"order_deleted"}
{"data":{"id":1722049078280192,"id_str":"1722049078280192","order_type":0,"datetime":"1709257113","microtimestamp":"1709257112909000","amount":0.00040756,"amount_str":"0.00040756","amount_traded":"0","amount_at_create":"0.00040756","price":61312,"price_str":"61312"},"channel":"live_orders_btcusd","event":"order_created"}
{"data":{"id":1722049078280192,"id_str":"1722049078280192","order_type":0,"datetime":"1709257113","microtimestamp":"1709257112953000","amount":0.00040756,"amount_str":"0.00040756","amount_traded":"0","amount_at_create":"0.00040756","price":61312,"price_str":"61312"},"channel":"live_orders_btcusd","event":"order_deleted"}
{"data":{"id":1722049078996993,"id_str":"1722049078996993","order_type":0,"datetime":"1709257113","microtimestamp":"1709257113085000","amount":0.00040756,"amount_str":"0.00040756","amount_traded":"0","amount_at_create":"0.00040756","price":61310,"price_str":"61310"},"channel":"live_orders_btcusd","event":"order_created"}
{"data":{"id":1722049078996993,"id_str":"1722049078996993","order_type":0,"datetime":"1709257113","microtimestamp":"1709257113121000","amount":0.00040756,"amount_str":"0.00040756","amount_traded":"0","amount_at_create":"0.00040756","price":61310,"price_str":"61310"},"channel":"live_orders_btcusd","event":"order_deleted"}
{"data":{"id":1722049067851776,"id_str":"1722049067851776","order_type":0,"datetime":"1709257113","microtimestamp":"1709257113127000","amount":3.06821096,"amount_str":"3.06821096","amount_traded":"0","amount_at_create":"3.06821096","price":61309,"price_str":"61309"},"channel":"live_orders_btcusd","event":"order_deleted"}
{"data":{"id":1722049068212230,"id_str":"1722049068212230","order_type":0,"datetime":"1709257113","microtimestamp":"1709257113148000","amount":0.48932724,"amount_str":"0.48932724","amount_traded":"0","amount_at_create":"0.48932724","price":61308,"price_str":"61308"},"channel":"live_orders_btcusd","event":"order_deleted"}
{"data":{"id":1722049076027392,"id_str":"1722049076027392","order_type":1,"datetime":"1709257113","microtimestamp":"1709257113148000","amount":0.48912699,"amount_str":"0.48912699","amount_traded":"0","amount_at_create":"0.48912699","price":61334,"price_str":"61334"},"channel":"live_orders_btcusd","event":"order_deleted"}
{"data":{"id":1722049075634179,"id_str":"1722049075634179","order_type":0,"datetime":"1709257113","microtimestamp":"1709257113148000","amount":0.01630788,"amount_str":"0.01630788","amount_traded":"0","amount_at_create":"0.01630788","price":61320,"price_str":"61320"},"channel":"live_orders_btcusd","event":"order_deleted"}
{"data":{"id":1722049068236801,"id_str":"1722049068236801","order_type":0,"datetime":"1709257113","microtimestamp":"1709257113149000","amount":0.48944347,"amount_str":"0.48944347","amount_traded":"0","amount_at_create":"0.48944347","price":61294,"price_str":"61294"},"channel":"live_orders_btcusd","event":"order_deleted"}
{"data":{"id":1722049075613698,"id_str":"1722049075613698","order_type":1,"datetime":"1709257113","microtimestamp":"1709257113149000","amount":0.01630474,"amount_str":"0.01630474","amount_traded":"0","amount_at_create":"0.01630474","price":61332,"price_str":"61332"},"channel":"live_orders_btcusd","event":"order_deleted"}
{"data":{"id":1722049068507139,"id_str":"1722049068507139","order_type":0,"datetime":"1709257113","microtimestamp":"1709257113150000","amount":0.48926014,"amount_str":"0.48926014","amount_traded":"0","amount_at_create":"0.48926014","price":61317,"price_str":"61317"},"channel":"live_orders_btcusd","event":"order_deleted"}
{"data":{"id":1722049068232705,"id_str":"1722049068232705","order_type":1,"datetime":"1709257113","microtimestamp":"1709257113150000","amount":0.48908868,"amount_str":"0.48908868","amount_traded":"0","amount_at_create":"0.48908868","price":61339,"price_str":"61339"},"channel":"live_orders_btcusd","event":"order_deleted"}
{"data":{"id":1722049075625986,"id_str":"1722049075625986","order_type":0,"datetime":"1709257113","microtimestamp":"1709257113153000","amount":0.48928549,"amount_str":"0.48928549","amount_traded":"0","amount_at_create":"0.48928549","price":61313,"price_str":"61313"},"channel":"live_orders_btcusd","event":"order_deleted"}
{"data":{"id":1722049079304194,"id_str":"1722049079304194","order_type":1,"datetime":"1709257113","microtimestamp":"1709257113159000","amount":0.40769201,"amount_str":"0.40769201","amount_traded":"0","amount_at_create":"0.40769201","price":61338,"price_str":"61338"},"channel":"live_orders_btcusd","event":"order_created"}
{"data":{"id":1722049067769856,"id_str":"1722049067769856","order_type":1,"datetime":"1709257113","microtimestamp":"1709257113169000","amount":0.93156573,"amount_str":"0.93156573","amount_traded":"0","amount_at_create":"0.93156573","price":61369,"price_str":"61369"},"channel":"live_orders_btcusd","event":"order_deleted"}
{"data":{"id":1722049076559873,"id_str":"1722049076559873","order_type":1,"datetime":"1709257113","microtimestamp":"1709257113176000","amount":0.02237146,"amount_str":"0.02237146","amount_traded":"0","amount_at_create":"0.02237146","price":61344,"price_str":"61344"},"channel":"live_orders_btcusd","event":"order_deleted"}
{"data":{"id":1722049079369737,"id_str":"1722049079369737","order_type":0,"datetime":"1709257113","microtimestamp":"1709257113176000","amount":3.06836111,"amount_str":"3.06836111","amount_traded":"0","amount_at_create":"3.06836111","price":61306,"price_str":"61306"},"channel":"live_orders_btcusd","event":"order_created"}
{"data":{"id":1722049079369737,"id_str":"1722049079369737","order_type":0,"datetime":"1709257113","microtimestamp":"1709257113179000","amount":3.06836111,"amount_str":"3.06836111","amount_traded":"0","amount_at_create":"3.06836111","price":61306,"price_str":"61306"},"channel":"live_orders_btcusd","event":"order_deleted"}
{"data":{"id":1722048983543808,"id_str":"1722048983543808","order_type":1,"datetime":"1709257113","microtimestamp":"1709257113183000","amount":0.04875518,"amount_str":"0.04875518","amount_traded":"0","amount_at_create":"0.04875518","price":61361,"price_str":"61361"},"channel":"live_orders_btcusd","event":"order_deleted"}
{"data":{"id":1722049073512449,"id_str":"1722049073512449","order_type":1,"datetime":"1709257113","microtimestamp":"1709257113198000","amount":0.48903158,"amount_str":"0.48903158","amount_traded":"0","amount_at_create":"0.48903158","price":61346,"price_str":"61346"},"channel":"live_orders_btcusd","event":"order_deleted"}
{"data":{"id":1722049079476227,"id_str":"1722049079476227","order_type":1,"datetime":"1709257113","microtimestamp":"1709257113201000","amount":0.48914206,"amount_str":"0.48914206","amount_traded":"0","amount_at_create":"0.48914206","price":61332,"price_str":"61332"},"channel":"live_orders_btcusd","event":"order_created"}
{"data":{"id":1722049079480323,"id_str":"1722049079480323","order_type":1,"datetime":"1709257113","microtimestamp":"1709257113202000","amount":0.01630529,"amount_str":"0.01630529","amount_traded":"0","amount_at_create":"0.01630529","price":61330,"price_str":"61330"},"channel":"live_orders_btcusd","event":"order_created"}
{"data":{"id":1722049079492610,"id_str":"1722049079492610","order_type":1,"datetime":"1709257113","microtimestamp":"1709257113206000","amount":0.48910715,"amount_str":"0.48910715","amount_traded":"0","amount_at_create":"0.48910715","price":61337,"price_str":"61337"},"channel":"live_orders_btcusd","event":"order_created"}
{"data":{"id":1722049079492611,"id_str":"1722049079492611","order_type":0,"datetime":"1709257113","microtimestamp":"1709257113206000","amount":0.01630852,"amount_str":"0.01630852","amount_traded":"0","amount_at_create":"0.01630852","price":61317,"price_str":"61317"},"channel":"live_orders_btcusd","event":"order_created"}
{"data":{"id":1722049079492613,"id_str":"1722049079492613","order_type":1,"datetime":"1709257113","microtimestamp":"1709257113206000","amount":0.1875,"amount_str":"0.18750000","amount_traded":"0","amount_at_create":"0.18750000","price":61332,"price_str":"61332"},"channel":"live_orders_btcusd","event":"order_created"}
{"data":{"id":1722049079496704,"id_str":"1722049079496704","order_type":0,"datetime":"1709257113","microtimestamp":"1709257113206000","amount":0.48930785,"amount_str":"0.48930785","amount_traded":"0","amount_at_create":"0.48930785","price":61311,"price_str":"61311"},"channel":"live_orders_btcusd","event":"order_created"}
{"data":{"id":1722049079500801,"id_str":"1722049079500801","order_type":0,"datetime":"1709257113","microtimestamp":"1709257113207000","amount":0.48947796,"amount_str":"0.48947796","amount_traded":"0","amount_at_create":"0.48947796","price":61289,"price_str":"61289"},"channel":"live_orders_btcusd","event":"order_created"}
{"data":{"id":1722049079500803,"id_str":"1722049079500803","order_type":0,"datetime":"1709257113","microtimestamp":"1709257113207000","amount":0.48927304,"amount_str":"0.48927304","amount_traded":"0","amount_at_create":"0.48927304","price":61315,"price_str":"61315"},"channel":"live_orders_btcusd","event":"order_created"}
{"data":{"id":1722049076629504,"id_str":"1722049076629504","order_type":0,"datetime":"1709257113","microtimestamp":"1709257113209000","amount":0.00815314,"amount_str":"0.00815314","amount_traded":"0","amount_at_create":"0.00815314","price":61319,"price_str":"61319"},"channel":"live_orders_btcusd","event":"order_deleted"}
{"data":{"id":1722049079508992,"id_str":"1722049079508992","order_type":0,"datetime":"1709257113","microtimestamp":"1709257113209000","amount":0.48936455,"amount_str":"0.48936455","amount_traded":"0","amount_at_create":"0.48936455","price":61303,"price_str":"61303"},"channel":"live_orders_btcusd","event":"order_created"}
{"data":{"id":1722049079545856,"id_str":"1722049079545856","order_type":0,"datetime":"1709257113","microtimestamp":"1709257113218000","amount":0.00914557,"amount_str":"0.00914557","amount_traded":"0","amount_at_create":"0.00914557","price":61318,"price_str":"61318"},"channel":"live_orders_btcusd","event":"order_created"}
{"data":{"id":1722049079570436,"id_str":"1722049079570436","order_type":0,"datetime":"1709257113","microtimestamp":"1709257113224000","amount":3.06846121,"amount_str":"3.06846121","amount_traded":"0","amount_at_create":"3.06846121","price":61304,"price_str":"61304"},"channel":"live_orders_btcusd","event":"order_created"}
{"data":{"id":1722049079480323,"id_str":"1722049079480323","order_type":1,"datetime":"1709257113","microtimestamp":"1709257113225000","amount":0.01630529,"amount_str":"0.01630529","amount_traded":"0","amount_at_create":"0.01630529","price":61330,"price_str":"61330"},"channel":"live_orders_btcusd","event":"order_deleted"}
{"data":{"id":1722049079492610,"id_str":"1722049079492610","order_type":1,"datetime":"1709257113","microtimestamp":"1709257113227000","amount":0.48910715,"amount_str":"0.48910715","amount_traded":"0","amount_at_create":"0.48910715","price":61337,"price_str":"61337"},"channel":"live_orders_btcusd","event":"order_deleted"}
{"data":{"id":1722049071476736,"id_str":"1722049071476736","order_type":0,"datetime":"1709257113","microtimestamp":"1709257113231000","amount":0.01630658,"amount_str":"0.01630658","amount_traded":"0","amount_at_create":"0.01630658","price":61306,"price_str":"61306"},"channel":"live_orders_btcusd","event":"order_deleted"}
{"data":{"id":1722049079664642,"id_str":"1722049079664642","order_type":1,"datetime":"1709257113","microtimestamp":"1709257113247000","amount":0.9316458,"amount_str":"0.93164580","amount_traded":"0","amount_at_create":"0.93164580","price":61364,"price_str":"61364"},"channel":"live_orders_btcusd","event":"order_created"}
{"data":{"id":1722048993533952,"id_str":"1722048993533952","order_type":0,"datetime":"1709257113","microtimestamp":"1709257113249000","amount":0.12188796,"amount_str":"0.12188796","amount_traded":"0","amount_at_create":"0.12188796","price":61269,"price_str":"61269"},"channel":"live_orders_btcusd","event":"order_deleted"}
{"data":{"id":1722049079492613,"id_str":"1722049079492613","order_type":1,"datetime":"1709257113","microtimestamp":"1709257113250000","amount":0.1875,"amount_str":"0.18750000","amount_traded":"0","amount_at_create":"0.18750000","price":61332,"price_str":"61332"},"channel":"live_orders_btcusd","event":"order_deleted"}
{"data":{"id":1722049067671554,"id_str":"1722049067671554","order_type":1,"datetime":"1709257113","microtimestamp":"1709257113253000","amount":0.03718287,"amount_str":"0.03718287","amount_traded":"0","amount_at_create":"0.03718287","price":61343,"price_str":"61343"},"channel":"live_orders_btcusd","event":"order_deleted"}
{"data":{"id":1722049079476227,"id_str":"1722049079476227","order_type":1,"datetime":"1709257113","microtimestamp":"1709257113259000","amount":0.48914206,"amount_str":"0.48914206","amount_traded":"0","amount_at_create":"0.48914206","price":61332,"price_str":"61332"},"channel":"live_orders_btcusd","event":"order_deleted"}
{"data":{"id":1722049079746564,"id_str":"1722049079746564","order_type":1,"datetime":"1709257113","microtimestamp":"1709257113267000","amount":0.03718287,"amount_str":"0.03718287","amount_traded":"0","amount_at_create":"0.03718287","price":61340,"price_str":"61340"},"channel":"live_orders_btcusd","event":"order_created"}
{"data":{"id":1722049079758848,"id_str":"1722049079758848","order_type":0,"datetime":"1709257113","microtimestamp":"1709257113270000","amount":0.00040756,"amount_str":"0.00040756","amount_traded":"0","amount_at_create":"0.00040756","price":61307,"price_str":"61307"},"channel":"live_orders_btcusd","event":"order_created"}
{"data":{"id":1722049079767041,"id_str":"1722049079767041","order_type":1,"datetime":"1709257113","microtimestamp":"1709257113272000","amount":0.48905682,"amount_str":"0.48905682","amount_traded":"0","amount_at_create":"0.48905682","price":61343,"price_str":"61343"},"channel":"live_orders_btcusd","event":"order_created"}
{"data":{"id":1722049079545856,"id_str":"1722049079545856","order_type":0,"datetime":"1709257113","microtimestamp":"1709257113277000","amount":0.00914557,"amount_str":"0.00914557","amount_traded":"0","amount_at_create":"0.00914557","price":61318,"price_str":"61318"},"channel":"live_orders_btcusd","event":"order_deleted"}
{"data":{"id":1722049079816196,"id_str":"1722049079816196","order_type":1,"datetime":"1709257113","microtimestamp":"1709257113284000","amount":0.0205372,"amount_str":"0.02053720","amount_traded":"0","amount_at_create":"0.02053720","price":61342,"price_str":"61342"},"channel":"live_orders_btcusd","event":"order_created"}
{"data":{"id":1722049073504256,"id_str":"1722049073504256","order_type":1,"datetime":"1709257113","microtimestamp":"1709257113298000","amount":0.48891956,"amount_str":"0.48891956","amount_traded":"0","amount_at_create":"0.48891956","price":61360,"price_str":"61360"},"channel":"live_orders_btcusd","event":"order_deleted"}
{"data":{"id":1722049079898112,"id_str":"1722049079898112","order_type":0,"datetime":"1709257113","microtimestamp":"1709257113304000","amount":0.12188796,"amount_str":"0.12188796","amount_traded":"0","amount_at_create":"0.12188796","price":61257,"price_str":"61257"},"channel":"live_orders_btcusd","event":"order_created"}
{"data":{"id":1722049079902212,"id_str":"1722049079902212","order_type":0,"datetime":"1709257113","microtimestamp":"1709257113306000","amount":0.00914527,"amount_str":"0.00914527","amount_traded":"0","amount_at_create":"0.00914527","price":61320,"price_str":"61320"},"channel":"live_orders_btcusd","event":"order_created"}
{"data":{"id":1722049079816196,"id_str":"1722049079816196","order_type":1,"datetime":"1709257113","microtimestamp":"1709257113307000","amount":0.0205372,"amount_str":"0.02053720","amount_traded":"0","amount_at_create":"0.02053720","price":61342,"price_str":"61342"},"channel":"live_orders_btcusd","event":"order_deleted"}
{"data":{"id":1722049079943169,"id_str":"1722049079943169","order_type":1,"datetime":"1709257113","microtimestamp":"1709257113316000","amount":0.0163057,"amount_str":"0.01630570","amount_traded":"0","amount_at_create":"0.01630570","price":61329,"price_str":"61329"},"channel":"live_orders_btcusd","event":"order_created"}
{"data":{"id":1722049079902212,"id_str":"1722049079902212","order_type":0,"datetime":"1709257113","microtimestamp":"1709257113318000","amount":0.00914527,"amount_str":"0.00914527","amount_traded":"0","amount_at_create":"0.00914527","price":61320,"price_str":"61320"},"channel":"live_orders_btcusd","event":"order_deleted"}
{"data":{"id":1722049079943169,"id_str":"1722049079943169","order_type":1,"datetime":"1709257113","microtimestamp":"1709257113330000","amount":0.0163057,"amount_str":"0.01630570","amount_traded":"0","amount_at_create":"0.01630570","price":61329,"price_str":"61329"},"channel":"live_orders_btcusd","event":"order_deleted"}
{"data":{"id":1722049080184833,"id_str":"1722049080184833","order_type":1,"datetime":"1709257113","microtimestamp":"1709257113374000","amount":0.48859845,"amount_str":"0.48859845","amount_traded":"0","amount_at_create":"0.48859845","price":61401,"price_str":"61401"},"channel":"live_orders_btcusd","event":"order_created"}
{"data":{"id":1722049079758848,"id_str":"1722049079758848","order_type":0,"datetime":"1709257113","microtimestamp":"1709257113408000","amount":0.00040756,"amount_str":"0.00040756","amount_traded":"0","amount_at_create":"0.00040756","price":61307,"price_str":"61307"},"channel":"live_orders_btcusd","event":"order_deleted"}
{"data":{"id":1722049080365060,"id_str":"1722049080365060","order_type":1,"datetime":"1709257113","microtimestamp":"1709257113419000","amount":0.01630578,"amount_str":"0.01630578","amount_traded":"0","amount_at_create":"0.01630578","price":61328,"price_str":"61328"},"channel":"live_orders_btcusd","event":"order_created"}
{"data":{"id":1722049080381441,"id_str":"1722049080381441","order_type":1,"datetime":"1709257113","microtimestamp":"1709257113422000","amount":0.48913309,"amount_str":"0.48913309","amount_traded":"0","amount_at_create":"0.48913309","price":61333,"price_str":"61333"},"channel":"live_orders_btcusd","event":"order_created"}
{"data":{"id":1722049080381441,"id_str":"1722049080381441","order_type":1,"datetime":"1709257113","microtimestamp":"1709257113438000","amount":0.48913309,"amount_str":"0.48913309","amount_traded":"0","amount_at_create":"0.48913309","price":61333,"price_str":"61333"},"channel":"live_orders_btcusd","event":"order_deleted"}
{"data":{"id":1722049080365060,"id_str":"1722049080365060","order_type":1,"datetime":"1709257113","microtimestamp":"1709257113439000","amount":0.01630578,"amount_str":"0.01630578","amount_traded":"0","amount_at_create":"0.01630578","price":61328,"price_str":"61328"},"channel":"live_orders_btcusd","event":"order_deleted"}
{"data":{"id":1722049080463363,"id_str":"1722049080463363","order_type":0,"datetime":"1709257113","microtimestamp":"1709257113442000","amount":0.1875,"amount_str":"0.18750000","amount_traded":"0","amount_at_create":"0.18750000","price":61310,"price_str":"61310"},"channel":"live_orders_btcusd","event":"order_created"}
{"data":{"id":1722049080487936,"id_str":"1722049080487936","order_type":1,"datetime":"1709257113","microtimestamp":"1709257113448000","amount":0.02485448,"amount_str":"0.02485448","amount_traded":"0","amount_at_create":"0.02485448","price":61343,"price_str":"61343"},"channel":"live_orders_btcusd","event":"order_created"}
{"data":{"id":1722049080492033,"id_str":"1722049080492033","order_type":0,"datetime":"1709257113","microtimestamp":"1709257113449000","amount":0.00914527,"amount_str":"0.00914527","amount_traded":"0","amount_at_create":"0.00914527","price":61318,"price_str":"61318"},"channel":"live_orders_btcusd","event":"order_created"}
{"data":{"id":1722049079492611,"id_str":"1722049079492611","order_type":0,"datetime":"1709257114","microtimestamp":"1709257113500000","amount":0.01630852,"amount_str":"0.01630852","amount_traded":"0","amount_at_create":"0.01630852","price":61317,"price_str":"61317"},"channel":"live_orders_btcusd","event":"order_deleted"}
{"data":{"id":1722049079500803,"id_str":"1722049079500803","order_type":0,"datetime":"1709257114","microtimestamp":"1709257113500000","amount":0.48927304,"amount_str":"0.48927304","amount_traded":"0","amount_at_create":"0.48927304","price":61315,"price_str":"61315"},"channel":"live_orders_btcusd","event":"order_deleted"}
{"data":{"id":1722049079496704,"id_str":"1722049079496704","order_type":0,"datetime":"1709257114","microtimestamp":"1709257113508000","amount":0.48930785,"amount_str":"0.48930785","amount_traded":"0","amount_at_create":"0.48930785","price":61311,"price_str":"61311"},"channel":"live_orders_btcusd","event":"order_deleted"}
{"data":{"id":1722049080913920,"id_str":"1722049080913920","order_type":0,"datetime":"1709257114","microtimestamp":"1709257113552000","amount":0.48925966,"amount_str":"0.48925966","amount_traded":"0","amount_at_create":"0.48925966","price":61317,"price_str":"61317"},"channel":"live_orders_btcusd","event":"order_created"}
{"data":{"id":1722049080913924,"id_str":"1722049080913924","order_type":0,"datetime":"1709257114","microtimestamp":"1709257113553000","amount":0.01630813,"amount_str":"0.01630813","amount_traded":"0","amount_at_create":"0.01630813","price":61319,"price_str":"61319"},"channel":"live_orders_btcusd","event":"order_created"}
{"data":{"id":1722049080922113,"id_str":"1722049080922113","order_type":1,"datetime":"1709257114","microtimestamp":"1709257113554000","amount":0.01630505,"amount_str":"0.01630505","amount_traded":"0","amount_at_create":"0.01630505","price":61331,"price_str":"61331"},"channel":"live_orders_btcusd","event":"order_created"}
{"data":{"id":1722049081073664,"id_str":"1722049081073664","order_type":0,"datetime":"1709257114","microtimestamp":"1709257113591000","amount":0.00040756,"amount_str":"0.00040756","amount_traded":"0","amount_at_create":"0.00040756","price":61306,"price_str":"61306"},"channel":"live_orders_btcusd","event":"order_created"}
{"data":{"id":1722049080922113,"id_str":"1722049080922113","order_type":1,"datetime":"1709257114","microtimestamp":"1709257113599000","amount":0.01630505,"amount_str":"0.01630505","amount_traded":"0","amount_at_create":"0.01630505","price":61331,"price_str":"61331"},"channel":"live_orders_btcusd","event":"order_deleted"}
{"data":{"id":1722049081282562,"id_str":"1722049081282562","order_type":1,"datetime":"1709257114","microtimestamp":"1709257113643000","amount":0.48913218,"amount_str":"0.48913218","amount_traded":"0","amount_at_create":"0.48913218","price":61334,"price_str":"61334"},"channel":"live_orders_btcusd","event":"order_created"}
{"data":{"id":1722049080492033,"id_str":"1722049080492033","order_type":0,"datetime":"1709257114","microtimestamp":"1709257113661000","amount":0.00914527,"amount_str":"0.00914527","amount_traded":"0","amount_at_create":"0.00914527","price":61318,"price_str":"61318"},"channel":"live_orders_btcusd","event":"order_deleted"}
{"data":{"id":1722049081466880,"id_str":"1722049081466880","order_type":1,"datetime":"1709257114","microtimestamp":"1709257113687000","amount":0.01630485,"amount_str":"0.01630485","amount_traded":"0","amount_at_create":"0.01630485","price":61332,"price_str":"61332"},"channel":"live_orders_btcusd","event":"order_created"}
{"data":{"id":1722049081282562,"id_str":"1722049081282562","order_type":1,"datetime":"1709257114","microtimestamp":"1709257113700000","amount":0.48913218,"amount_str":"0.48913218","amount_traded":"0","amount_at_create":"0.48913218","price":61334,"price_str":"61334"},"channel":"live_orders_btcusd","event":"order_deleted"}
{"data":{"id":1722049081466880,"id_str":"1722049081466880","order_type":1,"datetime":"1709257114","microtimestamp":"1709257113702000","amount":0.01630485,"amount_str":"0.01630485","amount_traded":"0","amount_at_create":"0.01630485","price":61332,"price_str":"61332"},"channel":"live_orders_btcusd","event":"order_deleted"}
{"data":{"id":1722049080463363,"id_str":"1722049080463363","order_type":0,"datetime":"1709257114","microtimestamp":"1709257113723000","amount":0.1875,"amount_str":"0.18750000","amount_traded":"0","amount_at_create":"0.18750000","price":61310,"price_str":"61310"},"channel":"live_orders_btcusd","event":"order_deleted"}
{"data":{"id":1722049081634817,"id_str":"1722049081634817","order_type":0,"datetime":"1709257114","microtimestamp":"1709257113728000","amount":0.00914557,"amount_str":"0.00914557","amount_traded":"0","amount_at_create":"0.00914557","price":61320,"price_str":"61320"},"channel":"live_orders_btcusd","event":"order_created"}
{"data":{"id":1722049081700352,"id_str":"1722049081700352","order_type":1,"datetime":"1709257114","microtimestamp":"1709257113744000","amount":0.48911624,"amount_str":"0.48911624","amount_traded":"0","amount_at_create":"0.48911624","price":61336,"price_str":"61336"},"channel":"live_orders_btcusd","event":"order_created"}
{"data":{"id":1722049081708544,"id_str":"1722049081708544","order_type":1,"datetime":"1709257114","microtimestamp":"1709257113746000","amount":0.48895078,"amount_str":"0.48895078","amount_traded":"0","amount_at_create":"0.48895078","price":61356,"price_str":"61356"},"channel":"live_orders_btcusd","event":"order_created"}
{"data":{"id":1722049081708545,"id_str":"1722049081708545","order_type":0,"datetime":"1709257114","microtimestamp":"1709257113746000","amount":0.48929269,"amount_str":"0.48929269","amount_traded":"0","amount_at_create":"0.48929269","price":61312,"price_str":"61312"},"channel":"live_orders_btcusd","event":"order_created"}
{"data":{"id":1722049081884672,"id_str":"1722049081884672","order_type":1,"datetime":"1709257114","microtimestamp":"1709257113789000","amount":0.01630503,"amount_str":"0.01630503","amount_traded":"0","amount_at_create":"0.01630503","price":61331,"price_str":"61331"},"channel":"live_orders_btcusd","event":"order_created"}
{"data":{"id":1722049081884672,"id_str":"1722049081884672","order_type":1,"datetime":"1709257114","microtimestamp":"1709257113900000","amount":0.01630503,"amount_str":"0.01630503","amount_traded":"0","amount_at_create":"0.01630503","price":61331,"price_str":"61331"},"channel":"live_orders_btcusd","event":"order_deleted"}
