{"data":{"id":1722048985993216,"id_str":"1722048985993216","order_type":0,"datetime":"1709257090","microtimestamp":"1709257090474000","amount":0.00040756,"amount_str":"0.00040756","amount_traded":"0","amount_at_create":"0.00040756","price":61316,"price_str":"61316"},"channel":"live_orders_btcusd","event":"order_deleted"}
{"data":{"id":1722048986763264,"id_str":"1722048986763264","order_type":0,"datetime":"1709257091","microtimestamp":"1709257090566000","amount":0.00040756,"amount_str":"0.00040756","amount_traded":"0","amount_at_create":"0.00040756","price":61317,"price_str":"61317"},"channel":"live_orders_btcusd","event":"order_created"}
{"data":{"id":1722048986206213,"id_str":"1722048986206213","order_type":0,"datetime":"1709257091","microtimestamp":"1709257090598000","amount":0.48947019,"amount_str":"0.48947019","amount_traded":"0","amount_at_create":"0.48947019","price":61290,"price_str":"61290"},"channel":"live_orders_btcusd","event":"order_deleted"}
{"data":{"id":1722048986763264,"id_str":"1722048986763264","order_type":0,"datetime":"1709257091","microtimestamp":"1709257090605000","amount":0.00040756,"amount_str":"0.00040756","amount_traded":"0","amount_at_create":"0.00040756","price":61317,"price_str":"61317"},"channel":"live_orders_btcusd","event":"order_deleted"}
{"data":{"id":1722048982986754,"id_str":"1722048982986754","order_type":0,"datetime":"1709257091","microtimestamp":"1709257090659000","amount":0.01630759,"amount_str":"0.01630759","amount_traded":"0","amount_at_create":"0.01630759","price":61321,"price_str":"61321"},"channel":"live_orders_btcusd","event":"order_deleted"}
{"data":{"id":1722048986202113,"id_str":"1722048986202113","order_type":0,"datetime":"1709257091","microtimestamp":"1709257090659000","amount":0.48927725,"amount_str":"0.48927725","amount_traded":"0","amount_at_create":"0.48927725","price":61314,"price_str":"61314"},"channel":"live_orders_btcusd","event":"order_deleted"}
{"data":{"id":1722048982978560,"id_str":"1722048982978560","order_type":1,"datetime":"1709257091","microtimestamp":"1709257090659000","amount":0.48915723,"amount_str":"0.48915723","amount_traded":"0","amount_at_create":"0.48915723","price":61330,"price_str":"61330"},"channel":"live_orders_btcusd","event":"order_deleted"}
{"data":{"id":1722048987279360,"id_str":"1722048987279360","order_type":0,"datetime":"1709257091","microtimestamp":"1709257090692000","amount":0.00040756,"amount_str":"0.00040756","amount_traded":"0","amount_at_create":"0.00040756","price":61316,"price_str":"61316"},"channel":"live_orders_btcusd","event":"order_created"}
{"data":{"id":1722048986206212,"id_str":"1722048986206212","order_type":1,"datetime":"1709257091","microtimestamp":"1709257090701000","amount":0.48897383,"amount_str":"0.48897383","amount_traded":"0","amount_at_create":"0.48897383","price":61353,"price_str":"61353"},"channel":"live_orders_btcusd","event":"order_deleted"}
{"data":{"id":1722048986206210,"id_str":"1722048986206210","order_type":1,"datetime":"1709257091","microtimestamp":"1709257090702000","amount":0.48912514,"amount_str":"0.48912514","amount_traded":"0","amount_at_create":"0.48912514","price":61334,"price_str":"61334"},"channel":"live_orders_btcusd","event":"order_deleted"}
{"data":{"id":1722048982097921,"id_str":"1722048982097921","order_type":1,"datetime":"1709257091","microtimestamp":"1709257090703000","amount":0.01630591,"amount_str":"0.01630591","amount_traded":"0","amount_at_create":"0.01630591","price":61328,"price_str":"61328"},"channel":"live_orders_btcusd","event":"order_deleted"}
{"data":{"id":1722048987324419,"id_str":"1722048987324419","order_type":0,"datetime":"1709257091","microtimestamp":"1709257090703000","amount":0.01630731,"amount_str":"0.01630731","amount_traded":"0","amount_at_create":"0.01630731","price":61322,"price_str":"61322"},"channel":"live_orders_btcusd","event":"order_created"}
{"data":{"id":1722048987324420,"id_str":"1722048987324420","order_type":1,"datetime":"1709257091","microtimestamp":"1709257090703000","amount":0.4891483,"amount_str":"0.48914830","amount_traded":"0","amount_at_create":"0.48914830","price":61332,"price_str":"61332"},"channel":"live_orders_btcusd","event":"order_created"}
{"data":{"id":1722048983576576,"id_str":"1722048983576576","order_type":0,"datetime":"1709257091","microtimestamp":"1709257090703000","amount":0.48924173,"amount_str":"0.48924173","amount_traded":"0","amount_at_create":"0.48924173","price":61319,"price_str":"61319"},"channel":"live_orders_btcusd","event":"order_deleted"}
{"data":{"id":1722048987324419,"id_str":"1722048987324419","order_type":0,"datetime":"1709257091","microtimestamp":"1709257090720000","amount":0.01630731,"amount_str":"0.01630731","amount_traded":"0","amount_at_create":"0.01630731","price":61322,"price_str":"61322"},"channel":"live_orders_btcusd","event":"order_deleted"}
{"data":{"id":1722048987570176,"id_str":"1722048987570176","order_type":0,"datetime":"1709257091","microtimestamp":"1709257090763000","amount":0.48922808,"amount_str":"0.48922808","amount_traded":"0","amount_at_create":"0.48922808","price":61321,"price_str":"61321"},"channel":"live_orders_btcusd","event":"order_created"}
{"data":{"id":1722048987570177,"id_str":"1722048987570177","order_type":1,"datetime":"1709257091","microtimestamp":"1709257090764000","amount":0.0163052,"amount_str":"0.01630520","amount_traded":"0","amount_at_create":"0.01630520","price":61331,"price_str":"61331"},"channel":"live_orders_btcusd","event":"order_created"}
{"data":{"id":1722048987570177,"id_str":"1722048987570177","order_type":1,"datetime":"1709257091","microtimestamp":"1709257090799000","amount":0.0163052,"amount_str":"0.01630520","amount_traded":"0","amount_at_create":"0.01630520","price":61331,"price_str":"61331"},"channel":"live_orders_btcusd","event":"order_deleted"}
{"data":{"id":1722048987570176,"id_str":"1722048987570176","order_type":0,"datetime":"1709257091","microtimestamp":"1709257090799000","amount":0.48922808,"amount_str":"0.48922808","amount_traded":"0","amount_at_create":"0.48922808","price":61321,"price_str":"61321"},"channel":"live_orders_btcusd","event":"order_deleted"}
{"data":{"id":1722048987324420,"id_str":"1722048987324420","order_type":1,"datetime":"1709257091","microtimestamp":"1709257090799000","amount":0.4891483,"amount_str":"0.48914830","amount_traded":"0","amount_at_create":"0.48914830","price":61332,"price_str":"61332"},"channel":"live_orders_btcusd","event":"order_deleted"}
{"data":{"id":1722048987754497,"id_str":"1722048987754497","order_type":0,"datetime":"1709257091","microtimestamp":"1709257090808000","amount":0.01630702,"amount_str":"0.01630702","amount_traded":"0","amount_at_create":"0.01630702","price":61323,"price_str":"61323"},"channel":"live_orders_btcusd","event":"order_created"}
{"data":{"id":1722048987754497,"id_str":"1722048987754497","order_type":0,"datetime":"1709257091","microtimestamp":"1709257090821000","amount":0.01630702,"amount_str":"0.01630702","amount_traded":"0","amount_at_create":"0.01630702","price":61323,"price_str":"61323"},"channel":"live_orders_btcusd","event":"order_deleted"}
{"data":{"id":1722048983838721,"id_str":"1722048983838721","order_type":0,"datetime":"1709257091","microtimestamp":"1709257090836000","amount":0.00133153,"amount_str":"0.00133153","amount_traded":"0","amount_at_create":"0.00133153","price":61265,"price_str":"61265"},"channel":"live_orders_btcusd","event":"order_deleted"}
{"data":{"id":1722048987279360,"id_str":"1722048987279360","order_type":0,"datetime":"1709257091","microtimestamp":"1709257090862000","amount":0.00040756,"amount_str":"0.00040756","amount_traded":"0","amount_at_create":"0.00040756","price":61316,"price_str":"61316"},"channel":"live_orders_btcusd","event":"order_deleted"}
{"data":{"id":1722048987975682,"id_str":"1722048987975682","order_type":1,"datetime":"1709257091","microtimestamp":"1709257090862000","amount":0.01630561,"amount_str":"0.01630561","amount_traded":"0","amount_at_create":"0.01630561","price":61329,"price_str":"61329"},"channel":"live_orders_btcusd","event":"order_created"}
{"data":{"id":1722048988147712,"id_str":"1722048988147712","order_type":1,"datetime":"1709257091","microtimestamp":"1709257090904000","amount":0.48915108,"amount_str":"0.48915108","amount_traded":"0","amount_at_create":"0.48915108","price":61331,"price_str":"61331"},"channel":"live_orders_btcusd","event":"order_created"}
{"data":{"id":1722048988241920,"id_str":"1722048988241920","order_type":0,"datetime":"1709257091","microtimestamp":"1709257090927000","amount":0.00133155,"amount_str":"0.00133155","amount_traded":"0","amount_at_create":"0.00133155","price":61261,"price_str":"61261"},"channel":"live_orders_btcusd","event":"order_created"}
{"data":{"id":1722048988327937,"id_str":"1722048988327937","order_type":1,"datetime":"1709257091","microtimestamp":"1709257090949000","amount":0.48911892,"amount_str":"0.48911892","amount_traded":"0","amount_at_create":"0.48911892","price":61335,"price_str":"61335"},"channel":"live_orders_btcusd","event":"order_created"}
{"data":{"id":1722048988327939,"id_str":"1722048988327939","order_type":0,"datetime":"1709257091","microtimestamp":"1709257090949000","amount":0.01630735,"amount_str":"0.01630735","amount_traded":"0","amount_at_create":"0.01630735","price":61322,"price_str":"61322"},"channel":"live_orders_btcusd","event":"order_created"}
{"data":{"id":1722048988336129,"id_str":"1722048988336129","order_type":0,"datetime":"1709257091","microtimestamp":"1709257090951000","amount":0.48926025,"amount_str":"0.48926025","amount_traded":"0","amount_at_create":"0.48926025","price":61317,"price_str":"61317"},"channel":"live_orders_btcusd","event":"order_created"}
{"data":{"id":1722048988483584,"id_str":"1722048988483584","order_type":0,"datetime":"1709257091","microtimestamp":"1709257090986000","amount":0.00040756,"amount_str":"0.00040756","amount_traded":"0","amount_at_create":"0.00040756","price":61317,"price_str":"61317"},"channel":"live_orders_btcusd","event":"order_created"}
{"data":{"id":1722048988528642,"id_str":"1722048988528642","order_type":0,"datetime":"1709257091","microtimestamp":"1709257090998000","amount":0.48954088,"amount_str":"0.48954088","amount_traded":"0","amount_at_create":"0.48954088","price":61281,"price_str":"61281"},"channel":"live_orders_btcusd","event":"order_created"}
{"data":{"id":1722048988532736,"id_str":"1722048988532736","order_type":0,"datetime":"1709257091","microtimestamp":"1709257090998000","amount":0.4892346,"amount_str":"0.48923460","amount_traded":"0","amount_at_create":"0.48923460","price":61320,"price_str":"61320"},"channel":"live_orders_btcusd","event":"order_created"}
{"data":{"id":1722048988618752,"id_str":"1722048988618752","order_type":0,"datetime":"1709257091","microtimestamp":"1709257091020000","amount":0.00033304,"amount_str":"0.00033304","amount_traded":"0","amount_at_create":"0.00033304","price":59932,"price_str":"59932"},"channel":"live_orders_btcusd","event":"order_created"}
{"data":{"id":1722048988483584,"id_str":"1722048988483584","order_type":0,"datetime":"1709257091","microtimestamp":"1709257091024000","amount":0.00040756,"amount_str":"0.00040756","amount_traded":"0","amount_at_create":"0.00040756","price":61317,"price_str":"61317"},"channel":"live_orders_btcusd","event":"order_deleted"}
{"data":{"id":1722048988241920,"id_str":"1722048988241920","order_type":0,"datetime":"1709257091","microtimestamp":"1709257091054000","amount":0.00133155,"amount_str":"0.00133155","amount_traded":"0","amount_at_create":"0.00133155","price":61261,"price_str":"61261"},"channel":"live_orders_btcusd","event":"order_deleted"}
{"data":{"id":1722048975855616,"id_str":"1722048975855616","order_type":0,"datetime":"1709257091","microtimestamp":"1709257091102000","amount":0.1875,"amount_str":"0.18750000","amount_traded":"0","amount_at_create":"0.18750000","price":61280,"price_str":"61280"},"channel":"live_orders_btcusd","event":"order_deleted"}
{"data":{"id":1722048976297986,"id_str":"1722048976297986","order_type":1,"datetime":"1709257091","microtimestamp":"1709257091103000","amount":0.1875,"amount_str":"0.18750000","amount_traded":"0","amount_at_create":"0.18750000","price":61376,"price_str":"61376"},"channel":"live_orders_btcusd","event":"order_deleted"}
{"data":{"id":1722048989052929,"id_str":"1722048989052929","order_type":0,"datetime":"1709257091","microtimestamp":"1709257091126000","amount":0.00133155,"amount_str":"0.00133155","amount_traded":"0","amount_at_create":"0.00133155","price":61266,"price_str":"61266"},"channel":"live_orders_btcusd","event":"order_created"}
{"data":{"id":1722048989061123,"id_str":"1722048989061123","order_type":0,"datetime":"1709257091","microtimestamp":"1709257091128000","amount":0.00040756,"amount_str":"0.00040756","amount_traded":"0","amount_at_create":"0.00040756","price":61316,"price_str":"61316"},"channel":"live_orders_btcusd","event":"order_created"}
{"data":{"id":1722048682762240,"id_str":"1722048682762240","order_type":0,"datetime":"1709257091","microtimestamp":"1709257091169000","amount":0.5,"amount_str":"0.50000000","amount_traded":"0","amount_at_create":"0.50000000","price":61259,"price_str":"61259"},"channel":"live_orders_btcusd","event":"order_deleted"}
{"data":{"id":1722048989061123,"id_str":"1722048989061123","order_type":0,"datetime":"1709257091","microtimestamp":"1709257091373000","amount":0.00040756,"amount_str":"0.00040756","amount_traded":"0","amount_at_create":"0.00040756","price":61316,"price_str":"61316"},"channel":"live_orders_btcusd","event":"order_deleted"}
{"data":{"id":1722048987975682,"id_str":"1722048987975682","order_type":1,"datetime":"1709257091","microtimestamp":"1709257091400000","amount":0.01630561,"amount_str":"0.01630561","amount_traded":"0","amount_at_create":"0.01630561","price":61329,"price_str":"61329"},"channel":"live_orders_btcusd","event":"order_deleted"}
{"data":{"id":1722048988327939,"id_str":"1722048988327939","order_type":0,"datetime":"1709257091","microtimestamp":"1709257091401000","amount":0.01630735,"amount_str":"0.01630735","amount_traded":"0","amount_at_create":"0.01630735","price":61322,"price_str":"61322"},"channel":"live_orders_btcusd","event":"order_deleted"}
{"data":{"id":1722048988147712,"id_str":"1722048988147712","order_type":1,"datetime":"1709257091","microtimestamp":"1709257091401000","amount":0.48915108,"amount_str":"0.48915108","amount_traded":"0","amount_at_create":"0.48915108","price":61331,"price_str":"61331"},"channel":"live_orders_btcusd","event":"order_deleted"}
{"data":{"id":1722048988532736,"id_str":"1722048988532736","order_type":0,"datetime":"1709257091","microtimestamp":"1709257091401000","amount":0.4892346,"amount_str":"0.48923460","amount_traded":"0","amount_at_create":"0.48923460","price":61320,"price_str":"61320"},"channel":"live_orders_btcusd","event":"order_deleted"}
{"data":{"id":1722048990371842,"id_str":"1722048990371842","order_type":1,"datetime":"1709257091","microtimestamp":"1709257091448000","amount":0.0163052,"amount_str":"0.01630520","amount_traded":"0","amount_at_create":"0.01630520","price":61331,"price_str":"61331"},"channel":"live_orders_btcusd","event":"order_created"}
{"data":{"id":1722048990384131,"id_str":"1722048990384131","order_type":1,"datetime":"1709257091","microtimestamp":"1709257091450000","amount":0.48913893,"amount_str":"0.48913893","amount_traded":"0","amount_at_create":"0.48913893","price":61333,"price_str":"61333"},"channel":"live_orders_btcusd","event":"order_created"}
{"data":{"id":1722048990388224,"id_str":"1722048990388224","order_type":0,"datetime":"1709257091","microtimestamp":"1709257091451000","amount":0.48922766,"amount_str":"0.48922766","amount_traded":"0","amount_at_create":"0.48922766","price":61321,"price_str":"61321"},"channel":"live_orders_btcusd","event":"order_created"}
{"data":{"id":1722048990392322,"id_str":"1722048990392322","order_type":0,"datetime":"1709257091","microtimestamp":"1709257091452000","amount":0.01630701,"amount_str":"0.01630701","amount_traded":"0","amount_at_create":"0.01630701","price":61323,"price_str":"61323"},"channel":"live_orders_btcusd","event":"order_created"}
{"data":{"id":1722048990371842,"id_str":"1722048990371842","order_type":1,"datetime":"1709257091","microtimestamp":"1709257091499000","amount":0.0163052,"amount_str":"0.01630520","amount_traded":"0","amount_at_create":"0.01630520","price":61331,"price_str":"61331"},"channel":"live_orders_btcusd","event":"order_deleted"}
{"data":{"id":1722048990384131,"id_str":"1722048990384131","order_type":1,"datetime":"1709257091","microtimestamp":"1709257091499000","amount":0.48913893,"amount_str":"0.48913893","amount_traded":"0","amount_at_create":"0.48913893","price":61333,"price_str":"61333"},"channel":"live_orders_btcusd","event":"order_deleted"}
{"data":{"id":1722048990392322,"id_str":"1722048990392322","order_type":0,"datetime":"1709257092","microtimestamp":"1709257091500000","amount":0.01630701,"amount_str":"0.01630701","amount_traded":"0","amount_at_create":"0.01630701","price":61323,"price_str":"61323"},"channel":"live_orders_btcusd","event":"order_deleted"}
{"data":{"id":1722048990388224,"id_str":"1722048990388224","order_type":0,"datetime":"1709257092","microtimestamp":"1709257091500000","amount":0.48922766,"amount_str":"0.48922766","amount_traded":"0","amount_at_create":"0.48922766","price":61321,"price_str":"61321"},"channel":"live_orders_btcusd","event":"order_deleted"}
{"data":{"id":1722048989052929,"id_str":"1722048989052929","order_type":0,"datetime":"1709257092","microtimestamp":"1709257091506000","amount":0.00133155,"amount_str":"0.00133155","amount_traded":"0","amount_at_create":"0.00133155","price":61266,"price_str":"61266"},"channel":"live_orders_btcusd","event":"order_deleted"}
{"data":{"id":1722048990904320,"id_str":"1722048990904320","order_type":0,"datetime":"1709257092","microtimestamp":"1709257091577000","amount":0.00040756,"amount_str":"0.00040756","amount_traded":"0","amount_at_create":"0.00040756","price":61317,"price_str":"61317"},"channel":"live_orders_btcusd","event":"order_created"}
{"data":{"id":1722048662200320,"id_str":"1722048662200320","order_type":0,"datetime":"1709257092","microtimestamp":"1709257091611000","amount":1,"amount_str":"1.00000000","amount_traded":"0","amount_at_create":"1.00000000","price":61141,"price_str":"61141"},"channel":"live_orders_btcusd","event":"order_deleted"}
{"data":{"id":1722048991109121,"id_str":"1722048991109121","order_type":1,"datetime":"1709257092","microtimestamp":"1709257091628000","amount":0.01630567,"amount_str":"0.01630567","amount_traded":"0","amount_at_create":"0.01630567","price":61329,"price_str":"61329"},"channel":"live_orders_btcusd","event":"order_created"}
{"data":{"id":1722048991117314,"id_str":"1722048991117314","order_type":0,"datetime":"1709257092","microtimestamp":"1709257091629000","amount":0.01630713,"amount_str":"0.01630713","amount_traded":"0","amount_at_create":"0.01630713","price":61322,"price_str":"61322"},"channel":"live_orders_btcusd","event":"order_created"}
{"data":{"id":1722048991121408,"id_str":"1722048991121408","order_type":1,"datetime":"1709257092","microtimestamp":"1709257091630000","amount":0.48883628,"amount_str":"0.48883628","amount_traded":"0","amount_at_create":"0.48883628","price":61371,"price_str":"61371"},"channel":"live_orders_btcusd","event":"order_created"}
{"data":{"id":1722048991121409,"id_str":"1722048991121409","order_type":1,"datetime":"1709257092","microtimestamp":"1709257091630000","amount":0.16270357,"amount_str":"0.16270357","amount_traded":"0","amount_at_create":"0.16270357","price":61462,"price_str":"61462"},"channel":"live_orders_btcusd","event":"order_created"}
{"data":{"id":1722048991117314,"id_str":"1722048991117314","order_type":0,"datetime":"1709257092","microtimestamp":"1709257091646000","amount":0.01630713,"amount_str":"0.01630713","amount_traded":"0","amount_at_create":"0.01630713","price":61322,"price_str":"61322"},"channel":"live_orders_btcusd","event":"order_deleted"}
{"data":{"id":1722048990904320,"id_str":"1722048990904320","order_type":0,"datetime":"1709257092","microtimestamp":"1709257091660000","amount":0.00040756,"amount_str":"0.00040756","amount_traded":"0","amount_at_create":"0.00040756","price":61317,"price_str":"61317"},"channel":"live_orders_btcusd","event":"order_deleted"}
{"data":{"id":1722048991309827,"id_str":"1722048991309827","order_type":1,"datetime":"1709257092","microtimestamp":"1709257091676000","amount":0.1875,"amount_str":"0.18750000","amount_traded":"0","amount_at_create":"0.18750000","price":61460,"price_str":"61460"},"channel":"live_orders_btcusd","event":"order_created"}
{"data":{"id":1722048991367169,"id_str":"1722048991367169","order_type":1,"datetime":"1709257092","microtimestamp":"1709257091690000","amount":0.48915292,"amount_str":"0.48915292","amount_traded":"0","amount_at_create":"0.48915292","price":61331,"price_str":"61331"},"channel":"live_orders_btcusd","event":"order_created"}
{"data":{"id":1722048991371265,"id_str":"1722048991371265","order_type":0,"datetime":"1709257092","microtimestamp":"1709257091691000","amount":0.48923153,"amount_str":"0.48923153","amount_traded":"0","amount_at_create":"0.48923153","price":61320,"price_str":"61320"},"channel":"live_orders_btcusd","event":"order_created"}
{"data":{"id":1722048991559680,"id_str":"1722048991559680","order_type":0,"datetime":"1709257092","microtimestamp":"1709257091737000","amount":0.01630709,"amount_str":"0.01630709","amount_traded":"0","amount_at_create":"0.01630709","price":61323,"price_str":"61323"},"channel":"live_orders_btcusd","event":"order_created"}
{"data":{"id":1722048869593088,"id_str":"1722048869593088","order_type":1,"datetime":"1709257092","microtimestamp":"1709257091831000","amount":0.00272853,"amount_str":"0.00272853","amount_traded":"0","amount_at_create":"0.00272853","price":61574,"price_str":"61574"},"channel":"live_orders_btcusd","event":"order_deleted"}
{"data":{"id":1722048991948800,"id_str":"1722048991948800","order_type":0,"datetime":"1709257092","microtimestamp":"1709257091832000","amount":0.00040756,"amount_str":"0.00040756","amount_traded":"0","amount_at_create":"0.00040756","price":61316,"price_str":"61316"},"channel":"live_orders_btcusd","event":"order_created"}
{"data":{"id":1722048992034818,"id_str":"1722048992034818","order_type":0,"datetime":"1709257092","microtimestamp":"1709257091853000","amount":0.00133155,"amount_str":"0.00133155","amount_traded":"0","amount_at_create":"0.00133155","price":61266,"price_str":"61266"},"channel":"live_orders_btcusd","event":"order_created"}
{"data":{"id":1722048991371265,"id_str":"1722048991371265","order_type":0,"datetime":"1709257092","microtimestamp":"1709257091866000","amount":0.48923153,"amount_str":"0.48923153","amount_traded":"0","amount_at_create":"0.48923153","price":61320,"price_str":"61320"},"channel":"live_orders_btcusd","event":"order_deleted"}
{"data":{"id":1722048991367169,"id_str":"1722048991367169","order_type":1,"datetime":"1709257092","microtimestamp":"1709257091901000","amount":0.48915292,"amount_str":"0.48915292","amount_traded":"0","amount_at_create":"0.48915292","price":61331,"price_str":"61331"},"channel":"live_orders_btcusd","event":"order_deleted"}
{"data":{"id":1722048991109121,"id_str":"1722048991109121","order_type":1,"datetime":"1709257092","microtimestamp":"1709257091902000","amount":0.01630567,"amount_str":"0.01630567","amount_traded":"0","amount_at_create":"0.01630567","price":61329,"price_str":"61329"},"channel":"live_orders_btcusd","event":"order_deleted"}
{"data":{"id":1722048992034818,"id_str":"1722048992034818","order_type":0,"datetime":"1709257092","microtimestamp":"1709257091908000","amount":0.00133155,"amount_str":"0.00133155","amount_traded":"0","amount_at_create":"0.00133155","price":61266,"price_str":"61266"},"channel":"live_orders_btcusd","event":"order_deleted"}
{"data":{"id":1722048992268288,"id_str":"1722048992268288","order_type":0,"datetime":"1709257092","microtimestamp":"1709257091910000","amount":0.48922773,"amount_str":"0.48922773","amount_traded":"0","amount_at_create":"0.48922773","price":61321,"price_str":"61321"},"channel":"live_orders_btcusd","event":"order_created"}
{"data":{"id":1722048992440320,"id_str":"1722048992440320","order_type":1,"datetime":"1709257092","microtimestamp":"1709257091953000","amount":0.48913904,"amount_str":"0.48913904","amount_traded":"0","amount_at_create":"0.48913904","price":61333,"price_str":"61333"},"channel":"live_orders_btcusd","event":"order_created"}
{"data":{"id":1722048992444418,"id_str":"1722048992444418","order_type":1,"datetime":"1709257092","microtimestamp":"1709257091953000","amount":0.01630521,"amount_str":"0.01630521","amount_traded":"0","amount_at_create":"0.01630521","price":61331,"price_str":"61331"},"channel":"live_orders_btcusd","event":"order_created"}
{"data":{"id":1722048992481280,"id_str":"1722048992481280","order_type":1,"datetime":"1709257092","microtimestamp":"1709257091962000","amount":0.00272853,"amount_str":"0.00272853","amount_traded":"0","amount_at_create":"0.00272853","price":61536,"price_str":"61536"},"channel":"live_orders_btcusd","event":"order_created"}
{"data":{"id":1722048991948800,"id_str":"1722048991948800","order_type":0,"datetime":"1709257092","microtimestamp":"1709257091978000","amount":0.00040756,"amount_str":"0.00040756","amount_traded":"0","amount_at_create":"0.00040756","price":61316,"price_str":"61316"},"channel":"live_orders_btcusd","event":"order_deleted"}
{"data":{"id":1722048992866304,"id_str":"1722048992866304","order_type":0,"datetime":"1709257092","microtimestamp":"1709257092056000","amount":0.00133155,"amount_str":"0.00133155","amount_traded":"0","amount_at_create":"0.00133155","price":61267,"price_str":"61267"},"channel":"live_orders_btcusd","event":"order_created"}
{"data":{"id":1722048992985088,"id_str":"1722048992985088","order_type":0,"datetime":"1709257092","microtimestamp":"1709257092085000","amount":0.00040756,"amount_str":"0.00040756","amount_traded":"0","amount_at_create":"0.00040756","price":61317,"price_str":"61317"},"channel":"live_orders_btcusd","event":"order_created"}
{"data":{"id":1722048992985088,"id_str":"1722048992985088","order_type":0,"datetime":"1709257092","microtimestamp":"1709257092174000","amount":0.00040756,"amount_str":"0.00040756","amount_traded":"0","amount_at_create":"0.00040756","price":61317,"price_str":"61317"},"channel":"live_orders_btcusd","event":"order_deleted"}
{"data":{"id":1722048993505281,"id_str":"1722048993505281","order_type":0,"datetime":"1709257092","microtimestamp":"1709257092212000","amount":0.04875518,"amount_str":"0.04875518","amount_traded":"0","amount_at_create":"0.04875518","price":61301,"price_str":"61301"},"channel":"live_orders_btcusd","event":"order_created"}
{"data":{"id":1722048993533952,"id_str":"1722048993533952","order_type":0,"datetime":"1709257092","microtimestamp":"1709257092219000","amount":0.12188796,"amount_str":"0.12188796","amount_traded":"0","amount_at_create":"0.12188796","price":61269,"price_str":"61269"},"channel":"live_orders_btcusd","event":"order_created"}
{"data":{"id":1722048992866304,"id_str":"1722048992866304","order_type":0,"datetime":"1709257092","microtimestamp":"1709257092265000","amount":0.00133155,"amount_str":"0.00133155","amount_traded":"0","amount_at_create":"0.00133155","price":61267,"price_str":"61267"},"channel":"live_orders_btcusd","event":"order_deleted"}
{"data":{"id":1722048992440320,"id_str":"1722048992440320","order_type":1,"datetime":"1709257092","microtimestamp":"1709257092299000","amount":0.48913904,"amount_str":"0.48913904","amount_traded":"0","amount_at_create":"0.48913904","price":61333,"price_str":"61333"},"channel":"live_orders_btcusd","event":"order_deleted"}
{"data":{"id":1722048992444418,"id_str":"1722048992444418","order_type":1,"datetime":"1709257092","microtimestamp":"1709257092300000","amount":0.01630521,"amount_str":"0.01630521","amount_traded":"0","amount_at_create":"0.01630521","price":61331,"price_str":"61331"},"channel":"live_orders_btcusd","event":"order_deleted"}
{"data":{"id":1722048993984512,"id_str":"1722048993984512","order_type":0,"datetime":"1709257092","microtimestamp":"1709257092329000","amount":0.00133155,"amount_str":"0.00133155","amount_traded":"0","amount_at_create":"0.00133155","price":61324,"price_str":"61324"},"channel":"live_orders_btcusd","event":"order_created"}
{"data":{"id":1722048994050051,"id_str":"1722048994050051","order_type":1,"datetime":"1709257092","microtimestamp":"1709257092346000","amount":0.48914462,"amount_str":"0.48914462","amount_traded":"0","amount_at_create":"0.48914462","price":61332,"price_str":"61332"},"channel":"live_orders_btcusd","event":"order_created"}
{"data":{"id":1722048994062338,"id_str":"1722048994062338","order_type":1,"datetime":"1709257092","microtimestamp":"1709257092348000","amount":0.01630539,"amount_str":"0.01630539","amount_traded":"0","amount_at_create":"0.01630539","price":61330,"price_str":"61330"},"channel":"live_orders_btcusd","event":"order_created"}
{"data":{"id":1722048994168832,"id_str":"1722048994168832","order_type":0,"datetime":"1709257092","microtimestamp":"1709257092375000","amount":0.1875,"amount_str":"0.18750000","amount_traded":"0","amount_at_create":"0.18750000","price":61282,"price_str":"61282"},"channel":"live_orders_btcusd","event":"order_created"}
{"data":{"id":1722048994254848,"id_str":"1722048994254848","order_type":0,"datetime":"1709257092","microtimestamp":"1709257092395000","amount":0.00040756,"amount_str":"0.00040756","amount_traded":"0","amount_at_create":"0.00040756","price":61316,"price_str":"61316"},"channel":"live_orders_btcusd","event":"order_created"}
{"data":{"id":1722048994254848,"id_str":"1722048994254848","order_type":0,"datetime":"1709257092","microtimestamp":"1709257092477000","amount":0.00040756,"amount_str":"0.00040756","amount_traded":"0","amount_at_create":"0.00040756","price":61316,"price_str":"61316"},"channel":"live_orders_btcusd","event":"order_deleted"}
{"data":{"id":1722048994820096,"id_str":"1722048994820096","order_type":1,"datetime":"1709257093","microtimestamp":"1709257092533000","amount":0.48893439,"amount_str":"0.48893439","amount_traded":"0","amount_at_create":"0.48893439","price":61358,"price_str":"61358"},"channel":"live_orders_btcusd","event":"order_created"}
{"data":{"id":1722048994820098,"id_str":"1722048994820098","order_type":0,"datetime":"1709257093","microtimestamp":"1709257092533000","amount":0.489443,"amount_str":"0.48944300","amount_traded":"0","amount_at_create":"0.48944300","price":61294,"price_str":"61294"},"channel":"live_orders_btcusd","event":"order_created"}
{"data":{"id":1722048995393536,"id_str":"1722048995393536","order_type":0,"datetime":"1709257093","microtimestamp":"1709257092673000","amount":0.00040756,"amount_str":"0.00040756","amount_traded":"0","amount_at_create":"0.00040756","price":61316,"price_str":"61316"},"channel":"live_orders_btcusd","event":"order_created"}
{"data":{"id":1722048992268288,"id_str":"1722048992268288","order_type":0,"datetime":"1709257093","microtimestamp":"1709257092703000","amount":0.48922773,"amount_str":"0.48922773","amount_traded":"0","amount_at_create":"0.48922773","price":61321,"price_str":"61321"},"channel":"live_orders_btcusd","event":"order_deleted"}
{"data":{"id":1722048991559680,"id_str":"1722048991559680","order_type":0,"datetime":"1709257093","microtimestamp":"1709257092704000","amount":0.01630709,"amount_str":"0.01630709","amount_traded":"0","amount_at_create":"0.01630709","price":61323,"price_str":"61323"},"channel":"live_orders_btcusd","event":"order_deleted"}
{"data":{"id":1722048994050051,"id_str":"1722048994050051","order_type":1,"datetime":"1709257093","microtimestamp":"1709257092704000","amount":0.48914462,"amount_str":"0.48914462","amount_traded":"0","amount_at_create":"0.48914462","price":61332,"price_str":"61332"},"channel":"live_orders_btcusd","event":"order_deleted"}
{"data":{"id":1722048994062338,"id_str":"1722048994062338","order_type":1,"datetime":"1709257093","microtimestamp":"1709257092704000","amount":0.01630539,"amount_str":"0.01630539","amount_traded":"0","amount_at_create":"0.01630539","price":61330,"price_str":"61330"},"channel":"live_orders_btcusd","event":"order_deleted"}
{"data":{"id":1722048995704832,"id_str":"1722048995704832","order_type":0,"datetime":"1709257093","microtimestamp":"1709257092749000","amount":0.48924119,"amount_str":"0.48924119","amount_traded":"0","amount_at_create":"0.48924119","price":61319,"price_str":"61319"},"channel":"live_orders_btcusd","event":"order_created"}
{"data":{"id":1722048995708928,"id_str":"1722048995708928","order_type":0,"datetime":"1709257093","microtimestamp":"1709257092750000","amount":0.01630746,"amount_str":"0.01630746","amount_traded":"0","amount_at_create":"0.01630746","price":61321,"price_str":"61321"},"channel":"live_orders_btcusd","event":"order_created"}
{"data":{"id":1722048995708929,"id_str":"1722048995708929","order_type":1,"datetime":"1709257093","microtimestamp":"1709257092750000","amount":0.01630572,"amount_str":"0.01630572","amount_traded":"0","amount_at_create":"0.01630572","price":61329,"price_str":"61329"},"channel":"live_orders_btcusd","event":"order_created"}
{"data":{"id":1722048995717120,"id_str":"1722048995717120","order_type":1,"datetime":"1709257093","microtimestamp":"1709257092752000","amount":0.48915425,"amount_str":"0.48915425","amount_traded":"0","amount_at_create":"0.48915425","price":61331,"price_str":"61331"},"channel":"live_orders_btcusd","event":"order_created"}
{"data":{"id":1722048995704832,"id_str":"1722048995704832","order_type":0,"datetime":"1709257093","microtimestamp":"1709257092800000","amount":0.48924119,"amount_str":"0.48924119","amount_traded":"0","amount_at_create":"0.48924119","price":61319,"price_str":"61319"},"channel":"live_orders_btcusd","event":"order_deleted"}
{"data":{"id":1722048995708928,"id_str":"1722048995708928","order_type":0,"datetime":"1709257093","microtimestamp":"1709257092800000","amount":0.01630746,"amount_str":"0.01630746","amount_traded":"0","amount_at_create":"0.01630746","price":61321,"price_str":"61321"},"channel":"live_orders_btcusd","event":"order_deleted"}
{"data":{"id":1722048993984512,"id_str":"1722048993984512","order_type":0,"datetime":"1709257093","microtimestamp":"1709257092830000","amount":0.00133155,"amount_str":"0.00133155","amount_traded":"0","amount_at_create":"0.00133155","price":61324,"price_str":"61324"},"channel":"live_orders_btcusd","event":"order_deleted"}
{"data":{"id":1722048995393536,"id_str":"1722048995393536","order_type":0,"datetime":"1709257093","microtimestamp":"1709257092871000","amount":0.00040756,"amount_str":"0.00040756","amount_traded":"0","amount_at_create":"0.00040756","price":61316,"price_str":"61316"},"channel":"live_orders_btcusd","event":"order_deleted"}
{"data":{"id":1722048954187780,"id_str":"1722048954187780","order_type":1,"datetime":"1709257093","microtimestamp":"1709257092904000","amount":0.93133633,"amount_str":"0.93133633","amount_traded":"0","amount_at_create":"0.93133633","price":61386,"price_str":"61386"},"channel":"live_orders_btcusd","event":"order_deleted"}
{"data":{"id":1722048996425729,"id_str":"1722048996425729","order_type":0,"datetime":"1709257093","microtimestamp":"1709257092926000","amount":0.00133155,"amount_str":"0.00133155","amount_traded":"0","amount_at_create":"0.00133155","price":61320,"price_str":"61320"},"channel":"live_orders_btcusd","event":"order_created"}
{"data":{"id":1722048996503552,"id_str":"1722048996503552","order_type":1,"datetime":"1709257093","microtimestamp":"1709257092944000","amount":0.93147957,"amount_str":"0.93147957","amount_traded":"0","amount_at_create":"0.93147957","price":61375,"price_str":"61375"},"channel":"live_orders_btcusd","event":"order_created"}
{"data":{"id":1722048996585474,"id_str":"1722048996585474","order_type":0,"datetime":"1709257093","microtimestamp":"1709257092964000","amount":0.00040756,"amount_str":"0.00040756","amount_traded":"0","amount_at_create":"0.00040756","price":61316,"price_str":"61316"},"channel":"live_orders_btcusd","event":"order_created"}
{"data":{"id":1722048984285185,"id_str":"1722048984285185","order_type":1,"datetime":"1709257093","microtimestamp":"1709257093023000","amount":0.24459646,"amount_str":"0.24459646","amount_traded":"0","amount_at_create":"0.24459646","price":61327,"price_str":"61327"},"channel":"live_orders_btcusd","event":"order_deleted"}
{"data":{"id":1722048996855810,"id_str":"1722048996855810","order_type":1,"datetime":"1709257093","microtimestamp":"1709257093030000","amount":0.4886111,"amount_str":"0.48861110","amount_traded":"0","amount_at_create":"0.48861110","price":61399,"price_str":"61399"},"channel":"live_orders_btcusd","event":"order_created"}
{"data":{"id":1722048996859907,"id_str":"1722048996859907","order_type":0,"datetime":"1709257093","microtimestamp":"1709257093032000","amount":0.48975725,"amount_str":"0.48975725","amount_traded":"0","amount_at_create":"0.48975725","price":61254,"price_str":"61254"},"channel":"live_orders_btcusd","event":"order_created"}
{"data":{"id":1722048996864000,"id_str":"1722048996864000","order_type":0,"datetime":"1709257093","microtimestamp":"1709257093032000","amount":0.01630789,"amount_str":"0.01630789","amount_traded":"0","amount_at_create":"0.01630789","price":61320,"price_str":"61320"},"channel":"live_orders_btcusd","event":"order_created"}
{"data":{"id":1722048996864001,"id_str":"1722048996864001","order_type":0,"datetime":"1709257093","microtimestamp":"1709257093032000","amount":0.48923541,"amount_str":"0.48923541","amount_traded":"0","amount_at_create":"0.48923541","price":61320,"price_str":"61320"},"channel":"live_orders_btcusd","event":"order_created"}
{"data":{"id":1722048996864000,"id_str":"1722048996864000","order_type":0,"datetime":"1709257093","microtimestamp":"1709257093048000","amount":0.01630789,"amount_str":"0.01630789","amount_traded":"0","amount_at_create":"0.01630789","price":61320,"price_str":"61320"},"channel":"live_orders_btcusd","event":"order_deleted"}
{"data":{"id":1722048951115778,"id_str":"1722048951115778","order_type":1,"datetime":"1709257093","microtimestamp":"1709257093052000","amount":0.1875,"amount_str":"0.18750000","amount_traded":"0","amount_at_create":"0.18750000","price":61701,"price_str":"61701"},"channel":"live_orders_btcusd","event":"order_deleted"}
{"data":{"id":1722048997146625,"id_str":"1722048997146625","order_type":1,"datetime":"1709257093","microtimestamp":"1709257093102000","amount":0.1875,"amount_str":"0.18750000","amount_traded":"0","amount_at_create":"0.18750000","price":61343,"price_str":"61343"},"channel":"live_orders_btcusd","event":"order_created"}
{"data":{"id":1722048996425729,"id_str":"1722048996425729","order_type":0,"datetime":"1709257093","microtimestamp":"1709257093104000","amount":0.00133155,"amount_str":"0.00133155","amount_traded":"0","amount_at_create":"0.00133155","price":61320,"price_str":"61320"},"channel":"live_orders_btcusd","event":"order_deleted"}
{"data":{"id":1722048996585474,"id_str":"1722048996585474","order_type":0,"datetime":"1709257093","microtimestamp":"1709257093144000","amount":0.00040756,"amount_str":"0.00040756","amount_traded":"0","amount_at_create":"0.00040756","price":61316,"price_str":"61316"},"channel":"live_orders_btcusd","event":"order_deleted"}
{"data":{"id":1722048988336129,"id_str":"1722048988336129","order_type":0,"datetime":"1709257093","microtimestamp":"1709257093152000","amount":0.48926025,"amount_str":"0.48926025","amount_traded":"0","amount_at_create":"0.48926025","price":61317,"price_str":"61317"},"channel":"live_orders_btcusd","event":"order_deleted"}
{"data":{"id":1722048995708929,"id_str":"1722048995708929","order_type":1,"datetime":"1709257093","microtimestamp":"1709257093153000","amount":0.01630572,"amount_str":"0.01630572","amount_traded":"0","amount_at_create":"0.01630572","price":61329,"price_str":"61329"},"channel":"live_orders_btcusd","event":"order_deleted"}
{"data":{"id":1722048995717120,"id_str":"1722048995717120","order_type":1,"datetime":"1709257093","microtimestamp":"1709257093153000","amount":0.48915425,"amount_str":"0.48915425","amount_traded":"0","amount_at_create":"0.48915425","price":61331,"price_str":"61331"},"channel":"live_orders_btcusd","event":"order_deleted"}
{"data":{"id":1722048997416962,"id_str":"1722048997416962","order_type":0,"datetime":"1709257093","microtimestamp":"1709257093167000","amount":0.5,"amount_str":"0.50000000","amount_traded":"0","amount_at_create":"0.50000000","price":61192,"price_str":"61192"},"channel":"live_orders_btcusd","event":"order_created"}
{"data":{"id":1722048997474304,"id_str":"1722048997474304","order_type":0,"datetime":"1709257093","microtimestamp":"1709257093181000","amount":0.01630738,"amount_str":"0.01630738","amount_traded":"0","amount_at_create":"0.01630738","price":61321,"price_str":"61321"},"channel":"live_orders_btcusd","event":"order_created"}
{"data":{"id":1722048997560323,"id_str":"1722048997560323","order_type":0,"datetime":"1709257093","microtimestamp":"1709257093203000","amount":0.00040756,"amount_str":"0.00040756","amount_traded":"0","amount_at_create":"0.00040756","price":61317,"price_str":"61317"},"channel":"live_orders_btcusd","event":"order_created"}
{"data":{"id":1722048997474304,"id_str":"1722048997474304","order_type":0,"datetime":"1709257093","microtimestamp":"1709257093206000","amount":0.01630738,"amount_str":"0.01630738","amount_traded":"0","amount_at_create":"0.01630738","price":61321,"price_str":"61321"},"channel":"live_orders_btcusd","event":"order_deleted"}
{"data":{"id":1722048994820096,"id_str":"1722048994820096","order_type":1,"datetime":"1709257093","microtimestamp":"1709257093206000","amount":0.48893439,"amount_str":"0.48893439","amount_traded":"0","amount_at_create":"0.48893439","price":61358,"price_str":"61358"},"channel":"live_orders_btcusd","event":"order_deleted"}
{"data":{"id":1722048988327937,"id_str":"1722048988327937","order_type":1,"datetime":"1709257093","microtimestamp":"1709257093206000","amount":0.48911892,"amount_str":"0.48911892","amount_traded":"0","amount_at_create":"0.48911892","price":61335,"price_str":"61335"},"channel":"live_orders_btcusd","event":"order_deleted"}
{"data":{"id":1722048996864001,"id_str":"1722048996864001","order_type":0,"datetime":"1709257093","microtimestamp":"1709257093206000","amount":0.48923541,"amount_str":"0.48923541","amount_traded":"0","amount_at_create":"0.48923541","price":61320,"price_str":"61320"},"channel":"live_orders_btcusd","event":"order_deleted"}
{"data":{"id":1722048997695489,"id_str":"1722048997695489","order_type":1,"datetime":"1709257093","microtimestamp":"1709257093235000","amount":0.48915752,"amount_str":"0.48915752","amount_traded":"0","amount_at_create":"0.48915752","price":61330,"price_str":"61330"},"channel":"live_orders_btcusd","event":"order_created"}
{"data":{"id":1722048997699584,"id_str":"1722048997699584","order_type":0,"datetime":"1709257093","microtimestamp":"1709257093236000","amount":0.48927688,"amount_str":"0.48927688","amount_traded":"0","amount_at_create":"0.48927688","price":61314,"price_str":"61314"},"channel":"live_orders_btcusd","event":"order_created"}
{"data":{"id":1722048997699586,"id_str":"1722048997699586","order_type":1,"datetime":"1709257093","microtimestamp":"1709257093236000","amount":0.01630582,"amount_str":"0.01630582","amount_traded":"0","amount_at_create":"0.01630582","price":61328,"price_str":"61328"},"channel":"live_orders_btcusd","event":"order_created"}
{"data":{"id":1722048997695489,"id_str":"1722048997695489","order_type":1,"datetime":"1709257093","microtimestamp":"1709257093251000","amount":0.48915752,"amount_str":"0.48915752","amount_traded":"0","amount_at_create":"0.48915752","price":61330,"price_str":"61330"},"channel":"live_orders_btcusd","event":"order_deleted"}
{"data":{"id":1722048997699586,"id_str":"1722048997699586","order_type":1,"datetime":"1709257093","microtimestamp":"1709257093252000","amount":0.01630582,"amount_str":"0.01630582","amount_traded":"0","amount_at_create":"0.01630582","price":61328,"price_str":"61328"},"channel":"live_orders_btcusd","event":"order_deleted"}
{"data":{"id":1722048997560323,"id_str":"1722048997560323","order_type":0,"datetime":"1709257093","microtimestamp":"1709257093279000","amount":0.00040756,"amount_str":"0.00040756","amount_traded":"0","amount_at_create":"0.00040756","price":61317,"price_str":"61317"},"channel":"live_orders_btcusd","event":"order_deleted"}
{"data":{"id":1722048997953540,"id_str":"1722048997953540","order_type":1,"datetime":"1709257093","microtimestamp":"1709257093299000","amount":0.48913941,"amount_str":"0.48913941","amount_traded":"0","amount_at_create":"0.48913941","price":61333,"price_str":"61333"},"channel":"live_orders_btcusd","event":"order_created"}
{"data":{"id":1722048997957632,"id_str":"1722048997957632","order_type":0,"datetime":"1709257093","microtimestamp":"1709257093299000","amount":0.01630804,"amount_str":"0.01630804","amount_traded":"0","amount_at_create":"0.01630804","price":61319,"price_str":"61319"},"channel":"live_orders_btcusd","event":"order_created"}
{"data":{"id":1722048997961730,"id_str":"1722048997961730","order_type":0,"datetime":"1709257093","microtimestamp":"1709257093300000","amount":0.48925876,"amount_str":"0.48925876","amount_traded":"0","amount_at_create":"0.48925876","price":61317,"price_str":"61317"},"channel":"live_orders_btcusd","event":"order_created"}
{"data":{"id":1722048998068224,"id_str":"1722048998068224","order_type":0,"datetime":"1709257093","microtimestamp":"1709257093326000","amount":0.00093255,"amount_str":"0.00093255","amount_traded":"0","amount_at_create":"0.00093255","price":61320,"price_str":"61320"},"channel":"live_orders_btcusd","event":"order_created"}
{"data":{"id":1722048981610500,"id_str":"1722048981610500","order_type":0,"datetime":"1709257093","microtimestamp":"1709257093332000","amount":0.1875,"amount_str":"0.18750000","amount_traded":"0","amount_at_create":"0.18750000","price":61310,"price_str":"61310"},"channel":"live_orders_btcusd","event":"order_deleted"}
{"data":{"id":1722048998146052,"id_str":"1722048998146052","order_type":1,"datetime":"1709257093","microtimestamp":"1709257093346000","amount":0.01630629,"amount_str":"0.01630629","amount_traded":"0","amount_at_create":"0.01630629","price":61326,"price_str":"61326"},"channel":"live_orders_btcusd","event":"order_created"}
{"data":{"id":1722048998359041,"id_str":"1722048998359041","order_type":0,"datetime":"1709257093","microtimestamp":"1709257093397000","amount":0.00040756,"amount_str":"0.00040756","amount_traded":"0","amount_at_create":"0.00040756","price":61316,"price_str":"61316"},"channel":"live_orders_btcusd","event":"order_created"}
{"data":{"id":1722048997699584,"id_str":"1722048997699584","order_type":0,"datetime":"1709257093","microtimestamp":"1709257093400000","amount":0.48927688,"amount_str":"0.48927688","amount_traded":"0","amount_at_create":"0.48927688","price":61314,"price_str":"61314"},"channel":"live_orders_btcusd","event":"order_deleted"}
{"data":{"id":1722048998146052,"id_str":"1722048998146052","order_type":1,"datetime":"1709257093","microtimestamp":"1709257093400000","amount":0.01630629,"amount_str":"0.01630629","amount_traded":"0","amount_at_create":"0.01630629","price":61326,"price_str":"61326"},"channel":"live_orders_btcusd","event":"order_deleted"}
{"data":{"id":1722048997961730,"id_str":"1722048997961730","order_type":0,"datetime":"1709257093","microtimestamp":"1709257093410000","amount":0.48925876,"amount_str":"0.48925876","amount_traded":"0","amount_at_create":"0.48925876","price":61317,"price_str":"61317"},"channel":"live_orders_btcusd","event":"order_deleted"}
{"data":{"id":1722048997953540,"id_str":"1722048997953540","order_type":1,"datetime":"1709257093","microtimestamp":"1709257093443000","amount":0.48913941,"amount_str":"0.48913941","amount_traded":"0","amount_at_create":"0.48913941","price":61333,"price_str":"61333"},"channel":"live_orders_btcusd","event":"order_deleted"}
{"data":{"id":1722048998580227,"id_str":"1722048998580227","order_type":1,"datetime":"1709257093","microtimestamp":"1709257093451000","amount":0.0163066,"amount_str":"0.01630660","amount_traded":"0","amount_at_create":"0.01630660","price":61325,"price_str":"61325"},"channel":"live_orders_btcusd","event":"order_created"}
{"data":{"id":1722048982568960,"id_str":"1722048982568960","order_type":1,"datetime":"1709257093","microtimestamp":"1709257093471000","amount":0.00487283,"amount_str":"0.00487283","amount_traded":"0","amount_at_create":"0.00487283","price":61335,"price_str":"61335"},"channel":"live_orders_btcusd","event":"order_deleted"}
{"data":{"id":1722048998727680,"id_str":"1722048998727680","order_type":1,"datetime":"1709257093","microtimestamp":"1709257093487000","amount":0.00487268,"amount_str":"0.00487268","amount_traded":"0","amount_at_create":"0.00487268","price":61337,"price_str":"61337"},"channel":"live_orders_btcusd","event":"order_created"}
{"data":{"id":1722048981565442,"id_str":"1722048981565442","order_type":1,"datetime":"1709257093","microtimestamp":"1709257093494000","amount":0.00487224,"amount_str":"0.00487224","amount_traded":"0","amount_at_create":"0.00487224","price":61340,"price_str":"61340"},"channel":"live_orders_btcusd","event":"order_deleted"}
{"data":{"id":1722048998760448,"id_str":"1722048998760448","order_type":1,"datetime":"1709257093","microtimestamp":"1709257093495000","amount":0.48914106,"amount_str":"0.48914106","amount_traded":"0","amount_at_create":"0.48914106","price":61332,"price_str":"61332"},"channel":"live_orders_btcusd","event":"order_created"}
{"data":{"id":1722048998940672,"id_str":"1722048998940672","order_type":0,"datetime":"1709257094","microtimestamp":"1709257093539000","amount":0.48927011,"amount_str":"0.48927011","amount_traded":"0","amount_at_create":"0.48927011","price":61315,"price_str":"61315"},"channel":"live_orders_btcusd","event":"order_created"}
{"data":{"id":1722048998940672,"id_str":"1722048998940672","order_type":0,"datetime":"1709257094","microtimestamp":"1709257093597000","amount":0.48927011,"amount_str":"0.48927011","amount_traded":"0","amount_at_create":"0.48927011","price":61315,"price_str":"61315"},"channel":"live_orders_btcusd","event":"order_deleted"}
{"data":{"id":1722048998359041,"id_str":"1722048998359041","order_type":0,"datetime":"1709257094","microtimestamp":"1709257093605000","amount":0.00040756,"amount_str":"0.00040756","amount_traded":"0","amount_at_create":"0.00040756","price":61316,"price_str":"61316"},"channel":"live_orders_btcusd","event":"order_deleted"}
{"data":{"id":1722048998580227,"id_str":"1722048998580227","order_type":1,"datetime":"1709257094","microtimestamp":"1709257093738000","amount":0.0163066,"amount_str":"0.01630660","amount_traded":"0","amount_at_create":"0.01630660","price":61325,"price_str":"61325"},"channel":"live_orders_btcusd","event":"order_deleted"}
{"data":{"id":1722048999948288,"id_str":"1722048999948288","order_type":1,"datetime":"1709257094","microtimestamp":"1709257093785000","amount":0.48916759,"amount_str":"0.48916759","amount_traded":"0","amount_at_create":"0.48916759","price":61329,"price_str":"61329"},"channel":"live_orders_btcusd","event":"order_created"}
{"data":{"id":1722048999952385,"id_str":"1722048999952385","order_type":0,"datetime":"1709257094","microtimestamp":"1709257093786000","amount":0.48925724,"amount_str":"0.48925724","amount_traded":"0","amount_at_create":"0.48925724","price":61317,"price_str":"61317"},"channel":"live_orders_btcusd","event":"order_created"}
{"data":{"id":1722048999956480,"id_str":"1722048999956480","order_type":0,"datetime":"1709257094","microtimestamp":"1709257093787000","amount":0.48930017,"amount_str":"0.48930017","amount_traded":"0","amount_at_create":"0.48930017","price":61312,"price_str":"61312"},"channel":"live_orders_btcusd","event":"order_created"}
{"data":{"id":1722048999956481,"id_str":"1722048999956481","order_type":1,"datetime":"1709257094","microtimestamp":"1709257093788000","amount":0.01630616,"amount_str":"0.01630616","amount_traded":"0","amount_at_create":"0.01630616","price":61327,"price_str":"61327"},"channel":"live_orders_btcusd","event":"order_created"}
{"data":{"id":1722049000013825,"id_str":"1722049000013825","order_type":0,"datetime":"1709257094","microtimestamp":"1709257093802000","amount":0.00040756,"amount_str":"0.00040756","amount_traded":"0","amount_at_create":"0.00040756","price":61317,"price_str":"61317"},"channel":"live_orders_btcusd","event":"order_created"}
{"data":{"id":1722048997416962,"id_str":"1722048997416962","order_type":0,"datetime":"1709257094","microtimestamp":"1709257093835000","amount":0.5,"amount_str":"0.50000000","amount_traded":"0","amount_at_create":"0.50000000","price":61192,"price_str":"61192"},"channel":"live_orders_btcusd","event":"order_deleted"}
{"data":{"id":1722048982474753,"id_str":"1722048982474753","order_type":0,"datetime":"1709257094","microtimestamp":"1709257093888000","amount":0.04893,"amount_str":"0.04893000","amount_traded":"0","amount_at_create":"0.04893000","price":61301,"price_str":"61301"},"channel":"live_orders_btcusd","event":"order_deleted"}
{"data":{"id":1722049000468480,"id_str":"1722049000468480","order_type":1,"datetime":"1709257094","microtimestamp":"1709257093912000","amount":0.00487295,"amount_str":"0.00487295","amount_traded":"0","amount_at_create":"0.00487295","price":61334,"price_str":"61334"},"channel":"live_orders_btcusd","event":"order_created"}
{"data":{"id":1722048988528642,"id_str":"1722048988528642","order_type":0,"datetime":"1709257094","microtimestamp":"1709257093915000","amount":0.48954088,"amount_str":"0.48954088","amount_traded":"0","amount_at_create":"0.48954088","price":61281,"price_str":"61281"},"channel":"live_orders_btcusd","event":"order_deleted"}
{"data":{"id":1722048986206209,"id_str":"1722048986206209","order_type":0,"datetime":"1709257094","microtimestamp":"1709257093915000","amount":0.48933635,"amount_str":"0.48933635","amount_traded":"0","amount_at_create":"0.48933635","price":61307,"price_str":"61307"},"channel":"live_orders_btcusd","event":"order_deleted"}
{"data":{"id":1722048996855810,"id_str":"1722048996855810","order_type":1,"datetime":"1709257094","microtimestamp":"1709257093915000","amount":0.4886111,"amount_str":"0.48861110","amount_traded":"0","amount_at_create":"0.48861110","price":61399,"price_str":"61399"},"channel":"live_orders_btcusd","event":"order_deleted"}
{"data":{"id":1722048999956481,"id_str":"1722048999956481","order_type":1,"datetime":"1709257094","microtimestamp":"1709257093915000","amount":0.01630616,"amount_str":"0.01630616","amount_traded":"0","amount_at_create":"0.01630616","price":61327,"price_str":"61327"},"channel":"live_orders_btcusd","event":"order_deleted"}
{"data":{"id":1722048994820098,"id_str":"1722048994820098","order_type":0,"datetime":"1709257094","microtimestamp":"1709257093915000","amount":0.489443,"amount_str":"0.48944300","amount_traded":"0","amount_at_create":"0.48944300","price":61294,"price_str":"61294"},"channel":"live_orders_btcusd","event":"order_deleted"}
{"data":{"id":1722048991121408,"id_str":"1722048991121408","order_type":1,"datetime":"1709257094","microtimestamp":"1709257093916000","amount":0.48883628,"amount_str":"0.48883628","amount_traded":"0","amount_at_create":"0.48883628","price":61371,"price_str":"61371"},"channel":"live_orders_btcusd","event":"order_deleted"}
{"data":{"id":1722048986202112,"id_str":"1722048986202112","order_type":1,"datetime":"1709257094","microtimestamp":"1709257093916000","amount":0.4890693,"amount_str":"0.48906930","amount_traded":"0","amount_at_create":"0.48906930","price":61341,"price_str":"61341"},"channel":"live_orders_btcusd","event":"order_deleted"}
{"data":{"id":1722048999948288,"id_str":"1722048999948288","order_type":1,"datetime":"1709257094","microtimestamp":"1709257093916000","amount":0.48916759,"amount_str":"0.48916759","amount_traded":"0","amount_at_create":"0.48916759","price":61329,"price_str":"61329"},"channel":"live_orders_btcusd","event":"order_deleted"}
{"data":{"id":1722048999956480,"id_str":"1722048999956480","order_type":0,"datetime":"1709257094","microtimestamp":"1709257093916000","amount":0.48930017,"amount_str":"0.48930017","amount_traded":"0","amount_at_create":"0.48930017","price":61312,"price_str":"61312"},"channel":"live_orders_btcusd","event":"order_deleted"}
{"data":{"id":1722048999952385,"id_str":"1722048999952385","order_type":0,"datetime":"1709257094","microtimestamp":"1709257093916000","amount":0.48925724,"amount_str":"0.48925724","amount_traded":"0","amount_at_create":"0.48925724","price":61317,"price_str":"61317"},"channel":"live_orders_btcusd","event":"order_deleted"}
{"data":{"id":1722048997957632,"id_str":"1722048997957632","order_type":0,"datetime":"1709257094","microtimestamp":"1709257093917000","amount":0.01630804,"amount_str":"0.01630804","amount_traded":"0","amount_at_create":"0.01630804","price":61319,"price_str":"61319"},"channel":"live_orders_btcusd","event":"order_deleted"}
{"data":{"id":1722048998760448,"id_str":"1722048998760448","order_type":1,"datetime":"1709257094","microtimestamp":"1709257093918000","amount":0.48914106,"amount_str":"0.48914106","amount_traded":"0","amount_at_create":"0.48914106","price":61332,"price_str":"61332"},"channel":"live_orders_btcusd","event":"order_deleted"}
{"data":{"id":1722048982646784,"id_str":"1722048982646784","order_type":0,"datetime":"1709257094","microtimestamp":"1709257093919000","amount":0.00815328,"amount_str":"0.00815328","amount_traded":"0","amount_at_create":"0.00815328","price":61319,"price_str":"61319"},"channel":"live_orders_btcusd","event":"order_deleted"}
{"data":{"id":1722049000013825,"id_str":"1722049000013825","order_type":0,"datetime":"1709257094","microtimestamp":"1709257093936000","amount":0.00040756,"amount_str":"0.00040756","amount_traded":"0","amount_at_create":"0.00040756","price":61317,"price_str":"61317"},"channel":"live_orders_btcusd","event":"order_deleted"}
{"data":{"id":1722049000574976,"id_str":"1722049000574976","order_type":0,"datetime":"1709257094","microtimestamp":"1709257093938000","amount":0.00815348,"amount_str":"0.00815348","amount_traded":"0","amount_at_create":"0.00815348","price":61317,"price_str":"61317"},"channel":"live_orders_btcusd","event":"order_created"}
{"data":{"id":1722049000595457,"id_str":"1722049000595457","order_type":1,"datetime":"1709257094","microtimestamp":"1709257093944000","amount":0.40767339,"amount_str":"0.40767339","amount_traded":"0","amount_at_create":"0.40767339","price":61343,"price_str":"61343"},"channel":"live_orders_btcusd","event":"order_created"}
{"data":{"id":1722048981463041,"id_str":"1722048981463041","order_type":1,"datetime":"1709257094","microtimestamp":"1709257093947000","amount":0.09744407,"amount_str":"0.09744407","amount_traded":"0","amount_at_create":"0.09744407","price":61359,"price_str":"61359"},"channel":"live_orders_btcusd","event":"order_deleted"}
{"data":{"id":1722048936448002,"id_str":"1722048936448002","order_type":1,"datetime":"1709257094","microtimestamp":"1709257093963000","amount":0.40755111,"amount_str":"0.40755111","amount_traded":"0","amount_at_create":"0.40755111","price":61359,"price_str":"61359"},"channel":"live_orders_btcusd","event":"order_deleted"}
{"data":{"id":1722049000677379,"id_str":"1722049000677379","order_type":1,"datetime":"1709257094","microtimestamp":"1709257093963000","amount":0.09745917,"amount_str":"0.09745917","amount_traded":"0","amount_at_create":"0.09745917","price":61352,"price_str":"61352"},"channel":"live_orders_btcusd","event":"order_created"}
{"data":{"id":1722049000706048,"id_str":"1722049000706048","order_type":1,"datetime":"1709257094","microtimestamp":"1709257093970000","amount":0.48915782,"amount_str":"0.48915782","amount_traded":"0","amount_at_create":"0.48915782","price":61330,"price_str":"61330"},"channel":"live_orders_btcusd","event":"order_created"}
{"data":{"id":1722049000714242,"id_str":"1722049000714242","order_type":1,"datetime":"1709257094","microtimestamp":"1709257093972000","amount":0.01630708,"amount_str":"0.01630708","amount_traded":"0","amount_at_create":"0.01630708","price":61324,"price_str":"61324"},"channel":"live_orders_btcusd","event":"order_created"}
{"data":{"id":1722049000722433,"id_str":"1722049000722433","order_type":1,"datetime":"1709257094","microtimestamp":"1709257093974000","amount":0.4891024,"amount_str":"0.48910240","amount_traded":"0","amount_at_create":"0.48910240","price":61337,"price_str":"61337"},"channel":"live_orders_btcusd","event":"order_created"}
{"data":{"id":1722049000726528,"id_str":"1722049000726528","order_type":0,"datetime":"1709257094","microtimestamp":"1709257093975000","amount":0.48937817,"amount_str":"0.48937817","amount_traded":"0","amount_at_create":"0.48937817","price":61302,"price_str":"61302"},"channel":"live_orders_btcusd","event":"order_created"}
{"data":{"id":1722049000726529,"id_str":"1722049000726529","order_type":0,"datetime":"1709257094","microtimestamp":"1709257093975000","amount":0.01630889,"amount_str":"0.01630889","amount_traded":"0","amount_at_create":"0.01630889","price":61316,"price_str":"61316"},"channel":"live_orders_btcusd","event":"order_created"}
{"data":{"id":1722049000706048,"id_str":"1722049000706048","order_type":1,"datetime":"1709257094","microtimestamp":"1709257094019000","amount":0.48915782,"amount_str":"0.48915782","amount_traded":"0","amount_at_create":"0.48915782","price":61330,"price_str":"61330"},"channel":"live_orders_btcusd","event":"order_deleted"}
{"data":{"id":1722049000726528,"id_str":"1722049000726528","order_type":0,"datetime":"1709257094","microtimestamp":"1709257094019000","amount":0.48937817,"amount_str":"0.48937817","amount_traded":"0","amount_at_create":"0.48937817","price":61302,"price_str":"61302"},"channel":"live_orders_btcusd","event":"order_deleted"}
{"data":{"id":1722049000726529,"id_str":"1722049000726529","order_type":0,"datetime":"1709257094","microtimestamp":"1709257094019000","amount":0.01630889,"amount_str":"0.01630889","amount_traded":"0","amount_at_create":"0.01630889","price":61316,"price_str":"61316"},"channel":"live_orders_btcusd","event":"order_deleted"}
{"data":{"id":1722049000714242,"id_str":"1722049000714242","order_type":1,"datetime":"1709257094","microtimestamp":"1709257094020000","amount":0.01630708,"amount_str":"0.01630708","amount_traded":"0","amount_at_create":"0.01630708","price":61324,"price_str":"61324"},"channel":"live_orders_btcusd","event":"order_deleted"}
{"data":{"id":1722048985124864,"id_str":"1722048985124864","order_type":0,"datetime":"1709257094","microtimestamp":"1709257094020000","amount":0.06519737,"amount_str":"0.06519737","amount_traded":"0","amount_at_create":"0.06519737","price":61308,"price_str":"61308"},"channel":"live_orders_btcusd","event":"order_deleted"}
{"data":{"id":1722049000910851,"id_str":"1722049000910851","order_type":0,"datetime":"1709257094","microtimestamp":"1709257094021000","amount":0.489282,"amount_str":"0.48928200","amount_traded":"0","amount_at_create":"0.48928200","price":61314,"price_str":"61314"},"channel":"live_orders_btcusd","event":"order_created"}
{"data":{"id":1722049000914945,"id_str":"1722049000914945","order_type":1,"datetime":"1709257094","microtimestamp":"1709257094021000","amount":0.48919358,"amount_str":"0.48919358","amount_traded":"0","amount_at_create":"0.48919358","price":61326,"price_str":"61326"},"channel":"live_orders_btcusd","event":"order_created"}
{"data":{"id":1722049000923137,"id_str":"1722049000923137","order_type":0,"datetime":"1709257094","microtimestamp":"1709257094023000","amount":0.48959942,"amount_str":"0.48959942","amount_traded":"0","amount_at_create":"0.48959942","price":61274,"price_str":"61274"},"channel":"live_orders_btcusd","event":"order_created"}
{"data":{"id":1722048982499328,"id_str":"1722048982499328","order_type":1,"datetime":"1709257094","microtimestamp":"1709257094037000","amount":0.02075279,"amount_str":"0.02075279","amount_traded":"0","amount_at_create":"0.02075279","price":61347,"price_str":"61347"},"channel":"live_orders_btcusd","event":"order_deleted"}
{"data":{"id":1722049000914945,"id_str":"1722049000914945","order_type":1,"datetime":"1709257094","microtimestamp":"1709257094040000","amount":0.48919358,"amount_str":"0.48919358","amount_traded":"0","amount_at_create":"0.48919358","price":61326,"price_str":"61326"},"channel":"live_orders_btcusd","event":"order_deleted"}
{"data":{"id":1722048998068224,"id_str":"1722048998068224","order_type":0,"datetime":"1709257094","microtimestamp":"1709257094062000","amount":0.00093255,"amount_str":"0.00093255","amount_traded":"0","amount_at_create":"0.00093255","price":61320,"price_str":"61320"},"channel":"live_orders_btcusd","event":"order_deleted"}
{"data":{"id":1722048993505281,"id_str":"1722048993505281","order_type":0,"datetime":"1709257094","microtimestamp":"1709257094074000","amount":0.04875518,"amount_str":"0.04875518","amount_traded":"0","amount_at_create":"0.04875518","price":61301,"price_str":"61301"},"channel":"live_orders_btcusd","event":"order_deleted"}
{"data":{"id":1722049001168896,"id_str":"1722049001168896","order_type":1,"datetime":"1709257094","microtimestamp":"1709257094083000","amount":0.01630627,"amount_str":"0.01630627","amount_traded":"0","amount_at_create":"0.01630627","price":61327,"price_str":"61327"},"channel":"live_orders_btcusd","event":"order_created"}
{"data":{"id":1722049001181184,"id_str":"1722049001181184","order_type":0,"datetime":"1709257094","microtimestamp":"1709257094086000","amount":0.01630808,"amount_str":"0.01630808","amount_traded":"0","amount_at_create":"0.01630808","price":61319,"price_str":"61319"},"channel":"live_orders_btcusd","event":"order_created"}
{"data":{"id":1722049001181185,"id_str":"1722049001181185","order_type":0,"datetime":"1709257094","microtimestamp":"1709257094086000","amount":0.00040756,"amount_str":"0.00040756","amount_traded":"0","amount_at_create":"0.00040756","price":61316,"price_str":"61316"},"channel":"live_orders_btcusd","event":"order_created"}
{"data":{"id":1722048982175747,"id_str":"1722048982175747","order_type":1,"datetime":"1709257094","microtimestamp":"1709257094102000","amount":0.03062118,"amount_str":"0.03062118","amount_traded":"0","amount_at_create":"0.03062118","price":61347,"price_str":"61347"},"channel":"live_orders_btcusd","event":"order_deleted"}
{"data":{"id":1722049001275392,"id_str":"1722049001275392","order_type":0,"datetime":"1709257094","microtimestamp":"1709257094109000","amount":0.1875,"amount_str":"0.18750000","amount_traded":"0","amount_at_create":"0.18750000","price":61310,"price_str":"61310"},"channel":"live_orders_btcusd","event":"order_created"}
{"data":{"id":1722049001299968,"id_str":"1722049001299968","order_type":1,"datetime":"1709257094","microtimestamp":"1709257094116000","amount":0.03062118,"amount_str":"0.03062118","amount_traded":"0","amount_at_create":"0.03062118","price":61342,"price_str":"61342"},"channel":"live_orders_btcusd","event":"order_created"}
{"data":{"id":1722049001357312,"id_str":"1722049001357312","order_type":1,"datetime":"1709257094","microtimestamp":"1709257094129000","amount":0.02438514,"amount_str":"0.02438514","amount_traded":"0","amount_at_create":"0.02438514","price":61346,"price_str":"61346"},"channel":"live_orders_btcusd","event":"order_created"}
{"data":{"id":1722049001357313,"id_str":"1722049001357313","order_type":0,"datetime":"1709257094","microtimestamp":"1709257094129000","amount":0.00093267,"amount_str":"0.00093267","amount_traded":"0","amount_at_create":"0.00093267","price":61279,"price_str":"61279"},"channel":"live_orders_btcusd","event":"order_created"}
{"data":{"id":1722049001361411,"id_str":"1722049001361411","order_type":0,"datetime":"1709257094","microtimestamp":"1709257094131000","amount":0.04875518,"amount_str":"0.04875518","amount_traded":"0","amount_at_create":"0.04875518","price":61291,"price_str":"61291"},"channel":"live_orders_btcusd","event":"order_created"}
{"data":{"id":1722049001181185,"id_str":"1722049001181185","order_type":0,"datetime":"1709257094","microtimestamp":"1709257094216000","amount":0.00040756,"amount_str":"0.00040756","amount_traded":"0","amount_at_create":"0.00040756","price":61316,"price_str":"61316"},"channel":"live_orders_btcusd","event":"order_deleted"}
{"data":{"id":1722049001803777,"id_str":"1722049001803777","order_type":1,"datetime":"1709257094","microtimestamp":"1709257094238000","amount":0.48917107,"amount_str":"0.48917107","amount_traded":"0","amount_at_create":"0.48917107","price":61329,"price_str":"61329"},"channel":"live_orders_btcusd","event":"order_created"}
{"data":{"id":1722049001357312,"id_str":"1722049001357312","order_type":1,"datetime":"1709257094","microtimestamp":"1709257094240000","amount":0.02438514,"amount_str":"0.02438514","amount_traded":"0","amount_at_create":"0.02438514","price":61346,"price_str":"61346"},"channel":"live_orders_btcusd","event":"order_deleted"}
{"data":{"id":1722049001811973,"id_str":"1722049001811973","order_type":0,"datetime":"1709257094","microtimestamp":"1709257094241000","amount":0.48925995,"amount_str":"0.48925995","amount_traded":"0","amount_at_create":"0.48925995","price":61317,"price_str":"61317"},"channel":"live_orders_btcusd","event":"order_created"}
{"data":{"id":1722048687276032,"id_str":"1722048687276032","order_type":0,"datetime":"1709257094","microtimestamp":"1709257094252000","amount":0.1875,"amount_str":"0.18750000","amount_traded":"0","amount_at_create":"0.18750000","price":61149,"price_str":"61149"},"channel":"live_orders_btcusd","event":"order_deleted"}
{"data":{"id":1722048825470976,"id_str":"1722048825470976","order_type":1,"datetime":"1709257094","microtimestamp":"1709257094254000","amount":0.1875,"amount_str":"0.18750000","amount_traded":"0","amount_at_create":"0.18750000","price":61395,"price_str":"61395"},"channel":"live_orders_btcusd","event":"order_deleted"}
{"data":{"id":1722049001869313,"id_str":"1722049001869313","order_type":0,"datetime":"1709257094","microtimestamp":"1709257094254000","amount":0.04893,"amount_str":"0.04893000","amount_traded":"0","amount_at_create":"0.04893000","price":61298,"price_str":"61298"},"channel":"live_orders_btcusd","event":"order_created"}
{"data":{"id":1722049001992194,"id_str":"1722049001992194","order_type":0,"datetime":"1709257094","microtimestamp":"1709257094285000","amount":0.48931906,"amount_str":"0.48931906","amount_traded":"0","amount_at_create":"0.48931906","price":61309,"price_str":"61309"},"channel":"live_orders_btcusd","event":"order_created"}
{"data":{"id":1722049002045440,"id_str":"1722049002045440","order_type":1,"datetime":"1709257094","microtimestamp":"1709257094297000","amount":0.1875,"amount_str":"0.18750000","amount_traded":"0","amount_at_create":"0.18750000","price":61390,"price_str":"61390"},"channel":"live_orders_btcusd","event":"order_created"}
{"data":{"id":1722049001357313,"id_str":"1722049001357313","order_type":0,"datetime":"1709257094","microtimestamp":"1709257094305000","amount":0.00093267,"amount_str":"0.00093267","amount_traded":"0","amount_at_create":"0.00093267","price":61279,"price_str":"61279"},"channel":"live_orders_btcusd","event":"order_deleted"}
{"data":{"id":1722049001361411,"id_str":"1722049001361411","order_type":0,"datetime":"1709257094","microtimestamp":"1709257094320000","amount":0.04875518,"amount_str":"0.04875518","amount_traded":"0","amount_at_create":"0.04875518","price":61291,"price_str":"61291"},"channel":"live_orders_btcusd","event":"order_deleted"}
{"data":{"id":1722049002176512,"id_str":"1722049002176512","order_type":1,"datetime":"1709257094","microtimestamp":"1709257094329000","amount":0.02365137,"amount_str":"0.02365137","amount_traded":"0","amount_at_create":"0.02365137","price":61344,"price_str":"61344"},"channel":"live_orders_btcusd","event":"order_created"}
{"data":{"id":1722049001811973,"id_str":"1722049001811973","order_type":0,"datetime":"1709257094","microtimestamp":"1709257094397000","amount":0.48925995,"amount_str":"0.48925995","amount_traded":"0","amount_at_create":"0.48925995","price":61317,"price_str":"61317"},"channel":"live_orders_btcusd","event":"order_deleted"}
{"data":{"id":1722049001181184,"id_str":"1722049001181184","order_type":0,"datetime":"1709257094","microtimestamp":"1709257094398000","amount":0.01630808,"amount_str":"0.01630808","amount_traded":"0","amount_at_create":"0.01630808","price":61319,"price_str":"61319"},"channel":"live_orders_btcusd","event":"order_deleted"}
{"data":{"id":1722049000722433,"id_str":"1722049000722433","order_type":1,"datetime":"1709257094","microtimestamp":"1709257094399000","amount":0.4891024,"amount_str":"0.48910240","amount_traded":"0","amount_at_create":"0.48910240","price":61337,"price_str":"61337"},"channel":"live_orders_btcusd","event":"order_deleted"}
{"data":{"id":1722049002463234,"id_str":"1722049002463234","order_type":0,"datetime":"1709257094","microtimestamp":"1709257094400000","amount":0.00040756,"amount_str":"0.00040756","amount_traded":"0","amount_at_create":"0.00040756","price":61317,"price_str":"61317"},"channel":"live_orders_btcusd","event":"order_created"}
{"data":{"id":1722049000923137,"id_str":"1722049000923137","order_type":0,"datetime":"1709257094","microtimestamp":"1709257094408000","amount":0.48959942,"amount_str":"0.48959942","amount_traded":"0","amount_at_create":"0.48959942","price":61274,"price_str":"61274"},"channel":"live_orders_btcusd","event":"order_deleted"}
{"data":{"id":1722049002668032,"id_str":"1722049002668032","order_type":0,"datetime":"1709257094","microtimestamp":"1709257094450000","amount":0.00093267,"amount_str":"0.00093267","amount_traded":"0","amount_at_create":"0.00093267","price":61281,"price_str":"61281"},"channel":"live_orders_btcusd","event":"order_created"}
{"data":{"id":1722049002692611,"id_str":"1722049002692611","order_type":0,"datetime":"1709257094","microtimestamp":"1709257094455000","amount":0.01630765,"amount_str":"0.01630765","amount_traded":"0","amount_at_create":"0.01630765","price":61320,"price_str":"61320"},"channel":"live_orders_btcusd","event":"order_created"}
{"data":{"id":1722049002704899,"id_str":"1722049002704899","order_type":0,"datetime":"1709257094","microtimestamp":"1709257094458000","amount":0.48924997,"amount_str":"0.48924997","amount_traded":"0","amount_at_create":"0.48924997","price":61318,"price_str":"61318"},"channel":"live_orders_btcusd","event":"order_created"}
{"data":{"id":1722049002749953,"id_str":"1722049002749953","order_type":0,"datetime":"1709257094","microtimestamp":"1709257094470000","amount":0.0003183,"amount_str":"0.00031830","amount_traded":"0","amount_at_create":"0.00031830","price":999999999,"price_str":"999999999"},"channel":"live_orders_btcusd","event":"order_created"}
{"data":{"id":1722049002749953,"id_str":"1722049002749953","order_type":0,"datetime":"1709257094","microtimestamp":"1709257094470000","amount":0,"amount_str":"0","amount_traded":"0.00031830","amount_at_create":"0.00031830","price":61327,"price_str":"61327"},"channel":"live_orders_btcusd","event":"order_deleted"}
{"data":{"id":1722049001168896,"id_str":"1722049001168896","order_type":1,"datetime":"1709257094","microtimestamp":"1709257094470000","amount":0.01598797,"amount_str":"0.01598797","amount_traded":"0.00031830","amount_at_create":"0.01630627","price":61327,"price_str":"61327"},"channel":"live_orders_btcusd","event":"order_changed"}
{"data":{"id":1722049002704899,"id_str":"1722049002704899","order_type":0,"datetime":"1709257095","microtimestamp":"1709257094500000","amount":0.48924997,"amount_str":"0.48924997","amount_traded":"0","amount_at_create":"0.48924997","price":61318,"price_str":"61318"},"channel":"live_orders_btcusd","event":"order_deleted"}
{"data":{"id":1722049001992194,"id_str":"1722049001992194","order_type":0,"datetime":"1709257095","microtimestamp":"1709257094500000","amount":0.48931906,"amount_str":"0.48931906","amount_traded":"0","amount_at_create":"0.48931906","price":61309,"price_str":"61309"},"channel":"live_orders_btcusd","event":"order_deleted"}
{"data":{"id":1722049001803777,"id_str":"1722049001803777","order_type":1,"datetime":"1709257095","microtimestamp":"1709257094501000","amount":0.48917107,"amount_str":"0.48917107","amount_traded":"0","amount_at_create":"0.48917107","price":61329,"price_str":"61329"},"channel":"live_orders_btcusd","event":"order_deleted"}
{"data":{"id":1722049001168896,"id_str":"1722049001168896","order_type":1,"datetime":"1709257095","microtimestamp":"1709257094501000","amount":0.01598797,"amount_str":"0.01598797","amount_traded":"0","amount_at_create":"0.01630627","price":61327,"price_str":"61327"},"channel":"live_orders_btcusd","event":"order_deleted"}
{"data":{"id":1722049002692611,"id_str":"1722049002692611","order_type":0,"datetime":"1709257095","microtimestamp":"1709257094502000","amount":0.01630765,"amount_str":"0.01630765","amount_traded":"0","amount_at_create":"0.01630765","price":61320,"price_str":"61320"},"channel":"live_orders_btcusd","event":"order_deleted"}
{"data":{"id":1722049002885120,"id_str":"1722049002885120","order_type":1,"datetime":"1709257095","microtimestamp":"1709257094502000","amount":0.48913905,"amount_str":"0.48913905","amount_traded":"0","amount_at_create":"0.48913905","price":61333,"price_str":"61333"},"channel":"live_orders_btcusd","event":"order_created"}
{"data":{"id":1722049002668032,"id_str":"1722049002668032","order_type":0,"datetime":"1709257095","microtimestamp":"1709257094505000","amount":0.00093267,"amount_str":"0.00093267","amount_traded":"0","amount_at_create":"0.00093267","price":61281,"price_str":"61281"},"channel":"live_orders_btcusd","event":"order_deleted"}
{"data":{"id":1722048997146625,"id_str":"1722048997146625","order_type":1,"datetime":"1709257095","microtimestamp":"1709257094521000","amount":0.1875,"amount_str":"0.18750000","amount_traded":"0","amount_at_create":"0.18750000","price":61343,"price_str":"61343"},"channel":"live_orders_btcusd","event":"order_deleted"}
{"data":{"id":1722049003073539,"id_str":"1722049003073539","order_type":1,"datetime":"1709257095","microtimestamp":"1709257094550000","amount":0.48917618,"amount_str":"0.48917618","amount_traded":"0","amount_at_create":"0.48917618","price":61328,"price_str":"61328"},"channel":"live_orders_btcusd","event":"order_created"}
{"data":{"id":1722049003081729,"id_str":"1722049003081729","order_type":1,"datetime":"1709257095","microtimestamp":"1709257094550000","amount":0.48896704,"amount_str":"0.48896704","amount_traded":"0","amount_at_create":"0.48896704","price":61354,"price_str":"61354"},"channel":"live_orders_btcusd","event":"order_created"}
{"data":{"id":1722049003085824,"id_str":"1722049003085824","order_type":0,"datetime":"1709257095","microtimestamp":"1709257094551000","amount":0.48945873,"amount_str":"0.48945873","amount_traded":"0","amount_at_create":"0.48945873","price":61292,"price_str":"61292"},"channel":"live_orders_btcusd","event":"order_created"}
{"data":{"id":1722049002463234,"id_str":"1722049002463234","order_type":0,"datetime":"1709257095","microtimestamp":"1709257094577000","amount":0.00040756,"amount_str":"0.00040756","amount_traded":"0","amount_at_create":"0.00040756","price":61317,"price_str":"61317"},"channel":"live_orders_btcusd","event":"order_deleted"}
{"data":{"id":1722049003073539,"id_str":"1722049003073539","order_type":1,"datetime":"1709257095","microtimestamp":"1709257094598000","amount":0.48917618,"amount_str":"0.48917618","amount_traded":"0","amount_at_create":"0.48917618","price":61328,"price_str":"61328"},"channel":"live_orders_btcusd","event":"order_deleted"}
{"data":{"id":1722049003294721,"id_str":"1722049003294721","order_type":1,"datetime":"1709257095","microtimestamp":"1709257094603000","amount":0.1875,"amount_str":"0.18750000","amount_traded":"0","amount_at_create":"0.18750000","price":61342,"price_str":"61342"},"channel":"live_orders_btcusd","event":"order_created"}
{"data":{"id":1722049003454464,"id_str":"1722049003454464","order_type":1,"datetime":"1709257095","microtimestamp":"1709257094641000","amount":0.01630594,"amount_str":"0.01630594","amount_traded":"0","amount_at_create":"0.01630594","price":61328,"price_str":"61328"},"channel":"live_orders_btcusd","event":"order_created"}
{"data":{"id":1722049003458567,"id_str":"1722049003458567","order_type":1,"datetime":"1709257095","microtimestamp":"1709257094643000","amount":0.48888137,"amount_str":"0.48888137","amount_traded":"0","amount_at_create":"0.48888137","price":61365,"price_str":"61365"},"channel":"live_orders_btcusd","event":"order_created"}
{"data":{"id":1722049003474947,"id_str":"1722049003474947","order_type":0,"datetime":"1709257095","microtimestamp":"1709257094647000","amount":0.01630774,"amount_str":"0.01630774","amount_traded":"0","amount_at_create":"0.01630774","price":61320,"price_str":"61320"},"channel":"live_orders_btcusd","event":"order_created"}
{"data":{"id":1722049003294721,"id_str":"1722049003294721","order_type":1,"datetime":"1709257095","microtimestamp":"1709257094662000","amount":0.1875,"amount_str":"0.18750000","amount_traded":"0","amount_at_create":"0.18750000","price":61342,"price_str":"61342"},"channel":"live_orders_btcusd","event":"order_deleted"}
{"data":{"id":1722049003544577,"id_str":"1722049003544577","order_type":0,"datetime":"1709257095","microtimestamp":"1709257094664000","amount":0.00093265,"amount_str":"0.00093265","amount_traded":"0","amount_at_create":"0.00093265","price":61279,"price_str":"61279"},"channel":"live_orders_btcusd","event":"order_created"}
{"data":{"id":1722049003610112,"id_str":"1722049003610112","order_type":0,"datetime":"1709257095","microtimestamp":"1709257094679000","amount":0.00040756,"amount_str":"0.00040756","amount_traded":"0","amount_at_create":"0.00040756","price":61316,"price_str":"61316"},"channel":"live_orders_btcusd","event":"order_created"}
{"data":{"id":1722049003663361,"id_str":"1722049003663361","order_type":0,"datetime":"1709257095","microtimestamp":"1709257094693000","amount":0.48924968,"amount_str":"0.48924968","amount_traded":"0","amount_at_create":"0.48924968","price":61318,"price_str":"61318"},"channel":"live_orders_btcusd","event":"order_created"}
{"data":{"id":1722049003454464,"id_str":"1722049003454464","order_type":1,"datetime":"1709257095","microtimestamp":"1709257094700000","amount":0.01630594,"amount_str":"0.01630594","amount_traded":"0","amount_at_create":"0.01630594","price":61328,"price_str":"61328"},"channel":"live_orders_btcusd","event":"order_deleted"}
{"data":{"id":1722049003474947,"id_str":"1722049003474947","order_type":0,"datetime":"1709257095","microtimestamp":"1709257094701000","amount":0.01630774,"amount_str":"0.01630774","amount_traded":"0","amount_at_create":"0.01630774","price":61320,"price_str":"61320"},"channel":"live_orders_btcusd","event":"order_deleted"}
{"data":{"id":1722049003753473,"id_str":"1722049003753473","order_type":1,"datetime":"1709257095","microtimestamp":"1709257094714000","amount":0.1875,"amount_str":"0.18750000","amount_traded":"0","amount_at_create":"0.18750000","price":61342,"price_str":"61342"},"channel":"live_orders_btcusd","event":"order_created"}
{"data":{"id":1722049000468480,"id_str":"1722049000468480","order_type":1,"datetime":"1709257095","microtimestamp":"1709257094728000","amount":0.00487295,"amount_str":"0.00487295","amount_traded":"0","amount_at_create":"0.00487295","price":61334,"price_str":"61334"},"channel":"live_orders_btcusd","event":"order_deleted"}
{"data":{"id":1722049003753473,"id_str":"1722049003753473","order_type":1,"datetime":"1709257095","microtimestamp":"1709257094733000","amount":0.1875,"amount_str":"0.18750000","amount_traded":"0","amount_at_create":"0.18750000","price":61342,"price_str":"61342"},"channel":"live_orders_btcusd","event":"order_deleted"}
{"data":{"id":1722049003892736,"id_str":"1722049003892736","order_type":1,"datetime":"1709257095","microtimestamp":"1709257094748000","amount":0.01630609,"amount_str":"0.01630609","amount_traded":"0","amount_at_create":"0.01630609","price":61327,"price_str":"61327"},"channel":"live_orders_btcusd","event":"order_created"}
{"data":{"id":1722049003892737,"id_str":"1722049003892737","order_type":0,"datetime":"1709257095","microtimestamp":"1709257094749000","amount":0.01630789,"amount_str":"0.01630789","amount_traded":"0","amount_at_create":"0.01630789","price":61319,"price_str":"61319"},"channel":"live_orders_btcusd","event":"order_created"}
{"data":{"id":1722048963203073,"id_str":"1722048963203073","order_type":1,"datetime":"1709257095","microtimestamp":"1709257094750000","amount":0.00033,"amount_str":"0.00033000","amount_traded":"0","amount_at_create":"0.00033000","price":61412,"price_str":"61412"},"channel":"live_orders_btcusd","event":"order_deleted"}
{"data":{"id":1722049003937794,"id_str":"1722049003937794","order_type":0,"datetime":"1709257095","microtimestamp":"1709257094759000","amount":0.00815341,"amount_str":"0.00815341","amount_traded":"0","amount_at_create":"0.00815341","price":61320,"price_str":"61320"},"channel":"live_orders_btcusd","event":"order_created"}
{"data":{"id":1722049003610112,"id_str":"1722049003610112","order_type":0,"datetime":"1709257095","microtimestamp":"1709257094791000","amount":0.00040756,"amount_str":"0.00040756","amount_traded":"0","amount_at_create":"0.00040756","price":61316,"price_str":"61316"},"channel":"live_orders_btcusd","event":"order_deleted"}
{"data":{"id":1722049004081152,"id_str":"1722049004081152","order_type":1,"datetime":"1709257095","microtimestamp":"1709257094794000","amount":0.48916552,"amount_str":"0.48916552","amount_traded":"0","amount_at_create":"0.48916552","price":61329,"price_str":"61329"},"channel":"live_orders_btcusd","event":"order_created"}
{"data":{"id":1722049003892737,"id_str":"1722049003892737","order_type":0,"datetime":"1709257095","microtimestamp":"1709257094797000","amount":0.01630789,"amount_str":"0.01630789","amount_traded":"0","amount_at_create":"0.01630789","price":61319,"price_str":"61319"},"channel":"live_orders_btcusd","event":"order_deleted"}
{"data":{"id":1722049004187649,"id_str":"1722049004187649","order_type":0,"datetime":"1709257095","microtimestamp":"1709257094820000","amount":0.04875518,"amount_str":"0.04875518","amount_traded":"0","amount_at_create":"0.04875518","price":61299,"price_str":"61299"},"channel":"live_orders_btcusd","event":"order_created"}
{"data":{"id":1722049004191746,"id_str":"1722049004191746","order_type":1,"datetime":"1709257095","microtimestamp":"1709257094821000","amount":0.00033,"amount_str":"0.00033000","amount_traded":"0","amount_at_create":"0.00033000","price":61394,"price_str":"61394"},"channel":"live_orders_btcusd","event":"order_created"}
{"data":{"id":1722049003544577,"id_str":"1722049003544577","order_type":0,"datetime":"1709257095","microtimestamp":"1709257094831000","amount":0.00093265,"amount_str":"0.00093265","amount_traded":"0","amount_at_create":"0.00093265","price":61279,"price_str":"61279"},"channel":"live_orders_btcusd","event":"order_deleted"}
{"data":{"id":1722049004302338,"id_str":"1722049004302338","order_type":0,"datetime":"1709257095","microtimestamp":"1709257094849000","amount":0.0163077,"amount_str":"0.01630770","amount_traded":"0","amount_at_create":"0.01630770","price":61320,"price_str":"61320"},"channel":"live_orders_btcusd","event":"order_created"}
{"data":{"id":1722049004498945,"id_str":"1722049004498945","order_type":0,"datetime":"1709257095","microtimestamp":"1709257094897000","amount":0.00040756,"amount_str":"0.00040756","amount_traded":"0","amount_at_create":"0.00040756","price":61317,"price_str":"61317"},"channel":"live_orders_btcusd","event":"order_created"}
{"data":{"id":1722049004625920,"id_str":"1722049004625920","order_type":0,"datetime":"1709257095","microtimestamp":"1709257094927000","amount":0.00093267,"amount_str":"0.00093267","amount_traded":"0","amount_at_create":"0.00093267","price":61282,"price_str":"61282"},"channel":"live_orders_btcusd","event":"order_created"}
{"data":{"id":1722049004781569,"id_str":"1722049004781569","order_type":1,"datetime":"1709257095","microtimestamp":"1709257094966000","amount":0.00487295,"amount_str":"0.00487295","amount_traded":"0","amount_at_create":"0.00487295","price":61335,"price_str":"61335"},"channel":"live_orders_btcusd","event":"order_created"}
{"data":{"id":1722049004498945,"id_str":"1722049004498945","order_type":0,"datetime":"1709257095","microtimestamp":"1709257095023000","amount":0.00040756,"amount_str":"0.00040756","amount_traded":"0","amount_at_create":"0.00040756","price":61317,"price_str":"61317"},"channel":"live_orders_btcusd","event":"order_deleted"}
{"data":{"id":1722049005449219,"id_str":"1722049005449219","order_type":0,"datetime":"1709257095","microtimestamp":"1709257095129000","amount":0.48935563,"amount_str":"0.48935563","amount_traded":"0","amount_at_create":"0.48935563","price":61305,"price_str":"61305"},"channel":"live_orders_btcusd","event":"order_created"}
{"data":{"id":1722049005449220,"id_str":"1722049005449220","order_type":1,"datetime":"1709257095","microtimestamp":"1709257095129000","amount":0.48906998,"amount_str":"0.48906998","amount_traded":"0","amount_at_create":"0.48906998","price":61341,"price_str":"61341"},"channel":"live_orders_btcusd","event":"order_created"}
{"data":{"id":1722049005453312,"id_str":"1722049005453312","order_type":0,"datetime":"1709257095","microtimestamp":"1709257095129000","amount":0.16334956,"amount_str":"0.16334956","amount_traded":"0","amount_at_create":"0.16334956","price":61218,"price_str":"61218"},"channel":"live_orders_btcusd","event":"order_created"}
{"data":{"id":1722049005506563,"id_str":"1722049005506563","order_type":0,"datetime":"1709257095","microtimestamp":"1709257095143000","amount":0.06519852,"amount_str":"0.06519852","amount_traded":"0","amount_at_create":"0.06519852","price":61308,"price_str":"61308"},"channel":"live_orders_btcusd","event":"order_created"}
{"data":{"id":1722049006018560,"id_str":"1722049006018560","order_type":0,"datetime":"1709257095","microtimestamp":"1709257095267000","amount":0.00093267,"amount_str":"0.00093267","amount_traded":"0","amount_at_create":"0.00093267","price":61319,"price_str":"61319"},"channel":"live_orders_btcusd","event":"order_created"}
{"data":{"id":1722049003937794,"id_str":"1722049003937794","order_type":0,"datetime":"1709257095","microtimestamp":"1709257095275000","amount":0.00815341,"amount_str":"0.00815341","amount_traded":"0","amount_at_create":"0.00815341","price":61320,"price_str":"61320"},"channel":"live_orders_btcusd","event":"order_deleted"}
{"data":{"id":1722049006120962,"id_str":"1722049006120962","order_type":0,"datetime":"1709257095","microtimestamp":"1709257095292000","amount":0.00040756,"amount_str":"0.00040756","amount_traded":"0","amount_at_create":"0.00040756","price":61316,"price_str":"61316"},"channel":"live_orders_btcusd","event":"order_created"}
{"data":{"id":1722049004302338,"id_str":"1722049004302338","order_type":0,"datetime":"1709257095","microtimestamp":"1709257095305000","amount":0.0163077,"amount_str":"0.01630770","amount_traded":"0","amount_at_create":"0.01630770","price":61320,"price_str":"61320"},"channel":"live_orders_btcusd","event":"order_deleted"}
{"data":{"id":1722049004081152,"id_str":"1722049004081152","order_type":1,"datetime":"1709257095","microtimestamp":"1709257095305000","amount":0.48916552,"amount_str":"0.48916552","amount_traded":"0","amount_at_create":"0.48916552","price":61329,"price_str":"61329"},"channel":"live_orders_btcusd","event":"order_deleted"}
{"data":{"id":1722049003663361,"id_str":"1722049003663361","order_type":0,"datetime":"1709257095","microtimestamp":"1709257095306000","amount":0.48924968,"amount_str":"0.48924968","amount_traded":"0","amount_at_create":"0.48924968","price":61318,"price_str":"61318"},"channel":"live_orders_btcusd","event":"order_deleted"}
{"data":{"id":1722049003892736,"id_str":"1722049003892736","order_type":1,"datetime":"1709257095","microtimestamp":"1709257095306000","amount":0.01630609,"amount_str":"0.01630609","amount_traded":"0","amount_at_create":"0.01630609","price":61327,"price_str":"61327"},"channel":"live_orders_btcusd","event":"order_deleted"}
{"data":{"id":1722049006358529,"id_str":"1722049006358529","order_type":1,"datetime":"1709257095","microtimestamp":"1709257095351000","amount":0.4891737,"amount_str":"0.48917370","amount_traded":"0","amount_at_create":"0.48917370","price":61328,"price_str":"61328"},"channel":"live_orders_btcusd","event":"order_created"}
{"data":{"id":1722049006358530,"id_str":"1722049006358530","order_type":0,"datetime":"1709257095","microtimestamp":"1709257095351000","amount":0.01630816,"amount_str":"0.01630816","amount_traded":"0","amount_at_create":"0.01630816","price":61318,"price_str":"61318"},"channel":"live_orders_btcusd","event":"order_created"}
{"data":{"id":1722049006366720,"id_str":"1722049006366720","order_type":1,"datetime":"1709257095","microtimestamp":"1709257095352000","amount":0.01630636,"amount_str":"0.01630636","amount_traded":"0","amount_at_create":"0.01630636","price":61326,"price_str":"61326"},"channel":"live_orders_btcusd","event":"order_created"}
{"data":{"id":1722049006379010,"id_str":"1722049006379010","order_type":0,"datetime":"1709257095","microtimestamp":"1709257095356000","amount":0.48926201,"amount_str":"0.48926201","amount_traded":"0","amount_at_create":"0.48926201","price":61316,"price_str":"61316"},"channel":"live_orders_btcusd","event":"order_created"}
{"data":{"id":1722048938520579,"id_str":"1722048938520579","order_type":0,"datetime":"1709257095","microtimestamp":"1709257095368000","amount":0.0016245,"amount_str":"0.00162450","amount_traded":"0","amount_at_create":"0.00162450","price":58276,"price_str":"58276"},"channel":"live_orders_btcusd","event":"order_deleted"}
{"data":{"id":1722049004625920,"id_str":"1722049004625920","order_type":0,"datetime":"1709257095","microtimestamp":"1709257095420000","amount":0.00093267,"amount_str":"0.00093267","amount_traded":"0","amount_at_create":"0.00093267","price":61282,"price_str":"61282"},"channel":"live_orders_btcusd","event":"order_deleted"}
{"data":{"id":1722049006358530,"id_str":"1722049006358530","order_type":0,"datetime":"1709257095","microtimestamp":"1709257095421000","amount":0.01630816,"amount_str":"0.01630816","amount_traded":"0","amount_at_create":"0.01630816","price":61318,"price_str":"61318"},"channel":"live_orders_btcusd","event":"order_deleted"}
{"data":{"id":1722049006379010,"id_str":"1722049006379010","order_type":0,"datetime":"1709257095","microtimestamp":"1709257095422000","amount":0.48926201,"amount_str":"0.48926201","amount_traded":"0","amount_at_create":"0.48926201","price":61316,"price_str":"61316"},"channel":"live_orders_btcusd","event":"order_deleted"}
{"data":{"id":1722049006850048,"id_str":"1722049006850048","order_type":0,"datetime":"1709257095","microtimestamp":"1709257095470000","amount":0.01630808,"amount_str":"0.01630808","amount_traded":"0","amount_at_create":"0.01630808","price":61319,"price_str":"61319"},"channel":"live_orders_btcusd","event":"order_created"}
{"data":{"id":1722049005506563,"id_str":"1722049005506563","order_type":0,"datetime":"1709257096","microtimestamp":"1709257095509000","amount":0.06519852,"amount_str":"0.06519852","amount_traded":"0","amount_at_create":"0.06519852","price":61308,"price_str":"61308"},"channel":"live_orders_btcusd","event":"order_deleted"}
{"data":{"id":1722049007087617,"id_str":"1722049007087617","order_type":0,"datetime":"1709257096","microtimestamp":"1709257095529000","amount":0.00093268,"amount_str":"0.00093268","amount_traded":"0","amount_at_create":"0.00093268","price":61279,"price_str":"61279"},"channel":"live_orders_btcusd","event":"order_created"}
{"data":{"id":1722049006120962,"id_str":"1722049006120962","order_type":0,"datetime":"1709257096","microtimestamp":"1709257095612000","amount":0.00040756,"amount_str":"0.00040756","amount_traded":"0","amount_at_create":"0.00040756","price":61316,"price_str":"61316"},"channel":"live_orders_btcusd","event":"order_deleted"}
{"data":{"id":1722049008037888,"id_str":"1722049008037888","order_type":0,"datetime":"1709257096","microtimestamp":"1709257095761000","amount":0.00040756,"amount_str":"0.00040756","amount_traded":"0","amount_at_create":"0.00040756","price":61317,"price_str":"61317"},"channel":"live_orders_btcusd","event":"order_created"}
{"data":{"id":1722049008037888,"id_str":"1722049008037888","order_type":0,"datetime":"1709257096","microtimestamp":"1709257095891000","amount":0.00040756,"amount_str":"0.00040756","amount_traded":"0","amount_at_create":"0.00040756","price":61317,"price_str":"61317"},"channel":"live_orders_btcusd","event":"order_deleted"}
{"data":{"id":1722049008742400,"id_str":"1722049008742400","order_type":0,"datetime":"1709257096","microtimestamp":"1709257095932000","amount":0.48925986,"amount_str":"0.48925986","amount_traded":"0","amount_at_create":"0.48925986","price":61317,"price_str":"61317"},"channel":"live_orders_btcusd","event":"order_created"}
{"data":{"id":1722048998727680,"id_str":"1722048998727680","order_type":1,"datetime":"1709257096","microtimestamp":"1709257095983000","amount":0.00487268,"amount_str":"0.00487268","amount_traded":"0","amount_at_create":"0.00487268","price":61337,"price_str":"61337"},"channel":"live_orders_btcusd","event":"order_deleted"}
{"data":{"id":1722049008959488,"id_str":"1722049008959488","order_type":0,"datetime":"1709257096","microtimestamp":"1709257095985000","amount":0.00040756,"amount_str":"0.00040756","amount_traded":"0","amount_at_create":"0.00040756","price":61316,"price_str":"61316"},"channel":"live_orders_btcusd","event":"order_created"}
{"data":{"id":1722049009106944,"id_str":"1722049009106944","order_type":1,"datetime":"1709257096","microtimestamp":"1709257096021000","amount":0.00487303,"amount_str":"0.00487303","amount_traded":"0","amount_at_create":"0.00487303","price":61333,"price_str":"61333"},"channel":"live_orders_btcusd","event":"order_created"}
{"data":{"id":1722049007087617,"id_str":"1722049007087617","order_type":0,"datetime":"1709257096","microtimestamp":"1709257096039000","amount":0.00093268,"amount_str":"0.00093268","amount_traded":"0","amount_at_create":"0.00093268","price":61279,"price_str":"61279"},"channel":"live_orders_btcusd","event":"order_deleted"}
{"data":{"id":1722049008742400,"id_str":"1722049008742400","order_type":0,"datetime":"1709257096","microtimestamp":"1709257096104000","amount":0.48925986,"amount_str":"0.48925986","amount_traded":"0","amount_at_create":"0.48925986","price":61317,"price_str":"61317"},"channel":"live_orders_btcusd","event":"order_deleted"}
{"data":{"id":1722049006850048,"id_str":"1722049006850048","order_type":0,"datetime":"1709257096","microtimestamp":"1709257096104000","amount":0.01630808,"amount_str":"0.01630808","amount_traded":"0","amount_at_create":"0.01630808","price":61319,"price_str":"61319"},"channel":"live_orders_btcusd","event":"order_deleted"}
{"data":{"id":1722049006366720,"id_str":"1722049006366720","order_type":1,"datetime":"1709257096","microtimestamp":"1709257096105000","amount":0.01630636,"amount_str":"0.01630636","amount_traded":"0","amount_at_create":"0.01630636","price":61326,"price_str":"61326"},"channel":"live_orders_btcusd","event":"order_deleted"}
{"data":{"id":1722049006358529,"id_str":"1722049006358529","order_type":1,"datetime":"1709257096","microtimestamp":"1709257096106000","amount":0.4891737,"amount_str":"0.48917370","amount_traded":"0","amount_at_create":"0.48917370","price":61328,"price_str":"61328"},"channel":"live_orders_btcusd","event":"order_deleted"}
{"data":{"id":1722049009541122,"id_str":"1722049009541122","order_type":0,"datetime":"1709257096","microtimestamp":"1709257096127000","amount":0.00093268,"amount_str":"0.00093268","amount_traded":"0","amount_at_create":"0.00093268","price":61281,"price_str":"61281"},"channel":"live_orders_btcusd","event":"order_created"}
{"data":{"id":1722049009606657,"id_str":"1722049009606657","order_type":0,"datetime":"1709257096","microtimestamp":"1709257096144000","amount":0.06519874,"amount_str":"0.06519874","amount_traded":"0","amount_at_create":"0.06519874","price":61307,"price_str":"61307"},"channel":"live_orders_btcusd","event":"order_created"}
{"data":{"id":1722049009651712,"id_str":"1722049009651712","order_type":1,"datetime":"1709257096","microtimestamp":"1709257096154000","amount":0.48916314,"amount_str":"0.48916314","amount_traded":"0","amount_at_create":"0.48916314","price":61330,"price_str":"61330"},"channel":"live_orders_btcusd","event":"order_created"}
{"data":{"id":1722049009651715,"id_str":"1722049009651715","order_type":1,"datetime":"1709257096","microtimestamp":"1709257096154000","amount":0.01630601,"amount_str":"0.01630601","amount_traded":"0","amount_at_create":"0.01630601","price":61328,"price_str":"61328"},"channel":"live_orders_btcusd","event":"order_created"}
{"data":{"id":1722049009651717,"id_str":"1722049009651717","order_type":0,"datetime":"1709257096","microtimestamp":"1709257096155000","amount":0.4892508,"amount_str":"0.48925080","amount_traded":"0","amount_at_create":"0.48925080","price":61318,"price_str":"61318"},"channel":"live_orders_btcusd","event":"order_created"}
{"data":{"id":1722049009659906,"id_str":"1722049009659906","order_type":0,"datetime":"1709257096","microtimestamp":"1709257096156000","amount":0.01630778,"amount_str":"0.01630778","amount_traded":"0","amount_at_create":"0.01630778","price":61320,"price_str":"61320"},"channel":"live_orders_btcusd","event":"order_created"}
{"data":{"id":1722049008959488,"id_str":"1722049008959488","order_type":0,"datetime":"1709257096","microtimestamp":"1709257096166000","amount":0.00040756,"amount_str":"0.00040756","amount_traded":"0","amount_at_create":"0.00040756","price":61316,"price_str":"61316"},"channel":"live_orders_btcusd","event":"order_deleted"}
{"data":{"id":1722049009541122,"id_str":"1722049009541122","order_type":0,"datetime":"1709257096","microtimestamp":"1709257096237000","amount":0.00093268,"amount_str":"0.00093268","amount_traded":"0","amount_at_create":"0.00093268","price":61281,"price_str":"61281"},"channel":"live_orders_btcusd","event":"order_deleted"}
{"data":{"id":1722049010270211,"id_str":"1722049010270211","order_type":0,"datetime":"1709257096","microtimestamp":"1709257096305000","amount":0.00040756,"amount_str":"0.00040756","amount_traded":"0","amount_at_create":"0.00040756","price":61317,"price_str":"61317"},"channel":"live_orders_btcusd","event":"order_created"}
{"data":{"id":1722049010364416,"id_str":"1722049010364416","order_type":0,"datetime":"1709257096","microtimestamp":"1709257096328000","amount":0.00093265,"amount_str":"0.00093265","amount_traded":"0","amount_at_create":"0.00093265","price":61282,"price_str":"61282"},"channel":"live_orders_btcusd","event":"order_created"}
{"data":{"id":1722049010270211,"id_str":"1722049010270211","order_type":0,"datetime":"1709257096","microtimestamp":"1709257096423000","amount":0.00040756,"amount_str":"0.00040756","amount_traded":"0","amount_at_create":"0.00040756","price":61317,"price_str":"61317"},"channel":"live_orders_btcusd","event":"order_deleted"}
{"data":{"id":1722049011384321,"id_str":"1722049011384321","order_type":0,"datetime":"1709257097","microtimestamp":"1709257096577000","amount":0.00040756,"amount_str":"0.00040756","amount_traded":"0","amount_at_create":"0.00040756","price":61316,"price_str":"61316"},"channel":"live_orders_btcusd","event":"order_created"}
{"data":{"id":1722049009651715,"id_str":"1722049009651715","order_type":1,"datetime":"1709257097","microtimestamp":"1709257096602000","amount":0.01630601,"amount_str":"0.01630601","amount_traded":"0","amount_at_create":"0.01630601","price":61328,"price_str":"61328"},"channel":"live_orders_btcusd","event":"order_deleted"}
{"data":{"id":1722049011662851,"id_str":"1722049011662851","order_type":1,"datetime":"1709257097","microtimestamp":"1709257096650000","amount":0.01630606,"amount_str":"0.01630606","amount_traded":"0","amount_at_create":"0.01630606","price":61327,"price_str":"61327"},"channel":"live_orders_btcusd","event":"order_created"}
{"data":{"id":1722049011384321,"id_str":"1722049011384321","order_type":0,"datetime":"1709257097","microtimestamp":"1709257096731000","amount":0.00040756,"amount_str":"0.00040756","amount_traded":"0","amount_at_create":"0.00040756","price":61316,"price_str":"61316"},"channel":"live_orders_btcusd","event":"order_deleted"}
{"data":{"id":1722049012383744,"id_str":"1722049012383744","order_type":0,"datetime":"1709257097","microtimestamp":"1709257096821000","amount":0.00040756,"amount_str":"0.00040756","amount_traded":"0","amount_at_create":"0.00040756","price":61317,"price_str":"61317"},"channel":"live_orders_btcusd","event":"order_created"}
{"data":{"id":1722049012383744,"id_str":"1722049012383744","order_type":0,"datetime":"1709257097","microtimestamp":"1709257096875000","amount":0.00040756,"amount_str":"0.00040756","amount_traded":"0","amount_at_create":"0.00040756","price":61317,"price_str":"61317"},"channel":"live_orders_btcusd","event":"order_deleted"}
{"data":{"id":1722049012965376,"id_str":"1722049012965376","order_type":0,"datetime":"1709257097","microtimestamp":"1709257096963000","amount":0.00040756,"amount_str":"0.00040756","amount_traded":"0","amount_at_create":"0.00040756","price":61316,"price_str":"61316"},"channel":"live_orders_btcusd","event":"order_created"}
{"data":{"id":1722049012965376,"id_str":"1722049012965376","order_type":0,"datetime":"1709257097","microtimestamp":"1709257097063000","amount":0.00040756,"amount_str":"0.00040756","amount_traded":"0","amount_at_create":"0.00040756","price":61316,"price_str":"61316"},"channel":"live_orders_btcusd","event":"order_deleted"}
{"data":{"id":1722049009651717,"id_str":"1722049009651717","order_type":0,"datetime":"1709257097","microtimestamp":"1709257097097000","amount":0.4892508,"amount_str":"0.48925080","amount_traded":"0","amount_at_create":"0.48925080","price":61318,"price_str":"61318"},"channel":"live_orders_btcusd","event":"order_deleted"}
{"data":{"id":1722049009659906,"id_str":"1722049009659906","order_type":0,"datetime":"1709257097","microtimestamp":"1709257097098000","amount":0.01630778,"amount_str":"0.01630778","amount_traded":"0","amount_at_create":"0.01630778","price":61320,"price_str":"61320"},"channel":"live_orders_btcusd","event":"order_deleted"}
{"data":{"id":1722049011662851,"id_str":"1722049011662851","order_type":1,"datetime":"1709257097","microtimestamp":"1709257097099000","amount":0.01630606,"amount_str":"0.01630606","amount_traded":"0","amount_at_create":"0.01630606","price":61327,"price_str":"61327"},"channel":"live_orders_btcusd","event":"order_deleted"}
{"data":{"id":1722049013653504,"id_str":"1722049013653504","order_type":0,"datetime":"1709257097","microtimestamp":"1709257097131000","amount":0.00040756,"amount_str":"0.00040756","amount_traded":"0","amount_at_create":"0.00040756","price":61317,"price_str":"61317"},"channel":"live_orders_btcusd","event":"order_created"}
{"data":{"id":1722049013698563,"id_str":"1722049013698563","order_type":1,"datetime":"1709257097","microtimestamp":"1709257097143000","amount":0.01630564,"amount_str":"0.01630564","amount_traded":"0","amount_at_create":"0.01630564","price":61329,"price_str":"61329"},"channel":"live_orders_btcusd","event":"order_created"}
{"data":{"id":1722049013706753,"id_str":"1722049013706753","order_type":0,"datetime":"1709257097","microtimestamp":"1709257097145000","amount":0.48955912,"amount_str":"0.48955912","amount_traded":"0","amount_at_create":"0.48955912","price":61279,"price_str":"61279"},"channel":"live_orders_btcusd","event":"order_created"}
{"data":{"id":1722049013706754,"id_str":"1722049013706754","order_type":0,"datetime":"1709257097","microtimestamp":"1709257097145000","amount":0.01630742,"amount_str":"0.01630742","amount_traded":"0","amount_at_create":"0.01630742","price":61321,"price_str":"61321"},"channel":"live_orders_btcusd","event":"order_created"}
{"data":{"id":1722049013710848,"id_str":"1722049013710848","order_type":0,"datetime":"1709257097","microtimestamp":"1709257097145000","amount":0.48923979,"amount_str":"0.48923979","amount_traded":"0","amount_at_create":"0.48923979","price":61319,"price_str":"61319"},"channel":"live_orders_btcusd","event":"order_created"}
{"data":{"id":1722049013653504,"id_str":"1722049013653504","order_type":0,"datetime":"1709257097","microtimestamp":"1709257097159000","amount":0.00040756,"amount_str":"0.00040756","amount_traded":"0","amount_at_create":"0.00040756","price":61317,"price_str":"61317"},"channel":"live_orders_btcusd","event":"order_deleted"}
{"data":{"id":1722049013891073,"id_str":"1722049013891073","order_type":0,"datetime":"1709257097","microtimestamp":"1709257097189000","amount":0.00040756,"amount_str":"0.00040756","amount_traded":"0","amount_at_create":"0.00040756","price":61316,"price_str":"61316"},"channel":"live_orders_btcusd","event":"order_created"}
{"data":{"id":1722049013698563,"id_str":"1722049013698563","order_type":1,"datetime":"1709257097","microtimestamp":"1709257097198000","amount":0.01630564,"amount_str":"0.01630564","amount_traded":"0","amount_at_create":"0.01630564","price":61329,"price_str":"61329"},"channel":"live_orders_btcusd","event":"order_deleted"}
{"data":{"id":1722049009106944,"id_str":"1722049009106944","order_type":1,"datetime":"1709257097","microtimestamp":"1709257097234000","amount":0.00487303,"amount_str":"0.00487303","amount_traded":"0","amount_at_create":"0.00487303","price":61333,"price_str":"61333"},"channel":"live_orders_btcusd","event":"order_deleted"}
{"data":{"id":1722049010364416,"id_str":"1722049010364416","order_type":0,"datetime":"1709257097","microtimestamp":"1709257097236000","amount":0.00093265,"amount_str":"0.00093265","amount_traded":"0","amount_at_create":"0.00093265","price":61282,"price_str":"61282"},"channel":"live_orders_btcusd","event":"order_deleted"}
{"data":{"id":1722049006018560,"id_str":"1722049006018560","order_type":0,"datetime":"1709257097","microtimestamp":"1709257097236000","amount":0.00093267,"amount_str":"0.00093267","amount_traded":"0","amount_at_create":"0.00093267","price":61319,"price_str":"61319"},"channel":"live_orders_btcusd","event":"order_deleted"}
{"data":{"id":1722049014153216,"id_str":"1722049014153216","order_type":0,"datetime":"1709257097","microtimestamp":"1709257097253000","amount":0.00815321,"amount_str":"0.00815321","amount_traded":"0","amount_at_create":"0.00815321","price":61319,"price_str":"61319"},"channel":"live_orders_btcusd","event":"order_created"}
{"data":{"id":1722049013891073,"id_str":"1722049013891073","order_type":0,"datetime":"1709257097","microtimestamp":"1709257097268000","amount":0.00040756,"amount_str":"0.00040756","amount_traded":"0","amount_at_create":"0.00040756","price":61316,"price_str":"61316"},"channel":"live_orders_btcusd","event":"order_deleted"}
{"data":{"id":1722049014317058,"id_str":"1722049014317058","order_type":0,"datetime":"1709257097","microtimestamp":"1709257097294000","amount":0.00093262,"amount_str":"0.00093262","amount_traded":"0","amount_at_create":"0.00093262","price":61283,"price_str":"61283"},"channel":"live_orders_btcusd","event":"order_created"}
{"data":{"id":1722049014321152,"id_str":"1722049014321152","order_type":0,"datetime":"1709257097","microtimestamp":"1709257097294000","amount":0.00093262,"amount_str":"0.00093262","amount_traded":"0","amount_at_create":"0.00093262","price":61320,"price_str":"61320"},"channel":"live_orders_btcusd","event":"order_created"}
{"data":{"id":1722049014431745,"id_str":"1722049014431745","order_type":0,"datetime":"1709257097","microtimestamp":"1709257097322000","amount":0.00040756,"amount_str":"0.00040756","amount_traded":"0","amount_at_create":"0.00040756","price":61317,"price_str":"61317"},"channel":"live_orders_btcusd","event":"order_created"}
{"data":{"id":1722049014448130,"id_str":"1722049014448130","order_type":1,"datetime":"1709257097","microtimestamp":"1709257097326000","amount":0.01630606,"amount_str":"0.01630606","amount_traded":"0","amount_at_create":"0.01630606","price":61327,"price_str":"61327"},"channel":"live_orders_btcusd","event":"order_created"}
{"data":{"id":1722049014431745,"id_str":"1722049014431745","order_type":0,"datetime":"1709257097","microtimestamp":"1709257097372000","amount":0.00040756,"amount_str":"0.00040756","amount_traded":"0","amount_at_create":"0.00040756","price":61317,"price_str":"61317"},"channel":"live_orders_btcusd","event":"order_deleted"}
{"data":{"id":1722049013710848,"id_str":"1722049013710848","order_type":0,"datetime":"1709257097","microtimestamp":"1709257097398000","amount":0.48923979,"amount_str":"0.48923979","amount_traded":"0","amount_at_create":"0.48923979","price":61319,"price_str":"61319"},"channel":"live_orders_btcusd","event":"order_deleted"}
{"data":{"id":1722049009651712,"id_str":"1722049009651712","order_type":1,"datetime":"1709257097","microtimestamp":"1709257097398000","amount":0.48916314,"amount_str":"0.48916314","amount_traded":"0","amount_at_create":"0.48916314","price":61330,"price_str":"61330"},"channel":"live_orders_btcusd","event":"order_deleted"}
{"data":{"id":1722049013706754,"id_str":"1722049013706754","order_type":0,"datetime":"1709257097","microtimestamp":"1709257097399000","amount":0.01630742,"amount_str":"0.01630742","amount_traded":"0","amount_at_create":"0.01630742","price":61321,"price_str":"61321"},"channel":"live_orders_btcusd","event":"order_deleted"}
{"data":{"id":1722049014829056,"id_str":"1722049014829056","order_type":0,"datetime":"1709257097","microtimestamp":"1709257097418000","amount":0.00040756,"amount_str":"0.00040756","amount_traded":"0","amount_at_create":"0.00040756","price":61316,"price_str":"61316"},"channel":"live_orders_btcusd","event":"order_created"}
{"data":{"id":1722049014947840,"id_str":"1722049014947840","order_type":1,"datetime":"1709257097","microtimestamp":"1709257097447000","amount":0.48916499,"amount_str":"0.48916499","amount_traded":"0","amount_at_create":"0.48916499","price":61329,"price_str":"61329"},"channel":"live_orders_btcusd","event":"order_created"}
{"data":{"id":1722049014947843,"id_str":"1722049014947843","order_type":0,"datetime":"1709257097","microtimestamp":"1709257097448000","amount":0.48925521,"amount_str":"0.48925521","amount_traded":"0","amount_at_create":"0.48925521","price":61317,"price_str":"61317"},"channel":"live_orders_btcusd","event":"order_created"}
{"data":{"id":1722049014951939,"id_str":"1722049014951939","order_type":0,"datetime":"1709257097","microtimestamp":"1709257097449000","amount":0.01630793,"amount_str":"0.01630793","amount_traded":"0","amount_at_create":"0.01630793","price":61319,"price_str":"61319"},"channel":"live_orders_btcusd","event":"order_created"}
{"data":{"id":1722047753756673,"id_str":"1722047753756673","order_type":1,"datetime":"1709257097","microtimestamp":"1709257097493000","amount":0.1875,"amount_str":"0.18750000","amount_traded":"0","amount_at_create":"0.18750000","price":61546,"price_str":"61546"},"channel":"live_orders_btcusd","event":"order_deleted"}
{"data":{"id":1722049014829056,"id_str":"1722049014829056","order_type":0,"datetime":"1709257098","microtimestamp":"1709257097504000","amount":0.00040756,"amount_str":"0.00040756","amount_traded":"0","amount_at_create":"0.00040756","price":61316,"price_str":"61316"},"channel":"live_orders_btcusd","event":"order_deleted"}
{"data":{"id":1722049014448130,"id_str":"1722049014448130","order_type":1,"datetime":"1709257098","microtimestamp":"1709257097504000","amount":0.01630606,"amount_str":"0.01630606","amount_traded":"0","amount_at_create":"0.01630606","price":61327,"price_str":"61327"},"channel":"live_orders_btcusd","event":"order_deleted"}
{"data":{"id":1722049014317058,"id_str":"1722049014317058","order_type":0,"datetime":"1709257098","microtimestamp":"1709257097505000","amount":0.00093262,"amount_str":"0.00093262","amount_traded":"0","amount_at_create":"0.00093262","price":61283,"price_str":"61283"},"channel":"live_orders_btcusd","event":"order_deleted"}
{"data":{"id":1722049014947840,"id_str":"1722049014947840","order_type":1,"datetime":"1709257098","microtimestamp":"1709257097505000","amount":0.48916499,"amount_str":"0.48916499","amount_traded":"0","amount_at_create":"0.48916499","price":61329,"price_str":"61329"},"channel":"live_orders_btcusd","event":"order_deleted"}
{"data":{"id":1722049015300096,"id_str":"1722049015300096","order_type":0,"datetime":"1709257098","microtimestamp":"1709257097533000","amount":0.00040756,"amount_str":"0.00040756","amount_traded":"0","amount_at_create":"0.00040756","price":61317,"price_str":"61317"},"channel":"live_orders_btcusd","event":"order_created"}
{"data":{"id":1722049015369729,"id_str":"1722049015369729","order_type":1,"datetime":"1709257098","microtimestamp":"1709257097550000","amount":0.01630637,"amount_str":"0.01630637","amount_traded":"0","amount_at_create":"0.01630637","price":61326,"price_str":"61326"},"channel":"live_orders_btcusd","event":"order_created"}
{"data":{"id":1722049015377920,"id_str":"1722049015377920","order_type":1,"datetime":"1709257098","microtimestamp":"1709257097552000","amount":0.1875,"amount_str":"0.18750000","amount_traded":"0","amount_at_create":"0.18750000","price":61343,"price_str":"61343"},"channel":"live_orders_btcusd","event":"order_created"}
{"data":{"id":1722049015377920,"id_str":"1722049015377920","order_type":1,"datetime":"1709257098","microtimestamp":"1709257097569000","amount":0.1875,"amount_str":"0.18750000","amount_traded":"0","amount_at_create":"0.18750000","price":61343,"price_str":"61343"},"channel":"live_orders_btcusd","event":"order_deleted"}
{"data":{"id":1722049015300096,"id_str":"1722049015300096","order_type":0,"datetime":"1709257098","microtimestamp":"1709257097625000","amount":0.00040756,"amount_str":"0.00040756","amount_traded":"0","amount_at_create":"0.00040756","price":61317,"price_str":"61317"},"channel":"live_orders_btcusd","event":"order_deleted"}
{"data":{"id":1722049015816193,"id_str":"1722049015816193","order_type":1,"datetime":"1709257098","microtimestamp":"1709257097659000","amount":0.48917421,"amount_str":"0.48917421","amount_traded":"0","amount_at_create":"0.48917421","price":61328,"price_str":"61328"},"channel":"live_orders_btcusd","event":"order_created"}
{"data":{"id":1722049015881728,"id_str":"1722049015881728","order_type":0,"datetime":"1709257098","microtimestamp":"1709257097675000","amount":0.00040756,"amount_str":"0.00040756","amount_traded":"0","amount_at_create":"0.00040756","price":61316,"price_str":"61316"},"channel":"live_orders_btcusd","event":"order_created"}
{"data":{"id":1722049014951939,"id_str":"1722049014951939","order_type":0,"datetime":"1709257098","microtimestamp":"1709257097699000","amount":0.01630793,"amount_str":"0.01630793","amount_traded":"0","amount_at_create":"0.01630793","price":61319,"price_str":"61319"},"channel":"live_orders_btcusd","event":"order_deleted"}
{"data":{"id":1722049016152066,"id_str":"1722049016152066","order_type":1,"datetime":"1709257098","microtimestamp":"1709257097741000","amount":0.1875,"amount_str":"0.18750000","amount_traded":"0","amount_at_create":"0.18750000","price":61340,"price_str":"61340"},"channel":"live_orders_btcusd","event":"order_created"}
{"data":{"id":1722049016168449,"id_str":"1722049016168449","order_type":0,"datetime":"1709257098","microtimestamp":"1709257097745000","amount":0.01630785,"amount_str":"0.01630785","amount_traded":"0","amount_at_create":"0.01630785","price":61320,"price_str":"61320"},"channel":"live_orders_btcusd","event":"order_created"}
{"data":{"id":1722049015881728,"id_str":"1722049015881728","order_type":0,"datetime":"1709257098","microtimestamp":"1709257097763000","amount":0.00040756,"amount_str":"0.00040756","amount_traded":"0","amount_at_create":"0.00040756","price":61316,"price_str":"61316"},"channel":"live_orders_btcusd","event":"order_deleted"}
{"data":{"id":1722049016369153,"id_str":"1722049016369153","order_type":0,"datetime":"1709257098","microtimestamp":"1709257097794000","amount":0.00040756,"amount_str":"0.00040756","amount_traded":"0","amount_at_create":"0.00040756","price":61317,"price_str":"61317"},"channel":"live_orders_btcusd","event":"order_created"}
{"data":{"id":1722049016168449,"id_str":"1722049016168449","order_type":0,"datetime":"1709257098","microtimestamp":"1709257097797000","amount":0.01630785,"amount_str":"0.01630785","amount_traded":"0","amount_at_create":"0.01630785","price":61320,"price_str":"61320"},"channel":"live_orders_btcusd","event":"order_deleted"}
{"data":{"id":1722049016369153,"id_str":"1722049016369153","order_type":0,"datetime":"1709257098","microtimestamp":"1709257097838000","amount":0.00040756,"amount_str":"0.00040756","amount_traded":"0","amount_at_create":"0.00040756","price":61317,"price_str":"61317"},"channel":"live_orders_btcusd","event":"order_deleted"}
{"data":{"id":1722049016705024,"id_str":"1722049016705024","order_type":0,"datetime":"1709257098","microtimestamp":"1709257097876000","amount":0.01630817,"amount_str":"0.01630817","amount_traded":"0","amount_at_create":"0.01630817","price":61318,"price_str":"61318"},"channel":"live_orders_btcusd","event":"order_created"}
{"data":{"id":1722049016705025,"id_str":"1722049016705025","order_type":0,"datetime":"1709257098","microtimestamp":"1709257097877000","amount":0.16343697,"amount_str":"0.16343697","amount_traded":"0","amount_at_create":"0.16343697","price":61185,"price_str":"61185"},"channel":"live_orders_btcusd","event":"order_created"}
{"data":{"id":1722049016758272,"id_str":"1722049016758272","order_type":0,"datetime":"1709257098","microtimestamp":"1709257097889000","amount":0.00040756,"amount_str":"0.00040756","amount_traded":"0","amount_at_create":"0.00040756","price":61316,"price_str":"61316"},"channel":"live_orders_btcusd","event":"order_created"}
{"data":{"id":1722049016705024,"id_str":"1722049016705024","order_type":0,"datetime":"1709257098","microtimestamp":"1709257097899000","amount":0.01630817,"amount_str":"0.01630817","amount_traded":"0","amount_at_create":"0.01630817","price":61318,"price_str":"61318"},"channel":"live_orders_btcusd","event":"order_deleted"}
{"data":{"id":1722049016758272,"id_str":"1722049016758272","order_type":0,"datetime":"1709257098","microtimestamp":"1709257098045000","amount":0.00040756,"amount_str":"0.00040756","amount_traded":"0","amount_at_create":"0.00040756","price":61316,"price_str":"61316"},"channel":"live_orders_btcusd","event":"order_deleted"}
{"data":{"id":1722049017602049,"id_str":"1722049017602049","order_type":0,"datetime":"1709257098","microtimestamp":"1709257098096000","amount":0.00040756,"amount_str":"0.00040756","amount_traded":"0","amount_at_create":"0.00040756","price":61317,"price_str":"61317"},"channel":"live_orders_btcusd","event":"order_created"}
{"data":{"id":1722049014947843,"id_str":"1722049014947843","order_type":0,"datetime":"1709257098","microtimestamp":"1709257098111000","amount":0.48925521,"amount_str":"0.48925521","amount_traded":"0","amount_at_create":"0.48925521","price":61317,"price_str":"61317"},"channel":"live_orders_btcusd","event":"order_deleted"}
{"data":{"id":1722049015816193,"id_str":"1722049015816193","order_type":1,"datetime":"1709257098","microtimestamp":"1709257098111000","amount":0.48917421,"amount_str":"0.48917421","amount_traded":"0","amount_at_create":"0.48917421","price":61328,"price_str":"61328"},"channel":"live_orders_btcusd","event":"order_deleted"}
{"data":{"id":1722049017602049,"id_str":"1722049017602049","order_type":0,"datetime":"1709257098","microtimestamp":"1709257098118000","amount":0.00040756,"amount_str":"0.00040756","amount_traded":"0","amount_at_create":"0.00040756","price":61317,"price_str":"61317"},"channel":"live_orders_btcusd","event":"order_deleted"}
{"data":{"id":1722049017810944,"id_str":"1722049017810944","order_type":0,"datetime":"1709257098","microtimestamp":"1709257098146000","amount":0.00040756,"amount_str":"0.00040756","amount_traded":"0","amount_at_create":"0.00040756","price":61316,"price_str":"61316"},"channel":"live_orders_btcusd","event":"order_created"}
{"data":{"id":1722049017851904,"id_str":"1722049017851904","order_type":0,"datetime":"1709257098","microtimestamp":"1709257098156000","amount":0.01630782,"amount_str":"0.01630782","amount_traded":"0","amount_at_create":"0.01630782","price":61320,"price_str":"61320"},"channel":"live_orders_btcusd","event":"order_created"}
{"data":{"id":1722049017860097,"id_str":"1722049017860097","order_type":1,"datetime":"1709257098","microtimestamp":"1709257098158000","amount":0.48916434,"amount_str":"0.48916434","amount_traded":"0","amount_at_create":"0.48916434","price":61330,"price_str":"61330"},"channel":"live_orders_btcusd","event":"order_created"}
{"data":{"id":1722049017860098,"id_str":"1722049017860098","order_type":1,"datetime":"1709257098","microtimestamp":"1709257098158000","amount":0.48867061,"amount_str":"0.48867061","amount_traded":"0","amount_at_create":"0.48867061","price":61392,"price_str":"61392"},"channel":"live_orders_btcusd","event":"order_created"}
{"data":{"id":1722049017868288,"id_str":"1722049017868288","order_type":0,"datetime":"1709257098","microtimestamp":"1709257098160000","amount":0.48925176,"amount_str":"0.48925176","amount_traded":"0","amount_at_create":"0.48925176","price":61318,"price_str":"61318"},"channel":"live_orders_btcusd","event":"order_created"}
{"data":{"id":1722049017872384,"id_str":"1722049017872384","order_type":0,"datetime":"1709257098","microtimestamp":"1709257098161000","amount":1,"amount_str":"1.00000000","amount_traded":"0","amount_at_create":"1.00000000","price":60997,"price_str":"60997"},"channel":"live_orders_btcusd","event":"order_created"}
{"data":{"id":1722049017810944,"id_str":"1722049017810944","order_type":0,"datetime":"1709257098","microtimestamp":"1709257098219000","amount":0.00040756,"amount_str":"0.00040756","amount_traded":"0","amount_at_create":"0.00040756","price":61316,"price_str":"61316"},"channel":"live_orders_btcusd","event":"order_deleted"}
{"data":{"id":1722049018228737,"id_str":"1722049018228737","order_type":0,"datetime":"1709257098","microtimestamp":"1709257098248000","amount":0.00040756,"amount_str":"0.00040756","amount_traded":"0","amount_at_create":"0.00040756","price":61317,"price_str":"61317"},"channel":"live_orders_btcusd","event":"order_created"}
{"data":{"id":1722049014153216,"id_str":"1722049014153216","order_type":0,"datetime":"1709257098","microtimestamp":"1709257098282000","amount":0.00815321,"amount_str":"0.00815321","amount_traded":"0","amount_at_create":"0.00815321","price":61319,"price_str":"61319"},"channel":"live_orders_btcusd","event":"order_deleted"}
{"data":{"id":1722049017860097,"id_str":"1722049017860097","order_type":1,"datetime":"1709257098","microtimestamp":"1709257098295000","amount":0.48916434,"amount_str":"0.48916434","amount_traded":"0","amount_at_create":"0.48916434","price":61330,"price_str":"61330"},"channel":"live_orders_btcusd","event":"order_deleted"}
{"data":{"id":1722049017868288,"id_str":"1722049017868288","order_type":0,"datetime":"1709257098","microtimestamp":"1709257098297000","amount":0.48925176,"amount_str":"0.48925176","amount_traded":"0","amount_at_create":"0.48925176","price":61318,"price_str":"61318"},"channel":"live_orders_btcusd","event":"order_deleted"}
{"data":{"id":1722049017851904,"id_str":"1722049017851904","order_type":0,"datetime":"1709257098","microtimestamp":"1709257098298000","amount":0.01630782,"amount_str":"0.01630782","amount_traded":"0","amount_at_create":"0.01630782","price":61320,"price_str":"61320"},"channel":"live_orders_btcusd","event":"order_deleted"}
{"data":{"id":1722049015369729,"id_str":"1722049015369729","order_type":1,"datetime":"1709257098","microtimestamp":"1709257098298000","amount":0.01630637,"amount_str":"0.01630637","amount_traded":"0","amount_at_create":"0.01630637","price":61326,"price_str":"61326"},"channel":"live_orders_btcusd","event":"order_deleted"}
{"data":{"id":1722049018478592,"id_str":"1722049018478592","order_type":1,"datetime":"1709257098","microtimestamp":"1709257098310000","amount":0.00487299,"amount_str":"0.00487299","amount_traded":"0","amount_at_create":"0.00487299","price":61333,"price_str":"61333"},"channel":"live_orders_btcusd","event":"order_created"}
{"data":{"id":1722049016152066,"id_str":"1722049016152066","order_type":1,"datetime":"1709257098","microtimestamp":"1709257098317000","amount":0.1875,"amount_str":"0.18750000","amount_traded":"0","amount_at_create":"0.18750000","price":61340,"price_str":"61340"},"channel":"live_orders_btcusd","event":"order_deleted"}
{"data":{"id":1722049018228737,"id_str":"1722049018228737","order_type":0,"datetime":"1709257098","microtimestamp":"1709257098320000","amount":0.00040756,"amount_str":"0.00040756","amount_traded":"0","amount_at_create":"0.00040756","price":61317,"price_str":"61317"},"channel":"live_orders_btcusd","event":"order_deleted"}
{"data":{"id":1722049018617857,"id_str":"1722049018617857","order_type":1,"datetime":"1709257098","microtimestamp":"1709257098343000","amount":0.01630571,"amount_str":"0.01630571","amount_traded":"0","amount_at_create":"0.01630571","price":61329,"price_str":"61329"},"channel":"live_orders_btcusd","event":"order_created"}
{"data":{"id":1722049018621953,"id_str":"1722049018621953","order_type":0,"datetime":"1709257098","microtimestamp":"1709257098344000","amount":0.01630752,"amount_str":"0.01630752","amount_traded":"0","amount_at_create":"0.01630752","price":61321,"price_str":"61321"},"channel":"live_orders_btcusd","event":"order_created"}
{"data":{"id":1722049018716160,"id_str":"1722049018716160","order_type":0,"datetime":"1709257098","microtimestamp":"1709257098367000","amount":0.00040756,"amount_str":"0.00040756","amount_traded":"0","amount_at_create":"0.00040756","price":61316,"price_str":"61316"},"channel":"live_orders_btcusd","event":"order_created"}
{"data":{"id":1722049018798080,"id_str":"1722049018798080","order_type":0,"datetime":"1709257098","microtimestamp":"1709257098388000","amount":0.48924294,"amount_str":"0.48924294","amount_traded":"0","amount_at_create":"0.48924294","price":61319,"price_str":"61319"},"channel":"live_orders_btcusd","event":"order_created"}
{"data":{"id":1722049018802179,"id_str":"1722049018802179","order_type":1,"datetime":"1709257098","microtimestamp":"1709257098388000","amount":0.4891543,"amount_str":"0.48915430","amount_traded":"0","amount_at_create":"0.48915430","price":61331,"price_str":"61331"},"channel":"live_orders_btcusd","event":"order_created"}
{"data":{"id":1722049005449219,"id_str":"1722049005449219","order_type":0,"datetime":"1709257098","microtimestamp":"1709257098398000","amount":0.48935563,"amount_str":"0.48935563","amount_traded":"0","amount_at_create":"0.48935563","price":61305,"price_str":"61305"},"channel":"live_orders_btcusd","event":"order_deleted"}
{"data":{"id":1722049002885120,"id_str":"1722049002885120","order_type":1,"datetime":"1709257098","microtimestamp":"1709257098400000","amount":0.48913905,"amount_str":"0.48913905","amount_traded":"0","amount_at_create":"0.48913905","price":61333,"price_str":"61333"},"channel":"live_orders_btcusd","event":"order_deleted"}
{"data":{"id":1722049018716160,"id_str":"1722049018716160","order_type":0,"datetime":"1709257098","microtimestamp":"1709257098436000","amount":0.00040756,"amount_str":"0.00040756","amount_traded":"0","amount_at_create":"0.00040756","price":61316,"price_str":"61316"},"channel":"live_orders_btcusd","event":"order_deleted"}
{"data":{"id":1722049019035650,"id_str":"1722049019035650","order_type":0,"datetime":"1709257098","microtimestamp":"1709257098445000","amount":0.48932917,"amount_str":"0.48932917","amount_traded":"0","amount_at_create":"0.48932917","price":61308,"price_str":"61308"},"channel":"live_orders_btcusd","event":"order_created"}
{"data":{"id":1722049018621953,"id_str":"1722049018621953","order_type":0,"datetime":"1709257098","microtimestamp":"1709257098446000","amount":0.01630752,"amount_str":"0.01630752","amount_traded":"0","amount_at_create":"0.01630752","price":61321,"price_str":"61321"},"channel":"live_orders_btcusd","event":"order_deleted"}
{"data":{"id":1722049000910851,"id_str":"1722049000910851","order_type":0,"datetime":"1709257098","microtimestamp":"1709257098447000","amount":0.489282,"amount_str":"0.48928200","amount_traded":"0","amount_at_create":"0.48928200","price":61314,"price_str":"61314"},"channel":"live_orders_btcusd","event":"order_deleted"}
{"data":{"id":1722049019043841,"id_str":"1722049019043841","order_type":1,"datetime":"1709257098","microtimestamp":"1709257098447000","amount":0.48911833,"amount_str":"0.48911833","amount_traded":"0","amount_at_create":"0.48911833","price":61335,"price_str":"61335"},"channel":"live_orders_btcusd","event":"order_created"}
{"data":{"id":1722049019228160,"id_str":"1722049019228160","order_type":0,"datetime":"1709257098","microtimestamp":"1709257098492000","amount":0.01630734,"amount_str":"0.01630734","amount_traded":"0","amount_at_create":"0.01630734","price":61322,"price_str":"61322"},"channel":"live_orders_btcusd","event":"order_created"}
{"data":{"id":1722049019232256,"id_str":"1722049019232256","order_type":0,"datetime":"1709257098","microtimestamp":"1709257098493000","amount":0.48926928,"amount_str":"0.48926928","amount_traded":"0","amount_at_create":"0.48926928","price":61315,"price_str":"61315"},"channel":"live_orders_btcusd","event":"order_created"}
{"data":{"id":1722049019236354,"id_str":"1722049019236354","order_type":0,"datetime":"1709257098","microtimestamp":"1709257098495000","amount":0.00040756,"amount_str":"0.00040756","amount_traded":"0","amount_at_create":"0.00040756","price":61317,"price_str":"61317"},"channel":"live_orders_btcusd","event":"order_created"}
{"data":{"id":1722049018798080,"id_str":"1722049018798080","order_type":0,"datetime":"1709257099","microtimestamp":"1709257098500000","amount":0.48924294,"amount_str":"0.48924294","amount_traded":"0","amount_at_create":"0.48924294","price":61319,"price_str":"61319"},"channel":"live_orders_btcusd","event":"order_deleted"}
{"data":{"id":1722049019236354,"id_str":"1722049019236354","order_type":0,"datetime":"1709257099","microtimestamp":"1709257098540000","amount":0.00040756,"amount_str":"0.00040756","amount_traded":"0","amount_at_create":"0.00040756","price":61317,"price_str":"61317"},"channel":"live_orders_btcusd","event":"order_deleted"}
{"data":{"id":1722049019564033,"id_str":"1722049019564033","order_type":0,"datetime":"1709257099","microtimestamp":"1709257098575000","amount":0.00040756,"amount_str":"0.00040756","amount_traded":"0","amount_at_create":"0.00040756","price":61316,"price_str":"61316"},"channel":"live_orders_btcusd","event":"order_created"}
{"data":{"id":1722049018478592,"id_str":"1722049018478592","order_type":1,"datetime":"1709257099","microtimestamp":"1709257098630000","amount":0.00487299,"amount_str":"0.00487299","amount_traded":"0","amount_at_create":"0.00487299","price":61333,"price_str":"61333"},"channel":"live_orders_btcusd","event":"order_deleted"}
{"data":{"id":1722049019564033,"id_str":"1722049019564033","order_type":0,"datetime":"1709257099","microtimestamp":"1709257098632000","amount":0.00040756,"amount_str":"0.00040756","amount_traded":"0","amount_at_create":"0.00040756","price":61316,"price_str":"61316"},"channel":"live_orders_btcusd","event":"order_deleted"}
{"data":{"id":1722049014321152,"id_str":"1722049014321152","order_type":0,"datetime":"1709257099","microtimestamp":"1709257098633000","amount":0.00093262,"amount_str":"0.00093262","amount_traded":"0","amount_at_create":"0.00093262","price":61320,"price_str":"61320"},"channel":"live_orders_btcusd","event":"order_deleted"}
{"data":{"id":1722049020051457,"id_str":"1722049020051457","order_type":1,"datetime":"1709257099","microtimestamp":"1709257098693000","amount":0.1875,"amount_str":"0.18750000","amount_traded":"0","amount_at_create":"0.18750000","price":61343,"price_str":"61343"},"channel":"live_orders_btcusd","event":"order_created"}
{"data":{"id":1722049020178432,"id_str":"1722049020178432","order_type":0,"datetime":"1709257099","microtimestamp":"1709257098724000","amount":0.00040756,"amount_str":"0.00040756","amount_traded":"0","amount_at_create":"0.00040756","price":61317,"price_str":"61317"},"channel":"live_orders_btcusd","event":"order_created"}
{"data":{"id":1722049020198913,"id_str":"1722049020198913","order_type":0,"datetime":"1709257099","microtimestamp":"1709257098730000","amount":0.00093264,"amount_str":"0.00093264","amount_traded":"0","amount_at_create":"0.00093264","price":61316,"price_str":"61316"},"channel":"live_orders_btcusd","event":"order_created"}
{"data":{"id":1722049019228160,"id_str":"1722049019228160","order_type":0,"datetime":"1709257099","microtimestamp":"1709257098797000","amount":0.01630734,"amount_str":"0.01630734","amount_traded":"0","amount_at_create":"0.01630734","price":61322,"price_str":"61322"},"channel":"live_orders_btcusd","event":"order_deleted"}
{"data":{"id":1722049018617857,"id_str":"1722049018617857","order_type":1,"datetime":"1709257099","microtimestamp":"1709257098798000","amount":0.01630571,"amount_str":"0.01630571","amount_traded":"0","amount_at_create":"0.01630571","price":61329,"price_str":"61329"},"channel":"live_orders_btcusd","event":"order_deleted"}
{"data":{"id":1722049020178432,"id_str":"1722049020178432","order_type":0,"datetime":"1709257099","microtimestamp":"1709257098803000","amount":0.00040756,"amount_str":"0.00040756","amount_traded":"0","amount_at_create":"0.00040756","price":61317,"price_str":"61317"},"channel":"live_orders_btcusd","event":"order_deleted"}
{"data":{"id":1722049018802179,"id_str":"1722049018802179","order_type":1,"datetime":"1709257099","microtimestamp":"1709257098838000","amount":0.4891543,"amount_str":"0.48915430","amount_traded":"0","amount_at_create":"0.48915430","price":61331,"price_str":"61331"},"channel":"live_orders_btcusd","event":"order_deleted"}
{"data":{"id":1722049020657666,"id_str":"1722049020657666","order_type":0,"datetime":"1709257099","microtimestamp":"1709257098841000","amount":0.01630762,"amount_str":"0.01630762","amount_traded":"0","amount_at_create":"0.01630762","price":61321,"price_str":"61321"},"channel":"live_orders_btcusd","event":"order_created"}
{"data":{"id":1722049020661760,"id_str":"1722049020661760","order_type":0,"datetime":"1709257099","microtimestamp":"1709257098842000","amount":0.48924578,"amount_str":"0.48924578","amount_traded":"0","amount_at_create":"0.48924578","price":61318,"price_str":"61318"},"channel":"live_orders_btcusd","event":"order_created"}
{"data":{"id":1722049020661761,"id_str":"1722049020661761","order_type":1,"datetime":"1709257099","microtimestamp":"1709257098843000","amount":0.0163058,"amount_str":"0.01630580","amount_traded":"0","amount_at_create":"0.01630580","price":61328,"price_str":"61328"},"channel":"live_orders_btcusd","event":"order_created"}
{"data":{"id":1722049020788737,"id_str":"1722049020788737","order_type":0,"datetime":"1709257099","microtimestamp":"1709257098873000","amount":0.00815321,"amount_str":"0.00815321","amount_traded":"0","amount_at_create":"0.00815321","price":61319,"price_str":"61319"},"channel":"live_orders_btcusd","event":"order_created"}
{"data":{"id":1722049020792832,"id_str":"1722049020792832","order_type":0,"datetime":"1709257099","microtimestamp":"1709257098874000","amount":0.00040756,"amount_str":"0.00040756","amount_traded":"0","amount_at_create":"0.00040756","price":61317,"price_str":"61317"},"channel":"live_orders_btcusd","event":"order_created"}
{"data":{"id":1722049020850176,"id_str":"1722049020850176","order_type":1,"datetime":"1709257099","microtimestamp":"1709257098888000","amount":0.48915701,"amount_str":"0.48915701","amount_traded":"0","amount_at_create":"0.48915701","price":61330,"price_str":"61330"},"channel":"live_orders_btcusd","event":"order_created"}
{"data":{"id":1722049020657666,"id_str":"1722049020657666","order_type":0,"datetime":"1709257099","microtimestamp":"1709257098899000","amount":0.01630762,"amount_str":"0.01630762","amount_traded":"0","amount_at_create":"0.01630762","price":61321,"price_str":"61321"},"channel":"live_orders_btcusd","event":"order_deleted"}
{"data":{"id":1722049020198913,"id_str":"1722049020198913","order_type":0,"datetime":"1709257099","microtimestamp":"1709257098905000","amount":0.00093264,"amount_str":"0.00093264","amount_traded":"0","amount_at_create":"0.00093264","price":61316,"price_str":"61316"},"channel":"live_orders_btcusd","event":"order_deleted"}
{"data":{"id":1722049021075459,"id_str":"1722049021075459","order_type":0,"datetime":"1709257099","microtimestamp":"1709257098944000","amount":0.01630777,"amount_str":"0.01630777","amount_traded":"0","amount_at_create":"0.01630777","price":61320,"price_str":"61320"},"channel":"live_orders_btcusd","event":"order_created"}
{"data":{"id":1722049020792832,"id_str":"1722049020792832","order_type":0,"datetime":"1709257099","microtimestamp":"1709257099043000","amount":0.00040756,"amount_str":"0.00040756","amount_traded":"0","amount_at_create":"0.00040756","price":61317,"price_str":"61317"},"channel":"live_orders_btcusd","event":"order_deleted"}
{"data":{"id":1722049021538304,"id_str":"1722049021538304","order_type":0,"datetime":"1709257099","microtimestamp":"1709257099056000","amount":0.00093265,"amount_str":"0.00093265","amount_traded":"0","amount_at_create":"0.00093265","price":61319,"price_str":"61319"},"channel":"live_orders_btcusd","event":"order_created"}
{"data":{"id":1722049021698049,"id_str":"1722049021698049","order_type":0,"datetime":"1709257099","microtimestamp":"1709257099096000","amount":0.00040756,"amount_str":"0.00040756","amount_traded":"0","amount_at_create":"0.00040756","price":61316,"price_str":"61316"},"channel":"live_orders_btcusd","event":"order_created"}
{"data":{"id":1722049021075459,"id_str":"1722049021075459","order_type":0,"datetime":"1709257099","microtimestamp":"1709257099197000","amount":0.01630777,"amount_str":"0.01630777","amount_traded":"0","amount_at_create":"0.01630777","price":61320,"price_str":"61320"},"channel":"live_orders_btcusd","event":"order_deleted"}
{"data":{"id":1722049020661760,"id_str":"1722049020661760","order_type":0,"datetime":"1709257099","microtimestamp":"1709257099197000","amount":0.48924578,"amount_str":"0.48924578","amount_traded":"0","amount_at_create":"0.48924578","price":61318,"price_str":"61318"},"channel":"live_orders_btcusd","event":"order_deleted"}
{"data":{"id":1722049022300160,"id_str":"1722049022300160","order_type":0,"datetime":"1709257099","microtimestamp":"1709257099242000","amount":0.01630757,"amount_str":"0.01630757","amount_traded":"0","amount_at_create":"0.01630757","price":61321,"price_str":"61321"},"channel":"live_orders_btcusd","event":"order_created"}
{"data":{"id":1722049022304259,"id_str":"1722049022304259","order_type":0,"datetime":"1709257099","microtimestamp":"1709257099243000","amount":0.48924433,"amount_str":"0.48924433","amount_traded":"0","amount_at_create":"0.48924433","price":61319,"price_str":"61319"},"channel":"live_orders_btcusd","event":"order_created"}
{"data":{"id":1722049021698049,"id_str":"1722049021698049","order_type":0,"datetime":"1709257099","microtimestamp":"1709257099271000","amount":0.00040756,"amount_str":"0.00040756","amount_traded":"0","amount_at_create":"0.00040756","price":61316,"price_str":"61316"},"channel":"live_orders_btcusd","event":"order_deleted"}
{"data":{"id":1722049022537728,"id_str":"1722049022537728","order_type":0,"datetime":"1709257099","microtimestamp":"1709257099300000","amount":0.00040756,"amount_str":"0.00040756","amount_traded":"0","amount_at_create":"0.00040756","price":61317,"price_str":"61317"},"channel":"live_orders_btcusd","event":"order_created"}
{"data":{"id":1722049021538304,"id_str":"1722049021538304","order_type":0,"datetime":"1709257099","microtimestamp":"1709257099305000","amount":0.00093265,"amount_str":"0.00093265","amount_traded":"0","amount_at_create":"0.00093265","price":61319,"price_str":"61319"},"channel":"live_orders_btcusd","event":"order_deleted"}
{"data":{"id":1722049022537728,"id_str":"1722049022537728","order_type":0,"datetime":"1709257099","microtimestamp":"1709257099311000","amount":0.00040756,"amount_str":"0.00040756","amount_traded":"0","amount_at_create":"0.00040756","price":61317,"price_str":"61317"},"channel":"live_orders_btcusd","event":"order_deleted"}
{"data":{"id":1722049022705664,"id_str":"1722049022705664","order_type":0,"datetime":"1709257099","microtimestamp":"1709257099341000","amount":0.00040756,"amount_str":"0.00040756","amount_traded":"0","amount_at_create":"0.00040756","price":61316,"price_str":"61316"},"channel":"live_orders_btcusd","event":"order_created"}
{"data":{"id":1722049023168512,"id_str":"1722049023168512","order_type":0,"datetime":"1709257099","microtimestamp":"1709257099454000","amount":0.00093265,"amount_str":"0.00093265","amount_traded":"0","amount_at_create":"0.00093265","price":61320,"price_str":"61320"},"channel":"live_orders_btcusd","event":"order_created"}
{"data":{"id":1722049022705664,"id_str":"1722049022705664","order_type":0,"datetime":"1709257099","microtimestamp":"1709257099458000","amount":0.00040756,"amount_str":"0.00040756","amount_traded":"0","amount_at_create":"0.00040756","price":61316,"price_str":"61316"},"channel":"live_orders_btcusd","event":"order_deleted"}
{"data":{"id":1722049019043841,"id_str":"1722049019043841","order_type":1,"datetime":"1709257100","microtimestamp":"1709257099500000","amount":0.48911833,"amount_str":"0.48911833","amount_traded":"0","amount_at_create":"0.48911833","price":61335,"price_str":"61335"},"channel":"live_orders_btcusd","event":"order_deleted"}
{"data":{"id":1722049022304259,"id_str":"1722049022304259","order_type":0,"datetime":"1709257100","microtimestamp":"1709257099501000","amount":0.48924433,"amount_str":"0.48924433","amount_traded":"0","amount_at_create":"0.48924433","price":61319,"price_str":"61319"},"channel":"live_orders_btcusd","event":"order_deleted"}
{"data":{"id":1722049020850176,"id_str":"1722049020850176","order_type":1,"datetime":"1709257100","microtimestamp":"1709257099501000","amount":0.48915701,"amount_str":"0.48915701","amount_traded":"0","amount_at_create":"0.48915701","price":61330,"price_str":"61330"},"channel":"live_orders_btcusd","event":"order_deleted"}
{"data":{"id":1722049022300160,"id_str":"1722049022300160","order_type":0,"datetime":"1709257100","microtimestamp":"1709257099501000","amount":0.01630757,"amount_str":"0.01630757","amount_traded":"0","amount_at_create":"0.01630757","price":61321,"price_str":"61321"},"channel":"live_orders_btcusd","event":"order_deleted"}
{"data":{"id":1722049023369216,"id_str":"1722049023369216","order_type":0,"datetime":"1709257100","microtimestamp":"1709257099503000","amount":0.00040756,"amount_str":"0.00040756","amount_traded":"0","amount_at_create":"0.00040756","price":61317,"price_str":"61317"},"channel":"live_orders_btcusd","event":"order_created"}
{"data":{"id":1722049020661761,"id_str":"1722049020661761","order_type":1,"datetime":"1709257100","microtimestamp":"1709257099504000","amount":0.0163058,"amount_str":"0.01630580","amount_traded":"0","amount_at_create":"0.01630580","price":61328,"price_str":"61328"},"channel":"live_orders_btcusd","event":"order_deleted"}
{"data":{"id":1722049023369216,"id_str":"1722049023369216","order_type":0,"datetime":"1709257100","microtimestamp":"1709257099530000","amount":0.00040756,"amount_str":"0.00040756","amount_traded":"0","amount_at_create":"0.00040756","price":61317,"price_str":"61317"},"channel":"live_orders_btcusd","event":"order_deleted"}
{"data":{"id":1722049023553537,"id_str":"1722049023553537","order_type":1,"datetime":"1709257100","microtimestamp":"1709257099548000","amount":0.48913586,"amount_str":"0.48913586","amount_traded":"0","amount_at_create":"0.48913586","price":61333,"price_str":"61333"},"channel":"live_orders_btcusd","event":"order_created"}
{"data":{"id":1722049023557632,"id_str":"1722049023557632","order_type":0,"datetime":"1709257100","microtimestamp":"1709257099549000","amount":0.4892541,"amount_str":"0.48925410","amount_traded":"0","amount_at_create":"0.48925410","price":61317,"price_str":"61317"},"channel":"live_orders_btcusd","event":"order_created"}
{"data":{"id":1722049023561729,"id_str":"1722049023561729","order_type":1,"datetime":"1709257100","microtimestamp":"1709257099550000","amount":0.01630615,"amount_str":"0.01630615","amount_traded":"0","amount_at_create":"0.01630615","price":61327,"price_str":"61327"},"channel":"live_orders_btcusd","event":"order_created"}
{"data":{"id":1722049023565824,"id_str":"1722049023565824","order_type":1,"datetime":"1709257100","microtimestamp":"1709257099551000","amount":0.48916757,"amount_str":"0.48916757","amount_traded":"0","amount_at_create":"0.48916757","price":61329,"price_str":"61329"},"channel":"live_orders_btcusd","event":"order_created"}
{"data":{"id":1722049023565825,"id_str":"1722049023565825","order_type":0,"datetime":"1709257100","microtimestamp":"1709257099551000","amount":0.0163079,"amount_str":"0.01630790","amount_traded":"0","amount_at_create":"0.01630790","price":61319,"price_str":"61319"},"channel":"live_orders_btcusd","event":"order_created"}
{"data":{"id":1722049023643648,"id_str":"1722049023643648","order_type":0,"datetime":"1709257100","microtimestamp":"1709257099570000","amount":0.00040756,"amount_str":"0.00040756","amount_traded":"0","amount_at_create":"0.00040756","price":61316,"price_str":"61316"},"channel":"live_orders_btcusd","event":"order_created"}
{"data":{"id":1722049020788737,"id_str":"1722049020788737","order_type":0,"datetime":"1709257100","microtimestamp":"1709257099626000","amount":0.00815321,"amount_str":"0.00815321","amount_traded":"0","amount_at_create":"0.00815321","price":61319,"price_str":"61319"},"channel":"live_orders_btcusd","event":"order_deleted"}
{"data":{"id":1722049023557632,"id_str":"1722049023557632","order_type":0,"datetime":"1709257100","microtimestamp":"1709257099633000","amount":0.4892541,"amount_str":"0.48925410","amount_traded":"0","amount_at_create":"0.48925410","price":61317,"price_str":"61317"},"channel":"live_orders_btcusd","event":"order_deleted"}
{"data":{"id":1722049023565825,"id_str":"1722049023565825","order_type":0,"datetime":"1709257100","microtimestamp":"1709257099634000","amount":0.0163079,"amount_str":"0.01630790","amount_traded":"0","amount_at_create":"0.01630790","price":61319,"price_str":"61319"},"channel":"live_orders_btcusd","event":"order_deleted"}
{"data":{"id":1722049023643648,"id_str":"1722049023643648","order_type":0,"datetime":"1709257100","microtimestamp":"1709257099640000","amount":0.00040756,"amount_str":"0.00040756","amount_traded":"0","amount_at_create":"0.00040756","price":61316,"price_str":"61316"},"channel":"live_orders_btcusd","event":"order_deleted"}
{"data":{"id":1722049024000001,"id_str":"1722049024000001","order_type":1,"datetime":"1709257100","microtimestamp":"1709257099658000","amount":0.00487287,"amount_str":"0.00487287","amount_traded":"0","amount_at_create":"0.00487287","price":61333,"price_str":"61333"},"channel":"live_orders_btcusd","event":"order_created"}
{"data":{"id":1722049024086018,"id_str":"1722049024086018","order_type":0,"datetime":"1709257100","microtimestamp":"1709257099679000","amount":0.01630782,"amount_str":"0.01630782","amount_traded":"0","amount_at_create":"0.01630782","price":61320,"price_str":"61320"},"channel":"live_orders_btcusd","event":"order_created"}
{"data":{"id":1722049024143361,"id_str":"1722049024143361","order_type":0,"datetime":"1709257100","microtimestamp":"1709257099692000","amount":0.00040756,"amount_str":"0.00040756","amount_traded":"0","amount_at_create":"0.00040756","price":61317,"price_str":"61317"},"channel":"live_orders_btcusd","event":"order_created"}
{"data":{"id":1722049023168512,"id_str":"1722049023168512","order_type":0,"datetime":"1709257100","microtimestamp":"1709257099706000","amount":0.00093265,"amount_str":"0.00093265","amount_traded":"0","amount_at_create":"0.00093265","price":61320,"price_str":"61320"},"channel":"live_orders_btcusd","event":"order_deleted"}
{"data":{"id":1722049024143361,"id_str":"1722049024143361","order_type":0,"datetime":"1709257100","microtimestamp":"1709257099719000","amount":0.00040756,"amount_str":"0.00040756","amount_traded":"0","amount_at_create":"0.00040756","price":61317,"price_str":"61317"},"channel":"live_orders_btcusd","event":"order_deleted"}
{"data":{"id":1722049024397312,"id_str":"1722049024397312","order_type":0,"datetime":"1709257100","microtimestamp":"1709257099754000","amount":0.00040756,"amount_str":"0.00040756","amount_traded":"0","amount_at_create":"0.00040756","price":61316,"price_str":"61316"},"channel":"live_orders_btcusd","event":"order_created"}
{"data":{"id":1722049024868353,"id_str":"1722049024868353","order_type":0,"datetime":"1709257100","microtimestamp":"1709257099869000","amount":0.00093267,"amount_str":"0.00093267","amount_traded":"0","amount_at_create":"0.00093267","price":61316,"price_str":"61316"},"channel":"live_orders_btcusd","event":"order_created"}
{"data":{"id":1722049024397312,"id_str":"1722049024397312","order_type":0,"datetime":"1709257100","microtimestamp":"1709257099882000","amount":0.00040756,"amount_str":"0.00040756","amount_traded":"0","amount_at_create":"0.00040756","price":61316,"price_str":"61316"},"channel":"live_orders_btcusd","event":"order_deleted"}
{"data":{"id":1722049025294336,"id_str":"1722049025294336","order_type":0,"datetime":"1709257100","microtimestamp":"1709257099973000","amount":0.00040756,"amount_str":"0.00040756","amount_traded":"0","amount_at_create":"0.00040756","price":61317,"price_str":"61317"},"channel":"live_orders_btcusd","event":"order_created"}
{"data":{"id":1722049025564672,"id_str":"1722049025564672","order_type":0,"datetime":"1709257100","microtimestamp":"1709257100039000","amount":0.4892519,"amount_str":"0.48925190","amount_traded":"0","amount_at_create":"0.48925190","price":61318,"price_str":"61318"},"channel":"live_orders_btcusd","event":"order_created"}
{"data":{"id":1722049025564672,"id_str":"1722049025564672","order_type":0,"datetime":"1709257100","microtimestamp":"1709257100081000","amount":0.4892519,"amount_str":"0.48925190","amount_traded":"0","amount_at_create":"0.48925190","price":61318,"price_str":"61318"},"channel":"live_orders_btcusd","event":"order_deleted"}
{"data":{"id":1722049024086018,"id_str":"1722049024086018","order_type":0,"datetime":"1709257100","microtimestamp":"1709257100081000","amount":0.01630782,"amount_str":"0.01630782","amount_traded":"0","amount_at_create":"0.01630782","price":61320,"price_str":"61320"},"channel":"live_orders_btcusd","event":"order_deleted"}
{"data":{"id":1722049023565824,"id_str":"1722049023565824","order_type":1,"datetime":"1709257100","microtimestamp":"1709257100109000","amount":0.48916757,"amount_str":"0.48916757","amount_traded":"0","amount_at_create":"0.48916757","price":61329,"price_str":"61329"},"channel":"live_orders_btcusd","event":"order_deleted"}
{"data":{"id":1722049020051457,"id_str":"1722049020051457","order_type":1,"datetime":"1709257100","microtimestamp":"1709257100110000","amount":0.1875,"amount_str":"0.18750000","amount_traded":"0","amount_at_create":"0.18750000","price":61343,"price_str":"61343"},"channel":"live_orders_btcusd","event":"order_deleted"}
{"data":{"id":1722049025933312,"id_str":"1722049025933312","order_type":0,"datetime":"1709257100","microtimestamp":"1709257100129000","amount":0.01630757,"amount_str":"0.01630757","amount_traded":"0","amount_at_create":"0.01630757","price":61321,"price_str":"61321"},"channel":"live_orders_btcusd","event":"order_created"}
{"data":{"id":1722049026162688,"id_str":"1722049026162688","order_type":1,"datetime":"1709257100","microtimestamp":"1709257100185000","amount":0.48915644,"amount_str":"0.48915644","amount_traded":"0","amount_at_create":"0.48915644","price":61331,"price_str":"61331"},"channel":"live_orders_btcusd","event":"order_created"}
{"data":{"id":1722049023561729,"id_str":"1722049023561729","order_type":1,"datetime":"1709257100","microtimestamp":"1709257100199000","amount":0.01630615,"amount_str":"0.01630615","amount_traded":"0","amount_at_create":"0.01630615","price":61327,"price_str":"61327"},"channel":"live_orders_btcusd","event":"order_deleted"}
{"data":{"id":1722049026392066,"id_str":"1722049026392066","order_type":1,"datetime":"1709257100","microtimestamp":"1709257100241000","amount":0.01630572,"amount_str":"0.01630572","amount_traded":"0","amount_at_create":"0.01630572","price":61329,"price_str":"61329"},"channel":"live_orders_btcusd","event":"order_created"}
{"data":{"id":1722049026408450,"id_str":"1722049026408450","order_type":0,"datetime":"1709257100","microtimestamp":"1709257100246000","amount":0.48924426,"amount_str":"0.48924426","amount_traded":"0","amount_at_create":"0.48924426","price":61319,"price_str":"61319"},"channel":"live_orders_btcusd","event":"order_created"}
{"data":{"id":1722049024000001,"id_str":"1722049024000001","order_type":1,"datetime":"1709257100","microtimestamp":"1709257100301000","amount":0.00487287,"amount_str":"0.00487287","amount_traded":"0","amount_at_create":"0.00487287","price":61333,"price_str":"61333"},"channel":"live_orders_btcusd","event":"order_deleted"}
{"data":{"id":1722049024868353,"id_str":"1722049024868353","order_type":0,"datetime":"1709257100","microtimestamp":"1709257100305000","amount":0.00093267,"amount_str":"0.00093267","amount_traded":"0","amount_at_create":"0.00093267","price":61316,"price_str":"61316"},"channel":"live_orders_btcusd","event":"order_deleted"}
{"data":{"id":1722049026793472,"id_str":"1722049026793472","order_type":0,"datetime":"1709257100","microtimestamp":"1709257100340000","amount":0.00815328,"amount_str":"0.00815328","amount_traded":"0","amount_at_create":"0.00815328","price":61319,"price_str":"61319"},"channel":"live_orders_btcusd","event":"order_created"}
{"data":{"id":1722049023553537,"id_str":"1722049023553537","order_type":1,"datetime":"1709257100","microtimestamp":"1709257100404000","amount":0.48913586,"amount_str":"0.48913586","amount_traded":"0","amount_at_create":"0.48913586","price":61333,"price_str":"61333"},"channel":"live_orders_btcusd","event":"order_deleted"}
{"data":{"id":1722049019232256,"id_str":"1722049019232256","order_type":0,"datetime":"1709257100","microtimestamp":"1709257100405000","amount":0.48926928,"amount_str":"0.48926928","amount_traded":"0","amount_at_create":"0.48926928","price":61315,"price_str":"61315"},"channel":"live_orders_btcusd","event":"order_deleted"}
{"data":{"id":1722049025933312,"id_str":"1722049025933312","order_type":0,"datetime":"1709257100","microtimestamp":"1709257100405000","amount":0.01630757,"amount_str":"0.01630757","amount_traded":"0","amount_at_create":"0.01630757","price":61321,"price_str":"61321"},"channel":"live_orders_btcusd","event":"order_deleted"}
{"data":{"id":1722049003458567,"id_str":"1722049003458567","order_type":1,"datetime":"1709257100","microtimestamp":"1709257100405000","amount":0.48888137,"amount_str":"0.48888137","amount_traded":"0","amount_at_create":"0.48888137","price":61365,"price_str":"61365"},"channel":"live_orders_btcusd","event":"order_deleted"}
{"data":{"id":1722049027268608,"id_str":"1722049027268608","order_type":0,"datetime":"1709257100","microtimestamp":"1709257100455000","amount":0.00093264,"amount_str":"0.00093264","amount_traded":"0","amount_at_create":"0.00093264","price":61320,"price_str":"61320"},"channel":"live_orders_btcusd","event":"order_created"}
{"data":{"id":1722049027268609,"id_str":"1722049027268609","order_type":0,"datetime":"1709257100","microtimestamp":"1709257100455000","amount":0.48922763,"amount_str":"0.48922763","amount_traded":"0","amount_at_create":"0.48922763","price":61321,"price_str":"61321"},"channel":"live_orders_btcusd","event":"order_created"}
{"data":{"id":1722049027272706,"id_str":"1722049027272706","order_type":0,"datetime":"1709257100","microtimestamp":"1709257100457000","amount":0.01630701,"amount_str":"0.01630701","amount_traded":"0","amount_at_create":"0.01630701","price":61323,"price_str":"61323"},"channel":"live_orders_btcusd","event":"order_created"}
{"data":{"id":1722049027280898,"id_str":"1722049027280898","order_type":1,"datetime":"1709257100","microtimestamp":"1709257100458000","amount":0.48910971,"amount_str":"0.48910971","amount_traded":"0","amount_at_create":"0.48910971","price":61336,"price_str":"61336"},"channel":"live_orders_btcusd","event":"order_created"}
{"data":{"id":1722049027284994,"id_str":"1722049027284994","order_type":1,"datetime":"1709257100","microtimestamp":"1709257100459000","amount":0.48883136,"amount_str":"0.48883136","amount_traded":"0","amount_at_create":"0.48883136","price":61371,"price_str":"61371"},"channel":"live_orders_btcusd","event":"order_created"}
{"data":{"id":1722049025294336,"id_str":"1722049025294336","order_type":0,"datetime":"1709257100","microtimestamp":"1709257100460000","amount":0.00040756,"amount_str":"0.00040756","amount_traded":"0","amount_at_create":"0.00040756","price":61317,"price_str":"61317"},"channel":"live_orders_btcusd","event":"order_deleted"}
{"data":{"id":1722049027268608,"id_str":"1722049027268608","order_type":0,"datetime":"1709257101","microtimestamp":"1709257100505000","amount":0.00093264,"amount_str":"0.00093264","amount_traded":"0","amount_at_create":"0.00093264","price":61320,"price_str":"61320"},"channel":"live_orders_btcusd","event":"order_deleted"}
{"data":{"id":1722049026408450,"id_str":"1722049026408450","order_type":0,"datetime":"1709257101","microtimestamp":"1709257100510000","amount":0.48924426,"amount_str":"0.48924426","amount_traded":"0","amount_at_create":"0.48924426","price":61319,"price_str":"61319"},"channel":"live_orders_btcusd","event":"order_deleted"}
{"data":{"id":1722049027526656,"id_str":"1722049027526656","order_type":0,"datetime":"1709257101","microtimestamp":"1709257100518000","amount":0.00040756,"amount_str":"0.00040756","amount_traded":"0","amount_at_create":"0.00040756","price":61316,"price_str":"61316"},"channel":"live_orders_btcusd","event":"order_created"}
{"data":{"id":1722049027670016,"id_str":"1722049027670016","order_type":0,"datetime":"1709257101","microtimestamp":"1709257100553000","amount":0.48926104,"amount_str":"0.48926104","amount_traded":"0","amount_at_create":"0.48926104","price":61316,"price_str":"61316"},"channel":"live_orders_btcusd","event":"order_created"}
{"data":{"id":1722049027526656,"id_str":"1722049027526656","order_type":0,"datetime":"1709257101","microtimestamp":"1709257100633000","amount":0.00040756,"amount_str":"0.00040756","amount_traded":"0","amount_at_create":"0.00040756","price":61316,"price_str":"61316"},"channel":"live_orders_btcusd","event":"order_deleted"}
{"data":{"id":1722049028059136,"id_str":"1722049028059136","order_type":0,"datetime":"1709257101","microtimestamp":"1709257100648000","amount":0.00093264,"amount_str":"0.00093264","amount_traded":"0","amount_at_create":"0.00093264","price":61322,"price_str":"61322"},"channel":"live_orders_btcusd","event":"order_created"}
{"data":{"id":1722049028247552,"id_str":"1722049028247552","order_type":0,"datetime":"1709257101","microtimestamp":"1709257100694000","amount":0.00040756,"amount_str":"0.00040756","amount_traded":"0","amount_at_create":"0.00040756","price":61317,"price_str":"61317"},"channel":"live_orders_btcusd","event":"order_created"}
{"data":{"id":1722047762534402,"id_str":"1722047762534402","order_type":1,"datetime":"1709257101","microtimestamp":"1709257100999000","amount":0.1875,"amount_str":"0.18750000","amount_traded":"0","amount_at_create":"0.18750000","price":61575,"price_str":"61575"},"channel":"live_orders_btcusd","event":"order_deleted"}
{"data":{"id":1722049002176512,"id_str":"1722049002176512","order_type":1,"datetime":"1709257101","microtimestamp":"1709257101191000","amount":0.02365137,"amount_str":"0.02365137","amount_traded":"0","amount_at_create":"0.02365137","price":61344,"price_str":"61344"},"channel":"live_orders_btcusd","event":"order_deleted"}
{"data":{"id":1722049004781569,"id_str":"1722049004781569","order_type":1,"datetime":"1709257101","microtimestamp":"1709257101197000","amount":0.00487295,"amount_str":"0.00487295","amount_traded":"0","amount_at_create":"0.00487295","price":61335,"price_str":"61335"},"channel":"live_orders_btcusd","event":"order_deleted"}
{"data":{"id":1722049027280898,"id_str":"1722049027280898","order_type":1,"datetime":"1709257101","microtimestamp":"1709257101205000","amount":0.48910971,"amount_str":"0.48910971","amount_traded":"0","amount_at_create":"0.48910971","price":61336,"price_str":"61336"},"channel":"live_orders_btcusd","event":"order_deleted"}
{"data":{"id":1722049003085824,"id_str":"1722049003085824","order_type":0,"datetime":"1709257101","microtimestamp":"1709257101205000","amount":0.48945873,"amount_str":"0.48945873","amount_traded":"0","amount_at_create":"0.48945873","price":61292,"price_str":"61292"},"channel":"live_orders_btcusd","event":"order_deleted"}
{"data":{"id":1722049000574976,"id_str":"1722049000574976","order_type":0,"datetime":"1709257101","microtimestamp":"1709257101205000","amount":0.00815348,"amount_str":"0.00815348","amount_traded":"0","amount_at_create":"0.00815348","price":61317,"price_str":"61317"},"channel":"live_orders_btcusd","event":"order_deleted"}
{"data":{"id":1722049019035650,"id_str":"1722049019035650","order_type":0,"datetime":"1709257101","microtimestamp":"1709257101206000","amount":0.48932917,"amount_str":"0.48932917","amount_traded":"0","amount_at_create":"0.48932917","price":61308,"price_str":"61308"},"channel":"live_orders_btcusd","event":"order_deleted"}
{"data":{"id":1722049027670016,"id_str":"1722049027670016","order_type":0,"datetime":"1709257101","microtimestamp":"1709257101206000","amount":0.48926104,"amount_str":"0.48926104","amount_traded":"0","amount_at_create":"0.48926104","price":61316,"price_str":"61316"},"channel":"live_orders_btcusd","event":"order_deleted"}
{"data":{"id":1722049013706753,"id_str":"1722049013706753","order_type":0,"datetime":"1709257101","microtimestamp":"1709257101207000","amount":0.48955912,"amount_str":"0.48955912","amount_traded":"0","amount_at_create":"0.48955912","price":61279,"price_str":"61279"},"channel":"live_orders_btcusd","event":"order_deleted"}
{"data":{"id":1722049026392066,"id_str":"1722049026392066","order_type":1,"datetime":"1709257101","microtimestamp":"1709257101207000","amount":0.01630572,"amount_str":"0.01630572","amount_traded":"0","amount_at_create":"0.01630572","price":61329,"price_str":"61329"},"channel":"live_orders_btcusd","event":"order_deleted"}
{"data":{"id":1722049003081729,"id_str":"1722049003081729","order_type":1,"datetime":"1709257101","microtimestamp":"1709257101207000","amount":0.48896704,"amount_str":"0.48896704","amount_traded":"0","amount_at_create":"0.48896704","price":61354,"price_str":"61354"},"channel":"live_orders_btcusd","event":"order_deleted"}
{"data":{"id":1722049027268609,"id_str":"1722049027268609","order_type":0,"datetime":"1709257101","microtimestamp":"1709257101208000","amount":0.48922763,"amount_str":"0.48922763","amount_traded":"0","amount_at_create":"0.48922763","price":61321,"price_str":"61321"},"channel":"live_orders_btcusd","event":"order_deleted"}
{"data":{"id":1722049017860098,"id_str":"1722049017860098","order_type":1,"datetime":"1709257101","microtimestamp":"1709257101208000","amount":0.48867061,"amount_str":"0.48867061","amount_traded":"0","amount_at_create":"0.48867061","price":61392,"price_str":"61392"},"channel":"live_orders_btcusd","event":"order_deleted"}
{"data":{"id":1722049027272706,"id_str":"1722049027272706","order_type":0,"datetime":"1709257101","microtimestamp":"1709257101208000","amount":0.01630701,"amount_str":"0.01630701","amount_traded":"0","amount_at_create":"0.01630701","price":61323,"price_str":"61323"},"channel":"live_orders_btcusd","event":"order_deleted"}
{"data":{"id":1722049005449220,"id_str":"1722049005449220","order_type":1,"datetime":"1709257101","microtimestamp":"1709257101209000","amount":0.48906998,"amount_str":"0.48906998","amount_traded":"0","amount_at_create":"0.48906998","price":61341,"price_str":"61341"},"channel":"live_orders_btcusd","event":"order_deleted"}
{"data":{"id":1722049026162688,"id_str":"1722049026162688","order_type":1,"datetime":"1709257101","microtimestamp":"1709257101209000","amount":0.48915644,"amount_str":"0.48915644","amount_traded":"0","amount_at_create":"0.48915644","price":61331,"price_str":"61331"},"channel":"live_orders_btcusd","event":"order_deleted"}
{"data":{"id":1722049030422535,"id_str":"1722049030422535","order_type":0,"datetime":"1709257101","microtimestamp":"1709257101226000","amount":0.00815314,"amount_str":"0.00815314","amount_traded":"0","amount_at_create":"0.00815314","price":61321,"price_str":"61321"},"channel":"live_orders_btcusd","event":"order_created"}
{"data":{"id":1722049030500352,"id_str":"1722049030500352","order_type":1,"datetime":"1709257101","microtimestamp":"1709257101244000","amount":0.00487275,"amount_str":"0.00487275","amount_traded":"0","amount_at_create":"0.00487275","price":61337,"price_str":"61337"},"channel":"live_orders_btcusd","event":"order_created"}
{"data":{"id":1722049026793472,"id_str":"1722049026793472","order_type":0,"datetime":"1709257101","microtimestamp":"1709257101252000","amount":0.00815328,"amount_str":"0.00815328","amount_traded":"0","amount_at_create":"0.00815328","price":61319,"price_str":"61319"},"channel":"live_orders_btcusd","event":"order_deleted"}
{"data":{"id":1722049030594561,"id_str":"1722049030594561","order_type":1,"datetime":"1709257101","microtimestamp":"1709257101267000","amount":0.48912424,"amount_str":"0.48912424","amount_traded":"0","amount_at_create":"0.48912424","price":61335,"price_str":"61335"},"channel":"live_orders_btcusd","event":"order_created"}
{"data":{"id":1722049030598656,"id_str":"1722049030598656","order_type":1,"datetime":"1709257101","microtimestamp":"1709257101268000","amount":0.02414301,"amount_str":"0.02414301","amount_traded":"0","amount_at_create":"0.02414301","price":61347,"price_str":"61347"},"channel":"live_orders_btcusd","event":"order_created"}
{"data":{"id":1722049030602753,"id_str":"1722049030602753","order_type":1,"datetime":"1709257101","microtimestamp":"1709257101269000","amount":0.48893364,"amount_str":"0.48893364","amount_traded":"0","amount_at_create":"0.48893364","price":61359,"price_str":"61359"},"channel":"live_orders_btcusd","event":"order_created"}
{"data":{"id":1722049030606848,"id_str":"1722049030606848","order_type":1,"datetime":"1709257101","microtimestamp":"1709257101270000","amount":0.48909405,"amount_str":"0.48909405","amount_traded":"0","amount_at_create":"0.48909405","price":61338,"price_str":"61338"},"channel":"live_orders_btcusd","event":"order_created"}
{"data":{"id":1722049030606849,"id_str":"1722049030606849","order_type":1,"datetime":"1709257101","microtimestamp":"1709257101270000","amount":0.48903553,"amount_str":"0.48903553","amount_traded":"0","amount_at_create":"0.48903553","price":61346,"price_str":"61346"},"channel":"live_orders_btcusd","event":"order_created"}
{"data":{"id":1722049030610944,"id_str":"1722049030610944","order_type":1,"datetime":"1709257101","microtimestamp":"1709257101271000","amount":0.0163047,"amount_str":"0.01630470","amount_traded":"0","amount_at_create":"0.01630470","price":61332,"price_str":"61332"},"channel":"live_orders_btcusd","event":"order_created"}
{"data":{"id":1722049030610947,"id_str":"1722049030610947","order_type":0,"datetime":"1709257101","microtimestamp":"1709257101271000","amount":0.48929945,"amount_str":"0.48929945","amount_traded":"0","amount_at_create":"0.48929945","price":61312,"price_str":"61312"},"channel":"live_orders_btcusd","event":"order_created"}
{"data":{"id":1722049030610948,"id_str":"1722049030610948","order_type":0,"datetime":"1709257101","microtimestamp":"1709257101271000","amount":0.48951925,"amount_str":"0.48951925","amount_traded":"0","amount_at_create":"0.48951925","price":61284,"price_str":"61284"},"channel":"live_orders_btcusd","event":"order_created"}
{"data":{"id":1722049030615040,"id_str":"1722049030615040","order_type":0,"datetime":"1709257101","microtimestamp":"1709257101272000","amount":0.01630628,"amount_str":"0.01630628","amount_traded":"0","amount_at_create":"0.01630628","price":61326,"price_str":"61326"},"channel":"live_orders_btcusd","event":"order_created"}
{"data":{"id":1722049030615041,"id_str":"1722049030615041","order_type":0,"datetime":"1709257101","microtimestamp":"1709257101272000","amount":0.4894229,"amount_str":"0.48942290","amount_traded":"0","amount_at_create":"0.48942290","price":61296,"price_str":"61296"},"channel":"live_orders_btcusd","event":"order_created"}
{"data":{"id":1722049030615042,"id_str":"1722049030615042","order_type":0,"datetime":"1709257101","microtimestamp":"1709257101272000","amount":0.00815314,"amount_str":"0.00815314","amount_traded":"0","amount_at_create":"0.00815314","price":61323,"price_str":"61323"},"channel":"live_orders_btcusd","event":"order_created"}
{"data":{"id":1722049030619136,"id_str":"1722049030619136","order_type":0,"datetime":"1709257101","microtimestamp":"1709257101273000","amount":0.48923737,"amount_str":"0.48923737","amount_traded":"0","amount_at_create":"0.48923737","price":61319,"price_str":"61319"},"channel":"live_orders_btcusd","event":"order_created"}
{"data":{"id":1722049030635520,"id_str":"1722049030635520","order_type":0,"datetime":"1709257101","microtimestamp":"1709257101277000","amount":0.48920487,"amount_str":"0.48920487","amount_traded":"0","amount_at_create":"0.48920487","price":61324,"price_str":"61324"},"channel":"live_orders_btcusd","event":"order_created"}
{"data":{"id":1722049030684672,"id_str":"1722049030684672","order_type":1,"datetime":"1709257101","microtimestamp":"1709257101289000","amount":0.00487275,"amount_str":"0.00487275","amount_traded":"0","amount_at_create":"0.00487275","price":61340,"price_str":"61340"},"channel":"live_orders_btcusd","event":"order_created"}
{"data":{"id":1722049030594561,"id_str":"1722049030594561","order_type":1,"datetime":"1709257101","microtimestamp":"1709257101293000","amount":0.48912424,"amount_str":"0.48912424","amount_traded":"0","amount_at_create":"0.48912424","price":61335,"price_str":"61335"},"channel":"live_orders_btcusd","event":"order_deleted"}
{"data":{"id":1722049030606848,"id_str":"1722049030606848","order_type":1,"datetime":"1709257101","microtimestamp":"1709257101293000","amount":0.48909405,"amount_str":"0.48909405","amount_traded":"0","amount_at_create":"0.48909405","price":61338,"price_str":"61338"},"channel":"live_orders_btcusd","event":"order_deleted"}
{"data":{"id":1722049030610944,"id_str":"1722049030610944","order_type":1,"datetime":"1709257101","microtimestamp":"1709257101294000","amount":0.0163047,"amount_str":"0.01630470","amount_traded":"0","amount_at_create":"0.01630470","price":61332,"price_str":"61332"},"channel":"live_orders_btcusd","event":"order_deleted"}
{"data":{"id":1722048983076866,"id_str":"1722048983076866","order_type":0,"datetime":"1709257101","microtimestamp":"1709257101296000","amount":0.16306829,"amount_str":"0.16306829","amount_traded":"0","amount_at_create":"0.16306829","price":61300,"price_str":"61300"},"channel":"live_orders_btcusd","event":"order_deleted"}
{"data":{"id":1722049028059136,"id_str":"1722049028059136","order_type":0,"datetime":"1709257101","microtimestamp":"1709257101306000","amount":0.00093264,"amount_str":"0.00093264","amount_traded":"0","amount_at_create":"0.00093264","price":61322,"price_str":"61322"},"channel":"live_orders_btcusd","event":"order_deleted"}
{"data":{"id":1722049030615040,"id_str":"1722049030615040","order_type":0,"datetime":"1709257101","microtimestamp":"1709257101308000","amount":0.01630628,"amount_str":"0.01630628","amount_traded":"0","amount_at_create":"0.01630628","price":61326,"price_str":"61326"},"channel":"live_orders_btcusd","event":"order_deleted"}
{"data":{"id":1722049030500352,"id_str":"1722049030500352","order_type":1,"datetime":"1709257101","microtimestamp":"1709257101310000","amount":0.00487275,"amount_str":"0.00487275","amount_traded":"0","amount_at_create":"0.00487275","price":61337,"price_str":"61337"},"channel":"live_orders_btcusd","event":"order_deleted"}
{"data":{"id":1722049000677379,"id_str":"1722049000677379","order_type":1,"datetime":"1709257101","microtimestamp":"1709257101317000","amount":0.09745917,"amount_str":"0.09745917","amount_traded":"0","amount_at_create":"0.09745917","price":61352,"price_str":"61352"},"channel":"live_orders_btcusd","event":"order_deleted"}
{"data":{"id":1722049030873090,"id_str":"1722049030873090","order_type":0,"datetime":"1709257101","microtimestamp":"1709257101335000","amount":0.16306297,"amount_str":"0.16306297","amount_traded":"0","amount_at_create":"0.16306297","price":61306,"price_str":"61306"},"channel":"live_orders_btcusd","event":"order_created"}
{"data":{"id":1722049030946819,"id_str":"1722049030946819","order_type":1,"datetime":"1709257101","microtimestamp":"1709257101353000","amount":0.09745519,"amount_str":"0.09745519","amount_traded":"0","amount_at_create":"0.09745519","price":61360,"price_str":"61360"},"channel":"live_orders_btcusd","event":"order_created"}
{"data":{"id":1722049030422535,"id_str":"1722049030422535","order_type":0,"datetime":"1709257101","microtimestamp":"1709257101360000","amount":0.00815314,"amount_str":"0.00815314","amount_traded":"0","amount_at_create":"0.00815314","price":61321,"price_str":"61321"},"channel":"live_orders_btcusd","event":"order_deleted"}
{"data":{"id":1722049031053313,"id_str":"1722049031053313","order_type":0,"datetime":"1709257101","microtimestamp":"1709257101379000","amount":0.00815274,"amount_str":"0.00815274","amount_traded":"0","amount_at_create":"0.00815274","price":61325,"price_str":"61325"},"channel":"live_orders_btcusd","event":"order_created"}
{"data":{"id":1722049030635520,"id_str":"1722049030635520","order_type":0,"datetime":"1709257101","microtimestamp":"1709257101398000","amount":0.48920487,"amount_str":"0.48920487","amount_traded":"0","amount_at_create":"0.48920487","price":61324,"price_str":"61324"},"channel":"live_orders_btcusd","event":"order_deleted"}
{"data":{"id":1722049031168000,"id_str":"1722049031168000","order_type":0,"datetime":"1709257101","microtimestamp":"1709257101407000","amount":0.01630641,"amount_str":"0.01630641","amount_traded":"0","amount_at_create":"0.01630641","price":61325,"price_str":"61325"},"channel":"live_orders_btcusd","event":"order_created"}
{"data":{"id":1722049031168001,"id_str":"1722049031168001","order_type":1,"datetime":"1709257101","microtimestamp":"1709257101407000","amount":0.01630475,"amount_str":"0.01630475","amount_traded":"0","amount_at_create":"0.01630475","price":61332,"price_str":"61332"},"channel":"live_orders_btcusd","event":"order_created"}
{"data":{"id":1722049028247552,"id_str":"1722049028247552","order_type":0,"datetime":"1709257101","microtimestamp":"1709257101416000","amount":0.00040756,"amount_str":"0.00040756","amount_traded":"0","amount_at_create":"0.00040756","price":61317,"price_str":"61317"},"channel":"live_orders_btcusd","event":"order_deleted"}
{"data":{"id":1722049030684672,"id_str":"1722049030684672","order_type":1,"datetime":"1709257101","microtimestamp":"1709257101417000","amount":0.00487275,"amount_str":"0.00487275","amount_traded":"0","amount_at_create":"0.00487275","price":61340,"price_str":"61340"},"channel":"live_orders_btcusd","event":"order_deleted"}
{"data":{"id":1722049031168001,"id_str":"1722049031168001","order_type":1,"datetime":"1709257101","microtimestamp":"1709257101421000","amount":0.01630475,"amount_str":"0.01630475","amount_traded":"0","amount_at_create":"0.01630475","price":61332,"price_str":"61332"},"channel":"live_orders_btcusd","event":"order_deleted"}
{"data":{"id":1722049031307266,"id_str":"1722049031307266","order_type":0,"datetime":"1709257101","microtimestamp":"1709257101442000","amount":0.00093247,"amount_str":"0.00093247","amount_traded":"0","amount_at_create":"0.00093247","price":61325,"price_str":"61325"},"channel":"live_orders_btcusd","event":"order_created"}
{"data":{"id":1722049031380996,"id_str":"1722049031380996","order_type":1,"datetime":"1709257101","microtimestamp":"1709257101460000","amount":0.00487224,"amount_str":"0.00487224","amount_traded":"0","amount_at_create":"0.00487224","price":61342,"price_str":"61342"},"channel":"live_orders_btcusd","event":"order_created"}
{"data":{"id":1722049031413760,"id_str":"1722049031413760","order_type":0,"datetime":"1709257101","microtimestamp":"1709257101467000","amount":0.4892173,"amount_str":"0.48921730","amount_traded":"0","amount_at_create":"0.48921730","price":61322,"price_str":"61322"},"channel":"live_orders_btcusd","event":"order_created"}
{"data":{"id":1722049031454723,"id_str":"1722049031454723","order_type":1,"datetime":"1709257101","microtimestamp":"1709257101478000","amount":0.1875,"amount_str":"0.18750000","amount_traded":"0","amount_at_create":"0.18750000","price":61341,"price_str":"61341"},"channel":"live_orders_btcusd","event":"order_created"}
{"data":{"id":1722049031581699,"id_str":"1722049031581699","order_type":0,"datetime":"1709257102","microtimestamp":"1709257101509000","amount":0.00040756,"amount_str":"0.00040756","amount_traded":"0","amount_at_create":"0.00040756","price":61316,"price_str":"61316"},"channel":"live_orders_btcusd","event":"order_created"}
{"data":{"id":1722049031589889,"id_str":"1722049031589889","order_type":1,"datetime":"1709257102","microtimestamp":"1709257101510000","amount":0.01630501,"amount_str":"0.01630501","amount_traded":"0","amount_at_create":"0.01630501","price":61331,"price_str":"61331"},"channel":"live_orders_btcusd","event":"order_created"}
{"data":{"id":1722049031454723,"id_str":"1722049031454723","order_type":1,"datetime":"1709257102","microtimestamp":"1709257101511000","amount":0.1875,"amount_str":"0.18750000","amount_traded":"0","amount_at_create":"0.18750000","price":61341,"price_str":"61341"},"channel":"live_orders_btcusd","event":"order_deleted"}
{"data":{"id":1722049031757826,"id_str":"1722049031757826","order_type":1,"datetime":"1709257102","microtimestamp":"1709257101551000","amount":0.40767339,"amount_str":"0.40767339","amount_traded":"0","amount_at_create":"0.40767339","price":61341,"price_str":"61341"},"channel":"live_orders_btcusd","event":"order_created"}
{"data":{"id":1722048980664322,"id_str":"1722048980664322","order_type":1,"datetime":"1709257102","microtimestamp":"1709257101566000","amount":0.40757636,"amount_str":"0.40757636","amount_traded":"0","amount_at_create":"0.40757636","price":61352,"price_str":"61352"},"channel":"live_orders_btcusd","event":"order_deleted"}
{"data":{"id":1722049031168000,"id_str":"1722049031168000","order_type":0,"datetime":"1709257102","microtimestamp":"1709257101601000","amount":0.01630641,"amount_str":"0.01630641","amount_traded":"0","amount_at_create":"0.01630641","price":61325,"price_str":"61325"},"channel":"live_orders_btcusd","event":"order_deleted"}
{"data":{"id":1722049031589889,"id_str":"1722049031589889","order_type":1,"datetime":"1709257102","microtimestamp":"1709257101628000","amount":0.01630501,"amount_str":"0.01630501","amount_traded":"0","amount_at_create":"0.01630501","price":61331,"price_str":"61331"},"channel":"live_orders_btcusd","event":"order_deleted"}
{"data":{"id":1722049031053313,"id_str":"1722049031053313","order_type":0,"datetime":"1709257102","microtimestamp":"1709257101628000","amount":0.00815274,"amount_str":"0.00815274","amount_traded":"0","amount_at_create":"0.00815274","price":61325,"price_str":"61325"},"channel":"live_orders_btcusd","event":"order_deleted"}
{"data":{"id":1722049032138757,"id_str":"1722049032138757","order_type":0,"datetime":"1709257102","microtimestamp":"1709257101644000","amount":0.01630687,"amount_str":"0.01630687","amount_traded":"0","amount_at_create":"0.01630687","price":61323,"price_str":"61323"},"channel":"live_orders_btcusd","event":"order_created"}
{"data":{"id":1722049032323073,"id_str":"1722049032323073","order_type":1,"datetime":"1709257102","microtimestamp":"1709257101690000","amount":0.48914321,"amount_str":"0.48914321","amount_traded":"0","amount_at_create":"0.48914321","price":61332,"price_str":"61332"},"channel":"live_orders_btcusd","event":"order_created"}
{"data":{"id":1722049032327168,"id_str":"1722049032327168","order_type":1,"datetime":"1709257102","microtimestamp":"1709257101690000","amount":0.01630526,"amount_str":"0.01630526","amount_traded":"0","amount_at_create":"0.01630526","price":61330,"price_str":"61330"},"channel":"live_orders_btcusd","event":"order_created"}
{"data":{"id":1722049031413760,"id_str":"1722049031413760","order_type":0,"datetime":"1709257102","microtimestamp":"1709257101698000","amount":0.4892173,"amount_str":"0.48921730","amount_traded":"0","amount_at_create":"0.48921730","price":61322,"price_str":"61322"},"channel":"live_orders_btcusd","event":"order_deleted"}
{"data":{"id":1722049030619136,"id_str":"1722049030619136","order_type":0,"datetime":"1709257102","microtimestamp":"1709257101699000","amount":0.48923737,"amount_str":"0.48923737","amount_traded":"0","amount_at_create":"0.48923737","price":61319,"price_str":"61319"},"channel":"live_orders_btcusd","event":"order_deleted"}
{"data":{"id":1722049030606849,"id_str":"1722049030606849","order_type":1,"datetime":"1709257102","microtimestamp":"1709257101700000","amount":0.48903553,"amount_str":"0.48903553","amount_traded":"0","amount_at_create":"0.48903553","price":61346,"price_str":"61346"},"channel":"live_orders_btcusd","event":"order_deleted"}
{"data":{"id":1722049032327168,"id_str":"1722049032327168","order_type":1,"datetime":"1709257102","microtimestamp":"1709257101704000","amount":0.01630526,"amount_str":"0.01630526","amount_traded":"0","amount_at_create":"0.01630526","price":61330,"price_str":"61330"},"channel":"live_orders_btcusd","event":"order_deleted"}
{"data":{"id":1722049032425474,"id_str":"1722049032425474","order_type":0,"datetime":"1709257102","microtimestamp":"1709257101714000","amount":0.00815221,"amount_str":"0.00815221","amount_traded":"0","amount_at_create":"0.00815221","price":61325,"price_str":"61325"},"channel":"live_orders_btcusd","event":"order_created"}
{"data":{"id":1722049031581699,"id_str":"1722049031581699","order_type":0,"datetime":"1709257102","microtimestamp":"1709257101745000","amount":0.00040756,"amount_str":"0.00040756","amount_traded":"0","amount_at_create":"0.00040756","price":61316,"price_str":"61316"},"channel":"live_orders_btcusd","event":"order_deleted"}
{"data":{"id":1722049032568832,"id_str":"1722049032568832","order_type":0,"datetime":"1709257102","microtimestamp":"1709257101749000","amount":0.48923128,"amount_str":"0.48923128","amount_traded":"0","amount_at_create":"0.48923128","price":61320,"price_str":"61320"},"channel":"live_orders_btcusd","event":"order_created"}
{"data":{"id":1722049032425474,"id_str":"1722049032425474","order_type":0,"datetime":"1709257102","microtimestamp":"1709257101765000","amount":0.00815221,"amount_str":"0.00815221","amount_traded":"0","amount_at_create":"0.00815221","price":61325,"price_str":"61325"},"channel":"live_orders_btcusd","event":"order_deleted"}
{"data":{"id":1722049032744961,"id_str":"1722049032744961","order_type":1,"datetime":"1709257102","microtimestamp":"1709257101793000","amount":0.40767339,"amount_str":"0.40767339","amount_traded":"0","amount_at_create":"0.40767339","price":61342,"price_str":"61342"},"channel":"live_orders_btcusd","event":"order_created"}
{"data":{"id":1722049032744962,"id_str":"1722049032744962","order_type":1,"datetime":"1709257102","microtimestamp":"1709257101793000","amount":0.48911155,"amount_str":"0.48911155","amount_traded":"0","amount_at_create":"0.48911155","price":61336,"price_str":"61336"},"channel":"live_orders_btcusd","event":"order_created"}
{"data":{"id":1722049032749057,"id_str":"1722049032749057","order_type":1,"datetime":"1709257102","microtimestamp":"1709257101793000","amount":0.0163055,"amount_str":"0.01630550","amount_traded":"0","amount_at_create":"0.01630550","price":61329,"price_str":"61329"},"channel":"live_orders_btcusd","event":"order_created"}
{"data":{"id":1722049032753152,"id_str":"1722049032753152","order_type":0,"datetime":"1709257102","microtimestamp":"1709257101794000","amount":0.48926295,"amount_str":"0.48926295","amount_traded":"0","amount_at_create":"0.48926295","price":61316,"price_str":"61316"},"channel":"live_orders_btcusd","event":"order_created"}
{"data":{"id":1722049032794112,"id_str":"1722049032794112","order_type":1,"datetime":"1709257102","microtimestamp":"1709257101804000","amount":0.0048722,"amount_str":"0.00487220","amount_traded":"0","amount_at_create":"0.00487220","price":61340,"price_str":"61340"},"channel":"live_orders_btcusd","event":"order_created"}
{"data":{"id":1722049000595457,"id_str":"1722049000595457","order_type":1,"datetime":"1709257102","microtimestamp":"1709257101807000","amount":0.40767339,"amount_str":"0.40767339","amount_traded":"0","amount_at_create":"0.40767339","price":61343,"price_str":"61343"},"channel":"live_orders_btcusd","event":"order_deleted"}
{"data":{"id":1722049032851457,"id_str":"1722049032851457","order_type":0,"datetime":"1709257102","microtimestamp":"1709257101818000","amount":0.00040756,"amount_str":"0.00040756","amount_traded":"0","amount_at_create":"0.00040756","price":61317,"price_str":"61317"},"channel":"live_orders_btcusd","event":"order_created"}
{"data":{"id":1722049030615042,"id_str":"1722049030615042","order_type":0,"datetime":"1709257102","microtimestamp":"1709257101835000","amount":0.00815314,"amount_str":"0.00815314","amount_traded":"0","amount_at_create":"0.00815314","price":61323,"price_str":"61323"},"channel":"live_orders_btcusd","event":"order_deleted"}
{"data":{"id":1722049032957955,"id_str":"1722049032957955","order_type":1,"datetime":"1709257102","microtimestamp":"1709257101844000","amount":0.1875,"amount_str":"0.18750000","amount_traded":"0","amount_at_create":"0.18750000","price":61343,"price_str":"61343"},"channel":"live_orders_btcusd","event":"order_created"}
{"data":{"id":1722049031307266,"id_str":"1722049031307266","order_type":0,"datetime":"1709257102","microtimestamp":"1709257101861000","amount":0.00093247,"amount_str":"0.00093247","amount_traded":"0","amount_at_create":"0.00093247","price":61325,"price_str":"61325"},"channel":"live_orders_btcusd","event":"order_deleted"}
{"data":{"id":1722049031380996,"id_str":"1722049031380996","order_type":1,"datetime":"1709257102","microtimestamp":"1709257101874000","amount":0.00487224,"amount_str":"0.00487224","amount_traded":"0","amount_at_create":"0.00487224","price":61342,"price_str":"61342"},"channel":"live_orders_btcusd","event":"order_deleted"}
{"data":{"id":1722049033146368,"id_str":"1722049033146368","order_type":1,"datetime":"1709257102","microtimestamp":"1709257101890000","amount":0.00487268,"amount_str":"0.00487268","amount_traded":"0","amount_at_create":"0.00487268","price":61337,"price_str":"61337"},"channel":"live_orders_btcusd","event":"order_created"}
{"data":{"id":1722049032568832,"id_str":"1722049032568832","order_type":0,"datetime":"1709257102","microtimestamp":"1709257101897000","amount":0.48923128,"amount_str":"0.48923128","amount_traded":"0","amount_at_create":"0.48923128","price":61320,"price_str":"61320"},"channel":"live_orders_btcusd","event":"order_deleted"}
{"data":{"id":1722049033236480,"id_str":"1722049033236480","order_type":0,"datetime":"1709257102","microtimestamp":"1709257101912000","amount":0.00815301,"amount_str":"0.00815301","amount_traded":"0","amount_at_create":"0.00815301","price":61321,"price_str":"61321"},"channel":"live_orders_btcusd","event":"order_created"}
{"data":{"id":1722049033293824,"id_str":"1722049033293824","order_type":0,"datetime":"1709257102","microtimestamp":"1709257101927000","amount":0.00093264,"amount_str":"0.00093264","amount_traded":"0","amount_at_create":"0.00093264","price":61321,"price_str":"61321"},"channel":"live_orders_btcusd","event":"order_created"}
{"data":{"id":1722049033293824,"id_str":"1722049033293824","order_type":0,"datetime":"1709257102","microtimestamp":"1709257102026000","amount":0.00093264,"amount_str":"0.00093264","amount_traded":"0","amount_at_create":"0.00093264","price":61321,"price_str":"61321"},"channel":"live_orders_btcusd","event":"order_deleted"}
{"data":{"id":1722049033711617,"id_str":"1722049033711617","order_type":0,"datetime":"1709257102","microtimestamp":"1709257102028000","amount":0.48922749,"amount_str":"0.48922749","amount_traded":"0","amount_at_create":"0.48922749","price":61321,"price_str":"61321"},"channel":"live_orders_btcusd","event":"order_created"}
{"data":{"id":1722049034117120,"id_str":"1722049034117120","order_type":0,"datetime":"1709257102","microtimestamp":"1709257102127000","amount":0.00093264,"amount_str":"0.00093264","amount_traded":"0","amount_at_create":"0.00093264","price":61322,"price_str":"61322"},"channel":"live_orders_btcusd","event":"order_created"}
{"data":{"id":1722049032749057,"id_str":"1722049032749057","order_type":1,"datetime":"1709257102","microtimestamp":"1709257102208000","amount":0.0163055,"amount_str":"0.01630550","amount_traded":"0","amount_at_create":"0.01630550","price":61329,"price_str":"61329"},"channel":"live_orders_btcusd","event":"order_deleted"}
{"data":{"id":1722049034625024,"id_str":"1722049034625024","order_type":1,"datetime":"1709257102","microtimestamp":"1709257102251000","amount":0.01630523,"amount_str":"0.01630523","amount_traded":"0","amount_at_create":"0.01630523","price":61330,"price_str":"61330"},"channel":"live_orders_btcusd","event":"order_created"}
{"data":{"id":1722049001299968,"id_str":"1722049001299968","order_type":1,"datetime":"1709257102","microtimestamp":"1709257102280000","amount":0.03062118,"amount_str":"0.03062118","amount_traded":"0","amount_at_create":"0.03062118","price":61342,"price_str":"61342"},"channel":"live_orders_btcusd","event":"order_deleted"}
{"data":{"id":1722049033146368,"id_str":"1722049033146368","order_type":1,"datetime":"1709257102","microtimestamp":"1709257102284000","amount":0.00487268,"amount_str":"0.00487268","amount_traded":"0","amount_at_create":"0.00487268","price":61337,"price_str":"61337"},"channel":"live_orders_btcusd","event":"order_deleted"}
{"data":{"id":1722049032753152,"id_str":"1722049032753152","order_type":0,"datetime":"1709257102","microtimestamp":"1709257102297000","amount":0.48926295,"amount_str":"0.48926295","amount_traded":"0","amount_at_create":"0.48926295","price":61316,"price_str":"61316"},"channel":"live_orders_btcusd","event":"order_deleted"}
{"data":{"id":1722049032138757,"id_str":"1722049032138757","order_type":0,"datetime":"1709257102","microtimestamp":"1709257102297000","amount":0.01630687,"amount_str":"0.01630687","amount_traded":"0","amount_at_create":"0.01630687","price":61323,"price_str":"61323"},"channel":"live_orders_btcusd","event":"order_deleted"}
{"data":{"id":1722049034813444,"id_str":"1722049034813444","order_type":1,"datetime":"1709257102","microtimestamp":"1709257102298000","amount":0.48905797,"amount_str":"0.48905797","amount_traded":"0","amount_at_create":"0.48905797","price":61343,"price_str":"61343"},"channel":"live_orders_btcusd","event":"order_created"}
{"data":{"id":1722049033711617,"id_str":"1722049033711617","order_type":0,"datetime":"1709257102","microtimestamp":"1709257102299000","amount":0.48922749,"amount_str":"0.48922749","amount_traded":"0","amount_at_create":"0.48922749","price":61321,"price_str":"61321"},"channel":"live_orders_btcusd","event":"order_deleted"}
{"data":{"id":1722049005453312,"id_str":"1722049005453312","order_type":0,"datetime":"1709257102","microtimestamp":"1709257102304000","amount":0.16334956,"amount_str":"0.16334956","amount_traded":"0","amount_at_create":"0.16334956","price":61218,"price_str":"61218"},"channel":"live_orders_btcusd","event":"order_deleted"}
{"data":{"id":1722049032323073,"id_str":"1722049032323073","order_type":1,"datetime":"1709257102","microtimestamp":"1709257102306000","amount":0.48914321,"amount_str":"0.48914321","amount_traded":"0","amount_at_create":"0.48914321","price":61332,"price_str":"61332"},"channel":"live_orders_btcusd","event":"order_deleted"}
{"data":{"id":1722049034625024,"id_str":"1722049034625024","order_type":1,"datetime":"1709257102","microtimestamp":"1709257102307000","amount":0.01630523,"amount_str":"0.01630523","amount_traded":"0","amount_at_create":"0.01630523","price":61330,"price_str":"61330"},"channel":"live_orders_btcusd","event":"order_deleted"}
{"data":{"id":1722049032744962,"id_str":"1722049032744962","order_type":1,"datetime":"1709257102","microtimestamp":"1709257102308000","amount":0.48911155,"amount_str":"0.48911155","amount_traded":"0","amount_at_create":"0.48911155","price":61336,"price_str":"61336"},"channel":"live_orders_btcusd","event":"order_deleted"}
{"data":{"id":1722049030615041,"id_str":"1722049030615041","order_type":0,"datetime":"1709257102","microtimestamp":"1709257102308000","amount":0.4894229,"amount_str":"0.48942290","amount_traded":"0","amount_at_create":"0.48942290","price":61296,"price_str":"61296"},"channel":"live_orders_btcusd","event":"order_deleted"}
{"data":{"id":1722049034813444,"id_str":"1722049034813444","order_type":1,"datetime":"1709257102","microtimestamp":"1709257102313000","amount":0.48905797,"amount_str":"0.48905797","amount_traded":"0","amount_at_create":"0.48905797","price":61343,"price_str":"61343"},"channel":"live_orders_btcusd","event":"order_deleted"}
{"data":{"id":1722049034887169,"id_str":"1722049034887169","order_type":0,"datetime":"1709257102","microtimestamp":"1709257102315000","amount":0.00815314,"amount_str":"0.00815314","amount_traded":"0","amount_at_create":"0.00815314","price":61324,"price_str":"61324"},"channel":"live_orders_btcusd","event":"order_created"}
{"data":{"id":1722049032794112,"id_str":"1722049032794112","order_type":1,"datetime":"1709257102","microtimestamp":"1709257102322000","amount":0.0048722,"amount_str":"0.00487220","amount_traded":"0","amount_at_create":"0.00487220","price":61340,"price_str":"61340"},"channel":"live_orders_btcusd","event":"order_deleted"}
{"data":{"id":1722049032957955,"id_str":"1722049032957955","order_type":1,"datetime":"1709257102","microtimestamp":"1709257102323000","amount":0.1875,"amount_str":"0.18750000","amount_traded":"0","amount_at_create":"0.18750000","price":61343,"price_str":"61343"},"channel":"live_orders_btcusd","event":"order_deleted"}
{"data":{"id":1722049030598656,"id_str":"1722049030598656","order_type":1,"datetime":"1709257102","microtimestamp":"1709257102339000","amount":0.02414301,"amount_str":"0.02414301","amount_traded":"0","amount_at_create":"0.02414301","price":61347,"price_str":"61347"},"channel":"live_orders_btcusd","event":"order_deleted"}
{"data":{"id":1722049034993667,"id_str":"1722049034993667","order_type":1,"datetime":"1709257102","microtimestamp":"1709257102341000","amount":0.00487272,"amount_str":"0.00487272","amount_traded":"0","amount_at_create":"0.00487272","price":61344,"price_str":"61344"},"channel":"live_orders_btcusd","event":"order_created"}
{"data":{"id":1722049035075586,"id_str":"1722049035075586","order_type":0,"datetime":"1709257102","microtimestamp":"1709257102361000","amount":0.48919478,"amount_str":"0.48919478","amount_traded":"0","amount_at_create":"0.48919478","price":61325,"price_str":"61325"},"channel":"live_orders_btcusd","event":"order_created"}
