{"data":{"id":1722049082527746,"id_str":"1722049082527746","order_type":1,"datetime":"1709257114","microtimestamp":"1709257113946000","amount":0.48913309,"amount_str":"0.48913309","amount_traded":"0","amount_at_create":"0.48913309","price":61333,"price_str":"61333"},"channel":"live_orders_btcusd","event":"order_created"}
{"data":{"id":1722049082527748,"id_str":"1722049082527748","order_type":1,"datetime":"1709257114","microtimestamp":"1709257113947000","amount":0.01630524,"amount_str":"0.01630524","amount_traded":"0","amount_at_create":"0.01630524","price":61330,"price_str":"61330"},"channel":"live_orders_btcusd","event":"order_created"}
{"data":{"id":1722049082695681,"id_str":"1722049082695681","order_type":1,"datetime":"1709257114","microtimestamp":"1709257113987000","amount":0.04875518,"amount_str":"0.04875518","amount_traded":"0","amount_at_create":"0.04875518","price":61354,"price_str":"61354"},"channel":"live_orders_btcusd","event":"order_created"}
{"data":{"id":1722049080913920,"id_str":"1722049080913920","order_type":0,"datetime":"1709257114","microtimestamp":"1709257113997000","amount":0.48925966,"amount_str":"0.48925966","amount_traded":"0","amount_at_create":"0.48925966","price":61317,"price_str":"61317"},"channel":"live_orders_btcusd","event":"order_deleted"}
{"data":{"id":1722049082941441,"id_str":"1722049082941441","order_type":0,"datetime":"1709257114","microtimestamp":"1709257114047000","amount":0.48926999,"amount_str":"0.48926999","amount_traded":"0","amount_at_create":"0.48926999","price":61315,"price_str":"61315"},"channel":"live_orders_btcusd","event":"order_created"}
{"data":{"id":1722049067737088,"id_str":"1722049067737088","order_type":1,"datetime":"1709257114","microtimestamp":"1709257114115000","amount":0.00487272,"amount_str":"0.00487272","amount_traded":"0","amount_at_create":"0.00487272","price":61336,"price_str":"61336"},"channel":"live_orders_btcusd","event":"order_deleted"}
{"data":{"id":1722049083392000,"id_str":"1722049083392000","order_type":1,"datetime":"1709257114","microtimestamp":"1709257114157000","amount":0.00487283,"amount_str":"0.00487283","amount_traded":"0","amount_at_create":"0.00487283","price":61332,"price_str":"61332"},"channel":"live_orders_btcusd","event":"order_created"}
{"data":{"id":1722049083977729,"id_str":"1722049083977729","order_type":0,"datetime":"1709257114","microtimestamp":"1709257114300000","amount":0.06520492,"amount_str":"0.06520492","amount_traded":"0","amount_at_create":"0.06520492","price":61301,"price_str":"61301"},"channel":"live_orders_btcusd","event":"order_created"}
{"data":{"id":1722049082527746,"id_str":"1722049082527746","order_type":1,"datetime":"1709257114","microtimestamp":"1709257114310000","amount":0.48913309,"amount_str":"0.48913309","amount_traded":"0","amount_at_create":"0.48913309","price":61333,"price_str":"61333"},"channel":"live_orders_btcusd","event":"order_deleted"}
{"data":{"id":1722049084198912,"id_str":"1722049084198912","order_type":1,"datetime":"1709257114","microtimestamp":"1709257114354000","amount":0.48914317,"amount_str":"0.48914317","amount_traded":"0","amount_at_create":"0.48914317","price":61332,"price_str":"61332"},"channel":"live_orders_btcusd","event":"order_created"}
{"data":{"id":1722049082941441,"id_str":"1722049082941441","order_type":0,"datetime":"1709257114","microtimestamp":"1709257114498000","amount":0.48926999,"amount_str":"0.48926999","amount_traded":"0","amount_at_create":"0.48926999","price":61315,"price_str":"61315"},"channel":"live_orders_btcusd","event":"order_deleted"}
{"data":{"id":1722049084968963,"id_str":"1722049084968963","order_type":0,"datetime":"1709257115","microtimestamp":"1709257114543000","amount":0.48926683,"amount_str":"0.48926683","amount_traded":"0","amount_at_create":"0.48926683","price":61316,"price_str":"61316"},"channel":"live_orders_btcusd","event":"order_created"}
{"data":{"id":1722048909688833,"id_str":"1722048909688833","order_type":0,"datetime":"1709257115","microtimestamp":"1709257114697000","amount":1.445688,"amount_str":"1.44568800","amount_traded":"0","amount_at_create":"1.44568800","price":61290,"price_str":"61290"},"channel":"live_orders_btcusd","event":"order_deleted"}
{"data":{"id":1722049085788163,"id_str":"1722049085788163","order_type":0,"datetime":"1709257115","microtimestamp":"1709257114743000","amount":1.445688,"amount_str":"1.44568800","amount_traded":"0","amount_at_create":"1.44568800","price":61274,"price_str":"61274"},"channel":"live_orders_btcusd","event":"order_created"}
{"data":{"id":1722049045200897,"id_str":"1722049045200897","order_type":1,"datetime":"1709257115","microtimestamp":"1709257114743000","amount":0.00033,"amount_str":"0.00033000","amount_traded":"0","amount_at_create":"0.00033000","price":61393,"price_str":"61393"},"channel":"live_orders_btcusd","event":"order_deleted"}
{"data":{"id":1722049086029826,"id_str":"1722049086029826","order_type":1,"datetime":"1709257115","microtimestamp":"1709257114802000","amount":0.00033,"amount_str":"0.00033000","amount_traded":"0","amount_at_create":"0.00033000","price":61395,"price_str":"61395"},"channel":"live_orders_btcusd","event":"order_created"}
{"data":{"id":1722049080913924,"id_str":"1722049080913924","order_type":0,"datetime":"1709257115","microtimestamp":"1709257114803000","amount":0.01630813,"amount_str":"0.01630813","amount_traded":"0","amount_at_create":"0.01630813","price":61319,"price_str":"61319"},"channel":"live_orders_btcusd","event":"order_deleted"}
{"data":{"id":1722049084968963,"id_str":"1722049084968963","order_type":0,"datetime":"1709257115","microtimestamp":"1709257114803000","amount":0.48926683,"amount_str":"0.48926683","amount_traded":"0","amount_at_create":"0.48926683","price":61316,"price_str":"61316"},"channel":"live_orders_btcusd","event":"order_deleted"}
{"data":{"id":1722049082527748,"id_str":"1722049082527748","order_type":1,"datetime":"1709257115","microtimestamp":"1709257114803000","amount":0.01630524,"amount_str":"0.01630524","amount_traded":"0","amount_at_create":"0.01630524","price":61330,"price_str":"61330"},"channel":"live_orders_btcusd","event":"order_deleted"}
{"data":{"id":1722049081700352,"id_str":"1722049081700352","order_type":1,"datetime":"1709257115","microtimestamp":"1709257114803000","amount":0.48911624,"amount_str":"0.48911624","amount_traded":"0","amount_at_create":"0.48911624","price":61336,"price_str":"61336"},"channel":"live_orders_btcusd","event":"order_deleted"}
{"data":{"id":1722049084198912,"id_str":"1722049084198912","order_type":1,"datetime":"1709257115","microtimestamp":"1709257114803000","amount":0.48914317,"amount_str":"0.48914317","amount_traded":"0","amount_at_create":"0.48914317","price":61332,"price_str":"61332"},"channel":"live_orders_btcusd","event":"order_deleted"}
{"data":{"id":1722049086271488,"id_str":"1722049086271488","order_type":1,"datetime":"1709257115","microtimestamp":"1709257114860000","amount":0.01630581,"amount_str":"0.01630581","amount_traded":"0","amount_at_create":"0.01630581","price":61328,"price_str":"61328"},"channel":"live_orders_btcusd","event":"order_created"}
{"data":{"id":1722049086279683,"id_str":"1722049086279683","order_type":0,"datetime":"1709257115","microtimestamp":"1709257114862000","amount":0.48928185,"amount_str":"0.48928185","amount_traded":"0","amount_at_create":"0.48928185","price":61314,"price_str":"61314"},"channel":"live_orders_btcusd","event":"order_created"}
{"data":{"id":1722049086279685,"id_str":"1722049086279685","order_type":1,"datetime":"1709257115","microtimestamp":"1709257114862000","amount":0.48915692,"amount_str":"0.48915692","amount_traded":"0","amount_at_create":"0.48915692","price":61331,"price_str":"61331"},"channel":"live_orders_btcusd","event":"order_created"}
{"data":{"id":1722049086279687,"id_str":"1722049086279687","order_type":1,"datetime":"1709257115","microtimestamp":"1709257114863000","amount":0.4891244,"amount_str":"0.48912440","amount_traded":"0","amount_at_create":"0.48912440","price":61335,"price_str":"61335"},"channel":"live_orders_btcusd","event":"order_created"}
{"data":{"id":1722049086283776,"id_str":"1722049086283776","order_type":0,"datetime":"1709257115","microtimestamp":"1709257114863000","amount":0.0163088,"amount_str":"0.01630880","amount_traded":"0","amount_at_create":"0.01630880","price":61316,"price_str":"61316"},"channel":"live_orders_btcusd","event":"order_created"}
{"data":{"id":1722049083977729,"id_str":"1722049083977729","order_type":0,"datetime":"1709257115","microtimestamp":"1709257114879000","amount":0.06520492,"amount_str":"0.06520492","amount_traded":"0","amount_at_create":"0.06520492","price":61301,"price_str":"61301"},"channel":"live_orders_btcusd","event":"order_deleted"}
{"data":{"id":1722049081634817,"id_str":"1722049081634817","order_type":0,"datetime":"1709257115","microtimestamp":"1709257114905000","amount":0.00914557,"amount_str":"0.00914557","amount_traded":"0","amount_at_create":"0.00914557","price":61320,"price_str":"61320"},"channel":"live_orders_btcusd","event":"order_deleted"}
{"data":{"id":1722049083392000,"id_str":"1722049083392000","order_type":1,"datetime":"1709257115","microtimestamp":"1709257114910000","amount":0.00487283,"amount_str":"0.00487283","amount_traded":"0","amount_at_create":"0.00487283","price":61332,"price_str":"61332"},"channel":"live_orders_btcusd","event":"order_deleted"}
{"data":{"id":1722049086746624,"id_str":"1722049086746624","order_type":0,"datetime":"1709257115","microtimestamp":"1709257114976000","amount":0.00815328,"amount_str":"0.00815328","amount_traded":"0","amount_at_create":"0.00815328","price":61319,"price_str":"61319"},"channel":"live_orders_btcusd","event":"order_created"}
{"data":{"id":1722049086283776,"id_str":"1722049086283776","order_type":0,"datetime":"1709257115","microtimestamp":"1709257115046000","amount":0.0163088,"amount_str":"0.01630880","amount_traded":"0","amount_at_create":"0.01630880","price":61316,"price_str":"61316"},"channel":"live_orders_btcusd","event":"order_deleted"}
{"data":{"id":1722049087217666,"id_str":"1722049087217666","order_type":0,"datetime":"1709257115","microtimestamp":"1709257115092000","amount":0.01630868,"amount_str":"0.01630868","amount_traded":"0","amount_at_create":"0.01630868","price":61317,"price_str":"61317"},"channel":"live_orders_btcusd","event":"order_created"}
{"data":{"id":1722049086279683,"id_str":"1722049086279683","order_type":0,"datetime":"1709257115","microtimestamp":"1709257115100000","amount":0.48928185,"amount_str":"0.48928185","amount_traded":"0","amount_at_create":"0.48928185","price":61314,"price_str":"61314"},"channel":"live_orders_btcusd","event":"order_deleted"}
{"data":{"id":1722049086746624,"id_str":"1722049086746624","order_type":0,"datetime":"1709257115","microtimestamp":"1709257115102000","amount":0.00815328,"amount_str":"0.00815328","amount_traded":"0","amount_at_create":"0.00815328","price":61319,"price_str":"61319"},"channel":"live_orders_btcusd","event":"order_deleted"}
{"data":{"id":1722049087438848,"id_str":"1722049087438848","order_type":0,"datetime":"1709257115","microtimestamp":"1709257115146000","amount":0.48927211,"amount_str":"0.48927211","amount_traded":"0","amount_at_create":"0.48927211","price":61315,"price_str":"61315"},"channel":"live_orders_btcusd","event":"order_created"}
{"data":{"id":1722049086271488,"id_str":"1722049086271488","order_type":1,"datetime":"1709257115","microtimestamp":"1709257115297000","amount":0.01630581,"amount_str":"0.01630581","amount_traded":"0","amount_at_create":"0.01630581","price":61328,"price_str":"61328"},"channel":"live_orders_btcusd","event":"order_deleted"}
{"data":{"id":1722049088241665,"id_str":"1722049088241665","order_type":1,"datetime":"1709257115","microtimestamp":"1709257115341000","amount":0.01630548,"amount_str":"0.01630548","amount_traded":"0","amount_at_create":"0.01630548","price":61330,"price_str":"61330"},"channel":"live_orders_btcusd","event":"order_created"}
{"data":{"id":1722049088241665,"id_str":"1722049088241665","order_type":1,"datetime":"1709257115","microtimestamp":"1709257115357000","amount":0.01630548,"amount_str":"0.01630548","amount_traded":"0","amount_at_create":"0.01630548","price":61330,"price_str":"61330"},"channel":"live_orders_btcusd","event":"order_deleted"}
{"data":{"id":1722049088499712,"id_str":"1722049088499712","order_type":0,"datetime":"1709257115","microtimestamp":"1709257115404000","amount":0.0163088,"amount_str":"0.01630880","amount_traded":"0","amount_at_create":"0.01630880","price":61303,"price_str":"61303"},"channel":"live_orders_btcusd","event":"order_created"}
{"data":{"id":1722049087438848,"id_str":"1722049087438848","order_type":0,"datetime":"1709257115","microtimestamp":"1709257115410000","amount":0.48927211,"amount_str":"0.48927211","amount_traded":"0","amount_at_create":"0.48927211","price":61315,"price_str":"61315"},"channel":"live_orders_btcusd","event":"order_deleted"}
{"data":{"id":1722049087217666,"id_str":"1722049087217666","order_type":0,"datetime":"1709257115","microtimestamp":"1709257115410000","amount":0.01630868,"amount_str":"0.01630868","amount_traded":"0","amount_at_create":"0.01630868","price":61317,"price_str":"61317"},"channel":"live_orders_btcusd","event":"order_deleted"}
{"data":{"id":1722049088708608,"id_str":"1722049088708608","order_type":0,"datetime":"1709257115","microtimestamp":"1709257115455000","amount":0.01630825,"amount_str":"0.01630825","amount_traded":"0","amount_at_create":"0.01630825","price":61318,"price_str":"61318"},"channel":"live_orders_btcusd","event":"order_created"}
{"data":{"id":1722049088712706,"id_str":"1722049088712706","order_type":1,"datetime":"1709257115","microtimestamp":"1709257115456000","amount":0.01630537,"amount_str":"0.01630537","amount_traded":"0","amount_at_create":"0.01630537","price":61330,"price_str":"61330"},"channel":"live_orders_btcusd","event":"order_created"}
{"data":{"id":1722049088712707,"id_str":"1722049088712707","order_type":0,"datetime":"1709257115","microtimestamp":"1709257115456000","amount":0.48926527,"amount_str":"0.48926527","amount_traded":"0","amount_at_create":"0.48926527","price":61316,"price_str":"61316"},"channel":"live_orders_btcusd","event":"order_created"}
{"data":{"id":1722049088712706,"id_str":"1722049088712706","order_type":1,"datetime":"1709257116","microtimestamp":"1709257115517000","amount":0.01630537,"amount_str":"0.01630537","amount_traded":"0","amount_at_create":"0.01630537","price":61330,"price_str":"61330"},"channel":"live_orders_btcusd","event":"order_deleted"}
{"data":{"id":1722049089138689,"id_str":"1722049089138689","order_type":1,"datetime":"1709257116","microtimestamp":"1709257115560000","amount":0.01630558,"amount_str":"0.01630558","amount_traded":"0","amount_at_create":"0.01630558","price":61329,"price_str":"61329"},"channel":"live_orders_btcusd","event":"order_created"}
{"data":{"id":1722049088708608,"id_str":"1722049088708608","order_type":0,"datetime":"1709257116","microtimestamp":"1709257115696000","amount":0.01630825,"amount_str":"0.01630825","amount_traded":"0","amount_at_create":"0.01630825","price":61318,"price_str":"61318"},"channel":"live_orders_btcusd","event":"order_deleted"}
{"data":{"id":1722049086279685,"id_str":"1722049086279685","order_type":1,"datetime":"1709257116","microtimestamp":"1709257115697000","amount":0.48915692,"amount_str":"0.48915692","amount_traded":"0","amount_at_create":"0.48915692","price":61331,"price_str":"61331"},"channel":"live_orders_btcusd","event":"order_deleted"}
{"data":{"id":1722049089871873,"id_str":"1722049089871873","order_type":0,"datetime":"1709257116","microtimestamp":"1709257115740000","amount":0.0163081,"amount_str":"0.01630810","amount_traded":"0","amount_at_create":"0.01630810","price":61319,"price_str":"61319"},"channel":"live_orders_btcusd","event":"order_created"}
{"data":{"id":1722049089888256,"id_str":"1722049089888256","order_type":1,"datetime":"1709257116","microtimestamp":"1709257115744000","amount":0.48913982,"amount_str":"0.48913982","amount_traded":"0","amount_at_create":"0.48913982","price":61333,"price_str":"61333"},"channel":"live_orders_btcusd","event":"order_created"}
{"data":{"id":1722049089138689,"id_str":"1722049089138689","order_type":1,"datetime":"1709257116","microtimestamp":"1709257115806000","amount":0.01630558,"amount_str":"0.01630558","amount_traded":"0","amount_at_create":"0.01630558","price":61329,"price_str":"61329"},"channel":"live_orders_btcusd","event":"order_deleted"}
{"data":{"id":1722049088712707,"id_str":"1722049088712707","order_type":0,"datetime":"1709257116","microtimestamp":"1709257115807000","amount":0.48926527,"amount_str":"0.48926527","amount_traded":"0","amount_at_create":"0.48926527","price":61316,"price_str":"61316"},"channel":"live_orders_btcusd","event":"order_deleted"}
{"data":{"id":1722049090342912,"id_str":"1722049090342912","order_type":1,"datetime":"1709257116","microtimestamp":"1709257115854000","amount":0.01630515,"amount_str":"0.01630515","amount_traded":"0","amount_at_create":"0.01630515","price":61331,"price_str":"61331"},"channel":"live_orders_btcusd","event":"order_created"}
{"data":{"id":1722049090351104,"id_str":"1722049090351104","order_type":0,"datetime":"1709257116","microtimestamp":"1709257115856000","amount":0.48925804,"amount_str":"0.48925804","amount_traded":"0","amount_at_create":"0.48925804","price":61317,"price_str":"61317"},"channel":"live_orders_btcusd","event":"order_created"}
{"data":{"id":1722049090342912,"id_str":"1722049090342912","order_type":1,"datetime":"1709257116","microtimestamp":"1709257115901000","amount":0.01630515,"amount_str":"0.01630515","amount_traded":"0","amount_at_create":"0.01630515","price":61331,"price_str":"61331"},"channel":"live_orders_btcusd","event":"order_deleted"}
{"data":{"id":1722049001869313,"id_str":"1722049001869313","order_type":0,"datetime":"1709257116","microtimestamp":"1709257115915000","amount":0.04893,"amount_str":"0.04893000","amount_traded":"0","amount_at_create":"0.04893000","price":61298,"price_str":"61298"},"channel":"live_orders_btcusd","event":"order_deleted"}
{"data":{"id":1722049068249090,"id_str":"1722049068249090","order_type":0,"datetime":"1709257116","microtimestamp":"1709257115916000","amount":0.00815308,"amount_str":"0.00815308","amount_traded":"0","amount_at_create":"0.00815308","price":61317,"price_str":"61317"},"channel":"live_orders_btcusd","event":"order_deleted"}
{"data":{"id":1722049079746564,"id_str":"1722049079746564","order_type":1,"datetime":"1709257116","microtimestamp":"1709257115918000","amount":0.03718287,"amount_str":"0.03718287","amount_traded":"0","amount_at_create":"0.03718287","price":61340,"price_str":"61340"},"channel":"live_orders_btcusd","event":"order_deleted"}
{"data":{"id":1722048981561344,"id_str":"1722048981561344","order_type":0,"datetime":"1709257116","microtimestamp":"1709257115918000","amount":0.815832,"amount_str":"0.81583200","amount_traded":"0","amount_at_create":"0.81583200","price":61305,"price_str":"61305"},"channel":"live_orders_btcusd","event":"order_deleted"}
{"data":{"id":1722049080487936,"id_str":"1722049080487936","order_type":1,"datetime":"1709257116","microtimestamp":"1709257115919000","amount":0.02485448,"amount_str":"0.02485448","amount_traded":"0","amount_at_create":"0.02485448","price":61343,"price_str":"61343"},"channel":"live_orders_btcusd","event":"order_deleted"}
{"data":{"id":1722049090654211,"id_str":"1722049090654211","order_type":1,"datetime":"1709257116","microtimestamp":"1709257115931000","amount":0.03718287,"amount_str":"0.03718287","amount_traded":"0","amount_at_create":"0.03718287","price":61334,"price_str":"61334"},"channel":"live_orders_btcusd","event":"order_created"}
{"data":{"id":1722049089888256,"id_str":"1722049089888256","order_type":1,"datetime":"1709257116","microtimestamp":"1709257115932000","amount":0.48913982,"amount_str":"0.48913982","amount_traded":"0","amount_at_create":"0.48913982","price":61333,"price_str":"61333"},"channel":"live_orders_btcusd","event":"order_deleted"}
{"data":{"id":1722049090351104,"id_str":"1722049090351104","order_type":0,"datetime":"1709257116","microtimestamp":"1709257115932000","amount":0.48925804,"amount_str":"0.48925804","amount_traded":"0","amount_at_create":"0.48925804","price":61317,"price_str":"61317"},"channel":"live_orders_btcusd","event":"order_deleted"}
{"data":{"id":1722049089871873,"id_str":"1722049089871873","order_type":0,"datetime":"1709257116","microtimestamp":"1709257115933000","amount":0.0163081,"amount_str":"0.01630810","amount_traded":"0","amount_at_create":"0.01630810","price":61319,"price_str":"61319"},"channel":"live_orders_btcusd","event":"order_deleted"}
{"data":{"id":1722049090666501,"id_str":"1722049090666501","order_type":1,"datetime":"1709257116","microtimestamp":"1709257115934000","amount":0.00487283,"amount_str":"0.00487283","amount_traded":"0","amount_at_create":"0.00487283","price":61332,"price_str":"61332"},"channel":"live_orders_btcusd","event":"order_created"}
{"data":{"id":1722049079500801,"id_str":"1722049079500801","order_type":0,"datetime":"1709257116","microtimestamp":"1709257115944000","amount":0.48947796,"amount_str":"0.48947796","amount_traded":"0","amount_at_create":"0.48947796","price":61289,"price_str":"61289"},"channel":"live_orders_btcusd","event":"order_deleted"}
{"data":{"id":1722049081708545,"id_str":"1722049081708545","order_type":0,"datetime":"1709257116","microtimestamp":"1709257115945000","amount":0.48929269,"amount_str":"0.48929269","amount_traded":"0","amount_at_create":"0.48929269","price":61312,"price_str":"61312"},"channel":"live_orders_btcusd","event":"order_deleted"}
{"data":{"id":1722049081708544,"id_str":"1722049081708544","order_type":1,"datetime":"1709257116","microtimestamp":"1709257115945000","amount":0.48895078,"amount_str":"0.48895078","amount_traded":"0","amount_at_create":"0.48895078","price":61356,"price_str":"61356"},"channel":"live_orders_btcusd","event":"order_deleted"}
{"data":{"id":1722049086279687,"id_str":"1722049086279687","order_type":1,"datetime":"1709257116","microtimestamp":"1709257115945000","amount":0.4891244,"amount_str":"0.48912440","amount_traded":"0","amount_at_create":"0.48912440","price":61335,"price_str":"61335"},"channel":"live_orders_btcusd","event":"order_deleted"}
{"data":{"id":1722049068236804,"id_str":"1722049068236804","order_type":0,"datetime":"1709257116","microtimestamp":"1709257115946000","amount":0.489571,"amount_str":"0.48957100","amount_traded":"0","amount_at_create":"0.48957100","price":61278,"price_str":"61278"},"channel":"live_orders_btcusd","event":"order_deleted"}
{"data":{"id":1722049079767041,"id_str":"1722049079767041","order_type":1,"datetime":"1709257116","microtimestamp":"1709257115946000","amount":0.48905682,"amount_str":"0.48905682","amount_traded":"0","amount_at_create":"0.48905682","price":61343,"price_str":"61343"},"channel":"live_orders_btcusd","event":"order_deleted"}
{"data":{"id":1722048996859907,"id_str":"1722048996859907","order_type":0,"datetime":"1709257116","microtimestamp":"1709257115946000","amount":0.48975725,"amount_str":"0.48975725","amount_traded":"0","amount_at_create":"0.48975725","price":61254,"price_str":"61254"},"channel":"live_orders_btcusd","event":"order_deleted"}
{"data":{"id":1722049027284994,"id_str":"1722049027284994","order_type":1,"datetime":"1709257116","microtimestamp":"1709257115947000","amount":0.48883136,"amount_str":"0.48883136","amount_traded":"0","amount_at_create":"0.48883136","price":61371,"price_str":"61371"},"channel":"live_orders_btcusd","event":"order_deleted"}
{"data":{"id":1722049090748418,"id_str":"1722049090748418","order_type":0,"datetime":"1709257116","microtimestamp":"1709257115954000","amount":0.00815328,"amount_str":"0.00815328","amount_traded":"0","amount_at_create":"0.00815328","price":61315,"price_str":"61315"},"channel":"live_orders_btcusd","event":"order_created"}
{"data":{"id":1722049039208448,"id_str":"1722049039208448","order_type":0,"datetime":"1709257116","microtimestamp":"1709257115960000","amount":0.16306297,"amount_str":"0.16306297","amount_traded":"0","amount_at_create":"0.16306297","price":61300,"price_str":"61300"},"channel":"live_orders_btcusd","event":"order_deleted"}
{"data":{"id":1722048982781952,"id_str":"1722048982781952","order_type":1,"datetime":"1709257116","microtimestamp":"1709257115960000","amount":0.16278032,"amount_str":"0.16278032","amount_traded":"0","amount_at_create":"0.16278032","price":61433,"price_str":"61433"},"channel":"live_orders_btcusd","event":"order_deleted"}
{"data":{"id":1722048981688320,"id_str":"1722048981688320","order_type":1,"datetime":"1709257116","microtimestamp":"1709257115962000","amount":0.06085916,"amount_str":"0.06085916","amount_traded":"0","amount_at_create":"0.06085916","price":61502,"price_str":"61502"},"channel":"live_orders_btcusd","event":"order_deleted"}
{"data":{"id":1722049079570436,"id_str":"1722049079570436","order_type":0,"datetime":"1709257116","microtimestamp":"1709257115963000","amount":3.06846121,"amount_str":"3.06846121","amount_traded":"0","amount_at_create":"3.06846121","price":61304,"price_str":"61304"},"channel":"live_orders_btcusd","event":"order_deleted"}
{"data":{"id":1722049080184833,"id_str":"1722049080184833","order_type":1,"datetime":"1709257116","microtimestamp":"1709257115963000","amount":0.48859845,"amount_str":"0.48859845","amount_traded":"0","amount_at_create":"0.48859845","price":61401,"price_str":"61401"},"channel":"live_orders_btcusd","event":"order_deleted"}
{"data":{"id":1722048380919815,"id_str":"1722048380919815","order_type":1,"datetime":"1709257116","microtimestamp":"1709257115965000","amount":0.5,"amount_str":"0.50000000","amount_traded":"0","amount_at_create":"0.50000000","price":61504,"price_str":"61504"},"channel":"live_orders_btcusd","event":"order_deleted"}
{"data":{"id":1722048914870273,"id_str":"1722048914870273","order_type":1,"datetime":"1709257116","microtimestamp":"1709257115965000","amount":2,"amount_str":"2.00000000","amount_traded":"0","amount_at_create":"2.00000000","price":61504,"price_str":"61504"},"channel":"live_orders_btcusd","event":"order_deleted"}
{"data":{"id":1722048914784260,"id_str":"1722048914784260","order_type":1,"datetime":"1709257116","microtimestamp":"1709257115965000","amount":0.5,"amount_str":"0.50000000","amount_traded":"0","amount_at_create":"0.50000000","price":61411,"price_str":"61411"},"channel":"live_orders_btcusd","event":"order_deleted"}
{"data":{"id":1722048632606722,"id_str":"1722048632606722","order_type":1,"datetime":"1709257116","microtimestamp":"1709257115966000","amount":1,"amount_str":"1.00000000","amount_traded":"0","amount_at_create":"1.00000000","price":61473,"price_str":"61473"},"channel":"live_orders_btcusd","event":"order_deleted"}
{"data":{"id":1722049068167169,"id_str":"1722049068167169","order_type":1,"datetime":"1709257116","microtimestamp":"1709257115966000","amount":0.00487272,"amount_str":"0.00487272","amount_traded":"0","amount_at_create":"0.00487272","price":61334,"price_str":"61334"},"channel":"live_orders_btcusd","event":"order_deleted"}
{"data":{"id":1722049090822148,"id_str":"1722049090822148","order_type":0,"datetime":"1709257116","microtimestamp":"1709257115972000","amount":0.815832,"amount_str":"0.81583200","amount_traded":"0","amount_at_create":"0.81583200","price":61292,"price_str":"61292"},"channel":"live_orders_btcusd","event":"order_created"}
{"data":{"id":1722049039310848,"id_str":"1722049039310848","order_type":1,"datetime":"1709257116","microtimestamp":"1709257115973000","amount":0.09744884,"amount_str":"0.09744884","amount_traded":"0","amount_at_create":"0.09744884","price":61355,"price_str":"61355"},"channel":"live_orders_btcusd","event":"order_deleted"}
{"data":{"id":1722049090879489,"id_str":"1722049090879489","order_type":1,"datetime":"1709257116","microtimestamp":"1709257115985000","amount":0.0213529,"amount_str":"0.02135290","amount_traded":"0","amount_at_create":"0.02135290","price":61337,"price_str":"61337"},"channel":"live_orders_btcusd","event":"order_created"}
{"data":{"id":1722049090899969,"id_str":"1722049090899969","order_type":1,"datetime":"1709257116","microtimestamp":"1709257115990000","amount":0.00487283,"amount_str":"0.00487283","amount_traded":"0","amount_at_create":"0.00487283","price":61330,"price_str":"61330"},"channel":"live_orders_btcusd","event":"order_created"}
{"data":{"id":1722049090924548,"id_str":"1722049090924548","order_type":1,"datetime":"1709257116","microtimestamp":"1709257115997000","amount":0.5,"amount_str":"0.50000000","amount_traded":"0","amount_at_create":"0.50000000","price":61380,"price_str":"61380"},"channel":"live_orders_btcusd","event":"order_created"}
{"data":{"id":1722049090945028,"id_str":"1722049090945028","order_type":1,"datetime":"1709257116","microtimestamp":"1709257116002000","amount":0.1875,"amount_str":"0.18750000","amount_traded":"0","amount_at_create":"0.18750000","price":61332,"price_str":"61332"},"channel":"live_orders_btcusd","event":"order_created"}
{"data":{"id":1722049090969605,"id_str":"1722049090969605","order_type":1,"datetime":"1709257116","microtimestamp":"1709257116008000","amount":0.5,"amount_str":"0.50000000","amount_traded":"0","amount_at_create":"0.50000000","price":61380,"price_str":"61380"},"channel":"live_orders_btcusd","event":"order_created"}
{"data":{"id":1722049090977795,"id_str":"1722049090977795","order_type":0,"datetime":"1709257116","microtimestamp":"1709257116009000","amount":3.06851126,"amount_str":"3.06851126","amount_traded":"0","amount_at_create":"3.06851126","price":61303,"price_str":"61303"},"channel":"live_orders_btcusd","event":"order_created"}
{"data":{"id":1722049090990081,"id_str":"1722049090990081","order_type":0,"datetime":"1709257116","microtimestamp":"1709257116012000","amount":0.00815328,"amount_str":"0.00815328","amount_traded":"0","amount_at_create":"0.00815328","price":61312,"price_str":"61312"},"channel":"live_orders_btcusd","event":"order_created"}
{"data":{"id":1722049090994178,"id_str":"1722049090994178","order_type":1,"datetime":"1709257116","microtimestamp":"1709257116014000","amount":0.162803,"amount_str":"0.16280300","amount_traded":"0","amount_at_create":"0.16280300","price":61424,"price_str":"61424"},"channel":"live_orders_btcusd","event":"order_created"}
{"data":{"id":1722049090998273,"id_str":"1722049090998273","order_type":1,"datetime":"1709257116","microtimestamp":"1709257116014000","amount":2,"amount_str":"2.00000000","amount_traded":"0","amount_at_create":"2.00000000","price":61473,"price_str":"61473"},"channel":"live_orders_btcusd","event":"order_created"}
{"data":{"id":1722049091002371,"id_str":"1722049091002371","order_type":0,"datetime":"1709257116","microtimestamp":"1709257116016000","amount":0.48942517,"amount_str":"0.48942517","amount_traded":"0","amount_at_create":"0.48942517","price":61296,"price_str":"61296"},"channel":"live_orders_btcusd","event":"order_created"}
{"data":{"id":1722049091006465,"id_str":"1722049091006465","order_type":1,"datetime":"1709257116","microtimestamp":"1709257116016000","amount":1,"amount_str":"1.00000000","amount_traded":"0","amount_at_create":"1.00000000","price":61411,"price_str":"61411"},"channel":"live_orders_btcusd","event":"order_created"}
{"data":{"id":1722049091010561,"id_str":"1722049091010561","order_type":0,"datetime":"1709257116","microtimestamp":"1709257116017000","amount":0.48964752,"amount_str":"0.48964752","amount_traded":"0","amount_at_create":"0.48964752","price":61268,"price_str":"61268"},"channel":"live_orders_btcusd","event":"order_created"}
{"data":{"id":1722049091010563,"id_str":"1722049091010563","order_type":0,"datetime":"1709257116","microtimestamp":"1709257116018000","amount":0.48985935,"amount_str":"0.48985935","amount_traded":"0","amount_at_create":"0.48985935","price":61242,"price_str":"61242"},"channel":"live_orders_btcusd","event":"order_created"}
{"data":{"id":1722049091014656,"id_str":"1722049091014656","order_type":1,"datetime":"1709257116","microtimestamp":"1709257116018000","amount":0.01630739,"amount_str":"0.01630739","amount_traded":"0","amount_at_create":"0.01630739","price":61322,"price_str":"61322"},"channel":"live_orders_btcusd","event":"order_created"}
{"data":{"id":1722049091018752,"id_str":"1722049091018752","order_type":1,"datetime":"1709257116","microtimestamp":"1709257116019000","amount":0.48899955,"amount_str":"0.48899955","amount_traded":"0","amount_at_create":"0.48899955","price":61350,"price_str":"61350"},"channel":"live_orders_btcusd","event":"order_created"}
{"data":{"id":1722049091018753,"id_str":"1722049091018753","order_type":1,"datetime":"1709257116","microtimestamp":"1709257116019000","amount":0.48915701,"amount_str":"0.48915701","amount_traded":"0","amount_at_create":"0.48915701","price":61330,"price_str":"61330"},"channel":"live_orders_btcusd","event":"order_created"}
{"data":{"id":1722049091022848,"id_str":"1722049091022848","order_type":0,"datetime":"1709257116","microtimestamp":"1709257116020000","amount":0.01631027,"amount_str":"0.01631027","amount_traded":"0","amount_at_create":"0.01631027","price":61311,"price_str":"61311"},"channel":"live_orders_btcusd","event":"order_created"}
{"data":{"id":1722049091022849,"id_str":"1722049091022849","order_type":0,"datetime":"1709257116","microtimestamp":"1709257116020000","amount":0.48953899,"amount_str":"0.48953899","amount_traded":"0","amount_at_create":"0.48953899","price":61282,"price_str":"61282"},"channel":"live_orders_btcusd","event":"order_created"}
{"data":{"id":1722049091022850,"id_str":"1722049091022850","order_type":1,"datetime":"1709257116","microtimestamp":"1709257116020000","amount":0.48889116,"amount_str":"0.48889116","amount_traded":"0","amount_at_create":"0.48889116","price":61364,"price_str":"61364"},"channel":"live_orders_btcusd","event":"order_created"}
{"data":{"id":1722049091051524,"id_str":"1722049091051524","order_type":1,"datetime":"1709257116","microtimestamp":"1709257116028000","amount":0.48911327,"amount_str":"0.48911327","amount_traded":"0","amount_at_create":"0.48911327","price":61336,"price_str":"61336"},"channel":"live_orders_btcusd","event":"order_created"}
{"data":{"id":1722049091063809,"id_str":"1722049091063809","order_type":1,"datetime":"1709257116","microtimestamp":"1709257116031000","amount":0.09745678,"amount_str":"0.09745678","amount_traded":"0","amount_at_create":"0.09745678","price":61346,"price_str":"61346"},"channel":"live_orders_btcusd","event":"order_created"}
{"data":{"id":1722049090748418,"id_str":"1722049090748418","order_type":0,"datetime":"1709257116","microtimestamp":"1709257116037000","amount":0.00815328,"amount_str":"0.00815328","amount_traded":"0","amount_at_create":"0.00815328","price":61315,"price_str":"61315"},"channel":"live_orders_btcusd","event":"order_deleted"}
{"data":{"id":1722049067978753,"id_str":"1722049067978753","order_type":0,"datetime":"1709257116","microtimestamp":"1709257116041000","amount":0.04875518,"amount_str":"0.04875518","amount_traded":"0","amount_at_create":"0.04875518","price":61291,"price_str":"61291"},"channel":"live_orders_btcusd","event":"order_deleted"}
{"data":{"id":1722049091014656,"id_str":"1722049091014656","order_type":1,"datetime":"1709257116","microtimestamp":"1709257116044000","amount":0.01630739,"amount_str":"0.01630739","amount_traded":"0","amount_at_create":"0.01630739","price":61322,"price_str":"61322"},"channel":"live_orders_btcusd","event":"order_deleted"}
{"data":{"id":1722049091162114,"id_str":"1722049091162114","order_type":0,"datetime":"1709257116","microtimestamp":"1709257116054000","amount":0.04893,"amount_str":"0.04893000","amount_traded":"0","amount_at_create":"0.04893000","price":61289,"price_str":"61289"},"channel":"live_orders_btcusd","event":"order_created"}
{"data":{"id":1722049091174403,"id_str":"1722049091174403","order_type":0,"datetime":"1709257116","microtimestamp":"1709257116058000","amount":0.16306563,"amount_str":"0.16306563","amount_traded":"0","amount_at_create":"0.16306563","price":61292,"price_str":"61292"},"channel":"live_orders_btcusd","event":"order_created"}
{"data":{"id":1722049090945028,"id_str":"1722049090945028","order_type":1,"datetime":"1709257116","microtimestamp":"1709257116062000","amount":0.1875,"amount_str":"0.18750000","amount_traded":"0","amount_at_create":"0.18750000","price":61332,"price_str":"61332"},"channel":"live_orders_btcusd","event":"order_deleted"}
{"data":{"id":1722049090990081,"id_str":"1722049090990081","order_type":0,"datetime":"1709257116","microtimestamp":"1709257116064000","amount":0.00815328,"amount_str":"0.00815328","amount_traded":"0","amount_at_create":"0.00815328","price":61312,"price_str":"61312"},"channel":"live_orders_btcusd","event":"order_deleted"}
{"data":{"id":1722048981995520,"id_str":"1722048981995520","order_type":1,"datetime":"1709257116","microtimestamp":"1709257116072000","amount":0.12188796,"amount_str":"0.12188796","amount_traded":"0","amount_at_create":"0.12188796","price":61391,"price_str":"61391"},"channel":"live_orders_btcusd","event":"order_deleted"}
{"data":{"id":1722049091260417,"id_str":"1722049091260417","order_type":1,"datetime":"1709257116","microtimestamp":"1709257116078000","amount":0.1875,"amount_str":"0.18750000","amount_traded":"0","amount_at_create":"0.18750000","price":61379,"price_str":"61379"},"channel":"live_orders_btcusd","event":"order_created"}
{"data":{"id":1722049091284994,"id_str":"1722049091284994","order_type":0,"datetime":"1709257116","microtimestamp":"1709257116085000","amount":0.00815361,"amount_str":"0.00815361","amount_traded":"0","amount_at_create":"0.00815361","price":61310,"price_str":"61310"},"channel":"live_orders_btcusd","event":"order_created"}
{"data":{"id":1722049091293185,"id_str":"1722049091293185","order_type":1,"datetime":"1709257116","microtimestamp":"1709257116086000","amount":0.06436541,"amount_str":"0.06436541","amount_traded":"0","amount_at_create":"0.06436541","price":61489,"price_str":"61489"},"channel":"live_orders_btcusd","event":"order_created"}
{"data":{"id":1722049091309568,"id_str":"1722049091309568","order_type":0,"datetime":"1709257116","microtimestamp":"1709257116090000","amount":0.489329,"amount_str":"0.48932900","amount_traded":"0","amount_at_create":"0.48932900","price":61308,"price_str":"61308"},"channel":"live_orders_btcusd","event":"order_created"}
{"data":{"id":1722049091313666,"id_str":"1722049091313666","order_type":1,"datetime":"1709257116","microtimestamp":"1709257116092000","amount":0.48919849,"amount_str":"0.48919849","amount_traded":"0","amount_at_create":"0.48919849","price":61325,"price_str":"61325"},"channel":"live_orders_btcusd","event":"order_created"}
{"data":{"id":1722049079508992,"id_str":"1722049079508992","order_type":0,"datetime":"1709257116","microtimestamp":"1709257116098000","amount":0.48936455,"amount_str":"0.48936455","amount_traded":"0","amount_at_create":"0.48936455","price":61303,"price_str":"61303"},"channel":"live_orders_btcusd","event":"order_deleted"}
{"data":{"id":1722049081073664,"id_str":"1722049081073664","order_type":0,"datetime":"1709257116","microtimestamp":"1709257116102000","amount":0.00040756,"amount_str":"0.00040756","amount_traded":"0","amount_at_create":"0.00040756","price":61306,"price_str":"61306"},"channel":"live_orders_btcusd","event":"order_deleted"}
{"data":{"id":1722049090879489,"id_str":"1722049090879489","order_type":1,"datetime":"1709257116","microtimestamp":"1709257116106000","amount":0.0213529,"amount_str":"0.02135290","amount_traded":"0","amount_at_create":"0.02135290","price":61337,"price_str":"61337"},"channel":"live_orders_btcusd","event":"order_deleted"}
{"data":{"id":1722049091309568,"id_str":"1722049091309568","order_type":0,"datetime":"1709257116","microtimestamp":"1709257116107000","amount":0.489329,"amount_str":"0.48932900","amount_traded":"0","amount_at_create":"0.48932900","price":61308,"price_str":"61308"},"channel":"live_orders_btcusd","event":"order_deleted"}
{"data":{"id":1722049091313666,"id_str":"1722049091313666","order_type":1,"datetime":"1709257116","microtimestamp":"1709257116108000","amount":0.48919849,"amount_str":"0.48919849","amount_traded":"0","amount_at_create":"0.48919849","price":61325,"price_str":"61325"},"channel":"live_orders_btcusd","event":"order_deleted"}
{"data":{"id":1722049088499712,"id_str":"1722049088499712","order_type":0,"datetime":"1709257116","microtimestamp":"1709257116110000","amount":0.0163088,"amount_str":"0.01630880","amount_traded":"0","amount_at_create":"0.01630880","price":61303,"price_str":"61303"},"channel":"live_orders_btcusd","event":"order_deleted"}
{"data":{"id":1722049091452928,"id_str":"1722049091452928","order_type":1,"datetime":"1709257116","microtimestamp":"1709257116125000","amount":0.12188796,"amount_str":"0.12188796","amount_traded":"0","amount_at_create":"0.12188796","price":61379,"price_str":"61379"},"channel":"live_orders_btcusd","event":"order_created"}
{"data":{"id":1722049091559424,"id_str":"1722049091559424","order_type":0,"datetime":"1709257116","microtimestamp":"1709257116151000","amount":0.48935247,"amount_str":"0.48935247","amount_traded":"0","amount_at_create":"0.48935247","price":61305,"price_str":"61305"},"channel":"live_orders_btcusd","event":"order_created"}
{"data":{"id":1722049091563520,"id_str":"1722049091563520","order_type":1,"datetime":"1709257116","microtimestamp":"1709257116152000","amount":0.01630701,"amount_str":"0.01630701","amount_traded":"0","amount_at_create":"0.01630701","price":61324,"price_str":"61324"},"channel":"live_orders_btcusd","event":"order_created"}
{"data":{"id":1722049091571712,"id_str":"1722049091571712","order_type":1,"datetime":"1709257116","microtimestamp":"1709257116155000","amount":0.1875,"amount_str":"0.18750000","amount_traded":"0","amount_at_create":"0.18750000","price":61332,"price_str":"61332"},"channel":"live_orders_btcusd","event":"order_created"}
{"data":{"id":1722048981549056,"id_str":"1722048981549056","order_type":1,"datetime":"1709257116","microtimestamp":"1709257116247000","amount":1.445688,"amount_str":"1.44568800","amount_traded":"0","amount_at_create":"1.44568800","price":61375,"price_str":"61375"},"channel":"live_orders_btcusd","event":"order_deleted"}
{"data":{"id":1722048981577729,"id_str":"1722048981577729","order_type":1,"datetime":"1709257116","microtimestamp":"1709257116247000","amount":0.815832,"amount_str":"0.81583200","amount_traded":"0","amount_at_create":"0.81583200","price":61348,"price_str":"61348"},"channel":"live_orders_btcusd","event":"order_deleted"}
{"data":{"id":1722048940621825,"id_str":"1722048940621825","order_type":1,"datetime":"1709257116","microtimestamp":"1709257116248000","amount":1.940436,"amount_str":"1.94043600","amount_traded":"0","amount_at_create":"1.94043600","price":61410,"price_str":"61410"},"channel":"live_orders_btcusd","event":"order_deleted"}
{"data":{"id":1722049092009986,"id_str":"1722049092009986","order_type":0,"datetime":"1709257116","microtimestamp":"1709257116262000","amount":0.00040756,"amount_str":"0.00040756","amount_traded":"0","amount_at_create":"0.00040756","price":61304,"price_str":"61304"},"channel":"live_orders_btcusd","event":"order_created"}
{"data":{"id":1722049090666501,"id_str":"1722049090666501","order_type":1,"datetime":"1709257116","microtimestamp":"1709257116262000","amount":0.00487283,"amount_str":"0.00487283","amount_traded":"0","amount_at_create":"0.00487283","price":61332,"price_str":"61332"},"channel":"live_orders_btcusd","event":"order_deleted"}
{"data":{"id":1722049092055040,"id_str":"1722049092055040","order_type":1,"datetime":"1709257116","microtimestamp":"1709257116272000","amount":0.02410135,"amount_str":"0.02410135","amount_traded":"0","amount_at_create":"0.02410135","price":61336,"price_str":"61336"},"channel":"live_orders_btcusd","event":"order_created"}
{"data":{"id":1722049092096000,"id_str":"1722049092096000","order_type":1,"datetime":"1709257116","microtimestamp":"1709257116282000","amount":0.00487343,"amount_str":"0.00487343","amount_traded":"0","amount_at_create":"0.00487343","price":61326,"price_str":"61326"},"channel":"live_orders_btcusd","event":"order_created"}
{"data":{"id":1722049092136960,"id_str":"1722049092136960","order_type":1,"datetime":"1709257116","microtimestamp":"1709257116292000","amount":1.445688,"amount_str":"1.44568800","amount_traded":"0","amount_at_create":"1.44568800","price":61361,"price_str":"61361"},"channel":"live_orders_btcusd","event":"order_created"}
{"data":{"id":1722049092136961,"id_str":"1722049092136961","order_type":1,"datetime":"1709257116","microtimestamp":"1709257116292000","amount":1.940436,"amount_str":"1.94043600","amount_traded":"0","amount_at_create":"1.94043600","price":61381,"price_str":"61381"},"channel":"live_orders_btcusd","event":"order_created"}
{"data":{"id":1722049092141057,"id_str":"1722049092141057","order_type":1,"datetime":"1709257116","microtimestamp":"1709257116294000","amount":0.815832,"amount_str":"0.81583200","amount_traded":"0","amount_at_create":"0.81583200","price":61334,"price_str":"61334"},"channel":"live_orders_btcusd","event":"order_created"}
{"data":{"id":1722049091022848,"id_str":"1722049091022848","order_type":0,"datetime":"1709257116","microtimestamp":"1709257116301000","amount":0.01631027,"amount_str":"0.01631027","amount_traded":"0","amount_at_create":"0.01631027","price":61311,"price_str":"61311"},"channel":"live_orders_btcusd","event":"order_deleted"}
{"data":{"id":1722049092173831,"id_str":"1722049092173831","order_type":1,"datetime":"1709257116","microtimestamp":"1709257116302000","amount":0.48919306,"amount_str":"0.48919306","amount_traded":"0","amount_at_create":"0.48919306","price":61326,"price_str":"61326"},"channel":"live_orders_btcusd","event":"order_created"}
{"data":{"id":1722049092182016,"id_str":"1722049092182016","order_type":0,"datetime":"1709257116","microtimestamp":"1709257116303000","amount":0.48932012,"amount_str":"0.48932012","amount_traded":"0","amount_at_create":"0.48932012","price":61309,"price_str":"61309"},"channel":"live_orders_btcusd","event":"order_created"}
{"data":{"id":1722049091571712,"id_str":"1722049091571712","order_type":1,"datetime":"1709257116","microtimestamp":"1709257116340000","amount":0.1875,"amount_str":"0.18750000","amount_traded":"0","amount_at_create":"0.18750000","price":61332,"price_str":"61332"},"channel":"live_orders_btcusd","event":"order_deleted"}
{"data":{"id":1722049092358144,"id_str":"1722049092358144","order_type":0,"datetime":"1709257116","microtimestamp":"1709257116346000","amount":0.01630996,"amount_str":"0.01630996","amount_traded":"0","amount_at_create":"0.01630996","price":61312,"price_str":"61312"},"channel":"live_orders_btcusd","event":"order_created"}
{"data":{"id":1722049092358144,"id_str":"1722049092358144","order_type":0,"datetime":"1709257116","microtimestamp":"1709257116368000","amount":0.01630996,"amount_str":"0.01630996","amount_traded":"0","amount_at_create":"0.01630996","price":61312,"price_str":"61312"},"channel":"live_orders_btcusd","event":"order_deleted"}
{"data":{"id":1722049091002371,"id_str":"1722049091002371","order_type":0,"datetime":"1709257116","microtimestamp":"1709257116368000","amount":0.48942517,"amount_str":"0.48942517","amount_traded":"0","amount_at_create":"0.48942517","price":61296,"price_str":"61296"},"channel":"live_orders_btcusd","event":"order_deleted"}
{"data":{"id":1722049092182016,"id_str":"1722049092182016","order_type":0,"datetime":"1709257116","microtimestamp":"1709257116368000","amount":0.48932012,"amount_str":"0.48932012","amount_traded":"0","amount_at_create":"0.48932012","price":61309,"price_str":"61309"},"channel":"live_orders_btcusd","event":"order_deleted"}
{"data":{"id":1722049091559424,"id_str":"1722049091559424","order_type":0,"datetime":"1709257116","microtimestamp":"1709257116370000","amount":0.48935247,"amount_str":"0.48935247","amount_traded":"0","amount_at_create":"0.48935247","price":61305,"price_str":"61305"},"channel":"live_orders_btcusd","event":"order_deleted"}
{"data":{"id":1722049091563520,"id_str":"1722049091563520","order_type":1,"datetime":"1709257116","microtimestamp":"1709257116388000","amount":0.01630701,"amount_str":"0.01630701","amount_traded":"0","amount_at_create":"0.01630701","price":61324,"price_str":"61324"},"channel":"live_orders_btcusd","event":"order_deleted"}
{"data":{"id":1722049092173831,"id_str":"1722049092173831","order_type":1,"datetime":"1709257116","microtimestamp":"1709257116388000","amount":0.48919306,"amount_str":"0.48919306","amount_traded":"0","amount_at_create":"0.48919306","price":61326,"price_str":"61326"},"channel":"live_orders_btcusd","event":"order_deleted"}
{"data":{"id":1722049092542464,"id_str":"1722049092542464","order_type":0,"datetime":"1709257116","microtimestamp":"1709257116392000","amount":0.16337697,"amount_str":"0.16337697","amount_traded":"0","amount_at_create":"0.16337697","price":61208,"price_str":"61208"},"channel":"live_orders_btcusd","event":"order_created"}
{"data":{"id":1722049091022849,"id_str":"1722049091022849","order_type":0,"datetime":"1709257116","microtimestamp":"1709257116399000","amount":0.48953899,"amount_str":"0.48953899","amount_traded":"0","amount_at_create":"0.48953899","price":61282,"price_str":"61282"},"channel":"live_orders_btcusd","event":"order_deleted"}
{"data":{"id":1722049092734977,"id_str":"1722049092734977","order_type":0,"datetime":"1709257116","microtimestamp":"1709257116438000","amount":0.1875,"amount_str":"0.18750000","amount_traded":"0","amount_at_create":"0.18750000","price":61212,"price_str":"61212"},"channel":"live_orders_btcusd","event":"order_created"}
{"data":{"id":1722049092755458,"id_str":"1722049092755458","order_type":1,"datetime":"1709257116","microtimestamp":"1709257116443000","amount":0.01630717,"amount_str":"0.01630717","amount_traded":"0","amount_at_create":"0.01630717","price":61323,"price_str":"61323"},"channel":"live_orders_btcusd","event":"order_created"}
{"data":{"id":1722049092755458,"id_str":"1722049092755458","order_type":1,"datetime":"1709257116","microtimestamp":"1709257116457000","amount":0.01630717,"amount_str":"0.01630717","amount_traded":"0","amount_at_create":"0.01630717","price":61323,"price_str":"61323"},"channel":"live_orders_btcusd","event":"order_deleted"}
{"data":{"id":1722049091010561,"id_str":"1722049091010561","order_type":0,"datetime":"1709257117","microtimestamp":"1709257116500000","amount":0.48964752,"amount_str":"0.48964752","amount_traded":"0","amount_at_create":"0.48964752","price":61268,"price_str":"61268"},"channel":"live_orders_btcusd","event":"order_deleted"}
{"data":{"id":1722049092009986,"id_str":"1722049092009986","order_type":0,"datetime":"1709257117","microtimestamp":"1709257116501000","amount":0.00040756,"amount_str":"0.00040756","amount_traded":"0","amount_at_create":"0.00040756","price":61304,"price_str":"61304"},"channel":"live_orders_btcusd","event":"order_deleted"}
{"data":{"id":1722049093005312,"id_str":"1722049093005312","order_type":1,"datetime":"1709257117","microtimestamp":"1709257116504000","amount":0.48919784,"amount_str":"0.48919784","amount_traded":"0","amount_at_create":"0.48919784","price":61325,"price_str":"61325"},"channel":"live_orders_btcusd","event":"order_created"}
{"data":{"id":1722049093005313,"id_str":"1722049093005313","order_type":0,"datetime":"1709257117","microtimestamp":"1709257116504000","amount":0.48930251,"amount_str":"0.48930251","amount_traded":"0","amount_at_create":"0.48930251","price":61311,"price_str":"61311"},"channel":"live_orders_btcusd","event":"order_created"}
{"data":{"id":1722049093009408,"id_str":"1722049093009408","order_type":0,"datetime":"1709257117","microtimestamp":"1709257116505000","amount":0.01630944,"amount_str":"0.01630944","amount_traded":"0","amount_at_create":"0.01630944","price":61314,"price_str":"61314"},"channel":"live_orders_btcusd","event":"order_created"}
{"data":{"id":1722049093021697,"id_str":"1722049093021697","order_type":1,"datetime":"1709257117","microtimestamp":"1709257116509000","amount":0.1875,"amount_str":"0.18750000","amount_traded":"0","amount_at_create":"0.18750000","price":61333,"price_str":"61333"},"channel":"live_orders_btcusd","event":"order_created"}
{"data":{"id":1722049093009408,"id_str":"1722049093009408","order_type":0,"datetime":"1709257117","microtimestamp":"1709257116521000","amount":0.01630944,"amount_str":"0.01630944","amount_traded":"0","amount_at_create":"0.01630944","price":61314,"price_str":"61314"},"channel":"live_orders_btcusd","event":"order_deleted"}
{"data":{"id":1722049093005312,"id_str":"1722049093005312","order_type":1,"datetime":"1709257117","microtimestamp":"1709257116521000","amount":0.48919784,"amount_str":"0.48919784","amount_traded":"0","amount_at_create":"0.48919784","price":61325,"price_str":"61325"},"channel":"live_orders_btcusd","event":"order_deleted"}
{"data":{"id":1722049093021697,"id_str":"1722049093021697","order_type":1,"datetime":"1709257117","microtimestamp":"1709257116523000","amount":0.1875,"amount_str":"0.18750000","amount_traded":"0","amount_at_create":"0.18750000","price":61333,"price_str":"61333"},"channel":"live_orders_btcusd","event":"order_deleted"}
{"data":{"id":1722049093246979,"id_str":"1722049093246979","order_type":1,"datetime":"1709257117","microtimestamp":"1709257116563000","amount":0.01630691,"amount_str":"0.01630691","amount_traded":"0","amount_at_create":"0.01630691","price":61324,"price_str":"61324"},"channel":"live_orders_btcusd","event":"order_created"}
{"data":{"id":1722049093341185,"id_str":"1722049093341185","order_type":1,"datetime":"1709257117","microtimestamp":"1709257116586000","amount":0.1875,"amount_str":"0.18750000","amount_traded":"0","amount_at_create":"0.18750000","price":61333,"price_str":"61333"},"channel":"live_orders_btcusd","event":"order_created"}
{"data":{"id":1722049093431297,"id_str":"1722049093431297","order_type":0,"datetime":"1709257117","microtimestamp":"1709257116609000","amount":0.01630918,"amount_str":"0.01630918","amount_traded":"0","amount_at_create":"0.01630918","price":61315,"price_str":"61315"},"channel":"live_orders_btcusd","event":"order_created"}
{"data":{"id":1722049093341185,"id_str":"1722049093341185","order_type":1,"datetime":"1709257117","microtimestamp":"1709257116629000","amount":0.1875,"amount_str":"0.18750000","amount_traded":"0","amount_at_create":"0.18750000","price":61333,"price_str":"61333"},"channel":"live_orders_btcusd","event":"order_deleted"}
{"data":{"id":1722049090654211,"id_str":"1722049090654211","order_type":1,"datetime":"1709257117","microtimestamp":"1709257116633000","amount":0.03718287,"amount_str":"0.03718287","amount_traded":"0","amount_at_create":"0.03718287","price":61334,"price_str":"61334"},"channel":"live_orders_btcusd","event":"order_deleted"}
{"data":{"id":1722049093005313,"id_str":"1722049093005313","order_type":0,"datetime":"1709257117","microtimestamp":"1709257116638000","amount":0.48930251,"amount_str":"0.48930251","amount_traded":"0","amount_at_create":"0.48930251","price":61311,"price_str":"61311"},"channel":"live_orders_btcusd","event":"order_deleted"}
{"data":{"id":1722049093595139,"id_str":"1722049093595139","order_type":1,"datetime":"1709257117","microtimestamp":"1709257116648000","amount":0.03718287,"amount_str":"0.03718287","amount_traded":"0","amount_at_create":"0.03718287","price":61333,"price_str":"61333"},"channel":"live_orders_btcusd","event":"order_created"}
{"data":{"id":1722049093623809,"id_str":"1722049093623809","order_type":0,"datetime":"1709257117","microtimestamp":"1709257116656000","amount":0.48932513,"amount_str":"0.48932513","amount_traded":"0","amount_at_create":"0.48932513","price":61308,"price_str":"61308"},"channel":"live_orders_btcusd","event":"order_created"}
{"data":{"id":1722049093746688,"id_str":"1722049093746688","order_type":0,"datetime":"1709257117","microtimestamp":"1709257116685000","amount":0.00040756,"amount_str":"0.00040756","amount_traded":"0","amount_at_create":"0.00040756","price":61305,"price_str":"61305"},"channel":"live_orders_btcusd","event":"order_created"}
{"data":{"id":1722049093947393,"id_str":"1722049093947393","order_type":0,"datetime":"1709257117","microtimestamp":"1709257116734000","amount":0.48929518,"amount_str":"0.48929518","amount_traded":"0","amount_at_create":"0.48929518","price":61312,"price_str":"61312"},"channel":"live_orders_btcusd","event":"order_created"}
{"data":{"id":1722049093951488,"id_str":"1722049093951488","order_type":1,"datetime":"1709257117","microtimestamp":"1709257116735000","amount":0.48918235,"amount_str":"0.48918235","amount_traded":"0","amount_at_create":"0.48918235","price":61327,"price_str":"61327"},"channel":"live_orders_btcusd","event":"order_created"}
{"data":{"id":1722049094217728,"id_str":"1722049094217728","order_type":0,"datetime":"1709257117","microtimestamp":"1709257116800000","amount":0.04875518,"amount_str":"0.04875518","amount_traded":"0","amount_at_create":"0.04875518","price":61288,"price_str":"61288"},"channel":"live_orders_btcusd","event":"order_created"}
{"data":{"id":1722049093746688,"id_str":"1722049093746688","order_type":0,"datetime":"1709257117","microtimestamp":"1709257116874000","amount":0.00040756,"amount_str":"0.00040756","amount_traded":"0","amount_at_create":"0.00040756","price":61305,"price_str":"61305"},"channel":"live_orders_btcusd","event":"order_deleted"}
{"data":{"id":1722048498528258,"id_str":"1722048498528258","order_type":1,"datetime":"1709257117","microtimestamp":"1709257116879000","amount":0.1875,"amount_str":"0.18750000","amount_traded":"0","amount_at_create":"0.18750000","price":61500,"price_str":"61500"},"channel":"live_orders_btcusd","event":"order_deleted"}
{"data":{"id":1722049095270402,"id_str":"1722049095270402","order_type":0,"datetime":"1709257117","microtimestamp":"1709257117057000","amount":0.00040756,"amount_str":"0.00040756","amount_traded":"0","amount_at_create":"0.00040756","price":61304,"price_str":"61304"},"channel":"live_orders_btcusd","event":"order_created"}
{"data":{"id":1722049092096000,"id_str":"1722049092096000","order_type":1,"datetime":"1709257117","microtimestamp":"1709257117063000","amount":0.00487343,"amount_str":"0.00487343","amount_traded":"0","amount_at_create":"0.00487343","price":61326,"price_str":"61326"},"channel":"live_orders_btcusd","event":"order_deleted"}
{"data":{"id":1722049095417856,"id_str":"1722049095417856","order_type":1,"datetime":"1709257117","microtimestamp":"1709257117093000","amount":0.00487327,"amount_str":"0.00487327","amount_traded":"0","amount_at_create":"0.00487327","price":61328,"price_str":"61328"},"channel":"live_orders_btcusd","event":"order_created"}
{"data":{"id":1722049094217728,"id_str":"1722049094217728","order_type":0,"datetime":"1709257117","microtimestamp":"1709257117096000","amount":0.04875518,"amount_str":"0.04875518","amount_traded":"0","amount_at_create":"0.04875518","price":61288,"price_str":"61288"},"channel":"live_orders_btcusd","event":"order_deleted"}
{"data":{"id":1722049095491585,"id_str":"1722049095491585","order_type":0,"datetime":"1709257117","microtimestamp":"1709257117112000","amount":0.00815401,"amount_str":"0.00815401","amount_traded":"0","amount_at_create":"0.00815401","price":61312,"price_str":"61312"},"channel":"live_orders_btcusd","event":"order_created"}
{"data":{"id":1722049095270402,"id_str":"1722049095270402","order_type":0,"datetime":"1709257117","microtimestamp":"1709257117252000","amount":0.00040756,"amount_str":"0.00040756","amount_traded":"0","amount_at_create":"0.00040756","price":61304,"price_str":"61304"},"channel":"live_orders_btcusd","event":"order_deleted"}
{"data":{"id":1722049093947393,"id_str":"1722049093947393","order_type":0,"datetime":"1709257117","microtimestamp":"1709257117298000","amount":0.48929518,"amount_str":"0.48929518","amount_traded":"0","amount_at_create":"0.48929518","price":61312,"price_str":"61312"},"channel":"live_orders_btcusd","event":"order_deleted"}
{"data":{"id":1722049096372225,"id_str":"1722049096372225","order_type":0,"datetime":"1709257117","microtimestamp":"1709257117326000","amount":0.06520848,"amount_str":"0.06520848","amount_traded":"0","amount_at_create":"0.06520848","price":61298,"price_str":"61298"},"channel":"live_orders_btcusd","event":"order_created"}
{"data":{"id":1722049096380419,"id_str":"1722049096380419","order_type":0,"datetime":"1709257117","microtimestamp":"1709257117329000","amount":0.00040756,"amount_str":"0.00040756","amount_traded":"0","amount_at_create":"0.00040756","price":61305,"price_str":"61305"},"channel":"live_orders_btcusd","event":"order_created"}
{"data":{"id":1722049091284994,"id_str":"1722049091284994","order_type":0,"datetime":"1709257117","microtimestamp":"1709257117339000","amount":0.00815361,"amount_str":"0.00815361","amount_traded":"0","amount_at_create":"0.00815361","price":61310,"price_str":"61310"},"channel":"live_orders_btcusd","event":"order_deleted"}
{"data":{"id":1722049096437761,"id_str":"1722049096437761","order_type":0,"datetime":"1709257117","microtimestamp":"1709257117343000","amount":0.48940006,"amount_str":"0.48940006","amount_traded":"0","amount_at_create":"0.48940006","price":61299,"price_str":"61299"},"channel":"live_orders_btcusd","event":"order_created"}
{"data":{"id":1722049093595139,"id_str":"1722049093595139","order_type":1,"datetime":"1709257117","microtimestamp":"1709257117343000","amount":0.03718287,"amount_str":"0.03718287","amount_traded":"0","amount_at_create":"0.03718287","price":61333,"price_str":"61333"},"channel":"live_orders_btcusd","event":"order_deleted"}
{"data":{"id":1722049096441857,"id_str":"1722049096441857","order_type":0,"datetime":"1709257117","microtimestamp":"1709257117344000","amount":0.48929075,"amount_str":"0.48929075","amount_traded":"0","amount_at_create":"0.48929075","price":61313,"price_str":"61313"},"channel":"live_orders_btcusd","event":"order_created"}
{"data":{"id":1722049093246979,"id_str":"1722049093246979","order_type":1,"datetime":"1709257117","microtimestamp":"1709257117350000","amount":0.01630691,"amount_str":"0.01630691","amount_traded":"0","amount_at_create":"0.01630691","price":61324,"price_str":"61324"},"channel":"live_orders_btcusd","event":"order_deleted"}
{"data":{"id":1722049092055040,"id_str":"1722049092055040","order_type":1,"datetime":"1709257117","microtimestamp":"1709257117356000","amount":0.02410135,"amount_str":"0.02410135","amount_traded":"0","amount_at_create":"0.02410135","price":61336,"price_str":"61336"},"channel":"live_orders_btcusd","event":"order_deleted"}
{"data":{"id":1722049095417856,"id_str":"1722049095417856","order_type":1,"datetime":"1709257117","microtimestamp":"1709257117358000","amount":0.00487327,"amount_str":"0.00487327","amount_traded":"0","amount_at_create":"0.00487327","price":61328,"price_str":"61328"},"channel":"live_orders_btcusd","event":"order_deleted"}
{"data":{"id":1722049091018753,"id_str":"1722049091018753","order_type":1,"datetime":"1709257117","microtimestamp":"1709257117360000","amount":0.48915701,"amount_str":"0.48915701","amount_traded":"0","amount_at_create":"0.48915701","price":61330,"price_str":"61330"},"channel":"live_orders_btcusd","event":"order_deleted"}
{"data":{"id":1722049091010563,"id_str":"1722049091010563","order_type":0,"datetime":"1709257117","microtimestamp":"1709257117361000","amount":0.48985935,"amount_str":"0.48985935","amount_traded":"0","amount_at_create":"0.48985935","price":61242,"price_str":"61242"},"channel":"live_orders_btcusd","event":"order_deleted"}
{"data":{"id":1722049091051524,"id_str":"1722049091051524","order_type":1,"datetime":"1709257117","microtimestamp":"1709257117361000","amount":0.48911327,"amount_str":"0.48911327","amount_traded":"0","amount_at_create":"0.48911327","price":61336,"price_str":"61336"},"channel":"live_orders_btcusd","event":"order_deleted"}
{"data":{"id":1722049091018752,"id_str":"1722049091018752","order_type":1,"datetime":"1709257117","microtimestamp":"1709257117361000","amount":0.48899955,"amount_str":"0.48899955","amount_traded":"0","amount_at_create":"0.48899955","price":61350,"price_str":"61350"},"channel":"live_orders_btcusd","event":"order_deleted"}
{"data":{"id":1722049093431297,"id_str":"1722049093431297","order_type":0,"datetime":"1709257117","microtimestamp":"1709257117362000","amount":0.01630918,"amount_str":"0.01630918","amount_traded":"0","amount_at_create":"0.01630918","price":61315,"price_str":"61315"},"channel":"live_orders_btcusd","event":"order_deleted"}
{"data":{"id":1722049093623809,"id_str":"1722049093623809","order_type":0,"datetime":"1709257117","microtimestamp":"1709257117363000","amount":0.48932513,"amount_str":"0.48932513","amount_traded":"0","amount_at_create":"0.48932513","price":61308,"price_str":"61308"},"channel":"live_orders_btcusd","event":"order_deleted"}
{"data":{"id":1722049093951488,"id_str":"1722049093951488","order_type":1,"datetime":"1709257117","microtimestamp":"1709257117363000","amount":0.48918235,"amount_str":"0.48918235","amount_traded":"0","amount_at_create":"0.48918235","price":61327,"price_str":"61327"},"channel":"live_orders_btcusd","event":"order_deleted"}
{"data":{"id":1722049092542464,"id_str":"1722049092542464","order_type":0,"datetime":"1709257117","microtimestamp":"1709257117366000","amount":0.16337697,"amount_str":"0.16337697","amount_traded":"0","amount_at_create":"0.16337697","price":61208,"price_str":"61208"},"channel":"live_orders_btcusd","event":"order_deleted"}
{"data":{"id":1722049096441857,"id_str":"1722049096441857","order_type":0,"datetime":"1709257117","microtimestamp":"1709257117366000","amount":0.48929075,"amount_str":"0.48929075","amount_traded":"0","amount_at_create":"0.48929075","price":61313,"price_str":"61313"},"channel":"live_orders_btcusd","event":"order_deleted"}
{"data":{"id":1722049096437761,"id_str":"1722049096437761","order_type":0,"datetime":"1709257117","microtimestamp":"1709257117368000","amount":0.48940006,"amount_str":"0.48940006","amount_traded":"0","amount_at_create":"0.48940006","price":61299,"price_str":"61299"},"channel":"live_orders_btcusd","event":"order_deleted"}
{"data":{"id":1722049091022850,"id_str":"1722049091022850","order_type":1,"datetime":"1709257117","microtimestamp":"1709257117372000","amount":0.48889116,"amount_str":"0.48889116","amount_traded":"0","amount_at_create":"0.48889116","price":61364,"price_str":"61364"},"channel":"live_orders_btcusd","event":"order_deleted"}
{"data":{"id":1722049096581120,"id_str":"1722049096581120","order_type":0,"datetime":"1709257117","microtimestamp":"1709257117377000","amount":0.00815401,"amount_str":"0.00815401","amount_traded":"0","amount_at_create":"0.00815401","price":61314,"price_str":"61314"},"channel":"live_orders_btcusd","event":"order_created"}
{"data":{"id":1722049096380419,"id_str":"1722049096380419","order_type":0,"datetime":"1709257117","microtimestamp":"1709257117389000","amount":0.00040756,"amount_str":"0.00040756","amount_traded":"0","amount_at_create":"0.00040756","price":61305,"price_str":"61305"},"channel":"live_orders_btcusd","event":"order_deleted"}
{"data":{"id":1722049096671233,"id_str":"1722049096671233","order_type":1,"datetime":"1709257117","microtimestamp":"1709257117399000","amount":0.03390203,"amount_str":"0.03390203","amount_traded":"0","amount_at_create":"0.03390203","price":61340,"price_str":"61340"},"channel":"live_orders_btcusd","event":"order_created"}
{"data":{"id":1722049096753156,"id_str":"1722049096753156","order_type":1,"datetime":"1709257117","microtimestamp":"1709257117419000","amount":0.48914292,"amount_str":"0.48914292","amount_traded":"0","amount_at_create":"0.48914292","price":61332,"price_str":"61332"},"channel":"live_orders_btcusd","event":"order_created"}
{"data":{"id":1722049096757251,"id_str":"1722049096757251","order_type":1,"datetime":"1709257117","microtimestamp":"1709257117421000","amount":0.01630534,"amount_str":"0.01630534","amount_traded":"0","amount_at_create":"0.01630534","price":61330,"price_str":"61330"},"channel":"live_orders_btcusd","event":"order_created"}
{"data":{"id":1722049096761346,"id_str":"1722049096761346","order_type":0,"datetime":"1709257117","microtimestamp":"1709257117422000","amount":0.01630781,"amount_str":"0.01630781","amount_traded":"0","amount_at_create":"0.01630781","price":61320,"price_str":"61320"},"channel":"live_orders_btcusd","event":"order_created"}
{"data":{"id":1722049096769538,"id_str":"1722049096769538","order_type":1,"datetime":"1709257117","microtimestamp":"1709257117424000","amount":0.48904956,"amount_str":"0.48904956","amount_traded":"0","amount_at_create":"0.48904956","price":61344,"price_str":"61344"},"channel":"live_orders_btcusd","event":"order_created"}
{"data":{"id":1722049096773633,"id_str":"1722049096773633","order_type":1,"datetime":"1709257117","microtimestamp":"1709257117425000","amount":0.48912491,"amount_str":"0.48912491","amount_traded":"0","amount_at_create":"0.48912491","price":61335,"price_str":"61335"},"channel":"live_orders_btcusd","event":"order_created"}
{"data":{"id":1722049096777729,"id_str":"1722049096777729","order_type":0,"datetime":"1709257117","microtimestamp":"1709257117425000","amount":0.48928391,"amount_str":"0.48928391","amount_traded":"0","amount_at_create":"0.48928391","price":61314,"price_str":"61314"},"channel":"live_orders_btcusd","event":"order_created"}
{"data":{"id":1722049091293185,"id_str":"1722049091293185","order_type":1,"datetime":"1709257117","microtimestamp":"1709257117426000","amount":0.06436541,"amount_str":"0.06436541","amount_traded":"0","amount_at_create":"0.06436541","price":61489,"price_str":"61489"},"channel":"live_orders_btcusd","event":"order_deleted"}
{"data":{"id":1722049096753156,"id_str":"1722049096753156","order_type":1,"datetime":"1709257117","microtimestamp":"1709257117444000","amount":0.48914292,"amount_str":"0.48914292","amount_traded":"0","amount_at_create":"0.48914292","price":61332,"price_str":"61332"},"channel":"live_orders_btcusd","event":"order_deleted"}
{"data":{"id":1722049096773633,"id_str":"1722049096773633","order_type":1,"datetime":"1709257117","microtimestamp":"1709257117444000","amount":0.48912491,"amount_str":"0.48912491","amount_traded":"0","amount_at_create":"0.48912491","price":61335,"price_str":"61335"},"channel":"live_orders_btcusd","event":"order_deleted"}
{"data":{"id":1722049096761346,"id_str":"1722049096761346","order_type":0,"datetime":"1709257117","microtimestamp":"1709257117445000","amount":0.01630781,"amount_str":"0.01630781","amount_traded":"0","amount_at_create":"0.01630781","price":61320,"price_str":"61320"},"channel":"live_orders_btcusd","event":"order_deleted"}
{"data":{"id":1722049096757251,"id_str":"1722049096757251","order_type":1,"datetime":"1709257117","microtimestamp":"1709257117445000","amount":0.01630534,"amount_str":"0.01630534","amount_traded":"0","amount_at_create":"0.01630534","price":61330,"price_str":"61330"},"channel":"live_orders_btcusd","event":"order_deleted"}
{"data":{"id":1722049096876033,"id_str":"1722049096876033","order_type":1,"datetime":"1709257117","microtimestamp":"1709257117449000","amount":0.02367419,"amount_str":"0.02367419","amount_traded":"0","amount_at_create":"0.02367419","price":61342,"price_str":"61342"},"channel":"live_orders_btcusd","event":"order_created"}
{"data":{"id":1722049096966147,"id_str":"1722049096966147","order_type":0,"datetime":"1709257117","microtimestamp":"1709257117471000","amount":0.1875,"amount_str":"0.18750000","amount_traded":"0","amount_at_create":"0.18750000","price":61312,"price_str":"61312"},"channel":"live_orders_btcusd","event":"order_created"}
{"data":{"id":1722049096876033,"id_str":"1722049096876033","order_type":1,"datetime":"1709257117","microtimestamp":"1709257117483000","amount":0.02367419,"amount_str":"0.02367419","amount_traded":"0","amount_at_create":"0.02367419","price":61342,"price_str":"61342"},"channel":"live_orders_btcusd","event":"order_deleted"}
{"data":{"id":1722049073512450,"id_str":"1722049073512450","order_type":1,"datetime":"1709257117","microtimestamp":"1709257117487000","amount":0.1875,"amount_str":"0.18750000","amount_traded":"0","amount_at_create":"0.18750000","price":61341,"price_str":"61341"},"channel":"live_orders_btcusd","event":"order_deleted"}
{"data":{"id":1722049097039873,"id_str":"1722049097039873","order_type":0,"datetime":"1709257117","microtimestamp":"1709257117490000","amount":0.00040756,"amount_str":"0.00040756","amount_traded":"0","amount_at_create":"0.00040756","price":61304,"price_str":"61304"},"channel":"live_orders_btcusd","event":"order_created"}
{"data":{"id":1722049090899969,"id_str":"1722049090899969","order_type":1,"datetime":"1709257118","microtimestamp":"1709257117505000","amount":0.00487283,"amount_str":"0.00487283","amount_traded":"0","amount_at_create":"0.00487283","price":61330,"price_str":"61330"},"channel":"live_orders_btcusd","event":"order_deleted"}
{"data":{"id":1722049097105408,"id_str":"1722049097105408","order_type":1,"datetime":"1709257118","microtimestamp":"1709257117505000","amount":0.0624925,"amount_str":"0.06249250","amount_traded":"0","amount_at_create":"0.06249250","price":61496,"price_str":"61496"},"channel":"live_orders_btcusd","event":"order_created"}
{"data":{"id":1722049095491585,"id_str":"1722049095491585","order_type":0,"datetime":"1709257118","microtimestamp":"1709257117511000","amount":0.00815401,"amount_str":"0.00815401","amount_traded":"0","amount_at_create":"0.00815401","price":61312,"price_str":"61312"},"channel":"live_orders_btcusd","event":"order_deleted"}
{"data":{"id":1722049091174403,"id_str":"1722049091174403","order_type":0,"datetime":"1709257118","microtimestamp":"1709257117517000","amount":0.16306563,"amount_str":"0.16306563","amount_traded":"0","amount_at_create":"0.16306563","price":61292,"price_str":"61292"},"channel":"live_orders_btcusd","event":"order_deleted"}
{"data":{"id":1722049097191424,"id_str":"1722049097191424","order_type":0,"datetime":"1709257118","microtimestamp":"1709257117526000","amount":0.0163077,"amount_str":"0.01630770","amount_traded":"0","amount_at_create":"0.01630770","price":61320,"price_str":"61320"},"channel":"live_orders_btcusd","event":"order_created"}
{"data":{"id":1722049097195520,"id_str":"1722049097195520","order_type":1,"datetime":"1709257118","microtimestamp":"1709257117528000","amount":0.02261012,"amount_str":"0.02261012","amount_traded":"0","amount_at_create":"0.02261012","price":61343,"price_str":"61343"},"channel":"live_orders_btcusd","event":"order_created"}
{"data":{"id":1722049097195522,"id_str":"1722049097195522","order_type":1,"datetime":"1709257118","microtimestamp":"1709257117528000","amount":0.01630526,"amount_str":"0.01630526","amount_traded":"0","amount_at_create":"0.01630526","price":61330,"price_str":"61330"},"channel":"live_orders_btcusd","event":"order_created"}
{"data":{"id":1722049097240577,"id_str":"1722049097240577","order_type":0,"datetime":"1709257118","microtimestamp":"1709257117539000","amount":0.00815401,"amount_str":"0.00815401","amount_traded":"0","amount_at_create":"0.00815401","price":61316,"price_str":"61316"},"channel":"live_orders_btcusd","event":"order_created"}
{"data":{"id":1722049096966147,"id_str":"1722049096966147","order_type":0,"datetime":"1709257118","microtimestamp":"1709257117542000","amount":0.1875,"amount_str":"0.18750000","amount_traded":"0","amount_at_create":"0.18750000","price":61312,"price_str":"61312"},"channel":"live_orders_btcusd","event":"order_deleted"}
{"data":{"id":1722049091452928,"id_str":"1722049091452928","order_type":1,"datetime":"1709257118","microtimestamp":"1709257117553000","amount":0.12188796,"amount_str":"0.12188796","amount_traded":"0","amount_at_create":"0.12188796","price":61379,"price_str":"61379"},"channel":"live_orders_btcusd","event":"order_deleted"}
{"data":{"id":1722049097351168,"id_str":"1722049097351168","order_type":0,"datetime":"1709257118","microtimestamp":"1709257117571000","amount":0.16308025,"amount_str":"0.16308025","amount_traded":"0","amount_at_create":"0.16308025","price":61297,"price_str":"61297"},"channel":"live_orders_btcusd","event":"order_created"}
{"data":{"id":1722049097420800,"id_str":"1722049097420800","order_type":1,"datetime":"1709257118","microtimestamp":"1709257117582000","amount":0.1875,"amount_str":"0.18750000","amount_traded":"0","amount_at_create":"0.18750000","price":61341,"price_str":"61341"},"channel":"live_orders_btcusd","event":"order_created"}
{"data":{"id":1722049097445376,"id_str":"1722049097445376","order_type":1,"datetime":"1709257118","microtimestamp":"1709257117598000","amount":0.00487327,"amount_str":"0.00487327","amount_traded":"0","amount_at_create":"0.00487327","price":61332,"price_str":"61332"},"channel":"live_orders_btcusd","event":"order_created"}
{"data":{"id":1722049097449472,"id_str":"1722049097449472","order_type":0,"datetime":"1709257118","microtimestamp":"1709257117598000","amount":0.48927668,"amount_str":"0.48927668","amount_traded":"0","amount_at_create":"0.48927668","price":61315,"price_str":"61315"},"channel":"live_orders_btcusd","event":"order_created"}
{"data":{"id":1722049097191424,"id_str":"1722049097191424","order_type":0,"datetime":"1709257118","microtimestamp":"1709257117600000","amount":0.0163077,"amount_str":"0.01630770","amount_traded":"0","amount_at_create":"0.01630770","price":61320,"price_str":"61320"},"channel":"live_orders_btcusd","event":"order_deleted"}
{"data":{"id":1722049097195522,"id_str":"1722049097195522","order_type":1,"datetime":"1709257118","microtimestamp":"1709257117603000","amount":0.01630526,"amount_str":"0.01630526","amount_traded":"0","amount_at_create":"0.01630526","price":61330,"price_str":"61330"},"channel":"live_orders_btcusd","event":"order_deleted"}
{"data":{"id":1722049097519104,"id_str":"1722049097519104","order_type":1,"datetime":"1709257118","microtimestamp":"1709257117606000","amount":0.12188796,"amount_str":"0.12188796","amount_traded":"0","amount_at_create":"0.12188796","price":61389,"price_str":"61389"},"channel":"live_orders_btcusd","event":"order_created"}
{"data":{"id":1722049097449472,"id_str":"1722049097449472","order_type":0,"datetime":"1709257118","microtimestamp":"1709257117625000","amount":0.48927668,"amount_str":"0.48927668","amount_traded":"0","amount_at_create":"0.48927668","price":61315,"price_str":"61315"},"channel":"live_orders_btcusd","event":"order_deleted"}
{"data":{"id":1722049091063809,"id_str":"1722049091063809","order_type":1,"datetime":"1709257118","microtimestamp":"1709257117631000","amount":0.09745678,"amount_str":"0.09745678","amount_traded":"0","amount_at_create":"0.09745678","price":61346,"price_str":"61346"},"channel":"live_orders_btcusd","event":"order_deleted"}
{"data":{"id":1722049097691137,"id_str":"1722049097691137","order_type":1,"datetime":"1709257118","microtimestamp":"1709257117648000","amount":0.4891517,"amount_str":"0.48915170","amount_traded":"0","amount_at_create":"0.48915170","price":61331,"price_str":"61331"},"channel":"live_orders_btcusd","event":"order_created"}
{"data":{"id":1722049097691139,"id_str":"1722049097691139","order_type":1,"datetime":"1709257118","microtimestamp":"1709257117648000","amount":0.09746155,"amount_str":"0.09746155","amount_traded":"0","amount_at_create":"0.09746155","price":61352,"price_str":"61352"},"channel":"live_orders_btcusd","event":"order_created"}
{"data":{"id":1722049097695232,"id_str":"1722049097695232","order_type":1,"datetime":"1709257118","microtimestamp":"1709257117649000","amount":0.01630563,"amount_str":"0.01630563","amount_traded":"0","amount_at_create":"0.01630563","price":61329,"price_str":"61329"},"channel":"live_orders_btcusd","event":"order_created"}
{"data":{"id":1722049097695233,"id_str":"1722049097695233","order_type":0,"datetime":"1709257118","microtimestamp":"1709257117649000","amount":0.01630922,"amount_str":"0.01630922","amount_traded":"0","amount_at_create":"0.01630922","price":61315,"price_str":"61315"},"channel":"live_orders_btcusd","event":"order_created"}
{"data":{"id":1722049097445376,"id_str":"1722049097445376","order_type":1,"datetime":"1709257118","microtimestamp":"1709257117657000","amount":0.00487327,"amount_str":"0.00487327","amount_traded":"0","amount_at_create":"0.00487327","price":61332,"price_str":"61332"},"channel":"live_orders_btcusd","event":"order_deleted"}
{"data":{"id":1722049097732096,"id_str":"1722049097732096","order_type":0,"datetime":"1709257118","microtimestamp":"1709257117658000","amount":0.1875,"amount_str":"0.18750000","amount_traded":"0","amount_at_create":"0.18750000","price":61309,"price_str":"61309"},"channel":"live_orders_btcusd","event":"order_created"}
{"data":{"id":1722049097695233,"id_str":"1722049097695233","order_type":0,"datetime":"1709257118","microtimestamp":"1709257117668000","amount":0.01630922,"amount_str":"0.01630922","amount_traded":"0","amount_at_create":"0.01630922","price":61315,"price_str":"61315"},"channel":"live_orders_btcusd","event":"order_deleted"}
{"data":{"id":1722049097797633,"id_str":"1722049097797633","order_type":1,"datetime":"1709257118","microtimestamp":"1709257117674000","amount":0.00487307,"amount_str":"0.00487307","amount_traded":"0","amount_at_create":"0.00487307","price":61334,"price_str":"61334"},"channel":"live_orders_btcusd","event":"order_created"}
{"data":{"id":1722049096581120,"id_str":"1722049096581120","order_type":0,"datetime":"1709257118","microtimestamp":"1709257117681000","amount":0.00815401,"amount_str":"0.00815401","amount_traded":"0","amount_at_create":"0.00815401","price":61314,"price_str":"61314"},"channel":"live_orders_btcusd","event":"order_deleted"}
{"data":{"id":1722049097904128,"id_str":"1722049097904128","order_type":0,"datetime":"1709257118","microtimestamp":"1709257117700000","amount":0.00815328,"amount_str":"0.00815328","amount_traded":"0","amount_at_create":"0.00815328","price":61318,"price_str":"61318"},"channel":"live_orders_btcusd","event":"order_created"}
{"data":{"id":1722049097039873,"id_str":"1722049097039873","order_type":0,"datetime":"1709257118","microtimestamp":"1709257117730000","amount":0.00040756,"amount_str":"0.00040756","amount_traded":"0","amount_at_create":"0.00040756","price":61304,"price_str":"61304"},"channel":"live_orders_btcusd","event":"order_deleted"}
{"data":{"id":1722049098182656,"id_str":"1722049098182656","order_type":0,"datetime":"1709257118","microtimestamp":"1709257117768000","amount":0.01630807,"amount_str":"0.01630807","amount_traded":"0","amount_at_create":"0.01630807","price":61319,"price_str":"61319"},"channel":"live_orders_btcusd","event":"order_created"}
{"data":{"id":1722049098358786,"id_str":"1722049098358786","order_type":0,"datetime":"1709257118","microtimestamp":"1709257117812000","amount":0.48925958,"amount_str":"0.48925958","amount_traded":"0","amount_at_create":"0.48925958","price":61317,"price_str":"61317"},"channel":"live_orders_btcusd","event":"order_created"}
{"data":{"id":1722049098510339,"id_str":"1722049098510339","order_type":0,"datetime":"1709257118","microtimestamp":"1709257117849000","amount":0.00040756,"amount_str":"0.00040756","amount_traded":"0","amount_at_create":"0.00040756","price":61305,"price_str":"61305"},"channel":"live_orders_btcusd","event":"order_created"}
{"data":{"id":1722049097695232,"id_str":"1722049097695232","order_type":1,"datetime":"1709257118","microtimestamp":"1709257117941000","amount":0.01630563,"amount_str":"0.01630563","amount_traded":"0","amount_at_create":"0.01630563","price":61329,"price_str":"61329"},"channel":"live_orders_btcusd","event":"order_deleted"}
{"data":{"id":1722049099005953,"id_str":"1722049099005953","order_type":1,"datetime":"1709257118","microtimestamp":"1709257117969000","amount":0.48911959,"amount_str":"0.48911959","amount_traded":"0","amount_at_create":"0.48911959","price":61335,"price_str":"61335"},"channel":"live_orders_btcusd","event":"order_created"}
{"data":{"id":1722049097904128,"id_str":"1722049097904128","order_type":0,"datetime":"1709257118","microtimestamp":"1709257118000000","amount":0.00815328,"amount_str":"0.00815328","amount_traded":"0","amount_at_create":"0.00815328","price":61318,"price_str":"61318"},"channel":"live_orders_btcusd","event":"order_deleted"}
{"data":{"id":1722049097691137,"id_str":"1722049097691137","order_type":1,"datetime":"1709257118","microtimestamp":"1709257118003000","amount":0.4891517,"amount_str":"0.48915170","amount_traded":"0","amount_at_create":"0.48915170","price":61331,"price_str":"61331"},"channel":"live_orders_btcusd","event":"order_deleted"}
{"data":{"id":1722049099194368,"id_str":"1722049099194368","order_type":1,"datetime":"1709257118","microtimestamp":"1709257118015000","amount":0.01630582,"amount_str":"0.01630582","amount_traded":"0","amount_at_create":"0.01630582","price":61328,"price_str":"61328"},"channel":"live_orders_btcusd","event":"order_created"}
{"data":{"id":1722049099194370,"id_str":"1722049099194370","order_type":1,"datetime":"1709257118","microtimestamp":"1709257118016000","amount":0.488961,"amount_str":"0.48896100","amount_traded":"0","amount_at_create":"0.48896100","price":61355,"price_str":"61355"},"channel":"live_orders_btcusd","event":"order_created"}
{"data":{"id":1722049099198464,"id_str":"1722049099198464","order_type":0,"datetime":"1709257118","microtimestamp":"1709257118016000","amount":0.48945059,"amount_str":"0.48945059","amount_traded":"0","amount_at_create":"0.48945059","price":61293,"price_str":"61293"},"channel":"live_orders_btcusd","event":"order_created"}
{"data":{"id":1722049098510339,"id_str":"1722049098510339","order_type":0,"datetime":"1709257118","microtimestamp":"1709257118023000","amount":0.00040756,"amount_str":"0.00040756","amount_traded":"0","amount_at_create":"0.00040756","price":61305,"price_str":"61305"},"channel":"live_orders_btcusd","event":"order_deleted"}
{"data":{"id":1722049099378689,"id_str":"1722049099378689","order_type":1,"datetime":"1709257118","microtimestamp":"1709257118061000","amount":0.48915837,"amount_str":"0.48915837","amount_traded":"0","amount_at_create":"0.48915837","price":61330,"price_str":"61330"},"channel":"live_orders_btcusd","event":"order_created"}
{"data":{"id":1722049099706369,"id_str":"1722049099706369","order_type":0,"datetime":"1709257118","microtimestamp":"1709257118140000","amount":0.00040756,"amount_str":"0.00040756","amount_traded":"0","amount_at_create":"0.00040756","price":61304,"price_str":"61304"},"channel":"live_orders_btcusd","event":"order_created"}
{"data":{"id":1722048604282881,"id_str":"1722048604282881","order_type":1,"datetime":"1709257118","microtimestamp":"1709257118158000","amount":2.318,"amount_str":"2.31800000","amount_traded":"0","amount_at_create":"2.31800000","price":61512,"price_str":"61512"},"channel":"live_orders_btcusd","event":"order_deleted"}
{"data":{"id":1722049099894784,"id_str":"1722049099894784","order_type":0,"datetime":"1709257118","microtimestamp":"1709257118186000","amount":0.04875518,"amount_str":"0.04875518","amount_traded":"0","amount_at_create":"0.04875518","price":61290,"price_str":"61290"},"channel":"live_orders_btcusd","event":"order_created"}
{"data":{"id":1722049100021760,"id_str":"1722049100021760","order_type":1,"datetime":"1709257118","microtimestamp":"1709257118218000","amount":2.321,"amount_str":"2.32100000","amount_traded":"0","amount_at_create":"2.32100000","price":61461,"price_str":"61461"},"channel":"live_orders_btcusd","event":"order_created"}
{"data":{"id":1722049099706369,"id_str":"1722049099706369","order_type":0,"datetime":"1709257118","microtimestamp":"1709257118292000","amount":0.00040756,"amount_str":"0.00040756","amount_traded":"0","amount_at_create":"0.00040756","price":61304,"price_str":"61304"},"channel":"live_orders_btcusd","event":"order_deleted"}
{"data":{"id":1722049100681216,"id_str":"1722049100681216","order_type":0,"datetime":"1709257118","microtimestamp":"1709257118378000","amount":0.00040756,"amount_str":"0.00040756","amount_traded":"0","amount_at_create":"0.00040756","price":61305,"price_str":"61305"},"channel":"live_orders_btcusd","event":"order_created"}
{"data":{"id":1722049100681216,"id_str":"1722049100681216","order_type":0,"datetime":"1709257118","microtimestamp":"1709257118450000","amount":0.00040756,"amount_str":"0.00040756","amount_traded":"0","amount_at_create":"0.00040756","price":61305,"price_str":"61305"},"channel":"live_orders_btcusd","event":"order_deleted"}
{"data":{"id":1722049101131776,"id_str":"1722049101131776","order_type":1,"datetime":"1709257118","microtimestamp":"1709257118488000","amount":0.00487295,"amount_str":"0.00487295","amount_traded":"0","amount_at_create":"0.00487295","price":61332,"price_str":"61332"},"channel":"live_orders_btcusd","event":"order_created"}
{"data":{"id":1722049101287424,"id_str":"1722049101287424","order_type":0,"datetime":"1709257119","microtimestamp":"1709257118526000","amount":0.00040756,"amount_str":"0.00040756","amount_traded":"0","amount_at_create":"0.00040756","price":61304,"price_str":"61304"},"channel":"live_orders_btcusd","event":"order_created"}
{"data":{"id":1722049097732096,"id_str":"1722049097732096","order_type":0,"datetime":"1709257119","microtimestamp":"1709257118611000","amount":0.1875,"amount_str":"0.18750000","amount_traded":"0","amount_at_create":"0.18750000","price":61309,"price_str":"61309"},"channel":"live_orders_btcusd","event":"order_deleted"}
{"data":{"id":1722049101287424,"id_str":"1722049101287424","order_type":0,"datetime":"1709257119","microtimestamp":"1709257118700000","amount":0.00040756,"amount_str":"0.00040756","amount_traded":"0","amount_at_create":"0.00040756","price":61304,"price_str":"61304"},"channel":"live_orders_btcusd","event":"order_deleted"}
{"data":{"id":1722049096769538,"id_str":"1722049096769538","order_type":1,"datetime":"1709257119","microtimestamp":"1709257118722000","amount":0.48904956,"amount_str":"0.48904956","amount_traded":"0","amount_at_create":"0.48904956","price":61344,"price_str":"61344"},"channel":"live_orders_btcusd","event":"order_deleted"}
{"data":{"id":1722049099194368,"id_str":"1722049099194368","order_type":1,"datetime":"1709257119","microtimestamp":"1709257118722000","amount":0.01630582,"amount_str":"0.01630582","amount_traded":"0","amount_at_create":"0.01630582","price":61328,"price_str":"61328"},"channel":"live_orders_btcusd","event":"order_deleted"}
{"data":{"id":1722049098182656,"id_str":"1722049098182656","order_type":0,"datetime":"1709257119","microtimestamp":"1709257118722000","amount":0.01630807,"amount_str":"0.01630807","amount_traded":"0","amount_at_create":"0.01630807","price":61319,"price_str":"61319"},"channel":"live_orders_btcusd","event":"order_deleted"}
{"data":{"id":1722049096777729,"id_str":"1722049096777729","order_type":0,"datetime":"1709257119","microtimestamp":"1709257118722000","amount":0.48928391,"amount_str":"0.48928391","amount_traded":"0","amount_at_create":"0.48928391","price":61314,"price_str":"61314"},"channel":"live_orders_btcusd","event":"order_deleted"}
{"data":{"id":1722049099005953,"id_str":"1722049099005953","order_type":1,"datetime":"1709257119","microtimestamp":"1709257118722000","amount":0.48911959,"amount_str":"0.48911959","amount_traded":"0","amount_at_create":"0.48911959","price":61335,"price_str":"61335"},"channel":"live_orders_btcusd","event":"order_deleted"}
{"data":{"id":1722049099378689,"id_str":"1722049099378689","order_type":1,"datetime":"1709257119","microtimestamp":"1709257118723000","amount":0.48915837,"amount_str":"0.48915837","amount_traded":"0","amount_at_create":"0.48915837","price":61330,"price_str":"61330"},"channel":"live_orders_btcusd","event":"order_deleted"}
{"data":{"id":1722049098358786,"id_str":"1722049098358786","order_type":0,"datetime":"1709257119","microtimestamp":"1709257118724000","amount":0.48925958,"amount_str":"0.48925958","amount_traded":"0","amount_at_create":"0.48925958","price":61317,"price_str":"61317"},"channel":"live_orders_btcusd","event":"order_deleted"}
{"data":{"id":1722049102290946,"id_str":"1722049102290946","order_type":1,"datetime":"1709257119","microtimestamp":"1709257118772000","amount":0.48916905,"amount_str":"0.48916905","amount_traded":"0","amount_at_create":"0.48916905","price":61329,"price_str":"61329"},"channel":"live_orders_btcusd","event":"order_created"}
{"data":{"id":1722049102295042,"id_str":"1722049102295042","order_type":0,"datetime":"1709257119","microtimestamp":"1709257118772000","amount":0.4893067,"amount_str":"0.48930670","amount_traded":"0","amount_at_create":"0.48930670","price":61311,"price_str":"61311"},"channel":"live_orders_btcusd","event":"order_created"}
{"data":{"id":1722049102299136,"id_str":"1722049102299136","order_type":1,"datetime":"1709257119","microtimestamp":"1709257118773000","amount":0.48861987,"amount_str":"0.48861987","amount_traded":"0","amount_at_create":"0.48861987","price":61398,"price_str":"61398"},"channel":"live_orders_btcusd","event":"order_created"}
{"data":{"id":1722049102307328,"id_str":"1722049102307328","order_type":0,"datetime":"1709257119","microtimestamp":"1709257118775000","amount":0.48927464,"amount_str":"0.48927464","amount_traded":"0","amount_at_create":"0.48927464","price":61315,"price_str":"61315"},"channel":"live_orders_btcusd","event":"order_created"}
{"data":{"id":1722049102307332,"id_str":"1722049102307332","order_type":0,"datetime":"1709257119","microtimestamp":"1709257118775000","amount":0.01630857,"amount_str":"0.01630857","amount_traded":"0","amount_at_create":"0.01630857","price":61317,"price_str":"61317"},"channel":"live_orders_btcusd","event":"order_created"}
{"data":{"id":1722049102307333,"id_str":"1722049102307333","order_type":0,"datetime":"1709257119","microtimestamp":"1709257118776000","amount":0.48934304,"amount_str":"0.48934304","amount_traded":"0","amount_at_create":"0.48934304","price":61306,"price_str":"61306"},"channel":"live_orders_btcusd","event":"order_created"}
{"data":{"id":1722049102311424,"id_str":"1722049102311424","order_type":1,"datetime":"1709257119","microtimestamp":"1709257118776000","amount":0.48913699,"amount_str":"0.48913699","amount_traded":"0","amount_at_create":"0.48913699","price":61333,"price_str":"61333"},"channel":"live_orders_btcusd","event":"order_created"}
{"data":{"id":1722049102311426,"id_str":"1722049102311426","order_type":1,"datetime":"1709257119","microtimestamp":"1709257118776000","amount":0.01630625,"amount_str":"0.01630625","amount_traded":"0","amount_at_create":"0.01630625","price":61327,"price_str":"61327"},"channel":"live_orders_btcusd","event":"order_created"}
{"data":{"id":1722049102323712,"id_str":"1722049102323712","order_type":1,"datetime":"1709257119","microtimestamp":"1709257118779000","amount":0.48907796,"amount_str":"0.48907796","amount_traded":"0","amount_at_create":"0.48907796","price":61340,"price_str":"61340"},"channel":"live_orders_btcusd","event":"order_created"}
{"data":{"id":1722049102311426,"id_str":"1722049102311426","order_type":1,"datetime":"1709257119","microtimestamp":"1709257118800000","amount":0.01630625,"amount_str":"0.01630625","amount_traded":"0","amount_at_create":"0.01630625","price":61327,"price_str":"61327"},"channel":"live_orders_btcusd","event":"order_deleted"}
{"data":{"id":1722049099198464,"id_str":"1722049099198464","order_type":0,"datetime":"1709257119","microtimestamp":"1709257118841000","amount":0.48945059,"amount_str":"0.48945059","amount_traded":"0","amount_at_create":"0.48945059","price":61293,"price_str":"61293"},"channel":"live_orders_btcusd","event":"order_deleted"}
{"data":{"id":1722049079664642,"id_str":"1722049079664642","order_type":1,"datetime":"1709257119","microtimestamp":"1709257118846000","amount":0.9316458,"amount_str":"0.93164580","amount_traded":"0","amount_at_create":"0.93164580","price":61364,"price_str":"61364"},"channel":"live_orders_btcusd","event":"order_deleted"}
{"data":{"id":1722049102598147,"id_str":"1722049102598147","order_type":0,"datetime":"1709257119","microtimestamp":"1709257118846000","amount":0.00040756,"amount_str":"0.00040756","amount_traded":"0","amount_at_create":"0.00040756","price":61305,"price_str":"61305"},"channel":"live_orders_btcusd","event":"order_created"}
{"data":{"id":1722049102761984,"id_str":"1722049102761984","order_type":1,"datetime":"1709257119","microtimestamp":"1709257118886000","amount":0.93124727,"amount_str":"0.93124727","amount_traded":"0","amount_at_create":"0.93124727","price":61363,"price_str":"61363"},"channel":"live_orders_btcusd","event":"order_created"}
{"data":{"id":1722049102766084,"id_str":"1722049102766084","order_type":1,"datetime":"1709257119","microtimestamp":"1709257118887000","amount":0.01630632,"amount_str":"0.01630632","amount_traded":"0","amount_at_create":"0.01630632","price":61326,"price_str":"61326"},"channel":"live_orders_btcusd","event":"order_created"}
{"data":{"id":1722049102290946,"id_str":"1722049102290946","order_type":1,"datetime":"1709257119","microtimestamp":"1709257118898000","amount":0.48916905,"amount_str":"0.48916905","amount_traded":"0","amount_at_create":"0.48916905","price":61329,"price_str":"61329"},"channel":"live_orders_btcusd","event":"order_deleted"}
{"data":{"id":1722049102598147,"id_str":"1722049102598147","order_type":0,"datetime":"1709257119","microtimestamp":"1709257118961000","amount":0.00040756,"amount_str":"0.00040756","amount_traded":"0","amount_at_create":"0.00040756","price":61305,"price_str":"61305"},"channel":"live_orders_btcusd","event":"order_deleted"}
{"data":{"id":1722049103970306,"id_str":"1722049103970306","order_type":0,"datetime":"1709257119","microtimestamp":"1709257119181000","amount":0.00040756,"amount_str":"0.00040756","amount_traded":"0","amount_at_create":"0.00040756","price":61304,"price_str":"61304"},"channel":"live_orders_btcusd","event":"order_created"}
{"data":{"id":1722049103970306,"id_str":"1722049103970306","order_type":0,"datetime":"1709257119","microtimestamp":"1709257119290000","amount":0.00040756,"amount_str":"0.00040756","amount_traded":"0","amount_at_create":"0.00040756","price":61304,"price_str":"61304"},"channel":"live_orders_btcusd","event":"order_deleted"}
{"data":{"id":1722049105395712,"id_str":"1722049105395712","order_type":0,"datetime":"1709257120","microtimestamp":"1709257119529000","amount":0.48956434,"amount_str":"0.48956434","amount_traded":"0","amount_at_create":"0.48956434","price":61278,"price_str":"61278"},"channel":"live_orders_btcusd","event":"order_created"}
{"data":{"id":1722049105395714,"id_str":"1722049105395714","order_type":1,"datetime":"1709257120","microtimestamp":"1709257119529000","amount":0.48917297,"amount_str":"0.48917297","amount_traded":"0","amount_at_create":"0.48917297","price":61328,"price_str":"61328"},"channel":"live_orders_btcusd","event":"order_created"}
{"data":{"id":1722049105399809,"id_str":"1722049105399809","order_type":1,"datetime":"1709257120","microtimestamp":"1709257119531000","amount":0.48883065,"amount_str":"0.48883065","amount_traded":"0","amount_at_create":"0.48883065","price":61371,"price_str":"61371"},"channel":"live_orders_btcusd","event":"order_created"}
{"data":{"id":1722049105428480,"id_str":"1722049105428480","order_type":0,"datetime":"1709257120","microtimestamp":"1709257119537000","amount":0.00040756,"amount_str":"0.00040756","amount_traded":"0","amount_at_create":"0.00040756","price":61305,"price_str":"61305"},"channel":"live_orders_btcusd","event":"order_created"}
{"data":{"id":1722049105428480,"id_str":"1722049105428480","order_type":0,"datetime":"1709257120","microtimestamp":"1709257119575000","amount":0.00040756,"amount_str":"0.00040756","amount_traded":"0","amount_at_create":"0.00040756","price":61305,"price_str":"61305"},"channel":"live_orders_btcusd","event":"order_deleted"}
{"data":{"id":1722049105768449,"id_str":"1722049105768449","order_type":0,"datetime":"1709257120","microtimestamp":"1709257119620000","amount":0.00040756,"amount_str":"0.00040756","amount_traded":"0","amount_at_create":"0.00040756","price":61304,"price_str":"61304"},"channel":"live_orders_btcusd","event":"order_created"}
{"data":{"id":1722049105768449,"id_str":"1722049105768449","order_type":0,"datetime":"1709257120","microtimestamp":"1709257119769000","amount":0.00040756,"amount_str":"0.00040756","amount_traded":"0","amount_at_create":"0.00040756","price":61304,"price_str":"61304"},"channel":"live_orders_btcusd","event":"order_deleted"}
{"data":{"id":1722049106501632,"id_str":"1722049106501632","order_type":0,"datetime":"1709257120","microtimestamp":"1709257119800000","amount":0.00040756,"amount_str":"0.00040756","amount_traded":"0","amount_at_create":"0.00040756","price":61305,"price_str":"61305"},"channel":"live_orders_btcusd","event":"order_created"}
{"data":{"id":1722049106501632,"id_str":"1722049106501632","order_type":0,"datetime":"1709257120","microtimestamp":"1709257119861000","amount":0.00040756,"amount_str":"0.00040756","amount_traded":"0","amount_at_create":"0.00040756","price":61305,"price_str":"61305"},"channel":"live_orders_btcusd","event":"order_deleted"}
{"data":{"id":1722049092734977,"id_str":"1722049092734977","order_type":0,"datetime":"1709257120","microtimestamp":"1709257119928000","amount":0.1875,"amount_str":"0.18750000","amount_traded":"0","amount_at_create":"0.18750000","price":61212,"price_str":"61212"},"channel":"live_orders_btcusd","event":"order_deleted"}
{"data":{"id":1722048564494337,"id_str":"1722048564494337","order_type":1,"datetime":"1709257120","microtimestamp":"1709257119929000","amount":0.1875,"amount_str":"0.18750000","amount_traded":"0","amount_at_create":"0.18750000","price":61507,"price_str":"61507"},"channel":"live_orders_btcusd","event":"order_deleted"}
{"data":{"id":1722049107140608,"id_str":"1722049107140608","order_type":0,"datetime":"1709257120","microtimestamp":"1709257119955000","amount":0.00040756,"amount_str":"0.00040756","amount_traded":"0","amount_at_create":"0.00040756","price":61304,"price_str":"61304"},"channel":"live_orders_btcusd","event":"order_created"}
{"data":{"id":1722049107140608,"id_str":"1722049107140608","order_type":0,"datetime":"1709257120","microtimestamp":"1709257120068000","amount":0.00040756,"amount_str":"0.00040756","amount_traded":"0","amount_at_create":"0.00040756","price":61304,"price_str":"61304"},"channel":"live_orders_btcusd","event":"order_deleted"}
{"data":{"id":1722049102307328,"id_str":"1722049102307328","order_type":0,"datetime":"1709257120","microtimestamp":"1709257120098000","amount":0.48927464,"amount_str":"0.48927464","amount_traded":"0","amount_at_create":"0.48927464","price":61315,"price_str":"61315"},"channel":"live_orders_btcusd","event":"order_deleted"}
{"data":{"id":1722049102307332,"id_str":"1722049102307332","order_type":0,"datetime":"1709257120","microtimestamp":"1709257120098000","amount":0.01630857,"amount_str":"0.01630857","amount_traded":"0","amount_at_create":"0.01630857","price":61317,"price_str":"61317"},"channel":"live_orders_btcusd","event":"order_deleted"}
{"data":{"id":1722049107918850,"id_str":"1722049107918850","order_type":0,"datetime":"1709257120","microtimestamp":"1709257120146000","amount":0.01630832,"amount_str":"0.01630832","amount_traded":"0","amount_at_create":"0.01630832","price":61318,"price_str":"61318"},"channel":"live_orders_btcusd","event":"order_created"}
{"data":{"id":1722049107918851,"id_str":"1722049107918851","order_type":0,"datetime":"1709257120","microtimestamp":"1709257120146000","amount":0.48926723,"amount_str":"0.48926723","amount_traded":"0","amount_at_create":"0.48926723","price":61316,"price_str":"61316"},"channel":"live_orders_btcusd","event":"order_created"}
{"data":{"id":1722049107927043,"id_str":"1722049107927043","order_type":0,"datetime":"1709257120","microtimestamp":"1709257120147000","amount":0.48948392,"amount_str":"0.48948392","amount_traded":"0","amount_at_create":"0.48948392","price":61289,"price_str":"61289"},"channel":"live_orders_btcusd","event":"order_created"}
{"data":{"id":1722049108062209,"id_str":"1722049108062209","order_type":0,"datetime":"1709257120","microtimestamp":"1709257120180000","amount":0.00040756,"amount_str":"0.00040756","amount_traded":"0","amount_at_create":"0.00040756","price":61304,"price_str":"61304"},"channel":"live_orders_btcusd","event":"order_created"}
{"data":{"id":1722049108062209,"id_str":"1722049108062209","order_type":0,"datetime":"1709257120","microtimestamp":"1709257120296000","amount":0.00040756,"amount_str":"0.00040756","amount_traded":"0","amount_at_create":"0.00040756","price":61304,"price_str":"61304"},"channel":"live_orders_btcusd","event":"order_deleted"}
{"data":{"id":1722049109053440,"id_str":"1722049109053440","order_type":0,"datetime":"1709257120","microtimestamp":"1709257120422000","amount":0.00040756,"amount_str":"0.00040756","amount_traded":"0","amount_at_create":"0.00040756","price":61305,"price_str":"61305"},"channel":"live_orders_btcusd","event":"order_created"}
{"data":{"id":1722049107918851,"id_str":"1722049107918851","order_type":0,"datetime":"1709257120","microtimestamp":"1709257120467000","amount":0.48926723,"amount_str":"0.48926723","amount_traded":"0","amount_at_create":"0.48926723","price":61316,"price_str":"61316"},"channel":"live_orders_btcusd","event":"order_deleted"}
{"data":{"id":1722049109053440,"id_str":"1722049109053440","order_type":0,"datetime":"1709257120","microtimestamp":"1709257120469000","amount":0.00040756,"amount_str":"0.00040756","amount_traded":"0","amount_at_create":"0.00040756","price":61305,"price_str":"61305"},"channel":"live_orders_btcusd","event":"order_deleted"}
{"data":{"id":1722049109430272,"id_str":"1722049109430272","order_type":0,"datetime":"1709257121","microtimestamp":"1709257120515000","amount":0.48927739,"amount_str":"0.48927739","amount_traded":"0","amount_at_create":"0.48927739","price":61314,"price_str":"61314"},"channel":"live_orders_btcusd","event":"order_created"}
{"data":{"id":1722049109430272,"id_str":"1722049109430272","order_type":0,"datetime":"1709257121","microtimestamp":"1709257120529000","amount":0.48927739,"amount_str":"0.48927739","amount_traded":"0","amount_at_create":"0.48927739","price":61314,"price_str":"61314"},"channel":"live_orders_btcusd","event":"order_deleted"}
{"data":{"id":1722049092141057,"id_str":"1722049092141057","order_type":1,"datetime":"1709257121","microtimestamp":"1709257120604000","amount":0.815832,"amount_str":"0.81583200","amount_traded":"0","amount_at_create":"0.81583200","price":61334,"price_str":"61334"},"channel":"live_orders_btcusd","event":"order_deleted"}
{"data":{"id":1722049107918850,"id_str":"1722049107918850","order_type":0,"datetime":"1709257121","microtimestamp":"1709257120606000","amount":0.01630832,"amount_str":"0.01630832","amount_traded":"0","amount_at_create":"0.01630832","price":61318,"price_str":"61318"},"channel":"live_orders_btcusd","event":"order_deleted"}
{"data":{"id":1722049102766084,"id_str":"1722049102766084","order_type":1,"datetime":"1709257121","microtimestamp":"1709257120606000","amount":0.01630632,"amount_str":"0.01630632","amount_traded":"0","amount_at_create":"0.01630632","price":61326,"price_str":"61326"},"channel":"live_orders_btcusd","event":"order_deleted"}
{"data":{"id":1722049102295042,"id_str":"1722049102295042","order_type":0,"datetime":"1709257121","microtimestamp":"1709257120606000","amount":0.4893067,"amount_str":"0.48930670","amount_traded":"0","amount_at_create":"0.48930670","price":61311,"price_str":"61311"},"channel":"live_orders_btcusd","event":"order_deleted"}
{"data":{"id":1722049105395714,"id_str":"1722049105395714","order_type":1,"datetime":"1709257121","microtimestamp":"1709257120607000","amount":0.48917297,"amount_str":"0.48917297","amount_traded":"0","amount_at_create":"0.48917297","price":61328,"price_str":"61328"},"channel":"live_orders_btcusd","event":"order_deleted"}
{"data":{"id":1722049109843969,"id_str":"1722049109843969","order_type":0,"datetime":"1709257121","microtimestamp":"1709257120616000","amount":0.00040756,"amount_str":"0.00040756","amount_traded":"0","amount_at_create":"0.00040756","price":61304,"price_str":"61304"},"channel":"live_orders_btcusd","event":"order_created"}
{"data":{"id":1722049109987328,"id_str":"1722049109987328","order_type":1,"datetime":"1709257121","microtimestamp":"1709257120650000","amount":0.01630571,"amount_str":"0.01630571","amount_traded":"0","amount_at_create":"0.01630571","price":61329,"price_str":"61329"},"channel":"live_orders_btcusd","event":"order_created"}
{"data":{"id":1722049109991427,"id_str":"1722049109991427","order_type":0,"datetime":"1709257121","microtimestamp":"1709257120652000","amount":0.01630796,"amount_str":"0.01630796","amount_traded":"0","amount_at_create":"0.01630796","price":61319,"price_str":"61319"},"channel":"live_orders_btcusd","event":"order_created"}
{"data":{"id":1722049109995521,"id_str":"1722049109995521","order_type":1,"datetime":"1709257121","microtimestamp":"1709257120652000","amount":0.48915387,"amount_str":"0.48915387","amount_traded":"0","amount_at_create":"0.48915387","price":61331,"price_str":"61331"},"channel":"live_orders_btcusd","event":"order_created"}
{"data":{"id":1722049109999616,"id_str":"1722049109999616","order_type":1,"datetime":"1709257121","microtimestamp":"1709257120653000","amount":0.815832,"amount_str":"0.81583200","amount_traded":"0","amount_at_create":"0.81583200","price":61341,"price_str":"61341"},"channel":"live_orders_btcusd","event":"order_created"}
{"data":{"id":1722049109991427,"id_str":"1722049109991427","order_type":0,"datetime":"1709257121","microtimestamp":"1709257120704000","amount":0.01630796,"amount_str":"0.01630796","amount_traded":"0","amount_at_create":"0.01630796","price":61319,"price_str":"61319"},"channel":"live_orders_btcusd","event":"order_deleted"}
{"data":{"id":1722049110261764,"id_str":"1722049110261764","order_type":0,"datetime":"1709257121","microtimestamp":"1709257120718000","amount":0.48925664,"amount_str":"0.48925664","amount_traded":"0","amount_at_create":"0.48925664","price":61317,"price_str":"61317"},"channel":"live_orders_btcusd","event":"order_created"}
{"data":{"id":1722049109843969,"id_str":"1722049109843969","order_type":0,"datetime":"1709257121","microtimestamp":"1709257120729000","amount":0.00040756,"amount_str":"0.00040756","amount_traded":"0","amount_at_create":"0.00040756","price":61304,"price_str":"61304"},"channel":"live_orders_btcusd","event":"order_deleted"}
{"data":{"id":1722049097420800,"id_str":"1722049097420800","order_type":1,"datetime":"1709257121","microtimestamp":"1709257120732000","amount":0.1875,"amount_str":"0.18750000","amount_traded":"0","amount_at_create":"0.18750000","price":61341,"price_str":"61341"},"channel":"live_orders_btcusd","event":"order_deleted"}
{"data":{"id":1722049110446082,"id_str":"1722049110446082","order_type":0,"datetime":"1709257121","microtimestamp":"1709257120763000","amount":0.01630786,"amount_str":"0.01630786","amount_traded":"0","amount_at_create":"0.01630786","price":61320,"price_str":"61320"},"channel":"live_orders_btcusd","event":"order_created"}
{"data":{"id":1722049110491136,"id_str":"1722049110491136","order_type":0,"datetime":"1709257121","microtimestamp":"1709257120773000","amount":0.1875,"amount_str":"0.18750000","amount_traded":"0","amount_at_create":"0.18750000","price":61310,"price_str":"61310"},"channel":"live_orders_btcusd","event":"order_created"}
{"data":{"id":1722049110900738,"id_str":"1722049110900738","order_type":0,"datetime":"1709257121","microtimestamp":"1709257120873000","amount":0.00040756,"amount_str":"0.00040756","amount_traded":"0","amount_at_create":"0.00040756","price":61305,"price_str":"61305"},"channel":"live_orders_btcusd","event":"order_created"}
{"data":{"id":1722049109987328,"id_str":"1722049109987328","order_type":1,"datetime":"1709257121","microtimestamp":"1709257120898000","amount":0.01630571,"amount_str":"0.01630571","amount_traded":"0","amount_at_create":"0.01630571","price":61329,"price_str":"61329"},"channel":"live_orders_btcusd","event":"order_deleted"}
{"data":{"id":1722049109995521,"id_str":"1722049109995521","order_type":1,"datetime":"1709257121","microtimestamp":"1709257120899000","amount":0.48915387,"amount_str":"0.48915387","amount_traded":"0","amount_at_create":"0.48915387","price":61331,"price_str":"61331"},"channel":"live_orders_btcusd","event":"order_deleted"}
{"data":{"id":1722049110491136,"id_str":"1722049110491136","order_type":0,"datetime":"1709257121","microtimestamp":"1709257120917000","amount":0.1875,"amount_str":"0.18750000","amount_traded":"0","amount_at_create":"0.18750000","price":61310,"price_str":"61310"},"channel":"live_orders_btcusd","event":"order_deleted"}
{"data":{"id":1722049111187456,"id_str":"1722049111187456","order_type":1,"datetime":"1709257121","microtimestamp":"1709257120943000","amount":0.1875,"amount_str":"0.18750000","amount_traded":"0","amount_at_create":"0.18750000","price":61339,"price_str":"61339"},"channel":"live_orders_btcusd","event":"order_created"}
{"data":{"id":1722049111191552,"id_str":"1722049111191552","order_type":1,"datetime":"1709257121","microtimestamp":"1709257120944000","amount":0.01630589,"amount_str":"0.01630589","amount_traded":"0","amount_at_create":"0.01630589","price":61328,"price_str":"61328"},"channel":"live_orders_btcusd","event":"order_created"}
{"data":{"id":1722049111191554,"id_str":"1722049111191554","order_type":1,"datetime":"1709257121","microtimestamp":"1709257120945000","amount":0.4891592,"amount_str":"0.48915920","amount_traded":"0","amount_at_create":"0.48915920","price":61330,"price_str":"61330"},"channel":"live_orders_btcusd","event":"order_created"}
{"data":{"id":1722049111207936,"id_str":"1722049111207936","order_type":0,"datetime":"1709257121","microtimestamp":"1709257120948000","amount":0.48929411,"amount_str":"0.48929411","amount_traded":"0","amount_at_create":"0.48929411","price":61312,"price_str":"61312"},"channel":"live_orders_btcusd","event":"order_created"}
{"data":{"id":1722049110900738,"id_str":"1722049110900738","order_type":0,"datetime":"1709257121","microtimestamp":"1709257120955000","amount":0.00040756,"amount_str":"0.00040756","amount_traded":"0","amount_at_create":"0.00040756","price":61305,"price_str":"61305"},"channel":"live_orders_btcusd","event":"order_deleted"}
{"data":{"id":1722049111191552,"id_str":"1722049111191552","order_type":1,"datetime":"1709257121","microtimestamp":"1709257120998000","amount":0.01630589,"amount_str":"0.01630589","amount_traded":"0","amount_at_create":"0.01630589","price":61328,"price_str":"61328"},"channel":"live_orders_btcusd","event":"order_deleted"}
{"data":{"id":1722049110446082,"id_str":"1722049110446082","order_type":0,"datetime":"1709257121","microtimestamp":"1709257120999000","amount":0.01630786,"amount_str":"0.01630786","amount_traded":"0","amount_at_create":"0.01630786","price":61320,"price_str":"61320"},"channel":"live_orders_btcusd","event":"order_deleted"}
{"data":{"id":1722049111609344,"id_str":"1722049111609344","order_type":1,"datetime":"1709257121","microtimestamp":"1709257121046000","amount":0.01630611,"amount_str":"0.01630611","amount_traded":"0","amount_at_create":"0.01630611","price":61327,"price_str":"61327"},"channel":"live_orders_btcusd","event":"order_created"}
{"data":{"id":1722049111613440,"id_str":"1722049111613440","order_type":0,"datetime":"1709257121","microtimestamp":"1709257121047000","amount":0.01630834,"amount_str":"0.01630834","amount_traded":"0","amount_at_create":"0.01630834","price":61318,"price_str":"61318"},"channel":"live_orders_btcusd","event":"order_created"}
{"data":{"id":1722049111613443,"id_str":"1722049111613443","order_type":0,"datetime":"1709257121","microtimestamp":"1709257121047000","amount":0.48979831,"amount_str":"0.48979831","amount_traded":"0","amount_at_create":"0.48979831","price":61249,"price_str":"61249"},"channel":"live_orders_btcusd","event":"order_created"}
{"data":{"id":1722049111191554,"id_str":"1722049111191554","order_type":1,"datetime":"1709257121","microtimestamp":"1709257121056000","amount":0.4891592,"amount_str":"0.48915920","amount_traded":"0","amount_at_create":"0.48915920","price":61330,"price_str":"61330"},"channel":"live_orders_btcusd","event":"order_deleted"}
{"data":{"id":1722049110261764,"id_str":"1722049110261764","order_type":0,"datetime":"1709257121","microtimestamp":"1709257121198000","amount":0.48925664,"amount_str":"0.48925664","amount_traded":"0","amount_at_create":"0.48925664","price":61317,"price_str":"61317"},"channel":"live_orders_btcusd","event":"order_deleted"}
{"data":{"id":1722049112281088,"id_str":"1722049112281088","order_type":0,"datetime":"1709257121","microtimestamp":"1709257121210000","amount":0.00040756,"amount_str":"0.00040756","amount_traded":"0","amount_at_create":"0.00040756","price":61304,"price_str":"61304"},"channel":"live_orders_btcusd","event":"order_created"}
{"data":{"id":1722049112408064,"id_str":"1722049112408064","order_type":1,"datetime":"1709257121","microtimestamp":"1709257121241000","amount":0.48916499,"amount_str":"0.48916499","amount_traded":"0","amount_at_create":"0.48916499","price":61329,"price_str":"61329"},"channel":"live_orders_btcusd","event":"order_created"}
{"data":{"id":1722049112416256,"id_str":"1722049112416256","order_type":0,"datetime":"1709257121","microtimestamp":"1709257121246000","amount":0.48926966,"amount_str":"0.48926966","amount_traded":"0","amount_at_create":"0.48926966","price":61315,"price_str":"61315"},"channel":"live_orders_btcusd","event":"order_created"}
{"data":{"id":1722049112281088,"id_str":"1722049112281088","order_type":0,"datetime":"1709257121","microtimestamp":"1709257121476000","amount":0.00040756,"amount_str":"0.00040756","amount_traded":"0","amount_at_create":"0.00040756","price":61304,"price_str":"61304"},"channel":"live_orders_btcusd","event":"order_deleted"}
{"data":{"id":1722049113903104,"id_str":"1722049113903104","order_type":0,"datetime":"1709257122","microtimestamp":"1709257121607000","amount":0.00040756,"amount_str":"0.00040756","amount_traded":"0","amount_at_create":"0.00040756","price":61305,"price_str":"61305"},"channel":"live_orders_btcusd","event":"order_created"}
{"data":{"id":1722049113903104,"id_str":"1722049113903104","order_type":0,"datetime":"1709257122","microtimestamp":"1709257121725000","amount":0.00040756,"amount_str":"0.00040756","amount_traded":"0","amount_at_create":"0.00040756","price":61305,"price_str":"61305"},"channel":"live_orders_btcusd","event":"order_deleted"}
{"data":{"id":1722049114861568,"id_str":"1722049114861568","order_type":0,"datetime":"1709257122","microtimestamp":"1709257121840000","amount":0.00040756,"amount_str":"0.00040756","amount_traded":"0","amount_at_create":"0.00040756","price":61304,"price_str":"61304"},"channel":"live_orders_btcusd","event":"order_created"}
{"data":{"id":1722049114861568,"id_str":"1722049114861568","order_type":0,"datetime":"1709257122","microtimestamp":"1709257121993000","amount":0.00040756,"amount_str":"0.00040756","amount_traded":"0","amount_at_create":"0.00040756","price":61304,"price_str":"61304"},"channel":"live_orders_btcusd","event":"order_deleted"}
{"data":{"id":1722049116221440,"id_str":"1722049116221440","order_type":0,"datetime":"1709257122","microtimestamp":"1709257122172000","amount":0.00040756,"amount_str":"0.00040756","amount_traded":"0","amount_at_create":"0.00040756","price":61305,"price_str":"61305"},"channel":"live_orders_btcusd","event":"order_created"}
{"data":{"id":1722049116221440,"id_str":"1722049116221440","order_type":0,"datetime":"1709257122","microtimestamp":"1709257122248000","amount":0.00040756,"amount_str":"0.00040756","amount_traded":"0","amount_at_create":"0.00040756","price":61305,"price_str":"61305"},"channel":"live_orders_btcusd","event":"order_deleted"}
{"data":{"id":1722049111609344,"id_str":"1722049111609344","order_type":1,"datetime":"1709257122","microtimestamp":"1709257122261000","amount":0.01630611,"amount_str":"0.01630611","amount_traded":"0","amount_at_create":"0.01630611","price":61327,"price_str":"61327"},"channel":"live_orders_btcusd","event":"order_deleted"}
{"data":{"id":1722049116766209,"id_str":"1722049116766209","order_type":1,"datetime":"1709257122","microtimestamp":"1709257122305000","amount":0.01630633,"amount_str":"0.01630633","amount_traded":"0","amount_at_create":"0.01630633","price":61326,"price_str":"61326"},"channel":"live_orders_btcusd","event":"order_created"}
{"data":{"id":1722049116827649,"id_str":"1722049116827649","order_type":0,"datetime":"1709257122","microtimestamp":"1709257122320000","amount":0.00040756,"amount_str":"0.00040756","amount_traded":"0","amount_at_create":"0.00040756","price":61304,"price_str":"61304"},"channel":"live_orders_btcusd","event":"order_created"}
{"data":{"id":1722049116827649,"id_str":"1722049116827649","order_type":0,"datetime":"1709257122","microtimestamp":"1709257122456000","amount":0.00040756,"amount_str":"0.00040756","amount_traded":"0","amount_at_create":"0.00040756","price":61304,"price_str":"61304"},"channel":"live_orders_btcusd","event":"order_deleted"}
{"data":{"id":1722049117736962,"id_str":"1722049117736962","order_type":0,"datetime":"1709257123","microtimestamp":"1709257122542000","amount":0.00040756,"amount_str":"0.00040756","amount_traded":"0","amount_at_create":"0.00040756","price":61305,"price_str":"61305"},"channel":"live_orders_btcusd","event":"order_created"}
{"data":{"id":1722049117736962,"id_str":"1722049117736962","order_type":0,"datetime":"1709257123","microtimestamp":"1709257122569000","amount":0.00040756,"amount_str":"0.00040756","amount_traded":"0","amount_at_create":"0.00040756","price":61305,"price_str":"61305"},"channel":"live_orders_btcusd","event":"order_deleted"}
{"data":{"id":1722049117966337,"id_str":"1722049117966337","order_type":0,"datetime":"1709257123","microtimestamp":"1709257122598000","amount":0.00040756,"amount_str":"0.00040756","amount_traded":"0","amount_at_create":"0.00040756","price":61304,"price_str":"61304"},"channel":"live_orders_btcusd","event":"order_created"}
{"data":{"id":1722049117966337,"id_str":"1722049117966337","order_type":0,"datetime":"1709257123","microtimestamp":"1709257122654000","amount":0.00040756,"amount_str":"0.00040756","amount_traded":"0","amount_at_create":"0.00040756","price":61304,"price_str":"61304"},"channel":"live_orders_btcusd","event":"order_deleted"}
{"data":{"id":1722049118703617,"id_str":"1722049118703617","order_type":0,"datetime":"1709257123","microtimestamp":"1709257122778000","amount":0.00040756,"amount_str":"0.00040756","amount_traded":"0","amount_at_create":"0.00040756","price":61305,"price_str":"61305"},"channel":"live_orders_btcusd","event":"order_created"}
{"data":{"id":1722049118703617,"id_str":"1722049118703617","order_type":0,"datetime":"1709257123","microtimestamp":"1709257122825000","amount":0.00040756,"amount_str":"0.00040756","amount_traded":"0","amount_at_create":"0.00040756","price":61305,"price_str":"61305"},"channel":"live_orders_btcusd","event":"order_deleted"}
{"data":{"id":1722049119084545,"id_str":"1722049119084545","order_type":0,"datetime":"1709257123","microtimestamp":"1709257122871000","amount":0.00040756,"amount_str":"0.00040756","amount_traded":"0","amount_at_create":"0.00040756","price":61304,"price_str":"61304"},"channel":"live_orders_btcusd","event":"order_created"}
{"data":{"id":1722049119084545,"id_str":"1722049119084545","order_type":0,"datetime":"1709257123","microtimestamp":"1709257122968000","amount":0.00040756,"amount_str":"0.00040756","amount_traded":"0","amount_at_create":"0.00040756","price":61304,"price_str":"61304"},"channel":"live_orders_btcusd","event":"order_deleted"}
{"data":{"id":1722049112408064,"id_str":"1722049112408064","order_type":1,"datetime":"1709257123","microtimestamp":"1709257122998000","amount":0.48916499,"amount_str":"0.48916499","amount_traded":"0","amount_at_create":"0.48916499","price":61329,"price_str":"61329"},"channel":"live_orders_btcusd","event":"order_deleted"}
{"data":{"id":1722049119604736,"id_str":"1722049119604736","order_type":0,"datetime":"1709257123","microtimestamp":"1709257122998000","amount":0.00040756,"amount_str":"0.00040756","amount_traded":"0","amount_at_create":"0.00040756","price":61305,"price_str":"61305"},"channel":"live_orders_btcusd","event":"order_created"}
{"data":{"id":1722049119776771,"id_str":"1722049119776771","order_type":1,"datetime":"1709257123","microtimestamp":"1709257123040000","amount":0.48917402,"amount_str":"0.48917402","amount_traded":"0","amount_at_create":"0.48917402","price":61328,"price_str":"61328"},"channel":"live_orders_btcusd","event":"order_created"}
{"data":{"id":1722049119604736,"id_str":"1722049119604736","order_type":0,"datetime":"1709257123","microtimestamp":"1709257123068000","amount":0.00040756,"amount_str":"0.00040756","amount_traded":"0","amount_at_create":"0.00040756","price":61305,"price_str":"61305"},"channel":"live_orders_btcusd","event":"order_deleted"}
{"data":{"id":1722049120432129,"id_str":"1722049120432129","order_type":0,"datetime":"1709257123","microtimestamp":"1709257123200000","amount":0.00040756,"amount_str":"0.00040756","amount_traded":"0","amount_at_create":"0.00040756","price":61304,"price_str":"61304"},"channel":"live_orders_btcusd","event":"order_created"}
{"data":{"id":1722049120432129,"id_str":"1722049120432129","order_type":0,"datetime":"1709257123","microtimestamp":"1709257123362000","amount":0.00040756,"amount_str":"0.00040756","amount_traded":"0","amount_at_create":"0.00040756","price":61304,"price_str":"61304"},"channel":"live_orders_btcusd","event":"order_deleted"}
{"data":{"id":1722049121275904,"id_str":"1722049121275904","order_type":0,"datetime":"1709257123","microtimestamp":"1709257123406000","amount":0.00040756,"amount_str":"0.00040756","amount_traded":"0","amount_at_create":"0.00040756","price":61305,"price_str":"61305"},"channel":"live_orders_btcusd","event":"order_created"}
{"data":{"id":1722049121275904,"id_str":"1722049121275904","order_type":0,"datetime":"1709257123","microtimestamp":"1709257123468000","amount":0.00040756,"amount_str":"0.00040756","amount_traded":"0","amount_at_create":"0.00040756","price":61305,"price_str":"61305"},"channel":"live_orders_btcusd","event":"order_deleted"}
{"data":{"id":1722049121804288,"id_str":"1722049121804288","order_type":0,"datetime":"1709257124","microtimestamp":"1709257123535000","amount":0.00040756,"amount_str":"0.00040756","amount_traded":"0","amount_at_create":"0.00040756","price":61304,"price_str":"61304"},"channel":"live_orders_btcusd","event":"order_created"}
{"data":{"id":1722049121804288,"id_str":"1722049121804288","order_type":0,"datetime":"1709257124","microtimestamp":"1709257123640000","amount":0.00040756,"amount_str":"0.00040756","amount_traded":"0","amount_at_create":"0.00040756","price":61304,"price_str":"61304"},"channel":"live_orders_btcusd","event":"order_deleted"}
{"data":{"id":1722049122590720,"id_str":"1722049122590720","order_type":0,"datetime":"1709257124","microtimestamp":"1709257123727000","amount":0.00040756,"amount_str":"0.00040756","amount_traded":"0","amount_at_create":"0.00040756","price":61305,"price_str":"61305"},"channel":"live_orders_btcusd","event":"order_created"}
{"data":{"id":1722049122590720,"id_str":"1722049122590720","order_type":0,"datetime":"1709257124","microtimestamp":"1709257123807000","amount":0.00040756,"amount_str":"0.00040756","amount_traded":"0","amount_at_create":"0.00040756","price":61305,"price_str":"61305"},"channel":"live_orders_btcusd","event":"order_deleted"}
{"data":{"id":1722049123233796,"id_str":"1722049123233796","order_type":0,"datetime":"1709257124","microtimestamp":"1709257123884000","amount":0.00040756,"amount_str":"0.00040756","amount_traded":"0","amount_at_create":"0.00040756","price":61304,"price_str":"61304"},"channel":"live_orders_btcusd","event":"order_created"}
{"data":{"id":1722049102311424,"id_str":"1722049102311424","order_type":1,"datetime":"1709257124","microtimestamp":"1709257123904000","amount":0.48913699,"amount_str":"0.48913699","amount_traded":"0","amount_at_create":"0.48913699","price":61333,"price_str":"61333"},"channel":"live_orders_btcusd","event":"order_deleted"}
{"data":{"id":1722049119776771,"id_str":"1722049119776771","order_type":1,"datetime":"1709257124","microtimestamp":"1709257123905000","amount":0.48917402,"amount_str":"0.48917402","amount_traded":"0","amount_at_create":"0.48917402","price":61328,"price_str":"61328"},"channel":"live_orders_btcusd","event":"order_deleted"}
{"data":{"id":1722049116766209,"id_str":"1722049116766209","order_type":1,"datetime":"1709257124","microtimestamp":"1709257123906000","amount":0.01630633,"amount_str":"0.01630633","amount_traded":"0","amount_at_create":"0.01630633","price":61326,"price_str":"61326"},"channel":"live_orders_btcusd","event":"order_deleted"}
{"data":{"id":1722049111207936,"id_str":"1722049111207936","order_type":0,"datetime":"1709257124","microtimestamp":"1709257123906000","amount":0.48929411,"amount_str":"0.48929411","amount_traded":"0","amount_at_create":"0.48929411","price":61312,"price_str":"61312"},"channel":"live_orders_btcusd","event":"order_deleted"}
{"data":{"id":1722049111613440,"id_str":"1722049111613440","order_type":0,"datetime":"1709257124","microtimestamp":"1709257123907000","amount":0.01630834,"amount_str":"0.01630834","amount_traded":"0","amount_at_create":"0.01630834","price":61318,"price_str":"61318"},"channel":"live_orders_btcusd","event":"order_deleted"}
{"data":{"id":1722049123540993,"id_str":"1722049123540993","order_type":0,"datetime":"1709257124","microtimestamp":"1709257123959000","amount":0.48931576,"amount_str":"0.48931576","amount_traded":"0","amount_at_create":"0.48931576","price":61310,"price_str":"61310"},"channel":"live_orders_btcusd","event":"order_created"}
{"data":{"id":1722049123545091,"id_str":"1722049123545091","order_type":1,"datetime":"1709257124","microtimestamp":"1709257123960000","amount":0.01630667,"amount_str":"0.01630667","amount_traded":"0","amount_at_create":"0.01630667","price":61325,"price_str":"61325"},"channel":"live_orders_btcusd","event":"order_created"}
{"data":{"id":1722049123549184,"id_str":"1722049123549184","order_type":0,"datetime":"1709257124","microtimestamp":"1709257123961000","amount":0.01630886,"amount_str":"0.01630886","amount_traded":"0","amount_at_create":"0.01630886","price":61316,"price_str":"61316"},"channel":"live_orders_btcusd","event":"order_created"}
{"data":{"id":1722049123549189,"id_str":"1722049123549189","order_type":1,"datetime":"1709257124","microtimestamp":"1709257123961000","amount":0.48918276,"amount_str":"0.48918276","amount_traded":"0","amount_at_create":"0.48918276","price":61327,"price_str":"61327"},"channel":"live_orders_btcusd","event":"order_created"}
{"data":{"id":1722049123549191,"id_str":"1722049123549191","order_type":1,"datetime":"1709257124","microtimestamp":"1709257123962000","amount":0.48915039,"amount_str":"0.48915039","amount_traded":"0","amount_at_create":"0.48915039","price":61331,"price_str":"61331"},"channel":"live_orders_btcusd","event":"order_created"}
{"data":{"id":1722049123577856,"id_str":"1722049123577856","order_type":0,"datetime":"1709257124","microtimestamp":"1709257123968000","amount":0.1875,"amount_str":"0.18750000","amount_traded":"0","amount_at_create":"0.18750000","price":61253,"price_str":"61253"},"channel":"live_orders_btcusd","event":"order_created"}
{"data":{"id":1722049123586052,"id_str":"1722049123586052","order_type":0,"datetime":"1709257124","microtimestamp":"1709257123971000","amount":0.16335329,"amount_str":"0.16335329","amount_traded":"0","amount_at_create":"0.16335329","price":61217,"price_str":"61217"},"channel":"live_orders_btcusd","event":"order_created"}
{"data":{"id":1722049112416256,"id_str":"1722049112416256","order_type":0,"datetime":"1709257124","microtimestamp":"1709257123998000","amount":0.48926966,"amount_str":"0.48926966","amount_traded":"0","amount_at_create":"0.48926966","price":61315,"price_str":"61315"},"channel":"live_orders_btcusd","event":"order_deleted"}
{"data":{"id":1722049102307333,"id_str":"1722049102307333","order_type":0,"datetime":"1709257124","microtimestamp":"1709257123998000","amount":0.48934304,"amount_str":"0.48934304","amount_traded":"0","amount_at_create":"0.48934304","price":61306,"price_str":"61306"},"channel":"live_orders_btcusd","event":"order_deleted"}
{"data":{"id":1722049123233796,"id_str":"1722049123233796","order_type":0,"datetime":"1709257124","microtimestamp":"1709257124009000","amount":0.00040756,"amount_str":"0.00040756","amount_traded":"0","amount_at_create":"0.00040756","price":61304,"price_str":"61304"},"channel":"live_orders_btcusd","event":"order_deleted"}
{"data":{"id":1722049123897347,"id_str":"1722049123897347","order_type":0,"datetime":"1709257124","microtimestamp":"1709257124047000","amount":0.48937876,"amount_str":"0.48937876","amount_traded":"0","amount_at_create":"0.48937876","price":61302,"price_str":"61302"},"channel":"live_orders_btcusd","event":"order_created"}
{"data":{"id":1722049123905538,"id_str":"1722049123905538","order_type":0,"datetime":"1709257124","microtimestamp":"1709257124048000","amount":0.48928691,"amount_str":"0.48928691","amount_traded":"0","amount_at_create":"0.48928691","price":61313,"price_str":"61313"},"channel":"live_orders_btcusd","event":"order_created"}
{"data":{"id":1722049123946501,"id_str":"1722049123946501","order_type":1,"datetime":"1709257124","microtimestamp":"1709257124059000","amount":0.1875,"amount_str":"0.18750000","amount_traded":"0","amount_at_create":"0.18750000","price":61332,"price_str":"61332"},"channel":"live_orders_btcusd","event":"order_created"}
{"data":{"id":1722049097195520,"id_str":"1722049097195520","order_type":1,"datetime":"1709257124","microtimestamp":"1709257124085000","amount":0.02261012,"amount_str":"0.02261012","amount_traded":"0","amount_at_create":"0.02261012","price":61343,"price_str":"61343"},"channel":"live_orders_btcusd","event":"order_deleted"}
{"data":{"id":1722049123549184,"id_str":"1722049123549184","order_type":0,"datetime":"1709257124","microtimestamp":"1709257124094000","amount":0.01630886,"amount_str":"0.01630886","amount_traded":"0","amount_at_create":"0.01630886","price":61316,"price_str":"61316"},"channel":"live_orders_btcusd","event":"order_deleted"}
{"data":{"id":1722049123545091,"id_str":"1722049123545091","order_type":1,"datetime":"1709257124","microtimestamp":"1709257124094000","amount":0.01630667,"amount_str":"0.01630667","amount_traded":"0","amount_at_create":"0.01630667","price":61325,"price_str":"61325"},"channel":"live_orders_btcusd","event":"order_deleted"}
{"data":{"id":1722049105399809,"id_str":"1722049105399809","order_type":1,"datetime":"1709257124","microtimestamp":"1709257124094000","amount":0.48883065,"amount_str":"0.48883065","amount_traded":"0","amount_at_create":"0.48883065","price":61371,"price_str":"61371"},"channel":"live_orders_btcusd","event":"order_deleted"}
{"data":{"id":1722049123540993,"id_str":"1722049123540993","order_type":0,"datetime":"1709257124","microtimestamp":"1709257124094000","amount":0.48931576,"amount_str":"0.48931576","amount_traded":"0","amount_at_create":"0.48931576","price":61310,"price_str":"61310"},"channel":"live_orders_btcusd","event":"order_deleted"}
{"data":{"id":1722049102323712,"id_str":"1722049102323712","order_type":1,"datetime":"1709257124","microtimestamp":"1709257124095000","amount":0.48907796,"amount_str":"0.48907796","amount_traded":"0","amount_at_create":"0.48907796","price":61340,"price_str":"61340"},"channel":"live_orders_btcusd","event":"order_deleted"}
{"data":{"id":1722049102299136,"id_str":"1722049102299136","order_type":1,"datetime":"1709257124","microtimestamp":"1709257124095000","amount":0.48861987,"amount_str":"0.48861987","amount_traded":"0","amount_at_create":"0.48861987","price":61398,"price_str":"61398"},"channel":"live_orders_btcusd","event":"order_deleted"}
{"data":{"id":1722049123549191,"id_str":"1722049123549191","order_type":1,"datetime":"1709257124","microtimestamp":"1709257124095000","amount":0.48915039,"amount_str":"0.48915039","amount_traded":"0","amount_at_create":"0.48915039","price":61331,"price_str":"61331"},"channel":"live_orders_btcusd","event":"order_deleted"}
{"data":{"id":1722049099194370,"id_str":"1722049099194370","order_type":1,"datetime":"1709257124","microtimestamp":"1709257124096000","amount":0.488961,"amount_str":"0.48896100","amount_traded":"0","amount_at_create":"0.48896100","price":61355,"price_str":"61355"},"channel":"live_orders_btcusd","event":"order_deleted"}
{"data":{"id":1722049123905538,"id_str":"1722049123905538","order_type":0,"datetime":"1709257124","microtimestamp":"1709257124098000","amount":0.48928691,"amount_str":"0.48928691","amount_traded":"0","amount_at_create":"0.48928691","price":61313,"price_str":"61313"},"channel":"live_orders_btcusd","event":"order_deleted"}
{"data":{"id":1722049105395712,"id_str":"1722049105395712","order_type":0,"datetime":"1709257124","microtimestamp":"1709257124100000","amount":0.48956434,"amount_str":"0.48956434","amount_traded":"0","amount_at_create":"0.48956434","price":61278,"price_str":"61278"},"channel":"live_orders_btcusd","event":"order_deleted"}
{"data":{"id":1722049123897347,"id_str":"1722049123897347","order_type":0,"datetime":"1709257124","microtimestamp":"1709257124101000","amount":0.48937876,"amount_str":"0.48937876","amount_traded":"0","amount_at_create":"0.48937876","price":61302,"price_str":"61302"},"channel":"live_orders_btcusd","event":"order_deleted"}
{"data":{"id":1722049107927043,"id_str":"1722049107927043","order_type":0,"datetime":"1709257124","microtimestamp":"1709257124101000","amount":0.48948392,"amount_str":"0.48948392","amount_traded":"0","amount_at_create":"0.48948392","price":61289,"price_str":"61289"},"channel":"live_orders_btcusd","event":"order_deleted"}
{"data":{"id":1722049097240577,"id_str":"1722049097240577","order_type":0,"datetime":"1709257124","microtimestamp":"1709257124117000","amount":0.00815401,"amount_str":"0.00815401","amount_traded":"0","amount_at_create":"0.00815401","price":61316,"price_str":"61316"},"channel":"live_orders_btcusd","event":"order_deleted"}
{"data":{"id":1722049097797633,"id_str":"1722049097797633","order_type":1,"datetime":"1709257124","microtimestamp":"1709257124123000","amount":0.00487307,"amount_str":"0.00487307","amount_traded":"0","amount_at_create":"0.00487307","price":61334,"price_str":"61334"},"channel":"live_orders_btcusd","event":"order_deleted"}
{"data":{"id":1722049124257796,"id_str":"1722049124257796","order_type":1,"datetime":"1709257124","microtimestamp":"1709257124135000","amount":0.02238049,"amount_str":"0.02238049","amount_traded":"0","amount_at_create":"0.02238049","price":61341,"price_str":"61341"},"channel":"live_orders_btcusd","event":"order_created"}
{"data":{"id":1722049124282371,"id_str":"1722049124282371","order_type":1,"datetime":"1709257124","microtimestamp":"1709257124141000","amount":0.00487319,"amount_str":"0.00487319","amount_traded":"0","amount_at_create":"0.00487319","price":61329,"price_str":"61329"},"channel":"live_orders_btcusd","event":"order_created"}
{"data":{"id":1722049097519104,"id_str":"1722049097519104","order_type":1,"datetime":"1709257124","microtimestamp":"1709257124144000","amount":0.12188796,"amount_str":"0.12188796","amount_traded":"0","amount_at_create":"0.12188796","price":61389,"price_str":"61389"},"channel":"live_orders_btcusd","event":"order_deleted"}
{"data":{"id":1722049124257796,"id_str":"1722049124257796","order_type":1,"datetime":"1709257124","microtimestamp":"1709257124147000","amount":0.02238049,"amount_str":"0.02238049","amount_traded":"0","amount_at_create":"0.02238049","price":61341,"price_str":"61341"},"channel":"live_orders_btcusd","event":"order_deleted"}
{"data":{"id":1722049124343815,"id_str":"1722049124343815","order_type":1,"datetime":"1709257124","microtimestamp":"1709257124156000","amount":0.48910847,"amount_str":"0.48910847","amount_traded":"0","amount_at_create":"0.48910847","price":61337,"price_str":"61337"},"channel":"live_orders_btcusd","event":"order_created"}
{"data":{"id":1722049124343817,"id_str":"1722049124343817","order_type":1,"datetime":"1709257124","microtimestamp":"1709257124156000","amount":0.0163078,"amount_str":"0.01630780","amount_traded":"0","amount_at_create":"0.01630780","price":61321,"price_str":"61321"},"channel":"live_orders_btcusd","event":"order_created"}
{"data":{"id":1722049124347905,"id_str":"1722049124347905","order_type":1,"datetime":"1709257124","microtimestamp":"1709257124156000","amount":0.48899486,"amount_str":"0.48899486","amount_traded":"0","amount_at_create":"0.48899486","price":61351,"price_str":"61351"},"channel":"live_orders_btcusd","event":"order_created"}
{"data":{"id":1722049124347906,"id_str":"1722049124347906","order_type":0,"datetime":"1709257124","microtimestamp":"1709257124157000","amount":0.48951562,"amount_str":"0.48951562","amount_traded":"0","amount_at_create":"0.48951562","price":61285,"price_str":"61285"},"channel":"live_orders_btcusd","event":"order_created"}
{"data":{"id":1722049124352000,"id_str":"1722049124352000","order_type":1,"datetime":"1709257124","microtimestamp":"1709257124157000","amount":0.48888653,"amount_str":"0.48888653","amount_traded":"0","amount_at_create":"0.48888653","price":61364,"price_str":"61364"},"channel":"live_orders_btcusd","event":"order_created"}
{"data":{"id":1722049124352001,"id_str":"1722049124352001","order_type":1,"datetime":"1709257124","microtimestamp":"1709257124157000","amount":0.48867522,"amount_str":"0.48867522","amount_traded":"0","amount_at_create":"0.48867522","price":61391,"price_str":"61391"},"channel":"live_orders_btcusd","event":"order_created"}
{"data":{"id":1722049124360195,"id_str":"1722049124360195","order_type":0,"datetime":"1709257124","microtimestamp":"1709257124159000","amount":0.00815388,"amount_str":"0.00815388","amount_traded":"0","amount_at_create":"0.00815388","price":61313,"price_str":"61313"},"channel":"live_orders_btcusd","event":"order_created"}
{"data":{"id":1722049124368385,"id_str":"1722049124368385","order_type":0,"datetime":"1709257124","microtimestamp":"1709257124162000","amount":0.48962116,"amount_str":"0.48962116","amount_traded":"0","amount_at_create":"0.48962116","price":61271,"price_str":"61271"},"channel":"live_orders_btcusd","event":"order_created"}
{"data":{"id":1722049124372480,"id_str":"1722049124372480","order_type":0,"datetime":"1709257124","microtimestamp":"1709257124162000","amount":0.01631004,"amount_str":"0.01631004","amount_traded":"0","amount_at_create":"0.01631004","price":61311,"price_str":"61311"},"channel":"live_orders_btcusd","event":"order_created"}
{"data":{"id":1722049124417536,"id_str":"1722049124417536","order_type":0,"datetime":"1709257124","microtimestamp":"1709257124173000","amount":0.00040756,"amount_str":"0.00040756","amount_traded":"0","amount_at_create":"0.00040756","price":61305,"price_str":"61305"},"channel":"live_orders_btcusd","event":"order_created"}
{"data":{"id":1722049124438016,"id_str":"1722049124438016","order_type":0,"datetime":"1709257124","microtimestamp":"1709257124178000","amount":0.00815388,"amount_str":"0.00815388","amount_traded":"0","amount_at_create":"0.00815388","price":61311,"price_str":"61311"},"channel":"live_orders_btcusd","event":"order_created"}
{"data":{"id":1722049124347905,"id_str":"1722049124347905","order_type":1,"datetime":"1709257124","microtimestamp":"1709257124179000","amount":0.48899486,"amount_str":"0.48899486","amount_traded":"0","amount_at_create":"0.48899486","price":61351,"price_str":"61351"},"channel":"live_orders_btcusd","event":"order_deleted"}
{"data":{"id":1722049124343815,"id_str":"1722049124343815","order_type":1,"datetime":"1709257124","microtimestamp":"1709257124179000","amount":0.48910847,"amount_str":"0.48910847","amount_traded":"0","amount_at_create":"0.48910847","price":61337,"price_str":"61337"},"channel":"live_orders_btcusd","event":"order_deleted"}
{"data":{"id":1722049124343817,"id_str":"1722049124343817","order_type":1,"datetime":"1709257124","microtimestamp":"1709257124180000","amount":0.0163078,"amount_str":"0.01630780","amount_traded":"0","amount_at_create":"0.01630780","price":61321,"price_str":"61321"},"channel":"live_orders_btcusd","event":"order_deleted"}
{"data":{"id":1722049123549189,"id_str":"1722049123549189","order_type":1,"datetime":"1709257124","microtimestamp":"1709257124184000","amount":0.48918276,"amount_str":"0.48918276","amount_traded":"0","amount_at_create":"0.48918276","price":61327,"price_str":"61327"},"channel":"live_orders_btcusd","event":"order_deleted"}
{"data":{"id":1722049101131776,"id_str":"1722049101131776","order_type":1,"datetime":"1709257124","microtimestamp":"1709257124186000","amount":0.00487295,"amount_str":"0.00487295","amount_traded":"0","amount_at_create":"0.00487295","price":61332,"price_str":"61332"},"channel":"live_orders_btcusd","event":"order_deleted"}
{"data":{"id":1722049123586052,"id_str":"1722049123586052","order_type":0,"datetime":"1709257124","microtimestamp":"1709257124190000","amount":0.16335329,"amount_str":"0.16335329","amount_traded":"0","amount_at_create":"0.16335329","price":61217,"price_str":"61217"},"channel":"live_orders_btcusd","event":"order_deleted"}
{"data":{"id":1722049124372480,"id_str":"1722049124372480","order_type":0,"datetime":"1709257124","microtimestamp":"1709257124191000","amount":0.01631004,"amount_str":"0.01631004","amount_traded":"0","amount_at_create":"0.01631004","price":61311,"price_str":"61311"},"channel":"live_orders_btcusd","event":"order_deleted"}
{"data":{"id":1722049111613443,"id_str":"1722049111613443","order_type":0,"datetime":"1709257124","microtimestamp":"1709257124191000","amount":0.48979831,"amount_str":"0.48979831","amount_traded":"0","amount_at_create":"0.48979831","price":61249,"price_str":"61249"},"channel":"live_orders_btcusd","event":"order_deleted"}
{"data":{"id":1722049097691139,"id_str":"1722049097691139","order_type":1,"datetime":"1709257124","microtimestamp":"1709257124192000","amount":0.09746155,"amount_str":"0.09746155","amount_traded":"0","amount_at_create":"0.09746155","price":61352,"price_str":"61352"},"channel":"live_orders_btcusd","event":"order_deleted"}
{"data":{"id":1722049124540416,"id_str":"1722049124540416","order_type":1,"datetime":"1709257124","microtimestamp":"1709257124203000","amount":0.12188796,"amount_str":"0.12188796","amount_traded":"0","amount_at_create":"0.12188796","price":61379,"price_str":"61379"},"channel":"live_orders_btcusd","event":"order_created"}
{"data":{"id":1722049124577282,"id_str":"1722049124577282","order_type":1,"datetime":"1709257124","microtimestamp":"1709257124212000","amount":0.00487319,"amount_str":"0.00487319","amount_traded":"0","amount_at_create":"0.00487319","price":61327,"price_str":"61327"},"channel":"live_orders_btcusd","event":"order_created"}
{"data":{"id":1722049124655107,"id_str":"1722049124655107","order_type":1,"datetime":"1709257124","microtimestamp":"1709257124231000","amount":0.09746394,"amount_str":"0.09746394","amount_traded":"0","amount_at_create":"0.09746394","price":61346,"price_str":"61346"},"channel":"live_orders_btcusd","event":"order_created"}
{"data":{"id":1722049099894784,"id_str":"1722049099894784","order_type":0,"datetime":"1709257124","microtimestamp":"1709257124233000","amount":0.04875518,"amount_str":"0.04875518","amount_traded":"0","amount_at_create":"0.04875518","price":61290,"price_str":"61290"},"channel":"live_orders_btcusd","event":"order_deleted"}
{"data":{"id":1722049124667394,"id_str":"1722049124667394","order_type":1,"datetime":"1709257124","microtimestamp":"1709257124234000","amount":0.48921669,"amount_str":"0.48921669","amount_traded":"0","amount_at_create":"0.48921669","price":61323,"price_str":"61323"},"channel":"live_orders_btcusd","event":"order_created"}
{"data":{"id":1722049124360195,"id_str":"1722049124360195","order_type":0,"datetime":"1709257124","microtimestamp":"1709257124238000","amount":0.00815388,"amount_str":"0.00815388","amount_traded":"0","amount_at_create":"0.00815388","price":61313,"price_str":"61313"},"channel":"live_orders_btcusd","event":"order_deleted"}
{"data":{"id":1722049096671233,"id_str":"1722049096671233","order_type":1,"datetime":"1709257124","microtimestamp":"1709257124243000","amount":0.03390203,"amount_str":"0.03390203","amount_traded":"0","amount_at_create":"0.03390203","price":61340,"price_str":"61340"},"channel":"live_orders_btcusd","event":"order_deleted"}
{"data":{"id":1722049124667394,"id_str":"1722049124667394","order_type":1,"datetime":"1709257124","microtimestamp":"1709257124249000","amount":0.48921669,"amount_str":"0.48921669","amount_traded":"0","amount_at_create":"0.48921669","price":61323,"price_str":"61323"},"channel":"live_orders_btcusd","event":"order_deleted"}
{"data":{"id":1722049124765699,"id_str":"1722049124765699","order_type":1,"datetime":"1709257124","microtimestamp":"1709257124259000","amount":0.03390203,"amount_str":"0.03390203","amount_traded":"0","amount_at_create":"0.03390203","price":61337,"price_str":"61337"},"channel":"live_orders_btcusd","event":"order_created"}
{"data":{"id":1722049123946501,"id_str":"1722049123946501","order_type":1,"datetime":"1709257124","microtimestamp":"1709257124261000","amount":0.1875,"amount_str":"0.18750000","amount_traded":"0","amount_at_create":"0.18750000","price":61332,"price_str":"61332"},"channel":"live_orders_btcusd","event":"order_deleted"}
{"data":{"id":1722049124823042,"id_str":"1722049124823042","order_type":1,"datetime":"1709257124","microtimestamp":"1709257124272000","amount":0.02345038,"amount_str":"0.02345038","amount_traded":"0","amount_at_create":"0.02345038","price":61338,"price_str":"61338"},"channel":"live_orders_btcusd","event":"order_created"}
{"data":{"id":1722049124417536,"id_str":"1722049124417536","order_type":0,"datetime":"1709257124","microtimestamp":"1709257124276000","amount":0.00040756,"amount_str":"0.00040756","amount_traded":"0","amount_at_create":"0.00040756","price":61305,"price_str":"61305"},"channel":"live_orders_btcusd","event":"order_deleted"}
{"data":{"id":1722049124904960,"id_str":"1722049124904960","order_type":1,"datetime":"1709257124","microtimestamp":"1709257124292000","amount":0.01630809,"amount_str":"0.01630809","amount_traded":"0","amount_at_create":"0.01630809","price":61320,"price_str":"61320"},"channel":"live_orders_btcusd","event":"order_created"}
{"data":{"id":1722049124917248,"id_str":"1722049124917248","order_type":0,"datetime":"1709257124","microtimestamp":"1709257124295000","amount":0.48933072,"amount_str":"0.48933072","amount_traded":"0","amount_at_create":"0.48933072","price":61308,"price_str":"61308"},"channel":"live_orders_btcusd","event":"order_created"}
{"data":{"id":1722049124917250,"id_str":"1722049124917250","order_type":0,"datetime":"1709257124","microtimestamp":"1709257124296000","amount":0.01631033,"amount_str":"0.01631033","amount_traded":"0","amount_at_create":"0.01631033","price":61310,"price_str":"61310"},"channel":"live_orders_btcusd","event":"order_created"}
{"data":{"id":1722049097351168,"id_str":"1722049097351168","order_type":0,"datetime":"1709257124","microtimestamp":"1709257124300000","amount":0.16308025,"amount_str":"0.16308025","amount_traded":"0","amount_at_create":"0.16308025","price":61297,"price_str":"61297"},"channel":"live_orders_btcusd","event":"order_deleted"}
{"data":{"id":1722049125064705,"id_str":"1722049125064705","order_type":0,"datetime":"1709257124","microtimestamp":"1709257124332000","amount":0.16308158,"amount_str":"0.16308158","amount_traded":"0","amount_at_create":"0.16308158","price":61292,"price_str":"61292"},"channel":"live_orders_btcusd","event":"order_created"}
{"data":{"id":1722049124917250,"id_str":"1722049124917250","order_type":0,"datetime":"1709257124","microtimestamp":"1709257124415000","amount":0.01631033,"amount_str":"0.01631033","amount_traded":"0","amount_at_create":"0.01631033","price":61310,"price_str":"61310"},"channel":"live_orders_btcusd","event":"order_deleted"}
{"data":{"id":1722049124904960,"id_str":"1722049124904960","order_type":1,"datetime":"1709257124","microtimestamp":"1709257124416000","amount":0.01630809,"amount_str":"0.01630809","amount_traded":"0","amount_at_create":"0.01630809","price":61320,"price_str":"61320"},"channel":"live_orders_btcusd","event":"order_deleted"}
{"data":{"id":1722049124917248,"id_str":"1722049124917248","order_type":0,"datetime":"1709257124","microtimestamp":"1709257124417000","amount":0.48933072,"amount_str":"0.48933072","amount_traded":"0","amount_at_create":"0.48933072","price":61308,"price_str":"61308"},"channel":"live_orders_btcusd","event":"order_deleted"}
{"data":{"id":1722049125613570,"id_str":"1722049125613570","order_type":0,"datetime":"1709257124","microtimestamp":"1709257124466000","amount":0.48935626,"amount_str":"0.48935626","amount_traded":"0","amount_at_create":"0.48935626","price":61305,"price_str":"61305"},"channel":"live_orders_btcusd","event":"order_created"}
{"data":{"id":1722049125621760,"id_str":"1722049125621760","order_type":1,"datetime":"1709257124","microtimestamp":"1709257124467000","amount":0.48919605,"amount_str":"0.48919605","amount_traded":"0","amount_at_create":"0.48919605","price":61326,"price_str":"61326"},"channel":"live_orders_btcusd","event":"order_created"}
{"data":{"id":1722049125621761,"id_str":"1722049125621761","order_type":1,"datetime":"1709257124","microtimestamp":"1709257124467000","amount":0.01630759,"amount_str":"0.01630759","amount_traded":"0","amount_at_create":"0.01630759","price":61322,"price_str":"61322"},"channel":"live_orders_btcusd","event":"order_created"}
{"data":{"id":1722049125629954,"id_str":"1722049125629954","order_type":0,"datetime":"1709257124","microtimestamp":"1709257124469000","amount":0.01630984,"amount_str":"0.01630984","amount_traded":"0","amount_at_create":"0.01630984","price":61312,"price_str":"61312"},"channel":"live_orders_btcusd","event":"order_created"}
{"data":{"id":1722049125634051,"id_str":"1722049125634051","order_type":1,"datetime":"1709257124","microtimestamp":"1709257124470000","amount":0.48921046,"amount_str":"0.48921046","amount_traded":"0","amount_at_create":"0.48921046","price":61324,"price_str":"61324"},"channel":"live_orders_btcusd","event":"order_created"}
{"data":{"id":1722049125629954,"id_str":"1722049125629954","order_type":0,"datetime":"1709257124","microtimestamp":"1709257124497000","amount":0.01630984,"amount_str":"0.01630984","amount_traded":"0","amount_at_create":"0.01630984","price":61312,"price_str":"61312"},"channel":"live_orders_btcusd","event":"order_deleted"}
{"data":{"id":1722049125613570,"id_str":"1722049125613570","order_type":0,"datetime":"1709257124","microtimestamp":"1709257124498000","amount":0.48935626,"amount_str":"0.48935626","amount_traded":"0","amount_at_create":"0.48935626","price":61305,"price_str":"61305"},"channel":"live_orders_btcusd","event":"order_deleted"}
{"data":{"id":1722049125634051,"id_str":"1722049125634051","order_type":1,"datetime":"1709257124","microtimestamp":"1709257124499000","amount":0.48921046,"amount_str":"0.48921046","amount_traded":"0","amount_at_create":"0.48921046","price":61324,"price_str":"61324"},"channel":"live_orders_btcusd","event":"order_deleted"}
{"data":{"id":1722049125621760,"id_str":"1722049125621760","order_type":1,"datetime":"1709257125","microtimestamp":"1709257124507000","amount":0.48919605,"amount_str":"0.48919605","amount_traded":"0","amount_at_create":"0.48919605","price":61326,"price_str":"61326"},"channel":"live_orders_btcusd","event":"order_deleted"}
{"data":{"id":1722049125818368,"id_str":"1722049125818368","order_type":0,"datetime":"1709257125","microtimestamp":"1709257124515000","amount":0.48931268,"amount_str":"0.48931268","amount_traded":"0","amount_at_create":"0.48931268","price":61310,"price_str":"61310"},"channel":"live_orders_btcusd","event":"order_created"}
{"data":{"id":1722049125818368,"id_str":"1722049125818368","order_type":0,"datetime":"1709257125","microtimestamp":"1709257124529000","amount":0.48931268,"amount_str":"0.48931268","amount_traded":"0","amount_at_create":"0.48931268","price":61310,"price_str":"61310"},"channel":"live_orders_btcusd","event":"order_deleted"}
{"data":{"id":1722049126043648,"id_str":"1722049126043648","order_type":0,"datetime":"1709257125","microtimestamp":"1709257124570000","amount":0.01630964,"amount_str":"0.01630964","amount_traded":"0","amount_at_create":"0.01630964","price":61313,"price_str":"61313"},"channel":"live_orders_btcusd","event":"order_created"}
{"data":{"id":1722049126182912,"id_str":"1722049126182912","order_type":0,"datetime":"1709257125","microtimestamp":"1709257124604000","amount":0.00040756,"amount_str":"0.00040756","amount_traded":"0","amount_at_create":"0.00040756","price":61304,"price_str":"61304"},"channel":"live_orders_btcusd","event":"order_created"}
{"data":{"id":1722049126445056,"id_str":"1722049126445056","order_type":1,"datetime":"1709257125","microtimestamp":"1709257124668000","amount":0.48920678,"amount_str":"0.48920678","amount_traded":"0","amount_at_create":"0.48920678","price":61324,"price_str":"61324"},"channel":"live_orders_btcusd","event":"order_created"}
{"data":{"id":1722049126727681,"id_str":"1722049126727681","order_type":0,"datetime":"1709257125","microtimestamp":"1709257124738000","amount":0.48930681,"amount_str":"0.48930681","amount_traded":"0","amount_at_create":"0.48930681","price":61311,"price_str":"61311"},"channel":"live_orders_btcusd","event":"order_created"}
{"data":{"id":1722049086029826,"id_str":"1722049086029826","order_type":1,"datetime":"1709257125","microtimestamp":"1709257124746000","amount":0.00033,"amount_str":"0.00033000","amount_traded":"0","amount_at_create":"0.00033000","price":61395,"price_str":"61395"},"channel":"live_orders_btcusd","event":"order_deleted"}
{"data":{"id":1722049125621761,"id_str":"1722049125621761","order_type":1,"datetime":"1709257125","microtimestamp":"1709257124797000","amount":0.01630759,"amount_str":"0.01630759","amount_traded":"0","amount_at_create":"0.01630759","price":61322,"price_str":"61322"},"channel":"live_orders_btcusd","event":"order_deleted"}
{"data":{"id":1722049127038976,"id_str":"1722049127038976","order_type":1,"datetime":"1709257125","microtimestamp":"1709257124813000","amount":0.00033,"amount_str":"0.00033000","amount_traded":"0","amount_at_create":"0.00033000","price":61386,"price_str":"61386"},"channel":"live_orders_btcusd","event":"order_created"}
{"data":{"id":1722049127161857,"id_str":"1722049127161857","order_type":1,"datetime":"1709257125","microtimestamp":"1709257124844000","amount":0.01630762,"amount_str":"0.01630762","amount_traded":"0","amount_at_create":"0.01630762","price":61321,"price_str":"61321"},"channel":"live_orders_btcusd","event":"order_created"}
{"data":{"id":1722049126445056,"id_str":"1722049126445056","order_type":1,"datetime":"1709257125","microtimestamp":"1709257124896000","amount":0.48920678,"amount_str":"0.48920678","amount_traded":"0","amount_at_create":"0.48920678","price":61324,"price_str":"61324"},"channel":"live_orders_btcusd","event":"order_deleted"}
{"data":{"id":1722049127559168,"id_str":"1722049127559168","order_type":1,"datetime":"1709257125","microtimestamp":"1709257124940000","amount":0.48921285,"amount_str":"0.48921285","amount_traded":"0","amount_at_create":"0.48921285","price":61323,"price_str":"61323"},"channel":"live_orders_btcusd","event":"order_created"}
{"data":{"id":1722049127723011,"id_str":"1722049127723011","order_type":0,"datetime":"1709257125","microtimestamp":"1709257124981000","amount":0.04875518,"amount_str":"0.04875518","amount_traded":"0","amount_at_create":"0.04875518","price":61286,"price_str":"61286"},"channel":"live_orders_btcusd","event":"order_created"}
{"data":{"id":1722049127739392,"id_str":"1722049127739392","order_type":1,"datetime":"1709257125","microtimestamp":"1709257124984000","amount":0.4891811,"amount_str":"0.48918110","amount_traded":"0","amount_at_create":"0.48918110","price":61327,"price_str":"61327"},"channel":"live_orders_btcusd","event":"order_created"}
{"data":{"id":1722049127751682,"id_str":"1722049127751682","order_type":0,"datetime":"1709257125","microtimestamp":"1709257124987000","amount":0.48933914,"amount_str":"0.48933914","amount_traded":"0","amount_at_create":"0.48933914","price":61307,"price_str":"61307"},"channel":"live_orders_btcusd","event":"order_created"}
{"data":{"id":1722049126182912,"id_str":"1722049126182912","order_type":0,"datetime":"1709257125","microtimestamp":"1709257125044000","amount":0.00040756,"amount_str":"0.00040756","amount_traded":"0","amount_at_create":"0.00040756","price":61304,"price_str":"61304"},"channel":"live_orders_btcusd","event":"order_deleted"}
{"data":{"id":1722049128800256,"id_str":"1722049128800256","order_type":0,"datetime":"1709257125","microtimestamp":"1709257125243000","amount":0.00040756,"amount_str":"0.00040756","amount_traded":"0","amount_at_create":"0.00040756","price":61305,"price_str":"61305"},"channel":"live_orders_btcusd","event":"order_created"}
{"data":{"id":1722049128800256,"id_str":"1722049128800256","order_type":0,"datetime":"1709257125","microtimestamp":"1709257125435000","amount":0.00040756,"amount_str":"0.00040756","amount_traded":"0","amount_at_create":"0.00040756","price":61305,"price_str":"61305"},"channel":"live_orders_btcusd","event":"order_deleted"}
{"data":{"id":1722049130176513,"id_str":"1722049130176513","order_type":0,"datetime":"1709257126","microtimestamp":"1709257125580000","amount":0.00040756,"amount_str":"0.00040756","amount_traded":"0","amount_at_create":"0.00040756","price":61304,"price_str":"61304"},"channel":"live_orders_btcusd","event":"order_created"}
{"data":{"id":1722049127161857,"id_str":"1722049127161857","order_type":1,"datetime":"1709257126","microtimestamp":"1709257125720000","amount":0.01630762,"amount_str":"0.01630762","amount_traded":"0","amount_at_create":"0.01630762","price":61321,"price_str":"61321"},"channel":"live_orders_btcusd","event":"order_deleted"}
{"data":{"id":1722049127559168,"id_str":"1722049127559168","order_type":1,"datetime":"1709257126","microtimestamp":"1709257125721000","amount":0.48921285,"amount_str":"0.48921285","amount_traded":"0","amount_at_create":"0.48921285","price":61323,"price_str":"61323"},"channel":"live_orders_btcusd","event":"order_deleted"}
{"data":{"id":1722049126727681,"id_str":"1722049126727681","order_type":0,"datetime":"1709257126","microtimestamp":"1709257125721000","amount":0.48930681,"amount_str":"0.48930681","amount_traded":"0","amount_at_create":"0.48930681","price":61311,"price_str":"61311"},"channel":"live_orders_btcusd","event":"order_deleted"}
{"data":{"id":1722049126043648,"id_str":"1722049126043648","order_type":0,"datetime":"1709257126","microtimestamp":"1709257125721000","amount":0.01630964,"amount_str":"0.01630964","amount_traded":"0","amount_at_create":"0.01630964","price":61313,"price_str":"61313"},"channel":"live_orders_btcusd","event":"order_deleted"}
{"data":{"id":1722049130176513,"id_str":"1722049130176513","order_type":0,"datetime":"1709257126","microtimestamp":"1709257125738000","amount":0.00040756,"amount_str":"0.00040756","amount_traded":"0","amount_at_create":"0.00040756","price":61304,"price_str":"61304"},"channel":"live_orders_btcusd","event":"order_deleted"}
{"data":{"id":1722049130950657,"id_str":"1722049130950657","order_type":1,"datetime":"1709257126","microtimestamp":"1709257125768000","amount":0.48912948,"amount_str":"0.48912948","amount_traded":"0","amount_at_create":"0.48912948","price":61334,"price_str":"61334"},"channel":"live_orders_btcusd","event":"order_created"}
{"data":{"id":1722049130950658,"id_str":"1722049130950658","order_type":1,"datetime":"1709257126","microtimestamp":"1709257125769000","amount":0.01630726,"amount_str":"0.01630726","amount_traded":"0","amount_at_create":"0.01630726","price":61323,"price_str":"61323"},"channel":"live_orders_btcusd","event":"order_created"}
{"data":{"id":1722049130950659,"id_str":"1722049130950659","order_type":1,"datetime":"1709257126","microtimestamp":"1709257125769000","amount":0.48920057,"amount_str":"0.48920057","amount_traded":"0","amount_at_create":"0.48920057","price":61325,"price_str":"61325"},"channel":"live_orders_btcusd","event":"order_created"}
{"data":{"id":1722049130954752,"id_str":"1722049130954752","order_type":0,"datetime":"1709257126","microtimestamp":"1709257125769000","amount":0.48929952,"amount_str":"0.48929952","amount_traded":"0","amount_at_create":"0.48929952","price":61312,"price_str":"61312"},"channel":"live_orders_btcusd","event":"order_created"}
{"data":{"id":1722049130954753,"id_str":"1722049130954753","order_type":0,"datetime":"1709257126","microtimestamp":"1709257125769000","amount":0.0163094,"amount_str":"0.01630940","amount_traded":"0","amount_at_create":"0.01630940","price":61314,"price_str":"61314"},"channel":"live_orders_btcusd","event":"order_created"}
{"data":{"id":1722049130954754,"id_str":"1722049130954754","order_type":0,"datetime":"1709257126","microtimestamp":"1709257125769000","amount":0.48940989,"amount_str":"0.48940989","amount_traded":"0","amount_at_create":"0.48940989","price":61298,"price_str":"61298"},"channel":"live_orders_btcusd","event":"order_created"}
{"data":{"id":1722049130950659,"id_str":"1722049130950659","order_type":1,"datetime":"1709257126","microtimestamp":"1709257125797000","amount":0.48920057,"amount_str":"0.48920057","amount_traded":"0","amount_at_create":"0.48920057","price":61325,"price_str":"61325"},"channel":"live_orders_btcusd","event":"order_deleted"}
{"data":{"id":1722049130950658,"id_str":"1722049130950658","order_type":1,"datetime":"1709257126","microtimestamp":"1709257125798000","amount":0.01630726,"amount_str":"0.01630726","amount_traded":"0","amount_at_create":"0.01630726","price":61323,"price_str":"61323"},"channel":"live_orders_btcusd","event":"order_deleted"}
{"data":{"id":1722049124577282,"id_str":"1722049124577282","order_type":1,"datetime":"1709257126","microtimestamp":"1709257125835000","amount":0.00487319,"amount_str":"0.00487319","amount_traded":"0","amount_at_create":"0.00487319","price":61327,"price_str":"61327"},"channel":"live_orders_btcusd","event":"order_deleted"}
{"data":{"id":1722049131360257,"id_str":"1722049131360257","order_type":1,"datetime":"1709257126","microtimestamp":"1709257125869000","amount":0.01630754,"amount_str":"0.01630754","amount_traded":"0","amount_at_create":"0.01630754","price":61322,"price_str":"61322"},"channel":"live_orders_btcusd","event":"order_created"}
{"data":{"id":1722049131364353,"id_str":"1722049131364353","order_type":0,"datetime":"1709257126","microtimestamp":"1709257125869000","amount":0.00815414,"amount_str":"0.00815414","amount_traded":"0","amount_at_create":"0.00815414","price":61313,"price_str":"61313"},"channel":"live_orders_btcusd","event":"order_created"}
{"data":{"id":1722049131470848,"id_str":"1722049131470848","order_type":0,"datetime":"1709257126","microtimestamp":"1709257125895000","amount":0.00040756,"amount_str":"0.00040756","amount_traded":"0","amount_at_create":"0.00040756","price":61305,"price_str":"61305"},"channel":"live_orders_btcusd","event":"order_created"}
{"data":{"id":1722049124765699,"id_str":"1722049124765699","order_type":1,"datetime":"1709257126","microtimestamp":"1709257125902000","amount":0.03390203,"amount_str":"0.03390203","amount_traded":"0","amount_at_create":"0.03390203","price":61337,"price_str":"61337"},"channel":"live_orders_btcusd","event":"order_deleted"}
{"data":{"id":1722049131556864,"id_str":"1722049131556864","order_type":1,"datetime":"1709257126","microtimestamp":"1709257125916000","amount":0.03390203,"amount_str":"0.03390203","amount_traded":"0","amount_at_create":"0.03390203","price":61334,"price_str":"61334"},"channel":"live_orders_btcusd","event":"order_created"}
{"data":{"id":1722049130954752,"id_str":"1722049130954752","order_type":0,"datetime":"1709257126","microtimestamp":"1709257125996000","amount":0.48929952,"amount_str":"0.48929952","amount_traded":"0","amount_at_create":"0.48929952","price":61312,"price_str":"61312"},"channel":"live_orders_btcusd","event":"order_deleted"}
{"data":{"id":1722049131470848,"id_str":"1722049131470848","order_type":0,"datetime":"1709257126","microtimestamp":"1709257126009000","amount":0.00040756,"amount_str":"0.00040756","amount_traded":"0","amount_at_create":"0.00040756","price":61305,"price_str":"61305"},"channel":"live_orders_btcusd","event":"order_deleted"}
{"data":{"id":1722049132064770,"id_str":"1722049132064770","order_type":1,"datetime":"1709257126","microtimestamp":"1709257126040000","amount":0.48920941,"amount_str":"0.48920941","amount_traded":"0","amount_at_create":"0.48920941","price":61324,"price_str":"61324"},"channel":"live_orders_btcusd","event":"order_created"}
{"data":{"id":1722049132068864,"id_str":"1722049132068864","order_type":0,"datetime":"1709257126","microtimestamp":"1709257126041000","amount":0.4893096,"amount_str":"0.48930960","amount_traded":"0","amount_at_create":"0.48930960","price":61310,"price_str":"61310"},"channel":"live_orders_btcusd","event":"order_created"}
{"data":{"id":1722049096372225,"id_str":"1722049096372225","order_type":0,"datetime":"1709257126","microtimestamp":"1709257126074000","amount":0.06520848,"amount_str":"0.06520848","amount_traded":"0","amount_at_create":"0.06520848","price":61298,"price_str":"61298"},"channel":"live_orders_btcusd","event":"order_deleted"}
{"data":{"id":1722049132277760,"id_str":"1722049132277760","order_type":0,"datetime":"1709257126","microtimestamp":"1709257126093000","amount":0.48986097,"amount_str":"0.48986097","amount_traded":"0","amount_at_create":"0.48986097","price":61241,"price_str":"61241"},"channel":"live_orders_btcusd","event":"order_created"}
{"data":{"id":1722049130954753,"id_str":"1722049130954753","order_type":0,"datetime":"1709257126","microtimestamp":"1709257126098000","amount":0.0163094,"amount_str":"0.01630940","amount_traded":"0","amount_at_create":"0.01630940","price":61314,"price_str":"61314"},"channel":"live_orders_btcusd","event":"order_deleted"}
{"data":{"id":1722049131360257,"id_str":"1722049131360257","order_type":1,"datetime":"1709257126","microtimestamp":"1709257126100000","amount":0.01630754,"amount_str":"0.01630754","amount_traded":"0","amount_at_create":"0.01630754","price":61322,"price_str":"61322"},"channel":"live_orders_btcusd","event":"order_deleted"}
{"data":{"id":1722049132347392,"id_str":"1722049132347392","order_type":0,"datetime":"1709257126","microtimestamp":"1709257126109000","amount":0.00040756,"amount_str":"0.00040756","amount_traded":"0","amount_at_create":"0.00040756","price":61304,"price_str":"61304"},"channel":"live_orders_btcusd","event":"order_created"}
{"data":{"id":1722049132482562,"id_str":"1722049132482562","order_type":1,"datetime":"1709257126","microtimestamp":"1709257126143000","amount":0.01630767,"amount_str":"0.01630767","amount_traded":"0","amount_at_create":"0.01630767","price":61321,"price_str":"61321"},"channel":"live_orders_btcusd","event":"order_created"}
{"data":{"id":1722049132498945,"id_str":"1722049132498945","order_type":0,"datetime":"1709257126","microtimestamp":"1709257126146000","amount":0.0163098,"amount_str":"0.01630980","amount_traded":"0","amount_at_create":"0.01630980","price":61312,"price_str":"61312"},"channel":"live_orders_btcusd","event":"order_created"}
{"data":{"id":1722048956411904,"id_str":"1722048956411904","order_type":0,"datetime":"1709257126","microtimestamp":"1709257126174000","amount":0.5,"amount_str":"0.50000000","amount_traded":"0","amount_at_create":"0.50000000","price":61287,"price_str":"61287"},"channel":"live_orders_btcusd","event":"order_deleted"}
{"data":{"id":1722049132679172,"id_str":"1722049132679172","order_type":1,"datetime":"1709257126","microtimestamp":"1709257126190000","amount":0.48902189,"amount_str":"0.48902189","amount_traded":"0","amount_at_create":"0.48902189","price":61347,"price_str":"61347"},"channel":"live_orders_btcusd","event":"order_created"}
{"data":{"id":1722049132068864,"id_str":"1722049132068864","order_type":0,"datetime":"1709257126","microtimestamp":"1709257126202000","amount":0.4893096,"amount_str":"0.48930960","amount_traded":"0","amount_at_create":"0.48930960","price":61310,"price_str":"61310"},"channel":"live_orders_btcusd","event":"order_deleted"}
{"data":{"id":1722049132482562,"id_str":"1722049132482562","order_type":1,"datetime":"1709257126","microtimestamp":"1709257126202000","amount":0.01630767,"amount_str":"0.01630767","amount_traded":"0","amount_at_create":"0.01630767","price":61321,"price_str":"61321"},"channel":"live_orders_btcusd","event":"order_deleted"}
{"data":{"id":1722049127739392,"id_str":"1722049127739392","order_type":1,"datetime":"1709257126","microtimestamp":"1709257126203000","amount":0.4891811,"amount_str":"0.48918110","amount_traded":"0","amount_at_create":"0.48918110","price":61327,"price_str":"61327"},"channel":"live_orders_btcusd","event":"order_deleted"}
{"data":{"id":1722049127751682,"id_str":"1722049127751682","order_type":0,"datetime":"1709257126","microtimestamp":"1709257126204000","amount":0.48933914,"amount_str":"0.48933914","amount_traded":"0","amount_at_create":"0.48933914","price":61307,"price_str":"61307"},"channel":"live_orders_btcusd","event":"order_deleted"}
{"data":{"id":1722049090977795,"id_str":"1722049090977795","order_type":0,"datetime":"1709257126","microtimestamp":"1709257126215000","amount":3.06851126,"amount_str":"3.06851126","amount_traded":"0","amount_at_create":"3.06851126","price":61303,"price_str":"61303"},"channel":"live_orders_btcusd","event":"order_deleted"}
{"data":{"id":1722049132498945,"id_str":"1722049132498945","order_type":0,"datetime":"1709257126","microtimestamp":"1709257126228000","amount":0.0163098,"amount_str":"0.01630980","amount_traded":"0","amount_at_create":"0.01630980","price":61312,"price_str":"61312"},"channel":"live_orders_btcusd","event":"order_deleted"}
{"data":{"id":1722048766943237,"id_str":"1722048766943237","order_type":0,"datetime":"1709257126","microtimestamp":"1709257126241000","amount":0.1875,"amount_str":"0.18750000","amount_traded":"0","amount_at_create":"0.18750000","price":61302,"price_str":"61302"},"channel":"live_orders_btcusd","event":"order_deleted"}
{"data":{"id":1722049132933123,"id_str":"1722049132933123","order_type":0,"datetime":"1709257126","microtimestamp":"1709257126252000","amount":0.48932575,"amount_str":"0.48932575","amount_traded":"0","amount_at_create":"0.48932575","price":61308,"price_str":"61308"},"channel":"live_orders_btcusd","event":"order_created"}
{"data":{"id":1722049132933127,"id_str":"1722049132933127","order_type":1,"datetime":"1709257126","microtimestamp":"1709257126252000","amount":0.01630814,"amount_str":"0.01630814","amount_traded":"0","amount_at_create":"0.01630814","price":61320,"price_str":"61320"},"channel":"live_orders_btcusd","event":"order_created"}
{"data":{"id":1722049132933128,"id_str":"1722049132933128","order_type":0,"datetime":"1709257126","microtimestamp":"1709257126253000","amount":0.48935801,"amount_str":"0.48935801","amount_traded":"0","amount_at_create":"0.48935801","price":61304,"price_str":"61304"},"channel":"live_orders_btcusd","event":"order_created"}
{"data":{"id":1722049132937217,"id_str":"1722049132937217","order_type":1,"datetime":"1709257126","microtimestamp":"1709257126253000","amount":0.48922702,"amount_str":"0.48922702","amount_traded":"0","amount_at_create":"0.48922702","price":61322,"price_str":"61322"},"channel":"live_orders_btcusd","event":"order_created"}
{"data":{"id":1722049132978177,"id_str":"1722049132978177","order_type":0,"datetime":"1709257126","microtimestamp":"1709257126263000","amount":3.06856132,"amount_str":"3.06856132","amount_traded":"0","amount_at_create":"3.06856132","price":61302,"price_str":"61302"},"channel":"live_orders_btcusd","event":"order_created"}
{"data":{"id":1722049132986369,"id_str":"1722049132986369","order_type":1,"datetime":"1709257126","microtimestamp":"1709257126265000","amount":0.1875,"amount_str":"0.18750000","amount_traded":"0","amount_at_create":"0.18750000","price":61328,"price_str":"61328"},"channel":"live_orders_btcusd","event":"order_created"}
{"data":{"id":1722049132933127,"id_str":"1722049132933127","order_type":1,"datetime":"1709257126","microtimestamp":"1709257126272000","amount":0.01630814,"amount_str":"0.01630814","amount_traded":"0","amount_at_create":"0.01630814","price":61320,"price_str":"61320"},"channel":"live_orders_btcusd","event":"order_deleted"}
{"data":{"id":1722048981594113,"id_str":"1722048981594113","order_type":1,"datetime":"1709257126","microtimestamp":"1709257126278000","amount":0.5,"amount_str":"0.50000000","amount_traded":"0","amount_at_create":"0.50000000","price":61367,"price_str":"61367"},"channel":"live_orders_btcusd","event":"order_deleted"}
{"data":{"id":1722049131364353,"id_str":"1722049131364353","order_type":0,"datetime":"1709257126","microtimestamp":"1709257126291000","amount":0.00815414,"amount_str":"0.00815414","amount_traded":"0","amount_at_create":"0.00815414","price":61313,"price_str":"61313"},"channel":"live_orders_btcusd","event":"order_deleted"}
{"data":{"id":1722049132937217,"id_str":"1722049132937217","order_type":1,"datetime":"1709257126","microtimestamp":"1709257126299000","amount":0.48922702,"amount_str":"0.48922702","amount_traded":"0","amount_at_create":"0.48922702","price":61322,"price_str":"61322"},"channel":"live_orders_btcusd","event":"order_deleted"}
{"data":{"id":1722049133142018,"id_str":"1722049133142018","order_type":1,"datetime":"1709257126","microtimestamp":"1709257126303000","amount":0.5,"amount_str":"0.50000000","amount_traded":"0","amount_at_create":"0.50000000","price":61356,"price_str":"61356"},"channel":"live_orders_btcusd","event":"order_created"}
{"data":{"id":1722049133162496,"id_str":"1722049133162496","order_type":0,"datetime":"1709257126","microtimestamp":"1709257126308000","amount":0.5,"amount_str":"0.50000000","amount_traded":"0","amount_at_create":"0.50000000","price":61287,"price_str":"61287"},"channel":"live_orders_btcusd","event":"order_created"}
{"data":{"id":1722049133170689,"id_str":"1722049133170689","order_type":1,"datetime":"1709257126","microtimestamp":"1709257126310000","amount":0.00487339,"amount_str":"0.00487339","amount_traded":"0","amount_at_create":"0.00487339","price":61327,"price_str":"61327"},"channel":"live_orders_btcusd","event":"order_created"}
{"data":{"id":1722049133178883,"id_str":"1722049133178883","order_type":0,"datetime":"1709257126","microtimestamp":"1709257126313000","amount":0.1875,"amount_str":"0.18750000","amount_traded":"0","amount_at_create":"0.18750000","price":61299,"price_str":"61299"},"channel":"live_orders_btcusd","event":"order_created"}
{"data":{"id":1722049133195265,"id_str":"1722049133195265","order_type":0,"datetime":"1709257126","microtimestamp":"1709257126316000","amount":0.01631031,"amount_str":"0.01631031","amount_traded":"0","amount_at_create":"0.01631031","price":61310,"price_str":"61310"},"channel":"live_orders_btcusd","event":"order_created"}
{"data":{"id":1722049133379586,"id_str":"1722049133379586","order_type":1,"datetime":"1709257126","microtimestamp":"1709257126362000","amount":0.01630838,"amount_str":"0.01630838","amount_traded":"0","amount_at_create":"0.01630838","price":61319,"price_str":"61319"},"channel":"live_orders_btcusd","event":"order_created"}
{"data":{"id":1722049132347392,"id_str":"1722049132347392","order_type":0,"datetime":"1709257126","microtimestamp":"1709257126376000","amount":0.00040756,"amount_str":"0.00040756","amount_traded":"0","amount_at_create":"0.00040756","price":61304,"price_str":"61304"},"channel":"live_orders_btcusd","event":"order_deleted"}
{"data":{"id":1722049132986369,"id_str":"1722049132986369","order_type":1,"datetime":"1709257126","microtimestamp":"1709257126385000","amount":0.1875,"amount_str":"0.18750000","amount_traded":"0","amount_at_create":"0.18750000","price":61328,"price_str":"61328"},"channel":"live_orders_btcusd","event":"order_deleted"}
{"data":{"id":1722049133588480,"id_str":"1722049133588480","order_type":0,"datetime":"1709257126","microtimestamp":"1709257126412000","amount":0.0163094,"amount_str":"0.01630940","amount_traded":"0","amount_at_create":"0.01630940","price":61299,"price_str":"61299"},"channel":"live_orders_btcusd","event":"order_created"}
{"data":{"id":1722049133682688,"id_str":"1722049133682688","order_type":0,"datetime":"1709257126","microtimestamp":"1709257126435000","amount":0.00040771,"amount_str":"0.00040771","amount_traded":"0","amount_at_create":"0.00040771","price":61303,"price_str":"61303"},"channel":"live_orders_btcusd","event":"order_created"}
{"data":{"id":1722049133813765,"id_str":"1722049133813765","order_type":1,"datetime":"1709257126","microtimestamp":"1709257126468000","amount":0.48923375,"amount_str":"0.48923375","amount_traded":"0","amount_at_create":"0.48923375","price":61321,"price_str":"61321"},"channel":"live_orders_btcusd","event":"order_created"}
{"data":{"id":1722049133682688,"id_str":"1722049133682688","order_type":0,"datetime":"1709257127","microtimestamp":"1709257126532000","amount":0.00040771,"amount_str":"0.00040771","amount_traded":"0","amount_at_create":"0.00040771","price":61303,"price_str":"61303"},"channel":"live_orders_btcusd","event":"order_deleted"}
{"data":{"id":1722049123577856,"id_str":"1722049123577856","order_type":0,"datetime":"1709257127","microtimestamp":"1709257126594000","amount":0.1875,"amount_str":"0.18750000","amount_traded":"0","amount_at_create":"0.18750000","price":61253,"price_str":"61253"},"channel":"live_orders_btcusd","event":"order_deleted"}
{"data":{"id":1722049134645249,"id_str":"1722049134645249","order_type":0,"datetime":"1709257127","microtimestamp":"1709257126671000","amount":0.00040771,"amount_str":"0.00040771","amount_traded":"0","amount_at_create":"0.00040771","price":61304,"price_str":"61304"},"channel":"live_orders_btcusd","event":"order_created"}
{"data":{"id":1722049132933128,"id_str":"1722049132933128","order_type":0,"datetime":"1709257127","microtimestamp":"1709257126703000","amount":0.48935801,"amount_str":"0.48935801","amount_traded":"0","amount_at_create":"0.48935801","price":61304,"price_str":"61304"},"channel":"live_orders_btcusd","event":"order_deleted"}
{"data":{"id":1722049133195265,"id_str":"1722049133195265","order_type":0,"datetime":"1709257127","microtimestamp":"1709257126703000","amount":0.01631031,"amount_str":"0.01631031","amount_traded":"0","amount_at_create":"0.01631031","price":61310,"price_str":"61310"},"channel":"live_orders_btcusd","event":"order_deleted"}
{"data":{"id":1722049133379586,"id_str":"1722049133379586","order_type":1,"datetime":"1709257127","microtimestamp":"1709257126703000","amount":0.01630838,"amount_str":"0.01630838","amount_traded":"0","amount_at_create":"0.01630838","price":61319,"price_str":"61319"},"channel":"live_orders_btcusd","event":"order_deleted"}
{"data":{"id":1722049133813765,"id_str":"1722049133813765","order_type":1,"datetime":"1709257127","microtimestamp":"1709257126704000","amount":0.48923375,"amount_str":"0.48923375","amount_traded":"0","amount_at_create":"0.48923375","price":61321,"price_str":"61321"},"channel":"live_orders_btcusd","event":"order_deleted"}
{"data":{"id":1722049134989313,"id_str":"1722049134989313","order_type":1,"datetime":"1709257127","microtimestamp":"1709257126754000","amount":0.48917158,"amount_str":"0.48917158","amount_traded":"0","amount_at_create":"0.48917158","price":61329,"price_str":"61329"},"channel":"live_orders_btcusd","event":"order_created"}
{"data":{"id":1722049134989318,"id_str":"1722049134989318","order_type":0,"datetime":"1709257127","microtimestamp":"1709257126755000","amount":0.01631002,"amount_str":"0.01631002","amount_traded":"0","amount_at_create":"0.01631002","price":61312,"price_str":"61312"},"channel":"live_orders_btcusd","event":"order_created"}
{"data":{"id":1722049134645249,"id_str":"1722049134645249","order_type":0,"datetime":"1709257127","microtimestamp":"1709257126756000","amount":0.00040771,"amount_str":"0.00040771","amount_traded":"0","amount_at_create":"0.00040771","price":61304,"price_str":"61304"},"channel":"live_orders_btcusd","event":"order_deleted"}
{"data":{"id":1722049134997505,"id_str":"1722049134997505","order_type":0,"datetime":"1709257127","microtimestamp":"1709257126756000","amount":0.48930062,"amount_str":"0.48930062","amount_traded":"0","amount_at_create":"0.48930062","price":61312,"price_str":"61312"},"channel":"live_orders_btcusd","event":"order_created"}
{"data":{"id":1722049135005696,"id_str":"1722049135005696","order_type":1,"datetime":"1709257127","microtimestamp":"1709257126758000","amount":0.01630739,"amount_str":"0.01630739","amount_traded":"0","amount_at_create":"0.01630739","price":61322,"price_str":"61322"},"channel":"live_orders_btcusd","event":"order_created"}
{"data":{"id":1722049134989318,"id_str":"1722049134989318","order_type":0,"datetime":"1709257127","microtimestamp":"1709257126800000","amount":0.01631002,"amount_str":"0.01631002","amount_traded":"0","amount_at_create":"0.01631002","price":61312,"price_str":"61312"},"channel":"live_orders_btcusd","event":"order_deleted"}
{"data":{"id":1722048977813504,"id_str":"1722048977813504","order_type":0,"datetime":"1709257127","microtimestamp":"1709257126821000","amount":0.25914631,"amount_str":"0.25914631","amount_traded":"0","amount_at_create":"0.25914631","price":61232,"price_str":"61232"},"channel":"live_orders_btcusd","event":"order_deleted"}
{"data":{"id":1722049135452161,"id_str":"1722049135452161","order_type":0,"datetime":"1709257127","microtimestamp":"1709257126867000","amount":0.01630958,"amount_str":"0.01630958","amount_traded":"0","amount_at_create":"0.01630958","price":61313,"price_str":"61313"},"channel":"live_orders_btcusd","event":"order_created"}
{"data":{"id":1722049135513600,"id_str":"1722049135513600","order_type":0,"datetime":"1709257127","microtimestamp":"1709257126882000","amount":0.88117309,"amount_str":"0.88117309","amount_traded":"0","amount_at_create":"0.88117309","price":61236,"price_str":"61236"},"channel":"live_orders_btcusd","event":"order_created"}
{"data":{"id":1722049132064770,"id_str":"1722049132064770","order_type":1,"datetime":"1709257127","microtimestamp":"1709257126899000","amount":0.48920941,"amount_str":"0.48920941","amount_traded":"0","amount_at_create":"0.48920941","price":61324,"price_str":"61324"},"channel":"live_orders_btcusd","event":"order_deleted"}
{"data":{"id":1722049135005696,"id_str":"1722049135005696","order_type":1,"datetime":"1709257127","microtimestamp":"1709257126899000","amount":0.01630739,"amount_str":"0.01630739","amount_traded":"0","amount_at_create":"0.01630739","price":61322,"price_str":"61322"},"channel":"live_orders_btcusd","event":"order_deleted"}
{"data":{"id":1722049134989313,"id_str":"1722049134989313","order_type":1,"datetime":"1709257127","microtimestamp":"1709257126900000","amount":0.48917158,"amount_str":"0.48917158","amount_traded":"0","amount_at_create":"0.48917158","price":61329,"price_str":"61329"},"channel":"live_orders_btcusd","event":"order_deleted"}
{"data":{"id":1722049135763457,"id_str":"1722049135763457","order_type":1,"datetime":"1709257127","microtimestamp":"1709257126943000","amount":0.01630773,"amount_str":"0.01630773","amount_traded":"0","amount_at_create":"0.01630773","price":61321,"price_str":"61321"},"channel":"live_orders_btcusd","event":"order_created"}
{"data":{"id":1722049135767552,"id_str":"1722049135767552","order_type":1,"datetime":"1709257127","microtimestamp":"1709257126944000","amount":0.48921445,"amount_str":"0.48921445","amount_traded":"0","amount_at_create":"0.48921445","price":61323,"price_str":"61323"},"channel":"live_orders_btcusd","event":"order_created"}
{"data":{"id":1722049135865856,"id_str":"1722049135865856","order_type":0,"datetime":"1709257127","microtimestamp":"1709257126969000","amount":0.1875,"amount_str":"0.18750000","amount_traded":"0","amount_at_create":"0.18750000","price":61306,"price_str":"61306"},"channel":"live_orders_btcusd","event":"order_created"}
{"data":{"id":1722049135996930,"id_str":"1722049135996930","order_type":0,"datetime":"1709257127","microtimestamp":"1709257127001000","amount":0.00040771,"amount_str":"0.00040771","amount_traded":"0","amount_at_create":"0.00040771","price":61303,"price_str":"61303"},"channel":"live_orders_btcusd","event":"order_created"}
{"data":{"id":1722049135452161,"id_str":"1722049135452161","order_type":0,"datetime":"1709257127","microtimestamp":"1709257127101000","amount":0.01630958,"amount_str":"0.01630958","amount_traded":"0","amount_at_create":"0.01630958","price":61313,"price_str":"61313"},"channel":"live_orders_btcusd","event":"order_deleted"}
{"data":{"id":1722049135767552,"id_str":"1722049135767552","order_type":1,"datetime":"1709257127","microtimestamp":"1709257127145000","amount":0.48921445,"amount_str":"0.48921445","amount_traded":"0","amount_at_create":"0.48921445","price":61323,"price_str":"61323"},"channel":"live_orders_btcusd","event":"order_deleted"}
{"data":{"id":1722049135763457,"id_str":"1722049135763457","order_type":1,"datetime":"1709257127","microtimestamp":"1709257127146000","amount":0.01630773,"amount_str":"0.01630773","amount_traded":"0","amount_at_create":"0.01630773","price":61321,"price_str":"61321"},"channel":"live_orders_btcusd","event":"order_deleted"}
{"data":{"id":1722049136599042,"id_str":"1722049136599042","order_type":0,"datetime":"1709257127","microtimestamp":"1709257127148000","amount":0.01630936,"amount_str":"0.01630936","amount_traded":"0","amount_at_create":"0.01630936","price":61314,"price_str":"61314"},"channel":"live_orders_btcusd","event":"order_created"}
{"data":{"id":1722049136791553,"id_str":"1722049136791553","order_type":1,"datetime":"1709257127","microtimestamp":"1709257127194000","amount":0.0163073,"amount_str":"0.01630730","amount_traded":"0","amount_at_create":"0.01630730","price":61323,"price_str":"61323"},"channel":"live_orders_btcusd","event":"order_created"}
{"data":{"id":1722049136799745,"id_str":"1722049136799745","order_type":1,"datetime":"1709257127","microtimestamp":"1709257127197000","amount":0.48920155,"amount_str":"0.48920155","amount_traded":"0","amount_at_create":"0.48920155","price":61325,"price_str":"61325"},"channel":"live_orders_btcusd","event":"order_created"}
{"data":{"id":1722049136791553,"id_str":"1722049136791553","order_type":1,"datetime":"1709257127","microtimestamp":"1709257127212000","amount":0.0163073,"amount_str":"0.01630730","amount_traded":"0","amount_at_create":"0.01630730","price":61323,"price_str":"61323"},"channel":"live_orders_btcusd","event":"order_deleted"}
{"data":{"id":1722049136799745,"id_str":"1722049136799745","order_type":1,"datetime":"1709257127","microtimestamp":"1709257127239000","amount":0.48920155,"amount_str":"0.48920155","amount_traded":"0","amount_at_create":"0.48920155","price":61325,"price_str":"61325"},"channel":"live_orders_btcusd","event":"order_deleted"}
{"data":{"id":1722049137049601,"id_str":"1722049137049601","order_type":1,"datetime":"1709257127","microtimestamp":"1709257127257000","amount":0.48918187,"amount_str":"0.48918187","amount_traded":"0","amount_at_create":"0.48918187","price":61327,"price_str":"61327"},"channel":"live_orders_btcusd","event":"order_created"}
{"data":{"id":1722049137049601,"id_str":"1722049137049601","order_type":1,"datetime":"1709257127","microtimestamp":"1709257127302000","amount":0.48918187,"amount_str":"0.48918187","amount_traded":"0","amount_at_create":"0.48918187","price":61327,"price_str":"61327"},"channel":"live_orders_btcusd","event":"order_deleted"}
{"data":{"id":1722049137217538,"id_str":"1722049137217538","order_type":1,"datetime":"1709257127","microtimestamp":"1709257127302000","amount":0.01630743,"amount_str":"0.01630743","amount_traded":"0","amount_at_create":"0.01630743","price":61322,"price_str":"61322"},"channel":"live_orders_btcusd","event":"order_created"}
{"data":{"id":1722049137217538,"id_str":"1722049137217538","order_type":1,"datetime":"1709257127","microtimestamp":"1709257127322000","amount":0.01630743,"amount_str":"0.01630743","amount_traded":"0","amount_at_create":"0.01630743","price":61322,"price_str":"61322"},"channel":"live_orders_btcusd","event":"order_deleted"}
{"data":{"id":1722049135996930,"id_str":"1722049135996930","order_type":0,"datetime":"1709257127","microtimestamp":"1709257127322000","amount":0.00040771,"amount_str":"0.00040771","amount_traded":"0","amount_at_create":"0.00040771","price":61303,"price_str":"61303"},"channel":"live_orders_btcusd","event":"order_deleted"}
{"data":{"id":1722049124823042,"id_str":"1722049124823042","order_type":1,"datetime":"1709257127","microtimestamp":"1709257127402000","amount":0.02345038,"amount_str":"0.02345038","amount_traded":"0","amount_at_create":"0.02345038","price":61338,"price_str":"61338"},"channel":"live_orders_btcusd","event":"order_deleted"}
{"data":{"id":1722049137696768,"id_str":"1722049137696768","order_type":0,"datetime":"1709257127","microtimestamp":"1709257127416000","amount":0.00040771,"amount_str":"0.00040771","amount_traded":"0","amount_at_create":"0.00040771","price":61304,"price_str":"61304"},"channel":"live_orders_btcusd","event":"order_created"}
{"data":{"id":1722049137770500,"id_str":"1722049137770500","order_type":1,"datetime":"1709257127","microtimestamp":"1709257127434000","amount":0.48918892,"amount_str":"0.48918892","amount_traded":"0","amount_at_create":"0.48918892","price":61326,"price_str":"61326"},"channel":"live_orders_btcusd","event":"order_created"}
{"data":{"id":1722049137778689,"id_str":"1722049137778689","order_type":1,"datetime":"1709257127","microtimestamp":"1709257127436000","amount":0.01630719,"amount_str":"0.01630719","amount_traded":"0","amount_at_create":"0.01630719","price":61323,"price_str":"61323"},"channel":"live_orders_btcusd","event":"order_created"}
{"data":{"id":1722049137778689,"id_str":"1722049137778689","order_type":1,"datetime":"1709257127","microtimestamp":"1709257127451000","amount":0.01630719,"amount_str":"0.01630719","amount_traded":"0","amount_at_create":"0.01630719","price":61323,"price_str":"61323"},"channel":"live_orders_btcusd","event":"order_deleted"}
{"data":{"id":1722049135865856,"id_str":"1722049135865856","order_type":0,"datetime":"1709257127","microtimestamp":"1709257127454000","amount":0.1875,"amount_str":"0.18750000","amount_traded":"0","amount_at_create":"0.18750000","price":61306,"price_str":"61306"},"channel":"live_orders_btcusd","event":"order_deleted"}
{"data":{"id":1722049137856515,"id_str":"1722049137856515","order_type":1,"datetime":"1709257127","microtimestamp":"1709257127455000","amount":0.02467134,"amount_str":"0.02467134","amount_traded":"0","amount_at_create":"0.02467134","price":61337,"price_str":"61337"},"channel":"live_orders_btcusd","event":"order_created"}
{"data":{"id":1722049138184192,"id_str":"1722049138184192","order_type":1,"datetime":"1709257128","microtimestamp":"1709257127534000","amount":0.01630763,"amount_str":"0.01630763","amount_traded":"0","amount_at_create":"0.01630763","price":61321,"price_str":"61321"},"channel":"live_orders_btcusd","event":"order_created"}
{"data":{"id":1722049134997505,"id_str":"1722049134997505","order_type":0,"datetime":"1709257128","microtimestamp":"1709257127603000","amount":0.48930062,"amount_str":"0.48930062","amount_traded":"0","amount_at_create":"0.48930062","price":61312,"price_str":"61312"},"channel":"live_orders_btcusd","event":"order_deleted"}
{"data":{"id":1722049137696768,"id_str":"1722049137696768","order_type":0,"datetime":"1709257128","microtimestamp":"1709257127618000","amount":0.00040771,"amount_str":"0.00040771","amount_traded":"0","amount_at_create":"0.00040771","price":61304,"price_str":"61304"},"channel":"live_orders_btcusd","event":"order_deleted"}
{"data":{"id":1722049138651136,"id_str":"1722049138651136","order_type":1,"datetime":"1709257128","microtimestamp":"1709257127648000","amount":0.4891969,"amount_str":"0.48919690","amount_traded":"0","amount_at_create":"0.48919690","price":61325,"price_str":"61325"},"channel":"live_orders_btcusd","event":"order_created"}
{"data":{"id":1722049138655233,"id_str":"1722049138655233","order_type":0,"datetime":"1709257128","microtimestamp":"1709257127649000","amount":0.48930974,"amount_str":"0.48930974","amount_traded":"0","amount_at_create":"0.48930974","price":61310,"price_str":"61310"},"channel":"live_orders_btcusd","event":"order_created"}
{"data":{"id":1722049138651136,"id_str":"1722049138651136","order_type":1,"datetime":"1709257128","microtimestamp":"1709257127665000","amount":0.4891969,"amount_str":"0.48919690","amount_traded":"0","amount_at_create":"0.48919690","price":61325,"price_str":"61325"},"channel":"live_orders_btcusd","event":"order_deleted"}
{"data":{"id":1722049138851840,"id_str":"1722049138851840","order_type":0,"datetime":"1709257128","microtimestamp":"1709257127697000","amount":0.00040771,"amount_str":"0.00040771","amount_traded":"0","amount_at_create":"0.00040771","price":61303,"price_str":"61303"},"channel":"live_orders_btcusd","event":"order_created"}
{"data":{"id":1722049138655233,"id_str":"1722049138655233","order_type":0,"datetime":"1709257128","microtimestamp":"1709257127698000","amount":0.48930974,"amount_str":"0.48930974","amount_traded":"0","amount_at_create":"0.48930974","price":61310,"price_str":"61310"},"channel":"live_orders_btcusd","event":"order_deleted"}
{"data":{"id":1722049136599042,"id_str":"1722049136599042","order_type":0,"datetime":"1709257128","microtimestamp":"1709257127797000","amount":0.01630936,"amount_str":"0.01630936","amount_traded":"0","amount_at_create":"0.01630936","price":61314,"price_str":"61314"},"channel":"live_orders_btcusd","event":"order_deleted"}
{"data":{"id":1722049139396610,"id_str":"1722049139396610","order_type":1,"datetime":"1709257128","microtimestamp":"1709257127830000","amount":0.5,"amount_str":"0.50000000","amount_traded":"0","amount_at_create":"0.50000000","price":61319,"price_str":"61319"},"channel":"live_orders_btcusd","event":"order_created"}
{"data":{"id":1722049139466241,"id_str":"1722049139466241","order_type":0,"datetime":"1709257128","microtimestamp":"1709257127847000","amount":0.01630979,"amount_str":"0.01630979","amount_traded":"0","amount_at_create":"0.01630979","price":61312,"price_str":"61312"},"channel":"live_orders_btcusd","event":"order_created"}
{"data":{"id":1722049139646465,"id_str":"1722049139646465","order_type":0,"datetime":"1709257128","microtimestamp":"1709257127892000","amount":0.48930768,"amount_str":"0.48930768","amount_traded":"0","amount_at_create":"0.48930768","price":61311,"price_str":"61311"},"channel":"live_orders_btcusd","event":"order_created"}
{"data":{"id":1722049139654657,"id_str":"1722049139654657","order_type":1,"datetime":"1709257128","microtimestamp":"1709257127893000","amount":0.48921458,"amount_str":"0.48921458","amount_traded":"0","amount_at_create":"0.48921458","price":61323,"price_str":"61323"},"channel":"live_orders_btcusd","event":"order_created"}
{"data":{"id":1722049138851840,"id_str":"1722049138851840","order_type":0,"datetime":"1709257128","microtimestamp":"1709257127917000","amount":0.00040771,"amount_str":"0.00040771","amount_traded":"0","amount_at_create":"0.00040771","price":61303,"price_str":"61303"},"channel":"live_orders_btcusd","event":"order_deleted"}
{"data":{"id":1722049138184192,"id_str":"1722049138184192","order_type":1,"datetime":"1709257128","microtimestamp":"1709257127997000","amount":0.01630763,"amount_str":"0.01630763","amount_traded":"0","amount_at_create":"0.01630763","price":61321,"price_str":"61321"},"channel":"live_orders_btcusd","event":"order_deleted"}
{"data":{"id":1722049140211714,"id_str":"1722049140211714","order_type":0,"datetime":"1709257128","microtimestamp":"1709257128030000","amount":0.00040771,"amount_str":"0.00040771","amount_traded":"0","amount_at_create":"0.00040771","price":61304,"price_str":"61304"},"channel":"live_orders_btcusd","event":"order_created"}
