{"event":"bts:subscription_succeeded","channel":"live_orders_btcusd","data":{}}
{"data":{"id":1722048902705154,"id_str":"1722048902705154","order_type":1,"datetime":"1709257070","microtimestamp":"1709257070202000","amount":0.01629838,"amount_str":"0.01629838","amount_traded":"0","amount_at_create":"0.01629838","price":61356,"price_str":"61356"},"channel":"live_orders_btcusd","event":"order_deleted"}
{"data":{"id":1722048902696960,"id_str":"1722048902696960","order_type":0,"datetime":"1709257070","microtimestamp":"1709257070202000","amount":0.48902063,"amount_str":"0.48902063","amount_traded":"0","amount_at_create":"0.48902063","price":61347,"price_str":"61347"},"channel":"live_orders_btcusd","event":"order_deleted"}
{"data":{"id":1722048901558272,"id_str":"1722048901558272","order_type":0,"datetime":"1709257070","microtimestamp":"1709257070202000","amount":0.0163001,"amount_str":"0.01630010","amount_traded":"0","amount_at_create":"0.01630010","price":61349,"price_str":"61349"},"channel":"live_orders_btcusd","event":"order_deleted"}
{"data":{"id":1722048902885376,"id_str":"1722048902885376","order_type":1,"datetime":"1709257070","microtimestamp":"1709257070202000","amount":0.48893379,"amount_str":"0.48893379","amount_traded":"0","amount_at_create":"0.48893379","price":61358,"price_str":"61358"},"channel":"live_orders_btcusd","event":"order_deleted"}
{"data":{"id":1722048903372800,"id_str":"1722048903372800","order_type":0,"datetime":"1709257070","microtimestamp":"1709257070207000","amount":0.00040751,"amount_str":"0.00040751","amount_traded":"0","amount_at_create":"0.00040751","price":61340,"price_str":"61340"},"channel":"live_orders_btcusd","event":"order_created"}
{"data":{"id":1722048901709824,"id_str":"1722048901709824","order_type":0,"datetime":"1709257070","microtimestamp":"1709257070247000","amount":0.1875,"amount_str":"0.18750000","amount_traded":"0","amount_at_create":"0.18750000","price":61334,"price_str":"61334"},"channel":"live_orders_btcusd","event":"order_deleted"}
{"data":{"id":1722048903544840,"id_str":"1722048903544840","order_type":1,"datetime":"1709257070","microtimestamp":"1709257070250000","amount":0.01629869,"amount_str":"0.01629869","amount_traded":"0","amount_at_create":"0.01629869","price":61355,"price_str":"61355"},"channel":"live_orders_btcusd","event":"order_created"}
{"data":{"id":1722048903553025,"id_str":"1722048903553025","order_type":0,"datetime":"1709257070","microtimestamp":"1709257070252000","amount":0.01630056,"amount_str":"0.01630056","amount_traded":"0","amount_at_create":"0.01630056","price":61347,"price_str":"61347"},"channel":"live_orders_btcusd","event":"order_created"}
{"data":{"id":1722048903557122,"id_str":"1722048903557122","order_type":0,"datetime":"1709257070","microtimestamp":"1709257070253000","amount":0.48903451,"amount_str":"0.48903451","amount_traded":"0","amount_at_create":"0.48903451","price":61345,"price_str":"61345"},"channel":"live_orders_btcusd","event":"order_created"}
{"data":{"id":1722048903696385,"id_str":"1722048903696385","order_type":0,"datetime":"1709257070","microtimestamp":"1709257070286000","amount":0.40749663,"amount_str":"0.40749663","amount_traded":"0","amount_at_create":"0.40749663","price":61141,"price_str":"61141"},"channel":"live_orders_btcusd","event":"order_created"}
{"data":{"id":1722048903737344,"id_str":"1722048903737344","order_type":1,"datetime":"1709257070","microtimestamp":"1709257070297000","amount":0.48891786,"amount_str":"0.48891786","amount_traded":"0","amount_at_create":"0.48891786","price":61360,"price_str":"61360"},"channel":"live_orders_btcusd","event":"order_created"}
{"data":{"id":1722048903696385,"id_str":"1722048903696385","order_type":0,"datetime":"1709257070","microtimestamp":"1709257070300000","amount":0.40749663,"amount_str":"0.40749663","amount_traded":"0","amount_at_create":"0.40749663","price":61141,"price_str":"61141"},"channel":"live_orders_btcusd","event":"order_deleted"}
{"data":{"id":1722048903766016,"id_str":"1722048903766016","order_type":1,"datetime":"1709257070","microtimestamp":"1709257070303000","amount":0.1875,"amount_str":"0.18750000","amount_traded":"0","amount_at_create":"0.18750000","price":61369,"price_str":"61369"},"channel":"live_orders_btcusd","event":"order_created"}
{"data":{"id":1722048903737344,"id_str":"1722048903737344","order_type":1,"datetime":"1709257070","microtimestamp":"1709257070312000","amount":0.48891786,"amount_str":"0.48891786","amount_traded":"0","amount_at_create":"0.48891786","price":61360,"price_str":"61360"},"channel":"live_orders_btcusd","event":"order_deleted"}
{"data":{"id":1722048903372800,"id_str":"1722048903372800","order_type":0,"datetime":"1709257070","microtimestamp":"1709257070357000","amount":0.00040751,"amount_str":"0.00040751","amount_traded":"0","amount_at_create":"0.00040751","price":61340,"price_str":"61340"},"channel":"live_orders_btcusd","event":"order_deleted"}
{"data":{"id":1722048904134656,"id_str":"1722048904134656","order_type":0,"datetime":"1709257070","microtimestamp":"1709257070394000","amount":0.00040751,"amount_str":"0.00040751","amount_traded":"0","amount_at_create":"0.00040751","price":61341,"price_str":"61341"},"channel":"live_orders_btcusd","event":"order_created"}
{"data":{"id":1722048904359937,"id_str":"1722048904359937","order_type":1,"datetime":"1709257070","microtimestamp":"1709257070448000","amount":0.12188796,"amount_str":"0.12188796","amount_traded":"0","amount_at_create":"0.12188796","price":61428,"price_str":"61428"},"channel":"live_orders_btcusd","event":"order_created"}
{"data":{"id":1722048904134656,"id_str":"1722048904134656","order_type":0,"datetime":"1709257070","microtimestamp":"1709257070487000","amount":0.00040751,"amount_str":"0.00040751","amount_traded":"0","amount_at_create":"0.00040751","price":61341,"price_str":"61341"},"channel":"live_orders_btcusd","event":"order_deleted"}
{"data":{"id":1722048901820416,"id_str":"1722048901820416","order_type":1,"datetime":"1709257070","microtimestamp":"1709257070491000","amount":0.1875,"amount_str":"0.18750000","amount_traded":"0","amount_at_create":"0.18750000","price":61700,"price_str":"61700"},"channel":"live_orders_btcusd","event":"order_deleted"}
{"data":{"id":1722048903553025,"id_str":"1722048903553025","order_type":0,"datetime":"1709257070","microtimestamp":"1709257070497000","amount":0.01630056,"amount_str":"0.01630056","amount_traded":"0","amount_at_create":"0.01630056","price":61347,"price_str":"61347"},"channel":"live_orders_btcusd","event":"order_deleted"}
{"data":{"id":1722048897613832,"id_str":"1722048897613832","order_type":1,"datetime":"1709257071","microtimestamp":"1709257070501000","amount":0.01749781,"amount_str":"0.01749781","amount_traded":"0","amount_at_create":"0.01749781","price":61374,"price_str":"61374"},"channel":"live_orders_btcusd","event":"order_deleted"}
{"data":{"id":1722048904724481,"id_str":"1722048904724481","order_type":1,"datetime":"1709257071","microtimestamp":"1709257070537000","amount":0.1875,"amount_str":"0.18750000","amount_traded":"0","amount_at_create":"0.18750000","price":61418,"price_str":"61418"},"channel":"live_orders_btcusd","event":"order_created"}
{"data":{"id":1722048904740865,"id_str":"1722048904740865","order_type":0,"datetime":"1709257071","microtimestamp":"1709257070541000","amount":0.01630043,"amount_str":"0.01630043","amount_traded":"0","amount_at_create":"0.01630043","price":61348,"price_str":"61348"},"channel":"live_orders_btcusd","event":"order_created"}
{"data":{"id":1722048904740867,"id_str":"1722048904740867","order_type":1,"datetime":"1709257071","microtimestamp":"1709257070542000","amount":0.48894509,"amount_str":"0.48894509","amount_traded":"0","amount_at_create":"0.48894509","price":61357,"price_str":"61357"},"channel":"live_orders_btcusd","event":"order_created"}
{"data":{"id":1722048904933378,"id_str":"1722048904933378","order_type":1,"datetime":"1709257071","microtimestamp":"1709257070589000","amount":0.4885961,"amount_str":"0.48859610","amount_traded":"0","amount_at_create":"0.48859610","price":61401,"price_str":"61401"},"channel":"live_orders_btcusd","event":"order_created"}
{"data":{"id":1722048905060352,"id_str":"1722048905060352","order_type":0,"datetime":"1709257071","microtimestamp":"1709257070619000","amount":0.00040751,"amount_str":"0.00040751","amount_traded":"0","amount_at_create":"0.00040751","price":61340,"price_str":"61340"},"channel":"live_orders_btcusd","event":"order_created"}
{"data":{"id":1722048905199616,"id_str":"1722048905199616","order_type":0,"datetime":"1709257071","microtimestamp":"1709257070653000","amount":0.1875,"amount_str":"0.18750000","amount_traded":"0","amount_at_create":"0.18750000","price":61334,"price_str":"61334"},"channel":"live_orders_btcusd","event":"order_created"}
{"data":{"id":1722048904359937,"id_str":"1722048904359937","order_type":1,"datetime":"1709257071","microtimestamp":"1709257070670000","amount":0.12188796,"amount_str":"0.12188796","amount_traded":"0","amount_at_create":"0.12188796","price":61428,"price_str":"61428"},"channel":"live_orders_btcusd","event":"order_deleted"}
{"data":{"id":1722048905723906,"id_str":"1722048905723906","order_type":0,"datetime":"1709257071","microtimestamp":"1709257070781000","amount":0.40749663,"amount_str":"0.40749663","amount_traded":"0","amount_at_create":"0.40749663","price":61140,"price_str":"61140"},"channel":"live_orders_btcusd","event":"order_created"}
{"data":{"id":1722048905723906,"id_str":"1722048905723906","order_type":0,"datetime":"1709257071","microtimestamp":"1709257070799000","amount":0.40749663,"amount_str":"0.40749663","amount_traded":"0","amount_at_create":"0.40749663","price":61140,"price_str":"61140"},"channel":"live_orders_btcusd","event":"order_deleted"}
{"data":{"id":1722048905060352,"id_str":"1722048905060352","order_type":0,"datetime":"1709257071","microtimestamp":"1709257070812000","amount":0.00040751,"amount_str":"0.00040751","amount_traded":"0","amount_at_create":"0.00040751","price":61340,"price_str":"61340"},"channel":"live_orders_btcusd","event":"order_deleted"}
{"data":{"id":1722048903544840,"id_str":"1722048903544840","order_type":1,"datetime":"1709257071","microtimestamp":"1709257070812000","amount":0.01629869,"amount_str":"0.01629869","amount_traded":"0","amount_at_create":"0.01629869","price":61355,"price_str":"61355"},"channel":"live_orders_btcusd","event":"order_deleted"}
{"data":{"id":1722048904740867,"id_str":"1722048904740867","order_type":1,"datetime":"1709257071","microtimestamp":"1709257070812000","amount":0.48894509,"amount_str":"0.48894509","amount_traded":"0","amount_at_create":"0.48894509","price":61357,"price_str":"61357"},"channel":"live_orders_btcusd","event":"order_deleted"}
{"data":{"id":1722048904740865,"id_str":"1722048904740865","order_type":0,"datetime":"1709257071","microtimestamp":"1709257070812000","amount":0.01630043,"amount_str":"0.01630043","amount_traded":"0","amount_at_create":"0.01630043","price":61348,"price_str":"61348"},"channel":"live_orders_btcusd","event":"order_deleted"}
{"data":{"id":1722048903557122,"id_str":"1722048903557122","order_type":0,"datetime":"1709257071","microtimestamp":"1709257070812000","amount":0.48903451,"amount_str":"0.48903451","amount_traded":"0","amount_at_create":"0.48903451","price":61345,"price_str":"61345"},"channel":"live_orders_btcusd","event":"order_deleted"}
{"data":{"id":1722048900419584,"id_str":"1722048900419584","order_type":0,"datetime":"1709257071","microtimestamp":"1709257070822000","amount":0.00814962,"amount_str":"0.00814962","amount_traded":"0","amount_at_create":"0.00814962","price":61348,"price_str":"61348"},"channel":"live_orders_btcusd","event":"order_deleted"}
{"data":{"id":1722048900194304,"id_str":"1722048900194304","order_type":1,"datetime":"1709257071","microtimestamp":"1709257070842000","amount":0.00487025,"amount_str":"0.00487025","amount_traded":"0","amount_at_create":"0.00487025","price":61366,"price_str":"61366"},"channel":"live_orders_btcusd","event":"order_deleted"}
{"data":{"id":1722048903766016,"id_str":"1722048903766016","order_type":1,"datetime":"1709257071","microtimestamp":"1709257070847000","amount":0.1875,"amount_str":"0.18750000","amount_traded":"0","amount_at_create":"0.18750000","price":61369,"price_str":"61369"},"channel":"live_orders_btcusd","event":"order_deleted"}
{"data":{"id":1722048905998337,"id_str":"1722048905998337","order_type":1,"datetime":"1709257071","microtimestamp":"1709257070849000","amount":0.04374456,"amount_str":"0.04374456","amount_traded":"0","amount_at_create":"0.04374456","price":61374,"price_str":"61374"},"channel":"live_orders_btcusd","event":"order_created"}
{"data":{"id":1722048897818630,"id_str":"1722048897818630","order_type":1,"datetime":"1709257071","microtimestamp":"1709257070849000","amount":0.09740357,"amount_str":"0.09740357","amount_traded":"0","amount_at_create":"0.09740357","price":61387,"price_str":"61387"},"channel":"live_orders_btcusd","event":"order_deleted"}
{"data":{"id":1722048906039296,"id_str":"1722048906039296","order_type":1,"datetime":"1709257071","microtimestamp":"1709257070858000","amount":0.01629831,"amount_str":"0.01629831","amount_traded":"0","amount_at_create":"0.01629831","price":61357,"price_str":"61357"},"channel":"live_orders_btcusd","event":"order_created"}
{"data":{"id":1722048906051584,"id_str":"1722048906051584","order_type":1,"datetime":"1709257071","microtimestamp":"1709257070861000","amount":0.48893187,"amount_str":"0.48893187","amount_traded":"0","amount_at_create":"0.48893187","price":61359,"price_str":"61359"},"channel":"live_orders_btcusd","event":"order_created"}
{"data":{"id":1722048906051587,"id_str":"1722048906051587","order_type":0,"datetime":"1709257071","microtimestamp":"1709257070862000","amount":0.0163001,"amount_str":"0.01630010","amount_traded":"0","amount_at_create":"0.01630010","price":61349,"price_str":"61349"},"channel":"live_orders_btcusd","event":"order_created"}
{"data":{"id":1722048906059778,"id_str":"1722048906059778","order_type":0,"datetime":"1709257071","microtimestamp":"1709257070863000","amount":0.48902074,"amount_str":"0.48902074","amount_traded":"0","amount_at_create":"0.48902074","price":61347,"price_str":"61347"},"channel":"live_orders_btcusd","event":"order_created"}
{"data":{"id":1722048906072067,"id_str":"1722048906072067","order_type":1,"datetime":"1709257071","microtimestamp":"1709257070866000","amount":0.00487073,"amount_str":"0.00487073","amount_traded":"0","amount_at_create":"0.00487073","price":61361,"price_str":"61361"},"channel":"live_orders_btcusd","event":"order_created"}
{"data":{"id":1722048906149888,"id_str":"1722048906149888","order_type":1,"datetime":"1709257071","microtimestamp":"1709257070885000","amount":0.09741469,"amount_str":"0.09741469","amount_traded":"0","amount_at_create":"0.09741469","price":61380,"price_str":"61380"},"channel":"live_orders_btcusd","event":"order_created"}
{"data":{"id":1722048906170368,"id_str":"1722048906170368","order_type":0,"datetime":"1709257071","microtimestamp":"1709257070890000","amount":0.00040751,"amount_str":"0.00040751","amount_traded":"0","amount_at_create":"0.00040751","price":61341,"price_str":"61341"},"channel":"live_orders_btcusd","event":"order_created"}
{"data":{"id":1722048906039296,"id_str":"1722048906039296","order_type":1,"datetime":"1709257071","microtimestamp":"1709257070899000","amount":0.01629831,"amount_str":"0.01629831","amount_traded":"0","amount_at_create":"0.01629831","price":61357,"price_str":"61357"},"channel":"live_orders_btcusd","event":"order_deleted"}
{"data":{"id":1722048906235905,"id_str":"1722048906235905","order_type":0,"datetime":"1709257071","microtimestamp":"1709257070906000","amount":0.00814975,"amount_str":"0.00814975","amount_traded":"0","amount_at_create":"0.00814975","price":61345,"price_str":"61345"},"channel":"live_orders_btcusd","event":"order_created"}
{"data":{"id":1722048906051584,"id_str":"1722048906051584","order_type":1,"datetime":"1709257071","microtimestamp":"1709257070907000","amount":0.48893187,"amount_str":"0.48893187","amount_traded":"0","amount_at_create":"0.48893187","price":61359,"price_str":"61359"},"channel":"live_orders_btcusd","event":"order_deleted"}
{"data":{"id":1722048906170368,"id_str":"1722048906170368","order_type":0,"datetime":"1709257071","microtimestamp":"1709257070960000","amount":0.00040751,"amount_str":"0.00040751","amount_traded":"0","amount_at_create":"0.00040751","price":61341,"price_str":"61341"},"channel":"live_orders_btcusd","event":"order_deleted"}
{"data":{"id":1722048900767744,"id_str":"1722048900767744","order_type":1,"datetime":"1709257071","microtimestamp":"1709257071003000","amount":0.48891103,"amount_str":"0.48891103","amount_traded":"0","amount_at_create":"0.48891103","price":61361,"price_str":"61361"},"channel":"live_orders_btcusd","event":"order_deleted"}
{"data":{"id":1722048906059778,"id_str":"1722048906059778","order_type":0,"datetime":"1709257071","microtimestamp":"1709257071003000","amount":0.48902074,"amount_str":"0.48902074","amount_traded":"0","amount_at_create":"0.48902074","price":61347,"price_str":"61347"},"channel":"live_orders_btcusd","event":"order_deleted"}
{"data":{"id":1722048906051587,"id_str":"1722048906051587","order_type":0,"datetime":"1709257071","microtimestamp":"1709257071003000","amount":0.0163001,"amount_str":"0.01630010","amount_traded":"0","amount_at_create":"0.01630010","price":61349,"price_str":"61349"},"channel":"live_orders_btcusd","event":"order_deleted"}
{"data":{"id":1722048906072067,"id_str":"1722048906072067","order_type":1,"datetime":"1709257071","microtimestamp":"1709257071011000","amount":0.00487073,"amount_str":"0.00487073","amount_traded":"0","amount_at_create":"0.00487073","price":61361,"price_str":"61361"},"channel":"live_orders_btcusd","event":"order_deleted"}
{"data":{"id":1722048906817536,"id_str":"1722048906817536","order_type":0,"datetime":"1709257071","microtimestamp":"1709257071048000","amount":0.00814929,"amount_str":"0.00814929","amount_traded":"0","amount_at_create":"0.00814929","price":61347,"price_str":"61347"},"channel":"live_orders_btcusd","event":"order_created"}
{"data":{"id":1722048906817537,"id_str":"1722048906817537","order_type":1,"datetime":"1709257071","microtimestamp":"1709257071048000","amount":0.01629799,"amount_str":"0.01629799","amount_traded":"0","amount_at_create":"0.01629799","price":61358,"price_str":"61358"},"channel":"live_orders_btcusd","event":"order_created"}
{"data":{"id":1722048906821634,"id_str":"1722048906821634","order_type":0,"datetime":"1709257071","microtimestamp":"1709257071049000","amount":0.01629977,"amount_str":"0.01629977","amount_traded":"0","amount_at_create":"0.01629977","price":61350,"price_str":"61350"},"channel":"live_orders_btcusd","event":"order_created"}
{"data":{"id":1722048906821637,"id_str":"1722048906821637","order_type":1,"datetime":"1709257071","microtimestamp":"1709257071050000","amount":0.48889002,"amount_str":"0.48889002","amount_traded":"0","amount_at_create":"0.48889002","price":61364,"price_str":"61364"},"channel":"live_orders_btcusd","event":"order_created"}
{"data":{"id":1722048906833921,"id_str":"1722048906833921","order_type":0,"datetime":"1709257071","microtimestamp":"1709257071052000","amount":0.00040751,"amount_str":"0.00040751","amount_traded":"0","amount_at_create":"0.00040751","price":61340,"price_str":"61340"},"channel":"live_orders_btcusd","event":"order_created"}
{"data":{"id":1722048906903552,"id_str":"1722048906903552","order_type":1,"datetime":"1709257071","microtimestamp":"1709257071069000","amount":0.086,"amount_str":"0.08600000","amount_traded":"0","amount_at_create":"0.08600000","price":61361,"price_str":"61361"},"channel":"live_orders_btcusd","event":"order_created"}
{"data":{"id":1722048907005953,"id_str":"1722048907005953","order_type":0,"datetime":"1709257071","microtimestamp":"1709257071094000","amount":0.48902943,"amount_str":"0.48902943","amount_traded":"0","amount_at_create":"0.48902943","price":61346,"price_str":"61346"},"channel":"live_orders_btcusd","event":"order_created"}
{"data":{"id":1722048907010050,"id_str":"1722048907010050","order_type":1,"datetime":"1709257071","microtimestamp":"1709257071095000","amount":0.48889395,"amount_str":"0.48889395","amount_traded":"0","amount_at_create":"0.48889395","price":61363,"price_str":"61363"},"channel":"live_orders_btcusd","event":"order_created"}
{"data":{"id":1722048906903552,"id_str":"1722048906903552","order_type":1,"datetime":"1709257071","microtimestamp":"1709257071104000","amount":0.086,"amount_str":"0.08600000","amount_traded":"0","amount_at_create":"0.08600000","price":61361,"price_str":"61361"},"channel":"live_orders_btcusd","event":"order_deleted"}
{"data":{"id":1722048906821637,"id_str":"1722048906821637","order_type":1,"datetime":"1709257071","microtimestamp":"1709257071107000","amount":0.48889002,"amount_str":"0.48889002","amount_traded":"0","amount_at_create":"0.48889002","price":61364,"price_str":"61364"},"channel":"live_orders_btcusd","event":"order_deleted"}
{"data":{"id":1722048907005953,"id_str":"1722048907005953","order_type":0,"datetime":"1709257071","microtimestamp":"1709257071109000","amount":0.48902943,"amount_str":"0.48902943","amount_traded":"0","amount_at_create":"0.48902943","price":61346,"price_str":"61346"},"channel":"live_orders_btcusd","event":"order_deleted"}
{"data":{"id":1722048907198465,"id_str":"1722048907198465","order_type":1,"datetime":"1709257071","microtimestamp":"1709257071142000","amount":0.12188796,"amount_str":"0.12188796","amount_traded":"0","amount_at_create":"0.12188796","price":61417,"price_str":"61417"},"channel":"live_orders_btcusd","event":"order_created"}
{"data":{"id":1722048906833921,"id_str":"1722048906833921","order_type":0,"datetime":"1709257071","microtimestamp":"1709257071165000","amount":0.00040751,"amount_str":"0.00040751","amount_traded":"0","amount_at_create":"0.00040751","price":61340,"price_str":"61340"},"channel":"live_orders_btcusd","event":"order_deleted"}
{"data":{"id":1722048902696961,"id_str":"1722048902696961","order_type":1,"datetime":"1709257071","microtimestamp":"1709257071292000","amount":0.00487061,"amount_str":"0.00487061","amount_traded":"0","amount_at_create":"0.00487061","price":61364,"price_str":"61364"},"channel":"live_orders_btcusd","event":"order_deleted"}
{"data":{"id":1722048907812868,"id_str":"1722048907812868","order_type":0,"datetime":"1709257071","microtimestamp":"1709257071292000","amount":0.40749663,"amount_str":"0.40749663","amount_traded":"0","amount_at_create":"0.40749663","price":61140,"price_str":"61140"},"channel":"live_orders_btcusd","event":"order_created"}
{"data":{"id":1722048906817537,"id_str":"1722048906817537","order_type":1,"datetime":"1709257071","microtimestamp":"1709257071298000","amount":0.01629799,"amount_str":"0.01629799","amount_traded":"0","amount_at_create":"0.01629799","price":61358,"price_str":"61358"},"channel":"live_orders_btcusd","event":"order_deleted"}
{"data":{"id":1722048907812868,"id_str":"1722048907812868","order_type":0,"datetime":"1709257071","microtimestamp":"1709257071305000","amount":0.40749663,"amount_str":"0.40749663","amount_traded":"0","amount_at_create":"0.40749663","price":61140,"price_str":"61140"},"channel":"live_orders_btcusd","event":"order_deleted"}
{"data":{"id":1722048907927552,"id_str":"1722048907927552","order_type":1,"datetime":"1709257071","microtimestamp":"1709257071319000","amount":0.48892314,"amount_str":"0.48892314","amount_traded":"0","amount_at_create":"0.48892314","price":61360,"price_str":"61360"},"channel":"live_orders_btcusd","event":"order_created"}
{"data":{"id":1722048907931648,"id_str":"1722048907931648","order_type":0,"datetime":"1709257071","microtimestamp":"1709257071320000","amount":0.48901144,"amount_str":"0.48901144","amount_traded":"0","amount_at_create":"0.48901144","price":61348,"price_str":"61348"},"channel":"live_orders_btcusd","event":"order_created"}
{"data":{"id":1722048906235905,"id_str":"1722048906235905","order_type":0,"datetime":"1709257071","microtimestamp":"1709257071325000","amount":0.00814975,"amount_str":"0.00814975","amount_traded":"0","amount_at_create":"0.00814975","price":61345,"price_str":"61345"},"channel":"live_orders_btcusd","event":"order_deleted"}
{"data":{"id":1722048907927552,"id_str":"1722048907927552","order_type":1,"datetime":"1709257071","microtimestamp":"1709257071335000","amount":0.48892314,"amount_str":"0.48892314","amount_traded":"0","amount_at_create":"0.48892314","price":61360,"price_str":"61360"},"channel":"live_orders_btcusd","event":"order_deleted"}
{"data":{"id":1722048908013568,"id_str":"1722048908013568","order_type":0,"datetime":"1709257071","microtimestamp":"1709257071340000","amount":0.00040751,"amount_str":"0.00040751","amount_traded":"0","amount_at_create":"0.00040751","price":61341,"price_str":"61341"},"channel":"live_orders_btcusd","event":"order_created"}
{"data":{"id":1722048908029953,"id_str":"1722048908029953","order_type":0,"datetime":"1709257071","microtimestamp":"1709257071344000","amount":0.00814942,"amount_str":"0.00814942","amount_traded":"0","amount_at_create":"0.00814942","price":61349,"price_str":"61349"},"channel":"live_orders_btcusd","event":"order_created"}
{"data":{"id":1722048908103682,"id_str":"1722048908103682","order_type":1,"datetime":"1709257071","microtimestamp":"1709257071362000","amount":0.00487053,"amount_str":"0.00487053","amount_traded":"0","amount_at_create":"0.00487053","price":61366,"price_str":"61366"},"channel":"live_orders_btcusd","event":"order_created"}
{"data":{"id":1722048908013568,"id_str":"1722048908013568","order_type":0,"datetime":"1709257071","microtimestamp":"1709257071376000","amount":0.00040751,"amount_str":"0.00040751","amount_traded":"0","amount_at_create":"0.00040751","price":61341,"price_str":"61341"},"channel":"live_orders_btcusd","event":"order_deleted"}
{"data":{"id":1722048908169217,"id_str":"1722048908169217","order_type":1,"datetime":"1709257071","microtimestamp":"1709257071378000","amount":0.01629815,"amount_str":"0.01629815","amount_traded":"0","amount_at_create":"0.01629815","price":61357,"price_str":"61357"},"channel":"live_orders_btcusd","event":"order_created"}
{"data":{"id":1722048908169217,"id_str":"1722048908169217","order_type":1,"datetime":"1709257071","microtimestamp":"1709257071447000","amount":0.01629815,"amount_str":"0.01629815","amount_traded":"0","amount_at_create":"0.01629815","price":61357,"price_str":"61357"},"channel":"live_orders_btcusd","event":"order_deleted"}
{"data":{"id":1722048905199616,"id_str":"1722048905199616","order_type":0,"datetime":"1709257071","microtimestamp":"1709257071471000","amount":0.1875,"amount_str":"0.18750000","amount_traded":"0","amount_at_create":"0.18750000","price":61334,"price_str":"61334"},"channel":"live_orders_btcusd","event":"order_deleted"}
{"data":{"id":1722048908632064,"id_str":"1722048908632064","order_type":0,"datetime":"1709257071","microtimestamp":"1709257071491000","amount":0.00040751,"amount_str":"0.00040751","amount_traded":"0","amount_at_create":"0.00040751","price":61340,"price_str":"61340"},"channel":"live_orders_btcusd","event":"order_created"}
{"data":{"id":1722048908636161,"id_str":"1722048908636161","order_type":1,"datetime":"1709257071","microtimestamp":"1709257071492000","amount":0.01629835,"amount_str":"0.01629835","amount_traded":"0","amount_at_create":"0.01629835","price":61356,"price_str":"61356"},"channel":"live_orders_btcusd","event":"order_created"}
{"data":{"id":1722048906821634,"id_str":"1722048906821634","order_type":0,"datetime":"1709257072","microtimestamp":"1709257071501000","amount":0.01629977,"amount_str":"0.01629977","amount_traded":"0","amount_at_create":"0.01629977","price":61350,"price_str":"61350"},"channel":"live_orders_btcusd","event":"order_deleted"}
{"data":{"id":1722048907931648,"id_str":"1722048907931648","order_type":0,"datetime":"1709257072","microtimestamp":"1709257071501000","amount":0.48901144,"amount_str":"0.48901144","amount_traded":"0","amount_at_create":"0.48901144","price":61348,"price_str":"61348"},"channel":"live_orders_btcusd","event":"order_deleted"}
{"data":{"id":1722048907010050,"id_str":"1722048907010050","order_type":1,"datetime":"1709257072","microtimestamp":"1709257071501000","amount":0.48889395,"amount_str":"0.48889395","amount_traded":"0","amount_at_create":"0.48889395","price":61363,"price_str":"61363"},"channel":"live_orders_btcusd","event":"order_deleted"}
{"data":{"id":1722048908636161,"id_str":"1722048908636161","order_type":1,"datetime":"1709257072","microtimestamp":"1709257071508000","amount":0.01629835,"amount_str":"0.01629835","amount_traded":"0","amount_at_create":"0.01629835","price":61356,"price_str":"61356"},"channel":"live_orders_btcusd","event":"order_deleted"}
{"data":{"id":1722048908750848,"id_str":"1722048908750848","order_type":0,"datetime":"1709257072","microtimestamp":"1709257071520000","amount":0.1875,"amount_str":"0.18750000","amount_traded":"0","amount_at_create":"0.18750000","price":61336,"price_str":"61336"},"channel":"live_orders_btcusd","event":"order_created"}
{"data":{"id":1722048908886019,"id_str":"1722048908886019","order_type":1,"datetime":"1709257072","microtimestamp":"1709257071554000","amount":0.16262379,"amount_str":"0.16262379","amount_traded":"0","amount_at_create":"0.16262379","price":61492,"price_str":"61492"},"channel":"live_orders_btcusd","event":"order_created"}
{"data":{"id":1722048908894208,"id_str":"1722048908894208","order_type":1,"datetime":"1709257072","microtimestamp":"1709257071555000","amount":0.48891044,"amount_str":"0.48891044","amount_traded":"0","amount_at_create":"0.48891044","price":61361,"price_str":"61361"},"channel":"live_orders_btcusd","event":"order_created"}
{"data":{"id":1722048908894209,"id_str":"1722048908894209","order_type":0,"datetime":"1709257072","microtimestamp":"1709257071556000","amount":0.01630044,"amount_str":"0.01630044","amount_traded":"0","amount_at_create":"0.01630044","price":61348,"price_str":"61348"},"channel":"live_orders_btcusd","event":"order_created"}
{"data":{"id":1722048908898304,"id_str":"1722048908898304","order_type":0,"datetime":"1709257072","microtimestamp":"1709257071556000","amount":0.48903089,"amount_str":"0.48903089","amount_traded":"0","amount_at_create":"0.48903089","price":61345,"price_str":"61345"},"channel":"live_orders_btcusd","event":"order_created"}
{"data":{"id":1722048909070336,"id_str":"1722048909070336","order_type":1,"datetime":"1709257072","microtimestamp":"1709257071598000","amount":0.01629867,"amount_str":"0.01629867","amount_traded":"0","amount_at_create":"0.01629867","price":61355,"price_str":"61355"},"channel":"live_orders_btcusd","event":"order_created"}
{"data":{"id":1722048908898304,"id_str":"1722048908898304","order_type":0,"datetime":"1709257072","microtimestamp":"1709257071598000","amount":0.48903089,"amount_str":"0.48903089","amount_traded":"0","amount_at_create":"0.48903089","price":61345,"price_str":"61345"},"channel":"live_orders_btcusd","event":"order_deleted"}
{"data":{"id":1722048909070336,"id_str":"1722048909070336","order_type":1,"datetime":"1709257072","microtimestamp":"1709257071612000","amount":0.01629867,"amount_str":"0.01629867","amount_traded":"0","amount_at_create":"0.01629867","price":61355,"price_str":"61355"},"channel":"live_orders_btcusd","event":"order_deleted"}
{"data":{"id":1722048908894208,"id_str":"1722048908894208","order_type":1,"datetime":"1709257072","microtimestamp":"1709257071642000","amount":0.48891044,"amount_str":"0.48891044","amount_traded":"0","amount_at_create":"0.48891044","price":61361,"price_str":"61361"},"channel":"live_orders_btcusd","event":"order_deleted"}
{"data":{"id":1722048909271040,"id_str":"1722048909271040","order_type":1,"datetime":"1709257072","microtimestamp":"1709257071647000","amount":0.1875,"amount_str":"0.18750000","amount_traded":"0","amount_at_create":"0.18750000","price":61369,"price_str":"61369"},"channel":"live_orders_btcusd","event":"order_created"}
{"data":{"id":1722048909271040,"id_str":"1722048909271040","order_type":1,"datetime":"1709257072","microtimestamp":"1709257071663000","amount":0.1875,"amount_str":"0.18750000","amount_traded":"0","amount_at_create":"0.18750000","price":61369,"price_str":"61369"},"channel":"live_orders_btcusd","event":"order_deleted"}
{"data":{"id":1722048909422592,"id_str":"1722048909422592","order_type":1,"datetime":"1709257072","microtimestamp":"1709257071684000","amount":0.48891786,"amount_str":"0.48891786","amount_traded":"0","amount_at_create":"0.48891786","price":61360,"price_str":"61360"},"channel":"live_orders_btcusd","event":"order_created"}
{"data":{"id":1722048899567616,"id_str":"1722048899567616","order_type":0,"datetime":"1709257072","microtimestamp":"1709257071700000","amount":0.815832,"amount_str":"0.81583200","amount_traded":"0","amount_at_create":"0.81583200","price":61334,"price_str":"61334"},"channel":"live_orders_btcusd","event":"order_deleted"}
{"data":{"id":1722048895512576,"id_str":"1722048895512576","order_type":0,"datetime":"1709257072","microtimestamp":"1709257071700000","amount":1.445688,"amount_str":"1.44568800","amount_traded":"0","amount_at_create":"1.44568800","price":61315,"price_str":"61315"},"channel":"live_orders_btcusd","event":"order_deleted"}
{"data":{"id":1722048855920643,"id_str":"1722048855920643","order_type":1,"datetime":"1709257072","microtimestamp":"1709257071700000","amount":2.473578,"amount_str":"2.47357800","amount_traded":"0","amount_at_create":"2.47357800","price":61444,"price_str":"61444"},"channel":"live_orders_btcusd","event":"order_deleted"}
{"data":{"id":1722048855928833,"id_str":"1722048855928833","order_type":1,"datetime":"1709257072","microtimestamp":"1709257071701000","amount":1.940436,"amount_str":"1.94043600","amount_traded":"0","amount_at_create":"1.94043600","price":61413,"price_str":"61413"},"channel":"live_orders_btcusd","event":"order_deleted"}
{"data":{"id":1722048897855488,"id_str":"1722048897855488","order_type":0,"datetime":"1709257072","microtimestamp":"1709257071705000","amount":0.48912323,"amount_str":"0.48912323","amount_traded":"0","amount_at_create":"0.48912323","price":61334,"price_str":"61334"},"channel":"live_orders_btcusd","event":"order_deleted"}
{"data":{"id":1722048898920449,"id_str":"1722048898920449","order_type":0,"datetime":"1709257072","microtimestamp":"1709257071707000","amount":0.48905264,"amount_str":"0.48905264","amount_traded":"0","amount_at_create":"0.48905264","price":61343,"price_str":"61343"},"channel":"live_orders_btcusd","event":"order_deleted"}
{"data":{"id":1722048908894209,"id_str":"1722048908894209","order_type":0,"datetime":"1709257072","microtimestamp":"1709257071707000","amount":0.01630044,"amount_str":"0.01630044","amount_traded":"0","amount_at_create":"0.01630044","price":61348,"price_str":"61348"},"channel":"live_orders_btcusd","event":"order_deleted"}
{"data":{"id":1722048909606912,"id_str":"1722048909606912","order_type":1,"datetime":"1709257072","microtimestamp":"1709257071729000","amount":0.0162985,"amount_str":"0.01629850","amount_traded":"0","amount_at_create":"0.01629850","price":61356,"price_str":"61356"},"channel":"live_orders_btcusd","event":"order_created"}
{"data":{"id":1722048909606912,"id_str":"1722048909606912","order_type":1,"datetime":"1709257072","microtimestamp":"1709257071743000","amount":0.0162985,"amount_str":"0.01629850","amount_traded":"0","amount_at_create":"0.01629850","price":61356,"price_str":"61356"},"channel":"live_orders_btcusd","event":"order_deleted"}
{"data":{"id":1722048909676549,"id_str":"1722048909676549","order_type":1,"datetime":"1709257072","microtimestamp":"1709257071746000","amount":1.940436,"amount_str":"1.94043600","amount_traded":"0","amount_at_create":"1.94043600","price":61442,"price_str":"61442"},"channel":"live_orders_btcusd","event":"order_created"}
{"data":{"id":1722048909680643,"id_str":"1722048909680643","order_type":1,"datetime":"1709257072","microtimestamp":"1709257071747000","amount":2.473578,"amount_str":"2.47357800","amount_traded":"0","amount_at_create":"2.47357800","price":61474,"price_str":"61474"},"channel":"live_orders_btcusd","event":"order_created"}
{"data":{"id":1722048909680647,"id_str":"1722048909680647","order_type":0,"datetime":"1709257072","microtimestamp":"1709257071747000","amount":0.815832,"amount_str":"0.81583200","amount_traded":"0","amount_at_create":"0.81583200","price":61316,"price_str":"61316"},"channel":"live_orders_btcusd","event":"order_created"}
{"data":{"id":1722048909688833,"id_str":"1722048909688833","order_type":0,"datetime":"1709257072","microtimestamp":"1709257071749000","amount":1.445688,"amount_str":"1.44568800","amount_traded":"0","amount_at_create":"1.44568800","price":61290,"price_str":"61290"},"channel":"live_orders_btcusd","event":"order_created"}
{"data":{"id":1722048908029953,"id_str":"1722048908029953","order_type":0,"datetime":"1709257072","microtimestamp":"1709257071759000","amount":0.00814942,"amount_str":"0.00814942","amount_traded":"0","amount_at_create":"0.00814942","price":61349,"price_str":"61349"},"channel":"live_orders_btcusd","event":"order_deleted"}
{"data":{"id":1722048908632064,"id_str":"1722048908632064","order_type":0,"datetime":"1709257072","microtimestamp":"1709257071762000","amount":0.00040751,"amount_str":"0.00040751","amount_traded":"0","amount_at_create":"0.00040751","price":61340,"price_str":"61340"},"channel":"live_orders_btcusd","event":"order_deleted"}
{"data":{"id":1722048909815810,"id_str":"1722048909815810","order_type":1,"datetime":"1709257072","microtimestamp":"1709257071780000","amount":0.00487049,"amount_str":"0.00487049","amount_traded":"0","amount_at_create":"0.00487049","price":61363,"price_str":"61363"},"channel":"live_orders_btcusd","event":"order_created"}
{"data":{"id":1722048909852672,"id_str":"1722048909852672","order_type":0,"datetime":"1709257072","microtimestamp":"1709257071789000","amount":0.48909822,"amount_str":"0.48909822","amount_traded":"0","amount_at_create":"0.48909822","price":61337,"price_str":"61337"},"channel":"live_orders_btcusd","event":"order_created"}
{"data":{"id":1722048909864960,"id_str":"1722048909864960","order_type":0,"datetime":"1709257072","microtimestamp":"1709257071792000","amount":0.48900655,"amount_str":"0.48900655","amount_traded":"0","amount_at_create":"0.48900655","price":61348,"price_str":"61348"},"channel":"live_orders_btcusd","event":"order_created"}
{"data":{"id":1722048909869056,"id_str":"1722048909869056","order_type":0,"datetime":"1709257072","microtimestamp":"1709257071793000","amount":0.01629963,"amount_str":"0.01629963","amount_traded":"0","amount_at_create":"0.01629963","price":61351,"price_str":"61351"},"channel":"live_orders_btcusd","event":"order_created"}
{"data":{"id":1722048900395008,"id_str":"1722048900395008","order_type":0,"datetime":"1709257072","microtimestamp":"1709257071805000","amount":0.48922553,"amount_str":"0.48922553","amount_traded":"0","amount_at_create":"0.48922553","price":61321,"price_str":"61321"},"channel":"live_orders_btcusd","event":"order_deleted"}
{"data":{"id":1722048909422592,"id_str":"1722048909422592","order_type":1,"datetime":"1709257072","microtimestamp":"1709257071805000","amount":0.48891786,"amount_str":"0.48891786","amount_traded":"0","amount_at_create":"0.48891786","price":61360,"price_str":"61360"},"channel":"live_orders_btcusd","event":"order_deleted"}
{"data":{"id":1722048900763648,"id_str":"1722048900763648","order_type":1,"datetime":"1709257072","microtimestamp":"1709257071805000","amount":0.4887376,"amount_str":"0.48873760","amount_traded":"0","amount_at_create":"0.48873760","price":61383,"price_str":"61383"},"channel":"live_orders_btcusd","event":"order_deleted"}
{"data":{"id":1722048909869056,"id_str":"1722048909869056","order_type":0,"datetime":"1709257072","microtimestamp":"1709257071809000","amount":0.01629963,"amount_str":"0.01629963","amount_traded":"0","amount_at_create":"0.01629963","price":61351,"price_str":"61351"},"channel":"live_orders_btcusd","event":"order_deleted"}
{"data":{"id":1722048909864960,"id_str":"1722048909864960","order_type":0,"datetime":"1709257072","microtimestamp":"1709257071811000","amount":0.48900655,"amount_str":"0.48900655","amount_traded":"0","amount_at_create":"0.48900655","price":61348,"price_str":"61348"},"channel":"live_orders_btcusd","event":"order_deleted"}
{"data":{"id":1722048910057473,"id_str":"1722048910057473","order_type":0,"datetime":"1709257072","microtimestamp":"1709257071839000","amount":0.40749663,"amount_str":"0.40749663","amount_traded":"0","amount_at_create":"0.40749663","price":61140,"price_str":"61140"},"channel":"live_orders_btcusd","event":"order_created"}
{"data":{"id":1722048910057473,"id_str":"1722048910057473","order_type":0,"datetime":"1709257072","microtimestamp":"1709257071853000","amount":0.40749663,"amount_str":"0.40749663","amount_traded":"0","amount_at_create":"0.40749663","price":61140,"price_str":"61140"},"channel":"live_orders_btcusd","event":"order_deleted"}
{"data":{"id":1722048910118916,"id_str":"1722048910118916","order_type":1,"datetime":"1709257072","microtimestamp":"1709257071855000","amount":0.48869855,"amount_str":"0.48869855","amount_traded":"0","amount_at_create":"0.48869855","price":61388,"price_str":"61388"},"channel":"live_orders_btcusd","event":"order_created"}
{"data":{"id":1722048910135300,"id_str":"1722048910135300","order_type":1,"datetime":"1709257072","microtimestamp":"1709257071859000","amount":0.01629736,"amount_str":"0.01629736","amount_traded":"0","amount_at_create":"0.01629736","price":61360,"price_str":"61360"},"channel":"live_orders_btcusd","event":"order_created"}
{"data":{"id":1722048910180354,"id_str":"1722048910180354","order_type":0,"datetime":"1709257072","microtimestamp":"1709257071869000","amount":0.48919657,"amount_str":"0.48919657","amount_traded":"0","amount_at_create":"0.48919657","price":61325,"price_str":"61325"},"channel":"live_orders_btcusd","event":"order_created"}
{"data":{"id":1722048910237696,"id_str":"1722048910237696","order_type":0,"datetime":"1709257072","microtimestamp":"1709257071883000","amount":0.00040751,"amount_str":"0.00040751","amount_traded":"0","amount_at_create":"0.00040751","price":61341,"price_str":"61341"},"channel":"live_orders_btcusd","event":"order_created"}
{"data":{"id":1722048905998337,"id_str":"1722048905998337","order_type":1,"datetime":"1709257072","microtimestamp":"1709257071901000","amount":0.04374456,"amount_str":"0.04374456","amount_traded":"0","amount_at_create":"0.04374456","price":61374,"price_str":"61374"},"channel":"live_orders_btcusd","event":"order_deleted"}
{"data":{"id":1722048910364673,"id_str":"1722048910364673","order_type":1,"datetime":"1709257072","microtimestamp":"1709257071915000","amount":0.04374456,"amount_str":"0.04374456","amount_traded":"0","amount_at_create":"0.04374456","price":61375,"price_str":"61375"},"channel":"live_orders_btcusd","event":"order_created"}
{"data":{"id":1722048910376960,"id_str":"1722048910376960","order_type":0,"datetime":"1709257072","microtimestamp":"1709257071918000","amount":0.01629913,"amount_str":"0.01629913","amount_traded":"0","amount_at_create":"0.01629913","price":61352,"price_str":"61352"},"channel":"live_orders_btcusd","event":"order_created"}
{"data":{"id":1722048910381056,"id_str":"1722048910381056","order_type":1,"datetime":"1709257072","microtimestamp":"1709257071919000","amount":0.4889036,"amount_str":"0.48890360","amount_traded":"0","amount_at_create":"0.48890360","price":61362,"price_str":"61362"},"channel":"live_orders_btcusd","event":"order_created"}
{"data":{"id":1722048895684608,"id_str":"1722048895684608","order_type":1,"datetime":"1709257072","microtimestamp":"1709257071939000","amount":0.04875518,"amount_str":"0.04875518","amount_traded":"0","amount_at_create":"0.04875518","price":61395,"price_str":"61395"},"channel":"live_orders_btcusd","event":"order_deleted"}
{"data":{"id":1722048910684161,"id_str":"1722048910684161","order_type":1,"datetime":"1709257072","microtimestamp":"1709257071992000","amount":0.04875518,"amount_str":"0.04875518","amount_traded":"0","amount_at_create":"0.04875518","price":61387,"price_str":"61387"},"channel":"live_orders_btcusd","event":"order_created"}
{"data":{"id":1722048910733312,"id_str":"1722048910733312","order_type":0,"datetime":"1709257072","microtimestamp":"1709257072004000","amount":0.48901349,"amount_str":"0.48901349","amount_traded":"0","amount_at_create":"0.48901349","price":61348,"price_str":"61348"},"channel":"live_orders_btcusd","event":"order_created"}
{"data":{"id":1722048910237696,"id_str":"1722048910237696","order_type":0,"datetime":"1709257072","microtimestamp":"1709257072009000","amount":0.00040751,"amount_str":"0.00040751","amount_traded":"0","amount_at_create":"0.00040751","price":61341,"price_str":"61341"},"channel":"live_orders_btcusd","event":"order_deleted"}
{"data":{"id":1722048909815810,"id_str":"1722048909815810","order_type":1,"datetime":"1709257072","microtimestamp":"1709257072034000","amount":0.00487049,"amount_str":"0.00487049","amount_traded":"0","amount_at_create":"0.00487049","price":61363,"price_str":"61363"},"channel":"live_orders_btcusd","event":"order_deleted"}
{"data":{"id":1722048910733312,"id_str":"1722048910733312","order_type":0,"datetime":"1709257072","microtimestamp":"1709257072039000","amount":0.48901349,"amount_str":"0.48901349","amount_traded":"0","amount_at_create":"0.48901349","price":61348,"price_str":"61348"},"channel":"live_orders_btcusd","event":"order_deleted"}
{"data":{"id":1722048911052800,"id_str":"1722048911052800","order_type":1,"datetime":"1709257072","microtimestamp":"1709257072082000","amount":0.48888647,"amount_str":"0.48888647","amount_traded":"0","amount_at_create":"0.48888647","price":61364,"price_str":"61364"},"channel":"live_orders_btcusd","event":"order_created"}
{"data":{"id":1722048911073282,"id_str":"1722048911073282","order_type":0,"datetime":"1709257072","microtimestamp":"1709257072087000","amount":0.00814916,"amount_str":"0.00814916","amount_traded":"0","amount_at_create":"0.00814916","price":61349,"price_str":"61349"},"channel":"live_orders_btcusd","event":"order_created"}
{"data":{"id":1722048900386816,"id_str":"1722048900386816","order_type":1,"datetime":"1709257072","microtimestamp":"1709257072096000","amount":0.48884522,"amount_str":"0.48884522","amount_traded":"0","amount_at_create":"0.48884522","price":61370,"price_str":"61370"},"channel":"live_orders_btcusd","event":"order_deleted"}
{"data":{"id":1722048910376960,"id_str":"1722048910376960","order_type":0,"datetime":"1709257072","microtimestamp":"1709257072098000","amount":0.01629913,"amount_str":"0.01629913","amount_traded":"0","amount_at_create":"0.01629913","price":61352,"price_str":"61352"},"channel":"live_orders_btcusd","event":"order_deleted"}
{"data":{"id":1722048911052800,"id_str":"1722048911052800","order_type":1,"datetime":"1709257072","microtimestamp":"1709257072098000","amount":0.48888647,"amount_str":"0.48888647","amount_traded":"0","amount_at_create":"0.48888647","price":61364,"price_str":"61364"},"channel":"live_orders_btcusd","event":"order_deleted"}
{"data":{"id":1722048911257600,"id_str":"1722048911257600","order_type":0,"datetime":"1709257072","microtimestamp":"1709257072132000","amount":0.00040751,"amount_str":"0.00040751","amount_traded":"0","amount_at_create":"0.00040751","price":61340,"price_str":"61340"},"channel":"live_orders_btcusd","event":"order_created"}
{"data":{"id":1722048911298561,"id_str":"1722048911298561","order_type":1,"datetime":"1709257072","microtimestamp":"1709257072143000","amount":0.48881075,"amount_str":"0.48881075","amount_traded":"0","amount_at_create":"0.48881075","price":61374,"price_str":"61374"},"channel":"live_orders_btcusd","event":"order_created"}
{"data":{"id":1722048911306753,"id_str":"1722048911306753","order_type":0,"datetime":"1709257072","microtimestamp":"1709257072144000","amount":0.0162991,"amount_str":"0.01629910","amount_traded":"0","amount_at_create":"0.01629910","price":61353,"price_str":"61353"},"channel":"live_orders_btcusd","event":"order_created"}
{"data":{"id":1722048911650816,"id_str":"1722048911650816","order_type":0,"datetime":"1709257072","microtimestamp":"1709257072228000","amount":0.48899418,"amount_str":"0.48899418","amount_traded":"0","amount_at_create":"0.48899418","price":61350,"price_str":"61350"},"channel":"live_orders_btcusd","event":"order_created"}
{"data":{"id":1722048910364673,"id_str":"1722048910364673","order_type":1,"datetime":"1709257072","microtimestamp":"1709257072256000","amount":0.04374456,"amount_str":"0.04374456","amount_traded":"0","amount_at_create":"0.04374456","price":61375,"price_str":"61375"},"channel":"live_orders_btcusd","event":"order_deleted"}
{"data":{"id":1722048911831041,"id_str":"1722048911831041","order_type":1,"datetime":"1709257072","microtimestamp":"1709257072272000","amount":0.04374456,"amount_str":"0.04374456","amount_traded":"0","amount_at_create":"0.04374456","price":61374,"price_str":"61374"},"channel":"live_orders_btcusd","event":"order_created"}
{"data":{"id":1722048911917056,"id_str":"1722048911917056","order_type":0,"datetime":"1709257072","microtimestamp":"1709257072293000","amount":0.40749663,"amount_str":"0.40749663","amount_traded":"0","amount_at_create":"0.40749663","price":61141,"price_str":"61141"},"channel":"live_orders_btcusd","event":"order_created"}
{"data":{"id":1722048911917056,"id_str":"1722048911917056","order_type":0,"datetime":"1709257072","microtimestamp":"1709257072307000","amount":0.40749663,"amount_str":"0.40749663","amount_traded":"0","amount_at_create":"0.40749663","price":61141,"price_str":"61141"},"channel":"live_orders_btcusd","event":"order_deleted"}
{"data":{"id":1722048911257600,"id_str":"1722048911257600","order_type":0,"datetime":"1709257072","microtimestamp":"1709257072375000","amount":0.00040751,"amount_str":"0.00040751","amount_traded":"0","amount_at_create":"0.00040751","price":61340,"price_str":"61340"},"channel":"live_orders_btcusd","event":"order_deleted"}
{"data":{"id":1722048911650816,"id_str":"1722048911650816","order_type":0,"datetime":"1709257072","microtimestamp":"1709257072498000","amount":0.48899418,"amount_str":"0.48899418","amount_traded":"0","amount_at_create":"0.48899418","price":61350,"price_str":"61350"},"channel":"live_orders_btcusd","event":"order_deleted"}
{"data":{"id":1722048912867329,"id_str":"1722048912867329","order_type":0,"datetime":"1709257073","microtimestamp":"1709257072525000","amount":0.00040751,"amount_str":"0.00040751","amount_traded":"0","amount_at_create":"0.00040751","price":61341,"price_str":"61341"},"channel":"live_orders_btcusd","event":"order_created"}
{"data":{"id":1722048912945152,"id_str":"1722048912945152","order_type":0,"datetime":"1709257073","microtimestamp":"1709257072544000","amount":0.48898766,"amount_str":"0.48898766","amount_traded":"0","amount_at_create":"0.48898766","price":61351,"price_str":"61351"},"channel":"live_orders_btcusd","event":"order_created"}
{"data":{"id":1722048913121281,"id_str":"1722048913121281","order_type":0,"datetime":"1709257073","microtimestamp":"1709257072587000","amount":0.48955656,"amount_str":"0.48955656","amount_traded":"0","amount_at_create":"0.48955656","price":61279,"price_str":"61279"},"channel":"live_orders_btcusd","event":"order_created"}
{"data":{"id":1722048913129472,"id_str":"1722048913129472","order_type":1,"datetime":"1709257073","microtimestamp":"1709257072589000","amount":0.48838504,"amount_str":"0.48838504","amount_traded":"0","amount_at_create":"0.48838504","price":61427,"price_str":"61427"},"channel":"live_orders_btcusd","event":"order_created"}
{"data":{"id":1722048913133568,"id_str":"1722048913133568","order_type":1,"datetime":"1709257073","microtimestamp":"1709257072590000","amount":0.48887009,"amount_str":"0.48887009","amount_traded":"0","amount_at_create":"0.48887009","price":61366,"price_str":"61366"},"channel":"live_orders_btcusd","event":"order_created"}
{"data":{"id":1722048913207296,"id_str":"1722048913207296","order_type":1,"datetime":"1709257073","microtimestamp":"1709257072608000","amount":0.02035029,"amount_str":"0.02035029","amount_traded":"0","amount_at_create":"0.02035029","price":61376,"price_str":"61376"},"channel":"live_orders_btcusd","event":"order_created"}
{"data":{"id":1722048783650819,"id_str":"1722048783650819","order_type":0,"datetime":"1709257073","microtimestamp":"1709257072674000","amount":0.857,"amount_str":"0.85700000","amount_traded":"0","amount_at_create":"0.85700000","price":61313,"price_str":"61313"},"channel":"live_orders_btcusd","event":"order_deleted"}
{"data":{"id":1722048844066819,"id_str":"1722048844066819","order_type":1,"datetime":"1709257073","microtimestamp":"1709257072675000","amount":0.858,"amount_str":"0.85800000","amount_traded":"0","amount_at_create":"0.85800000","price":61380,"price_str":"61380"},"channel":"live_orders_btcusd","event":"order_deleted"}
{"data":{"id":1722048783855617,"id_str":"1722048783855617","order_type":1,"datetime":"1709257073","microtimestamp":"1709257072676000","amount":0.841,"amount_str":"0.84100000","amount_traded":"0","amount_at_create":"0.84100000","price":61396,"price_str":"61396"},"channel":"live_orders_btcusd","event":"order_deleted"}
{"data":{"id":1722048844161024,"id_str":"1722048844161024","order_type":0,"datetime":"1709257073","microtimestamp":"1709257072677000","amount":0.532,"amount_str":"0.53200000","amount_traded":"0","amount_at_create":"0.53200000","price":61297,"price_str":"61297"},"channel":"live_orders_btcusd","event":"order_deleted"}
{"data":{"id":1722048911306753,"id_str":"1722048911306753","order_type":0,"datetime":"1709257073","microtimestamp":"1709257072703000","amount":0.0162991,"amount_str":"0.01629910","amount_traded":"0","amount_at_create":"0.01629910","price":61353,"price_str":"61353"},"channel":"live_orders_btcusd","event":"order_deleted"}
{"data":{"id":1722048912945152,"id_str":"1722048912945152","order_type":0,"datetime":"1709257073","microtimestamp":"1709257072703000","amount":0.48898766,"amount_str":"0.48898766","amount_traded":"0","amount_at_create":"0.48898766","price":61351,"price_str":"61351"},"channel":"live_orders_btcusd","event":"order_deleted"}
{"data":{"id":1722048913133568,"id_str":"1722048913133568","order_type":1,"datetime":"1709257073","microtimestamp":"1709257072703000","amount":0.48887009,"amount_str":"0.48887009","amount_traded":"0","amount_at_create":"0.48887009","price":61366,"price_str":"61366"},"channel":"live_orders_btcusd","event":"order_deleted"}
{"data":{"id":1722048910135300,"id_str":"1722048910135300","order_type":1,"datetime":"1709257073","microtimestamp":"1709257072704000","amount":0.01629736,"amount_str":"0.01629736","amount_traded":"0","amount_at_create":"0.01629736","price":61360,"price_str":"61360"},"channel":"live_orders_btcusd","event":"order_deleted"}
{"data":{"id":1722048913600517,"id_str":"1722048913600517","order_type":1,"datetime":"1709257073","microtimestamp":"1709257072705000","amount":0.473,"amount_str":"0.47300000","amount_traded":"0","amount_at_create":"0.47300000","price":61387,"price_str":"61387"},"channel":"live_orders_btcusd","event":"order_created"}
{"data":{"id":1722048913604610,"id_str":"1722048913604610","order_type":0,"datetime":"1709257073","microtimestamp":"1709257072705000","amount":0.545,"amount_str":"0.54500000","amount_traded":"0","amount_at_create":"0.54500000","price":61320,"price_str":"61320"},"channel":"live_orders_btcusd","event":"order_created"}
{"data":{"id":1722048913612805,"id_str":"1722048913612805","order_type":0,"datetime":"1709257073","microtimestamp":"1709257072708000","amount":0.784,"amount_str":"0.78400000","amount_traded":"0","amount_at_create":"0.78400000","price":61304,"price_str":"61304"},"channel":"live_orders_btcusd","event":"order_created"}
{"data":{"id":1722048912867329,"id_str":"1722048912867329","order_type":0,"datetime":"1709257073","microtimestamp":"1709257072713000","amount":0.00040751,"amount_str":"0.00040751","amount_traded":"0","amount_at_create":"0.00040751","price":61341,"price_str":"61341"},"channel":"live_orders_btcusd","event":"order_deleted"}
{"data":{"id":1722048913788929,"id_str":"1722048913788929","order_type":1,"datetime":"1709257073","microtimestamp":"1709257072751000","amount":0.48892282,"amount_str":"0.48892282","amount_traded":"0","amount_at_create":"0.48892282","price":61360,"price_str":"61360"},"channel":"live_orders_btcusd","event":"order_created"}
{"data":{"id":1722048913793024,"id_str":"1722048913793024","order_type":1,"datetime":"1709257073","microtimestamp":"1709257072751000","amount":0.016298,"amount_str":"0.01629800","amount_traded":"0","amount_at_create":"0.01629800","price":61358,"price_str":"61358"},"channel":"live_orders_btcusd","event":"order_created"}
{"data":{"id":1722048913793025,"id_str":"1722048913793025","order_type":0,"datetime":"1709257073","microtimestamp":"1709257072751000","amount":0.40749663,"amount_str":"0.40749663","amount_traded":"0","amount_at_create":"0.40749663","price":61141,"price_str":"61141"},"channel":"live_orders_btcusd","event":"order_created"}
{"data":{"id":1722048913797121,"id_str":"1722048913797121","order_type":0,"datetime":"1709257073","microtimestamp":"1709257072752000","amount":0.01629973,"amount_str":"0.01629973","amount_traded":"0","amount_at_create":"0.01629973","price":61350,"price_str":"61350"},"channel":"live_orders_btcusd","event":"order_created"}
{"data":{"id":1722048913801218,"id_str":"1722048913801218","order_type":1,"datetime":"1709257073","microtimestamp":"1709257072753000","amount":0.563,"amount_str":"0.56300000","amount_traded":"0","amount_at_create":"0.56300000","price":61403,"price_str":"61403"},"channel":"live_orders_btcusd","event":"order_created"}
{"data":{"id":1722048913805314,"id_str":"1722048913805314","order_type":0,"datetime":"1709257073","microtimestamp":"1709257072754000","amount":0.48900963,"amount_str":"0.48900963","amount_traded":"0","amount_at_create":"0.48900963","price":61348,"price_str":"61348"},"channel":"live_orders_btcusd","event":"order_created"}
{"data":{"id":1722048913793025,"id_str":"1722048913793025","order_type":0,"datetime":"1709257073","microtimestamp":"1709257072765000","amount":0.40749663,"amount_str":"0.40749663","amount_traded":"0","amount_at_create":"0.40749663","price":61141,"price_str":"61141"},"channel":"live_orders_btcusd","event":"order_deleted"}
{"data":{"id":1722048913887234,"id_str":"1722048913887234","order_type":1,"datetime":"1709257073","microtimestamp":"1709257072774000","amount":0.038,"amount_str":"0.03800000","amount_traded":"0","amount_at_create":"0.03800000","price":61361,"price_str":"61361"},"channel":"live_orders_btcusd","event":"order_created"}
{"data":{"id":1722048893251587,"id_str":"1722048893251587","order_type":1,"datetime":"1709257073","microtimestamp":"1709257072790000","amount":0.1875,"amount_str":"0.18750000","amount_traded":"0","amount_at_create":"0.18750000","price":61429,"price_str":"61429"},"channel":"live_orders_btcusd","event":"order_deleted"}
{"data":{"id":1722048913887234,"id_str":"1722048913887234","order_type":1,"datetime":"1709257073","microtimestamp":"1709257072812000","amount":0.038,"amount_str":"0.03800000","amount_traded":"0","amount_at_create":"0.03800000","price":61361,"price_str":"61361"},"channel":"live_orders_btcusd","event":"order_deleted"}
{"data":{"id":1722048911298561,"id_str":"1722048911298561","order_type":1,"datetime":"1709257073","microtimestamp":"1709257072814000","amount":0.48881075,"amount_str":"0.48881075","amount_traded":"0","amount_at_create":"0.48881075","price":61374,"price_str":"61374"},"channel":"live_orders_btcusd","event":"order_deleted"}
{"data":{"id":1722048913793024,"id_str":"1722048913793024","order_type":1,"datetime":"1709257073","microtimestamp":"1709257072814000","amount":0.016298,"amount_str":"0.01629800","amount_traded":"0","amount_at_create":"0.01629800","price":61358,"price_str":"61358"},"channel":"live_orders_btcusd","event":"order_deleted"}
{"data":{"id":1722048910180354,"id_str":"1722048910180354","order_type":0,"datetime":"1709257073","microtimestamp":"1709257072814000","amount":0.48919657,"amount_str":"0.48919657","amount_traded":"0","amount_at_create":"0.48919657","price":61325,"price_str":"61325"},"channel":"live_orders_btcusd","event":"order_deleted"}
{"data":{"id":1722048910118916,"id_str":"1722048910118916","order_type":1,"datetime":"1709257073","microtimestamp":"1709257072815000","amount":0.48869855,"amount_str":"0.48869855","amount_traded":"0","amount_at_create":"0.48869855","price":61388,"price_str":"61388"},"channel":"live_orders_btcusd","event":"order_deleted"}
{"data":{"id":1722048913788929,"id_str":"1722048913788929","order_type":1,"datetime":"1709257073","microtimestamp":"1709257072815000","amount":0.48892282,"amount_str":"0.48892282","amount_traded":"0","amount_at_create":"0.48892282","price":61360,"price_str":"61360"},"channel":"live_orders_btcusd","event":"order_deleted"}
{"data":{"id":1722048913805314,"id_str":"1722048913805314","order_type":0,"datetime":"1709257073","microtimestamp":"1709257072815000","amount":0.48900963,"amount_str":"0.48900963","amount_traded":"0","amount_at_create":"0.48900963","price":61348,"price_str":"61348"},"channel":"live_orders_btcusd","event":"order_deleted"}
{"data":{"id":1722048914153473,"id_str":"1722048914153473","order_type":1,"datetime":"1709257073","microtimestamp":"1709257072839000","amount":0.1875,"amount_str":"0.18750000","amount_traded":"0","amount_at_create":"0.18750000","price":61701,"price_str":"61701"},"channel":"live_orders_btcusd","event":"order_created"}
{"data":{"id":1722048913797121,"id_str":"1722048913797121","order_type":0,"datetime":"1709257073","microtimestamp":"1709257072843000","amount":0.01629973,"amount_str":"0.01629973","amount_traded":"0","amount_at_create":"0.01629973","price":61350,"price_str":"61350"},"channel":"live_orders_btcusd","event":"order_deleted"}
{"data":{"id":1722048908750848,"id_str":"1722048908750848","order_type":0,"datetime":"1709257073","microtimestamp":"1709257072849000","amount":0.1875,"amount_str":"0.18750000","amount_traded":"0","amount_at_create":"0.18750000","price":61336,"price_str":"61336"},"channel":"live_orders_btcusd","event":"order_deleted"}
{"data":{"id":1722048914243585,"id_str":"1722048914243585","order_type":0,"datetime":"1709257073","microtimestamp":"1709257072861000","amount":0.48905352,"amount_str":"0.48905352","amount_traded":"0","amount_at_create":"0.48905352","price":61342,"price_str":"61342"},"channel":"live_orders_btcusd","event":"order_created"}
{"data":{"id":1722048914268161,"id_str":"1722048914268161","order_type":1,"datetime":"1709257073","microtimestamp":"1709257072867000","amount":0.01629839,"amount_str":"0.01629839","amount_traded":"0","amount_at_create":"0.01629839","price":61356,"price_str":"61356"},"channel":"live_orders_btcusd","event":"order_created"}
{"data":{"id":1722048914305027,"id_str":"1722048914305027","order_type":1,"datetime":"1709257073","microtimestamp":"1709257072876000","amount":0.1875,"amount_str":"0.18750000","amount_traded":"0","amount_at_create":"0.18750000","price":61369,"price_str":"61369"},"channel":"live_orders_btcusd","event":"order_created"}
{"data":{"id":1722048914268161,"id_str":"1722048914268161","order_type":1,"datetime":"1709257073","microtimestamp":"1709257072898000","amount":0.01629839,"amount_str":"0.01629839","amount_traded":"0","amount_at_create":"0.01629839","price":61356,"price_str":"61356"},"channel":"live_orders_btcusd","event":"order_deleted"}
{"data":{"id":1722048914448384,"id_str":"1722048914448384","order_type":0,"datetime":"1709257073","microtimestamp":"1709257072911000","amount":0.1875,"amount_str":"0.18750000","amount_traded":"0","amount_at_create":"0.18750000","price":61272,"price_str":"61272"},"channel":"live_orders_btcusd","event":"order_created"}
{"data":{"id":1722048914456577,"id_str":"1722048914456577","order_type":0,"datetime":"1709257073","microtimestamp":"1709257072913000","amount":0.01630023,"amount_str":"0.01630023","amount_traded":"0","amount_at_create":"0.01630023","price":61348,"price_str":"61348"},"channel":"live_orders_btcusd","event":"order_created"}
{"data":{"id":1722048914477057,"id_str":"1722048914477057","order_type":0,"datetime":"1709257073","microtimestamp":"1709257072918000","amount":0.1875,"amount_str":"0.18750000","amount_traded":"0","amount_at_create":"0.18750000","price":61335,"price_str":"61335"},"channel":"live_orders_btcusd","event":"order_created"}
{"data":{"id":1722048914501633,"id_str":"1722048914501633","order_type":0,"datetime":"1709257073","microtimestamp":"1709257072924000","amount":0.00040751,"amount_str":"0.00040751","amount_traded":"0","amount_at_create":"0.00040751","price":61340,"price_str":"61340"},"channel":"live_orders_btcusd","event":"order_created"}
{"data":{"id":1722048914477057,"id_str":"1722048914477057","order_type":0,"datetime":"1709257073","microtimestamp":"1709257072933000","amount":0.1875,"amount_str":"0.18750000","amount_traded":"0","amount_at_create":"0.18750000","price":61335,"price_str":"61335"},"channel":"live_orders_btcusd","event":"order_deleted"}
{"data":{"id":1722048901742593,"id_str":"1722048901742593","order_type":0,"datetime":"1709257073","microtimestamp":"1709257072945000","amount":0.4893128,"amount_str":"0.48931280","amount_traded":"0","amount_at_create":"0.48931280","price":61310,"price_str":"61310"},"channel":"live_orders_btcusd","event":"order_deleted"}
{"data":{"id":1722048904933378,"id_str":"1722048904933378","order_type":1,"datetime":"1709257073","microtimestamp":"1709257072945000","amount":0.4885961,"amount_str":"0.48859610","amount_traded":"0","amount_at_create":"0.48859610","price":61401,"price_str":"61401"},"channel":"live_orders_btcusd","event":"order_deleted"}
{"data":{"id":1722048914456577,"id_str":"1722048914456577","order_type":0,"datetime":"1709257073","microtimestamp":"1709257072946000","amount":0.01630023,"amount_str":"0.01630023","amount_traded":"0","amount_at_create":"0.01630023","price":61348,"price_str":"61348"},"channel":"live_orders_btcusd","event":"order_deleted"}
{"data":{"id":1722048913129472,"id_str":"1722048913129472","order_type":1,"datetime":"1709257073","microtimestamp":"1709257072947000","amount":0.48838504,"amount_str":"0.48838504","amount_traded":"0","amount_at_create":"0.48838504","price":61427,"price_str":"61427"},"channel":"live_orders_btcusd","event":"order_deleted"}
{"data":{"id":1722048914632707,"id_str":"1722048914632707","order_type":0,"datetime":"1709257073","microtimestamp":"1709257072956000","amount":0.48902274,"amount_str":"0.48902274","amount_traded":"0","amount_at_create":"0.48902274","price":61346,"price_str":"61346"},"channel":"live_orders_btcusd","event":"order_created"}
{"data":{"id":1722048914640897,"id_str":"1722048914640897","order_type":1,"datetime":"1709257073","microtimestamp":"1709257072958000","amount":0.48894176,"amount_str":"0.48894176","amount_traded":"0","amount_at_create":"0.48894176","price":61357,"price_str":"61357"},"channel":"live_orders_btcusd","event":"order_created"}
{"data":{"id":1722048892289025,"id_str":"1722048892289025","order_type":1,"datetime":"1709257073","microtimestamp":"1709257072964000","amount":1,"amount_str":"1.00000000","amount_traded":"0","amount_at_create":"1.00000000","price":61504,"price_str":"61504"},"channel":"live_orders_btcusd","event":"order_deleted"}
{"data":{"id":1722048892391425,"id_str":"1722048892391425","order_type":1,"datetime":"1709257073","microtimestamp":"1709257072965000","amount":2,"amount_str":"2.00000000","amount_traded":"0","amount_at_create":"2.00000000","price":61535,"price_str":"61535"},"channel":"live_orders_btcusd","event":"order_deleted"}
{"data":{"id":1722048892338177,"id_str":"1722048892338177","order_type":1,"datetime":"1709257073","microtimestamp":"1709257072965000","amount":0.5,"amount_str":"0.50000000","amount_traded":"0","amount_at_create":"0.50000000","price":61535,"price_str":"61535"},"channel":"live_orders_btcusd","event":"order_deleted"}
{"data":{"id":1722048787623939,"id_str":"1722048787623939","order_type":1,"datetime":"1709257073","microtimestamp":"1709257072965000","amount":0.5,"amount_str":"0.50000000","amount_traded":"0","amount_at_create":"0.50000000","price":61442,"price_str":"61442"},"channel":"live_orders_btcusd","event":"order_deleted"}
{"data":{"id":1722048914632707,"id_str":"1722048914632707","order_type":0,"datetime":"1709257073","microtimestamp":"1709257072972000","amount":0.48902274,"amount_str":"0.48902274","amount_traded":"0","amount_at_create":"0.48902274","price":61346,"price_str":"61346"},"channel":"live_orders_btcusd","event":"order_deleted"}
{"data":{"id":1722048911073282,"id_str":"1722048911073282","order_type":0,"datetime":"1709257073","microtimestamp":"1709257072972000","amount":0.00814916,"amount_str":"0.00814916","amount_traded":"0","amount_at_create":"0.00814916","price":61349,"price_str":"61349"},"channel":"live_orders_btcusd","event":"order_deleted"}
{"data":{"id":1722048913207296,"id_str":"1722048913207296","order_type":1,"datetime":"1709257073","microtimestamp":"1709257072973000","amount":0.02035029,"amount_str":"0.02035029","amount_traded":"0","amount_at_create":"0.02035029","price":61376,"price_str":"61376"},"channel":"live_orders_btcusd","event":"order_deleted"}
{"data":{"id":1722048892428293,"id_str":"1722048892428293","order_type":1,"datetime":"1709257073","microtimestamp":"1709257072983000","amount":0.06327759,"amount_str":"0.06327759","amount_traded":"0","amount_at_create":"0.06327759","price":61535,"price_str":"61535"},"channel":"live_orders_btcusd","event":"order_deleted"}
{"data":{"id":1722048914767876,"id_str":"1722048914767876","order_type":1,"datetime":"1709257073","microtimestamp":"1709257072989000","amount":0.00487065,"amount_str":"0.00487065","amount_traded":"0","amount_at_create":"0.00487065","price":61363,"price_str":"61363"},"channel":"live_orders_btcusd","event":"order_created"}
{"data":{"id":1722048914153473,"id_str":"1722048914153473","order_type":1,"datetime":"1709257073","microtimestamp":"1709257072990000","amount":0.1875,"amount_str":"0.18750000","amount_traded":"0","amount_at_create":"0.18750000","price":61701,"price_str":"61701"},"channel":"live_orders_btcusd","event":"order_deleted"}
{"data":{"id":1722048914784260,"id_str":"1722048914784260","order_type":1,"datetime":"1709257073","microtimestamp":"1709257072993000","amount":0.5,"amount_str":"0.50000000","amount_traded":"0","amount_at_create":"0.50000000","price":61411,"price_str":"61411"},"channel":"live_orders_btcusd","event":"order_created"}
{"data":{"id":1722048895692803,"id_str":"1722048895692803","order_type":0,"datetime":"1709257073","microtimestamp":"1709257072994000","amount":0.04875518,"amount_str":"0.04875518","amount_traded":"0","amount_at_create":"0.04875518","price":61331,"price_str":"61331"},"channel":"live_orders_btcusd","event":"order_deleted"}
{"data":{"id":1722048910381056,"id_str":"1722048910381056","order_type":1,"datetime":"1709257073","microtimestamp":"1709257072998000","amount":0.4889036,"amount_str":"0.48890360","amount_traded":"0","amount_at_create":"0.48890360","price":61362,"price_str":"61362"},"channel":"live_orders_btcusd","event":"order_deleted"}
{"data":{"id":1722048914837505,"id_str":"1722048914837505","order_type":1,"datetime":"1709257073","microtimestamp":"1709257073006000","amount":0.5,"amount_str":"0.50000000","amount_traded":"0","amount_at_create":"0.50000000","price":61411,"price_str":"61411"},"channel":"live_orders_btcusd","event":"order_created"}
{"data":{"id":1722048914870273,"id_str":"1722048914870273","order_type":1,"datetime":"1709257073","microtimestamp":"1709257073014000","amount":2,"amount_str":"2.00000000","amount_traded":"0","amount_at_create":"2.00000000","price":61504,"price_str":"61504"},"channel":"live_orders_btcusd","event":"order_created"}
{"data":{"id":1722048914870275,"id_str":"1722048914870275","order_type":1,"datetime":"1709257073","microtimestamp":"1709257073015000","amount":1,"amount_str":"1.00000000","amount_traded":"0","amount_at_create":"1.00000000","price":61442,"price_str":"61442"},"channel":"live_orders_btcusd","event":"order_created"}
{"data":{"id":1722048914874368,"id_str":"1722048914874368","order_type":1,"datetime":"1709257073","microtimestamp":"1709257073015000","amount":0.1875,"amount_str":"0.18750000","amount_traded":"0","amount_at_create":"0.18750000","price":61361,"price_str":"61361"},"channel":"live_orders_btcusd","event":"order_created"}
{"data":{"id":1722048897712128,"id_str":"1722048897712128","order_type":0,"datetime":"1709257073","microtimestamp":"1709257073018000","amount":0.04893,"amount_str":"0.04893000","amount_traded":"0","amount_at_create":"0.04893000","price":61329,"price_str":"61329"},"channel":"live_orders_btcusd","event":"order_deleted"}
{"data":{"id":1722048914886658,"id_str":"1722048914886658","order_type":1,"datetime":"1709257073","microtimestamp":"1709257073018000","amount":0.01629959,"amount_str":"0.01629959","amount_traded":"0","amount_at_create":"0.01629959","price":61352,"price_str":"61352"},"channel":"live_orders_btcusd","event":"order_created"}
{"data":{"id":1722048914886661,"id_str":"1722048914886661","order_type":0,"datetime":"1709257073","microtimestamp":"1709257073019000","amount":0.01630141,"amount_str":"0.01630141","amount_traded":"0","amount_at_create":"0.01630141","price":61344,"price_str":"61344"},"channel":"live_orders_btcusd","event":"order_created"}
{"data":{"id":1722048914886662,"id_str":"1722048914886662","order_type":0,"datetime":"1709257073","microtimestamp":"1709257073019000","amount":0.4891516,"amount_str":"0.48915160","amount_traded":"0","amount_at_create":"0.48915160","price":61330,"price_str":"61330"},"channel":"live_orders_btcusd","event":"order_created"}
{"data":{"id":1722048911831041,"id_str":"1722048911831041","order_type":1,"datetime":"1709257073","microtimestamp":"1709257073021000","amount":0.04374456,"amount_str":"0.04374456","amount_traded":"0","amount_at_create":"0.04374456","price":61374,"price_str":"61374"},"channel":"live_orders_btcusd","event":"order_deleted"}
{"data":{"id":1722048914898950,"id_str":"1722048914898950","order_type":0,"datetime":"1709257073","microtimestamp":"1709257073022000","amount":0.48937347,"amount_str":"0.48937347","amount_traded":"0","amount_at_create":"0.48937347","price":61302,"price_str":"61302"},"channel":"live_orders_btcusd","event":"order_created"}
{"data":{"id":1722048914956292,"id_str":"1722048914956292","order_type":1,"datetime":"1709257073","microtimestamp":"1709257073036000","amount":0.04374456,"amount_str":"0.04374456","amount_traded":"0","amount_at_create":"0.04374456","price":61369,"price_str":"61369"},"channel":"live_orders_btcusd","event":"order_created"}
{"data":{"id":1722048914886661,"id_str":"1722048914886661","order_type":0,"datetime":"1709257073","microtimestamp":"1709257073037000","amount":0.01630141,"amount_str":"0.01630141","amount_traded":"0","amount_at_create":"0.01630141","price":61344,"price_str":"61344"},"channel":"live_orders_btcusd","event":"order_deleted"}
{"data":{"id":1722048914886658,"id_str":"1722048914886658","order_type":1,"datetime":"1709257073","microtimestamp":"1709257073037000","amount":0.01629959,"amount_str":"0.01629959","amount_traded":"0","amount_at_create":"0.01629959","price":61352,"price_str":"61352"},"channel":"live_orders_btcusd","event":"order_deleted"}
{"data":{"id":1722048906817536,"id_str":"1722048906817536","order_type":0,"datetime":"1709257073","microtimestamp":"1709257073040000","amount":0.00814929,"amount_str":"0.00814929","amount_traded":"0","amount_at_create":"0.00814929","price":61347,"price_str":"61347"},"channel":"live_orders_btcusd","event":"order_deleted"}
{"data":{"id":1722048892395523,"id_str":"1722048892395523","order_type":1,"datetime":"1709257073","microtimestamp":"1709257073065000","amount":0.5,"amount_str":"0.50000000","amount_traded":"0","amount_at_create":"0.50000000","price":61400,"price_str":"61400"},"channel":"live_orders_btcusd","event":"order_deleted"}
{"data":{"id":1722048915034112,"id_str":"1722048915034112","order_type":0,"datetime":"1709257073","microtimestamp":"1709257073065000","amount":0.04875518,"amount_str":"0.04875518","amount_traded":"0","amount_at_create":"0.04875518","price":61324,"price_str":"61324"},"channel":"live_orders_btcusd","event":"order_created"}
{"data":{"id":1722048914874368,"id_str":"1722048914874368","order_type":1,"datetime":"1709257073","microtimestamp":"1709257073065000","amount":0.1875,"amount_str":"0.18750000","amount_traded":"0","amount_at_create":"0.18750000","price":61361,"price_str":"61361"},"channel":"live_orders_btcusd","event":"order_deleted"}
{"data":{"id":1722048915152897,"id_str":"1722048915152897","order_type":0,"datetime":"1709257073","microtimestamp":"1709257073083000","amount":0.00814969,"amount_str":"0.00814969","amount_traded":"0","amount_at_create":"0.00814969","price":61345,"price_str":"61345"},"channel":"live_orders_btcusd","event":"order_created"}
{"data":{"id":1722048915152898,"id_str":"1722048915152898","order_type":1,"datetime":"1709257073","microtimestamp":"1709257073083000","amount":0.5,"amount_str":"0.50000000","amount_traded":"0","amount_at_create":"0.50000000","price":61389,"price_str":"61389"},"channel":"live_orders_btcusd","event":"order_created"}
{"data":{"id":1722048915169280,"id_str":"1722048915169280","order_type":1,"datetime":"1709257073","microtimestamp":"1709257073087000","amount":0.02099532,"amount_str":"0.02099532","amount_traded":"0","amount_at_create":"0.02099532","price":61373,"price_str":"61373"},"channel":"live_orders_btcusd","event":"order_created"}
{"data":{"id":1722048914956292,"id_str":"1722048914956292","order_type":1,"datetime":"1709257073","microtimestamp":"1709257073091000","amount":0.04374456,"amount_str":"0.04374456","amount_traded":"0","amount_at_create":"0.04374456","price":61369,"price_str":"61369"},"channel":"live_orders_btcusd","event":"order_deleted"}
{"data":{"id":1722048908103682,"id_str":"1722048908103682","order_type":1,"datetime":"1709257073","microtimestamp":"1709257073093000","amount":0.00487053,"amount_str":"0.00487053","amount_traded":"0","amount_at_create":"0.00487053","price":61366,"price_str":"61366"},"channel":"live_orders_btcusd","event":"order_deleted"}
{"data":{"id":1722048900984832,"id_str":"1722048900984832","order_type":0,"datetime":"1709257073","microtimestamp":"1709257073095000","amount":3.06659845,"amount_str":"3.06659845","amount_traded":"0","amount_at_create":"3.06659845","price":61339,"price_str":"61339"},"channel":"live_orders_btcusd","event":"order_deleted"}
{"data":{"id":1722048914243585,"id_str":"1722048914243585","order_type":0,"datetime":"1709257073","microtimestamp":"1709257073098000","amount":0.48905352,"amount_str":"0.48905352","amount_traded":"0","amount_at_create":"0.48905352","price":61342,"price_str":"61342"},"channel":"live_orders_btcusd","event":"order_deleted"}
{"data":{"id":1722048914640897,"id_str":"1722048914640897","order_type":1,"datetime":"1709257073","microtimestamp":"1709257073098000","amount":0.48894176,"amount_str":"0.48894176","amount_traded":"0","amount_at_create":"0.48894176","price":61357,"price_str":"61357"},"channel":"live_orders_btcusd","event":"order_deleted"}
{"data":{"id":1722048915234818,"id_str":"1722048915234818","order_type":0,"datetime":"1709257073","microtimestamp":"1709257073104000","amount":0.04893,"amount_str":"0.04893000","amount_traded":"0","amount_at_create":"0.04893000","price":61325,"price_str":"61325"},"channel":"live_orders_btcusd","event":"order_created"}
{"data":{"id":1722048915169280,"id_str":"1722048915169280","order_type":1,"datetime":"1709257073","microtimestamp":"1709257073105000","amount":0.02099532,"amount_str":"0.02099532","amount_traded":"0","amount_at_create":"0.02099532","price":61373,"price_str":"61373"},"channel":"live_orders_btcusd","event":"order_deleted"}
{"data":{"id":1722048909852672,"id_str":"1722048909852672","order_type":0,"datetime":"1709257073","microtimestamp":"1709257073106000","amount":0.48909822,"amount_str":"0.48909822","amount_traded":"0","amount_at_create":"0.48909822","price":61337,"price_str":"61337"},"channel":"live_orders_btcusd","event":"order_deleted"}
{"data":{"id":1722048915247108,"id_str":"1722048915247108","order_type":1,"datetime":"1709257073","microtimestamp":"1709257073106000","amount":0.04374456,"amount_str":"0.04374456","amount_traded":"0","amount_at_create":"0.04374456","price":61366,"price_str":"61366"},"channel":"live_orders_btcusd","event":"order_created"}
{"data":{"id":1722048915251203,"id_str":"1722048915251203","order_type":1,"datetime":"1709257073","microtimestamp":"1709257073107000","amount":0.06199507,"amount_str":"0.06199507","amount_traded":"0","amount_at_create":"0.06199507","price":61528,"price_str":"61528"},"channel":"live_orders_btcusd","event":"order_created"}
{"data":{"id":1722048915263488,"id_str":"1722048915263488","order_type":1,"datetime":"1709257073","microtimestamp":"1709257073110000","amount":0.00487069,"amount_str":"0.00487069","amount_traded":"0","amount_at_create":"0.00487069","price":61361,"price_str":"61361"},"channel":"live_orders_btcusd","event":"order_created"}
{"data":{"id":1722048915283968,"id_str":"1722048915283968","order_type":0,"datetime":"1709257073","microtimestamp":"1709257073115000","amount":0.041,"amount_str":"0.04100000","amount_traded":"0","amount_at_create":"0.04100000","price":61343,"price_str":"61343"},"channel":"live_orders_btcusd","event":"order_created"}
{"data":{"id":1722048898150400,"id_str":"1722048898150400","order_type":0,"datetime":"1709257073","microtimestamp":"1709257073117000","amount":0.16298988,"amount_str":"0.16298988","amount_traded":"0","amount_at_create":"0.16298988","price":61330,"price_str":"61330"},"channel":"live_orders_btcusd","event":"order_deleted"}
{"data":{"id":1722048908886019,"id_str":"1722048908886019","order_type":1,"datetime":"1709257073","microtimestamp":"1709257073120000","amount":0.16262379,"amount_str":"0.16262379","amount_traded":"0","amount_at_create":"0.16262379","price":61492,"price_str":"61492"},"channel":"live_orders_btcusd","event":"order_deleted"}
{"data":{"id":1722048913121281,"id_str":"1722048913121281","order_type":0,"datetime":"1709257073","microtimestamp":"1709257073121000","amount":0.48955656,"amount_str":"0.48955656","amount_traded":"0","amount_at_create":"0.48955656","price":61279,"price_str":"61279"},"channel":"live_orders_btcusd","event":"order_deleted"}
{"data":{"id":1722048914886662,"id_str":"1722048914886662","order_type":0,"datetime":"1709257073","microtimestamp":"1709257073121000","amount":0.4891516,"amount_str":"0.48915160","amount_traded":"0","amount_at_create":"0.48915160","price":61330,"price_str":"61330"},"channel":"live_orders_btcusd","event":"order_deleted"}
{"data":{"id":1722048914767876,"id_str":"1722048914767876","order_type":1,"datetime":"1709257073","microtimestamp":"1709257073124000","amount":0.00487065,"amount_str":"0.00487065","amount_traded":"0","amount_at_create":"0.00487065","price":61363,"price_str":"61363"},"channel":"live_orders_btcusd","event":"order_deleted"}
{"data":{"id":1722048915394563,"id_str":"1722048915394563","order_type":1,"datetime":"1709257073","microtimestamp":"1709257073142000","amount":0.00487069,"amount_str":"0.00487069","amount_traded":"0","amount_at_create":"0.00487069","price":61359,"price_str":"61359"},"channel":"live_orders_btcusd","event":"order_created"}
{"data":{"id":1722048915283968,"id_str":"1722048915283968","order_type":0,"datetime":"1709257073","microtimestamp":"1709257073143000","amount":0.041,"amount_str":"0.04100000","amount_traded":"0","amount_at_create":"0.04100000","price":61343,"price_str":"61343"},"channel":"live_orders_btcusd","event":"order_deleted"}
{"data":{"id":1722048895078400,"id_str":"1722048895078400","order_type":1,"datetime":"1709257073","microtimestamp":"1709257073143000","amount":0.93106524,"amount_str":"0.93106524","amount_traded":"0","amount_at_create":"0.93106524","price":61404,"price_str":"61404"},"channel":"live_orders_btcusd","event":"order_deleted"}
{"data":{"id":1722048915406849,"id_str":"1722048915406849","order_type":0,"datetime":"1709257073","microtimestamp":"1709257073145000","amount":3.06674844,"amount_str":"3.06674844","amount_traded":"0","amount_at_create":"3.06674844","price":61336,"price_str":"61336"},"channel":"live_orders_btcusd","event":"order_created"}
{"data":{"id":1722048915406849,"id_str":"1722048915406849","order_type":0,"datetime":"1709257073","microtimestamp":"1709257073150000","amount":3.06674844,"amount_str":"3.06674844","amount_traded":"0","amount_at_create":"3.06674844","price":61336,"price_str":"61336"},"channel":"live_orders_btcusd","event":"order_deleted"}
{"data":{"id":1722048915472389,"id_str":"1722048915472389","order_type":0,"datetime":"1709257073","microtimestamp":"1709257073161000","amount":0.00814969,"amount_str":"0.00814969","amount_traded":"0","amount_at_create":"0.00814969","price":61343,"price_str":"61343"},"channel":"live_orders_btcusd","event":"order_created"}
{"data":{"id":1722048915034112,"id_str":"1722048915034112","order_type":0,"datetime":"1709257073","microtimestamp":"1709257073164000","amount":0.04875518,"amount_str":"0.04875518","amount_traded":"0","amount_at_create":"0.04875518","price":61324,"price_str":"61324"},"channel":"live_orders_btcusd","event":"order_deleted"}
{"data":{"id":1722048915484674,"id_str":"1722048915484674","order_type":1,"datetime":"1709257073","microtimestamp":"1709257073164000","amount":0.1875,"amount_str":"0.18750000","amount_traded":"0","amount_at_create":"0.18750000","price":61360,"price_str":"61360"},"channel":"live_orders_btcusd","event":"order_created"}
{"data":{"id":1722048915492867,"id_str":"1722048915492867","order_type":1,"datetime":"1709257073","microtimestamp":"1709257073166000","amount":0.48894973,"amount_str":"0.48894973","amount_traded":"0","amount_at_create":"0.48894973","price":61356,"price_str":"61356"},"channel":"live_orders_btcusd","event":"order_created"}
{"data":{"id":1722048915492868,"id_str":"1722048915492868","order_type":1,"datetime":"1709257073","microtimestamp":"1709257073167000","amount":0.01630097,"amount_str":"0.01630097","amount_traded":"0","amount_at_create":"0.01630097","price":61347,"price_str":"61347"},"channel":"live_orders_btcusd","event":"order_created"}
{"data":{"id":1722048915496960,"id_str":"1722048915496960","order_type":1,"datetime":"1709257073","microtimestamp":"1709257073167000","amount":0.48889894,"amount_str":"0.48889894","amount_traded":"0","amount_at_create":"0.48889894","price":61363,"price_str":"61363"},"channel":"live_orders_btcusd","event":"order_created"}
{"data":{"id":1722048915152897,"id_str":"1722048915152897","order_type":0,"datetime":"1709257073","microtimestamp":"1709257073167000","amount":0.00814969,"amount_str":"0.00814969","amount_traded":"0","amount_at_create":"0.00814969","price":61345,"price_str":"61345"},"channel":"live_orders_btcusd","event":"order_deleted"}
{"data":{"id":1722048915501057,"id_str":"1722048915501057","order_type":0,"datetime":"1709257073","microtimestamp":"1709257073169000","amount":0.01630278,"amount_str":"0.01630278","amount_traded":"0","amount_at_create":"0.01630278","price":61339,"price_str":"61339"},"channel":"live_orders_btcusd","event":"order_created"}
{"data":{"id":1722048915505156,"id_str":"1722048915505156","order_type":1,"datetime":"1709257073","microtimestamp":"1709257073169000","amount":0.48894973,"amount_str":"0.48894973","amount_traded":"0","amount_at_create":"0.48894973","price":61356,"price_str":"61356"},"channel":"live_orders_btcusd","event":"order_created"}
{"data":{"id":1722048915517441,"id_str":"1722048915517441","order_type":0,"datetime":"1709257073","microtimestamp":"1709257073172000","amount":0.48910345,"amount_str":"0.48910345","amount_traded":"0","amount_at_create":"0.48910345","price":61336,"price_str":"61336"},"channel":"live_orders_btcusd","event":"order_created"}
{"data":{"id":1722048915533827,"id_str":"1722048915533827","order_type":1,"datetime":"1709257073","microtimestamp":"1709257073177000","amount":0.02061514,"amount_str":"0.02061514","amount_traded":"0","amount_at_create":"0.02061514","price":61368,"price_str":"61368"},"channel":"live_orders_btcusd","event":"order_created"}
{"data":{"id":1722048915578880,"id_str":"1722048915578880","order_type":0,"datetime":"1709257073","microtimestamp":"1709257073187000","amount":0.16299387,"amount_str":"0.16299387","amount_traded":"0","amount_at_create":"0.16299387","price":61324,"price_str":"61324"},"channel":"live_orders_btcusd","event":"order_created"}
{"data":{"id":1722048915595266,"id_str":"1722048915595266","order_type":0,"datetime":"1709257073","microtimestamp":"1709257073192000","amount":3.06689844,"amount_str":"3.06689844","amount_traded":"0","amount_at_create":"3.06689844","price":61333,"price_str":"61333"},"channel":"live_orders_btcusd","event":"order_created"}
{"data":{"id":1722048910684161,"id_str":"1722048910684161","order_type":1,"datetime":"1709257073","microtimestamp":"1709257073194000","amount":0.04875518,"amount_str":"0.04875518","amount_traded":"0","amount_at_create":"0.04875518","price":61387,"price_str":"61387"},"channel":"live_orders_btcusd","event":"order_deleted"}
{"data":{"id":1722048893308929,"id_str":"1722048893308929","order_type":0,"datetime":"1709257073","microtimestamp":"1709257073195000","amount":0.12188796,"amount_str":"0.12188796","amount_traded":"0","amount_at_create":"0.12188796","price":61298,"price_str":"61298"},"channel":"live_orders_btcusd","event":"order_deleted"}
{"data":{"id":1722048915496960,"id_str":"1722048915496960","order_type":1,"datetime":"1709257073","microtimestamp":"1709257073201000","amount":0.48889894,"amount_str":"0.48889894","amount_traded":"0","amount_at_create":"0.48889894","price":61363,"price_str":"61363"},"channel":"live_orders_btcusd","event":"order_deleted"}
{"data":{"id":1722048915492868,"id_str":"1722048915492868","order_type":1,"datetime":"1709257073","microtimestamp":"1709257073201000","amount":0.01630097,"amount_str":"0.01630097","amount_traded":"0","amount_at_create":"0.01630097","price":61347,"price_str":"61347"},"channel":"live_orders_btcusd","event":"order_deleted"}
{"data":{"id":1722048915660800,"id_str":"1722048915660800","order_type":1,"datetime":"1709257073","microtimestamp":"1709257073207000","amount":0.93122736,"amount_str":"0.93122736","amount_traded":"0","amount_at_create":"0.93122736","price":61393,"price_str":"61393"},"channel":"live_orders_btcusd","event":"order_created"}
{"data":{"id":1722048915234818,"id_str":"1722048915234818","order_type":0,"datetime":"1709257073","microtimestamp":"1709257073218000","amount":0.04893,"amount_str":"0.04893000","amount_traded":"0","amount_at_create":"0.04893000","price":61325,"price_str":"61325"},"channel":"live_orders_btcusd","event":"order_deleted"}
{"data":{"id":1722048915533827,"id_str":"1722048915533827","order_type":1,"datetime":"1709257073","microtimestamp":"1709257073220000","amount":0.02061514,"amount_str":"0.02061514","amount_traded":"0","amount_at_create":"0.02061514","price":61368,"price_str":"61368"},"channel":"live_orders_btcusd","event":"order_deleted"}
{"data":{"id":1722048915492867,"id_str":"1722048915492867","order_type":1,"datetime":"1709257073","microtimestamp":"1709257073225000","amount":0.48894973,"amount_str":"0.48894973","amount_traded":"0","amount_at_create":"0.48894973","price":61356,"price_str":"61356"},"channel":"live_orders_btcusd","event":"order_deleted"}
{"data":{"id":1722048915505156,"id_str":"1722048915505156","order_type":1,"datetime":"1709257073","microtimestamp":"1709257073226000","amount":0.48894973,"amount_str":"0.48894973","amount_traded":"0","amount_at_create":"0.48894973","price":61356,"price_str":"61356"},"channel":"live_orders_btcusd","event":"order_deleted"}
{"data":{"id":1722048915824641,"id_str":"1722048915824641","order_type":0,"datetime":"1709257073","microtimestamp":"1709257073247000","amount":0.16337902,"amount_str":"0.16337902","amount_traded":"0","amount_at_create":"0.16337902","price":61207,"price_str":"61207"},"channel":"live_orders_btcusd","event":"order_created"}
{"data":{"id":1722048915484674,"id_str":"1722048915484674","order_type":1,"datetime":"1709257073","microtimestamp":"1709257073257000","amount":0.1875,"amount_str":"0.18750000","amount_traded":"0","amount_at_create":"0.18750000","price":61360,"price_str":"61360"},"channel":"live_orders_btcusd","event":"order_deleted"}
{"data":{"id":1722048915898371,"id_str":"1722048915898371","order_type":1,"datetime":"1709257073","microtimestamp":"1709257073266000","amount":0.04875518,"amount_str":"0.04875518","amount_traded":"0","amount_at_create":"0.04875518","price":61379,"price_str":"61379"},"channel":"live_orders_btcusd","event":"order_created"}
{"data":{"id":1722048915472389,"id_str":"1722048915472389","order_type":0,"datetime":"1709257073","microtimestamp":"1709257073266000","amount":0.00814969,"amount_str":"0.00814969","amount_traded":"0","amount_at_create":"0.00814969","price":61343,"price_str":"61343"},"channel":"live_orders_btcusd","event":"order_deleted"}
{"data":{"id":1722048915910657,"id_str":"1722048915910657","order_type":0,"datetime":"1709257073","microtimestamp":"1709257073269000","amount":0.12188796,"amount_str":"0.12188796","amount_traded":"0","amount_at_create":"0.12188796","price":61288,"price_str":"61288"},"channel":"live_orders_btcusd","event":"order_created"}
{"data":{"id":1722048915927040,"id_str":"1722048915927040","order_type":0,"datetime":"1709257073","microtimestamp":"1709257073272000","amount":0.40749663,"amount_str":"0.40749663","amount_traded":"0","amount_at_create":"0.40749663","price":61136,"price_str":"61136"},"channel":"live_orders_btcusd","event":"order_created"}
{"data":{"id":1722048915927040,"id_str":"1722048915927040","order_type":0,"datetime":"1709257073","microtimestamp":"1709257073286000","amount":0.40749663,"amount_str":"0.40749663","amount_traded":"0","amount_at_create":"0.40749663","price":61136,"price_str":"61136"},"channel":"live_orders_btcusd","event":"order_deleted"}
{"data":{"id":1722048915988481,"id_str":"1722048915988481","order_type":0,"datetime":"1709257073","microtimestamp":"1709257073287000","amount":0.00814982,"amount_str":"0.00814982","amount_traded":"0","amount_at_create":"0.00814982","price":61341,"price_str":"61341"},"channel":"live_orders_btcusd","event":"order_created"}
{"data":{"id":1722048916004864,"id_str":"1722048916004864","order_type":1,"datetime":"1709257073","microtimestamp":"1709257073291000","amount":0.01630115,"amount_str":"0.01630115","amount_traded":"0","amount_at_create":"0.01630115","price":61346,"price_str":"61346"},"channel":"live_orders_btcusd","event":"order_created"}
{"data":{"id":1722048915263488,"id_str":"1722048915263488","order_type":1,"datetime":"1709257073","microtimestamp":"1709257073295000","amount":0.00487069,"amount_str":"0.00487069","amount_traded":"0","amount_at_create":"0.00487069","price":61361,"price_str":"61361"},"channel":"live_orders_btcusd","event":"order_deleted"}
{"data":{"id":1722048914501633,"id_str":"1722048914501633","order_type":0,"datetime":"1709257073","microtimestamp":"1709257073304000","amount":0.00040751,"amount_str":"0.00040751","amount_traded":"0","amount_at_create":"0.00040751","price":61340,"price_str":"61340"},"channel":"live_orders_btcusd","event":"order_deleted"}
{"data":{"id":1722048916004864,"id_str":"1722048916004864","order_type":1,"datetime":"1709257073","microtimestamp":"1709257073305000","amount":0.01630115,"amount_str":"0.01630115","amount_traded":"0","amount_at_create":"0.01630115","price":61346,"price_str":"61346"},"channel":"live_orders_btcusd","event":"order_deleted"}
{"data":{"id":1722048916090885,"id_str":"1722048916090885","order_type":1,"datetime":"1709257073","microtimestamp":"1709257073313000","amount":0.00487125,"amount_str":"0.00487125","amount_traded":"0","amount_at_create":"0.00487125","price":61356,"price_str":"61356"},"channel":"live_orders_btcusd","event":"order_created"}
{"data":{"id":1722048916152321,"id_str":"1722048916152321","order_type":1,"datetime":"1709257073","microtimestamp":"1709257073328000","amount":0.02128707,"amount_str":"0.02128707","amount_traded":"0","amount_at_create":"0.02128707","price":61368,"price_str":"61368"},"channel":"live_orders_btcusd","event":"order_created"}
{"data":{"id":1722048916295682,"id_str":"1722048916295682","order_type":0,"datetime":"1709257073","microtimestamp":"1709257073363000","amount":0.48914102,"amount_str":"0.48914102","amount_traded":"0","amount_at_create":"0.48914102","price":61332,"price_str":"61332"},"channel":"live_orders_btcusd","event":"order_created"}
{"data":{"id":1722048916484096,"id_str":"1722048916484096","order_type":1,"datetime":"1709257073","microtimestamp":"1709257073408000","amount":0.01630097,"amount_str":"0.01630097","amount_traded":"0","amount_at_create":"0.01630097","price":61347,"price_str":"61347"},"channel":"live_orders_btcusd","event":"order_created"}
{"data":{"id":1722048916484097,"id_str":"1722048916484097","order_type":1,"datetime":"1709257073","microtimestamp":"1709257073408000","amount":0.48901184,"amount_str":"0.48901184","amount_traded":"0","amount_at_create":"0.48901184","price":61349,"price_str":"61349"},"channel":"live_orders_btcusd","event":"order_created"}
{"data":{"id":1722048915517441,"id_str":"1722048915517441","order_type":0,"datetime":"1709257073","microtimestamp":"1709257073419000","amount":0.48910345,"amount_str":"0.48910345","amount_traded":"0","amount_at_create":"0.48910345","price":61336,"price_str":"61336"},"channel":"live_orders_btcusd","event":"order_deleted"}
{"data":{"id":1722048916090885,"id_str":"1722048916090885","order_type":1,"datetime":"1709257073","microtimestamp":"1709257073427000","amount":0.00487125,"amount_str":"0.00487125","amount_traded":"0","amount_at_create":"0.00487125","price":61356,"price_str":"61356"},"channel":"live_orders_btcusd","event":"order_deleted"}
{"data":{"id":1722048691175425,"id_str":"1722048691175425","order_type":0,"datetime":"1709257073","microtimestamp":"1709257073452000","amount":0.06517693,"amount_str":"0.06517693","amount_traded":"0","amount_at_create":"0.06517693","price":61330,"price_str":"61330"},"channel":"live_orders_btcusd","event":"order_deleted"}
{"data":{"id":1722048916684800,"id_str":"1722048916684800","order_type":1,"datetime":"1709257073","microtimestamp":"1709257073457000","amount":0.1875,"amount_str":"0.18750000","amount_traded":"0","amount_at_create":"0.18750000","price":61361,"price_str":"61361"},"channel":"live_orders_btcusd","event":"order_created"}
{"data":{"id":1722048916713476,"id_str":"1722048916713476","order_type":0,"datetime":"1709257073","microtimestamp":"1709257073464000","amount":0.48909973,"amount_str":"0.48909973","amount_traded":"0","amount_at_create":"0.48909973","price":61337,"price_str":"61337"},"channel":"live_orders_btcusd","event":"order_created"}
{"data":{"id":1722048916152321,"id_str":"1722048916152321","order_type":1,"datetime":"1709257074","microtimestamp":"1709257073504000","amount":0.02128707,"amount_str":"0.02128707","amount_traded":"0","amount_at_create":"0.02128707","price":61368,"price_str":"61368"},"channel":"live_orders_btcusd","event":"order_deleted"}
{"data":{"id":1722048916905984,"id_str":"1722048916905984","order_type":1,"datetime":"1709257074","microtimestamp":"1709257073511000","amount":0.00487133,"amount_str":"0.00487133","amount_traded":"0","amount_at_create":"0.00487133","price":61356,"price_str":"61356"},"channel":"live_orders_btcusd","event":"order_created"}
{"data":{"id":1722048917250048,"id_str":"1722048917250048","order_type":1,"datetime":"1709257074","microtimestamp":"1709257073595000","amount":0.48870387,"amount_str":"0.48870387","amount_traded":"0","amount_at_create":"0.48870387","price":61387,"price_str":"61387"},"channel":"live_orders_btcusd","event":"order_created"}
{"data":{"id":1722048917528578,"id_str":"1722048917528578","order_type":1,"datetime":"1709257074","microtimestamp":"1709257073664000","amount":0.0242011,"amount_str":"0.02420110","amount_traded":"0","amount_at_create":"0.02420110","price":61367,"price_str":"61367"},"channel":"live_orders_btcusd","event":"order_created"}
{"data":{"id":1722048917639168,"id_str":"1722048917639168","order_type":0,"datetime":"1709257074","microtimestamp":"1709257073690000","amount":0.00040751,"amount_str":"0.00040751","amount_traded":"0","amount_at_create":"0.00040751","price":61334,"price_str":"61334"},"channel":"live_orders_btcusd","event":"order_created"}
{"data":{"id":1722048917856257,"id_str":"1722048917856257","order_type":0,"datetime":"1709257074","microtimestamp":"1709257073744000","amount":0.04875518,"amount_str":"0.04875518","amount_traded":"0","amount_at_create":"0.04875518","price":61317,"price_str":"61317"},"channel":"live_orders_btcusd","event":"order_created"}
{"data":{"id":1722048918425600,"id_str":"1722048918425600","order_type":0,"datetime":"1709257074","microtimestamp":"1709257073882000","amount":0.40752985,"amount_str":"0.40752985","amount_traded":"0","amount_at_create":"0.40752985","price":61133,"price_str":"61133"},"channel":"live_orders_btcusd","event":"order_created"}
{"data":{"id":1722048918425602,"id_str":"1722048918425602","order_type":0,"datetime":"1709257074","microtimestamp":"1709257073882000","amount":0.003314,"amount_str":"0.00331400","amount_traded":"0","amount_at_create":"0.00331400","price":61338,"price_str":"61338"},"channel":"live_orders_btcusd","event":"order_created"}
{"data":{"id":1722048918425600,"id_str":"1722048918425600","order_type":0,"datetime":"1709257074","microtimestamp":"1709257073896000","amount":0.40752985,"amount_str":"0.40752985","amount_traded":"0","amount_at_create":"0.40752985","price":61133,"price_str":"61133"},"channel":"live_orders_btcusd","event":"order_deleted"}
{"data":{"id":1722048918671360,"id_str":"1722048918671360","order_type":0,"datetime":"1709257074","microtimestamp":"1709257073942000","amount":0.06517771,"amount_str":"0.06517771","amount_traded":"0","amount_at_create":"0.06517771","price":61329,"price_str":"61329"},"channel":"live_orders_btcusd","event":"order_created"}
{"data":{"id":1722048916295682,"id_str":"1722048916295682","order_type":0,"datetime":"1709257074","microtimestamp":"1709257074038000","amount":0.48914102,"amount_str":"0.48914102","amount_traded":"0","amount_at_create":"0.48914102","price":61332,"price_str":"61332"},"channel":"live_orders_btcusd","event":"order_deleted"}
{"data":{"id":1722048915501057,"id_str":"1722048915501057","order_type":0,"datetime":"1709257074","microtimestamp":"1709257074038000","amount":0.01630278,"amount_str":"0.01630278","amount_traded":"0","amount_at_create":"0.01630278","price":61339,"price_str":"61339"},"channel":"live_orders_btcusd","event":"order_deleted"}
{"data":{"id":1722048916713476,"id_str":"1722048916713476","order_type":0,"datetime":"1709257074","microtimestamp":"1709257074043000","amount":0.48909973,"amount_str":"0.48909973","amount_traded":"0","amount_at_create":"0.48909973","price":61337,"price_str":"61337"},"channel":"live_orders_btcusd","event":"order_deleted"}
{"data":{"id":1722048919126016,"id_str":"1722048919126016","order_type":0,"datetime":"1709257074","microtimestamp":"1709257074053000","amount":0.48930576,"amount_str":"0.48930576","amount_traded":"0","amount_at_create":"0.48930576","price":61311,"price_str":"61311"},"channel":"live_orders_btcusd","event":"order_created"}
{"data":{"id":1722048919126019,"id_str":"1722048919126019","order_type":1,"datetime":"1709257074","microtimestamp":"1709257074054000","amount":0.48897956,"amount_str":"0.48897956","amount_traded":"0","amount_at_create":"0.48897956","price":61353,"price_str":"61353"},"channel":"live_orders_btcusd","event":"order_created"}
{"data":{"id":1722048919130112,"id_str":"1722048919130112","order_type":1,"datetime":"1709257074","microtimestamp":"1709257074054000","amount":0.4887962,"amount_str":"0.48879620","amount_traded":"0","amount_at_create":"0.48879620","price":61376,"price_str":"61376"},"channel":"live_orders_btcusd","event":"order_created"}
{"data":{"id":1722048919134209,"id_str":"1722048919134209","order_type":0,"datetime":"1709257074","microtimestamp":"1709257074055000","amount":0.48919234,"amount_str":"0.48919234","amount_traded":"0","amount_at_create":"0.48919234","price":61325,"price_str":"61325"},"channel":"live_orders_btcusd","event":"order_created"}
{"data":{"id":1722048917639168,"id_str":"1722048917639168","order_type":0,"datetime":"1709257074","microtimestamp":"1709257074096000","amount":0.00040751,"amount_str":"0.00040751","amount_traded":"0","amount_at_create":"0.00040751","price":61334,"price_str":"61334"},"channel":"live_orders_btcusd","event":"order_deleted"}
{"data":{"id":1722048919334912,"id_str":"1722048919334912","order_type":0,"datetime":"1709257074","microtimestamp":"1709257074104000","amount":0.48912499,"amount_str":"0.48912499","amount_traded":"0","amount_at_create":"0.48912499","price":61334,"price_str":"61334"},"channel":"live_orders_btcusd","event":"order_created"}
{"data":{"id":1722048919334916,"id_str":"1722048919334916","order_type":0,"datetime":"1709257074","microtimestamp":"1709257074105000","amount":0.48909133,"amount_str":"0.48909133","amount_traded":"0","amount_at_create":"0.48909133","price":61338,"price_str":"61338"},"channel":"live_orders_btcusd","event":"order_created"}
{"data":{"id":1722048918425602,"id_str":"1722048918425602","order_type":0,"datetime":"1709257074","microtimestamp":"1709257074105000","amount":0.003314,"amount_str":"0.00331400","amount_traded":"0","amount_at_create":"0.00331400","price":61338,"price_str":"61338"},"channel":"live_orders_btcusd","event":"order_deleted"}
{"data":{"id":1722048919126019,"id_str":"1722048919126019","order_type":1,"datetime":"1709257074","microtimestamp":"1709257074105000","amount":0.48897956,"amount_str":"0.48897956","amount_traded":"0","amount_at_create":"0.48897956","price":61353,"price_str":"61353"},"channel":"live_orders_btcusd","event":"order_deleted"}
{"data":{"id":1722048919339011,"id_str":"1722048919339011","order_type":0,"datetime":"1709257074","microtimestamp":"1709257074106000","amount":0.01630256,"amount_str":"0.01630256","amount_traded":"0","amount_at_create":"0.01630256","price":61340,"price_str":"61340"},"channel":"live_orders_btcusd","event":"order_created"}
{"data":{"id":1722048916484097,"id_str":"1722048916484097","order_type":1,"datetime":"1709257074","microtimestamp":"1709257074106000","amount":0.48901184,"amount_str":"0.48901184","amount_traded":"0","amount_at_create":"0.48901184","price":61349,"price_str":"61349"},"channel":"live_orders_btcusd","event":"order_deleted"}
{"data":{"id":1722048916484096,"id_str":"1722048916484096","order_type":1,"datetime":"1709257074","microtimestamp":"1709257074107000","amount":0.01630097,"amount_str":"0.01630097","amount_traded":"0","amount_at_create":"0.01630097","price":61347,"price_str":"61347"},"channel":"live_orders_btcusd","event":"order_deleted"}
{"data":{"id":1722048919339011,"id_str":"1722048919339011","order_type":0,"datetime":"1709257074","microtimestamp":"1709257074127000","amount":0.01630256,"amount_str":"0.01630256","amount_traded":"0","amount_at_create":"0.01630256","price":61340,"price_str":"61340"},"channel":"live_orders_btcusd","event":"order_deleted"}
{"data":{"id":1722048919334916,"id_str":"1722048919334916","order_type":0,"datetime":"1709257074","microtimestamp":"1709257074127000","amount":0.48909133,"amount_str":"0.48909133","amount_traded":"0","amount_at_create":"0.48909133","price":61338,"price_str":"61338"},"channel":"live_orders_btcusd","event":"order_deleted"}
{"data":{"id":1722048916684800,"id_str":"1722048916684800","order_type":1,"datetime":"1709257074","microtimestamp":"1709257074149000","amount":0.1875,"amount_str":"0.18750000","amount_traded":"0","amount_at_create":"0.18750000","price":61361,"price_str":"61361"},"channel":"live_orders_btcusd","event":"order_deleted"}
{"data":{"id":1722048919609345,"id_str":"1722048919609345","order_type":1,"datetime":"1709257074","microtimestamp":"1709257074171000","amount":0.48899007,"amount_str":"0.48899007","amount_traded":"0","amount_at_create":"0.48899007","price":61351,"price_str":"61351"},"channel":"live_orders_btcusd","event":"order_created"}
{"data":{"id":1722048919613442,"id_str":"1722048919613442","order_type":1,"datetime":"1709257074","microtimestamp":"1709257074172000","amount":0.01630025,"amount_str":"0.01630025","amount_traded":"0","amount_at_create":"0.01630025","price":61349,"price_str":"61349"},"channel":"live_orders_btcusd","event":"order_created"}
{"data":{"id":1722048919617536,"id_str":"1722048919617536","order_type":1,"datetime":"1709257074","microtimestamp":"1709257074173000","amount":0.4889255,"amount_str":"0.48892550","amount_traded":"0","amount_at_create":"0.48892550","price":61360,"price_str":"61360"},"channel":"live_orders_btcusd","event":"order_created"}
{"data":{"id":1722048919810048,"id_str":"1722048919810048","order_type":0,"datetime":"1709257074","microtimestamp":"1709257074220000","amount":0.01630214,"amount_str":"0.01630214","amount_traded":"0","amount_at_create":"0.01630214","price":61341,"price_str":"61341"},"channel":"live_orders_btcusd","event":"order_created"}
{"data":{"id":1722048919969794,"id_str":"1722048919969794","order_type":0,"datetime":"1709257074","microtimestamp":"1709257074260000","amount":0.04893,"amount_str":"0.04893000","amount_traded":"0","amount_at_create":"0.04893000","price":61320,"price_str":"61320"},"channel":"live_orders_btcusd","event":"order_created"}
{"data":{"id":1722048920092674,"id_str":"1722048920092674","order_type":0,"datetime":"1709257074","microtimestamp":"1709257074289000","amount":0.40752985,"amount_str":"0.40752985","amount_traded":"0","amount_at_create":"0.40752985","price":61133,"price_str":"61133"},"channel":"live_orders_btcusd","event":"order_created"}
{"data":{"id":1722048920109058,"id_str":"1722048920109058","order_type":0,"datetime":"1709257074","microtimestamp":"1709257074294000","amount":0.00331389,"amount_str":"0.00331389","amount_traded":"0","amount_at_create":"0.00331389","price":61335,"price_str":"61335"},"channel":"live_orders_btcusd","event":"order_created"}
{"data":{"id":1722048919613442,"id_str":"1722048919613442","order_type":1,"datetime":"1709257074","microtimestamp":"1709257074299000","amount":0.01630025,"amount_str":"0.01630025","amount_traded":"0","amount_at_create":"0.01630025","price":61349,"price_str":"61349"},"channel":"live_orders_btcusd","event":"order_deleted"}
{"data":{"id":1722048920092674,"id_str":"1722048920092674","order_type":0,"datetime":"1709257074","microtimestamp":"1709257074304000","amount":0.40752985,"amount_str":"0.40752985","amount_traded":"0","amount_at_create":"0.40752985","price":61133,"price_str":"61133"},"channel":"live_orders_btcusd","event":"order_deleted"}
{"data":{"id":1722048920231937,"id_str":"1722048920231937","order_type":0,"datetime":"1709257074","microtimestamp":"1709257074323000","amount":0.00040751,"amount_str":"0.00040751","amount_traded":"0","amount_at_create":"0.00040751","price":61335,"price_str":"61335"},"channel":"live_orders_btcusd","event":"order_created"}
{"data":{"id":1722048920322048,"id_str":"1722048920322048","order_type":1,"datetime":"1709257074","microtimestamp":"1709257074345000","amount":0.01630045,"amount_str":"0.01630045","amount_traded":"0","amount_at_create":"0.01630045","price":61348,"price_str":"61348"},"channel":"live_orders_btcusd","event":"order_created"}
{"data":{"id":1722048920326144,"id_str":"1722048920326144","order_type":0,"datetime":"1709257074","microtimestamp":"1709257074346000","amount":0.48908184,"amount_str":"0.48908184","amount_traded":"0","amount_at_create":"0.48908184","price":61339,"price_str":"61339"},"channel":"live_orders_btcusd","event":"order_created"}
{"data":{"id":1722048920596480,"id_str":"1722048920596480","order_type":1,"datetime":"1709257074","microtimestamp":"1709257074412000","amount":0.1875,"amount_str":"0.18750000","amount_traded":"0","amount_at_create":"0.18750000","price":61362,"price_str":"61362"},"channel":"live_orders_btcusd","event":"order_created"}
{"data":{"id":1722048920109058,"id_str":"1722048920109058","order_type":0,"datetime":"1709257074","microtimestamp":"1709257074433000","amount":0.00331389,"amount_str":"0.00331389","amount_traded":"0","amount_at_create":"0.00331389","price":61335,"price_str":"61335"},"channel":"live_orders_btcusd","event":"order_deleted"}
{"data":{"id":1722048919609345,"id_str":"1722048919609345","order_type":1,"datetime":"1709257075","microtimestamp":"1709257074544000","amount":0.48899007,"amount_str":"0.48899007","amount_traded":"0","amount_at_create":"0.48899007","price":61351,"price_str":"61351"},"channel":"live_orders_btcusd","event":"order_deleted"}
{"data":{"id":1722048921309184,"id_str":"1722048921309184","order_type":1,"datetime":"1709257075","microtimestamp":"1709257074587000","amount":0.48895779,"amount_str":"0.48895779","amount_traded":"0","amount_at_create":"0.48895779","price":61355,"price_str":"61355"},"channel":"live_orders_btcusd","event":"order_created"}
{"data":{"id":1722048921317377,"id_str":"1722048921317377","order_type":1,"datetime":"1709257075","microtimestamp":"1709257074589000","amount":0.48899845,"amount_str":"0.48899845","amount_traded":"0","amount_at_create":"0.48899845","price":61350,"price_str":"61350"},"channel":"live_orders_btcusd","event":"order_created"}
{"data":{"id":1722048881332226,"id_str":"1722048881332226","order_type":1,"datetime":"1709257075","microtimestamp":"1709257074768000","amount":0.00033,"amount_str":"0.00033000","amount_traded":"0","amount_at_create":"0.00033000","price":61417,"price_str":"61417"},"channel":"live_orders_btcusd","event":"order_deleted"}
{"data":{"id":1722048922292224,"id_str":"1722048922292224","order_type":1,"datetime":"1709257075","microtimestamp":"1709257074827000","amount":0.00033,"amount_str":"0.00033000","amount_traded":"0","amount_at_create":"0.00033000","price":61416,"price_str":"61416"},"channel":"live_orders_btcusd","event":"order_created"}
{"data":{"id":1722048922513410,"id_str":"1722048922513410","order_type":0,"datetime":"1709257075","microtimestamp":"1709257074881000","amount":0.40755111,"amount_str":"0.40755111","amount_traded":"0","amount_at_create":"0.40755111","price":61133,"price_str":"61133"},"channel":"live_orders_btcusd","event":"order_created"}
{"data":{"id":1722048922513410,"id_str":"1722048922513410","order_type":0,"datetime":"1709257075","microtimestamp":"1709257074894000","amount":0.40755111,"amount_str":"0.40755111","amount_traded":"0","amount_at_create":"0.40755111","price":61133,"price_str":"61133"},"channel":"live_orders_btcusd","event":"order_deleted"}
{"data":{"id":1722048919810048,"id_str":"1722048919810048","order_type":0,"datetime":"1709257075","microtimestamp":"1709257075401000","amount":0.01630214,"amount_str":"0.01630214","amount_traded":"0","amount_at_create":"0.01630214","price":61341,"price_str":"61341"},"channel":"live_orders_btcusd","event":"order_deleted"}
{"data":{"id":1722048920322048,"id_str":"1722048920322048","order_type":1,"datetime":"1709257075","microtimestamp":"1709257075401000","amount":0.01630045,"amount_str":"0.01630045","amount_traded":"0","amount_at_create":"0.01630045","price":61348,"price_str":"61348"},"channel":"live_orders_btcusd","event":"order_deleted"}
{"data":{"id":1722048920326144,"id_str":"1722048920326144","order_type":0,"datetime":"1709257075","microtimestamp":"1709257075401000","amount":0.48908184,"amount_str":"0.48908184","amount_traded":"0","amount_at_create":"0.48908184","price":61339,"price_str":"61339"},"channel":"live_orders_btcusd","event":"order_deleted"}
{"data":{"id":1722048921309184,"id_str":"1722048921309184","order_type":1,"datetime":"1709257075","microtimestamp":"1709257075402000","amount":0.48895779,"amount_str":"0.48895779","amount_traded":"0","amount_at_create":"0.48895779","price":61355,"price_str":"61355"},"channel":"live_orders_btcusd","event":"order_deleted"}
{"data":{"id":1722048921317377,"id_str":"1722048921317377","order_type":1,"datetime":"1709257075","microtimestamp":"1709257075402000","amount":0.48899845,"amount_str":"0.48899845","amount_traded":"0","amount_at_create":"0.48899845","price":61350,"price_str":"61350"},"channel":"live_orders_btcusd","event":"order_deleted"}
{"data":{"id":1722048924844033,"id_str":"1722048924844033","order_type":1,"datetime":"1709257075","microtimestamp":"1709257075449000","amount":0.48901116,"amount_str":"0.48901116","amount_traded":"0","amount_at_create":"0.48901116","price":61349,"price_str":"61349"},"channel":"live_orders_btcusd","event":"order_created"}
{"data":{"id":1722048924848128,"id_str":"1722048924848128","order_type":1,"datetime":"1709257075","microtimestamp":"1709257075450000","amount":0.01630095,"amount_str":"0.01630095","amount_traded":"0","amount_at_create":"0.01630095","price":61347,"price_str":"61347"},"channel":"live_orders_btcusd","event":"order_created"}
{"data":{"id":1722048924848129,"id_str":"1722048924848129","order_type":0,"datetime":"1709257075","microtimestamp":"1709257075450000","amount":0.01630274,"amount_str":"0.01630274","amount_traded":"0","amount_at_create":"0.01630274","price":61339,"price_str":"61339"},"channel":"live_orders_btcusd","event":"order_created"}
{"data":{"id":1722048924852224,"id_str":"1722048924852224","order_type":1,"datetime":"1709257075","microtimestamp":"1709257075451000","amount":0.48897904,"amount_str":"0.48897904","amount_traded":"0","amount_at_create":"0.48897904","price":61353,"price_str":"61353"},"channel":"live_orders_btcusd","event":"order_created"}
{"data":{"id":1722048924864512,"id_str":"1722048924864512","order_type":0,"datetime":"1709257075","microtimestamp":"1709257075454000","amount":0.48909984,"amount_str":"0.48909984","amount_traded":"0","amount_at_create":"0.48909984","price":61337,"price_str":"61337"},"channel":"live_orders_btcusd","event":"order_created"}
{"data":{"id":1722048924844033,"id_str":"1722048924844033","order_type":1,"datetime":"1709257075","microtimestamp":"1709257075467000","amount":0.48901116,"amount_str":"0.48901116","amount_traded":"0","amount_at_create":"0.48901116","price":61349,"price_str":"61349"},"channel":"live_orders_btcusd","event":"order_deleted"}
{"data":{"id":1722048924852224,"id_str":"1722048924852224","order_type":1,"datetime":"1709257075","microtimestamp":"1709257075469000","amount":0.48897904,"amount_str":"0.48897904","amount_traded":"0","amount_at_create":"0.48897904","price":61353,"price_str":"61353"},"channel":"live_orders_btcusd","event":"order_deleted"}
{"data":{"id":1722048924848128,"id_str":"1722048924848128","order_type":1,"datetime":"1709257075","microtimestamp":"1709257075496000","amount":0.01630095,"amount_str":"0.01630095","amount_traded":"0","amount_at_create":"0.01630095","price":61347,"price_str":"61347"},"channel":"live_orders_btcusd","event":"order_deleted"}
{"data":{"id":1722048925134848,"id_str":"1722048925134848","order_type":0,"datetime":"1709257076","microtimestamp":"1709257075521000","amount":0.16329874,"amount_str":"0.16329874","amount_traded":"0","amount_at_create":"0.16329874","price":61237,"price_str":"61237"},"channel":"live_orders_btcusd","event":"order_created"}
{"data":{"id":1722048925147136,"id_str":"1722048925147136","order_type":1,"datetime":"1709257076","microtimestamp":"1709257075523000","amount":0.16273602,"amount_str":"0.16273602","amount_traded":"0","amount_at_create":"0.16273602","price":61450,"price_str":"61450"},"channel":"live_orders_btcusd","event":"order_created"}
{"data":{"id":1722048925261824,"id_str":"1722048925261824","order_type":0,"datetime":"1709257076","microtimestamp":"1709257075551000","amount":0.40755111,"amount_str":"0.40755111","amount_traded":"0","amount_at_create":"0.40755111","price":61133,"price_str":"61133"},"channel":"live_orders_btcusd","event":"order_created"}
{"data":{"id":1722048925261824,"id_str":"1722048925261824","order_type":0,"datetime":"1709257076","microtimestamp":"1709257075566000","amount":0.40755111,"amount_str":"0.40755111","amount_traded":"0","amount_at_create":"0.40755111","price":61133,"price_str":"61133"},"channel":"live_orders_btcusd","event":"order_deleted"}
{"data":{"id":1722048925327360,"id_str":"1722048925327360","order_type":1,"datetime":"1709257076","microtimestamp":"1709257075567000","amount":0.016301,"amount_str":"0.01630100","amount_traded":"0","amount_at_create":"0.01630100","price":61346,"price_str":"61346"},"channel":"live_orders_btcusd","event":"order_created"}
{"data":{"id":1722048915988481,"id_str":"1722048915988481","order_type":0,"datetime":"1709257076","microtimestamp":"1709257075759000","amount":0.00814982,"amount_str":"0.00814982","amount_traded":"0","amount_at_create":"0.00814982","price":61341,"price_str":"61341"},"channel":"live_orders_btcusd","event":"order_deleted"}
{"data":{"id":1722048926220288,"id_str":"1722048926220288","order_type":0,"datetime":"1709257076","microtimestamp":"1709257075786000","amount":0.00815082,"amount_str":"0.00815082","amount_traded":"0","amount_at_create":"0.00815082","price":61339,"price_str":"61339"},"channel":"live_orders_btcusd","event":"order_created"}
{"data":{"id":1722048918671360,"id_str":"1722048918671360","order_type":0,"datetime":"1709257076","microtimestamp":"1709257075861000","amount":0.06517771,"amount_str":"0.06517771","amount_traded":"0","amount_at_create":"0.06517771","price":61329,"price_str":"61329"},"channel":"live_orders_btcusd","event":"order_deleted"}
{"data":{"id":1722048926543872,"id_str":"1722048926543872","order_type":0,"datetime":"1709257076","microtimestamp":"1709257075864000","amount":0.40755111,"amount_str":"0.40755111","amount_traded":"0","amount_at_create":"0.40755111","price":61133,"price_str":"61133"},"channel":"live_orders_btcusd","event":"order_created"}
{"data":{"id":1722048926543872,"id_str":"1722048926543872","order_type":0,"datetime":"1709257076","microtimestamp":"1709257075879000","amount":0.40755111,"amount_str":"0.40755111","amount_traded":"0","amount_at_create":"0.40755111","price":61133,"price_str":"61133"},"channel":"live_orders_btcusd","event":"order_deleted"}
{"data":{"id":1722048774414336,"id_str":"1722048774414336","order_type":0,"datetime":"1709257076","microtimestamp":"1709257075907000","amount":0.1875,"amount_str":"0.18750000","amount_traded":"0","amount_at_create":"0.18750000","price":61280,"price_str":"61280"},"channel":"live_orders_btcusd","event":"order_deleted"}
{"data":{"id":1722048904724481,"id_str":"1722048904724481","order_type":1,"datetime":"1709257076","microtimestamp":"1709257075909000","amount":0.1875,"amount_str":"0.18750000","amount_traded":"0","amount_at_create":"0.18750000","price":61418,"price_str":"61418"},"channel":"live_orders_btcusd","event":"order_deleted"}
{"data":{"id":1722048927096833,"id_str":"1722048927096833","order_type":0,"datetime":"1709257076","microtimestamp":"1709257075999000","amount":0.1875,"amount_str":"0.18750000","amount_traded":"0","amount_at_create":"0.18750000","price":61220,"price_str":"61220"},"channel":"live_orders_btcusd","event":"order_created"}
{"data":{"id":1722048915394563,"id_str":"1722048915394563","order_type":1,"datetime":"1709257076","microtimestamp":"1709257076167000","amount":0.00487069,"amount_str":"0.00487069","amount_traded":"0","amount_at_create":"0.00487069","price":61359,"price_str":"61359"},"channel":"live_orders_btcusd","event":"order_deleted"}
{"data":{"id":1722048915247108,"id_str":"1722048915247108","order_type":1,"datetime":"1709257076","microtimestamp":"1709257076184000","amount":0.04374456,"amount_str":"0.04374456","amount_traded":"0","amount_at_create":"0.04374456","price":61366,"price_str":"61366"},"channel":"live_orders_btcusd","event":"order_deleted"}
{"data":{"id":1722048917528578,"id_str":"1722048917528578","order_type":1,"datetime":"1709257076","microtimestamp":"1709257076184000","amount":0.0242011,"amount_str":"0.02420110","amount_traded":"0","amount_at_create":"0.02420110","price":61367,"price_str":"61367"},"channel":"live_orders_btcusd","event":"order_deleted"}
{"data":{"id":1722048919130112,"id_str":"1722048919130112","order_type":1,"datetime":"1709257076","microtimestamp":"1709257076185000","amount":0.4887962,"amount_str":"0.48879620","amount_traded":"0","amount_at_create":"0.48879620","price":61376,"price_str":"61376"},"channel":"live_orders_btcusd","event":"order_deleted"}
{"data":{"id":1722048925327360,"id_str":"1722048925327360","order_type":1,"datetime":"1709257076","microtimestamp":"1709257076185000","amount":0.016301,"amount_str":"0.01630100","amount_traded":"0","amount_at_create":"0.01630100","price":61346,"price_str":"61346"},"channel":"live_orders_btcusd","event":"order_deleted"}
{"data":{"id":1722048914898950,"id_str":"1722048914898950","order_type":0,"datetime":"1709257076","microtimestamp":"1709257076186000","amount":0.48937347,"amount_str":"0.48937347","amount_traded":"0","amount_at_create":"0.48937347","price":61302,"price_str":"61302"},"channel":"live_orders_btcusd","event":"order_deleted"}
{"data":{"id":1722048924864512,"id_str":"1722048924864512","order_type":0,"datetime":"1709257076","microtimestamp":"1709257076186000","amount":0.48909984,"amount_str":"0.48909984","amount_traded":"0","amount_at_create":"0.48909984","price":61337,"price_str":"61337"},"channel":"live_orders_btcusd","event":"order_deleted"}
{"data":{"id":1722048924848129,"id_str":"1722048924848129","order_type":0,"datetime":"1709257076","microtimestamp":"1709257076186000","amount":0.01630274,"amount_str":"0.01630274","amount_traded":"0","amount_at_create":"0.01630274","price":61339,"price_str":"61339"},"channel":"live_orders_btcusd","event":"order_deleted"}
{"data":{"id":1722048919334912,"id_str":"1722048919334912","order_type":0,"datetime":"1709257076","microtimestamp":"1709257076186000","amount":0.48912499,"amount_str":"0.48912499","amount_traded":"0","amount_at_create":"0.48912499","price":61334,"price_str":"61334"},"channel":"live_orders_btcusd","event":"order_deleted"}
{"data":{"id":1722048906149888,"id_str":"1722048906149888","order_type":1,"datetime":"1709257076","microtimestamp":"1709257076187000","amount":0.09741469,"amount_str":"0.09741469","amount_traded":"0","amount_at_create":"0.09741469","price":61380,"price_str":"61380"},"channel":"live_orders_btcusd","event":"order_deleted"}
{"data":{"id":1722048915578880,"id_str":"1722048915578880","order_type":0,"datetime":"1709257076","microtimestamp":"1709257076193000","amount":0.16299387,"amount_str":"0.16299387","amount_traded":"0","amount_at_create":"0.16299387","price":61324,"price_str":"61324"},"channel":"live_orders_btcusd","event":"order_deleted"}
{"data":{"id":1722048915251203,"id_str":"1722048915251203","order_type":1,"datetime":"1709257076","microtimestamp":"1709257076198000","amount":0.06199507,"amount_str":"0.06199507","amount_traded":"0","amount_at_create":"0.06199507","price":61528,"price_str":"61528"},"channel":"live_orders_btcusd","event":"order_deleted"}
{"data":{"id":1722048927920128,"id_str":"1722048927920128","order_type":1,"datetime":"1709257076","microtimestamp":"1709257076200000","amount":0.04374456,"amount_str":"0.04374456","amount_traded":"0","amount_at_create":"0.04374456","price":61361,"price_str":"61361"},"channel":"live_orders_btcusd","event":"order_created"}
{"data":{"id":1722048919617536,"id_str":"1722048919617536","order_type":1,"datetime":"1709257076","microtimestamp":"1709257076204000","amount":0.4889255,"amount_str":"0.48892550","amount_traded":"0","amount_at_create":"0.48892550","price":61360,"price_str":"61360"},"channel":"live_orders_btcusd","event":"order_deleted"}
{"data":{"id":1722048927969280,"id_str":"1722048927969280","order_type":0,"datetime":"1709257076","microtimestamp":"1709257076212000","amount":0.16301911,"amount_str":"0.16301911","amount_traded":"0","amount_at_create":"0.16301911","price":61319,"price_str":"61319"},"channel":"live_orders_btcusd","event":"order_created"}
{"data":{"id":1722048928002050,"id_str":"1722048928002050","order_type":1,"datetime":"1709257076","microtimestamp":"1709257076221000","amount":0.0221914,"amount_str":"0.02219140","amount_traded":"0","amount_at_create":"0.02219140","price":61364,"price_str":"61364"},"channel":"live_orders_btcusd","event":"order_created"}
{"data":{"id":1722048915910657,"id_str":"1722048915910657","order_type":0,"datetime":"1709257076","microtimestamp":"1709257076223000","amount":0.12188796,"amount_str":"0.12188796","amount_traded":"0","amount_at_create":"0.12188796","price":61288,"price_str":"61288"},"channel":"live_orders_btcusd","event":"order_deleted"}
{"data":{"id":1722048928034818,"id_str":"1722048928034818","order_type":1,"datetime":"1709257076","microtimestamp":"1709257076229000","amount":0.00487144,"amount_str":"0.00487144","amount_traded":"0","amount_at_create":"0.00487144","price":61354,"price_str":"61354"},"channel":"live_orders_btcusd","event":"order_created"}
{"data":{"id":1722048928002050,"id_str":"1722048928002050","order_type":1,"datetime":"1709257076","microtimestamp":"1709257076245000","amount":0.0221914,"amount_str":"0.02219140","amount_traded":"0","amount_at_create":"0.02219140","price":61364,"price_str":"61364"},"channel":"live_orders_btcusd","event":"order_deleted"}
{"data":{"id":1722048928120833,"id_str":"1722048928120833","order_type":1,"datetime":"1709257076","microtimestamp":"1709257076249000","amount":0.09742898,"amount_str":"0.09742898","amount_traded":"0","amount_at_create":"0.09742898","price":61373,"price_str":"61373"},"channel":"live_orders_btcusd","event":"order_created"}
{"data":{"id":1722048928129026,"id_str":"1722048928129026","order_type":1,"datetime":"1709257076","microtimestamp":"1709257076252000","amount":0.48903741,"amount_str":"0.48903741","amount_traded":"0","amount_at_create":"0.48903741","price":61345,"price_str":"61345"},"channel":"live_orders_btcusd","event":"order_created"}
{"data":{"id":1722048928137216,"id_str":"1722048928137216","order_type":1,"datetime":"1709257076","microtimestamp":"1709257076253000","amount":0.48900834,"amount_str":"0.48900834","amount_traded":"0","amount_at_create":"0.48900834","price":61349,"price_str":"61349"},"channel":"live_orders_btcusd","event":"order_created"}
{"data":{"id":1722048928137217,"id_str":"1722048928137217","order_type":0,"datetime":"1709257076","microtimestamp":"1709257076253000","amount":0.48914712,"amount_str":"0.48914712","amount_traded":"0","amount_at_create":"0.48914712","price":61331,"price_str":"61331"},"channel":"live_orders_btcusd","event":"order_created"}
{"data":{"id":1722048928137218,"id_str":"1722048928137218","order_type":0,"datetime":"1709257076","microtimestamp":"1709257076254000","amount":0.48942714,"amount_str":"0.48942714","amount_traded":"0","amount_at_create":"0.48942714","price":61296,"price_str":"61296"},"channel":"live_orders_btcusd","event":"order_created"}
{"data":{"id":1722048920231937,"id_str":"1722048920231937","order_type":0,"datetime":"1709257076","microtimestamp":"1709257076254000","amount":0.00040751,"amount_str":"0.00040751","amount_traded":"0","amount_at_create":"0.00040751","price":61335,"price_str":"61335"},"channel":"live_orders_btcusd","event":"order_deleted"}
{"data":{"id":1722048928141314,"id_str":"1722048928141314","order_type":1,"datetime":"1709257076","microtimestamp":"1709257076254000","amount":0.01630192,"amount_str":"0.01630192","amount_traded":"0","amount_at_create":"0.01630192","price":61343,"price_str":"61343"},"channel":"live_orders_btcusd","event":"order_created"}
{"data":{"id":1722048928141316,"id_str":"1722048928141316","order_type":0,"datetime":"1709257076","microtimestamp":"1709257076255000","amount":0.48912918,"amount_str":"0.48912918","amount_traded":"0","amount_at_create":"0.48912918","price":61333,"price_str":"61333"},"channel":"live_orders_btcusd","event":"order_created"}
{"data":{"id":1722048928145412,"id_str":"1722048928145412","order_type":0,"datetime":"1709257076","microtimestamp":"1709257076255000","amount":0.0163036,"amount_str":"0.01630360","amount_traded":"0","amount_at_create":"0.01630360","price":61336,"price_str":"61336"},"channel":"live_orders_btcusd","event":"order_created"}
{"data":{"id":1722048926220288,"id_str":"1722048926220288","order_type":0,"datetime":"1709257076","microtimestamp":"1709257076257000","amount":0.00815082,"amount_str":"0.00815082","amount_traded":"0","amount_at_create":"0.00815082","price":61339,"price_str":"61339"},"channel":"live_orders_btcusd","event":"order_deleted"}
{"data":{"id":1722048928157697,"id_str":"1722048928157697","order_type":1,"datetime":"1709257076","microtimestamp":"1709257076258000","amount":0.48882346,"amount_str":"0.48882346","amount_traded":"0","amount_at_create":"0.48882346","price":61372,"price_str":"61372"},"channel":"live_orders_btcusd","event":"order_created"}
{"data":{"id":1722048928157698,"id_str":"1722048928157698","order_type":1,"datetime":"1709257076","microtimestamp":"1709257076258000","amount":0.48894489,"amount_str":"0.48894489","amount_traded":"0","amount_at_create":"0.48894489","price":61357,"price_str":"61357"},"channel":"live_orders_btcusd","event":"order_created"}
{"data":{"id":1722048928190466,"id_str":"1722048928190466","order_type":1,"datetime":"1709257076","microtimestamp":"1709257076266000","amount":0.06129906,"amount_str":"0.06129906","amount_traded":"0","amount_at_create":"0.06129906","price":61518,"price_str":"61518"},"channel":"live_orders_btcusd","event":"order_created"}
{"data":{"id":1722048928129026,"id_str":"1722048928129026","order_type":1,"datetime":"1709257076","microtimestamp":"1709257076273000","amount":0.48903741,"amount_str":"0.48903741","amount_traded":"0","amount_at_create":"0.48903741","price":61345,"price_str":"61345"},"channel":"live_orders_btcusd","event":"order_deleted"}
{"data":{"id":1722048928137216,"id_str":"1722048928137216","order_type":1,"datetime":"1709257076","microtimestamp":"1709257076275000","amount":0.48900834,"amount_str":"0.48900834","amount_traded":"0","amount_at_create":"0.48900834","price":61349,"price_str":"61349"},"channel":"live_orders_btcusd","event":"order_deleted"}
{"data":{"id":1722048928239616,"id_str":"1722048928239616","order_type":0,"datetime":"1709257076","microtimestamp":"1709257076279000","amount":0.12188796,"amount_str":"0.12188796","amount_traded":"0","amount_at_create":"0.12188796","price":61273,"price_str":"61273"},"channel":"live_orders_btcusd","event":"order_created"}
{"data":{"id":1722048928243712,"id_str":"1722048928243712","order_type":0,"datetime":"1709257076","microtimestamp":"1709257076279000","amount":0.00815095,"amount_str":"0.00815095","amount_traded":"0","amount_at_create":"0.00815095","price":61337,"price_str":"61337"},"channel":"live_orders_btcusd","event":"order_created"}
{"data":{"id":1722048928260097,"id_str":"1722048928260097","order_type":0,"datetime":"1709257076","microtimestamp":"1709257076283000","amount":0.40755111,"amount_str":"0.40755111","amount_traded":"0","amount_at_create":"0.40755111","price":61133,"price_str":"61133"},"channel":"live_orders_btcusd","event":"order_created"}
{"data":{"id":1722048928141316,"id_str":"1722048928141316","order_type":0,"datetime":"1709257076","microtimestamp":"1709257076290000","amount":0.48912918,"amount_str":"0.48912918","amount_traded":"0","amount_at_create":"0.48912918","price":61333,"price_str":"61333"},"channel":"live_orders_btcusd","event":"order_deleted"}
{"data":{"id":1722048928141314,"id_str":"1722048928141314","order_type":1,"datetime":"1709257076","microtimestamp":"1709257076291000","amount":0.01630192,"amount_str":"0.01630192","amount_traded":"0","amount_at_create":"0.01630192","price":61343,"price_str":"61343"},"channel":"live_orders_btcusd","event":"order_deleted"}
{"data":{"id":1722048928260097,"id_str":"1722048928260097","order_type":0,"datetime":"1709257076","microtimestamp":"1709257076298000","amount":0.40755111,"amount_str":"0.40755111","amount_traded":"0","amount_at_create":"0.40755111","price":61133,"price_str":"61133"},"channel":"live_orders_btcusd","event":"order_deleted"}
{"data":{"id":1722048928325635,"id_str":"1722048928325635","order_type":0,"datetime":"1709257076","microtimestamp":"1709257076300000","amount":0.00815029,"amount_str":"0.00815029","amount_traded":"0","amount_at_create":"0.00815029","price":61339,"price_str":"61339"},"channel":"live_orders_btcusd","event":"order_created"}
{"data":{"id":1722048909680647,"id_str":"1722048909680647","order_type":0,"datetime":"1709257076","microtimestamp":"1709257076303000","amount":0.815832,"amount_str":"0.81583200","amount_traded":"0","amount_at_create":"0.81583200","price":61316,"price_str":"61316"},"channel":"live_orders_btcusd","event":"order_deleted"}
{"data":{"id":1722048928145412,"id_str":"1722048928145412","order_type":0,"datetime":"1709257076","microtimestamp":"1709257076317000","amount":0.0163036,"amount_str":"0.01630360","amount_traded":"0","amount_at_create":"0.01630360","price":61336,"price_str":"61336"},"channel":"live_orders_btcusd","event":"order_deleted"}
{"data":{"id":1722048928440320,"id_str":"1722048928440320","order_type":0,"datetime":"1709257076","microtimestamp":"1709257076327000","amount":0.00040751,"amount_str":"0.00040751","amount_traded":"0","amount_at_create":"0.00040751","price":61334,"price_str":"61334"},"channel":"live_orders_btcusd","event":"order_created"}
{"data":{"id":1722048928444416,"id_str":"1722048928444416","order_type":1,"datetime":"1709257076","microtimestamp":"1709257076328000","amount":0.02174033,"amount_str":"0.02174033","amount_traded":"0","amount_at_create":"0.02174033","price":61364,"price_str":"61364"},"channel":"live_orders_btcusd","event":"order_created"}
{"data":{"id":1722048928325635,"id_str":"1722048928325635","order_type":0,"datetime":"1709257076","microtimestamp":"1709257076331000","amount":0.00815029,"amount_str":"0.00815029","amount_traded":"0","amount_at_create":"0.00815029","price":61339,"price_str":"61339"},"channel":"live_orders_btcusd","event":"order_deleted"}
{"data":{"id":1722048928534530,"id_str":"1722048928534530","order_type":0,"datetime":"1709257076","microtimestamp":"1709257076351000","amount":0.815832,"amount_str":"0.81583200","amount_traded":"0","amount_at_create":"0.81583200","price":61304,"price_str":"61304"},"channel":"live_orders_btcusd","event":"order_created"}
{"data":{"id":1722048928579586,"id_str":"1722048928579586","order_type":0,"datetime":"1709257076","microtimestamp":"1709257076362000","amount":0.0163031,"amount_str":"0.01630310","amount_traded":"0","amount_at_create":"0.01630310","price":61338,"price_str":"61338"},"channel":"live_orders_btcusd","event":"order_created"}
{"data":{"id":1722048928583684,"id_str":"1722048928583684","order_type":1,"datetime":"1709257076","microtimestamp":"1709257076363000","amount":0.01630115,"amount_str":"0.01630115","amount_traded":"0","amount_at_create":"0.01630115","price":61346,"price_str":"61346"},"channel":"live_orders_btcusd","event":"order_created"}
{"data":{"id":1722048929034240,"id_str":"1722048929034240","order_type":0,"datetime":"1709257076","microtimestamp":"1709257076472000","amount":0.48910581,"amount_str":"0.48910581","amount_traded":"0","amount_at_create":"0.48910581","price":61336,"price_str":"61336"},"channel":"live_orders_btcusd","event":"order_created"}
{"data":{"id":1722048929042435,"id_str":"1722048929042435","order_type":1,"datetime":"1709257076","microtimestamp":"1709257076475000","amount":0.48901726,"amount_str":"0.48901726","amount_traded":"0","amount_at_create":"0.48901726","price":61348,"price_str":"61348"},"channel":"live_orders_btcusd","event":"order_created"}
{"data":{"id":1722048928583684,"id_str":"1722048928583684","order_type":1,"datetime":"1709257076","microtimestamp":"1709257076498000","amount":0.01630115,"amount_str":"0.01630115","amount_traded":"0","amount_at_create":"0.01630115","price":61346,"price_str":"61346"},"channel":"live_orders_btcusd","event":"order_deleted"}
{"data":{"id":1722048929042435,"id_str":"1722048929042435","order_type":1,"datetime":"1709257076","microtimestamp":"1709257076498000","amount":0.48901726,"amount_str":"0.48901726","amount_traded":"0","amount_at_create":"0.48901726","price":61348,"price_str":"61348"},"channel":"live_orders_btcusd","event":"order_deleted"}
{"data":{"id":1722048928440320,"id_str":"1722048928440320","order_type":0,"datetime":"1709257076","microtimestamp":"1709257076499000","amount":0.00040751,"amount_str":"0.00040751","amount_traded":"0","amount_at_create":"0.00040751","price":61334,"price_str":"61334"},"channel":"live_orders_btcusd","event":"order_deleted"}
{"data":{"id":1722048929316864,"id_str":"1722048929316864","order_type":1,"datetime":"1709257077","microtimestamp":"1709257076541000","amount":0.01630134,"amount_str":"0.01630134","amount_traded":"0","amount_at_create":"0.01630134","price":61345,"price_str":"61345"},"channel":"live_orders_btcusd","event":"order_created"}
{"data":{"id":1722048929525760,"id_str":"1722048929525760","order_type":0,"datetime":"1709257077","microtimestamp":"1709257076593000","amount":0.00040751,"amount_str":"0.00040751","amount_traded":"0","amount_at_create":"0.00040751","price":61335,"price_str":"61335"},"channel":"live_orders_btcusd","event":"order_created"}
{"data":{"id":1722048929316864,"id_str":"1722048929316864","order_type":1,"datetime":"1709257077","microtimestamp":"1709257076702000","amount":0.01630134,"amount_str":"0.01630134","amount_traded":"0","amount_at_create":"0.01630134","price":61345,"price_str":"61345"},"channel":"live_orders_btcusd","event":"order_deleted"}
{"data":{"id":1722048929525760,"id_str":"1722048929525760","order_type":0,"datetime":"1709257077","microtimestamp":"1709257076709000","amount":0.00040751,"amount_str":"0.00040751","amount_traded":"0","amount_at_create":"0.00040751","price":61335,"price_str":"61335"},"channel":"live_orders_btcusd","event":"order_deleted"}
{"data":{"id":1722048930156545,"id_str":"1722048930156545","order_type":1,"datetime":"1709257077","microtimestamp":"1709257076747000","amount":0.01630153,"amount_str":"0.01630153","amount_traded":"0","amount_at_create":"0.01630153","price":61344,"price_str":"61344"},"channel":"live_orders_btcusd","event":"order_created"}
{"data":{"id":1722048930160644,"id_str":"1722048930160644","order_type":1,"datetime":"1709257077","microtimestamp":"1709257076748000","amount":0.48902308,"amount_str":"0.48902308","amount_traded":"0","amount_at_create":"0.48902308","price":61347,"price_str":"61347"},"channel":"live_orders_btcusd","event":"order_created"}
{"data":{"id":1722048930336768,"id_str":"1722048930336768","order_type":0,"datetime":"1709257077","microtimestamp":"1709257076790000","amount":0.00040751,"amount_str":"0.00040751","amount_traded":"0","amount_at_create":"0.00040751","price":61334,"price_str":"61334"},"channel":"live_orders_btcusd","event":"order_created"}
{"data":{"id":1722048930349056,"id_str":"1722048930349056","order_type":1,"datetime":"1709257077","microtimestamp":"1709257076793000","amount":0.48900337,"amount_str":"0.48900337","amount_traded":"0","amount_at_create":"0.48900337","price":61350,"price_str":"61350"},"channel":"live_orders_btcusd","event":"order_created"}
{"data":{"id":1722048930529280,"id_str":"1722048930529280","order_type":0,"datetime":"1709257077","microtimestamp":"1709257076837000","amount":0.40755111,"amount_str":"0.40755111","amount_traded":"0","amount_at_create":"0.40755111","price":61132,"price_str":"61132"},"channel":"live_orders_btcusd","event":"order_created"}
{"data":{"id":1722048930529280,"id_str":"1722048930529280","order_type":0,"datetime":"1709257077","microtimestamp":"1709257076852000","amount":0.40755111,"amount_str":"0.40755111","amount_traded":"0","amount_at_create":"0.40755111","price":61132,"price_str":"61132"},"channel":"live_orders_btcusd","event":"order_deleted"}
{"data":{"id":1722048930336768,"id_str":"1722048930336768","order_type":0,"datetime":"1709257077","microtimestamp":"1709257076887000","amount":0.00040751,"amount_str":"0.00040751","amount_traded":"0","amount_at_create":"0.00040751","price":61334,"price_str":"61334"},"channel":"live_orders_btcusd","event":"order_deleted"}
{"data":{"id":1722048928444416,"id_str":"1722048928444416","order_type":1,"datetime":"1709257077","microtimestamp":"1709257076905000","amount":0.02174033,"amount_str":"0.02174033","amount_traded":"0","amount_at_create":"0.02174033","price":61364,"price_str":"61364"},"channel":"live_orders_btcusd","event":"order_deleted"}
{"data":{"id":1722048931106817,"id_str":"1722048931106817","order_type":0,"datetime":"1709257077","microtimestamp":"1709257076979000","amount":0.00040751,"amount_str":"0.00040751","amount_traded":"0","amount_at_create":"0.00040751","price":61334,"price_str":"61334"},"channel":"live_orders_btcusd","event":"order_created"}
{"data":{"id":1722048931106817,"id_str":"1722048931106817","order_type":0,"datetime":"1709257077","microtimestamp":"1709257077057000","amount":0.00040751,"amount_str":"0.00040751","amount_traded":"0","amount_at_create":"0.00040751","price":61334,"price_str":"61334"},"channel":"live_orders_btcusd","event":"order_deleted"}
{"data":{"id":1722048931426311,"id_str":"1722048931426311","order_type":1,"datetime":"1709257077","microtimestamp":"1709257077057000","amount":0.02354638,"amount_str":"0.02354638","amount_traded":"0","amount_at_create":"0.02354638","price":61363,"price_str":"61363"},"channel":"live_orders_btcusd","event":"order_created"}
{"data":{"id":1722048931852289,"id_str":"1722048931852289","order_type":0,"datetime":"1709257077","microtimestamp":"1709257077160000","amount":0.01630134,"amount_str":"0.01630134","amount_traded":"0","amount_at_create":"0.01630134","price":61329,"price_str":"61329"},"channel":"live_orders_btcusd","event":"order_created"}
{"data":{"id":1722048931889153,"id_str":"1722048931889153","order_type":0,"datetime":"1709257077","microtimestamp":"1709257077169000","amount":0.00040751,"amount_str":"0.00040751","amount_traded":"0","amount_at_create":"0.00040751","price":61335,"price_str":"61335"},"channel":"live_orders_btcusd","event":"order_created"}
{"data":{"id":1722048931889153,"id_str":"1722048931889153","order_type":0,"datetime":"1709257077","microtimestamp":"1709257077205000","amount":0.00040751,"amount_str":"0.00040751","amount_traded":"0","amount_at_create":"0.00040751","price":61335,"price_str":"61335"},"channel":"live_orders_btcusd","event":"order_deleted"}
{"data":{"id":1722048930156545,"id_str":"1722048930156545","order_type":1,"datetime":"1709257077","microtimestamp":"1709257077238000","amount":0.01630153,"amount_str":"0.01630153","amount_traded":"0","amount_at_create":"0.01630153","price":61344,"price_str":"61344"},"channel":"live_orders_btcusd","event":"order_deleted"}
{"data":{"id":1722048932237312,"id_str":"1722048932237312","order_type":0,"datetime":"1709257077","microtimestamp":"1709257077254000","amount":0.00040751,"amount_str":"0.00040751","amount_traded":"0","amount_at_create":"0.00040751","price":61334,"price_str":"61334"},"channel":"live_orders_btcusd","event":"order_created"}
{"data":{"id":1722048932327424,"id_str":"1722048932327424","order_type":0,"datetime":"1709257077","microtimestamp":"1709257077276000","amount":0.40755111,"amount_str":"0.40755111","amount_traded":"0","amount_at_create":"0.40755111","price":61132,"price_str":"61132"},"channel":"live_orders_btcusd","event":"order_created"}
{"data":{"id":1722048932356099,"id_str":"1722048932356099","order_type":1,"datetime":"1709257077","microtimestamp":"1709257077284000","amount":0.01630118,"amount_str":"0.01630118","amount_traded":"0","amount_at_create":"0.01630118","price":61346,"price_str":"61346"},"channel":"live_orders_btcusd","event":"order_created"}
{"data":{"id":1722048932327424,"id_str":"1722048932327424","order_type":0,"datetime":"1709257077","microtimestamp":"1709257077289000","amount":0.40755111,"amount_str":"0.40755111","amount_traded":"0","amount_at_create":"0.40755111","price":61132,"price_str":"61132"},"channel":"live_orders_btcusd","event":"order_deleted"}
{"data":{"id":1722048932675584,"id_str":"1722048932675584","order_type":0,"datetime":"1709257077","microtimestamp":"1709257077361000","amount":0.00815102,"amount_str":"0.00815102","amount_traded":"0","amount_at_create":"0.00815102","price":61339,"price_str":"61339"},"channel":"live_orders_btcusd","event":"order_created"}
{"data":{"id":1722048932237312,"id_str":"1722048932237312","order_type":0,"datetime":"1709257077","microtimestamp":"1709257077376000","amount":0.00040751,"amount_str":"0.00040751","amount_traded":"0","amount_at_create":"0.00040751","price":61334,"price_str":"61334"},"channel":"live_orders_btcusd","event":"order_deleted"}
{"data":{"id":1722048920596480,"id_str":"1722048920596480","order_type":1,"datetime":"1709257077","microtimestamp":"1709257077396000","amount":0.1875,"amount_str":"0.18750000","amount_traded":"0","amount_at_create":"0.18750000","price":61362,"price_str":"61362"},"channel":"live_orders_btcusd","event":"order_deleted"}
{"data":{"id":1722048929034240,"id_str":"1722048929034240","order_type":0,"datetime":"1709257077","microtimestamp":"1709257077403000","amount":0.48910581,"amount_str":"0.48910581","amount_traded":"0","amount_at_create":"0.48910581","price":61336,"price_str":"61336"},"channel":"live_orders_btcusd","event":"order_deleted"}
{"data":{"id":1722048928157698,"id_str":"1722048928157698","order_type":1,"datetime":"1709257077","microtimestamp":"1709257077404000","amount":0.48894489,"amount_str":"0.48894489","amount_traded":"0","amount_at_create":"0.48894489","price":61357,"price_str":"61357"},"channel":"live_orders_btcusd","event":"order_deleted"}
{"data":{"id":1722048930160644,"id_str":"1722048930160644","order_type":1,"datetime":"1709257077","microtimestamp":"1709257077404000","amount":0.48902308,"amount_str":"0.48902308","amount_traded":"0","amount_at_create":"0.48902308","price":61347,"price_str":"61347"},"channel":"live_orders_btcusd","event":"order_deleted"}
{"data":{"id":1722048928579586,"id_str":"1722048928579586","order_type":0,"datetime":"1709257077","microtimestamp":"1709257077404000","amount":0.0163031,"amount_str":"0.01630310","amount_traded":"0","amount_at_create":"0.01630310","price":61338,"price_str":"61338"},"channel":"live_orders_btcusd","event":"order_deleted"}
{"data":{"id":1722048928137217,"id_str":"1722048928137217","order_type":0,"datetime":"1709257077","microtimestamp":"1709257077406000","amount":0.48914712,"amount_str":"0.48914712","amount_traded":"0","amount_at_create":"0.48914712","price":61331,"price_str":"61331"},"channel":"live_orders_btcusd","event":"order_deleted"}
{"data":{"id":1722048932356099,"id_str":"1722048932356099","order_type":1,"datetime":"1709257077","microtimestamp":"1709257077407000","amount":0.01630118,"amount_str":"0.01630118","amount_traded":"0","amount_at_create":"0.01630118","price":61346,"price_str":"61346"},"channel":"live_orders_btcusd","event":"order_deleted"}
{"data":{"id":1722048932909056,"id_str":"1722048932909056","order_type":0,"datetime":"1709257077","microtimestamp":"1709257077418000","amount":0.00040751,"amount_str":"0.00040751","amount_traded":"0","amount_at_create":"0.00040751","price":61335,"price_str":"61335"},"channel":"live_orders_btcusd","event":"order_created"}
{"data":{"id":1722048932954113,"id_str":"1722048932954113","order_type":0,"datetime":"1709257077","microtimestamp":"1709257077429000","amount":0.1875,"amount_str":"0.18750000","amount_traded":"0","amount_at_create":"0.18750000","price":61332,"price_str":"61332"},"channel":"live_orders_btcusd","event":"order_created"}
{"data":{"id":1722048932909056,"id_str":"1722048932909056","order_type":0,"datetime":"1709257077","microtimestamp":"1709257077451000","amount":0.00040751,"amount_str":"0.00040751","amount_traded":"0","amount_at_create":"0.00040751","price":61335,"price_str":"61335"},"channel":"live_orders_btcusd","event":"order_deleted"}
{"data":{"id":1722048933056512,"id_str":"1722048933056512","order_type":0,"datetime":"1709257077","microtimestamp":"1709257077454000","amount":0.48909733,"amount_str":"0.48909733","amount_traded":"0","amount_at_create":"0.48909733","price":61337,"price_str":"61337"},"channel":"live_orders_btcusd","event":"order_created"}
{"data":{"id":1722048933056514,"id_str":"1722048933056514","order_type":0,"datetime":"1709257077","microtimestamp":"1709257077454000","amount":0.48912932,"amount_str":"0.48912932","amount_traded":"0","amount_at_create":"0.48912932","price":61333,"price_str":"61333"},"channel":"live_orders_btcusd","event":"order_created"}
{"data":{"id":1722048933056515,"id_str":"1722048933056515","order_type":1,"datetime":"1709257077","microtimestamp":"1709257077455000","amount":0.48897197,"amount_str":"0.48897197","amount_traded":"0","amount_at_create":"0.48897197","price":61354,"price_str":"61354"},"channel":"live_orders_btcusd","event":"order_created"}
{"data":{"id":1722048933056516,"id_str":"1722048933056516","order_type":1,"datetime":"1709257077","microtimestamp":"1709257077455000","amount":0.48891303,"amount_str":"0.48891303","amount_traded":"0","amount_at_create":"0.48891303","price":61361,"price_str":"61361"},"channel":"live_orders_btcusd","event":"order_created"}
{"data":{"id":1722048933064704,"id_str":"1722048933064704","order_type":1,"datetime":"1709257077","microtimestamp":"1709257077456000","amount":0.0163007,"amount_str":"0.01630070","amount_traded":"0","amount_at_create":"0.01630070","price":61348,"price_str":"61348"},"channel":"live_orders_btcusd","event":"order_created"}
{"data":{"id":1722048933064706,"id_str":"1722048933064706","order_type":0,"datetime":"1709257077","microtimestamp":"1709257077456000","amount":0.01630266,"amount_str":"0.01630266","amount_traded":"0","amount_at_create":"0.01630266","price":61339,"price_str":"61339"},"channel":"live_orders_btcusd","event":"order_created"}
{"data":{"id":1722048933056512,"id_str":"1722048933056512","order_type":0,"datetime":"1709257077","microtimestamp":"1709257077498000","amount":0.48909733,"amount_str":"0.48909733","amount_traded":"0","amount_at_create":"0.48909733","price":61337,"price_str":"61337"},"channel":"live_orders_btcusd","event":"order_deleted"}
{"data":{"id":1722048933064706,"id_str":"1722048933064706","order_type":0,"datetime":"1709257077","microtimestamp":"1709257077498000","amount":0.01630266,"amount_str":"0.01630266","amount_traded":"0","amount_at_create":"0.01630266","price":61339,"price_str":"61339"},"channel":"live_orders_btcusd","event":"order_deleted"}
{"data":{"id":1722048933552128,"id_str":"1722048933552128","order_type":0,"datetime":"1709257078","microtimestamp":"1709257077575000","amount":0.00040751,"amount_str":"0.00040751","amount_traded":"0","amount_at_create":"0.00040751","price":61334,"price_str":"61334"},"channel":"live_orders_btcusd","event":"order_created"}
{"data":{"id":1722048933777409,"id_str":"1722048933777409","order_type":0,"datetime":"1709257078","microtimestamp":"1709257077630000","amount":0.01630248,"amount_str":"0.01630248","amount_traded":"0","amount_at_create":"0.01630248","price":61340,"price_str":"61340"},"channel":"live_orders_btcusd","event":"order_created"}
{"data":{"id":1722048933777410,"id_str":"1722048933777410","order_type":0,"datetime":"1709257078","microtimestamp":"1709257077631000","amount":0.48962539,"amount_str":"0.48962539","amount_traded":"0","amount_at_create":"0.48962539","price":61271,"price_str":"61271"},"channel":"live_orders_btcusd","event":"order_created"}
{"data":{"id":1722048933781504,"id_str":"1722048933781504","order_type":1,"datetime":"1709257078","microtimestamp":"1709257077631000","amount":0.48850503,"amount_str":"0.48850503","amount_traded":"0","amount_at_create":"0.48850503","price":61412,"price_str":"61412"},"channel":"live_orders_btcusd","event":"order_created"}
{"data":{"id":1722048933957633,"id_str":"1722048933957633","order_type":0,"datetime":"1709257078","microtimestamp":"1709257077674000","amount":0.48909186,"amount_str":"0.48909186","amount_traded":"0","amount_at_create":"0.48909186","price":61338,"price_str":"61338"},"channel":"live_orders_btcusd","event":"order_created"}
{"data":{"id":1722048933552128,"id_str":"1722048933552128","order_type":0,"datetime":"1709257078","microtimestamp":"1709257077710000","amount":0.00040751,"amount_str":"0.00040751","amount_traded":"0","amount_at_create":"0.00040751","price":61334,"price_str":"61334"},"channel":"live_orders_btcusd","event":"order_deleted"}
{"data":{"id":1722048934289412,"id_str":"1722048934289412","order_type":0,"datetime":"1709257078","microtimestamp":"1709257077755000","amount":0.40755111,"amount_str":"0.40755111","amount_traded":"0","amount_at_create":"0.40755111","price":61132,"price_str":"61132"},"channel":"live_orders_btcusd","event":"order_created"}
{"data":{"id":1722048934289412,"id_str":"1722048934289412","order_type":0,"datetime":"1709257078","microtimestamp":"1709257077770000","amount":0.40755111,"amount_str":"0.40755111","amount_traded":"0","amount_at_create":"0.40755111","price":61132,"price_str":"61132"},"channel":"live_orders_btcusd","event":"order_deleted"}
{"data":{"id":1722048933064704,"id_str":"1722048933064704","order_type":1,"datetime":"1709257078","microtimestamp":"1709257077798000","amount":0.0163007,"amount_str":"0.01630070","amount_traded":"0","amount_at_create":"0.01630070","price":61348,"price_str":"61348"},"channel":"live_orders_btcusd","event":"order_deleted"}
{"data":{"id":1722048934469632,"id_str":"1722048934469632","order_type":0,"datetime":"1709257078","microtimestamp":"1709257077799000","amount":0.00040751,"amount_str":"0.00040751","amount_traded":"0","amount_at_create":"0.00040751","price":61335,"price_str":"61335"},"channel":"live_orders_btcusd","event":"order_created"}
{"data":{"id":1722048932954113,"id_str":"1722048932954113","order_type":0,"datetime":"1709257078","microtimestamp":"1709257077821000","amount":0.1875,"amount_str":"0.18750000","amount_traded":"0","amount_at_create":"0.18750000","price":61332,"price_str":"61332"},"channel":"live_orders_btcusd","event":"order_deleted"}
{"data":{"id":1722048930349056,"id_str":"1722048930349056","order_type":1,"datetime":"1709257078","microtimestamp":"1709257077841000","amount":0.48900337,"amount_str":"0.48900337","amount_traded":"0","amount_at_create":"0.48900337","price":61350,"price_str":"61350"},"channel":"live_orders_btcusd","event":"order_deleted"}
{"data":{"id":1722048934653956,"id_str":"1722048934653956","order_type":1,"datetime":"1709257078","microtimestamp":"1709257077845000","amount":0.01630076,"amount_str":"0.01630076","amount_traded":"0","amount_at_create":"0.01630076","price":61347,"price_str":"61347"},"channel":"live_orders_btcusd","event":"order_created"}
{"data":{"id":1722048934834177,"id_str":"1722048934834177","order_type":1,"datetime":"1709257078","microtimestamp":"1709257077889000","amount":0.48900552,"amount_str":"0.48900552","amount_traded":"0","amount_at_create":"0.48900552","price":61349,"price_str":"61349"},"channel":"live_orders_btcusd","event":"order_created"}
{"data":{"id":1722048934469632,"id_str":"1722048934469632","order_type":0,"datetime":"1709257078","microtimestamp":"1709257077925000","amount":0.00040751,"amount_str":"0.00040751","amount_traded":"0","amount_at_create":"0.00040751","price":61335,"price_str":"61335"},"channel":"live_orders_btcusd","event":"order_deleted"}
{"data":{"id":1722048934653956,"id_str":"1722048934653956","order_type":1,"datetime":"1709257078","microtimestamp":"1709257078004000","amount":0.01630076,"amount_str":"0.01630076","amount_traded":"0","amount_at_create":"0.01630076","price":61347,"price_str":"61347"},"channel":"live_orders_btcusd","event":"order_deleted"}
{"data":{"id":1722048933957633,"id_str":"1722048933957633","order_type":0,"datetime":"1709257078","microtimestamp":"1709257078004000","amount":0.48909186,"amount_str":"0.48909186","amount_traded":"0","amount_at_create":"0.48909186","price":61338,"price_str":"61338"},"channel":"live_orders_btcusd","event":"order_deleted"}
{"data":{"id":1722048934834177,"id_str":"1722048934834177","order_type":1,"datetime":"1709257078","microtimestamp":"1709257078004000","amount":0.48900552,"amount_str":"0.48900552","amount_traded":"0","amount_at_create":"0.48900552","price":61349,"price_str":"61349"},"channel":"live_orders_btcusd","event":"order_deleted"}
{"data":{"id":1722048933056515,"id_str":"1722048933056515","order_type":1,"datetime":"1709257078","microtimestamp":"1709257078004000","amount":0.48897197,"amount_str":"0.48897197","amount_traded":"0","amount_at_create":"0.48897197","price":61354,"price_str":"61354"},"channel":"live_orders_btcusd","event":"order_deleted"}
{"data":{"id":1722048933777409,"id_str":"1722048933777409","order_type":0,"datetime":"1709257078","microtimestamp":"1709257078005000","amount":0.01630248,"amount_str":"0.01630248","amount_traded":"0","amount_at_create":"0.01630248","price":61340,"price_str":"61340"},"channel":"live_orders_btcusd","event":"order_deleted"}
{"data":{"id":1722048935501827,"id_str":"1722048935501827","order_type":1,"datetime":"1709257078","microtimestamp":"1709257078052000","amount":0.48898617,"amount_str":"0.48898617","amount_traded":"0","amount_at_create":"0.48898617","price":61352,"price_str":"61352"},"channel":"live_orders_btcusd","event":"order_created"}
{"data":{"id":1722048935510017,"id_str":"1722048935510017","order_type":1,"datetime":"1709257078","microtimestamp":"1709257078053000","amount":0.01630117,"amount_str":"0.01630117","amount_traded":"0","amount_at_create":"0.01630117","price":61346,"price_str":"61346"},"channel":"live_orders_btcusd","event":"order_created"}
{"data":{"id":1722048935518209,"id_str":"1722048935518209","order_type":0,"datetime":"1709257078","microtimestamp":"1709257078055000","amount":0.01630296,"amount_str":"0.01630296","amount_traded":"0","amount_at_create":"0.01630296","price":61338,"price_str":"61338"},"channel":"live_orders_btcusd","event":"order_created"}
{"data":{"id":1722048935518212,"id_str":"1722048935518212","order_type":0,"datetime":"1709257078","microtimestamp":"1709257078056000","amount":0.48910607,"amount_str":"0.48910607","amount_traded":"0","amount_at_create":"0.48910607","price":61336,"price_str":"61336"},"channel":"live_orders_btcusd","event":"order_created"}
{"data":{"id":1722048935731200,"id_str":"1722048935731200","order_type":1,"datetime":"1709257078","microtimestamp":"1709257078107000","amount":0.1875,"amount_str":"0.18750000","amount_traded":"0","amount_at_create":"0.18750000","price":61360,"price_str":"61360"},"channel":"live_orders_btcusd","event":"order_created"}
{"data":{"id":1722048935804928,"id_str":"1722048935804928","order_type":0,"datetime":"1709257078","microtimestamp":"1709257078125000","amount":0.00040751,"amount_str":"0.00040751","amount_traded":"0","amount_at_create":"0.00040751","price":61334,"price_str":"61334"},"channel":"live_orders_btcusd","event":"order_created"}
{"data":{"id":1722048935845889,"id_str":"1722048935845889","order_type":1,"datetime":"1709257078","microtimestamp":"1709257078135000","amount":0.48901507,"amount_str":"0.48901507","amount_traded":"0","amount_at_create":"0.48901507","price":61348,"price_str":"61348"},"channel":"live_orders_btcusd","event":"order_created"}
{"data":{"id":1722048936448002,"id_str":"1722048936448002","order_type":1,"datetime":"1709257078","microtimestamp":"1709257078283000","amount":0.40755111,"amount_str":"0.40755111","amount_traded":"0","amount_at_create":"0.40755111","price":61359,"price_str":"61359"},"channel":"live_orders_btcusd","event":"order_created"}
{"data":{"id":1722048935518209,"id_str":"1722048935518209","order_type":0,"datetime":"1709257078","microtimestamp":"1709257078299000","amount":0.01630296,"amount_str":"0.01630296","amount_traded":"0","amount_at_create":"0.01630296","price":61338,"price_str":"61338"},"channel":"live_orders_btcusd","event":"order_deleted"}
{"data":{"id":1722048931426311,"id_str":"1722048931426311","order_type":1,"datetime":"1709257078","microtimestamp":"1709257078305000","amount":0.02354638,"amount_str":"0.02354638","amount_traded":"0","amount_at_create":"0.02354638","price":61363,"price_str":"61363"},"channel":"live_orders_btcusd","event":"order_deleted"}
{"data":{"id":1722048935518212,"id_str":"1722048935518212","order_type":0,"datetime":"1709257078","microtimestamp":"1709257078316000","amount":0.48910607,"amount_str":"0.48910607","amount_traded":"0","amount_at_create":"0.48910607","price":61336,"price_str":"61336"},"channel":"live_orders_btcusd","event":"order_deleted"}
{"data":{"id":1722048935804928,"id_str":"1722048935804928","order_type":0,"datetime":"1709257078","microtimestamp":"1709257078326000","amount":0.00040751,"amount_str":"0.00040751","amount_traded":"0","amount_at_create":"0.00040751","price":61334,"price_str":"61334"},"channel":"live_orders_btcusd","event":"order_deleted"}
{"data":{"id":1722048936697856,"id_str":"1722048936697856","order_type":0,"datetime":"1709257078","microtimestamp":"1709257078344000","amount":0.0163028,"amount_str":"0.01630280","amount_traded":"0","amount_at_create":"0.01630280","price":61339,"price_str":"61339"},"channel":"live_orders_btcusd","event":"order_created"}
{"data":{"id":1722048936837120,"id_str":"1722048936837120","order_type":0,"datetime":"1709257078","microtimestamp":"1709257078377000","amount":0.1875,"amount_str":"0.18750000","amount_traded":"0","amount_at_create":"0.18750000","price":61332,"price_str":"61332"},"channel":"live_orders_btcusd","event":"order_created"}
{"data":{"id":1722048935731200,"id_str":"1722048935731200","order_type":1,"datetime":"1709257078","microtimestamp":"1709257078386000","amount":0.1875,"amount_str":"0.18750000","amount_traded":"0","amount_at_create":"0.18750000","price":61360,"price_str":"61360"},"channel":"live_orders_btcusd","event":"order_deleted"}
{"data":{"id":1722048936869893,"id_str":"1722048936869893","order_type":0,"datetime":"1709257078","microtimestamp":"1709257078386000","amount":0.48910047,"amount_str":"0.48910047","amount_traded":"0","amount_at_create":"0.48910047","price":61337,"price_str":"61337"},"channel":"live_orders_btcusd","event":"order_created"}
{"data":{"id":1722048935845889,"id_str":"1722048935845889","order_type":1,"datetime":"1709257078","microtimestamp":"1709257078407000","amount":0.48901507,"amount_str":"0.48901507","amount_traded":"0","amount_at_create":"0.48901507","price":61348,"price_str":"61348"},"channel":"live_orders_btcusd","event":"order_deleted"}
{"data":{"id":1722048936697856,"id_str":"1722048936697856","order_type":0,"datetime":"1709257078","microtimestamp":"1709257078407000","amount":0.0163028,"amount_str":"0.01630280","amount_traded":"0","amount_at_create":"0.01630280","price":61339,"price_str":"61339"},"channel":"live_orders_btcusd","event":"order_deleted"}
{"data":{"id":1722048933056514,"id_str":"1722048933056514","order_type":0,"datetime":"1709257078","microtimestamp":"1709257078408000","amount":0.48912932,"amount_str":"0.48912932","amount_traded":"0","amount_at_create":"0.48912932","price":61333,"price_str":"61333"},"channel":"live_orders_btcusd","event":"order_deleted"}
{"data":{"id":1722048935510017,"id_str":"1722048935510017","order_type":1,"datetime":"1709257078","microtimestamp":"1709257078408000","amount":0.01630117,"amount_str":"0.01630117","amount_traded":"0","amount_at_create":"0.01630117","price":61346,"price_str":"61346"},"channel":"live_orders_btcusd","event":"order_deleted"}
{"data":{"id":1722048935501827,"id_str":"1722048935501827","order_type":1,"datetime":"1709257078","microtimestamp":"1709257078408000","amount":0.48898617,"amount_str":"0.48898617","amount_traded":"0","amount_at_create":"0.48898617","price":61352,"price_str":"61352"},"channel":"live_orders_btcusd","event":"order_deleted"}
{"data":{"id":1722048928157697,"id_str":"1722048928157697","order_type":1,"datetime":"1709257078","microtimestamp":"1709257078409000","amount":0.48882346,"amount_str":"0.48882346","amount_traded":"0","amount_at_create":"0.48882346","price":61372,"price_str":"61372"},"channel":"live_orders_btcusd","event":"order_deleted"}
{"data":{"id":1722048937181184,"id_str":"1722048937181184","order_type":1,"datetime":"1709257078","microtimestamp":"1709257078461000","amount":0.01630033,"amount_str":"0.01630033","amount_traded":"0","amount_at_create":"0.01630033","price":61349,"price_str":"61349"},"channel":"live_orders_btcusd","event":"order_created"}
{"data":{"id":1722048937181186,"id_str":"1722048937181186","order_type":1,"datetime":"1709257078","microtimestamp":"1709257078461000","amount":0.48899284,"amount_str":"0.48899284","amount_traded":"0","amount_at_create":"0.48899284","price":61351,"price_str":"61351"},"channel":"live_orders_btcusd","event":"order_created"}
{"data":{"id":1722048937185282,"id_str":"1722048937185282","order_type":1,"datetime":"1709257078","microtimestamp":"1709257078462000","amount":0.4887891,"amount_str":"0.48878910","amount_traded":"0","amount_at_create":"0.48878910","price":61377,"price_str":"61377"},"channel":"live_orders_btcusd","event":"order_created"}
{"data":{"id":1722048937185288,"id_str":"1722048937185288","order_type":0,"datetime":"1709257078","microtimestamp":"1709257078463000","amount":0.01630211,"amount_str":"0.01630211","amount_traded":"0","amount_at_create":"0.01630211","price":61341,"price_str":"61341"},"channel":"live_orders_btcusd","event":"order_created"}
{"data":{"id":1722048937181186,"id_str":"1722048937181186","order_type":1,"datetime":"1709257078","microtimestamp":"1709257078478000","amount":0.48899284,"amount_str":"0.48899284","amount_traded":"0","amount_at_create":"0.48899284","price":61351,"price_str":"61351"},"channel":"live_orders_btcusd","event":"order_deleted"}
{"data":{"id":1722048937336833,"id_str":"1722048937336833","order_type":1,"datetime":"1709257079","microtimestamp":"1709257078500000","amount":0.02161798,"amount_str":"0.02161798","amount_traded":"0","amount_at_create":"0.02161798","price":61364,"price_str":"61364"},"channel":"live_orders_btcusd","event":"order_created"}
{"data":{"id":1722048937574401,"id_str":"1722048937574401","order_type":1,"datetime":"1709257079","microtimestamp":"1709257078558000","amount":0.48896086,"amount_str":"0.48896086","amount_traded":"0","amount_at_create":"0.48896086","price":61355,"price_str":"61355"},"channel":"live_orders_btcusd","event":"order_created"}
{"data":{"id":1722048928034818,"id_str":"1722048928034818","order_type":1,"datetime":"1709257079","microtimestamp":"1709257078594000","amount":0.00487144,"amount_str":"0.00487144","amount_traded":"0","amount_at_create":"0.00487144","price":61354,"price_str":"61354"},"channel":"live_orders_btcusd","event":"order_deleted"}
{"data":{"id":1722048937185288,"id_str":"1722048937185288","order_type":0,"datetime":"1709257079","microtimestamp":"1709257078602000","amount":0.01630211,"amount_str":"0.01630211","amount_traded":"0","amount_at_create":"0.01630211","price":61341,"price_str":"61341"},"channel":"live_orders_btcusd","event":"order_deleted"}
{"data":{"id":1722048919134209,"id_str":"1722048919134209","order_type":0,"datetime":"1709257079","microtimestamp":"1709257078603000","amount":0.48919234,"amount_str":"0.48919234","amount_traded":"0","amount_at_create":"0.48919234","price":61325,"price_str":"61325"},"channel":"live_orders_btcusd","event":"order_deleted"}
{"data":{"id":1722048937762816,"id_str":"1722048937762816","order_type":0,"datetime":"1709257079","microtimestamp":"1709257078603000","amount":0.48908065,"amount_str":"0.48908065","amount_traded":"0","amount_at_create":"0.48908065","price":61339,"price_str":"61339"},"channel":"live_orders_btcusd","event":"order_created"}
{"data":{"id":1722048937951237,"id_str":"1722048937951237","order_type":0,"datetime":"1709257079","microtimestamp":"1709257078650000","amount":0.48916786,"amount_str":"0.48916786","amount_traded":"0","amount_at_create":"0.48916786","price":61328,"price_str":"61328"},"channel":"live_orders_btcusd","event":"order_created"}
{"data":{"id":1722048937963520,"id_str":"1722048937963520","order_type":0,"datetime":"1709257079","microtimestamp":"1709257078652000","amount":0.016302,"amount_str":"0.01630200","amount_traded":"0","amount_at_create":"0.01630200","price":61342,"price_str":"61342"},"channel":"live_orders_btcusd","event":"order_created"}
{"data":{"id":1722048938102785,"id_str":"1722048938102785","order_type":0,"datetime":"1709257079","microtimestamp":"1709257078686000","amount":0.00040751,"amount_str":"0.00040751","amount_traded":"0","amount_at_create":"0.00040751","price":61335,"price_str":"61335"},"channel":"live_orders_btcusd","event":"order_created"}
{"data":{"id":1722048938143746,"id_str":"1722048938143746","order_type":1,"datetime":"1709257079","microtimestamp":"1709257078696000","amount":0.4889953,"amount_str":"0.48899530","amount_traded":"0","amount_at_create":"0.48899530","price":61351,"price_str":"61351"},"channel":"live_orders_btcusd","event":"order_created"}
{"data":{"id":1722048937963520,"id_str":"1722048937963520","order_type":0,"datetime":"1709257079","microtimestamp":"1709257078703000","amount":0.016302,"amount_str":"0.01630200","amount_traded":"0","amount_at_create":"0.01630200","price":61342,"price_str":"61342"},"channel":"live_orders_btcusd","event":"order_deleted"}
{"data":{"id":1722048938405888,"id_str":"1722048938405888","order_type":0,"datetime":"1709257079","microtimestamp":"1709257078760000","amount":0.01630218,"amount_str":"0.01630218","amount_traded":"0","amount_at_create":"0.01630218","price":61341,"price_str":"61341"},"channel":"live_orders_btcusd","event":"order_created"}
{"data":{"id":1722048938520579,"id_str":"1722048938520579","order_type":0,"datetime":"1709257079","microtimestamp":"1709257078789000","amount":0.0016245,"amount_str":"0.00162450","amount_traded":"0","amount_at_create":"0.00162450","price":58276,"price_str":"58276"},"channel":"live_orders_btcusd","event":"order_created"}
{"data":{"id":1722048937181184,"id_str":"1722048937181184","order_type":1,"datetime":"1709257079","microtimestamp":"1709257078799000","amount":0.01630033,"amount_str":"0.01630033","amount_traded":"0","amount_at_create":"0.01630033","price":61349,"price_str":"61349"},"channel":"live_orders_btcusd","event":"order_deleted"}
{"data":{"id":1722048936869893,"id_str":"1722048936869893","order_type":0,"datetime":"1709257079","microtimestamp":"1709257078799000","amount":0.48910047,"amount_str":"0.48910047","amount_traded":"0","amount_at_create":"0.48910047","price":61337,"price_str":"61337"},"channel":"live_orders_btcusd","event":"order_deleted"}
{"data":{"id":1722048938102785,"id_str":"1722048938102785","order_type":0,"datetime":"1709257079","microtimestamp":"1709257078846000","amount":0.00040751,"amount_str":"0.00040751","amount_traded":"0","amount_at_create":"0.00040751","price":61335,"price_str":"61335"},"channel":"live_orders_btcusd","event":"order_deleted"}
{"data":{"id":1722048938758147,"id_str":"1722048938758147","order_type":1,"datetime":"1709257079","microtimestamp":"1709257078846000","amount":0.01630048,"amount_str":"0.01630048","amount_traded":"0","amount_at_create":"0.01630048","price":61348,"price_str":"61348"},"channel":"live_orders_btcusd","event":"order_created"}
{"data":{"id":1722048938766336,"id_str":"1722048938766336","order_type":0,"datetime":"1709257079","microtimestamp":"1709257078848000","amount":0.4891165,"amount_str":"0.48911650","amount_traded":"0","amount_at_create":"0.48911650","price":61335,"price_str":"61335"},"channel":"live_orders_btcusd","event":"order_created"}
{"data":{"id":1722048938758147,"id_str":"1722048938758147","order_type":1,"datetime":"1709257079","microtimestamp":"1709257078864000","amount":0.01630048,"amount_str":"0.01630048","amount_traded":"0","amount_at_create":"0.01630048","price":61348,"price_str":"61348"},"channel":"live_orders_btcusd","event":"order_deleted"}
{"data":{"id":1722048896774147,"id_str":"1722048896774147","order_type":1,"datetime":"1709257079","microtimestamp":"1709257079105000","amount":0.1875,"amount_str":"0.18750000","amount_traded":"0","amount_at_create":"0.18750000","price":61457,"price_str":"61457"},"channel":"live_orders_btcusd","event":"order_deleted"}
{"data":{"id":1722048939905025,"id_str":"1722048939905025","order_type":1,"datetime":"1709257079","microtimestamp":"1709257079126000","amount":0.01630048,"amount_str":"0.01630048","amount_traded":"0","amount_at_create":"0.01630048","price":61348,"price_str":"61348"},"channel":"live_orders_btcusd","event":"order_created"}
{"data":{"id":1722048940019712,"id_str":"1722048940019712","order_type":0,"datetime":"1709257079","microtimestamp":"1709257079154000","amount":0.00040751,"amount_str":"0.00040751","amount_traded":"0","amount_at_create":"0.00040751","price":61334,"price_str":"61334"},"channel":"live_orders_btcusd","event":"order_created"}
{"data":{"id":1722048939905025,"id_str":"1722048939905025","order_type":1,"datetime":"1709257079","microtimestamp":"1709257079198000","amount":0.01630048,"amount_str":"0.01630048","amount_traded":"0","amount_at_create":"0.01630048","price":61348,"price_str":"61348"},"channel":"live_orders_btcusd","event":"order_deleted"}
{"data":{"id":1722048940376067,"id_str":"1722048940376067","order_type":1,"datetime":"1709257079","microtimestamp":"1709257079242000","amount":0.01629991,"amount_str":"0.01629991","amount_traded":"0","amount_at_create":"0.01629991","price":61350,"price_str":"61350"},"channel":"live_orders_btcusd","event":"order_created"}
{"data":{"id":1722048909676549,"id_str":"1722048909676549","order_type":1,"datetime":"1709257079","microtimestamp":"1709257079258000","amount":1.940436,"amount_str":"1.94043600","amount_traded":"0","amount_at_create":"1.94043600","price":61442,"price_str":"61442"},"channel":"live_orders_btcusd","event":"order_deleted"}
{"data":{"id":1722048895528960,"id_str":"1722048895528960","order_type":1,"datetime":"1709257079","microtimestamp":"1709257079258000","amount":0.815832,"amount_str":"0.81583200","amount_traded":"0","amount_at_create":"0.81583200","price":61384,"price_str":"61384"},"channel":"live_orders_btcusd","event":"order_deleted"}
{"data":{"id":1722048928534530,"id_str":"1722048928534530","order_type":0,"datetime":"1709257079","microtimestamp":"1709257079258000","amount":0.815832,"amount_str":"0.81583200","amount_traded":"0","amount_at_create":"0.81583200","price":61304,"price_str":"61304"},"channel":"live_orders_btcusd","event":"order_deleted"}
{"data":{"id":1722048895508481,"id_str":"1722048895508481","order_type":1,"datetime":"1709257079","microtimestamp":"1709257079258000","amount":1.445688,"amount_str":"1.44568800","amount_traded":"0","amount_at_create":"1.44568800","price":61410,"price_str":"61410"},"channel":"live_orders_btcusd","event":"order_deleted"}
{"data":{"id":1722048940376067,"id_str":"1722048940376067","order_type":1,"datetime":"1709257079","microtimestamp":"1709257079258000","amount":0.01629991,"amount_str":"0.01629991","amount_traded":"0","amount_at_create":"0.01629991","price":61350,"price_str":"61350"},"channel":"live_orders_btcusd","event":"order_deleted"}
{"data":{"id":1722048940621825,"id_str":"1722048940621825","order_type":1,"datetime":"1709257079","microtimestamp":"1709257079301000","amount":1.940436,"amount_str":"1.94043600","amount_traded":"0","amount_at_create":"1.94043600","price":61410,"price_str":"61410"},"channel":"live_orders_btcusd","event":"order_created"}
{"data":{"id":1722048940630016,"id_str":"1722048940630016","order_type":1,"datetime":"1709257079","microtimestamp":"1709257079303000","amount":1.445688,"amount_str":"1.44568800","amount_traded":"0","amount_at_create":"1.44568800","price":61388,"price_str":"61388"},"channel":"live_orders_btcusd","event":"order_created"}
{"data":{"id":1722048940638208,"id_str":"1722048940638208","order_type":1,"datetime":"1709257079","microtimestamp":"1709257079305000","amount":0.815832,"amount_str":"0.81583200","amount_traded":"0","amount_at_create":"0.81583200","price":61363,"price_str":"61363"},"channel":"live_orders_btcusd","event":"order_created"}
{"data":{"id":1722048940642304,"id_str":"1722048940642304","order_type":0,"datetime":"1709257079","microtimestamp":"1709257079306000","amount":0.815832,"amount_str":"0.81583200","amount_traded":"0","amount_at_create":"0.81583200","price":61322,"price_str":"61322"},"channel":"live_orders_btcusd","event":"order_created"}
{"data":{"id":1722048940019712,"id_str":"1722048940019712","order_type":0,"datetime":"1709257079","microtimestamp":"1709257079411000","amount":0.00040751,"amount_str":"0.00040751","amount_traded":"0","amount_at_create":"0.00040751","price":61334,"price_str":"61334"},"channel":"live_orders_btcusd","event":"order_deleted"}
{"data":{"id":1722048941166592,"id_str":"1722048941166592","order_type":1,"datetime":"1709257079","microtimestamp":"1709257079434000","amount":0.01630036,"amount_str":"0.01630036","amount_traded":"0","amount_at_create":"0.01630036","price":61349,"price_str":"61349"},"channel":"live_orders_btcusd","event":"order_created"}
{"data":{"id":1722048941506560,"id_str":"1722048941506560","order_type":0,"datetime":"1709257080","microtimestamp":"1709257079517000","amount":0.00040751,"amount_str":"0.00040751","amount_traded":"0","amount_at_create":"0.00040751","price":61335,"price_str":"61335"},"channel":"live_orders_btcusd","event":"order_created"}
{"data":{"id":1722048941506560,"id_str":"1722048941506560","order_type":0,"datetime":"1709257080","microtimestamp":"1709257079579000","amount":0.00040751,"amount_str":"0.00040751","amount_traded":"0","amount_at_create":"0.00040751","price":61335,"price_str":"61335"},"channel":"live_orders_btcusd","event":"order_deleted"}
{"data":{"id":1722048942043136,"id_str":"1722048942043136","order_type":0,"datetime":"1709257080","microtimestamp":"1709257079648000","amount":0.00040751,"amount_str":"0.00040751","amount_traded":"0","amount_at_create":"0.00040751","price":61334,"price_str":"61334"},"channel":"live_orders_btcusd","event":"order_created"}
{"data":{"id":1722048942043136,"id_str":"1722048942043136","order_type":0,"datetime":"1709257080","microtimestamp":"1709257079780000","amount":0.00040751,"amount_str":"0.00040751","amount_traded":"0","amount_at_create":"0.00040751","price":61334,"price_str":"61334"},"channel":"live_orders_btcusd","event":"order_deleted"}
{"data":{"id":1722048942866434,"id_str":"1722048942866434","order_type":0,"datetime":"1709257080","microtimestamp":"1709257079850000","amount":0.00040751,"amount_str":"0.00040751","amount_traded":"0","amount_at_create":"0.00040751","price":61335,"price_str":"61335"},"channel":"live_orders_btcusd","event":"order_created"}
{"data":{"id":1722048942866434,"id_str":"1722048942866434","order_type":0,"datetime":"1709257080","microtimestamp":"1709257079886000","amount":0.00040751,"amount_str":"0.00040751","amount_traded":"0","amount_at_create":"0.00040751","price":61335,"price_str":"61335"},"channel":"live_orders_btcusd","event":"order_deleted"}
{"data":{"id":1722048941166592,"id_str":"1722048941166592","order_type":1,"datetime":"1709257080","microtimestamp":"1709257079899000","amount":0.01630036,"amount_str":"0.01630036","amount_traded":"0","amount_at_create":"0.01630036","price":61349,"price_str":"61349"},"channel":"live_orders_btcusd","event":"order_deleted"}
{"data":{"id":1722048943255554,"id_str":"1722048943255554","order_type":1,"datetime":"1709257080","microtimestamp":"1709257079944000","amount":0.01630045,"amount_str":"0.01630045","amount_traded":"0","amount_at_create":"0.01630045","price":61348,"price_str":"61348"},"channel":"live_orders_btcusd","event":"order_created"}
{"data":{"id":1722048936837120,"id_str":"1722048936837120","order_type":0,"datetime":"1709257080","microtimestamp":"1709257079948000","amount":0.1875,"amount_str":"0.18750000","amount_traded":"0","amount_at_create":"0.18750000","price":61332,"price_str":"61332"},"channel":"live_orders_btcusd","event":"order_deleted"}
{"data":{"id":1722048943448064,"id_str":"1722048943448064","order_type":0,"datetime":"1709257080","microtimestamp":"1709257079991000","amount":0.00040751,"amount_str":"0.00040751","amount_traded":"0","amount_at_create":"0.00040751","price":61334,"price_str":"61334"},"channel":"live_orders_btcusd","event":"order_created"}
{"data":{"id":1722048938143746,"id_str":"1722048938143746","order_type":1,"datetime":"1709257080","microtimestamp":"1709257079999000","amount":0.4889953,"amount_str":"0.48899530","amount_traded":"0","amount_at_create":"0.48899530","price":61351,"price_str":"61351"},"channel":"live_orders_btcusd","event":"order_deleted"}
{"data":{"id":1722048943562752,"id_str":"1722048943562752","order_type":1,"datetime":"1709257080","microtimestamp":"1709257080019000","amount":0.1875,"amount_str":"0.18750000","amount_traded":"0","amount_at_create":"0.18750000","price":61362,"price_str":"61362"},"channel":"live_orders_btcusd","event":"order_created"}
{"data":{"id":1722048932675584,"id_str":"1722048932675584","order_type":0,"datetime":"1709257080","microtimestamp":"1709257080031000","amount":0.00815102,"amount_str":"0.00815102","amount_traded":"0","amount_at_create":"0.00815102","price":61339,"price_str":"61339"},"channel":"live_orders_btcusd","event":"order_deleted"}
{"data":{"id":1722048943656965,"id_str":"1722048943656965","order_type":1,"datetime":"1709257080","microtimestamp":"1709257080042000","amount":0.48899948,"amount_str":"0.48899948","amount_traded":"0","amount_at_create":"0.48899948","price":61350,"price_str":"61350"},"channel":"live_orders_btcusd","event":"order_created"}
{"data":{"id":1722048943693824,"id_str":"1722048943693824","order_type":1,"datetime":"1709257080","microtimestamp":"1709257080051000","amount":0.00487125,"amount_str":"0.00487125","amount_traded":"0","amount_at_create":"0.00487125","price":61354,"price_str":"61354"},"channel":"live_orders_btcusd","event":"order_created"}
{"data":{"id":1722048928239616,"id_str":"1722048928239616","order_type":0,"datetime":"1709257080","microtimestamp":"1709257080076000","amount":0.12188796,"amount_str":"0.12188796","amount_traded":"0","amount_at_create":"0.12188796","price":61273,"price_str":"61273"},"channel":"live_orders_btcusd","event":"order_deleted"}
{"data":{"id":1722048943448064,"id_str":"1722048943448064","order_type":0,"datetime":"1709257080","microtimestamp":"1709257080080000","amount":0.00040751,"amount_str":"0.00040751","amount_traded":"0","amount_at_create":"0.00040751","price":61334,"price_str":"61334"},"channel":"live_orders_btcusd","event":"order_deleted"}
{"data":{"id":1722048944013313,"id_str":"1722048944013313","order_type":0,"datetime":"1709257080","microtimestamp":"1709257080130000","amount":0.12188796,"amount_str":"0.12188796","amount_traded":"0","amount_at_create":"0.12188796","price":61288,"price_str":"61288"},"channel":"live_orders_btcusd","event":"order_created"}
{"data":{"id":1722048944455680,"id_str":"1722048944455680","order_type":0,"datetime":"1709257080","microtimestamp":"1709257080237000","amount":0.00040751,"amount_str":"0.00040751","amount_traded":"0","amount_at_create":"0.00040751","price":61335,"price_str":"61335"},"channel":"live_orders_btcusd","event":"order_created"}
{"data":{"id":1722048944455680,"id_str":"1722048944455680","order_type":0,"datetime":"1709257080","microtimestamp":"1709257080329000","amount":0.00040751,"amount_str":"0.00040751","amount_traded":"0","amount_at_create":"0.00040751","price":61335,"price_str":"61335"},"channel":"live_orders_btcusd","event":"order_deleted"}
{"data":{"id":1722048945680384,"id_str":"1722048945680384","order_type":0,"datetime":"1709257081","microtimestamp":"1709257080537000","amount":0.00040751,"amount_str":"0.00040751","amount_traded":"0","amount_at_create":"0.00040751","price":61334,"price_str":"61334"},"channel":"live_orders_btcusd","event":"order_created"}
{"data":{"id":1722048945680384,"id_str":"1722048945680384","order_type":0,"datetime":"1709257081","microtimestamp":"1709257080704000","amount":0.00040751,"amount_str":"0.00040751","amount_traded":"0","amount_at_create":"0.00040751","price":61334,"price_str":"61334"},"channel":"live_orders_btcusd","event":"order_deleted"}
{"data":{"id":1722048946835456,"id_str":"1722048946835456","order_type":0,"datetime":"1709257081","microtimestamp":"1709257080818000","amount":0.00040751,"amount_str":"0.00040751","amount_traded":"0","amount_at_create":"0.00040751","price":61335,"price_str":"61335"},"channel":"live_orders_btcusd","event":"order_created"}
{"data":{"id":1722048943693824,"id_str":"1722048943693824","order_type":1,"datetime":"1709257081","microtimestamp":"1709257080945000","amount":0.00487125,"amount_str":"0.00487125","amount_traded":"0","amount_at_create":"0.00487125","price":61354,"price_str":"61354"},"channel":"live_orders_btcusd","event":"order_deleted"}
{"data":{"id":1722048927920128,"id_str":"1722048927920128","order_type":1,"datetime":"1709257081","microtimestamp":"1709257080947000","amount":0.04374456,"amount_str":"0.04374456","amount_traded":"0","amount_at_create":"0.04374456","price":61361,"price_str":"61361"},"channel":"live_orders_btcusd","event":"order_deleted"}
{"data":{"id":1722048937762816,"id_str":"1722048937762816","order_type":0,"datetime":"1709257081","microtimestamp":"1709257080962000","amount":0.48908065,"amount_str":"0.48908065","amount_traded":"0","amount_at_create":"0.48908065","price":61339,"price_str":"61339"},"channel":"live_orders_btcusd","event":"order_deleted"}
{"data":{"id":1722048919126016,"id_str":"1722048919126016","order_type":0,"datetime":"1709257081","microtimestamp":"1709257080962000","amount":0.48930576,"amount_str":"0.48930576","amount_traded":"0","amount_at_create":"0.48930576","price":61311,"price_str":"61311"},"channel":"live_orders_btcusd","event":"order_deleted"}
{"data":{"id":1722048938405888,"id_str":"1722048938405888","order_type":0,"datetime":"1709257081","microtimestamp":"1709257080962000","amount":0.01630218,"amount_str":"0.01630218","amount_traded":"0","amount_at_create":"0.01630218","price":61341,"price_str":"61341"},"channel":"live_orders_btcusd","event":"order_deleted"}
{"data":{"id":1722048943656965,"id_str":"1722048943656965","order_type":1,"datetime":"1709257081","microtimestamp":"1709257080963000","amount":0.48899948,"amount_str":"0.48899948","amount_traded":"0","amount_at_create":"0.48899948","price":61350,"price_str":"61350"},"channel":"live_orders_btcusd","event":"order_deleted"}
{"data":{"id":1722048928137218,"id_str":"1722048928137218","order_type":0,"datetime":"1709257081","microtimestamp":"1709257080967000","amount":0.48942714,"amount_str":"0.48942714","amount_traded":"0","amount_at_create":"0.48942714","price":61296,"price_str":"61296"},"channel":"live_orders_btcusd","event":"order_deleted"}
{"data":{"id":1722048938766336,"id_str":"1722048938766336","order_type":0,"datetime":"1709257081","microtimestamp":"1709257080967000","amount":0.4891165,"amount_str":"0.48911650","amount_traded":"0","amount_at_create":"0.48911650","price":61335,"price_str":"61335"},"channel":"live_orders_btcusd","event":"order_deleted"}
{"data":{"id":1722048943255554,"id_str":"1722048943255554","order_type":1,"datetime":"1709257081","microtimestamp":"1709257080968000","amount":0.01630045,"amount_str":"0.01630045","amount_traded":"0","amount_at_create":"0.01630045","price":61348,"price_str":"61348"},"channel":"live_orders_btcusd","event":"order_deleted"}
{"data":{"id":1722048946835456,"id_str":"1722048946835456","order_type":0,"datetime":"1709257081","microtimestamp":"1709257080975000","amount":0.00040751,"amount_str":"0.00040751","amount_traded":"0","amount_at_create":"0.00040751","price":61335,"price_str":"61335"},"channel":"live_orders_btcusd","event":"order_deleted"}
{"data":{"id":1722048947486721,"id_str":"1722048947486721","order_type":0,"datetime":"1709257081","microtimestamp":"1709257080978000","amount":0.00815068,"amount_str":"0.00815068","amount_traded":"0","amount_at_create":"0.00815068","price":61340,"price_str":"61340"},"channel":"live_orders_btcusd","event":"order_created"}
{"data":{"id":1722048937336833,"id_str":"1722048937336833","order_type":1,"datetime":"1709257081","microtimestamp":"1709257080979000","amount":0.02161798,"amount_str":"0.02161798","amount_traded":"0","amount_at_create":"0.02161798","price":61364,"price_str":"61364"},"channel":"live_orders_btcusd","event":"order_deleted"}
{"data":{"id":1722048947515392,"id_str":"1722048947515392","order_type":0,"datetime":"1709257081","microtimestamp":"1709257080984000","amount":0.1875,"amount_str":"0.18750000","amount_traded":"0","amount_at_create":"0.18750000","price":61334,"price_str":"61334"},"channel":"live_orders_btcusd","event":"order_created"}
{"data":{"id":1722048943562752,"id_str":"1722048943562752","order_type":1,"datetime":"1709257081","microtimestamp":"1709257080990000","amount":0.1875,"amount_str":"0.18750000","amount_traded":"0","amount_at_create":"0.18750000","price":61362,"price_str":"61362"},"channel":"live_orders_btcusd","event":"order_deleted"}
{"data":{"id":1722048947666944,"id_str":"1722048947666944","order_type":1,"datetime":"1709257081","microtimestamp":"1709257081021000","amount":0.01629985,"amount_str":"0.01629985","amount_traded":"0","amount_at_create":"0.01629985","price":61351,"price_str":"61351"},"channel":"live_orders_btcusd","event":"order_created"}
{"data":{"id":1722048947515392,"id_str":"1722048947515392","order_type":0,"datetime":"1709257081","microtimestamp":"1709257081022000","amount":0.1875,"amount_str":"0.18750000","amount_traded":"0","amount_at_create":"0.18750000","price":61334,"price_str":"61334"},"channel":"live_orders_btcusd","event":"order_deleted"}
{"data":{"id":1722048947671043,"id_str":"1722048947671043","order_type":1,"datetime":"1709257081","microtimestamp":"1709257081023000","amount":0.48898916,"amount_str":"0.48898916","amount_traded":"0","amount_at_create":"0.48898916","price":61352,"price_str":"61352"},"channel":"live_orders_btcusd","event":"order_created"}
{"data":{"id":1722048947683332,"id_str":"1722048947683332","order_type":0,"datetime":"1709257081","microtimestamp":"1709257081026000","amount":0.0163014,"amount_str":"0.01630140","amount_traded":"0","amount_at_create":"0.01630140","price":61344,"price_str":"61344"},"channel":"live_orders_btcusd","event":"order_created"}
{"data":{"id":1722048947687430,"id_str":"1722048947687430","order_type":0,"datetime":"1709257081","microtimestamp":"1709257081027000","amount":0.48906132,"amount_str":"0.48906132","amount_traded":"0","amount_at_create":"0.48906132","price":61342,"price_str":"61342"},"channel":"live_orders_btcusd","event":"order_created"}
{"data":{"id":1722048947695618,"id_str":"1722048947695618","order_type":0,"datetime":"1709257081","microtimestamp":"1709257081028000","amount":0.48927694,"amount_str":"0.48927694","amount_traded":"0","amount_at_create":"0.48927694","price":61314,"price_str":"61314"},"channel":"live_orders_btcusd","event":"order_created"}
{"data":{"id":1722048947695621,"id_str":"1722048947695621","order_type":0,"datetime":"1709257081","microtimestamp":"1709257081029000","amount":0.48909518,"amount_str":"0.48909518","amount_traded":"0","amount_at_create":"0.48909518","price":61337,"price_str":"61337"},"channel":"live_orders_btcusd","event":"order_created"}
{"data":{"id":1722048947699712,"id_str":"1722048947699712","order_type":0,"datetime":"1709257081","microtimestamp":"1709257081029000","amount":0.48937361,"amount_str":"0.48937361","amount_traded":"0","amount_at_create":"0.48937361","price":61302,"price_str":"61302"},"channel":"live_orders_btcusd","event":"order_created"}
{"data":{"id":1722048916905984,"id_str":"1722048916905984","order_type":1,"datetime":"1709257081","microtimestamp":"1709257081033000","amount":0.00487133,"amount_str":"0.00487133","amount_traded":"0","amount_at_create":"0.00487133","price":61356,"price_str":"61356"},"channel":"live_orders_btcusd","event":"order_deleted"}
{"data":{"id":1722048947671043,"id_str":"1722048947671043","order_type":1,"datetime":"1709257081","microtimestamp":"1709257081045000","amount":0.48898916,"amount_str":"0.48898916","amount_traded":"0","amount_at_create":"0.48898916","price":61352,"price_str":"61352"},"channel":"live_orders_btcusd","event":"order_deleted"}
{"data":{"id":1722048947683332,"id_str":"1722048947683332","order_type":0,"datetime":"1709257081","microtimestamp":"1709257081045000","amount":0.0163014,"amount_str":"0.01630140","amount_traded":"0","amount_at_create":"0.01630140","price":61344,"price_str":"61344"},"channel":"live_orders_btcusd","event":"order_deleted"}
{"data":{"id":1722048947867648,"id_str":"1722048947867648","order_type":1,"datetime":"1709257081","microtimestamp":"1709257081071000","amount":0.00487105,"amount_str":"0.00487105","amount_traded":"0","amount_at_create":"0.00487105","price":61358,"price_str":"61358"},"channel":"live_orders_btcusd","event":"order_created"}
{"data":{"id":1722048947916800,"id_str":"1722048947916800","order_type":1,"datetime":"1709257081","microtimestamp":"1709257081083000","amount":0.02099506,"amount_str":"0.02099506","amount_traded":"0","amount_at_create":"0.02099506","price":61367,"price_str":"61367"},"channel":"live_orders_btcusd","event":"order_created"}
{"data":{"id":1722048948056064,"id_str":"1722048948056064","order_type":1,"datetime":"1709257081","microtimestamp":"1709257081116000","amount":0.03062118,"amount_str":"0.03062118","amount_traded":"0","amount_at_create":"0.03062118","price":61365,"price_str":"61365"},"channel":"live_orders_btcusd","event":"order_created"}
{"data":{"id":1722048948080642,"id_str":"1722048948080642","order_type":0,"datetime":"1709257081","microtimestamp":"1709257081122000","amount":0.01630154,"amount_str":"0.01630154","amount_traded":"0","amount_at_create":"0.01630154","price":61343,"price_str":"61343"},"channel":"live_orders_btcusd","event":"order_created"}
{"data":{"id":1722048948097025,"id_str":"1722048948097025","order_type":0,"datetime":"1709257081","microtimestamp":"1709257081127000","amount":0.00040751,"amount_str":"0.00040751","amount_traded":"0","amount_at_create":"0.00040751","price":61334,"price_str":"61334"},"channel":"live_orders_btcusd","event":"order_created"}
{"data":{"id":1722048948097025,"id_str":"1722048948097025","order_type":0,"datetime":"1709257081","microtimestamp":"1709257081227000","amount":0.00040751,"amount_str":"0.00040751","amount_traded":"0","amount_at_create":"0.00040751","price":61334,"price_str":"61334"},"channel":"live_orders_btcusd","event":"order_deleted"}
{"data":{"id":1722048948609027,"id_str":"1722048948609027","order_type":1,"datetime":"1709257081","microtimestamp":"1709257081252000","amount":0.48898045,"amount_str":"0.48898045","amount_traded":"0","amount_at_create":"0.48898045","price":61353,"price_str":"61353"},"channel":"live_orders_btcusd","event":"order_created"}
{"data":{"id":1722048947666944,"id_str":"1722048947666944","order_type":1,"datetime":"1709257081","microtimestamp":"1709257081399000","amount":0.01629985,"amount_str":"0.01629985","amount_traded":"0","amount_at_create":"0.01629985","price":61351,"price_str":"61351"},"channel":"live_orders_btcusd","event":"order_deleted"}
{"data":{"id":1722048948609027,"id_str":"1722048948609027","order_type":1,"datetime":"1709257081","microtimestamp":"1709257081399000","amount":0.48898045,"amount_str":"0.48898045","amount_traded":"0","amount_at_create":"0.48898045","price":61353,"price_str":"61353"},"channel":"live_orders_btcusd","event":"order_deleted"}
{"data":{"id":1722048949342208,"id_str":"1722048949342208","order_type":0,"datetime":"1709257081","microtimestamp":"1709257081430000","amount":0.00040751,"amount_str":"0.00040751","amount_traded":"0","amount_at_create":"0.00040751","price":61335,"price_str":"61335"},"channel":"live_orders_btcusd","event":"order_created"}
{"data":{"id":1722048949411840,"id_str":"1722048949411840","order_type":1,"datetime":"1709257081","microtimestamp":"1709257081447000","amount":0.01630001,"amount_str":"0.01630001","amount_traded":"0","amount_at_create":"0.01630001","price":61350,"price_str":"61350"},"channel":"live_orders_btcusd","event":"order_created"}
