{"data":{"id":1722048949432320,"id_str":"1722048949432320","order_type":1,"datetime":"1709257081","microtimestamp":"1709257081452000","amount":0.1875,"amount_str":"0.18750000","amount_traded":"0","amount_at_create":"0.18750000","price":61362,"price_str":"61362"},"channel":"live_orders_btcusd","event":"order_created"}
{"data":{"id":1722048949604354,"id_str":"1722048949604354","order_type":1,"datetime":"1709257081","microtimestamp":"1709257081494000","amount":0.48896567,"amount_str":"0.48896567","amount_traded":"0","amount_at_create":"0.48896567","price":61354,"price_str":"61354"},"channel":"live_orders_btcusd","event":"order_created"}
{"data":{"id":1722048949604354,"id_str":"1722048949604354","order_type":1,"datetime":"1709257082","microtimestamp":"1709257081510000","amount":0.48896567,"amount_str":"0.48896567","amount_traded":"0","amount_at_create":"0.48896567","price":61354,"price_str":"61354"},"channel":"live_orders_btcusd","event":"order_deleted"}
{"data":{"id":1722048949862401,"id_str":"1722048949862401","order_type":1,"datetime":"1709257082","microtimestamp":"1709257081557000","amount":0.16265164,"amount_str":"0.16265164","amount_traded":"0","amount_at_create":"0.16265164","price":61482,"price_str":"61482"},"channel":"live_orders_btcusd","event":"order_created"}
{"data":{"id":1722048947687430,"id_str":"1722048947687430","order_type":0,"datetime":"1709257082","microtimestamp":"1709257081600000","amount":0.48906132,"amount_str":"0.48906132","amount_traded":"0","amount_at_create":"0.48906132","price":61342,"price_str":"61342"},"channel":"live_orders_btcusd","event":"order_deleted"}
{"data":{"id":1722048949342208,"id_str":"1722048949342208","order_type":0,"datetime":"1709257082","microtimestamp":"1709257081607000","amount":0.00040751,"amount_str":"0.00040751","amount_traded":"0","amount_at_create":"0.00040751","price":61335,"price_str":"61335"},"channel":"live_orders_btcusd","event":"order_deleted"}
{"data":{"id":1722048950231040,"id_str":"1722048950231040","order_type":0,"datetime":"1709257082","microtimestamp":"1709257081647000","amount":0.48907363,"amount_str":"0.48907363","amount_traded":"0","amount_at_create":"0.48907363","price":61340,"price_str":"61340"},"channel":"live_orders_btcusd","event":"order_created"}
{"data":{"id":1722048949411840,"id_str":"1722048949411840","order_type":1,"datetime":"1709257082","microtimestamp":"1709257081667000","amount":0.01630001,"amount_str":"0.01630001","amount_traded":"0","amount_at_create":"0.01630001","price":61350,"price_str":"61350"},"channel":"live_orders_btcusd","event":"order_deleted"}
{"data":{"id":1722048948080642,"id_str":"1722048948080642","order_type":0,"datetime":"1709257082","microtimestamp":"1709257081704000","amount":0.01630154,"amount_str":"0.01630154","amount_traded":"0","amount_at_create":"0.01630154","price":61343,"price_str":"61343"},"channel":"live_orders_btcusd","event":"order_deleted"}
{"data":{"id":1722048950484992,"id_str":"1722048950484992","order_type":1,"datetime":"1709257082","microtimestamp":"1709257081709000","amount":0.48898242,"amount_str":"0.48898242","amount_traded":"0","amount_at_create":"0.48898242","price":61352,"price_str":"61352"},"channel":"live_orders_btcusd","event":"order_created"}
{"data":{"id":1722048950501376,"id_str":"1722048950501376","order_type":1,"datetime":"1709257082","microtimestamp":"1709257081713000","amount":0.0163002,"amount_str":"0.01630020","amount_traded":"0","amount_at_create":"0.01630020","price":61349,"price_str":"61349"},"channel":"live_orders_btcusd","event":"order_created"}
{"data":{"id":1722048950484992,"id_str":"1722048950484992","order_type":1,"datetime":"1709257082","microtimestamp":"1709257081728000","amount":0.48898242,"amount_str":"0.48898242","amount_traded":"0","amount_at_create":"0.48898242","price":61352,"price_str":"61352"},"channel":"live_orders_btcusd","event":"order_deleted"}
{"data":{"id":1722048950640642,"id_str":"1722048950640642","order_type":0,"datetime":"1709257082","microtimestamp":"1709257081748000","amount":0.00040751,"amount_str":"0.00040751","amount_traded":"0","amount_at_create":"0.00040751","price":61334,"price_str":"61334"},"channel":"live_orders_btcusd","event":"order_created"}
{"data":{"id":1722048950759426,"id_str":"1722048950759426","order_type":0,"datetime":"1709257082","microtimestamp":"1709257081776000","amount":0.01630208,"amount_str":"0.01630208","amount_traded":"0","amount_at_create":"0.01630208","price":61341,"price_str":"61341"},"channel":"live_orders_btcusd","event":"order_created"}
{"data":{"id":1722048950501376,"id_str":"1722048950501376","order_type":1,"datetime":"1709257082","microtimestamp":"1709257081802000","amount":0.0163002,"amount_str":"0.01630020","amount_traded":"0","amount_at_create":"0.01630020","price":61349,"price_str":"61349"},"channel":"live_orders_btcusd","event":"order_deleted"}
{"data":{"id":1722048950231040,"id_str":"1722048950231040","order_type":0,"datetime":"1709257082","microtimestamp":"1709257081802000","amount":0.48907363,"amount_str":"0.48907363","amount_traded":"0","amount_at_create":"0.48907363","price":61340,"price_str":"61340"},"channel":"live_orders_btcusd","event":"order_deleted"}
{"data":{"id":1722048947695621,"id_str":"1722048947695621","order_type":0,"datetime":"1709257082","microtimestamp":"1709257081802000","amount":0.48909518,"amount_str":"0.48909518","amount_traded":"0","amount_at_create":"0.48909518","price":61337,"price_str":"61337"},"channel":"live_orders_btcusd","event":"order_deleted"}
{"data":{"id":1722048937574401,"id_str":"1722048937574401","order_type":1,"datetime":"1709257082","microtimestamp":"1709257081803000","amount":0.48896086,"amount_str":"0.48896086","amount_traded":"0","amount_at_create":"0.48896086","price":61355,"price_str":"61355"},"channel":"live_orders_btcusd","event":"order_deleted"}
{"data":{"id":1722048951070722,"id_str":"1722048951070722","order_type":1,"datetime":"1709257082","microtimestamp":"1709257081852000","amount":0.48896567,"amount_str":"0.48896567","amount_traded":"0","amount_at_create":"0.48896567","price":61354,"price_str":"61354"},"channel":"live_orders_btcusd","event":"order_created"}
{"data":{"id":1722048951070723,"id_str":"1722048951070723","order_type":0,"datetime":"1709257082","microtimestamp":"1709257081852000","amount":0.48908762,"amount_str":"0.48908762","amount_traded":"0","amount_at_create":"0.48908762","price":61338,"price_str":"61338"},"channel":"live_orders_btcusd","event":"order_created"}
{"data":{"id":1722048951083009,"id_str":"1722048951083009","order_type":1,"datetime":"1709257082","microtimestamp":"1709257081855000","amount":0.01630063,"amount_str":"0.01630063","amount_traded":"0","amount_at_create":"0.01630063","price":61348,"price_str":"61348"},"channel":"live_orders_btcusd","event":"order_created"}
{"data":{"id":1722048951095296,"id_str":"1722048951095296","order_type":0,"datetime":"1709257082","microtimestamp":"1709257081858000","amount":0.48911932,"amount_str":"0.48911932","amount_traded":"0","amount_at_create":"0.48911932","price":61334,"price_str":"61334"},"channel":"live_orders_btcusd","event":"order_created"}
{"data":{"id":1722048951107589,"id_str":"1722048951107589","order_type":1,"datetime":"1709257082","microtimestamp":"1709257081862000","amount":0.00487125,"amount_str":"0.00487125","amount_traded":"0","amount_at_create":"0.00487125","price":61356,"price_str":"61356"},"channel":"live_orders_btcusd","event":"order_created"}
{"data":{"id":1722048951115778,"id_str":"1722048951115778","order_type":1,"datetime":"1709257082","microtimestamp":"1709257081864000","amount":0.1875,"amount_str":"0.18750000","amount_traded":"0","amount_at_create":"0.18750000","price":61701,"price_str":"61701"},"channel":"live_orders_btcusd","event":"order_created"}
{"data":{"id":1722048951070722,"id_str":"1722048951070722","order_type":1,"datetime":"1709257082","microtimestamp":"1709257081874000","amount":0.48896567,"amount_str":"0.48896567","amount_traded":"0","amount_at_create":"0.48896567","price":61354,"price_str":"61354"},"channel":"live_orders_btcusd","event":"order_deleted"}
{"data":{"id":1722048951083009,"id_str":"1722048951083009","order_type":1,"datetime":"1709257082","microtimestamp":"1709257081899000","amount":0.01630063,"amount_str":"0.01630063","amount_traded":"0","amount_at_create":"0.01630063","price":61348,"price_str":"61348"},"channel":"live_orders_btcusd","event":"order_deleted"}
{"data":{"id":1722048951357440,"id_str":"1722048951357440","order_type":1,"datetime":"1709257082","microtimestamp":"1709257081922000","amount":0.48894176,"amount_str":"0.48894176","amount_traded":"0","amount_at_create":"0.48894176","price":61357,"price_str":"61357"},"channel":"live_orders_btcusd","event":"order_created"}
{"data":{"id":1722048951357440,"id_str":"1722048951357440","order_type":1,"datetime":"1709257082","microtimestamp":"1709257081938000","amount":0.48894176,"amount_str":"0.48894176","amount_traded":"0","amount_at_create":"0.48894176","price":61357,"price_str":"61357"},"channel":"live_orders_btcusd","event":"order_deleted"}
{"data":{"id":1722048950640642,"id_str":"1722048950640642","order_type":0,"datetime":"1709257082","microtimestamp":"1709257081970000","amount":0.00040751,"amount_str":"0.00040751","amount_traded":"0","amount_at_create":"0.00040751","price":61334,"price_str":"61334"},"channel":"live_orders_btcusd","event":"order_deleted"}
{"data":{"id":1722048951623680,"id_str":"1722048951623680","order_type":1,"datetime":"1709257082","microtimestamp":"1709257081987000","amount":0.01630079,"amount_str":"0.01630079","amount_traded":"0","amount_at_create":"0.01630079","price":61347,"price_str":"61347"},"channel":"live_orders_btcusd","event":"order_created"}
{"data":{"id":1722002670313475,"id_str":"1722002670313475","order_type":0,"datetime":"1709257082","microtimestamp":"1709257082143000","amount":0.00033432,"amount_str":"0.00033432","amount_traded":"0","amount_at_create":"0.00033432","price":59703,"price_str":"59703"},"channel":"live_orders_btcusd","event":"order_deleted"}
{"data":{"id":1722048952365056,"id_str":"1722048952365056","order_type":0,"datetime":"1709257082","microtimestamp":"1709257082168000","amount":0.00040751,"amount_str":"0.00040751","amount_traded":"0","amount_at_create":"0.00040751","price":61335,"price_str":"61335"},"channel":"live_orders_btcusd","event":"order_created"}
{"data":{"id":1722048844414978,"id_str":"1722048844414978","order_type":1,"datetime":"1709257082","microtimestamp":"1709257082324000","amount":0.1875,"amount_str":"0.18750000","amount_traded":"0","amount_at_create":"0.18750000","price":61522,"price_str":"61522"},"channel":"live_orders_btcusd","event":"order_deleted"}
{"data":{"id":1722048947916800,"id_str":"1722048947916800","order_type":1,"datetime":"1709257082","microtimestamp":"1709257082492000","amount":0.02099506,"amount_str":"0.02099506","amount_traded":"0","amount_at_create":"0.02099506","price":61367,"price_str":"61367"},"channel":"live_orders_btcusd","event":"order_deleted"}
{"data":{"id":1722048915595266,"id_str":"1722048915595266","order_type":0,"datetime":"1709257082","microtimestamp":"1709257082494000","amount":3.06689844,"amount_str":"3.06689844","amount_traded":"0","amount_at_create":"3.06689844","price":61333,"price_str":"61333"},"channel":"live_orders_btcusd","event":"order_deleted"}
{"data":{"id":1722048937185282,"id_str":"1722048937185282","order_type":1,"datetime":"1709257083","microtimestamp":"1709257082508000","amount":0.4887891,"amount_str":"0.48878910","amount_traded":"0","amount_at_create":"0.48878910","price":61377,"price_str":"61377"},"channel":"live_orders_btcusd","event":"order_deleted"}
{"data":{"id":1722048951070723,"id_str":"1722048951070723","order_type":0,"datetime":"1709257083","microtimestamp":"1709257082508000","amount":0.48908762,"amount_str":"0.48908762","amount_traded":"0","amount_at_create":"0.48908762","price":61338,"price_str":"61338"},"channel":"live_orders_btcusd","event":"order_deleted"}
{"data":{"id":1722048947486721,"id_str":"1722048947486721","order_type":0,"datetime":"1709257083","microtimestamp":"1709257082509000","amount":0.00815068,"amount_str":"0.00815068","amount_traded":"0","amount_at_create":"0.00815068","price":61340,"price_str":"61340"},"channel":"live_orders_btcusd","event":"order_deleted"}
{"data":{"id":1722048951623680,"id_str":"1722048951623680","order_type":1,"datetime":"1709257083","microtimestamp":"1709257082510000","amount":0.01630079,"amount_str":"0.01630079","amount_traded":"0","amount_at_create":"0.01630079","price":61347,"price_str":"61347"},"channel":"live_orders_btcusd","event":"order_deleted"}
{"data":{"id":1722048950759426,"id_str":"1722048950759426","order_type":0,"datetime":"1709257083","microtimestamp":"1709257082510000","amount":0.01630208,"amount_str":"0.01630208","amount_traded":"0","amount_at_create":"0.01630208","price":61341,"price_str":"61341"},"channel":"live_orders_btcusd","event":"order_deleted"}
{"data":{"id":1722048919969794,"id_str":"1722048919969794","order_type":0,"datetime":"1709257083","microtimestamp":"1709257082516000","amount":0.04893,"amount_str":"0.04893000","amount_traded":"0","amount_at_create":"0.04893000","price":61320,"price_str":"61320"},"channel":"live_orders_btcusd","event":"order_deleted"}
{"data":{"id":1722048947867648,"id_str":"1722048947867648","order_type":1,"datetime":"1709257083","microtimestamp":"1709257082516000","amount":0.00487105,"amount_str":"0.00487105","amount_traded":"0","amount_at_create":"0.00487105","price":61358,"price_str":"61358"},"channel":"live_orders_btcusd","event":"order_deleted"}
{"data":{"id":1722048948056064,"id_str":"1722048948056064","order_type":1,"datetime":"1709257083","microtimestamp":"1709257082517000","amount":0.03062118,"amount_str":"0.03062118","amount_traded":"0","amount_at_create":"0.03062118","price":61365,"price_str":"61365"},"channel":"live_orders_btcusd","event":"order_deleted"}
{"data":{"id":1722048947695618,"id_str":"1722048947695618","order_type":0,"datetime":"1709257083","microtimestamp":"1709257082525000","amount":0.48927694,"amount_str":"0.48927694","amount_traded":"0","amount_at_create":"0.48927694","price":61314,"price_str":"61314"},"channel":"live_orders_btcusd","event":"order_deleted"}
{"data":{"id":1722048951095296,"id_str":"1722048951095296","order_type":0,"datetime":"1709257083","microtimestamp":"1709257082526000","amount":0.48911932,"amount_str":"0.48911932","amount_traded":"0","amount_at_create":"0.48911932","price":61334,"price_str":"61334"},"channel":"live_orders_btcusd","event":"order_deleted"}
{"data":{"id":1722048937951237,"id_str":"1722048937951237","order_type":0,"datetime":"1709257083","microtimestamp":"1709257082526000","amount":0.48916786,"amount_str":"0.48916786","amount_traded":"0","amount_at_create":"0.48916786","price":61328,"price_str":"61328"},"channel":"live_orders_btcusd","event":"order_deleted"}
{"data":{"id":1722048632823808,"id_str":"1722048632823808","order_type":1,"datetime":"1709257083","microtimestamp":"1709257082527000","amount":0.10343362,"amount_str":"0.10343362","amount_traded":"0","amount_at_create":"0.10343362","price":61517,"price_str":"61517"},"channel":"live_orders_btcusd","event":"order_deleted"}
{"data":{"id":1722048947699712,"id_str":"1722048947699712","order_type":0,"datetime":"1709257083","microtimestamp":"1709257082527000","amount":0.48937361,"amount_str":"0.48937361","amount_traded":"0","amount_at_create":"0.48937361","price":61302,"price_str":"61302"},"channel":"live_orders_btcusd","event":"order_deleted"}
{"data":{"id":1722048933056516,"id_str":"1722048933056516","order_type":1,"datetime":"1709257083","microtimestamp":"1709257082527000","amount":0.48891303,"amount_str":"0.48891303","amount_traded":"0","amount_at_create":"0.48891303","price":61361,"price_str":"61361"},"channel":"live_orders_btcusd","event":"order_deleted"}
{"data":{"id":1722048953856004,"id_str":"1722048953856004","order_type":1,"datetime":"1709257083","microtimestamp":"1709257082533000","amount":0.03062118,"amount_str":"0.03062118","amount_traded":"0","amount_at_create":"0.03062118","price":61360,"price_str":"61360"},"channel":"live_orders_btcusd","event":"order_created"}
{"data":{"id":1722048953860099,"id_str":"1722048953860099","order_type":1,"datetime":"1709257083","microtimestamp":"1709257082533000","amount":0.00487133,"amount_str":"0.00487133","amount_traded":"0","amount_at_create":"0.00487133","price":61354,"price_str":"61354"},"channel":"live_orders_btcusd","event":"order_created"}
{"data":{"id":1722048925147136,"id_str":"1722048925147136","order_type":1,"datetime":"1709257083","microtimestamp":"1709257082534000","amount":0.16273602,"amount_str":"0.16273602","amount_traded":"0","amount_at_create":"0.16273602","price":61450,"price_str":"61450"},"channel":"live_orders_btcusd","event":"order_deleted"}
{"data":{"id":1722048917250048,"id_str":"1722048917250048","order_type":1,"datetime":"1709257083","microtimestamp":"1709257082538000","amount":0.48870387,"amount_str":"0.48870387","amount_traded":"0","amount_at_create":"0.48870387","price":61387,"price_str":"61387"},"channel":"live_orders_btcusd","event":"order_deleted"}
{"data":{"id":1722048535883780,"id_str":"1722048535883780","order_type":0,"datetime":"1709257083","microtimestamp":"1709257082538000","amount":0.1875,"amount_str":"0.18750000","amount_traded":"0","amount_at_create":"0.18750000","price":61325,"price_str":"61325"},"channel":"live_orders_btcusd","event":"order_deleted"}
{"data":{"id":1722048915660800,"id_str":"1722048915660800","order_type":1,"datetime":"1709257083","microtimestamp":"1709257082539000","amount":0.93122736,"amount_str":"0.93122736","amount_traded":"0","amount_at_create":"0.93122736","price":61393,"price_str":"61393"},"channel":"live_orders_btcusd","event":"order_deleted"}
{"data":{"id":1722048951107589,"id_str":"1722048951107589","order_type":1,"datetime":"1709257083","microtimestamp":"1709257082540000","amount":0.00487125,"amount_str":"0.00487125","amount_traded":"0","amount_at_create":"0.00487125","price":61356,"price_str":"61356"},"channel":"live_orders_btcusd","event":"order_deleted"}
{"data":{"id":1722048766492679,"id_str":"1722048766492679","order_type":0,"datetime":"1709257083","microtimestamp":"1709257082541000","amount":0.5,"amount_str":"0.50000000","amount_traded":"0","amount_at_create":"0.50000000","price":61323,"price_str":"61323"},"channel":"live_orders_btcusd","event":"order_deleted"}
{"data":{"id":1722048953901058,"id_str":"1722048953901058","order_type":0,"datetime":"1709257083","microtimestamp":"1709257082543000","amount":3.0671985,"amount_str":"3.06719850","amount_traded":"0","amount_at_create":"3.06719850","price":61327,"price_str":"61327"},"channel":"live_orders_btcusd","event":"order_created"}
{"data":{"id":1722048944013313,"id_str":"1722048944013313","order_type":0,"datetime":"1709257083","microtimestamp":"1709257082548000","amount":0.12188796,"amount_str":"0.12188796","amount_traded":"0","amount_at_create":"0.12188796","price":61288,"price_str":"61288"},"channel":"live_orders_btcusd","event":"order_deleted"}
{"data":{"id":1722048953901058,"id_str":"1722048953901058","order_type":0,"datetime":"1709257083","microtimestamp":"1709257082550000","amount":3.0671985,"amount_str":"3.06719850","amount_traded":"0","amount_at_create":"3.06719850","price":61327,"price_str":"61327"},"channel":"live_orders_btcusd","event":"order_deleted"}
{"data":{"id":1722048953954310,"id_str":"1722048953954310","order_type":1,"datetime":"1709257083","microtimestamp":"1709257082557000","amount":0.00487133,"amount_str":"0.00487133","amount_traded":"0","amount_at_create":"0.00487133","price":61352,"price_str":"61352"},"channel":"live_orders_btcusd","event":"order_created"}
{"data":{"id":1722048953856004,"id_str":"1722048953856004","order_type":1,"datetime":"1709257083","microtimestamp":"1709257082562000","amount":0.03062118,"amount_str":"0.03062118","amount_traded":"0","amount_at_create":"0.03062118","price":61360,"price_str":"61360"},"channel":"live_orders_btcusd","event":"order_deleted"}
{"data":{"id":1722048928243712,"id_str":"1722048928243712","order_type":0,"datetime":"1709257083","microtimestamp":"1709257082563000","amount":0.00815095,"amount_str":"0.00815095","amount_traded":"0","amount_at_create":"0.00815095","price":61337,"price_str":"61337"},"channel":"live_orders_btcusd","event":"order_deleted"}
{"data":{"id":1722048953987079,"id_str":"1722048953987079","order_type":1,"datetime":"1709257083","microtimestamp":"1709257082565000","amount":0.02310158,"amount_str":"0.02310158","amount_traded":"0","amount_at_create":"0.02310158","price":61365,"price_str":"61365"},"channel":"live_orders_btcusd","event":"order_created"}
{"data":{"id":1722048954032134,"id_str":"1722048954032134","order_type":1,"datetime":"1709257083","microtimestamp":"1709257082575000","amount":0.03062118,"amount_str":"0.03062118","amount_traded":"0","amount_at_create":"0.03062118","price":61359,"price_str":"61359"},"channel":"live_orders_btcusd","event":"order_created"}
{"data":{"id":1722048953987079,"id_str":"1722048953987079","order_type":1,"datetime":"1709257083","microtimestamp":"1709257082577000","amount":0.02310158,"amount_str":"0.02310158","amount_traded":"0","amount_at_create":"0.02310158","price":61365,"price_str":"61365"},"channel":"live_orders_btcusd","event":"order_deleted"}
{"data":{"id":1722048954040329,"id_str":"1722048954040329","order_type":1,"datetime":"1709257083","microtimestamp":"1709257082578000","amount":0.1875,"amount_str":"0.18750000","amount_traded":"0","amount_at_create":"0.18750000","price":61355,"price_str":"61355"},"channel":"live_orders_btcusd","event":"order_created"}
{"data":{"id":1722048917856257,"id_str":"1722048917856257","order_type":0,"datetime":"1709257083","microtimestamp":"1709257082580000","amount":0.04875518,"amount_str":"0.04875518","amount_traded":"0","amount_at_create":"0.04875518","price":61317,"price_str":"61317"},"channel":"live_orders_btcusd","event":"order_deleted"}
{"data":{"id":1722048954064899,"id_str":"1722048954064899","order_type":0,"datetime":"1709257083","microtimestamp":"1709257082584000","amount":0.00815075,"amount_str":"0.00815075","amount_traded":"0","amount_at_create":"0.00815075","price":61335,"price_str":"61335"},"channel":"live_orders_btcusd","event":"order_created"}
{"data":{"id":1722048766390281,"id_str":"1722048766390281","order_type":1,"datetime":"1709257083","microtimestamp":"1709257082587000","amount":2.473578,"amount_str":"2.47357800","amount_traded":"0","amount_at_create":"2.47357800","price":61503,"price_str":"61503"},"channel":"live_orders_btcusd","event":"order_deleted"}
{"data":{"id":1722048954089477,"id_str":"1722048954089477","order_type":1,"datetime":"1709257083","microtimestamp":"1709257082589000","amount":0.14861154,"amount_str":"0.14861154","amount_traded":"0","amount_at_create":"0.14861154","price":61478,"price_str":"61478"},"channel":"live_orders_btcusd","event":"order_created"}
{"data":{"id":1722048954093570,"id_str":"1722048954093570","order_type":0,"datetime":"1709257083","microtimestamp":"1709257082590000","amount":0.04893,"amount_str":"0.04893000","amount_traded":"0","amount_at_create":"0.04893000","price":61313,"price_str":"61313"},"channel":"live_orders_btcusd","event":"order_created"}
{"data":{"id":1722048954093574,"id_str":"1722048954093574","order_type":1,"datetime":"1709257083","microtimestamp":"1709257082591000","amount":0.48902943,"amount_str":"0.48902943","amount_traded":"0","amount_at_create":"0.48902943","price":61346,"price_str":"61346"},"channel":"live_orders_btcusd","event":"order_created"}
{"data":{"id":1722048954093576,"id_str":"1722048954093576","order_type":1,"datetime":"1709257083","microtimestamp":"1709257082591000","amount":0.4888539,"amount_str":"0.48885390","amount_traded":"0","amount_at_create":"0.48885390","price":61369,"price_str":"61369"},"channel":"live_orders_btcusd","event":"order_created"}
{"data":{"id":1722048954101760,"id_str":"1722048954101760","order_type":1,"datetime":"1709257083","microtimestamp":"1709257082592000","amount":0.48896607,"amount_str":"0.48896607","amount_traded":"0","amount_at_create":"0.48896607","price":61354,"price_str":"61354"},"channel":"live_orders_btcusd","event":"order_created"}
{"data":{"id":1722048954105856,"id_str":"1722048954105856","order_type":0,"datetime":"1709257083","microtimestamp":"1709257082593000","amount":0.48914307,"amount_str":"0.48914307","amount_traded":"0","amount_at_create":"0.48914307","price":61331,"price_str":"61331"},"channel":"live_orders_btcusd","event":"order_created"}
{"data":{"id":1722048954105860,"id_str":"1722048954105860","order_type":1,"datetime":"1709257083","microtimestamp":"1709257082594000","amount":0.16275718,"amount_str":"0.16275718","amount_traded":"0","amount_at_create":"0.16275718","price":61442,"price_str":"61442"},"channel":"live_orders_btcusd","event":"order_created"}
{"data":{"id":1722048954118144,"id_str":"1722048954118144","order_type":1,"datetime":"1709257083","microtimestamp":"1709257082596000","amount":0.48874957,"amount_str":"0.48874957","amount_traded":"0","amount_at_create":"0.48874957","price":61382,"price_str":"61382"},"channel":"live_orders_btcusd","event":"order_created"}
{"data":{"id":1722048954118147,"id_str":"1722048954118147","order_type":1,"datetime":"1709257083","microtimestamp":"1709257082596000","amount":0.4890276,"amount_str":"0.48902760","amount_traded":"0","amount_at_create":"0.48902760","price":61347,"price_str":"61347"},"channel":"live_orders_btcusd","event":"order_created"}
{"data":{"id":1722048954122242,"id_str":"1722048954122242","order_type":0,"datetime":"1709257083","microtimestamp":"1709257082597000","amount":0.48923321,"amount_str":"0.48923321","amount_traded":"0","amount_at_create":"0.48923321","price":61320,"price_str":"61320"},"channel":"live_orders_btcusd","event":"order_created"}
{"data":{"id":1722048954126342,"id_str":"1722048954126342","order_type":1,"datetime":"1709257083","microtimestamp":"1709257082599000","amount":0.01630204,"amount_str":"0.01630204","amount_traded":"0","amount_at_create":"0.01630204","price":61342,"price_str":"61342"},"channel":"live_orders_btcusd","event":"order_created"}
{"data":{"id":1722048954130438,"id_str":"1722048954130438","order_type":0,"datetime":"1709257083","microtimestamp":"1709257082599000","amount":3.06724851,"amount_str":"3.06724851","amount_traded":"0","amount_at_create":"3.06724851","price":61326,"price_str":"61326"},"channel":"live_orders_btcusd","event":"order_created"}
{"data":{"id":1722048954130439,"id_str":"1722048954130439","order_type":0,"datetime":"1709257083","microtimestamp":"1709257082599000","amount":0.0163042,"amount_str":"0.01630420","amount_traded":"0","amount_at_create":"0.01630420","price":61333,"price_str":"61333"},"channel":"live_orders_btcusd","event":"order_created"}
{"data":{"id":1722048952365056,"id_str":"1722048952365056","order_type":0,"datetime":"1709257083","microtimestamp":"1709257082603000","amount":0.00040751,"amount_str":"0.00040751","amount_traded":"0","amount_at_create":"0.00040751","price":61335,"price_str":"61335"},"channel":"live_orders_btcusd","event":"order_deleted"}
{"data":{"id":1722048954032134,"id_str":"1722048954032134","order_type":1,"datetime":"1709257083","microtimestamp":"1709257082610000","amount":0.03062118,"amount_str":"0.03062118","amount_traded":"0","amount_at_create":"0.03062118","price":61359,"price_str":"61359"},"channel":"live_orders_btcusd","event":"order_deleted"}
{"data":{"id":1722048915898371,"id_str":"1722048915898371","order_type":1,"datetime":"1709257083","microtimestamp":"1709257082612000","amount":0.04875518,"amount_str":"0.04875518","amount_traded":"0","amount_at_create":"0.04875518","price":61379,"price_str":"61379"},"channel":"live_orders_btcusd","event":"order_deleted"}
{"data":{"id":1722048954187780,"id_str":"1722048954187780","order_type":1,"datetime":"1709257083","microtimestamp":"1709257082613000","amount":0.93133633,"amount_str":"0.93133633","amount_traded":"0","amount_at_create":"0.93133633","price":61386,"price_str":"61386"},"channel":"live_orders_btcusd","event":"order_created"}
{"data":{"id":1722048954130439,"id_str":"1722048954130439","order_type":0,"datetime":"1709257083","microtimestamp":"1709257082615000","amount":0.0163042,"amount_str":"0.01630420","amount_traded":"0","amount_at_create":"0.01630420","price":61333,"price_str":"61333"},"channel":"live_orders_btcusd","event":"order_deleted"}
{"data":{"id":1722048954118147,"id_str":"1722048954118147","order_type":1,"datetime":"1709257083","microtimestamp":"1709257082617000","amount":0.4890276,"amount_str":"0.48902760","amount_traded":"0","amount_at_create":"0.48902760","price":61347,"price_str":"61347"},"channel":"live_orders_btcusd","event":"order_deleted"}
{"data":{"id":1722048954105856,"id_str":"1722048954105856","order_type":0,"datetime":"1709257083","microtimestamp":"1709257082617000","amount":0.48914307,"amount_str":"0.48914307","amount_traded":"0","amount_at_create":"0.48914307","price":61331,"price_str":"61331"},"channel":"live_orders_btcusd","event":"order_deleted"}
{"data":{"id":1722048954101760,"id_str":"1722048954101760","order_type":1,"datetime":"1709257083","microtimestamp":"1709257082624000","amount":0.48896607,"amount_str":"0.48896607","amount_traded":"0","amount_at_create":"0.48896607","price":61354,"price_str":"61354"},"channel":"live_orders_btcusd","event":"order_deleted"}
{"data":{"id":1722048954093576,"id_str":"1722048954093576","order_type":1,"datetime":"1709257083","microtimestamp":"1709257082624000","amount":0.4888539,"amount_str":"0.48885390","amount_traded":"0","amount_at_create":"0.48885390","price":61369,"price_str":"61369"},"channel":"live_orders_btcusd","event":"order_deleted"}
{"data":{"id":1722048949862401,"id_str":"1722048949862401","order_type":1,"datetime":"1709257083","microtimestamp":"1709257082625000","amount":0.16265164,"amount_str":"0.16265164","amount_traded":"0","amount_at_create":"0.16265164","price":61482,"price_str":"61482"},"channel":"live_orders_btcusd","event":"order_deleted"}
{"data":{"id":1722048933777410,"id_str":"1722048933777410","order_type":0,"datetime":"1709257083","microtimestamp":"1709257082625000","amount":0.48962539,"amount_str":"0.48962539","amount_traded":"0","amount_at_create":"0.48962539","price":61271,"price_str":"61271"},"channel":"live_orders_btcusd","event":"order_deleted"}
{"data":{"id":1722048954236936,"id_str":"1722048954236936","order_type":1,"datetime":"1709257083","microtimestamp":"1709257082626000","amount":0.03062118,"amount_str":"0.03062118","amount_traded":"0","amount_at_create":"0.03062118","price":61358,"price_str":"61358"},"channel":"live_orders_btcusd","event":"order_created"}
{"data":{"id":1722048933781504,"id_str":"1722048933781504","order_type":1,"datetime":"1709257083","microtimestamp":"1709257082626000","amount":0.48850503,"amount_str":"0.48850503","amount_traded":"0","amount_at_create":"0.48850503","price":61412,"price_str":"61412"},"channel":"live_orders_btcusd","event":"order_deleted"}
{"data":{"id":1722048954273794,"id_str":"1722048954273794","order_type":1,"datetime":"1709257083","microtimestamp":"1709257082634000","amount":0.02110536,"amount_str":"0.02110536","amount_traded":"0","amount_at_create":"0.02110536","price":61361,"price_str":"61361"},"channel":"live_orders_btcusd","event":"order_created"}
{"data":{"id":1722048954273795,"id_str":"1722048954273795","order_type":1,"datetime":"1709257083","microtimestamp":"1709257082634000","amount":2.473578,"amount_str":"2.47357800","amount_traded":"0","amount_at_create":"2.47357800","price":61453,"price_str":"61453"},"channel":"live_orders_btcusd","event":"order_created"}
{"data":{"id":1722048954126342,"id_str":"1722048954126342","order_type":1,"datetime":"1709257083","microtimestamp":"1709257082653000","amount":0.01630204,"amount_str":"0.01630204","amount_traded":"0","amount_at_create":"0.01630204","price":61342,"price_str":"61342"},"channel":"live_orders_btcusd","event":"order_deleted"}
{"data":{"id":1722048954093574,"id_str":"1722048954093574","order_type":1,"datetime":"1709257083","microtimestamp":"1709257082654000","amount":0.48902943,"amount_str":"0.48902943","amount_traded":"0","amount_at_create":"0.48902943","price":61346,"price_str":"61346"},"channel":"live_orders_btcusd","event":"order_deleted"}
{"data":{"id":1722048954273794,"id_str":"1722048954273794","order_type":1,"datetime":"1709257083","microtimestamp":"1709257082657000","amount":0.02110536,"amount_str":"0.02110536","amount_traded":"0","amount_at_create":"0.02110536","price":61361,"price_str":"61361"},"channel":"live_orders_btcusd","event":"order_deleted"}
{"data":{"id":1722048954421248,"id_str":"1722048954421248","order_type":1,"datetime":"1709257083","microtimestamp":"1709257082670000","amount":0.04875518,"amount_str":"0.04875518","amount_traded":"0","amount_at_create":"0.04875518","price":61372,"price_str":"61372"},"channel":"live_orders_btcusd","event":"order_created"}
{"data":{"id":1722048954433537,"id_str":"1722048954433537","order_type":1,"datetime":"1709257083","microtimestamp":"1709257082673000","amount":0.48856256,"amount_str":"0.48856256","amount_traded":"0","amount_at_create":"0.48856256","price":61405,"price_str":"61405"},"channel":"live_orders_btcusd","event":"order_created"}
{"data":{"id":1722048954437633,"id_str":"1722048954437633","order_type":0,"datetime":"1709257083","microtimestamp":"1709257082674000","amount":0.1875,"amount_str":"0.18750000","amount_traded":"0","amount_at_create":"0.18750000","price":61321,"price_str":"61321"},"channel":"live_orders_btcusd","event":"order_created"}
{"data":{"id":1722048953860099,"id_str":"1722048953860099","order_type":1,"datetime":"1709257083","microtimestamp":"1709257082676000","amount":0.00487133,"amount_str":"0.00487133","amount_traded":"0","amount_at_create":"0.00487133","price":61354,"price_str":"61354"},"channel":"live_orders_btcusd","event":"order_deleted"}
{"data":{"id":1722048954449920,"id_str":"1722048954449920","order_type":0,"datetime":"1709257083","microtimestamp":"1709257082677000","amount":0.48916832,"amount_str":"0.48916832","amount_traded":"0","amount_at_create":"0.48916832","price":61328,"price_str":"61328"},"channel":"live_orders_btcusd","event":"order_created"}
{"data":{"id":1722048954466304,"id_str":"1722048954466304","order_type":0,"datetime":"1709257083","microtimestamp":"1709257082681000","amount":0.48968851,"amount_str":"0.48968851","amount_traded":"0","amount_at_create":"0.48968851","price":61263,"price_str":"61263"},"channel":"live_orders_btcusd","event":"order_created"}
{"data":{"id":1722048954519555,"id_str":"1722048954519555","order_type":1,"datetime":"1709257083","microtimestamp":"1709257082694000","amount":0.00487133,"amount_str":"0.00487133","amount_traded":"0","amount_at_create":"0.00487133","price":61350,"price_str":"61350"},"channel":"live_orders_btcusd","event":"order_created"}
{"data":{"id":1722048907198465,"id_str":"1722048907198465","order_type":1,"datetime":"1709257083","microtimestamp":"1709257082701000","amount":0.12188796,"amount_str":"0.12188796","amount_traded":"0","amount_at_create":"0.12188796","price":61417,"price_str":"61417"},"channel":"live_orders_btcusd","event":"order_deleted"}
{"data":{"id":1722048954667008,"id_str":"1722048954667008","order_type":0,"datetime":"1709257083","microtimestamp":"1709257082730000","amount":0.01630504,"amount_str":"0.01630504","amount_traded":"0","amount_at_create":"0.01630504","price":61330,"price_str":"61330"},"channel":"live_orders_btcusd","event":"order_created"}
{"data":{"id":1722048954667011,"id_str":"1722048954667011","order_type":1,"datetime":"1709257083","microtimestamp":"1709257082731000","amount":0.0163033,"amount_str":"0.01630330","amount_traded":"0","amount_at_create":"0.01630330","price":61338,"price_str":"61338"},"channel":"live_orders_btcusd","event":"order_created"}
{"data":{"id":1722048954687490,"id_str":"1722048954687490","order_type":1,"datetime":"1709257083","microtimestamp":"1709257082735000","amount":0.02070266,"amount_str":"0.02070266","amount_traded":"0","amount_at_create":"0.02070266","price":61359,"price_str":"61359"},"channel":"live_orders_btcusd","event":"order_created"}
{"data":{"id":1722048954707972,"id_str":"1722048954707972","order_type":0,"datetime":"1709257083","microtimestamp":"1709257082741000","amount":0.00815075,"amount_str":"0.00815075","amount_traded":"0","amount_at_create":"0.00815075","price":61333,"price_str":"61333"},"channel":"live_orders_btcusd","event":"order_created"}
{"data":{"id":1722048954667011,"id_str":"1722048954667011","order_type":1,"datetime":"1709257083","microtimestamp":"1709257082745000","amount":0.0163033,"amount_str":"0.01630330","amount_traded":"0","amount_at_create":"0.01630330","price":61338,"price_str":"61338"},"channel":"live_orders_btcusd","event":"order_deleted"}
{"data":{"id":1722048954667008,"id_str":"1722048954667008","order_type":0,"datetime":"1709257083","microtimestamp":"1709257082746000","amount":0.01630504,"amount_str":"0.01630504","amount_traded":"0","amount_at_create":"0.01630504","price":61330,"price_str":"61330"},"channel":"live_orders_btcusd","event":"order_deleted"}
{"data":{"id":1722048954064899,"id_str":"1722048954064899","order_type":0,"datetime":"1709257083","microtimestamp":"1709257082747000","amount":0.00815075,"amount_str":"0.00815075","amount_traded":"0","amount_at_create":"0.00815075","price":61335,"price_str":"61335"},"channel":"live_orders_btcusd","event":"order_deleted"}
{"data":{"id":1722048954769412,"id_str":"1722048954769412","order_type":1,"datetime":"1709257083","microtimestamp":"1709257082756000","amount":0.12188796,"amount_str":"0.12188796","amount_traded":"0","amount_at_create":"0.12188796","price":61402,"price_str":"61402"},"channel":"live_orders_btcusd","event":"order_created"}
{"data":{"id":1722048954040329,"id_str":"1722048954040329","order_type":1,"datetime":"1709257083","microtimestamp":"1709257082771000","amount":0.1875,"amount_str":"0.18750000","amount_traded":"0","amount_at_create":"0.18750000","price":61355,"price_str":"61355"},"channel":"live_orders_btcusd","event":"order_deleted"}
{"data":{"id":1722048931852289,"id_str":"1722048931852289","order_type":0,"datetime":"1709257083","microtimestamp":"1709257082773000","amount":0.01630134,"amount_str":"0.01630134","amount_traded":"0","amount_at_create":"0.01630134","price":61329,"price_str":"61329"},"channel":"live_orders_btcusd","event":"order_deleted"}
{"data":{"id":1722048954892288,"id_str":"1722048954892288","order_type":0,"datetime":"1709257083","microtimestamp":"1709257082785000","amount":0.00040751,"amount_str":"0.00040751","amount_traded":"0","amount_at_create":"0.00040751","price":61326,"price_str":"61326"},"channel":"live_orders_btcusd","event":"order_created"}
{"data":{"id":1722048955080705,"id_str":"1722048955080705","order_type":0,"datetime":"1709257083","microtimestamp":"1709257082831000","amount":0.01630453,"amount_str":"0.01630453","amount_traded":"0","amount_at_create":"0.01630453","price":61332,"price_str":"61332"},"channel":"live_orders_btcusd","event":"order_created"}
{"data":{"id":1722048955088896,"id_str":"1722048955088896","order_type":1,"datetime":"1709257083","microtimestamp":"1709257082833000","amount":0.01629965,"amount_str":"0.01629965","amount_traded":"0","amount_at_create":"0.01629965","price":61351,"price_str":"61351"},"channel":"live_orders_btcusd","event":"order_created"}
{"data":{"id":1722048927969280,"id_str":"1722048927969280","order_type":0,"datetime":"1709257083","microtimestamp":"1709257082835000","amount":0.16301911,"amount_str":"0.16301911","amount_traded":"0","amount_at_create":"0.16301911","price":61319,"price_str":"61319"},"channel":"live_orders_btcusd","event":"order_deleted"}
{"data":{"id":1722048953954310,"id_str":"1722048953954310","order_type":1,"datetime":"1709257083","microtimestamp":"1709257082844000","amount":0.00487133,"amount_str":"0.00487133","amount_traded":"0","amount_at_create":"0.00487133","price":61352,"price_str":"61352"},"channel":"live_orders_btcusd","event":"order_deleted"}
{"data":{"id":1722048955088896,"id_str":"1722048955088896","order_type":1,"datetime":"1709257083","microtimestamp":"1709257082848000","amount":0.01629965,"amount_str":"0.01629965","amount_traded":"0","amount_at_create":"0.01629965","price":61351,"price_str":"61351"},"channel":"live_orders_btcusd","event":"order_deleted"}
{"data":{"id":1722048928120833,"id_str":"1722048928120833","order_type":1,"datetime":"1709257083","microtimestamp":"1709257082852000","amount":0.09742898,"amount_str":"0.09742898","amount_traded":"0","amount_at_create":"0.09742898","price":61373,"price_str":"61373"},"channel":"live_orders_btcusd","event":"order_deleted"}
{"data":{"id":1722048955236353,"id_str":"1722048955236353","order_type":1,"datetime":"1709257083","microtimestamp":"1709257082869000","amount":0.0048716,"amount_str":"0.00487160","amount_traded":"0","amount_at_create":"0.00487160","price":61348,"price_str":"61348"},"channel":"live_orders_btcusd","event":"order_created"}
{"data":{"id":1722048955322369,"id_str":"1722048955322369","order_type":0,"datetime":"1709257083","microtimestamp":"1709257082891000","amount":0.16302442,"amount_str":"0.16302442","amount_traded":"0","amount_at_create":"0.16302442","price":61313,"price_str":"61313"},"channel":"live_orders_btcusd","event":"order_created"}
{"data":{"id":1722048955330560,"id_str":"1722048955330560","order_type":0,"datetime":"1709257083","microtimestamp":"1709257082892000","amount":0.48915394,"amount_str":"0.48915394","amount_traded":"0","amount_at_create":"0.48915394","price":61330,"price_str":"61330"},"channel":"live_orders_btcusd","event":"order_created"}
{"data":{"id":1722048955330564,"id_str":"1722048955330564","order_type":1,"datetime":"1709257083","microtimestamp":"1709257082892000","amount":0.48900552,"amount_str":"0.48900552","amount_traded":"0","amount_at_create":"0.48900552","price":61349,"price_str":"61349"},"channel":"live_orders_btcusd","event":"order_created"}
{"data":{"id":1722048913604610,"id_str":"1722048913604610","order_type":0,"datetime":"1709257083","microtimestamp":"1709257082896000","amount":0.545,"amount_str":"0.54500000","amount_traded":"0","amount_at_create":"0.54500000","price":61320,"price_str":"61320"},"channel":"live_orders_btcusd","event":"order_deleted"}
{"data":{"id":1722048913801218,"id_str":"1722048913801218","order_type":1,"datetime":"1709257083","microtimestamp":"1709257082899000","amount":0.563,"amount_str":"0.56300000","amount_traded":"0","amount_at_create":"0.56300000","price":61403,"price_str":"61403"},"channel":"live_orders_btcusd","event":"order_deleted"}
{"data":{"id":1722048955080705,"id_str":"1722048955080705","order_type":0,"datetime":"1709257083","microtimestamp":"1709257082903000","amount":0.01630453,"amount_str":"0.01630453","amount_traded":"0","amount_at_create":"0.01630453","price":61332,"price_str":"61332"},"channel":"live_orders_btcusd","event":"order_deleted"}
{"data":{"id":1722048955330564,"id_str":"1722048955330564","order_type":1,"datetime":"1709257083","microtimestamp":"1709257082906000","amount":0.48900552,"amount_str":"0.48900552","amount_traded":"0","amount_at_create":"0.48900552","price":61349,"price_str":"61349"},"channel":"live_orders_btcusd","event":"order_deleted"}
{"data":{"id":1722048955482115,"id_str":"1722048955482115","order_type":1,"datetime":"1709257083","microtimestamp":"1709257082930000","amount":0.515,"amount_str":"0.51500000","amount_traded":"0","amount_at_create":"0.51500000","price":61371,"price_str":"61371"},"channel":"live_orders_btcusd","event":"order_created"}
{"data":{"id":1722048955486208,"id_str":"1722048955486208","order_type":0,"datetime":"1709257083","microtimestamp":"1709257082931000","amount":0.839,"amount_str":"0.83900000","amount_traded":"0","amount_at_create":"0.83900000","price":61288,"price_str":"61288"},"channel":"live_orders_btcusd","event":"order_created"}
{"data":{"id":1722048955576321,"id_str":"1722048955576321","order_type":1,"datetime":"1709257083","microtimestamp":"1709257082952000","amount":0.01630279,"amount_str":"0.01630279","amount_traded":"0","amount_at_create":"0.01630279","price":61340,"price_str":"61340"},"channel":"live_orders_btcusd","event":"order_created"}
{"data":{"id":1722048955236353,"id_str":"1722048955236353","order_type":1,"datetime":"1709257083","microtimestamp":"1709257082953000","amount":0.0048716,"amount_str":"0.00487160","amount_traded":"0","amount_at_create":"0.00487160","price":61348,"price_str":"61348"},"channel":"live_orders_btcusd","event":"order_deleted"}
{"data":{"id":1722048955592704,"id_str":"1722048955592704","order_type":0,"datetime":"1709257083","microtimestamp":"1709257082956000","amount":0.01630443,"amount_str":"0.01630443","amount_traded":"0","amount_at_create":"0.01630443","price":61333,"price_str":"61333"},"channel":"live_orders_btcusd","event":"order_created"}
{"data":{"id":1722048955645952,"id_str":"1722048955645952","order_type":1,"datetime":"1709257083","microtimestamp":"1709257082969000","amount":0.09743057,"amount_str":"0.09743057","amount_traded":"0","amount_at_create":"0.09743057","price":61369,"price_str":"61369"},"channel":"live_orders_btcusd","event":"order_created"}
{"data":{"id":1722048955576321,"id_str":"1722048955576321","order_type":1,"datetime":"1709257083","microtimestamp":"1709257083014000","amount":0.01630279,"amount_str":"0.01630279","amount_traded":"0","amount_at_create":"0.01630279","price":61340,"price_str":"61340"},"channel":"live_orders_btcusd","event":"order_deleted"}
{"data":{"id":1722048955592704,"id_str":"1722048955592704","order_type":0,"datetime":"1709257083","microtimestamp":"1709257083014000","amount":0.01630443,"amount_str":"0.01630443","amount_traded":"0","amount_at_create":"0.01630443","price":61333,"price_str":"61333"},"channel":"live_orders_btcusd","event":"order_deleted"}
{"data":{"id":1722048955330560,"id_str":"1722048955330560","order_type":0,"datetime":"1709257083","microtimestamp":"1709257083015000","amount":0.48915394,"amount_str":"0.48915394","amount_traded":"0","amount_at_create":"0.48915394","price":61330,"price_str":"61330"},"channel":"live_orders_btcusd","event":"order_deleted"}
{"data":{"id":1722048955887616,"id_str":"1722048955887616","order_type":0,"datetime":"1709257083","microtimestamp":"1709257083028000","amount":0.48935531,"amount_str":"0.48935531","amount_traded":"0","amount_at_create":"0.48935531","price":61305,"price_str":"61305"},"channel":"live_orders_btcusd","event":"order_created"}
{"data":{"id":1722048956084225,"id_str":"1722048956084225","order_type":1,"datetime":"1709257083","microtimestamp":"1709257083076000","amount":0.01630225,"amount_str":"0.01630225","amount_traded":"0","amount_at_create":"0.01630225","price":61342,"price_str":"61342"},"channel":"live_orders_btcusd","event":"order_created"}
{"data":{"id":1722048956100609,"id_str":"1722048956100609","order_type":0,"datetime":"1709257083","microtimestamp":"1709257083080000","amount":0.01630408,"amount_str":"0.01630408","amount_traded":"0","amount_at_create":"0.01630408","price":61334,"price_str":"61334"},"channel":"live_orders_btcusd","event":"order_created"}
{"data":{"id":1722048954892288,"id_str":"1722048954892288","order_type":0,"datetime":"1709257083","microtimestamp":"1709257083091000","amount":0.00040751,"amount_str":"0.00040751","amount_traded":"0","amount_at_create":"0.00040751","price":61326,"price_str":"61326"},"channel":"live_orders_btcusd","event":"order_deleted"}
{"data":{"id":1722048956084225,"id_str":"1722048956084225","order_type":1,"datetime":"1709257083","microtimestamp":"1709257083102000","amount":0.01630225,"amount_str":"0.01630225","amount_traded":"0","amount_at_create":"0.01630225","price":61342,"price_str":"61342"},"channel":"live_orders_btcusd","event":"order_deleted"}
{"data":{"id":1722048956100609,"id_str":"1722048956100609","order_type":0,"datetime":"1709257083","microtimestamp":"1709257083102000","amount":0.01630408,"amount_str":"0.01630408","amount_traded":"0","amount_at_create":"0.01630408","price":61334,"price_str":"61334"},"channel":"live_orders_btcusd","event":"order_deleted"}
{"data":{"id":1722048956289024,"id_str":"1722048956289024","order_type":1,"datetime":"1709257083","microtimestamp":"1709257083126000","amount":0.48900552,"amount_str":"0.48900552","amount_traded":"0","amount_at_create":"0.48900552","price":61349,"price_str":"61349"},"channel":"live_orders_btcusd","event":"order_created"}
{"data":{"id":1722048956297216,"id_str":"1722048956297216","order_type":1,"datetime":"1709257083","microtimestamp":"1709257083128000","amount":0.48900552,"amount_str":"0.48900552","amount_traded":"0","amount_at_create":"0.48900552","price":61349,"price_str":"61349"},"channel":"live_orders_btcusd","event":"order_created"}
{"data":{"id":1722048956305410,"id_str":"1722048956305410","order_type":0,"datetime":"1709257083","microtimestamp":"1709257083130000","amount":0.48913964,"amount_str":"0.48913964","amount_traded":"0","amount_at_create":"0.48913964","price":61332,"price_str":"61332"},"channel":"live_orders_btcusd","event":"order_created"}
{"data":{"id":1722048956297216,"id_str":"1722048956297216","order_type":1,"datetime":"1709257083","microtimestamp":"1709257083150000","amount":0.48900552,"amount_str":"0.48900552","amount_traded":"0","amount_at_create":"0.48900552","price":61349,"price_str":"61349"},"channel":"live_orders_btcusd","event":"order_deleted"}
{"data":{"id":1722048956305410,"id_str":"1722048956305410","order_type":0,"datetime":"1709257083","microtimestamp":"1709257083150000","amount":0.48913964,"amount_str":"0.48913964","amount_traded":"0","amount_at_create":"0.48913964","price":61332,"price_str":"61332"},"channel":"live_orders_btcusd","event":"order_deleted"}
{"data":{"id":1722048956399616,"id_str":"1722048956399616","order_type":0,"datetime":"1709257083","microtimestamp":"1709257083153000","amount":0.5,"amount_str":"0.50000000","amount_traded":"0","amount_at_create":"0.50000000","price":61314,"price_str":"61314"},"channel":"live_orders_btcusd","event":"order_created"}
{"data":{"id":1722048956407808,"id_str":"1722048956407808","order_type":0,"datetime":"1709257083","microtimestamp":"1709257083155000","amount":1,"amount_str":"1.00000000","amount_traded":"0","amount_at_create":"1.00000000","price":61256,"price_str":"61256"},"channel":"live_orders_btcusd","event":"order_created"}
{"data":{"id":1722048956411904,"id_str":"1722048956411904","order_type":0,"datetime":"1709257083","microtimestamp":"1709257083156000","amount":0.5,"amount_str":"0.50000000","amount_traded":"0","amount_at_create":"0.50000000","price":61287,"price_str":"61287"},"channel":"live_orders_btcusd","event":"order_created"}
{"data":{"id":1722048956428288,"id_str":"1722048956428288","order_type":0,"datetime":"1709257083","microtimestamp":"1709257083161000","amount":0.5,"amount_str":"0.50000000","amount_traded":"0","amount_at_create":"0.50000000","price":61225,"price_str":"61225"},"channel":"live_orders_btcusd","event":"order_created"}
{"data":{"id":1722048956571648,"id_str":"1722048956571648","order_type":1,"datetime":"1709257083","microtimestamp":"1709257083195000","amount":0.01630186,"amount_str":"0.01630186","amount_traded":"0","amount_at_create":"0.01630186","price":61343,"price_str":"61343"},"channel":"live_orders_btcusd","event":"order_created"}
{"data":{"id":1722048956583936,"id_str":"1722048956583936","order_type":0,"datetime":"1709257083","microtimestamp":"1709257083198000","amount":0.01630368,"amount_str":"0.01630368","amount_traded":"0","amount_at_create":"0.01630368","price":61335,"price_str":"61335"},"channel":"live_orders_btcusd","event":"order_created"}
{"data":{"id":1722048954449920,"id_str":"1722048954449920","order_type":0,"datetime":"1709257083","microtimestamp":"1709257083201000","amount":0.48916832,"amount_str":"0.48916832","amount_traded":"0","amount_at_create":"0.48916832","price":61328,"price_str":"61328"},"channel":"live_orders_btcusd","event":"order_deleted"}
{"data":{"id":1722048955887616,"id_str":"1722048955887616","order_type":0,"datetime":"1709257083","microtimestamp":"1709257083201000","amount":0.48935531,"amount_str":"0.48935531","amount_traded":"0","amount_at_create":"0.48935531","price":61305,"price_str":"61305"},"channel":"live_orders_btcusd","event":"order_deleted"}
{"data":{"id":1722048956583936,"id_str":"1722048956583936","order_type":0,"datetime":"1709257083","microtimestamp":"1709257083212000","amount":0.01630368,"amount_str":"0.01630368","amount_traded":"0","amount_at_create":"0.01630368","price":61335,"price_str":"61335"},"channel":"live_orders_btcusd","event":"order_deleted"}
{"data":{"id":1722048954122242,"id_str":"1722048954122242","order_type":0,"datetime":"1709257083","microtimestamp":"1709257083230000","amount":0.48923321,"amount_str":"0.48923321","amount_traded":"0","amount_at_create":"0.48923321","price":61320,"price_str":"61320"},"channel":"live_orders_btcusd","event":"order_deleted"}
{"data":{"id":1722048956829697,"id_str":"1722048956829697","order_type":0,"datetime":"1709257083","microtimestamp":"1709257083259000","amount":0.48915366,"amount_str":"0.48915366","amount_traded":"0","amount_at_create":"0.48915366","price":61330,"price_str":"61330"},"channel":"live_orders_btcusd","event":"order_created"}
{"data":{"id":1722048957009920,"id_str":"1722048957009920","order_type":0,"datetime":"1709257083","microtimestamp":"1709257083302000","amount":0.0163034,"amount_str":"0.01630340","amount_traded":"0","amount_at_create":"0.01630340","price":61336,"price_str":"61336"},"channel":"live_orders_btcusd","event":"order_created"}
{"data":{"id":1722048957014017,"id_str":"1722048957014017","order_type":0,"datetime":"1709257083","microtimestamp":"1709257083303000","amount":0.00040751,"amount_str":"0.00040751","amount_traded":"0","amount_at_create":"0.00040751","price":61327,"price_str":"61327"},"channel":"live_orders_btcusd","event":"order_created"}
{"data":{"id":1722048957075456,"id_str":"1722048957075456","order_type":0,"datetime":"1709257083","microtimestamp":"1709257083318000","amount":0.12188796,"amount_str":"0.12188796","amount_traded":"0","amount_at_create":"0.12188796","price":61273,"price_str":"61273"},"channel":"live_orders_btcusd","event":"order_created"}
{"data":{"id":1722048957190144,"id_str":"1722048957190144","order_type":0,"datetime":"1709257083","microtimestamp":"1709257083346000","amount":0.489122,"amount_str":"0.48912200","amount_traded":"0","amount_at_create":"0.48912200","price":61334,"price_str":"61334"},"channel":"live_orders_btcusd","event":"order_created"}
{"data":{"id":1722048957194240,"id_str":"1722048957194240","order_type":1,"datetime":"1709257083","microtimestamp":"1709257083347000","amount":0.48903904,"amount_str":"0.48903904","amount_traded":"0","amount_at_create":"0.48903904","price":61345,"price_str":"61345"},"channel":"live_orders_btcusd","event":"order_created"}
{"data":{"id":1722048957308928,"id_str":"1722048957308928","order_type":0,"datetime":"1709257083","microtimestamp":"1709257083375000","amount":0.04875518,"amount_str":"0.04875518","amount_traded":"0","amount_at_create":"0.04875518","price":61305,"price_str":"61305"},"channel":"live_orders_btcusd","event":"order_created"}
{"data":{"id":1722048957366273,"id_str":"1722048957366273","order_type":0,"datetime":"1709257083","microtimestamp":"1709257083389000","amount":0.1875,"amount_str":"0.18750000","amount_traded":"0","amount_at_create":"0.18750000","price":61329,"price_str":"61329"},"channel":"live_orders_btcusd","event":"order_created"}
{"data":{"id":1722048957997059,"id_str":"1722048957997059","order_type":0,"datetime":"1709257084","microtimestamp":"1709257083544000","amount":0.00423152,"amount_str":"0.00423152","amount_traded":"0","amount_at_create":"0.00423152","price":61348,"price_str":"61348"},"channel":"live_orders_btcusd","event":"order_created"}
{"data":{"id":1722048957997059,"id_str":"1722048957997059","order_type":0,"datetime":"1709257084","microtimestamp":"1709257083544000","amount":0,"amount_str":"0","amount_traded":"0.00423152","amount_at_create":"0.00423152","price":61343,"price_str":"61343"},"channel":"live_orders_btcusd","event":"order_deleted"}
{"data":{"id":1722048956571648,"id_str":"1722048956571648","order_type":1,"datetime":"1709257084","microtimestamp":"1709257083544000","amount":0.01207034,"amount_str":"0.01207034","amount_traded":"0.00423152","amount_at_create":"0.01630186","price":61343,"price_str":"61343"},"channel":"live_orders_btcusd","event":"order_changed"}
{"data":{"id":1722048956571648,"id_str":"1722048956571648","order_type":1,"datetime":"1709257084","microtimestamp":"1709257083569000","amount":0.01207034,"amount_str":"0.01207034","amount_traded":"0","amount_at_create":"0.01630186","price":61343,"price_str":"61343"},"channel":"live_orders_btcusd","event":"order_deleted"}
{"data":{"id":1722048957366273,"id_str":"1722048957366273","order_type":0,"datetime":"1709257084","microtimestamp":"1709257083595000","amount":0.1875,"amount_str":"0.18750000","amount_traded":"0","amount_at_create":"0.18750000","price":61329,"price_str":"61329"},"channel":"live_orders_btcusd","event":"order_deleted"}
{"data":{"id":1722048958275586,"id_str":"1722048958275586","order_type":1,"datetime":"1709257084","microtimestamp":"1709257083611000","amount":0.48894503,"amount_str":"0.48894503","amount_traded":"0","amount_at_create":"0.48894503","price":61357,"price_str":"61357"},"channel":"live_orders_btcusd","event":"order_created"}
{"data":{"id":1722048958283777,"id_str":"1722048958283777","order_type":0,"datetime":"1709257084","microtimestamp":"1709257083613000","amount":0.48920946,"amount_str":"0.48920946","amount_traded":"0","amount_at_create":"0.48920946","price":61323,"price_str":"61323"},"channel":"live_orders_btcusd","event":"order_created"}
{"data":{"id":1722048957014017,"id_str":"1722048957014017","order_type":0,"datetime":"1709257084","microtimestamp":"1709257083646000","amount":0.00040751,"amount_str":"0.00040751","amount_traded":"0","amount_at_create":"0.00040751","price":61327,"price_str":"61327"},"channel":"live_orders_btcusd","event":"order_deleted"}
{"data":{"id":1722048958685187,"id_str":"1722048958685187","order_type":1,"datetime":"1709257084","microtimestamp":"1709257083711000","amount":0.01630175,"amount_str":"0.01630175","amount_traded":"0","amount_at_create":"0.01630175","price":61344,"price_str":"61344"},"channel":"live_orders_btcusd","event":"order_created"}
{"data":{"id":1722048958685187,"id_str":"1722048958685187","order_type":1,"datetime":"1709257084","microtimestamp":"1709257083802000","amount":0.01630175,"amount_str":"0.01630175","amount_traded":"0","amount_at_create":"0.01630175","price":61344,"price_str":"61344"},"channel":"live_orders_btcusd","event":"order_deleted"}
{"data":{"id":1722048959209473,"id_str":"1722048959209473","order_type":0,"datetime":"1709257084","microtimestamp":"1709257083840000","amount":0.00040751,"amount_str":"0.00040751","amount_traded":"0","amount_at_create":"0.00040751","price":61328,"price_str":"61328"},"channel":"live_orders_btcusd","event":"order_created"}
{"data":{"id":1722048959242243,"id_str":"1722048959242243","order_type":1,"datetime":"1709257084","microtimestamp":"1709257083847000","amount":0.0163019,"amount_str":"0.01630190","amount_traded":"0","amount_at_create":"0.01630190","price":61343,"price_str":"61343"},"channel":"live_orders_btcusd","event":"order_created"}
{"data":{"id":1722048959868928,"id_str":"1722048959868928","order_type":0,"datetime":"1709257084","microtimestamp":"1709257084000000","amount":0.06518467,"amount_str":"0.06518467","amount_traded":"0","amount_at_create":"0.06518467","price":61321,"price_str":"61321"},"channel":"live_orders_btcusd","event":"order_created"}
{"data":{"id":1722048959209473,"id_str":"1722048959209473","order_type":0,"datetime":"1709257084","microtimestamp":"1709257084063000","amount":0.00040751,"amount_str":"0.00040751","amount_traded":"0","amount_at_create":"0.00040751","price":61328,"price_str":"61328"},"channel":"live_orders_btcusd","event":"order_deleted"}
{"data":{"id":1722048954466304,"id_str":"1722048954466304","order_type":0,"datetime":"1709257084","microtimestamp":"1709257084089000","amount":0.48968851,"amount_str":"0.48968851","amount_traded":"0","amount_at_create":"0.48968851","price":61263,"price_str":"61263"},"channel":"live_orders_btcusd","event":"order_deleted"}
{"data":{"id":1722048957190144,"id_str":"1722048957190144","order_type":0,"datetime":"1709257084","microtimestamp":"1709257084089000","amount":0.489122,"amount_str":"0.48912200","amount_traded":"0","amount_at_create":"0.48912200","price":61334,"price_str":"61334"},"channel":"live_orders_btcusd","event":"order_deleted"}
{"data":{"id":1722048957194240,"id_str":"1722048957194240","order_type":1,"datetime":"1709257084","microtimestamp":"1709257084090000","amount":0.48903904,"amount_str":"0.48903904","amount_traded":"0","amount_at_create":"0.48903904","price":61345,"price_str":"61345"},"channel":"live_orders_btcusd","event":"order_deleted"}
{"data":{"id":1722048957009920,"id_str":"1722048957009920","order_type":0,"datetime":"1709257084","microtimestamp":"1709257084090000","amount":0.0163034,"amount_str":"0.01630340","amount_traded":"0","amount_at_create":"0.01630340","price":61336,"price_str":"61336"},"channel":"live_orders_btcusd","event":"order_deleted"}
{"data":{"id":1722048959242243,"id_str":"1722048959242243","order_type":1,"datetime":"1709257084","microtimestamp":"1709257084090000","amount":0.0163019,"amount_str":"0.01630190","amount_traded":"0","amount_at_create":"0.01630190","price":61343,"price_str":"61343"},"channel":"live_orders_btcusd","event":"order_deleted"}
{"data":{"id":1722048954236936,"id_str":"1722048954236936","order_type":1,"datetime":"1709257084","microtimestamp":"1709257084101000","amount":0.03062118,"amount_str":"0.03062118","amount_traded":"0","amount_at_create":"0.03062118","price":61358,"price_str":"61358"},"channel":"live_orders_btcusd","event":"order_deleted"}
{"data":{"id":1722048960315396,"id_str":"1722048960315396","order_type":0,"datetime":"1709257084","microtimestamp":"1709257084110000","amount":0.00815135,"amount_str":"0.00815135","amount_traded":"0","amount_at_create":"0.00815135","price":61335,"price_str":"61335"},"channel":"live_orders_btcusd","event":"order_created"}
{"data":{"id":1722048956829697,"id_str":"1722048956829697","order_type":0,"datetime":"1709257084","microtimestamp":"1709257084112000","amount":0.48915366,"amount_str":"0.48915366","amount_traded":"0","amount_at_create":"0.48915366","price":61330,"price_str":"61330"},"channel":"live_orders_btcusd","event":"order_deleted"}
{"data":{"id":1722048956289024,"id_str":"1722048956289024","order_type":1,"datetime":"1709257084","microtimestamp":"1709257084115000","amount":0.48900552,"amount_str":"0.48900552","amount_traded":"0","amount_at_create":"0.48900552","price":61349,"price_str":"61349"},"channel":"live_orders_btcusd","event":"order_deleted"}
{"data":{"id":1722048954433537,"id_str":"1722048954433537","order_type":1,"datetime":"1709257084","microtimestamp":"1709257084116000","amount":0.48856256,"amount_str":"0.48856256","amount_traded":"0","amount_at_create":"0.48856256","price":61405,"price_str":"61405"},"channel":"live_orders_btcusd","event":"order_deleted"}
{"data":{"id":1722048960425986,"id_str":"1722048960425986","order_type":0,"datetime":"1709257084","microtimestamp":"1709257084137000","amount":0.48943745,"amount_str":"0.48943745","amount_traded":"0","amount_at_create":"0.48943745","price":61294,"price_str":"61294"},"channel":"live_orders_btcusd","event":"order_created"}
{"data":{"id":1722048960430080,"id_str":"1722048960430080","order_type":0,"datetime":"1709257084","microtimestamp":"1709257084138000","amount":0.48911335,"amount_str":"0.48911335","amount_traded":"0","amount_at_create":"0.48911335","price":61335,"price_str":"61335"},"channel":"live_orders_btcusd","event":"order_created"}
{"data":{"id":1722048960438273,"id_str":"1722048960438273","order_type":1,"datetime":"1709257084","microtimestamp":"1709257084139000","amount":0.01630168,"amount_str":"0.01630168","amount_traded":"0","amount_at_create":"0.01630168","price":61344,"price_str":"61344"},"channel":"live_orders_btcusd","event":"order_created"}
{"data":{"id":1722048960438274,"id_str":"1722048960438274","order_type":0,"datetime":"1709257084","microtimestamp":"1709257084139000","amount":0.01630417,"amount_str":"0.01630417","amount_traded":"0","amount_at_create":"0.01630417","price":61334,"price_str":"61334"},"channel":"live_orders_btcusd","event":"order_created"}
{"data":{"id":1722048960446464,"id_str":"1722048960446464","order_type":1,"datetime":"1709257084","microtimestamp":"1709257084141000","amount":0.48901349,"amount_str":"0.48901349","amount_traded":"0","amount_at_create":"0.48901349","price":61348,"price_str":"61348"},"channel":"live_orders_btcusd","event":"order_created"}
{"data":{"id":1722048960450560,"id_str":"1722048960450560","order_type":0,"datetime":"1709257084","microtimestamp":"1709257084142000","amount":0.1875,"amount_str":"0.18750000","amount_traded":"0","amount_at_create":"0.18750000","price":61329,"price_str":"61329"},"channel":"live_orders_btcusd","event":"order_created"}
{"data":{"id":1722048954687490,"id_str":"1722048954687490","order_type":1,"datetime":"1709257084","microtimestamp":"1709257084147000","amount":0.02070266,"amount_str":"0.02070266","amount_traded":"0","amount_at_create":"0.02070266","price":61359,"price_str":"61359"},"channel":"live_orders_btcusd","event":"order_deleted"}
{"data":{"id":1722048960438273,"id_str":"1722048960438273","order_type":1,"datetime":"1709257084","microtimestamp":"1709257084157000","amount":0.01630168,"amount_str":"0.01630168","amount_traded":"0","amount_at_create":"0.01630168","price":61344,"price_str":"61344"},"channel":"live_orders_btcusd","event":"order_deleted"}
{"data":{"id":1722048960438274,"id_str":"1722048960438274","order_type":0,"datetime":"1709257084","microtimestamp":"1709257084157000","amount":0.01630417,"amount_str":"0.01630417","amount_traded":"0","amount_at_create":"0.01630417","price":61334,"price_str":"61334"},"channel":"live_orders_btcusd","event":"order_deleted"}
{"data":{"id":1722048958283777,"id_str":"1722048958283777","order_type":0,"datetime":"1709257084","microtimestamp":"1709257084198000","amount":0.48920946,"amount_str":"0.48920946","amount_traded":"0","amount_at_create":"0.48920946","price":61323,"price_str":"61323"},"channel":"live_orders_btcusd","event":"order_deleted"}
{"data":{"id":1722048954118144,"id_str":"1722048954118144","order_type":1,"datetime":"1709257084","microtimestamp":"1709257084200000","amount":0.48874957,"amount_str":"0.48874957","amount_traded":"0","amount_at_create":"0.48874957","price":61382,"price_str":"61382"},"channel":"live_orders_btcusd","event":"order_deleted"}
{"data":{"id":1722048960688131,"id_str":"1722048960688131","order_type":0,"datetime":"1709257084","microtimestamp":"1709257084200000","amount":0.48913334,"amount_str":"0.48913334","amount_traded":"0","amount_at_create":"0.48913334","price":61332,"price_str":"61332"},"channel":"live_orders_btcusd","event":"order_created"}
{"data":{"id":1722048960692224,"id_str":"1722048960692224","order_type":1,"datetime":"1709257084","microtimestamp":"1709257084201000","amount":0.48899021,"amount_str":"0.48899021","amount_traded":"0","amount_at_create":"0.48899021","price":61351,"price_str":"61351"},"channel":"live_orders_btcusd","event":"order_created"}
{"data":{"id":1722048960688131,"id_str":"1722048960688131","order_type":0,"datetime":"1709257084","microtimestamp":"1709257084215000","amount":0.48913334,"amount_str":"0.48913334","amount_traded":"0","amount_at_create":"0.48913334","price":61332,"price_str":"61332"},"channel":"live_orders_btcusd","event":"order_deleted"}
{"data":{"id":1722048960782337,"id_str":"1722048960782337","order_type":0,"datetime":"1709257084","microtimestamp":"1709257084224000","amount":0.00040751,"amount_str":"0.00040751","amount_traded":"0","amount_at_create":"0.00040751","price":61327,"price_str":"61327"},"channel":"live_orders_btcusd","event":"order_created"}
{"data":{"id":1722048954519555,"id_str":"1722048954519555","order_type":1,"datetime":"1709257084","microtimestamp":"1709257084230000","amount":0.00487133,"amount_str":"0.00487133","amount_traded":"0","amount_at_create":"0.00487133","price":61350,"price_str":"61350"},"channel":"live_orders_btcusd","event":"order_deleted"}
{"data":{"id":1722048960430080,"id_str":"1722048960430080","order_type":0,"datetime":"1709257084","microtimestamp":"1709257084238000","amount":0.48911335,"amount_str":"0.48911335","amount_traded":"0","amount_at_create":"0.48911335","price":61335,"price_str":"61335"},"channel":"live_orders_btcusd","event":"order_deleted"}
{"data":{"id":1722048960921600,"id_str":"1722048960921600","order_type":1,"datetime":"1709257084","microtimestamp":"1709257084257000","amount":0.02450374,"amount_str":"0.02450374","amount_traded":"0","amount_at_create":"0.02450374","price":61363,"price_str":"61363"},"channel":"live_orders_btcusd","event":"order_created"}
{"data":{"id":1722048960921601,"id_str":"1722048960921601","order_type":1,"datetime":"1709257084","microtimestamp":"1709257084257000","amount":0.01630044,"amount_str":"0.01630044","amount_traded":"0","amount_at_create":"0.01630044","price":61348,"price_str":"61348"},"channel":"live_orders_btcusd","event":"order_created"}
{"data":{"id":1722048960921603,"id_str":"1722048960921603","order_type":0,"datetime":"1709257084","microtimestamp":"1709257084258000","amount":0.01630255,"amount_str":"0.01630255","amount_traded":"0","amount_at_create":"0.01630255","price":61340,"price_str":"61340"},"channel":"live_orders_btcusd","event":"order_created"}
{"data":{"id":1722048960921603,"id_str":"1722048960921603","order_type":0,"datetime":"1709257084","microtimestamp":"1709257084272000","amount":0.01630255,"amount_str":"0.01630255","amount_traded":"0","amount_at_create":"0.01630255","price":61340,"price_str":"61340"},"channel":"live_orders_btcusd","event":"order_deleted"}
{"data":{"id":1722048960921601,"id_str":"1722048960921601","order_type":1,"datetime":"1709257084","microtimestamp":"1709257084272000","amount":0.01630044,"amount_str":"0.01630044","amount_traded":"0","amount_at_create":"0.01630044","price":61348,"price_str":"61348"},"channel":"live_orders_btcusd","event":"order_deleted"}
{"data":{"id":1722048960987136,"id_str":"1722048960987136","order_type":1,"datetime":"1709257084","microtimestamp":"1709257084273000","amount":0.00487152,"amount_str":"0.00487152","amount_traded":"0","amount_at_create":"0.00487152","price":61352,"price_str":"61352"},"channel":"live_orders_btcusd","event":"order_created"}
{"data":{"id":1722048960446464,"id_str":"1722048960446464","order_type":1,"datetime":"1709257084","microtimestamp":"1709257084298000","amount":0.48901349,"amount_str":"0.48901349","amount_traded":"0","amount_at_create":"0.48901349","price":61348,"price_str":"61348"},"channel":"live_orders_btcusd","event":"order_deleted"}
{"data":{"id":1722048960450560,"id_str":"1722048960450560","order_type":0,"datetime":"1709257084","microtimestamp":"1709257084309000","amount":0.1875,"amount_str":"0.18750000","amount_traded":"0","amount_at_create":"0.18750000","price":61329,"price_str":"61329"},"channel":"live_orders_btcusd","event":"order_deleted"}
{"data":{"id":1722048961273856,"id_str":"1722048961273856","order_type":1,"datetime":"1709257084","microtimestamp":"1709257084343000","amount":0.48902146,"amount_str":"0.48902146","amount_traded":"0","amount_at_create":"0.48902146","price":61347,"price_str":"61347"},"channel":"live_orders_btcusd","event":"order_created"}
{"data":{"id":1722048961277952,"id_str":"1722048961277952","order_type":0,"datetime":"1709257084","microtimestamp":"1709257084344000","amount":0.48911069,"amount_str":"0.48911069","amount_traded":"0","amount_at_create":"0.48911069","price":61335,"price_str":"61335"},"channel":"live_orders_btcusd","event":"order_created"}
{"data":{"id":1722048961454080,"id_str":"1722048961454080","order_type":1,"datetime":"1709257084","microtimestamp":"1709257084387000","amount":0.01630141,"amount_str":"0.01630141","amount_traded":"0","amount_at_create":"0.01630141","price":61345,"price_str":"61345"},"channel":"live_orders_btcusd","event":"order_created"}
{"data":{"id":1722048961462272,"id_str":"1722048961462272","order_type":0,"datetime":"1709257084","microtimestamp":"1709257084389000","amount":0.01630312,"amount_str":"0.01630312","amount_traded":"0","amount_at_create":"0.01630312","price":61337,"price_str":"61337"},"channel":"live_orders_btcusd","event":"order_created"}
{"data":{"id":1722048960782337,"id_str":"1722048960782337","order_type":0,"datetime":"1709257084","microtimestamp":"1709257084397000","amount":0.00040751,"amount_str":"0.00040751","amount_traded":"0","amount_at_create":"0.00040751","price":61327,"price_str":"61327"},"channel":"live_orders_btcusd","event":"order_deleted"}
{"data":{"id":1722048961277952,"id_str":"1722048961277952","order_type":0,"datetime":"1709257084","microtimestamp":"1709257084403000","amount":0.48911069,"amount_str":"0.48911069","amount_traded":"0","amount_at_create":"0.48911069","price":61335,"price_str":"61335"},"channel":"live_orders_btcusd","event":"order_deleted"}
{"data":{"id":1722048961519616,"id_str":"1722048961519616","order_type":0,"datetime":"1709257084","microtimestamp":"1709257084403000","amount":0.1875,"amount_str":"0.18750000","amount_traded":"0","amount_at_create":"0.18750000","price":61328,"price_str":"61328"},"channel":"live_orders_btcusd","event":"order_created"}
{"data":{"id":1722048961462272,"id_str":"1722048961462272","order_type":0,"datetime":"1709257084","microtimestamp":"1709257084404000","amount":0.01630312,"amount_str":"0.01630312","amount_traded":"0","amount_at_create":"0.01630312","price":61337,"price_str":"61337"},"channel":"live_orders_btcusd","event":"order_deleted"}
{"data":{"id":1722048961654784,"id_str":"1722048961654784","order_type":1,"datetime":"1709257084","microtimestamp":"1709257084436000","amount":0.03062118,"amount_str":"0.03062118","amount_traded":"0","amount_at_create":"0.03062118","price":61361,"price_str":"61361"},"channel":"live_orders_btcusd","event":"order_created"}
{"data":{"id":1722048961519616,"id_str":"1722048961519616","order_type":0,"datetime":"1709257084","microtimestamp":"1709257084448000","amount":0.1875,"amount_str":"0.18750000","amount_traded":"0","amount_at_create":"0.18750000","price":61328,"price_str":"61328"},"channel":"live_orders_btcusd","event":"order_deleted"}
{"data":{"id":1722048962023424,"id_str":"1722048962023424","order_type":0,"datetime":"1709257085","microtimestamp":"1709257084526000","amount":0.01630363,"amount_str":"0.01630363","amount_traded":"0","amount_at_create":"0.01630363","price":61336,"price_str":"61336"},"channel":"live_orders_btcusd","event":"order_created"}
{"data":{"id":1722048962084865,"id_str":"1722048962084865","order_type":0,"datetime":"1709257085","microtimestamp":"1709257084542000","amount":0.00040751,"amount_str":"0.00040751","amount_traded":"0","amount_at_create":"0.00040751","price":61328,"price_str":"61328"},"channel":"live_orders_btcusd","event":"order_created"}
{"data":{"id":1722048962023424,"id_str":"1722048962023424","order_type":0,"datetime":"1709257085","microtimestamp":"1709257084549000","amount":0.01630363,"amount_str":"0.01630363","amount_traded":"0","amount_at_create":"0.01630363","price":61336,"price_str":"61336"},"channel":"live_orders_btcusd","event":"order_deleted"}
{"data":{"id":1722048962199552,"id_str":"1722048962199552","order_type":0,"datetime":"1709257085","microtimestamp":"1709257084569000","amount":0.48910916,"amount_str":"0.48910916","amount_traded":"0","amount_at_create":"0.48910916","price":61336,"price_str":"61336"},"channel":"live_orders_btcusd","event":"order_created"}
{"data":{"id":1722048962367489,"id_str":"1722048962367489","order_type":1,"datetime":"1709257085","microtimestamp":"1709257084610000","amount":0.48881557,"amount_str":"0.48881557","amount_traded":"0","amount_at_create":"0.48881557","price":61373,"price_str":"61373"},"channel":"live_orders_btcusd","event":"order_created"}
{"data":{"id":1722048962084865,"id_str":"1722048962084865","order_type":0,"datetime":"1709257085","microtimestamp":"1709257084625000","amount":0.00040751,"amount_str":"0.00040751","amount_traded":"0","amount_at_create":"0.00040751","price":61328,"price_str":"61328"},"channel":"live_orders_btcusd","event":"order_deleted"}
{"data":{"id":1722048962543617,"id_str":"1722048962543617","order_type":0,"datetime":"1709257085","microtimestamp":"1709257084653000","amount":0.01630307,"amount_str":"0.01630307","amount_traded":"0","amount_at_create":"0.01630307","price":61338,"price_str":"61338"},"channel":"live_orders_btcusd","event":"order_created"}
{"data":{"id":1722048962547712,"id_str":"1722048962547712","order_type":0,"datetime":"1709257085","microtimestamp":"1709257084654000","amount":0.4891838,"amount_str":"0.48918380","amount_traded":"0","amount_at_create":"0.48918380","price":61326,"price_str":"61326"},"channel":"live_orders_btcusd","event":"order_created"}
{"data":{"id":1722048962748416,"id_str":"1722048962748416","order_type":0,"datetime":"1709257085","microtimestamp":"1709257084704000","amount":0.48912528,"amount_str":"0.48912528","amount_traded":"0","amount_at_create":"0.48912528","price":61333,"price_str":"61333"},"channel":"live_orders_btcusd","event":"order_created"}
{"data":{"id":1722048962834432,"id_str":"1722048962834432","order_type":0,"datetime":"1709257085","microtimestamp":"1709257084724000","amount":0.00040751,"amount_str":"0.00040751","amount_traded":"0","amount_at_create":"0.00040751","price":61327,"price_str":"61327"},"channel":"live_orders_btcusd","event":"order_created"}
{"data":{"id":1722048922292224,"id_str":"1722048922292224","order_type":1,"datetime":"1709257085","microtimestamp":"1709257084746000","amount":0.00033,"amount_str":"0.00033000","amount_traded":"0","amount_at_create":"0.00033000","price":61416,"price_str":"61416"},"channel":"live_orders_btcusd","event":"order_deleted"}
{"data":{"id":1722048963203073,"id_str":"1722048963203073","order_type":1,"datetime":"1709257085","microtimestamp":"1709257084814000","amount":0.00033,"amount_str":"0.00033000","amount_traded":"0","amount_at_create":"0.00033000","price":61412,"price_str":"61412"},"channel":"live_orders_btcusd","event":"order_created"}
{"data":{"id":1722048962834432,"id_str":"1722048962834432","order_type":0,"datetime":"1709257085","microtimestamp":"1709257084899000","amount":0.00040751,"amount_str":"0.00040751","amount_traded":"0","amount_at_create":"0.00040751","price":61327,"price_str":"61327"},"channel":"live_orders_btcusd","event":"order_deleted"}
{"data":{"id":1722048961454080,"id_str":"1722048961454080","order_type":1,"datetime":"1709257085","microtimestamp":"1709257084903000","amount":0.01630141,"amount_str":"0.01630141","amount_traded":"0","amount_at_create":"0.01630141","price":61345,"price_str":"61345"},"channel":"live_orders_btcusd","event":"order_deleted"}
{"data":{"id":1722048961273856,"id_str":"1722048961273856","order_type":1,"datetime":"1709257085","microtimestamp":"1709257084903000","amount":0.48902146,"amount_str":"0.48902146","amount_traded":"0","amount_at_create":"0.48902146","price":61347,"price_str":"61347"},"channel":"live_orders_btcusd","event":"order_deleted"}
{"data":{"id":1722048962748416,"id_str":"1722048962748416","order_type":0,"datetime":"1709257085","microtimestamp":"1709257084903000","amount":0.48912528,"amount_str":"0.48912528","amount_traded":"0","amount_at_create":"0.48912528","price":61333,"price_str":"61333"},"channel":"live_orders_btcusd","event":"order_deleted"}
{"data":{"id":1722048963751937,"id_str":"1722048963751937","order_type":1,"datetime":"1709257085","microtimestamp":"1709257084948000","amount":0.01630159,"amount_str":"0.01630159","amount_traded":"0","amount_at_create":"0.01630159","price":61344,"price_str":"61344"},"channel":"live_orders_btcusd","event":"order_created"}
{"data":{"id":1722048963751938,"id_str":"1722048963751938","order_type":1,"datetime":"1709257085","microtimestamp":"1709257084948000","amount":0.48903097,"amount_str":"0.48903097","amount_traded":"0","amount_at_create":"0.48903097","price":61346,"price_str":"61346"},"channel":"live_orders_btcusd","event":"order_created"}
{"data":{"id":1722048963801089,"id_str":"1722048963801089","order_type":0,"datetime":"1709257085","microtimestamp":"1709257084961000","amount":0.00040751,"amount_str":"0.00040751","amount_traded":"0","amount_at_create":"0.00040751","price":61328,"price_str":"61328"},"channel":"live_orders_btcusd","event":"order_created"}
{"data":{"id":1722048963801089,"id_str":"1722048963801089","order_type":0,"datetime":"1709257085","microtimestamp":"1709257085053000","amount":0.00040751,"amount_str":"0.00040751","amount_traded":"0","amount_at_create":"0.00040751","price":61328,"price_str":"61328"},"channel":"live_orders_btcusd","event":"order_deleted"}
{"data":{"id":1722048964513795,"id_str":"1722048964513795","order_type":0,"datetime":"1709257085","microtimestamp":"1709257085134000","amount":0.00040751,"amount_str":"0.00040751","amount_traded":"0","amount_at_create":"0.00040751","price":61327,"price_str":"61327"},"channel":"live_orders_btcusd","event":"order_created"}
{"data":{"id":1722048962199552,"id_str":"1722048962199552","order_type":0,"datetime":"1709257085","microtimestamp":"1709257085210000","amount":0.48910916,"amount_str":"0.48910916","amount_traded":"0","amount_at_create":"0.48910916","price":61336,"price_str":"61336"},"channel":"live_orders_btcusd","event":"order_deleted"}
{"data":{"id":1722048962543617,"id_str":"1722048962543617","order_type":0,"datetime":"1709257085","microtimestamp":"1709257085211000","amount":0.01630307,"amount_str":"0.01630307","amount_traded":"0","amount_at_create":"0.01630307","price":61338,"price_str":"61338"},"channel":"live_orders_btcusd","event":"order_deleted"}
{"data":{"id":1722048965009410,"id_str":"1722048965009410","order_type":0,"datetime":"1709257085","microtimestamp":"1709257085256000","amount":0.48932443,"amount_str":"0.48932443","amount_traded":"0","amount_at_create":"0.48932443","price":61309,"price_str":"61309"},"channel":"live_orders_btcusd","event":"order_created"}
{"data":{"id":1722048965013505,"id_str":"1722048965013505","order_type":0,"datetime":"1709257085","microtimestamp":"1709257085256000","amount":0.01630339,"amount_str":"0.01630339","amount_traded":"0","amount_at_create":"0.01630339","price":61336,"price_str":"61336"},"channel":"live_orders_btcusd","event":"order_created"}
{"data":{"id":1722048965013506,"id_str":"1722048965013506","order_type":0,"datetime":"1709257085","microtimestamp":"1709257085256000","amount":0.48914788,"amount_str":"0.48914788","amount_traded":"0","amount_at_create":"0.48914788","price":61331,"price_str":"61331"},"channel":"live_orders_btcusd","event":"order_created"}
{"data":{"id":1722048965017603,"id_str":"1722048965017603","order_type":0,"datetime":"1709257085","microtimestamp":"1709257085257000","amount":0.48911891,"amount_str":"0.48911891","amount_traded":"0","amount_at_create":"0.48911891","price":61334,"price_str":"61334"},"channel":"live_orders_btcusd","event":"order_created"}
{"data":{"id":1722048964513795,"id_str":"1722048964513795","order_type":0,"datetime":"1709257085","microtimestamp":"1709257085273000","amount":0.00040751,"amount_str":"0.00040751","amount_traded":"0","amount_at_create":"0.00040751","price":61327,"price_str":"61327"},"channel":"live_orders_btcusd","event":"order_deleted"}
{"data":{"id":1722048896217092,"id_str":"1722048896217092","order_type":1,"datetime":"1709257085","microtimestamp":"1709257085280000","amount":0.1875,"amount_str":"0.18750000","amount_traded":"0","amount_at_create":"0.18750000","price":61376,"price_str":"61376"},"channel":"live_orders_btcusd","event":"order_deleted"}
{"data":{"id":1722048965357568,"id_str":"1722048965357568","order_type":0,"datetime":"1709257085","microtimestamp":"1709257085340000","amount":0.00040751,"amount_str":"0.00040751","amount_traded":"0","amount_at_create":"0.00040751","price":61327,"price_str":"61327"},"channel":"live_orders_btcusd","event":"order_created"}
{"data":{"id":1722048965357568,"id_str":"1722048965357568","order_type":0,"datetime":"1709257085","microtimestamp":"1709257085446000","amount":0.00040751,"amount_str":"0.00040751","amount_traded":"0","amount_at_create":"0.00040751","price":61327,"price_str":"61327"},"channel":"live_orders_btcusd","event":"order_deleted"}
{"data":{"id":1722048965013505,"id_str":"1722048965013505","order_type":0,"datetime":"1709257085","microtimestamp":"1709257085498000","amount":0.01630339,"amount_str":"0.01630339","amount_traded":"0","amount_at_create":"0.01630339","price":61336,"price_str":"61336"},"channel":"live_orders_btcusd","event":"order_deleted"}
{"data":{"id":1722048965017603,"id_str":"1722048965017603","order_type":0,"datetime":"1709257085","microtimestamp":"1709257085498000","amount":0.48911891,"amount_str":"0.48911891","amount_traded":"0","amount_at_create":"0.48911891","price":61334,"price_str":"61334"},"channel":"live_orders_btcusd","event":"order_deleted"}
{"data":{"id":1722048966107136,"id_str":"1722048966107136","order_type":0,"datetime":"1709257086","microtimestamp":"1709257085523000","amount":0.00040751,"amount_str":"0.00040751","amount_traded":"0","amount_at_create":"0.00040751","price":61328,"price_str":"61328"},"channel":"live_orders_btcusd","event":"order_created"}
{"data":{"id":1722048966193153,"id_str":"1722048966193153","order_type":0,"datetime":"1709257086","microtimestamp":"1709257085544000","amount":0.48911343,"amount_str":"0.48911343","amount_traded":"0","amount_at_create":"0.48911343","price":61335,"price_str":"61335"},"channel":"live_orders_btcusd","event":"order_created"}
{"data":{"id":1722048966193154,"id_str":"1722048966193154","order_type":0,"datetime":"1709257086","microtimestamp":"1709257085544000","amount":0.01630321,"amount_str":"0.01630321","amount_traded":"0","amount_at_create":"0.01630321","price":61337,"price_str":"61337"},"channel":"live_orders_btcusd","event":"order_created"}
{"data":{"id":1722048966369280,"id_str":"1722048966369280","order_type":1,"datetime":"1709257086","microtimestamp":"1709257085587000","amount":0.48869761,"amount_str":"0.48869761","amount_traded":"0","amount_at_create":"0.48869761","price":61388,"price_str":"61388"},"channel":"live_orders_btcusd","event":"order_created"}
{"data":{"id":1722048966107136,"id_str":"1722048966107136","order_type":0,"datetime":"1709257086","microtimestamp":"1709257085614000","amount":0.00040751,"amount_str":"0.00040751","amount_traded":"0","amount_at_create":"0.00040751","price":61328,"price_str":"61328"},"channel":"live_orders_btcusd","event":"order_deleted"}
{"data":{"id":1722048966696960,"id_str":"1722048966696960","order_type":0,"datetime":"1709257086","microtimestamp":"1709257085667000","amount":0.00040751,"amount_str":"0.00040751","amount_traded":"0","amount_at_create":"0.00040751","price":61327,"price_str":"61327"},"channel":"live_orders_btcusd","event":"order_created"}
{"data":{"id":1722048966696960,"id_str":"1722048966696960","order_type":0,"datetime":"1709257086","microtimestamp":"1709257085744000","amount":0.00040751,"amount_str":"0.00040751","amount_traded":"0","amount_at_create":"0.00040751","price":61327,"price_str":"61327"},"channel":"live_orders_btcusd","event":"order_deleted"}
{"data":{"id":1722048967172096,"id_str":"1722048967172096","order_type":0,"datetime":"1709257086","microtimestamp":"1709257085784000","amount":0.00040751,"amount_str":"0.00040751","amount_traded":"0","amount_at_create":"0.00040751","price":61328,"price_str":"61328"},"channel":"live_orders_btcusd","event":"order_created"}
{"data":{"id":1722048967172096,"id_str":"1722048967172096","order_type":0,"datetime":"1709257086","microtimestamp":"1709257085871000","amount":0.00040751,"amount_str":"0.00040751","amount_traded":"0","amount_at_create":"0.00040751","price":61328,"price_str":"61328"},"channel":"live_orders_btcusd","event":"order_deleted"}
{"data":{"id":1722048966193153,"id_str":"1722048966193153","order_type":0,"datetime":"1709257086","microtimestamp":"1709257085904000","amount":0.48911343,"amount_str":"0.48911343","amount_traded":"0","amount_at_create":"0.48911343","price":61335,"price_str":"61335"},"channel":"live_orders_btcusd","event":"order_deleted"}
{"data":{"id":1722048963751937,"id_str":"1722048963751937","order_type":1,"datetime":"1709257086","microtimestamp":"1709257085904000","amount":0.01630159,"amount_str":"0.01630159","amount_traded":"0","amount_at_create":"0.01630159","price":61344,"price_str":"61344"},"channel":"live_orders_btcusd","event":"order_deleted"}
{"data":{"id":1722048962547712,"id_str":"1722048962547712","order_type":0,"datetime":"1709257086","microtimestamp":"1709257085904000","amount":0.4891838,"amount_str":"0.48918380","amount_traded":"0","amount_at_create":"0.48918380","price":61326,"price_str":"61326"},"channel":"live_orders_btcusd","event":"order_deleted"}
{"data":{"id":1722048960692224,"id_str":"1722048960692224","order_type":1,"datetime":"1709257086","microtimestamp":"1709257085904000","amount":0.48899021,"amount_str":"0.48899021","amount_traded":"0","amount_at_create":"0.48899021","price":61351,"price_str":"61351"},"channel":"live_orders_btcusd","event":"order_deleted"}
{"data":{"id":1722048963751938,"id_str":"1722048963751938","order_type":1,"datetime":"1709257086","microtimestamp":"1709257085904000","amount":0.48903097,"amount_str":"0.48903097","amount_traded":"0","amount_at_create":"0.48903097","price":61346,"price_str":"61346"},"channel":"live_orders_btcusd","event":"order_deleted"}
{"data":{"id":1722048966193154,"id_str":"1722048966193154","order_type":0,"datetime":"1709257086","microtimestamp":"1709257085905000","amount":0.01630321,"amount_str":"0.01630321","amount_traded":"0","amount_at_create":"0.01630321","price":61337,"price_str":"61337"},"channel":"live_orders_btcusd","event":"order_deleted"}
{"data":{"id":1722048967860226,"id_str":"1722048967860226","order_type":1,"datetime":"1709257086","microtimestamp":"1709257085952000","amount":0.01630196,"amount_str":"0.01630196","amount_traded":"0","amount_at_create":"0.01630196","price":61343,"price_str":"61343"},"channel":"live_orders_btcusd","event":"order_created"}
{"data":{"id":1722048967868421,"id_str":"1722048967868421","order_type":1,"datetime":"1709257086","microtimestamp":"1709257085954000","amount":0.48901022,"amount_str":"0.48901022","amount_traded":"0","amount_at_create":"0.48901022","price":61349,"price_str":"61349"},"channel":"live_orders_btcusd","event":"order_created"}
{"data":{"id":1722048967872514,"id_str":"1722048967872514","order_type":1,"datetime":"1709257086","microtimestamp":"1709257085954000","amount":0.48904191,"amount_str":"0.48904191","amount_traded":"0","amount_at_create":"0.48904191","price":61345,"price_str":"61345"},"channel":"live_orders_btcusd","event":"order_created"}
{"data":{"id":1722048967872515,"id_str":"1722048967872515","order_type":0,"datetime":"1709257086","microtimestamp":"1709257085955000","amount":0.01630366,"amount_str":"0.01630366","amount_traded":"0","amount_at_create":"0.01630366","price":61335,"price_str":"61335"},"channel":"live_orders_btcusd","event":"order_created"}
{"data":{"id":1722048967876608,"id_str":"1722048967876608","order_type":0,"datetime":"1709257086","microtimestamp":"1709257085955000","amount":0.48912714,"amount_str":"0.48912714","amount_traded":"0","amount_at_create":"0.48912714","price":61333,"price_str":"61333"},"channel":"live_orders_btcusd","event":"order_created"}
{"data":{"id":1722048967876612,"id_str":"1722048967876612","order_type":0,"datetime":"1709257086","microtimestamp":"1709257085956000","amount":0.48921742,"amount_str":"0.48921742","amount_traded":"0","amount_at_create":"0.48921742","price":61322,"price_str":"61322"},"channel":"live_orders_btcusd","event":"order_created"}
{"data":{"id":1722048967999488,"id_str":"1722048967999488","order_type":0,"datetime":"1709257086","microtimestamp":"1709257085985000","amount":0.00040751,"amount_str":"0.00040751","amount_traded":"0","amount_at_create":"0.00040751","price":61327,"price_str":"61327"},"channel":"live_orders_btcusd","event":"order_created"}
{"data":{"id":1722048967860226,"id_str":"1722048967860226","order_type":1,"datetime":"1709257086","microtimestamp":"1709257085996000","amount":0.01630196,"amount_str":"0.01630196","amount_traded":"0","amount_at_create":"0.01630196","price":61343,"price_str":"61343"},"channel":"live_orders_btcusd","event":"order_deleted"}
{"data":{"id":1722048967999488,"id_str":"1722048967999488","order_type":0,"datetime":"1709257086","microtimestamp":"1709257086035000","amount":0.00040751,"amount_str":"0.00040751","amount_traded":"0","amount_at_create":"0.00040751","price":61327,"price_str":"61327"},"channel":"live_orders_btcusd","event":"order_deleted"}
{"data":{"id":1722048967872514,"id_str":"1722048967872514","order_type":1,"datetime":"1709257086","microtimestamp":"1709257086039000","amount":0.48904191,"amount_str":"0.48904191","amount_traded":"0","amount_at_create":"0.48904191","price":61345,"price_str":"61345"},"channel":"live_orders_btcusd","event":"order_deleted"}
{"data":{"id":1722048968269824,"id_str":"1722048968269824","order_type":1,"datetime":"1709257086","microtimestamp":"1709257086051000","amount":0.01630208,"amount_str":"0.01630208","amount_traded":"0","amount_at_create":"0.01630208","price":61342,"price_str":"61342"},"channel":"live_orders_btcusd","event":"order_created"}
{"data":{"id":1722048968425473,"id_str":"1722048968425473","order_type":0,"datetime":"1709257086","microtimestamp":"1709257086089000","amount":0.00040751,"amount_str":"0.00040751","amount_traded":"0","amount_at_create":"0.00040751","price":61328,"price_str":"61328"},"channel":"live_orders_btcusd","event":"order_created"}
{"data":{"id":1722048968269824,"id_str":"1722048968269824","order_type":1,"datetime":"1709257086","microtimestamp":"1709257086097000","amount":0.01630208,"amount_str":"0.01630208","amount_traded":"0","amount_at_create":"0.01630208","price":61342,"price_str":"61342"},"channel":"live_orders_btcusd","event":"order_deleted"}
{"data":{"id":1722048967872515,"id_str":"1722048967872515","order_type":0,"datetime":"1709257086","microtimestamp":"1709257086098000","amount":0.01630366,"amount_str":"0.01630366","amount_traded":"0","amount_at_create":"0.01630366","price":61335,"price_str":"61335"},"channel":"live_orders_btcusd","event":"order_deleted"}
{"data":{"id":1722048968425473,"id_str":"1722048968425473","order_type":0,"datetime":"1709257086","microtimestamp":"1709257086124000","amount":0.00040751,"amount_str":"0.00040751","amount_traded":"0","amount_at_create":"0.00040751","price":61328,"price_str":"61328"},"channel":"live_orders_btcusd","event":"order_deleted"}
{"data":{"id":1722048968646656,"id_str":"1722048968646656","order_type":0,"datetime":"1709257086","microtimestamp":"1709257086143000","amount":0.01630362,"amount_str":"0.01630362","amount_traded":"0","amount_at_create":"0.01630362","price":61336,"price_str":"61336"},"channel":"live_orders_btcusd","event":"order_created"}
{"data":{"id":1722048955322369,"id_str":"1722048955322369","order_type":0,"datetime":"1709257086","microtimestamp":"1709257086158000","amount":0.16302442,"amount_str":"0.16302442","amount_traded":"0","amount_at_create":"0.16302442","price":61313,"price_str":"61313"},"channel":"live_orders_btcusd","event":"order_deleted"}
{"data":{"id":1722048968753153,"id_str":"1722048968753153","order_type":0,"datetime":"1709257086","microtimestamp":"1709257086169000","amount":0.00040751,"amount_str":"0.00040751","amount_traded":"0","amount_at_create":"0.00040751","price":61327,"price_str":"61327"},"channel":"live_orders_btcusd","event":"order_created"}
{"data":{"id":1722048968785921,"id_str":"1722048968785921","order_type":0,"datetime":"1709257086","microtimestamp":"1709257086178000","amount":0.16302974,"amount_str":"0.16302974","amount_traded":"0","amount_at_create":"0.16302974","price":61318,"price_str":"61318"},"channel":"live_orders_btcusd","event":"order_created"}
{"data":{"id":1722048968822784,"id_str":"1722048968822784","order_type":1,"datetime":"1709257086","microtimestamp":"1709257086186000","amount":0.48904538,"amount_str":"0.48904538","amount_traded":"0","amount_at_create":"0.48904538","price":61344,"price_str":"61344"},"channel":"live_orders_btcusd","event":"order_created"}
{"data":{"id":1722048968839168,"id_str":"1722048968839168","order_type":1,"datetime":"1709257086","microtimestamp":"1709257086190000","amount":0.01630191,"amount_str":"0.01630191","amount_traded":"0","amount_at_create":"0.01630191","price":61343,"price_str":"61343"},"channel":"live_orders_btcusd","event":"order_created"}
{"data":{"id":1722048967876608,"id_str":"1722048967876608","order_type":0,"datetime":"1709257086","microtimestamp":"1709257086198000","amount":0.48912714,"amount_str":"0.48912714","amount_traded":"0","amount_at_create":"0.48912714","price":61333,"price_str":"61333"},"channel":"live_orders_btcusd","event":"order_deleted"}
{"data":{"id":1722048954707972,"id_str":"1722048954707972","order_type":0,"datetime":"1709257086","microtimestamp":"1709257086226000","amount":0.00815075,"amount_str":"0.00815075","amount_traded":"0","amount_at_create":"0.00815075","price":61333,"price_str":"61333"},"channel":"live_orders_btcusd","event":"order_deleted"}
{"data":{"id":1722048968753153,"id_str":"1722048968753153","order_type":0,"datetime":"1709257086","microtimestamp":"1709257086232000","amount":0.00040751,"amount_str":"0.00040751","amount_traded":"0","amount_at_create":"0.00040751","price":61327,"price_str":"61327"},"channel":"live_orders_btcusd","event":"order_deleted"}
{"data":{"id":1722048969043971,"id_str":"1722048969043971","order_type":0,"datetime":"1709257086","microtimestamp":"1709257086240000","amount":0.48912469,"amount_str":"0.48912469","amount_traded":"0","amount_at_create":"0.48912469","price":61334,"price_str":"61334"},"channel":"live_orders_btcusd","event":"order_created"}
{"data":{"id":1722048969150465,"id_str":"1722048969150465","order_type":0,"datetime":"1709257086","microtimestamp":"1709257086267000","amount":0.00815135,"amount_str":"0.00815135","amount_traded":"0","amount_at_create":"0.00815135","price":61337,"price_str":"61337"},"channel":"live_orders_btcusd","event":"order_created"}
{"data":{"id":1722048969211904,"id_str":"1722048969211904","order_type":0,"datetime":"1709257086","microtimestamp":"1709257086282000","amount":0.00040751,"amount_str":"0.00040751","amount_traded":"0","amount_at_create":"0.00040751","price":61328,"price_str":"61328"},"channel":"live_orders_btcusd","event":"order_created"}
{"data":{"id":1722048969211904,"id_str":"1722048969211904","order_type":0,"datetime":"1709257086","microtimestamp":"1709257086351000","amount":0.00040751,"amount_str":"0.00040751","amount_traded":"0","amount_at_create":"0.00040751","price":61328,"price_str":"61328"},"channel":"live_orders_btcusd","event":"order_deleted"}
{"data":{"id":1722048969654272,"id_str":"1722048969654272","order_type":0,"datetime":"1709257086","microtimestamp":"1709257086389000","amount":0.00040751,"amount_str":"0.00040751","amount_traded":"0","amount_at_create":"0.00040751","price":61327,"price_str":"61327"},"channel":"live_orders_btcusd","event":"order_created"}
{"data":{"id":1722048969654272,"id_str":"1722048969654272","order_type":0,"datetime":"1709257086","microtimestamp":"1709257086461000","amount":0.00040751,"amount_str":"0.00040751","amount_traded":"0","amount_at_create":"0.00040751","price":61327,"price_str":"61327"},"channel":"live_orders_btcusd","event":"order_deleted"}
{"data":{"id":1722048968839168,"id_str":"1722048968839168","order_type":1,"datetime":"1709257087","microtimestamp":"1709257086502000","amount":0.01630191,"amount_str":"0.01630191","amount_traded":"0","amount_at_create":"0.01630191","price":61343,"price_str":"61343"},"channel":"live_orders_btcusd","event":"order_deleted"}
{"data":{"id":1722048970223616,"id_str":"1722048970223616","order_type":0,"datetime":"1709257087","microtimestamp":"1709257086528000","amount":0.00040751,"amount_str":"0.00040751","amount_traded":"0","amount_at_create":"0.00040751","price":61328,"price_str":"61328"},"channel":"live_orders_btcusd","event":"order_created"}
{"data":{"id":1722048970305536,"id_str":"1722048970305536","order_type":1,"datetime":"1709257087","microtimestamp":"1709257086549000","amount":0.0163021,"amount_str":"0.01630210","amount_traded":"0","amount_at_create":"0.01630210","price":61342,"price_str":"61342"},"channel":"live_orders_btcusd","event":"order_created"}
{"data":{"id":1722048970223616,"id_str":"1722048970223616","order_type":0,"datetime":"1709257087","microtimestamp":"1709257086578000","amount":0.00040751,"amount_str":"0.00040751","amount_traded":"0","amount_at_create":"0.00040751","price":61328,"price_str":"61328"},"channel":"live_orders_btcusd","event":"order_deleted"}
{"data":{"id":1722048970653696,"id_str":"1722048970653696","order_type":0,"datetime":"1709257087","microtimestamp":"1709257086633000","amount":0.00040751,"amount_str":"0.00040751","amount_traded":"0","amount_at_create":"0.00040751","price":61327,"price_str":"61327"},"channel":"live_orders_btcusd","event":"order_created"}
{"data":{"id":1722048970653696,"id_str":"1722048970653696","order_type":0,"datetime":"1709257087","microtimestamp":"1709257086742000","amount":0.00040751,"amount_str":"0.00040751","amount_traded":"0","amount_at_create":"0.00040751","price":61327,"price_str":"61327"},"channel":"live_orders_btcusd","event":"order_deleted"}
{"data":{"id":1722048971276289,"id_str":"1722048971276289","order_type":0,"datetime":"1709257087","microtimestamp":"1709257086785000","amount":0.00040751,"amount_str":"0.00040751","amount_traded":"0","amount_at_create":"0.00040751","price":61328,"price_str":"61328"},"channel":"live_orders_btcusd","event":"order_created"}
{"data":{"id":1722048971276289,"id_str":"1722048971276289","order_type":0,"datetime":"1709257087","microtimestamp":"1709257086856000","amount":0.00040751,"amount_str":"0.00040751","amount_traded":"0","amount_at_create":"0.00040751","price":61328,"price_str":"61328"},"channel":"live_orders_btcusd","event":"order_deleted"}
{"data":{"id":1722048965013506,"id_str":"1722048965013506","order_type":0,"datetime":"1709257087","microtimestamp":"1709257086898000","amount":0.48914788,"amount_str":"0.48914788","amount_traded":"0","amount_at_create":"0.48914788","price":61331,"price_str":"61331"},"channel":"live_orders_btcusd","event":"order_deleted"}
{"data":{"id":1722048969043971,"id_str":"1722048969043971","order_type":0,"datetime":"1709257087","microtimestamp":"1709257086898000","amount":0.48912469,"amount_str":"0.48912469","amount_traded":"0","amount_at_create":"0.48912469","price":61334,"price_str":"61334"},"channel":"live_orders_btcusd","event":"order_deleted"}
{"data":{"id":1722048971751425,"id_str":"1722048971751425","order_type":0,"datetime":"1709257087","microtimestamp":"1709257086901000","amount":0.00040751,"amount_str":"0.00040751","amount_traded":"0","amount_at_create":"0.00040751","price":61327,"price_str":"61327"},"channel":"live_orders_btcusd","event":"order_created"}
{"data":{"id":1722048971923457,"id_str":"1722048971923457","order_type":0,"datetime":"1709257087","microtimestamp":"1709257086943000","amount":0.48913357,"amount_str":"0.48913357","amount_traded":"0","amount_at_create":"0.48913357","price":61332,"price_str":"61332"},"channel":"live_orders_btcusd","event":"order_created"}
{"data":{"id":1722048971935744,"id_str":"1722048971935744","order_type":0,"datetime":"1709257087","microtimestamp":"1709257086946000","amount":0.4891654,"amount_str":"0.48916540","amount_traded":"0","amount_at_create":"0.48916540","price":61328,"price_str":"61328"},"channel":"live_orders_btcusd","event":"order_created"}
{"data":{"id":1722048971923457,"id_str":"1722048971923457","order_type":0,"datetime":"1709257087","microtimestamp":"1709257087098000","amount":0.48913357,"amount_str":"0.48913357","amount_traded":"0","amount_at_create":"0.48913357","price":61332,"price_str":"61332"},"channel":"live_orders_btcusd","event":"order_deleted"}
{"data":{"id":1722048971751425,"id_str":"1722048971751425","order_type":0,"datetime":"1709257087","microtimestamp":"1709257087117000","amount":0.00040751,"amount_str":"0.00040751","amount_traded":"0","amount_at_create":"0.00040751","price":61327,"price_str":"61327"},"channel":"live_orders_btcusd","event":"order_deleted"}
{"data":{"id":1722048973393920,"id_str":"1722048973393920","order_type":0,"datetime":"1709257087","microtimestamp":"1709257087302000","amount":0.00040751,"amount_str":"0.00040751","amount_traded":"0","amount_at_create":"0.00040751","price":61328,"price_str":"61328"},"channel":"live_orders_btcusd","event":"order_created"}
{"data":{"id":1722048973393920,"id_str":"1722048973393920","order_type":0,"datetime":"1709257087","microtimestamp":"1709257087339000","amount":0.00040751,"amount_str":"0.00040751","amount_traded":"0","amount_at_create":"0.00040751","price":61328,"price_str":"61328"},"channel":"live_orders_btcusd","event":"order_deleted"}
{"data":{"id":1722048974020608,"id_str":"1722048974020608","order_type":0,"datetime":"1709257087","microtimestamp":"1709257087455000","amount":0.00040751,"amount_str":"0.00040751","amount_traded":"0","amount_at_create":"0.00040751","price":61327,"price_str":"61327"},"channel":"live_orders_btcusd","event":"order_created"}
{"data":{"id":1722048974020608,"id_str":"1722048974020608","order_type":0,"datetime":"1709257088","microtimestamp":"1709257087534000","amount":0.00040751,"amount_str":"0.00040751","amount_traded":"0","amount_at_create":"0.00040751","price":61327,"price_str":"61327"},"channel":"live_orders_btcusd","event":"order_deleted"}
{"data":{"id":1722048974671872,"id_str":"1722048974671872","order_type":0,"datetime":"1709257088","microtimestamp":"1709257087614000","amount":0.00040751,"amount_str":"0.00040751","amount_traded":"0","amount_at_create":"0.00040751","price":61328,"price_str":"61328"},"channel":"live_orders_btcusd","event":"order_created"}
{"data":{"id":1722048974671872,"id_str":"1722048974671872","order_type":0,"datetime":"1709257088","microtimestamp":"1709257087639000","amount":0.00040751,"amount_str":"0.00040751","amount_traded":"0","amount_at_create":"0.00040751","price":61328,"price_str":"61328"},"channel":"live_orders_btcusd","event":"order_deleted"}
{"data":{"id":1722048974995456,"id_str":"1722048974995456","order_type":0,"datetime":"1709257088","microtimestamp":"1709257087693000","amount":0.00040751,"amount_str":"0.00040751","amount_traded":"0","amount_at_create":"0.00040751","price":61327,"price_str":"61327"},"channel":"live_orders_btcusd","event":"order_created"}
{"data":{"id":1722048969150465,"id_str":"1722048969150465","order_type":0,"datetime":"1709257088","microtimestamp":"1709257087785000","amount":0.00815135,"amount_str":"0.00815135","amount_traded":"0","amount_at_create":"0.00815135","price":61337,"price_str":"61337"},"channel":"live_orders_btcusd","event":"order_deleted"}
{"data":{"id":1722048960921600,"id_str":"1722048960921600","order_type":1,"datetime":"1709257088","microtimestamp":"1709257087793000","amount":0.02450374,"amount_str":"0.02450374","amount_traded":"0","amount_at_create":"0.02450374","price":61363,"price_str":"61363"},"channel":"live_orders_btcusd","event":"order_deleted"}
{"data":{"id":1722048965009410,"id_str":"1722048965009410","order_type":0,"datetime":"1709257088","microtimestamp":"1709257087808000","amount":0.48932443,"amount_str":"0.48932443","amount_traded":"0","amount_at_create":"0.48932443","price":61309,"price_str":"61309"},"channel":"live_orders_btcusd","event":"order_deleted"}
{"data":{"id":1722048954130438,"id_str":"1722048954130438","order_type":0,"datetime":"1709257088","microtimestamp":"1709257087809000","amount":3.06724851,"amount_str":"3.06724851","amount_traded":"0","amount_at_create":"3.06724851","price":61326,"price_str":"61326"},"channel":"live_orders_btcusd","event":"order_deleted"}
{"data":{"id":1722048958275586,"id_str":"1722048958275586","order_type":1,"datetime":"1709257088","microtimestamp":"1709257087809000","amount":0.48894503,"amount_str":"0.48894503","amount_traded":"0","amount_at_create":"0.48894503","price":61357,"price_str":"61357"},"channel":"live_orders_btcusd","event":"order_deleted"}
{"data":{"id":1722048962367489,"id_str":"1722048962367489","order_type":1,"datetime":"1709257088","microtimestamp":"1709257087809000","amount":0.48881557,"amount_str":"0.48881557","amount_traded":"0","amount_at_create":"0.48881557","price":61373,"price_str":"61373"},"channel":"live_orders_btcusd","event":"order_deleted"}
{"data":{"id":1722048966369280,"id_str":"1722048966369280","order_type":1,"datetime":"1709257088","microtimestamp":"1709257087810000","amount":0.48869761,"amount_str":"0.48869761","amount_traded":"0","amount_at_create":"0.48869761","price":61388,"price_str":"61388"},"channel":"live_orders_btcusd","event":"order_deleted"}
{"data":{"id":1722048968646656,"id_str":"1722048968646656","order_type":0,"datetime":"1709257088","microtimestamp":"1709257087810000","amount":0.01630362,"amount_str":"0.01630362","amount_traded":"0","amount_at_create":"0.01630362","price":61336,"price_str":"61336"},"channel":"live_orders_btcusd","event":"order_deleted"}
{"data":{"id":1722048967876612,"id_str":"1722048967876612","order_type":0,"datetime":"1709257088","microtimestamp":"1709257087811000","amount":0.48921742,"amount_str":"0.48921742","amount_traded":"0","amount_at_create":"0.48921742","price":61322,"price_str":"61322"},"channel":"live_orders_btcusd","event":"order_deleted"}
{"data":{"id":1722048970305536,"id_str":"1722048970305536","order_type":1,"datetime":"1709257088","microtimestamp":"1709257087811000","amount":0.0163021,"amount_str":"0.01630210","amount_traded":"0","amount_at_create":"0.01630210","price":61342,"price_str":"61342"},"channel":"live_orders_btcusd","event":"order_deleted"}
{"data":{"id":1722048968822784,"id_str":"1722048968822784","order_type":1,"datetime":"1709257088","microtimestamp":"1709257087811000","amount":0.48904538,"amount_str":"0.48904538","amount_traded":"0","amount_at_create":"0.48904538","price":61344,"price_str":"61344"},"channel":"live_orders_btcusd","event":"order_deleted"}
{"data":{"id":1722048971935744,"id_str":"1722048971935744","order_type":0,"datetime":"1709257088","microtimestamp":"1709257087811000","amount":0.4891654,"amount_str":"0.48916540","amount_traded":"0","amount_at_create":"0.48916540","price":61328,"price_str":"61328"},"channel":"live_orders_btcusd","event":"order_deleted"}
{"data":{"id":1722048967868421,"id_str":"1722048967868421","order_type":1,"datetime":"1709257088","microtimestamp":"1709257087811000","amount":0.48901022,"amount_str":"0.48901022","amount_traded":"0","amount_at_create":"0.48901022","price":61349,"price_str":"61349"},"channel":"live_orders_btcusd","event":"order_deleted"}
{"data":{"id":1722048915824641,"id_str":"1722048915824641","order_type":0,"datetime":"1709257088","microtimestamp":"1709257087812000","amount":0.16337902,"amount_str":"0.16337902","amount_traded":"0","amount_at_create":"0.16337902","price":61207,"price_str":"61207"},"channel":"live_orders_btcusd","event":"order_deleted"}
{"data":{"id":1722048960315396,"id_str":"1722048960315396","order_type":0,"datetime":"1709257088","microtimestamp":"1709257087824000","amount":0.00815135,"amount_str":"0.00815135","amount_traded":"0","amount_at_create":"0.00815135","price":61335,"price_str":"61335"},"channel":"live_orders_btcusd","event":"order_deleted"}
{"data":{"id":1722048974995456,"id_str":"1722048974995456","order_type":0,"datetime":"1709257088","microtimestamp":"1709257087829000","amount":0.00040751,"amount_str":"0.00040751","amount_traded":"0","amount_at_create":"0.00040751","price":61327,"price_str":"61327"},"channel":"live_orders_btcusd","event":"order_deleted"}
{"data":{"id":1722048954437633,"id_str":"1722048954437633","order_type":0,"datetime":"1709257088","microtimestamp":"1709257087835000","amount":0.1875,"amount_str":"0.18750000","amount_traded":"0","amount_at_create":"0.18750000","price":61321,"price_str":"61321"},"channel":"live_orders_btcusd","event":"order_deleted"}
{"data":{"id":1722048975605760,"id_str":"1722048975605760","order_type":1,"datetime":"1709257088","microtimestamp":"1709257087842000","amount":0.00487168,"amount_str":"0.00487168","amount_traded":"0","amount_at_create":"0.00487168","price":61350,"price_str":"61350"},"channel":"live_orders_btcusd","event":"order_created"}
{"data":{"id":1722048925134848,"id_str":"1722048925134848","order_type":0,"datetime":"1709257088","microtimestamp":"1709257087847000","amount":0.16329874,"amount_str":"0.16329874","amount_traded":"0","amount_at_create":"0.16329874","price":61237,"price_str":"61237"},"channel":"live_orders_btcusd","event":"order_deleted"}
{"data":{"id":1722048960425986,"id_str":"1722048960425986","order_type":0,"datetime":"1709257088","microtimestamp":"1709257087850000","amount":0.48943745,"amount_str":"0.48943745","amount_traded":"0","amount_at_create":"0.48943745","price":61294,"price_str":"61294"},"channel":"live_orders_btcusd","event":"order_deleted"}
{"data":{"id":1722048975642625,"id_str":"1722048975642625","order_type":1,"datetime":"1709257088","microtimestamp":"1709257087851000","amount":0.02272192,"amount_str":"0.02272192","amount_traded":"0","amount_at_create":"0.02272192","price":61362,"price_str":"61362"},"channel":"live_orders_btcusd","event":"order_created"}
{"data":{"id":1722048975663113,"id_str":"1722048975663113","order_type":0,"datetime":"1709257088","microtimestamp":"1709257087857000","amount":3.06707818,"amount_str":"3.06707818","amount_traded":"0","amount_at_create":"3.06707818","price":61325,"price_str":"61325"},"channel":"live_orders_btcusd","event":"order_created"}
{"data":{"id":1722048975691782,"id_str":"1722048975691782","order_type":0,"datetime":"1709257088","microtimestamp":"1709257087863000","amount":0.00815135,"amount_str":"0.00815135","amount_traded":"0","amount_at_create":"0.00815135","price":61333,"price_str":"61333"},"channel":"live_orders_btcusd","event":"order_created"}
{"data":{"id":1722048960987136,"id_str":"1722048960987136","order_type":1,"datetime":"1709257088","microtimestamp":"1709257087872000","amount":0.00487152,"amount_str":"0.00487152","amount_traded":"0","amount_at_create":"0.00487152","price":61352,"price_str":"61352"},"channel":"live_orders_btcusd","event":"order_deleted"}
{"data":{"id":1722048975740933,"id_str":"1722048975740933","order_type":1,"datetime":"1709257088","microtimestamp":"1709257087876000","amount":0.48887958,"amount_str":"0.48887958","amount_traded":"0","amount_at_create":"0.48887958","price":61365,"price_str":"61365"},"channel":"live_orders_btcusd","event":"order_created"}
{"data":{"id":1722048975753218,"id_str":"1722048975753218","order_type":1,"datetime":"1709257088","microtimestamp":"1709257087879000","amount":0.48855241,"amount_str":"0.48855241","amount_traded":"0","amount_at_create":"0.48855241","price":61406,"price_str":"61406"},"channel":"live_orders_btcusd","event":"order_created"}
{"data":{"id":1722048975757314,"id_str":"1722048975757314","order_type":0,"datetime":"1709257088","microtimestamp":"1709257087880000","amount":0.48917456,"amount_str":"0.48917456","amount_traded":"0","amount_at_create":"0.48917456","price":61327,"price_str":"61327"},"channel":"live_orders_btcusd","event":"order_created"}
{"data":{"id":1722048915152898,"id_str":"1722048915152898","order_type":1,"datetime":"1709257088","microtimestamp":"1709257087880000","amount":0.5,"amount_str":"0.50000000","amount_traded":"0","amount_at_create":"0.50000000","price":61389,"price_str":"61389"},"channel":"live_orders_btcusd","event":"order_deleted"}
{"data":{"id":1722048975769600,"id_str":"1722048975769600","order_type":0,"datetime":"1709257088","microtimestamp":"1709257087882000","amount":0.48969318,"amount_str":"0.48969318","amount_traded":"0","amount_at_create":"0.48969318","price":61262,"price_str":"61262"},"channel":"live_orders_btcusd","event":"order_created"}
{"data":{"id":1722048975769602,"id_str":"1722048975769602","order_type":1,"datetime":"1709257088","microtimestamp":"1709257087882000","amount":0.48899241,"amount_str":"0.48899241","amount_traded":"0","amount_at_create":"0.48899241","price":61351,"price_str":"61351"},"channel":"live_orders_btcusd","event":"order_created"}
{"data":{"id":1722048975769603,"id_str":"1722048975769603","order_type":1,"datetime":"1709257088","microtimestamp":"1709257087883000","amount":0.48905254,"amount_str":"0.48905254","amount_traded":"0","amount_at_create":"0.48905254","price":61344,"price_str":"61344"},"channel":"live_orders_btcusd","event":"order_created"}
{"data":{"id":1722048975773699,"id_str":"1722048975773699","order_type":0,"datetime":"1709257088","microtimestamp":"1709257087884000","amount":0.48935589,"amount_str":"0.48935589","amount_traded":"0","amount_at_create":"0.48935589","price":61305,"price_str":"61305"},"channel":"live_orders_btcusd","event":"order_created"}
{"data":{"id":1722048975777792,"id_str":"1722048975777792","order_type":0,"datetime":"1709257088","microtimestamp":"1709257087884000","amount":0.48924932,"amount_str":"0.48924932","amount_traded":"0","amount_at_create":"0.48924932","price":61318,"price_str":"61318"},"channel":"live_orders_btcusd","event":"order_created"}
{"data":{"id":1722048975777795,"id_str":"1722048975777795","order_type":1,"datetime":"1709257088","microtimestamp":"1709257087884000","amount":0.01630337,"amount_str":"0.01630337","amount_traded":"0","amount_at_create":"0.01630337","price":61337,"price_str":"61337"},"channel":"live_orders_btcusd","event":"order_created"}
{"data":{"id":1722048975777798,"id_str":"1722048975777798","order_type":0,"datetime":"1709257088","microtimestamp":"1709257087884000","amount":0.016305,"amount_str":"0.01630500","amount_traded":"0","amount_at_create":"0.01630500","price":61330,"price_str":"61330"},"channel":"live_orders_btcusd","event":"order_created"}
{"data":{"id":1722048975777802,"id_str":"1722048975777802","order_type":0,"datetime":"1709257088","microtimestamp":"1709257087885000","amount":0.48919036,"amount_str":"0.48919036","amount_traded":"0","amount_at_create":"0.48919036","price":61325,"price_str":"61325"},"channel":"live_orders_btcusd","event":"order_created"}
{"data":{"id":1722048975781889,"id_str":"1722048975781889","order_type":0,"datetime":"1709257088","microtimestamp":"1709257087885000","amount":0.16340834,"amount_str":"0.16340834","amount_traded":"0","amount_at_create":"0.16340834","price":61196,"price_str":"61196"},"channel":"live_orders_btcusd","event":"order_created"}
{"data":{"id":1722048975790085,"id_str":"1722048975790085","order_type":1,"datetime":"1709257088","microtimestamp":"1709257087888000","amount":0.1875,"amount_str":"0.18750000","amount_traded":"0","amount_at_create":"0.18750000","price":61352,"price_str":"61352"},"channel":"live_orders_btcusd","event":"order_created"}
{"data":{"id":1722048975798276,"id_str":"1722048975798276","order_type":1,"datetime":"1709257088","microtimestamp":"1709257087890000","amount":0.4890693,"amount_str":"0.48906930","amount_traded":"0","amount_at_create":"0.48906930","price":61341,"price_str":"61341"},"channel":"live_orders_btcusd","event":"order_created"}
{"data":{"id":1722048975802372,"id_str":"1722048975802372","order_type":1,"datetime":"1709257088","microtimestamp":"1709257087891000","amount":0.00487168,"amount_str":"0.00487168","amount_traded":"0","amount_at_create":"0.00487168","price":61348,"price_str":"61348"},"channel":"live_orders_btcusd","event":"order_created"}
{"data":{"id":1722048968785921,"id_str":"1722048968785921","order_type":0,"datetime":"1709257088","microtimestamp":"1709257087898000","amount":0.16302974,"amount_str":"0.16302974","amount_traded":"0","amount_at_create":"0.16302974","price":61318,"price_str":"61318"},"channel":"live_orders_btcusd","event":"order_deleted"}
{"data":{"id":1722048975855616,"id_str":"1722048975855616","order_type":0,"datetime":"1709257088","microtimestamp":"1709257087904000","amount":0.1875,"amount_str":"0.18750000","amount_traded":"0","amount_at_create":"0.18750000","price":61280,"price_str":"61280"},"channel":"live_orders_btcusd","event":"order_created"}
{"data":{"id":1722048975642625,"id_str":"1722048975642625","order_type":1,"datetime":"1709257088","microtimestamp":"1709257087904000","amount":0.02272192,"amount_str":"0.02272192","amount_traded":"0","amount_at_create":"0.02272192","price":61362,"price_str":"61362"},"channel":"live_orders_btcusd","event":"order_deleted"}
{"data":{"id":1722048975892480,"id_str":"1722048975892480","order_type":1,"datetime":"1709257088","microtimestamp":"1709257087912000","amount":0.5,"amount_str":"0.50000000","amount_traded":"0","amount_at_create":"0.50000000","price":61378,"price_str":"61378"},"channel":"live_orders_btcusd","event":"order_created"}
{"data":{"id":1722048975769603,"id_str":"1722048975769603","order_type":1,"datetime":"1709257088","microtimestamp":"1709257087913000","amount":0.48905254,"amount_str":"0.48905254","amount_traded":"0","amount_at_create":"0.48905254","price":61344,"price_str":"61344"},"channel":"live_orders_btcusd","event":"order_deleted"}
{"data":{"id":1722048975798276,"id_str":"1722048975798276","order_type":1,"datetime":"1709257088","microtimestamp":"1709257087913000","amount":0.4890693,"amount_str":"0.48906930","amount_traded":"0","amount_at_create":"0.48906930","price":61341,"price_str":"61341"},"channel":"live_orders_btcusd","event":"order_deleted"}
{"data":{"id":1722048975777802,"id_str":"1722048975777802","order_type":0,"datetime":"1709257088","microtimestamp":"1709257087913000","amount":0.48919036,"amount_str":"0.48919036","amount_traded":"0","amount_at_create":"0.48919036","price":61325,"price_str":"61325"},"channel":"live_orders_btcusd","event":"order_deleted"}
{"data":{"id":1722048975912960,"id_str":"1722048975912960","order_type":0,"datetime":"1709257088","microtimestamp":"1709257087918000","amount":0.00815142,"amount_str":"0.00815142","amount_traded":"0","amount_at_create":"0.00815142","price":61331,"price_str":"61331"},"channel":"live_orders_btcusd","event":"order_created"}
{"data":{"id":1722048975949826,"id_str":"1722048975949826","order_type":0,"datetime":"1709257088","microtimestamp":"1709257087927000","amount":0.00040751,"amount_str":"0.00040751","amount_traded":"0","amount_at_create":"0.00040751","price":61328,"price_str":"61328"},"channel":"live_orders_btcusd","event":"order_created"}
{"data":{"id":1722048975777798,"id_str":"1722048975777798","order_type":0,"datetime":"1709257088","microtimestamp":"1709257087934000","amount":0.016305,"amount_str":"0.01630500","amount_traded":"0","amount_at_create":"0.01630500","price":61330,"price_str":"61330"},"channel":"live_orders_btcusd","event":"order_deleted"}
{"data":{"id":1722048975777795,"id_str":"1722048975777795","order_type":1,"datetime":"1709257088","microtimestamp":"1709257087935000","amount":0.01630337,"amount_str":"0.01630337","amount_traded":"0","amount_at_create":"0.01630337","price":61337,"price_str":"61337"},"channel":"live_orders_btcusd","event":"order_deleted"}
{"data":{"id":1722048975773699,"id_str":"1722048975773699","order_type":0,"datetime":"1709257088","microtimestamp":"1709257087936000","amount":0.48935589,"amount_str":"0.48935589","amount_traded":"0","amount_at_create":"0.48935589","price":61305,"price_str":"61305"},"channel":"live_orders_btcusd","event":"order_deleted"}
{"data":{"id":1722048959868928,"id_str":"1722048959868928","order_type":0,"datetime":"1709257088","microtimestamp":"1709257087938000","amount":0.06518467,"amount_str":"0.06518467","amount_traded":"0","amount_at_create":"0.06518467","price":61321,"price_str":"61321"},"channel":"live_orders_btcusd","event":"order_deleted"}
{"data":{"id":1722048975691782,"id_str":"1722048975691782","order_type":0,"datetime":"1709257088","microtimestamp":"1709257087948000","amount":0.00815135,"amount_str":"0.00815135","amount_traded":"0","amount_at_create":"0.00815135","price":61333,"price_str":"61333"},"channel":"live_orders_btcusd","event":"order_deleted"}
{"data":{"id":1722048976113665,"id_str":"1722048976113665","order_type":0,"datetime":"1709257088","microtimestamp":"1709257087966000","amount":0.16302841,"amount_str":"0.16302841","amount_traded":"0","amount_at_create":"0.16302841","price":61311,"price_str":"61311"},"channel":"live_orders_btcusd","event":"order_created"}
{"data":{"id":1722048975605760,"id_str":"1722048975605760","order_type":1,"datetime":"1709257088","microtimestamp":"1709257087973000","amount":0.00487168,"amount_str":"0.00487168","amount_traded":"0","amount_at_create":"0.00487168","price":61350,"price_str":"61350"},"channel":"live_orders_btcusd","event":"order_deleted"}
{"data":{"id":1722048976179203,"id_str":"1722048976179203","order_type":0,"datetime":"1709257088","microtimestamp":"1709257087983000","amount":0.16332364,"amount_str":"0.16332364","amount_traded":"0","amount_at_create":"0.16332364","price":61228,"price_str":"61228"},"channel":"live_orders_btcusd","event":"order_created"}
{"data":{"id":1722048976183296,"id_str":"1722048976183296","order_type":1,"datetime":"1709257088","microtimestamp":"1709257087983000","amount":0.01630369,"amount_str":"0.01630369","amount_traded":"0","amount_at_create":"0.01630369","price":61336,"price_str":"61336"},"channel":"live_orders_btcusd","event":"order_created"}
{"data":{"id":1722048976191488,"id_str":"1722048976191488","order_type":0,"datetime":"1709257088","microtimestamp":"1709257087985000","amount":0.48948895,"amount_str":"0.48948895","amount_traded":"0","amount_at_create":"0.48948895","price":61288,"price_str":"61288"},"channel":"live_orders_btcusd","event":"order_created"}
{"data":{"id":1722048976199682,"id_str":"1722048976199682","order_type":0,"datetime":"1709257088","microtimestamp":"1709257087987000","amount":0.01630559,"amount_str":"0.01630559","amount_traded":"0","amount_at_create":"0.01630559","price":61328,"price_str":"61328"},"channel":"live_orders_btcusd","event":"order_created"}
{"data":{"id":1722048976220161,"id_str":"1722048976220161","order_type":1,"datetime":"1709257088","microtimestamp":"1709257087992000","amount":0.00487172,"amount_str":"0.00487172","amount_traded":"0","amount_at_create":"0.00487172","price":61346,"price_str":"61346"},"channel":"live_orders_btcusd","event":"order_created"}
{"data":{"id":1722048975777792,"id_str":"1722048975777792","order_type":0,"datetime":"1709257088","microtimestamp":"1709257088005000","amount":0.48924932,"amount_str":"0.48924932","amount_traded":"0","amount_at_create":"0.48924932","price":61318,"price_str":"61318"},"channel":"live_orders_btcusd","event":"order_deleted"}
{"data":{"id":1722048975757314,"id_str":"1722048975757314","order_type":0,"datetime":"1709257088","microtimestamp":"1709257088005000","amount":0.48917456,"amount_str":"0.48917456","amount_traded":"0","amount_at_create":"0.48917456","price":61327,"price_str":"61327"},"channel":"live_orders_btcusd","event":"order_deleted"}
{"data":{"id":1722048976183296,"id_str":"1722048976183296","order_type":1,"datetime":"1709257088","microtimestamp":"1709257088006000","amount":0.01630369,"amount_str":"0.01630369","amount_traded":"0","amount_at_create":"0.01630369","price":61336,"price_str":"61336"},"channel":"live_orders_btcusd","event":"order_deleted"}
{"data":{"id":1722048976297986,"id_str":"1722048976297986","order_type":1,"datetime":"1709257088","microtimestamp":"1709257088012000","amount":0.1875,"amount_str":"0.18750000","amount_traded":"0","amount_at_create":"0.18750000","price":61376,"price_str":"61376"},"channel":"live_orders_btcusd","event":"order_created"}
{"data":{"id":1722048961654784,"id_str":"1722048961654784","order_type":1,"datetime":"1709257088","microtimestamp":"1709257088027000","amount":0.03062118,"amount_str":"0.03062118","amount_traded":"0","amount_at_create":"0.03062118","price":61361,"price_str":"61361"},"channel":"live_orders_btcusd","event":"order_deleted"}
{"data":{"id":1722048976416769,"id_str":"1722048976416769","order_type":1,"datetime":"1709257088","microtimestamp":"1709257088040000","amount":0.03062118,"amount_str":"0.03062118","amount_traded":"0","amount_at_create":"0.03062118","price":61358,"price_str":"61358"},"channel":"live_orders_btcusd","event":"order_created"}
{"data":{"id":1722048976478211,"id_str":"1722048976478211","order_type":1,"datetime":"1709257088","microtimestamp":"1709257088056000","amount":0.02000918,"amount_str":"0.02000918","amount_traded":"0","amount_at_create":"0.02000918","price":61358,"price_str":"61358"},"channel":"live_orders_btcusd","event":"order_created"}
{"data":{"id":1722048975802372,"id_str":"1722048975802372","order_type":1,"datetime":"1709257088","microtimestamp":"1709257088058000","amount":0.00487168,"amount_str":"0.00487168","amount_traded":"0","amount_at_create":"0.00487168","price":61348,"price_str":"61348"},"channel":"live_orders_btcusd","event":"order_deleted"}
{"data":{"id":1722048502099969,"id_str":"1722048502099969","order_type":0,"datetime":"1709257088","microtimestamp":"1709257088061000","amount":2.0360106,"amount_str":"2.03601060","amount_traded":"0","amount_at_create":"2.03601060","price":61113,"price_str":"61113"},"channel":"live_orders_btcusd","event":"order_deleted"}
{"data":{"id":1722048976560129,"id_str":"1722048976560129","order_type":0,"datetime":"1709257088","microtimestamp":"1709257088075000","amount":0.48919407,"amount_str":"0.48919407","amount_traded":"0","amount_at_create":"0.48919407","price":61325,"price_str":"61325"},"channel":"live_orders_btcusd","event":"order_created"}
{"data":{"id":1722048976564226,"id_str":"1722048976564226","order_type":1,"datetime":"1709257088","microtimestamp":"1709257088077000","amount":0.48903741,"amount_str":"0.48903741","amount_traded":"0","amount_at_create":"0.48903741","price":61345,"price_str":"61345"},"channel":"live_orders_btcusd","event":"order_created"}
{"data":{"id":1722048976576515,"id_str":"1722048976576515","order_type":1,"datetime":"1709257088","microtimestamp":"1709257088080000","amount":0.00487204,"amount_str":"0.00487204","amount_traded":"0","amount_at_create":"0.00487204","price":61344,"price_str":"61344"},"channel":"live_orders_btcusd","event":"order_created"}
{"data":{"id":1722048975912960,"id_str":"1722048975912960","order_type":0,"datetime":"1709257088","microtimestamp":"1709257088086000","amount":0.00815142,"amount_str":"0.00815142","amount_traded":"0","amount_at_create":"0.00815142","price":61331,"price_str":"61331"},"channel":"live_orders_btcusd","event":"order_deleted"}
{"data":{"id":1722048976683011,"id_str":"1722048976683011","order_type":0,"datetime":"1709257088","microtimestamp":"1709257088105000","amount":0.00815195,"amount_str":"0.00815195","amount_traded":"0","amount_at_create":"0.00815195","price":61328,"price_str":"61328"},"channel":"live_orders_btcusd","event":"order_created"}
{"data":{"id":1722048976564226,"id_str":"1722048976564226","order_type":1,"datetime":"1709257088","microtimestamp":"1709257088106000","amount":0.48903741,"amount_str":"0.48903741","amount_traded":"0","amount_at_create":"0.48903741","price":61345,"price_str":"61345"},"channel":"live_orders_btcusd","event":"order_deleted"}
{"data":{"id":1722048940642304,"id_str":"1722048940642304","order_type":0,"datetime":"1709257088","microtimestamp":"1709257088116000","amount":0.815832,"amount_str":"0.81583200","amount_traded":"0","amount_at_create":"0.81583200","price":61322,"price_str":"61322"},"channel":"live_orders_btcusd","event":"order_deleted"}
{"data":{"id":1722048564219905,"id_str":"1722048564219905","order_type":0,"datetime":"1709257088","microtimestamp":"1709257088117000","amount":2.473578,"amount_str":"2.47357800","amount_traded":"0","amount_at_create":"2.47357800","price":61255,"price_str":"61255"},"channel":"live_orders_btcusd","event":"order_deleted"}
{"data":{"id":1722048834326528,"id_str":"1722048834326528","order_type":0,"datetime":"1709257088","microtimestamp":"1709257088117000","amount":1.940436,"amount_str":"1.94043600","amount_traded":"0","amount_at_create":"1.94043600","price":61290,"price_str":"61290"},"channel":"live_orders_btcusd","event":"order_deleted"}
{"data":{"id":1722048976732163,"id_str":"1722048976732163","order_type":1,"datetime":"1709257088","microtimestamp":"1709257088118000","amount":0.01630404,"amount_str":"0.01630404","amount_traded":"0","amount_at_create":"0.01630404","price":61335,"price_str":"61335"},"channel":"live_orders_btcusd","event":"order_created"}
{"data":{"id":1722048954093570,"id_str":"1722048954093570","order_type":0,"datetime":"1709257088","microtimestamp":"1709257088146000","amount":0.04893,"amount_str":"0.04893000","amount_traded":"0","amount_at_create":"0.04893000","price":61313,"price_str":"61313"},"channel":"live_orders_btcusd","event":"order_deleted"}
{"data":{"id":1722048955645952,"id_str":"1722048955645952","order_type":1,"datetime":"1709257088","microtimestamp":"1709257088154000","amount":0.09743057,"amount_str":"0.09743057","amount_traded":"0","amount_at_create":"0.09743057","price":61369,"price_str":"61369"},"channel":"live_orders_btcusd","event":"order_deleted"}
{"data":{"id":1722048975769602,"id_str":"1722048975769602","order_type":1,"datetime":"1709257088","microtimestamp":"1709257088159000","amount":0.48899241,"amount_str":"0.48899241","amount_traded":"0","amount_at_create":"0.48899241","price":61351,"price_str":"61351"},"channel":"live_orders_btcusd","event":"order_deleted"}
{"data":{"id":1722048976732163,"id_str":"1722048976732163","order_type":1,"datetime":"1709257088","microtimestamp":"1709257088160000","amount":0.01630404,"amount_str":"0.01630404","amount_traded":"0","amount_at_create":"0.01630404","price":61335,"price_str":"61335"},"channel":"live_orders_btcusd","event":"order_deleted"}
{"data":{"id":1722048976908288,"id_str":"1722048976908288","order_type":0,"datetime":"1709257088","microtimestamp":"1709257088160000","amount":2.473578,"amount_str":"2.47357800","amount_traded":"0","amount_at_create":"2.47357800","price":61222,"price_str":"61222"},"channel":"live_orders_btcusd","event":"order_created"}
{"data":{"id":1722048976199682,"id_str":"1722048976199682","order_type":0,"datetime":"1709257088","microtimestamp":"1709257088161000","amount":0.01630559,"amount_str":"0.01630559","amount_traded":"0","amount_at_create":"0.01630559","price":61328,"price_str":"61328"},"channel":"live_orders_btcusd","event":"order_deleted"}
{"data":{"id":1722048976912384,"id_str":"1722048976912384","order_type":0,"datetime":"1709257088","microtimestamp":"1709257088161000","amount":0.815832,"amount_str":"0.81583200","amount_traded":"0","amount_at_create":"0.81583200","price":61315,"price_str":"61315"},"channel":"live_orders_btcusd","event":"order_created"}
{"data":{"id":1722048976916480,"id_str":"1722048976916480","order_type":0,"datetime":"1709257088","microtimestamp":"1709257088162000","amount":1.940436,"amount_str":"1.94043600","amount_traded":"0","amount_at_create":"1.94043600","price":61268,"price_str":"61268"},"channel":"live_orders_btcusd","event":"order_created"}
{"data":{"id":1722048976953344,"id_str":"1722048976953344","order_type":1,"datetime":"1709257088","microtimestamp":"1709257088171000","amount":0.09743931,"amount_str":"0.09743931","amount_traded":"0","amount_at_create":"0.09743931","price":61364,"price_str":"61364"},"channel":"live_orders_btcusd","event":"order_created"}
{"data":{"id":1722048928190466,"id_str":"1722048928190466","order_type":1,"datetime":"1709257088","microtimestamp":"1709257088202000","amount":0.06129906,"amount_str":"0.06129906","amount_traded":"0","amount_at_create":"0.06129906","price":61518,"price_str":"61518"},"channel":"live_orders_btcusd","event":"order_deleted"}
{"data":{"id":1722048976478211,"id_str":"1722048976478211","order_type":1,"datetime":"1709257088","microtimestamp":"1709257088203000","amount":0.02000918,"amount_str":"0.02000918","amount_traded":"0","amount_at_create":"0.02000918","price":61358,"price_str":"61358"},"channel":"live_orders_btcusd","event":"order_deleted"}
{"data":{"id":1722048977104898,"id_str":"1722048977104898","order_type":0,"datetime":"1709257088","microtimestamp":"1709257088209000","amount":0.01630622,"amount_str":"0.01630622","amount_traded":"0","amount_at_create":"0.01630622","price":61326,"price_str":"61326"},"channel":"live_orders_btcusd","event":"order_created"}
{"data":{"id":1722048977104898,"id_str":"1722048977104898","order_type":0,"datetime":"1709257088","microtimestamp":"1709257088224000","amount":0.01630622,"amount_str":"0.01630622","amount_traded":"0","amount_at_create":"0.01630622","price":61326,"price_str":"61326"},"channel":"live_orders_btcusd","event":"order_deleted"}
{"data":{"id":1722048977235970,"id_str":"1722048977235970","order_type":0,"datetime":"1709257088","microtimestamp":"1709257088241000","amount":2.0370678,"amount_str":"2.03706780","amount_traded":"0","amount_at_create":"2.03706780","price":61081,"price_str":"61081"},"channel":"live_orders_btcusd","event":"order_created"}
{"data":{"id":1722048977326080,"id_str":"1722048977326080","order_type":1,"datetime":"1709257088","microtimestamp":"1709257088262000","amount":0.02128786,"amount_str":"0.02128786","amount_traded":"0","amount_at_create":"0.02128786","price":61357,"price_str":"61357"},"channel":"live_orders_btcusd","event":"order_created"}
{"data":{"id":1722048975949826,"id_str":"1722048975949826","order_type":0,"datetime":"1709257088","microtimestamp":"1709257088264000","amount":0.00040751,"amount_str":"0.00040751","amount_traded":"0","amount_at_create":"0.00040751","price":61328,"price_str":"61328"},"channel":"live_orders_btcusd","event":"order_deleted"}
{"data":{"id":1722048977346562,"id_str":"1722048977346562","order_type":1,"datetime":"1709257088","microtimestamp":"1709257088267000","amount":0.01630177,"amount_str":"0.01630177","amount_traded":"0","amount_at_create":"0.01630177","price":61343,"price_str":"61343"},"channel":"live_orders_btcusd","event":"order_created"}
{"data":{"id":1722048977358851,"id_str":"1722048977358851","order_type":0,"datetime":"1709257088","microtimestamp":"1709257088271000","amount":0.1875,"amount_str":"0.18750000","amount_traded":"0","amount_at_create":"0.18750000","price":61321,"price_str":"61321"},"channel":"live_orders_btcusd","event":"order_created"}
{"data":{"id":1722048977391618,"id_str":"1722048977391618","order_type":1,"datetime":"1709257088","microtimestamp":"1709257088278000","amount":0.06266882,"amount_str":"0.06266882","amount_traded":"0","amount_at_create":"0.06266882","price":61510,"price_str":"61510"},"channel":"live_orders_btcusd","event":"order_created"}
{"data":{"id":1722048927096833,"id_str":"1722048927096833","order_type":0,"datetime":"1709257088","microtimestamp":"1709257088297000","amount":0.1875,"amount_str":"0.18750000","amount_traded":"0","amount_at_create":"0.18750000","price":61220,"price_str":"61220"},"channel":"live_orders_btcusd","event":"order_deleted"}
{"data":{"id":1722048641187842,"id_str":"1722048641187842","order_type":1,"datetime":"1709257088","microtimestamp":"1709257088298000","amount":0.1875,"amount_str":"0.18750000","amount_traded":"0","amount_at_create":"0.18750000","price":61515,"price_str":"61515"},"channel":"live_orders_btcusd","event":"order_deleted"}
{"data":{"id":1722048977358851,"id_str":"1722048977358851","order_type":0,"datetime":"1709257088","microtimestamp":"1709257088300000","amount":0.1875,"amount_str":"0.18750000","amount_traded":"0","amount_at_create":"0.18750000","price":61321,"price_str":"61321"},"channel":"live_orders_btcusd","event":"order_deleted"}
{"data":{"id":1722048976416769,"id_str":"1722048976416769","order_type":1,"datetime":"1709257088","microtimestamp":"1709257088301000","amount":0.03062118,"amount_str":"0.03062118","amount_traded":"0","amount_at_create":"0.03062118","price":61358,"price_str":"61358"},"channel":"live_orders_btcusd","event":"order_deleted"}
{"data":{"id":1722048977346562,"id_str":"1722048977346562","order_type":1,"datetime":"1709257088","microtimestamp":"1709257088303000","amount":0.01630177,"amount_str":"0.01630177","amount_traded":"0","amount_at_create":"0.01630177","price":61343,"price_str":"61343"},"channel":"live_orders_btcusd","event":"order_deleted"}
{"data":{"id":1722048976560129,"id_str":"1722048976560129","order_type":0,"datetime":"1709257088","microtimestamp":"1709257088303000","amount":0.48919407,"amount_str":"0.48919407","amount_traded":"0","amount_at_create":"0.48919407","price":61325,"price_str":"61325"},"channel":"live_orders_btcusd","event":"order_deleted"}
{"data":{"id":1722048977326080,"id_str":"1722048977326080","order_type":1,"datetime":"1709257088","microtimestamp":"1709257088305000","amount":0.02128786,"amount_str":"0.02128786","amount_traded":"0","amount_at_create":"0.02128786","price":61357,"price_str":"61357"},"channel":"live_orders_btcusd","event":"order_deleted"}
{"data":{"id":1722048977534977,"id_str":"1722048977534977","order_type":0,"datetime":"1709257088","microtimestamp":"1709257088313000","amount":0.01630594,"amount_str":"0.01630594","amount_traded":"0","amount_at_create":"0.01630594","price":61327,"price_str":"61327"},"channel":"live_orders_btcusd","event":"order_created"}
{"data":{"id":1722048977534980,"id_str":"1722048977534980","order_type":1,"datetime":"1709257088","microtimestamp":"1709257088314000","amount":0.03062118,"amount_str":"0.03062118","amount_traded":"0","amount_at_create":"0.03062118","price":61356,"price_str":"61356"},"channel":"live_orders_btcusd","event":"order_created"}
{"data":{"id":1722048977543169,"id_str":"1722048977543169","order_type":1,"datetime":"1709257088","microtimestamp":"1709257088315000","amount":0.48905335,"amount_str":"0.48905335","amount_traded":"0","amount_at_create":"0.48905335","price":61343,"price_str":"61343"},"channel":"live_orders_btcusd","event":"order_created"}
{"data":{"id":1722048833613824,"id_str":"1722048833613824","order_type":0,"datetime":"1709257088","microtimestamp":"1709257088322000","amount":0.25813698,"amount_str":"0.25813698","amount_traded":"0","amount_at_create":"0.25813698","price":61262,"price_str":"61262"},"channel":"live_orders_btcusd","event":"order_deleted"}
{"data":{"id":1722048977534977,"id_str":"1722048977534977","order_type":0,"datetime":"1709257088","microtimestamp":"1709257088331000","amount":0.01630594,"amount_str":"0.01630594","amount_traded":"0","amount_at_create":"0.01630594","price":61327,"price_str":"61327"},"channel":"live_orders_btcusd","event":"order_deleted"}
{"data":{"id":1722048977715202,"id_str":"1722048977715202","order_type":0,"datetime":"1709257088","microtimestamp":"1709257088358000","amount":0.1875,"amount_str":"0.18750000","amount_traded":"0","amount_at_create":"0.18750000","price":61223,"price_str":"61223"},"channel":"live_orders_btcusd","event":"order_created"}
{"data":{"id":1722048977793025,"id_str":"1722048977793025","order_type":0,"datetime":"1709257088","microtimestamp":"1709257088377000","amount":0.48918286,"amount_str":"0.48918286","amount_traded":"0","amount_at_create":"0.48918286","price":61326,"price_str":"61326"},"channel":"live_orders_btcusd","event":"order_created"}
{"data":{"id":1722048977793026,"id_str":"1722048977793026","order_type":1,"datetime":"1709257088","microtimestamp":"1709257088377000","amount":0.01630366,"amount_str":"0.01630366","amount_traded":"0","amount_at_create":"0.01630366","price":61336,"price_str":"61336"},"channel":"live_orders_btcusd","event":"order_created"}
{"data":{"id":1722048977797120,"id_str":"1722048977797120","order_type":0,"datetime":"1709257088","microtimestamp":"1709257088377000","amount":0.4892151,"amount_str":"0.48921510","amount_traded":"0","amount_at_create":"0.48921510","price":61322,"price_str":"61322"},"channel":"live_orders_btcusd","event":"order_created"}
{"data":{"id":1722048977797122,"id_str":"1722048977797122","order_type":0,"datetime":"1709257088","microtimestamp":"1709257088377000","amount":0.00040756,"amount_str":"0.00040756","amount_traded":"0","amount_at_create":"0.00040756","price":61326,"price_str":"61326"},"channel":"live_orders_btcusd","event":"order_created"}
{"data":{"id":1722048977813504,"id_str":"1722048977813504","order_type":0,"datetime":"1709257088","microtimestamp":"1709257088381000","amount":0.25914631,"amount_str":"0.25914631","amount_traded":"0","amount_at_create":"0.25914631","price":61232,"price_str":"61232"},"channel":"live_orders_btcusd","event":"order_created"}
{"data":{"id":1722048977543169,"id_str":"1722048977543169","order_type":1,"datetime":"1709257088","microtimestamp":"1709257088398000","amount":0.48905335,"amount_str":"0.48905335","amount_traded":"0","amount_at_create":"0.48905335","price":61343,"price_str":"61343"},"channel":"live_orders_btcusd","event":"order_deleted"}
{"data":{"id":1722048977989640,"id_str":"1722048977989640","order_type":0,"datetime":"1709257088","microtimestamp":"1709257088425000","amount":0.01630556,"amount_str":"0.01630556","amount_traded":"0","amount_at_create":"0.01630556","price":61328,"price_str":"61328"},"channel":"live_orders_btcusd","event":"order_created"}
{"data":{"id":1722048978075651,"id_str":"1722048978075651","order_type":0,"datetime":"1709257088","microtimestamp":"1709257088446000","amount":0.04893,"amount_str":"0.04893000","amount_traded":"0","amount_at_create":"0.04893000","price":61309,"price_str":"61309"},"channel":"live_orders_btcusd","event":"order_created"}
{"data":{"id":1722048978104321,"id_str":"1722048978104321","order_type":1,"datetime":"1709257088","microtimestamp":"1709257088452000","amount":0.02214096,"amount_str":"0.02214096","amount_traded":"0","amount_at_create":"0.02214096","price":61355,"price_str":"61355"},"channel":"live_orders_btcusd","event":"order_created"}
{"data":{"id":1722048977534980,"id_str":"1722048977534980","order_type":1,"datetime":"1709257089","microtimestamp":"1709257088503000","amount":0.03062118,"amount_str":"0.03062118","amount_traded":"0","amount_at_create":"0.03062118","price":61356,"price_str":"61356"},"channel":"live_orders_btcusd","event":"order_deleted"}
{"data":{"id":1722048978345984,"id_str":"1722048978345984","order_type":0,"datetime":"1709257089","microtimestamp":"1709257088511000","amount":0.1875,"amount_str":"0.18750000","amount_traded":"0","amount_at_create":"0.18750000","price":61321,"price_str":"61321"},"channel":"live_orders_btcusd","event":"order_created"}
{"data":{"id":1722048978370560,"id_str":"1722048978370560","order_type":1,"datetime":"1709257089","microtimestamp":"1709257088517000","amount":0.03062118,"amount_str":"0.03062118","amount_traded":"0","amount_at_create":"0.03062118","price":61354,"price_str":"61354"},"channel":"live_orders_btcusd","event":"order_created"}
{"data":{"id":1722048978456576,"id_str":"1722048978456576","order_type":1,"datetime":"1709257089","microtimestamp":"1709257088538000","amount":0.48909924,"amount_str":"0.48909924","amount_traded":"0","amount_at_create":"0.48909924","price":61338,"price_str":"61338"},"channel":"live_orders_btcusd","event":"order_created"}
{"data":{"id":1722048978669572,"id_str":"1722048978669572","order_type":1,"datetime":"1709257089","microtimestamp":"1709257088591000","amount":0.4887909,"amount_str":"0.48879090","amount_traded":"0","amount_at_create":"0.48879090","price":61376,"price_str":"61376"},"channel":"live_orders_btcusd","event":"order_created"}
{"data":{"id":1722048977793025,"id_str":"1722048977793025","order_type":0,"datetime":"1709257089","microtimestamp":"1709257088600000","amount":0.48918286,"amount_str":"0.48918286","amount_traded":"0","amount_at_create":"0.48918286","price":61326,"price_str":"61326"},"channel":"live_orders_btcusd","event":"order_deleted"}
{"data":{"id":1722048977989640,"id_str":"1722048977989640","order_type":0,"datetime":"1709257089","microtimestamp":"1709257088601000","amount":0.01630556,"amount_str":"0.01630556","amount_traded":"0","amount_at_create":"0.01630556","price":61328,"price_str":"61328"},"channel":"live_orders_btcusd","event":"order_deleted"}
{"data":{"id":1722048977797122,"id_str":"1722048977797122","order_type":0,"datetime":"1709257089","microtimestamp":"1709257088646000","amount":0.00040756,"amount_str":"0.00040756","amount_traded":"0","amount_at_create":"0.00040756","price":61326,"price_str":"61326"},"channel":"live_orders_btcusd","event":"order_deleted"}
{"data":{"id":1722048978898947,"id_str":"1722048978898947","order_type":0,"datetime":"1709257089","microtimestamp":"1709257088646000","amount":0.48917937,"amount_str":"0.48917937","amount_traded":"0","amount_at_create":"0.48917937","price":61327,"price_str":"61327"},"channel":"live_orders_btcusd","event":"order_created"}
{"data":{"id":1722048978907137,"id_str":"1722048978907137","order_type":0,"datetime":"1709257089","microtimestamp":"1709257088648000","amount":0.01630539,"amount_str":"0.01630539","amount_traded":"0","amount_at_create":"0.01630539","price":61329,"price_str":"61329"},"channel":"live_orders_btcusd","event":"order_created"}
{"data":{"id":1722048975790085,"id_str":"1722048975790085","order_type":1,"datetime":"1709257089","microtimestamp":"1709257088679000","amount":0.1875,"amount_str":"0.18750000","amount_traded":"0","amount_at_create":"0.18750000","price":61352,"price_str":"61352"},"channel":"live_orders_btcusd","event":"order_deleted"}
{"data":{"id":1722048979378176,"id_str":"1722048979378176","order_type":0,"datetime":"1709257089","microtimestamp":"1709257088763000","amount":0.00040756,"amount_str":"0.00040756","amount_traded":"0","amount_at_create":"0.00040756","price":61327,"price_str":"61327"},"channel":"live_orders_btcusd","event":"order_created"}
{"data":{"id":1722048975663113,"id_str":"1722048975663113","order_type":0,"datetime":"1709257089","microtimestamp":"1709257088860000","amount":3.06707818,"amount_str":"3.06707818","amount_traded":"0","amount_at_create":"3.06707818","price":61325,"price_str":"61325"},"channel":"live_orders_btcusd","event":"order_deleted"}
{"data":{"id":1722048976683011,"id_str":"1722048976683011","order_type":0,"datetime":"1709257089","microtimestamp":"1709257088863000","amount":0.00815195,"amount_str":"0.00815195","amount_traded":"0","amount_at_create":"0.00815195","price":61328,"price_str":"61328"},"channel":"live_orders_btcusd","event":"order_deleted"}
{"data":{"id":1722048978075651,"id_str":"1722048978075651","order_type":0,"datetime":"1709257089","microtimestamp":"1709257088864000","amount":0.04893,"amount_str":"0.04893000","amount_traded":"0","amount_at_create":"0.04893000","price":61309,"price_str":"61309"},"channel":"live_orders_btcusd","event":"order_deleted"}
{"data":{"id":1722048978345984,"id_str":"1722048978345984","order_type":0,"datetime":"1709257089","microtimestamp":"1709257088867000","amount":0.1875,"amount_str":"0.18750000","amount_traded":"0","amount_at_create":"0.18750000","price":61321,"price_str":"61321"},"channel":"live_orders_btcusd","event":"order_deleted"}
{"data":{"id":1722048978104321,"id_str":"1722048978104321","order_type":1,"datetime":"1709257089","microtimestamp":"1709257088871000","amount":0.02214096,"amount_str":"0.02214096","amount_traded":"0","amount_at_create":"0.02214096","price":61355,"price_str":"61355"},"channel":"live_orders_btcusd","event":"order_deleted"}
{"data":{"id":1722048806547458,"id_str":"1722048806547458","order_type":1,"datetime":"1709257089","microtimestamp":"1709257088876000","amount":1.9734,"amount_str":"1.97340000","amount_traded":"0","amount_at_create":"1.97340000","price":61454,"price_str":"61454"},"channel":"live_orders_btcusd","event":"order_deleted"}
{"data":{"id":1722048979849219,"id_str":"1722048979849219","order_type":1,"datetime":"1709257089","microtimestamp":"1709257088879000","amount":0.1875,"amount_str":"0.18750000","amount_traded":"0","amount_at_create":"0.18750000","price":61350,"price_str":"61350"},"channel":"live_orders_btcusd","event":"order_created"}
{"data":{"id":1722048978456576,"id_str":"1722048978456576","order_type":1,"datetime":"1709257089","microtimestamp":"1709257088887000","amount":0.48909924,"amount_str":"0.48909924","amount_traded":"0","amount_at_create":"0.48909924","price":61338,"price_str":"61338"},"channel":"live_orders_btcusd","event":"order_deleted"}
{"data":{"id":1722048977793026,"id_str":"1722048977793026","order_type":1,"datetime":"1709257089","microtimestamp":"1709257088887000","amount":0.01630366,"amount_str":"0.01630366","amount_traded":"0","amount_at_create":"0.01630366","price":61336,"price_str":"61336"},"channel":"live_orders_btcusd","event":"order_deleted"}
{"data":{"id":1722048978898947,"id_str":"1722048978898947","order_type":0,"datetime":"1709257089","microtimestamp":"1709257088888000","amount":0.48917937,"amount_str":"0.48917937","amount_traded":"0","amount_at_create":"0.48917937","price":61327,"price_str":"61327"},"channel":"live_orders_btcusd","event":"order_deleted"}
{"data":{"id":1722048978907137,"id_str":"1722048978907137","order_type":0,"datetime":"1709257089","microtimestamp":"1709257088888000","amount":0.01630539,"amount_str":"0.01630539","amount_traded":"0","amount_at_create":"0.01630539","price":61329,"price_str":"61329"},"channel":"live_orders_btcusd","event":"order_deleted"}
{"data":{"id":1722048977797120,"id_str":"1722048977797120","order_type":0,"datetime":"1709257089","microtimestamp":"1709257088888000","amount":0.4892151,"amount_str":"0.48921510","amount_traded":"0","amount_at_create":"0.48921510","price":61322,"price_str":"61322"},"channel":"live_orders_btcusd","event":"order_deleted"}
{"data":{"id":1722048975740933,"id_str":"1722048975740933","order_type":1,"datetime":"1709257089","microtimestamp":"1709257088890000","amount":0.48887958,"amount_str":"0.48887958","amount_traded":"0","amount_at_create":"0.48887958","price":61365,"price_str":"61365"},"channel":"live_orders_btcusd","event":"order_deleted"}
{"data":{"id":1722048956399616,"id_str":"1722048956399616","order_type":0,"datetime":"1709257089","microtimestamp":"1709257088898000","amount":0.5,"amount_str":"0.50000000","amount_traded":"0","amount_at_create":"0.50000000","price":61314,"price_str":"61314"},"channel":"live_orders_btcusd","event":"order_deleted"}
{"data":{"id":1722048975753218,"id_str":"1722048975753218","order_type":1,"datetime":"1709257089","microtimestamp":"1709257088900000","amount":0.48855241,"amount_str":"0.48855241","amount_traded":"0","amount_at_create":"0.48855241","price":61406,"price_str":"61406"},"channel":"live_orders_btcusd","event":"order_deleted"}
{"data":{"id":1722048954105860,"id_str":"1722048954105860","order_type":1,"datetime":"1709257089","microtimestamp":"1709257088901000","amount":0.16275718,"amount_str":"0.16275718","amount_traded":"0","amount_at_create":"0.16275718","price":61442,"price_str":"61442"},"channel":"live_orders_btcusd","event":"order_deleted"}
{"data":{"id":1722048976191488,"id_str":"1722048976191488","order_type":0,"datetime":"1709257089","microtimestamp":"1709257088902000","amount":0.48948895,"amount_str":"0.48948895","amount_traded":"0","amount_at_create":"0.48948895","price":61288,"price_str":"61288"},"channel":"live_orders_btcusd","event":"order_deleted"}
{"data":{"id":1722048979947523,"id_str":"1722048979947523","order_type":1,"datetime":"1709257089","microtimestamp":"1709257088902000","amount":1.9984,"amount_str":"1.99840000","amount_traded":"0","amount_at_create":"1.99840000","price":61421,"price_str":"61421"},"channel":"live_orders_btcusd","event":"order_created"}
{"data":{"id":1722048976220161,"id_str":"1722048976220161","order_type":1,"datetime":"1709257089","microtimestamp":"1709257088903000","amount":0.00487172,"amount_str":"0.00487172","amount_traded":"0","amount_at_create":"0.00487172","price":61346,"price_str":"61346"},"channel":"live_orders_btcusd","event":"order_deleted"}
{"data":{"id":1722048979955712,"id_str":"1722048979955712","order_type":0,"datetime":"1709257089","microtimestamp":"1709257088904000","amount":0.48928561,"amount_str":"0.48928561","amount_traded":"0","amount_at_create":"0.48928561","price":61313,"price_str":"61313"},"channel":"live_orders_btcusd","event":"order_created"}
{"data":{"id":1722048979955714,"id_str":"1722048979955714","order_type":1,"datetime":"1709257089","microtimestamp":"1709257088904000","amount":0.48902102,"amount_str":"0.48902102","amount_traded":"0","amount_at_create":"0.48902102","price":61348,"price_str":"61348"},"channel":"live_orders_btcusd","event":"order_created"}
{"data":{"id":1722048978370560,"id_str":"1722048978370560","order_type":1,"datetime":"1709257089","microtimestamp":"1709257088905000","amount":0.03062118,"amount_str":"0.03062118","amount_traded":"0","amount_at_create":"0.03062118","price":61354,"price_str":"61354"},"channel":"live_orders_btcusd","event":"order_deleted"}
{"data":{"id":1722048979959808,"id_str":"1722048979959808","order_type":1,"datetime":"1709257089","microtimestamp":"1709257088905000","amount":0.48906132,"amount_str":"0.48906132","amount_traded":"0","amount_at_create":"0.48906132","price":61342,"price_str":"61342"},"channel":"live_orders_btcusd","event":"order_created"}
{"data":{"id":1722048979959810,"id_str":"1722048979959810","order_type":0,"datetime":"1709257089","microtimestamp":"1709257088905000","amount":3.06737833,"amount_str":"3.06737833","amount_traded":"0","amount_at_create":"3.06737833","price":61319,"price_str":"61319"},"channel":"live_orders_btcusd","event":"order_created"}
{"data":{"id":1722048980021249,"id_str":"1722048980021249","order_type":1,"datetime":"1709257089","microtimestamp":"1709257088920000","amount":0.00487224,"amount_str":"0.00487224","amount_traded":"0","amount_at_create":"0.00487224","price":61342,"price_str":"61342"},"channel":"live_orders_btcusd","event":"order_created"}
{"data":{"id":1722048980021250,"id_str":"1722048980021250","order_type":1,"datetime":"1709257089","microtimestamp":"1709257088920000","amount":0.03062118,"amount_str":"0.03062118","amount_traded":"0","amount_at_create":"0.03062118","price":61350,"price_str":"61350"},"channel":"live_orders_btcusd","event":"order_created"}
{"data":{"id":1722048980037634,"id_str":"1722048980037634","order_type":1,"datetime":"1709257089","microtimestamp":"1709257088924000","amount":0.02202816,"amount_str":"0.02202816","amount_traded":"0","amount_at_create":"0.02202816","price":61353,"price_str":"61353"},"channel":"live_orders_btcusd","event":"order_created"}
{"data":{"id":1722048979959808,"id_str":"1722048979959808","order_type":1,"datetime":"1709257089","microtimestamp":"1709257088926000","amount":0.48906132,"amount_str":"0.48906132","amount_traded":"0","amount_at_create":"0.48906132","price":61342,"price_str":"61342"},"channel":"live_orders_btcusd","event":"order_deleted"}
{"data":{"id":1722048980045825,"id_str":"1722048980045825","order_type":0,"datetime":"1709257089","microtimestamp":"1709257088926000","amount":0.5,"amount_str":"0.50000000","amount_traded":"0","amount_at_create":"0.50000000","price":61303,"price_str":"61303"},"channel":"live_orders_btcusd","event":"order_created"}
{"data":{"id":1722048979955714,"id_str":"1722048979955714","order_type":1,"datetime":"1709257089","microtimestamp":"1709257088926000","amount":0.48902102,"amount_str":"0.48902102","amount_traded":"0","amount_at_create":"0.48902102","price":61348,"price_str":"61348"},"channel":"live_orders_btcusd","event":"order_deleted"}
{"data":{"id":1722048979955712,"id_str":"1722048979955712","order_type":0,"datetime":"1709257089","microtimestamp":"1709257088935000","amount":0.48928561,"amount_str":"0.48928561","amount_traded":"0","amount_at_create":"0.48928561","price":61313,"price_str":"61313"},"channel":"live_orders_btcusd","event":"order_deleted"}
{"data":{"id":1722048980094976,"id_str":"1722048980094976","order_type":0,"datetime":"1709257089","microtimestamp":"1709257088938000","amount":0.00133118,"amount_str":"0.00133118","amount_traded":"0","amount_at_create":"0.00133118","price":61261,"price_str":"61261"},"channel":"live_orders_btcusd","event":"order_created"}
{"data":{"id":1722048980107264,"id_str":"1722048980107264","order_type":0,"datetime":"1709257089","microtimestamp":"1709257088941000","amount":0.00815228,"amount_str":"0.00815228","amount_traded":"0","amount_at_create":"0.00815228","price":61326,"price_str":"61326"},"channel":"live_orders_btcusd","event":"order_created"}
{"data":{"id":1722048979378176,"id_str":"1722048979378176","order_type":0,"datetime":"1709257089","microtimestamp":"1709257088971000","amount":0.00040756,"amount_str":"0.00040756","amount_traded":"0","amount_at_create":"0.00040756","price":61327,"price_str":"61327"},"channel":"live_orders_btcusd","event":"order_deleted"}
{"data":{"id":1722048980258819,"id_str":"1722048980258819","order_type":1,"datetime":"1709257089","microtimestamp":"1709257088979000","amount":0.01630517,"amount_str":"0.01630517","amount_traded":"0","amount_at_create":"0.01630517","price":61331,"price_str":"61331"},"channel":"live_orders_btcusd","event":"order_created"}
{"data":{"id":1722048980262912,"id_str":"1722048980262912","order_type":0,"datetime":"1709257089","microtimestamp":"1709257088979000","amount":0.01630697,"amount_str":"0.01630697","amount_traded":"0","amount_at_create":"0.01630697","price":61323,"price_str":"61323"},"channel":"live_orders_btcusd","event":"order_created"}
{"data":{"id":1722048980267008,"id_str":"1722048980267008","order_type":0,"datetime":"1709257089","microtimestamp":"1709257088980000","amount":0.48926144,"amount_str":"0.48926144","amount_traded":"0","amount_at_create":"0.48926144","price":61316,"price_str":"61316"},"channel":"live_orders_btcusd","event":"order_created"}
{"data":{"id":1722048980271104,"id_str":"1722048980271104","order_type":0,"datetime":"1709257089","microtimestamp":"1709257088981000","amount":0.48922659,"amount_str":"0.48922659","amount_traded":"0","amount_at_create":"0.48922659","price":61321,"price_str":"61321"},"channel":"live_orders_btcusd","event":"order_created"}
{"data":{"id":1722048980279297,"id_str":"1722048980279297","order_type":1,"datetime":"1709257089","microtimestamp":"1709257088983000","amount":0.48905335,"amount_str":"0.48905335","amount_traded":"0","amount_at_create":"0.48905335","price":61343,"price_str":"61343"},"channel":"live_orders_btcusd","event":"order_created"}
{"data":{"id":1722048980258819,"id_str":"1722048980258819","order_type":1,"datetime":"1709257089","microtimestamp":"1709257088998000","amount":0.01630517,"amount_str":"0.01630517","amount_traded":"0","amount_at_create":"0.01630517","price":61331,"price_str":"61331"},"channel":"live_orders_btcusd","event":"order_deleted"}
{"data":{"id":1722048980107264,"id_str":"1722048980107264","order_type":0,"datetime":"1709257089","microtimestamp":"1709257089024000","amount":0.00815228,"amount_str":"0.00815228","amount_traded":"0","amount_at_create":"0.00815228","price":61326,"price_str":"61326"},"channel":"live_orders_btcusd","event":"order_deleted"}
{"data":{"id":1722048980037634,"id_str":"1722048980037634","order_type":1,"datetime":"1709257089","microtimestamp":"1709257089029000","amount":0.02202816,"amount_str":"0.02202816","amount_traded":"0","amount_at_create":"0.02202816","price":61353,"price_str":"61353"},"channel":"live_orders_btcusd","event":"order_deleted"}
{"data":{"id":1722048980094976,"id_str":"1722048980094976","order_type":0,"datetime":"1709257089","microtimestamp":"1709257089030000","amount":0.00133118,"amount_str":"0.00133118","amount_traded":"0","amount_at_create":"0.00133118","price":61261,"price_str":"61261"},"channel":"live_orders_btcusd","event":"order_deleted"}
{"data":{"id":1722048957308928,"id_str":"1722048957308928","order_type":0,"datetime":"1709257089","microtimestamp":"1709257089033000","amount":0.04875518,"amount_str":"0.04875518","amount_traded":"0","amount_at_create":"0.04875518","price":61305,"price_str":"61305"},"channel":"live_orders_btcusd","event":"order_deleted"}
{"data":{"id":1722048957075456,"id_str":"1722048957075456","order_type":0,"datetime":"1709257089","microtimestamp":"1709257089034000","amount":0.12188796,"amount_str":"0.12188796","amount_traded":"0","amount_at_create":"0.12188796","price":61273,"price_str":"61273"},"channel":"live_orders_btcusd","event":"order_deleted"}
{"data":{"id":1722048954421248,"id_str":"1722048954421248","order_type":1,"datetime":"1709257089","microtimestamp":"1709257089034000","amount":0.04875518,"amount_str":"0.04875518","amount_traded":"0","amount_at_create":"0.04875518","price":61372,"price_str":"61372"},"channel":"live_orders_btcusd","event":"order_deleted"}
{"data":{"id":1722048976113665,"id_str":"1722048976113665","order_type":0,"datetime":"1709257089","microtimestamp":"1709257089041000","amount":0.16302841,"amount_str":"0.16302841","amount_traded":"0","amount_at_create":"0.16302841","price":61311,"price_str":"61311"},"channel":"live_orders_btcusd","event":"order_deleted"}
{"data":{"id":1722048980594688,"id_str":"1722048980594688","order_type":0,"datetime":"1709257089","microtimestamp":"1709257089061000","amount":0.00040756,"amount_str":"0.00040756","amount_traded":"0","amount_at_create":"0.00040756","price":61316,"price_str":"61316"},"channel":"live_orders_btcusd","event":"order_created"}
{"data":{"id":1722048980602882,"id_str":"1722048980602882","order_type":0,"datetime":"1709257089","microtimestamp":"1709257089063000","amount":0.06519236,"amount_str":"0.06519236","amount_traded":"0","amount_at_create":"0.06519236","price":61313,"price_str":"61313"},"channel":"live_orders_btcusd","event":"order_created"}
{"data":{"id":1722048980611074,"id_str":"1722048980611074","order_type":0,"datetime":"1709257089","microtimestamp":"1709257089064000","amount":0.00815281,"amount_str":"0.00815281","amount_traded":"0","amount_at_create":"0.00815281","price":61324,"price_str":"61324"},"channel":"live_orders_btcusd","event":"order_created"}
{"data":{"id":1722048980664322,"id_str":"1722048980664322","order_type":1,"datetime":"1709257089","microtimestamp":"1709257089077000","amount":0.40757636,"amount_str":"0.40757636","amount_traded":"0","amount_at_create":"0.40757636","price":61352,"price_str":"61352"},"channel":"live_orders_btcusd","event":"order_created"}
{"data":{"id":1722048980692992,"id_str":"1722048980692992","order_type":0,"datetime":"1709257089","microtimestamp":"1709257089084000","amount":0.16305632,"amount_str":"0.16305632","amount_traded":"0","amount_at_create":"0.16305632","price":61305,"price_str":"61305"},"channel":"live_orders_btcusd","event":"order_created"}
{"data":{"id":1722048980705281,"id_str":"1722048980705281","order_type":1,"datetime":"1709257089","microtimestamp":"1709257089087000","amount":0.04875518,"amount_str":"0.04875518","amount_traded":"0","amount_at_create":"0.04875518","price":61368,"price_str":"61368"},"channel":"live_orders_btcusd","event":"order_created"}
{"data":{"id":1722048975769600,"id_str":"1722048975769600","order_type":0,"datetime":"1709257089","microtimestamp":"1709257089094000","amount":0.48969318,"amount_str":"0.48969318","amount_traded":"0","amount_at_create":"0.48969318","price":61262,"price_str":"61262"},"channel":"live_orders_btcusd","event":"order_deleted"}
{"data":{"id":1722048980271104,"id_str":"1722048980271104","order_type":0,"datetime":"1709257089","microtimestamp":"1709257089104000","amount":0.48922659,"amount_str":"0.48922659","amount_traded":"0","amount_at_create":"0.48922659","price":61321,"price_str":"61321"},"channel":"live_orders_btcusd","event":"order_deleted"}
{"data":{"id":1722048978669572,"id_str":"1722048978669572","order_type":1,"datetime":"1709257089","microtimestamp":"1709257089105000","amount":0.4887909,"amount_str":"0.48879090","amount_traded":"0","amount_at_create":"0.48879090","price":61376,"price_str":"61376"},"channel":"live_orders_btcusd","event":"order_deleted"}
{"data":{"id":1722048980262912,"id_str":"1722048980262912","order_type":0,"datetime":"1709257089","microtimestamp":"1709257089121000","amount":0.01630697,"amount_str":"0.01630697","amount_traded":"0","amount_at_create":"0.01630697","price":61323,"price_str":"61323"},"channel":"live_orders_btcusd","event":"order_deleted"}
{"data":{"id":1722048980877315,"id_str":"1722048980877315","order_type":1,"datetime":"1709257089","microtimestamp":"1709257089130000","amount":0.02371292,"amount_str":"0.02371292","amount_traded":"0","amount_at_create":"0.02371292","price":61352,"price_str":"61352"},"channel":"live_orders_btcusd","event":"order_created"}
{"data":{"id":1722048981012480,"id_str":"1722048981012480","order_type":1,"datetime":"1709257089","microtimestamp":"1709257089163000","amount":0.4890693,"amount_str":"0.48906930","amount_traded":"0","amount_at_create":"0.48906930","price":61341,"price_str":"61341"},"channel":"live_orders_btcusd","event":"order_created"}
{"data":{"id":1722048981020672,"id_str":"1722048981020672","order_type":1,"datetime":"1709257089","microtimestamp":"1709257089164000","amount":0.01630553,"amount_str":"0.01630553","amount_traded":"0","amount_at_create":"0.01630553","price":61329,"price_str":"61329"},"channel":"live_orders_btcusd","event":"order_created"}
{"data":{"id":1722048981028864,"id_str":"1722048981028864","order_type":0,"datetime":"1709257089","microtimestamp":"1709257089166000","amount":0.01630744,"amount_str":"0.01630744","amount_traded":"0","amount_at_create":"0.01630744","price":61321,"price_str":"61321"},"channel":"live_orders_btcusd","event":"order_created"}
{"data":{"id":1722048979959810,"id_str":"1722048979959810","order_type":0,"datetime":"1709257089","microtimestamp":"1709257089172000","amount":3.06737833,"amount_str":"3.06737833","amount_traded":"0","amount_at_create":"3.06737833","price":61319,"price_str":"61319"},"channel":"live_orders_btcusd","event":"order_deleted"}
{"data":{"id":1722048981028864,"id_str":"1722048981028864","order_type":0,"datetime":"1709257089","microtimestamp":"1709257089189000","amount":0.01630744,"amount_str":"0.01630744","amount_traded":"0","amount_at_create":"0.01630744","price":61321,"price_str":"61321"},"channel":"live_orders_btcusd","event":"order_deleted"}
{"data":{"id":1722048981020672,"id_str":"1722048981020672","order_type":1,"datetime":"1709257089","microtimestamp":"1709257089190000","amount":0.01630553,"amount_str":"0.01630553","amount_traded":"0","amount_at_create":"0.01630553","price":61329,"price_str":"61329"},"channel":"live_orders_btcusd","event":"order_deleted"}
{"data":{"id":1722048981221376,"id_str":"1722048981221376","order_type":0,"datetime":"1709257089","microtimestamp":"1709257089213000","amount":0.48923804,"amount_str":"0.48923804","amount_traded":"0","amount_at_create":"0.48923804","price":61319,"price_str":"61319"},"channel":"live_orders_btcusd","event":"order_created"}
{"data":{"id":1722048981225472,"id_str":"1722048981225472","order_type":0,"datetime":"1709257089","microtimestamp":"1709257089214000","amount":3.06757844,"amount_str":"3.06757844","amount_traded":"0","amount_at_create":"3.06757844","price":61315,"price_str":"61315"},"channel":"live_orders_btcusd","event":"order_created"}
{"data":{"id":1722048981012480,"id_str":"1722048981012480","order_type":1,"datetime":"1709257089","microtimestamp":"1709257089219000","amount":0.4890693,"amount_str":"0.48906930","amount_traded":"0","amount_at_create":"0.48906930","price":61341,"price_str":"61341"},"channel":"live_orders_btcusd","event":"order_deleted"}
{"data":{"id":1722048976953344,"id_str":"1722048976953344","order_type":1,"datetime":"1709257089","microtimestamp":"1709257089224000","amount":0.09743931,"amount_str":"0.09743931","amount_traded":"0","amount_at_create":"0.09743931","price":61364,"price_str":"61364"},"channel":"live_orders_btcusd","event":"order_deleted"}
{"data":{"id":1722048980877315,"id_str":"1722048980877315","order_type":1,"datetime":"1709257089","microtimestamp":"1709257089225000","amount":0.02371292,"amount_str":"0.02371292","amount_traded":"0","amount_at_create":"0.02371292","price":61352,"price_str":"61352"},"channel":"live_orders_btcusd","event":"order_deleted"}
{"data":{"id":1722048980705281,"id_str":"1722048980705281","order_type":1,"datetime":"1709257089","microtimestamp":"1709257089227000","amount":0.04875518,"amount_str":"0.04875518","amount_traded":"0","amount_at_create":"0.04875518","price":61368,"price_str":"61368"},"channel":"live_orders_btcusd","event":"order_deleted"}
{"data":{"id":1722048975781889,"id_str":"1722048975781889","order_type":0,"datetime":"1709257089","microtimestamp":"1709257089239000","amount":0.16340834,"amount_str":"0.16340834","amount_traded":"0","amount_at_create":"0.16340834","price":61196,"price_str":"61196"},"channel":"live_orders_btcusd","event":"order_deleted"}
{"data":{"id":1722048980279297,"id_str":"1722048980279297","order_type":1,"datetime":"1709257089","microtimestamp":"1709257089240000","amount":0.48905335,"amount_str":"0.48905335","amount_traded":"0","amount_at_create":"0.48905335","price":61343,"price_str":"61343"},"channel":"live_orders_btcusd","event":"order_deleted"}
{"data":{"id":1722048980267008,"id_str":"1722048980267008","order_type":0,"datetime":"1709257089","microtimestamp":"1709257089240000","amount":0.48926144,"amount_str":"0.48926144","amount_traded":"0","amount_at_create":"0.48926144","price":61316,"price_str":"61316"},"channel":"live_orders_btcusd","event":"order_deleted"}
{"data":{"id":1722048981221376,"id_str":"1722048981221376","order_type":0,"datetime":"1709257089","microtimestamp":"1709257089241000","amount":0.48923804,"amount_str":"0.48923804","amount_traded":"0","amount_at_create":"0.48923804","price":61319,"price_str":"61319"},"channel":"live_orders_btcusd","event":"order_deleted"}
{"data":{"id":1722048976179203,"id_str":"1722048976179203","order_type":0,"datetime":"1709257089","microtimestamp":"1709257089241000","amount":0.16332364,"amount_str":"0.16332364","amount_traded":"0","amount_at_create":"0.16332364","price":61228,"price_str":"61228"},"channel":"live_orders_btcusd","event":"order_deleted"}
{"data":{"id":1722048861769731,"id_str":"1722048861769731","order_type":0,"datetime":"1709257089","microtimestamp":"1709257089249000","amount":0.1875,"amount_str":"0.18750000","amount_traded":"0","amount_at_create":"0.18750000","price":61314,"price_str":"61314"},"channel":"live_orders_btcusd","event":"order_deleted"}
{"data":{"id":1722048940638208,"id_str":"1722048940638208","order_type":1,"datetime":"1709257089","microtimestamp":"1709257089250000","amount":0.815832,"amount_str":"0.81583200","amount_traded":"0","amount_at_create":"0.81583200","price":61363,"price_str":"61363"},"channel":"live_orders_btcusd","event":"order_deleted"}
{"data":{"id":1722048940630016,"id_str":"1722048940630016","order_type":1,"datetime":"1709257089","microtimestamp":"1709257089250000","amount":1.445688,"amount_str":"1.44568800","amount_traded":"0","amount_at_create":"1.44568800","price":61388,"price_str":"61388"},"channel":"live_orders_btcusd","event":"order_deleted"}
{"data":{"id":1722048976912384,"id_str":"1722048976912384","order_type":0,"datetime":"1709257089","microtimestamp":"1709257089250000","amount":0.815832,"amount_str":"0.81583200","amount_traded":"0","amount_at_create":"0.81583200","price":61315,"price_str":"61315"},"channel":"live_orders_btcusd","event":"order_deleted"}
{"data":{"id":1722048909680643,"id_str":"1722048909680643","order_type":1,"datetime":"1709257089","microtimestamp":"1709257089250000","amount":2.473578,"amount_str":"2.47357800","amount_traded":"0","amount_at_create":"2.47357800","price":61474,"price_str":"61474"},"channel":"live_orders_btcusd","event":"order_deleted"}
{"data":{"id":1722048518557696,"id_str":"1722048518557696","order_type":1,"datetime":"1709257089","microtimestamp":"1709257089251000","amount":8.181,"amount_str":"8.18100000","amount_traded":"0","amount_at_create":"8.18100000","price":61578,"price_str":"61578"},"channel":"live_orders_btcusd","event":"order_deleted"}
{"data":{"id":1722048981438467,"id_str":"1722048981438467","order_type":1,"datetime":"1709257089","microtimestamp":"1709257089266000","amount":0.02318209,"amount_str":"0.02318209","amount_traded":"0","amount_at_create":"0.02318209","price":61350,"price_str":"61350"},"channel":"live_orders_btcusd","event":"order_created"}
{"data":{"id":1722048981463041,"id_str":"1722048981463041","order_type":1,"datetime":"1709257089","microtimestamp":"1709257089272000","amount":0.09744407,"amount_str":"0.09744407","amount_traded":"0","amount_at_create":"0.09744407","price":61359,"price_str":"61359"},"channel":"live_orders_btcusd","event":"order_created"}
{"data":{"id":1722048975892480,"id_str":"1722048975892480","order_type":1,"datetime":"1709257089","microtimestamp":"1709257089273000","amount":0.5,"amount_str":"0.50000000","amount_traded":"0","amount_at_create":"0.50000000","price":61378,"price_str":"61378"},"channel":"live_orders_btcusd","event":"order_deleted"}
{"data":{"id":1722048977391618,"id_str":"1722048977391618","order_type":1,"datetime":"1709257089","microtimestamp":"1709257089278000","amount":0.06266882,"amount_str":"0.06266882","amount_traded":"0","amount_at_create":"0.06266882","price":61510,"price_str":"61510"},"channel":"live_orders_btcusd","event":"order_deleted"}
{"data":{"id":1722048976576515,"id_str":"1722048976576515","order_type":1,"datetime":"1709257089","microtimestamp":"1709257089278000","amount":0.00487204,"amount_str":"0.00487204","amount_traded":"0","amount_at_create":"0.00487204","price":61344,"price_str":"61344"},"channel":"live_orders_btcusd","event":"order_deleted"}
{"data":{"id":1722048981438467,"id_str":"1722048981438467","order_type":1,"datetime":"1709257089","microtimestamp":"1709257089279000","amount":0.02318209,"amount_str":"0.02318209","amount_traded":"0","amount_at_create":"0.02318209","price":61350,"price_str":"61350"},"channel":"live_orders_btcusd","event":"order_deleted"}
{"data":{"id":1722048981508100,"id_str":"1722048981508100","order_type":1,"datetime":"1709257089","microtimestamp":"1709257089283000","amount":0.1875,"amount_str":"0.18750000","amount_traded":"0","amount_at_create":"0.18750000","price":61342,"price_str":"61342"},"channel":"live_orders_btcusd","event":"order_created"}
{"data":{"id":1722048981540867,"id_str":"1722048981540867","order_type":0,"datetime":"1709257089","microtimestamp":"1709257089292000","amount":0.01630788,"amount_str":"0.01630788","amount_traded":"0","amount_at_create":"0.01630788","price":61320,"price_str":"61320"},"channel":"live_orders_btcusd","event":"order_created"}
{"data":{"id":1722048981549056,"id_str":"1722048981549056","order_type":1,"datetime":"1709257089","microtimestamp":"1709257089293000","amount":1.445688,"amount_str":"1.44568800","amount_traded":"0","amount_at_create":"1.44568800","price":61375,"price_str":"61375"},"channel":"live_orders_btcusd","event":"order_created"}
{"data":{"id":1722048981549057,"id_str":"1722048981549057","order_type":1,"datetime":"1709257089","microtimestamp":"1709257089293000","amount":2.473578,"amount_str":"2.47357800","amount_traded":"0","amount_at_create":"2.47357800","price":61426,"price_str":"61426"},"channel":"live_orders_btcusd","event":"order_created"}
{"data":{"id":1722048981549058,"id_str":"1722048981549058","order_type":1,"datetime":"1709257089","microtimestamp":"1709257089294000","amount":0.01630608,"amount_str":"0.01630608","amount_traded":"0","amount_at_create":"0.01630608","price":61327,"price_str":"61327"},"channel":"live_orders_btcusd","event":"order_created"}
{"data":{"id":1722048981561344,"id_str":"1722048981561344","order_type":0,"datetime":"1709257089","microtimestamp":"1709257089296000","amount":0.815832,"amount_str":"0.81583200","amount_traded":"0","amount_at_create":"0.81583200","price":61305,"price_str":"61305"},"channel":"live_orders_btcusd","event":"order_created"}
{"data":{"id":1722048981565442,"id_str":"1722048981565442","order_type":1,"datetime":"1709257089","microtimestamp":"1709257089297000","amount":0.00487224,"amount_str":"0.00487224","amount_traded":"0","amount_at_create":"0.00487224","price":61340,"price_str":"61340"},"channel":"live_orders_btcusd","event":"order_created"}
{"data":{"id":1722048981573632,"id_str":"1722048981573632","order_type":1,"datetime":"1709257089","microtimestamp":"1709257089299000","amount":8.181,"amount_str":"8.18100000","amount_traded":"0","amount_at_create":"8.18100000","price":61521,"price_str":"61521"},"channel":"live_orders_btcusd","event":"order_created"}
{"data":{"id":1722048981577729,"id_str":"1722048981577729","order_type":1,"datetime":"1709257089","microtimestamp":"1709257089300000","amount":0.815832,"amount_str":"0.81583200","amount_traded":"0","amount_at_create":"0.81583200","price":61348,"price_str":"61348"},"channel":"live_orders_btcusd","event":"order_created"}
{"data":{"id":1722048980611074,"id_str":"1722048980611074","order_type":0,"datetime":"1709257089","microtimestamp":"1709257089304000","amount":0.00815281,"amount_str":"0.00815281","amount_traded":"0","amount_at_create":"0.00815281","price":61324,"price_str":"61324"},"channel":"live_orders_btcusd","event":"order_deleted"}
{"data":{"id":1722048981594113,"id_str":"1722048981594113","order_type":1,"datetime":"1709257089","microtimestamp":"1709257089304000","amount":0.5,"amount_str":"0.50000000","amount_traded":"0","amount_at_create":"0.50000000","price":61367,"price_str":"61367"},"channel":"live_orders_btcusd","event":"order_created"}
{"data":{"id":1722048980594688,"id_str":"1722048980594688","order_type":0,"datetime":"1709257089","microtimestamp":"1709257089306000","amount":0.00040756,"amount_str":"0.00040756","amount_traded":"0","amount_at_create":"0.00040756","price":61316,"price_str":"61316"},"channel":"live_orders_btcusd","event":"order_deleted"}
{"data":{"id":1722048981540867,"id_str":"1722048981540867","order_type":0,"datetime":"1709257089","microtimestamp":"1709257089308000","amount":0.01630788,"amount_str":"0.01630788","amount_traded":"0","amount_at_create":"0.01630788","price":61320,"price_str":"61320"},"channel":"live_orders_btcusd","event":"order_deleted"}
{"data":{"id":1722048981610500,"id_str":"1722048981610500","order_type":0,"datetime":"1709257089","microtimestamp":"1709257089308000","amount":0.1875,"amount_str":"0.18750000","amount_traded":"0","amount_at_create":"0.18750000","price":61310,"price_str":"61310"},"channel":"live_orders_btcusd","event":"order_created"}
{"data":{"id":1722048981549058,"id_str":"1722048981549058","order_type":1,"datetime":"1709257089","microtimestamp":"1709257089309000","amount":0.01630608,"amount_str":"0.01630608","amount_traded":"0","amount_at_create":"0.01630608","price":61327,"price_str":"61327"},"channel":"live_orders_btcusd","event":"order_deleted"}
{"data":{"id":1722048981508100,"id_str":"1722048981508100","order_type":1,"datetime":"1709257089","microtimestamp":"1709257089317000","amount":0.1875,"amount_str":"0.18750000","amount_traded":"0","amount_at_create":"0.18750000","price":61342,"price_str":"61342"},"channel":"live_orders_btcusd","event":"order_deleted"}
{"data":{"id":1722048981676033,"id_str":"1722048981676033","order_type":0,"datetime":"1709257089","microtimestamp":"1709257089325000","amount":0.00815228,"amount_str":"0.00815228","amount_traded":"0","amount_at_create":"0.00815228","price":61322,"price_str":"61322"},"channel":"live_orders_btcusd","event":"order_created"}
{"data":{"id":1722048981688320,"id_str":"1722048981688320","order_type":1,"datetime":"1709257089","microtimestamp":"1709257089327000","amount":0.06085916,"amount_str":"0.06085916","amount_traded":"0","amount_at_create":"0.06085916","price":61502,"price_str":"61502"},"channel":"live_orders_btcusd","event":"order_created"}
{"data":{"id":1722048981757954,"id_str":"1722048981757954","order_type":1,"datetime":"1709257089","microtimestamp":"1709257089345000","amount":0.02339129,"amount_str":"0.02339129","amount_traded":"0","amount_at_create":"0.02339129","price":61349,"price_str":"61349"},"channel":"live_orders_btcusd","event":"order_created"}
{"data":{"id":1722048981762048,"id_str":"1722048981762048","order_type":1,"datetime":"1709257089","microtimestamp":"1709257089345000","amount":0.1875,"amount_str":"0.18750000","amount_traded":"0","amount_at_create":"0.18750000","price":61425,"price_str":"61425"},"channel":"live_orders_btcusd","event":"order_created"}
{"data":{"id":1722048954769412,"id_str":"1722048954769412","order_type":1,"datetime":"1709257089","microtimestamp":"1709257089350000","amount":0.12188796,"amount_str":"0.12188796","amount_traded":"0","amount_at_create":"0.12188796","price":61402,"price_str":"61402"},"channel":"live_orders_btcusd","event":"order_deleted"}
{"data":{"id":1722048981876738,"id_str":"1722048981876738","order_type":1,"datetime":"1709257089","microtimestamp":"1709257089373000","amount":0.1875,"amount_str":"0.18750000","amount_traded":"0","amount_at_create":"0.18750000","price":61515,"price_str":"61515"},"channel":"live_orders_btcusd","event":"order_created"}
{"data":{"id":1722048980602882,"id_str":"1722048980602882","order_type":0,"datetime":"1709257089","microtimestamp":"1709257089396000","amount":0.06519236,"amount_str":"0.06519236","amount_traded":"0","amount_at_create":"0.06519236","price":61313,"price_str":"61313"},"channel":"live_orders_btcusd","event":"order_deleted"}
{"data":{"id":1722048981995520,"id_str":"1722048981995520","order_type":1,"datetime":"1709257089","microtimestamp":"1709257089402000","amount":0.12188796,"amount_str":"0.12188796","amount_traded":"0","amount_at_create":"0.12188796","price":61391,"price_str":"61391"},"channel":"live_orders_btcusd","event":"order_created"}
{"data":{"id":1722048982097921,"id_str":"1722048982097921","order_type":1,"datetime":"1709257089","microtimestamp":"1709257089428000","amount":0.01630591,"amount_str":"0.01630591","amount_traded":"0","amount_at_create":"0.01630591","price":61328,"price_str":"61328"},"channel":"live_orders_btcusd","event":"order_created"}
{"data":{"id":1722048982102019,"id_str":"1722048982102019","order_type":1,"datetime":"1709257089","microtimestamp":"1709257089429000","amount":0.48916016,"amount_str":"0.48916016","amount_traded":"0","amount_at_create":"0.48916016","price":61330,"price_str":"61330"},"channel":"live_orders_btcusd","event":"order_created"}
{"data":{"id":1722048982106112,"id_str":"1722048982106112","order_type":0,"datetime":"1709257089","microtimestamp":"1709257089430000","amount":0.48925074,"amount_str":"0.48925074","amount_traded":"0","amount_at_create":"0.48925074","price":61318,"price_str":"61318"},"channel":"live_orders_btcusd","event":"order_created"}
{"data":{"id":1722048980021250,"id_str":"1722048980021250","order_type":1,"datetime":"1709257089","microtimestamp":"1709257089432000","amount":0.03062118,"amount_str":"0.03062118","amount_traded":"0","amount_at_create":"0.03062118","price":61350,"price_str":"61350"},"channel":"live_orders_btcusd","event":"order_deleted"}
{"data":{"id":1722048981757954,"id_str":"1722048981757954","order_type":1,"datetime":"1709257089","microtimestamp":"1709257089435000","amount":0.02339129,"amount_str":"0.02339129","amount_traded":"0","amount_at_create":"0.02339129","price":61349,"price_str":"61349"},"channel":"live_orders_btcusd","event":"order_deleted"}
{"data":{"id":1722048982142977,"id_str":"1722048982142977","order_type":0,"datetime":"1709257089","microtimestamp":"1709257089439000","amount":0.01630778,"amount_str":"0.01630778","amount_traded":"0","amount_at_create":"0.01630778","price":61320,"price_str":"61320"},"channel":"live_orders_btcusd","event":"order_created"}
{"data":{"id":1722048982175747,"id_str":"1722048982175747","order_type":1,"datetime":"1709257089","microtimestamp":"1709257089446000","amount":0.03062118,"amount_str":"0.03062118","amount_traded":"0","amount_at_create":"0.03062118","price":61347,"price_str":"61347"},"channel":"live_orders_btcusd","event":"order_created"}
{"data":{"id":1722048982102019,"id_str":"1722048982102019","order_type":1,"datetime":"1709257089","microtimestamp":"1709257089449000","amount":0.48916016,"amount_str":"0.48916016","amount_traded":"0","amount_at_create":"0.48916016","price":61330,"price_str":"61330"},"channel":"live_orders_btcusd","event":"order_deleted"}
{"data":{"id":1722048982212608,"id_str":"1722048982212608","order_type":0,"datetime":"1709257089","microtimestamp":"1709257089455000","amount":0.00133127,"amount_str":"0.00133127","amount_traded":"0","amount_at_create":"0.00133127","price":61261,"price_str":"61261"},"channel":"live_orders_btcusd","event":"order_created"}
{"data":{"id":1722048982364160,"id_str":"1722048982364160","order_type":1,"datetime":"1709257089","microtimestamp":"1709257089492000","amount":0.48908524,"amount_str":"0.48908524","amount_traded":"0","amount_at_create":"0.48908524","price":61339,"price_str":"61339"},"channel":"live_orders_btcusd","event":"order_created"}
{"data":{"id":1722048982368256,"id_str":"1722048982368256","order_type":0,"datetime":"1709257089","microtimestamp":"1709257089493000","amount":0.48928619,"amount_str":"0.48928619","amount_traded":"0","amount_at_create":"0.48928619","price":61313,"price_str":"61313"},"channel":"live_orders_btcusd","event":"order_created"}
{"data":{"id":1722048982212608,"id_str":"1722048982212608","order_type":0,"datetime":"1709257090","microtimestamp":"1709257089505000","amount":0.00133127,"amount_str":"0.00133127","amount_traded":"0","amount_at_create":"0.00133127","price":61261,"price_str":"61261"},"channel":"live_orders_btcusd","event":"order_deleted"}
{"data":{"id":1722048981676033,"id_str":"1722048981676033","order_type":0,"datetime":"1709257090","microtimestamp":"1709257089505000","amount":0.00815228,"amount_str":"0.00815228","amount_traded":"0","amount_at_create":"0.00815228","price":61322,"price_str":"61322"},"channel":"live_orders_btcusd","event":"order_deleted"}
{"data":{"id":1722048982364160,"id_str":"1722048982364160","order_type":1,"datetime":"1709257090","microtimestamp":"1709257089507000","amount":0.48908524,"amount_str":"0.48908524","amount_traded":"0","amount_at_create":"0.48908524","price":61339,"price_str":"61339"},"channel":"live_orders_btcusd","event":"order_deleted"}
{"data":{"id":1722048982450176,"id_str":"1722048982450176","order_type":0,"datetime":"1709257090","microtimestamp":"1709257089514000","amount":0.00040756,"amount_str":"0.00040756","amount_traded":"0","amount_at_create":"0.00040756","price":61317,"price_str":"61317"},"channel":"live_orders_btcusd","event":"order_created"}
{"data":{"id":1722048982474753,"id_str":"1722048982474753","order_type":0,"datetime":"1709257090","microtimestamp":"1709257089519000","amount":0.04893,"amount_str":"0.04893000","amount_traded":"0","amount_at_create":"0.04893000","price":61301,"price_str":"61301"},"channel":"live_orders_btcusd","event":"order_created"}
{"data":{"id":1722048980021249,"id_str":"1722048980021249","order_type":1,"datetime":"1709257090","microtimestamp":"1709257089523000","amount":0.00487224,"amount_str":"0.00487224","amount_traded":"0","amount_at_create":"0.00487224","price":61342,"price_str":"61342"},"channel":"live_orders_btcusd","event":"order_deleted"}
{"data":{"id":1722048982499328,"id_str":"1722048982499328","order_type":1,"datetime":"1709257090","microtimestamp":"1709257089525000","amount":0.02075279,"amount_str":"0.02075279","amount_traded":"0","amount_at_create":"0.02075279","price":61347,"price_str":"61347"},"channel":"live_orders_btcusd","event":"order_created"}
{"data":{"id":1722048982568960,"id_str":"1722048982568960","order_type":1,"datetime":"1709257090","microtimestamp":"1709257089542000","amount":0.00487283,"amount_str":"0.00487283","amount_traded":"0","amount_at_create":"0.00487283","price":61335,"price_str":"61335"},"channel":"live_orders_btcusd","event":"order_created"}
{"data":{"id":1722048982646784,"id_str":"1722048982646784","order_type":0,"datetime":"1709257090","microtimestamp":"1709257089562000","amount":0.00815328,"amount_str":"0.00815328","amount_traded":"0","amount_at_create":"0.00815328","price":61319,"price_str":"61319"},"channel":"live_orders_btcusd","event":"order_created"}
{"data":{"id":1722048982781952,"id_str":"1722048982781952","order_type":1,"datetime":"1709257090","microtimestamp":"1709257089598000","amount":0.16278032,"amount_str":"0.16278032","amount_traded":"0","amount_at_create":"0.16278032","price":61433,"price_str":"61433"},"channel":"live_orders_btcusd","event":"order_created"}
{"data":{"id":1722048982368256,"id_str":"1722048982368256","order_type":0,"datetime":"1709257090","microtimestamp":"1709257089598000","amount":0.48928619,"amount_str":"0.48928619","amount_traded":"0","amount_at_create":"0.48928619","price":61313,"price_str":"61313"},"channel":"live_orders_btcusd","event":"order_deleted"}
{"data":{"id":1722048982142977,"id_str":"1722048982142977","order_type":0,"datetime":"1709257090","microtimestamp":"1709257089599000","amount":0.01630778,"amount_str":"0.01630778","amount_traded":"0","amount_at_create":"0.01630778","price":61320,"price_str":"61320"},"channel":"live_orders_btcusd","event":"order_deleted"}
{"data":{"id":1722048980692992,"id_str":"1722048980692992","order_type":0,"datetime":"1709257090","microtimestamp":"1709257089634000","amount":0.16305632,"amount_str":"0.16305632","amount_traded":"0","amount_at_create":"0.16305632","price":61305,"price_str":"61305"},"channel":"live_orders_btcusd","event":"order_deleted"}
{"data":{"id":1722048982978560,"id_str":"1722048982978560","order_type":1,"datetime":"1709257090","microtimestamp":"1709257089642000","amount":0.48915723,"amount_str":"0.48915723","amount_traded":"0","amount_at_create":"0.48915723","price":61330,"price_str":"61330"},"channel":"live_orders_btcusd","event":"order_created"}
{"data":{"id":1722048982986754,"id_str":"1722048982986754","order_type":0,"datetime":"1709257090","microtimestamp":"1709257089644000","amount":0.01630759,"amount_str":"0.01630759","amount_traded":"0","amount_at_create":"0.01630759","price":61321,"price_str":"61321"},"channel":"live_orders_btcusd","event":"order_created"}
{"data":{"id":1722048983076866,"id_str":"1722048983076866","order_type":0,"datetime":"1709257090","microtimestamp":"1709257089667000","amount":0.16306829,"amount_str":"0.16306829","amount_traded":"0","amount_at_create":"0.16306829","price":61300,"price_str":"61300"},"channel":"live_orders_btcusd","event":"order_created"}
{"data":{"id":1722048982106112,"id_str":"1722048982106112","order_type":0,"datetime":"1709257090","microtimestamp":"1709257089744000","amount":0.48925074,"amount_str":"0.48925074","amount_traded":"0","amount_at_create":"0.48925074","price":61318,"price_str":"61318"},"channel":"live_orders_btcusd","event":"order_deleted"}
{"data":{"id":1722048982450176,"id_str":"1722048982450176","order_type":0,"datetime":"1709257090","microtimestamp":"1709257089762000","amount":0.00040756,"amount_str":"0.00040756","amount_traded":"0","amount_at_create":"0.00040756","price":61317,"price_str":"61317"},"channel":"live_orders_btcusd","event":"order_deleted"}
{"data":{"id":1722048983543808,"id_str":"1722048983543808","order_type":1,"datetime":"1709257090","microtimestamp":"1709257089780000","amount":0.04875518,"amount_str":"0.04875518","amount_traded":"0","amount_at_create":"0.04875518","price":61361,"price_str":"61361"},"channel":"live_orders_btcusd","event":"order_created"}
{"data":{"id":1722048983576576,"id_str":"1722048983576576","order_type":0,"datetime":"1709257090","microtimestamp":"1709257089789000","amount":0.48924173,"amount_str":"0.48924173","amount_traded":"0","amount_at_create":"0.48924173","price":61319,"price_str":"61319"},"channel":"live_orders_btcusd","event":"order_created"}
{"data":{"id":1722048983838721,"id_str":"1722048983838721","order_type":0,"datetime":"1709257090","microtimestamp":"1709257089853000","amount":0.00133153,"amount_str":"0.00133153","amount_traded":"0","amount_at_create":"0.00133153","price":61265,"price_str":"61265"},"channel":"live_orders_btcusd","event":"order_created"}
{"data":{"id":1722048984121346,"id_str":"1722048984121346","order_type":0,"datetime":"1709257090","microtimestamp":"1709257089921000","amount":0.00040756,"amount_str":"0.00040756","amount_traded":"0","amount_at_create":"0.00040756","price":61316,"price_str":"61316"},"channel":"live_orders_btcusd","event":"order_created"}
{"data":{"id":1722048984285185,"id_str":"1722048984285185","order_type":1,"datetime":"1709257090","microtimestamp":"1709257089962000","amount":0.24459646,"amount_str":"0.24459646","amount_traded":"0","amount_at_create":"0.24459646","price":61327,"price_str":"61327"},"channel":"live_orders_btcusd","event":"order_created"}
{"data":{"id":1722048984121346,"id_str":"1722048984121346","order_type":0,"datetime":"1709257090","microtimestamp":"1709257090140000","amount":0.00040756,"amount_str":"0.00040756","amount_traded":"0","amount_at_create":"0.00040756","price":61316,"price_str":"61316"},"channel":"live_orders_btcusd","event":"order_deleted"}
{"data":{"id":1722048985124864,"id_str":"1722048985124864","order_type":0,"datetime":"1709257090","microtimestamp":"1709257090166000","amount":0.06519737,"amount_str":"0.06519737","amount_traded":"0","amount_at_create":"0.06519737","price":61308,"price_str":"61308"},"channel":"live_orders_btcusd","event":"order_created"}
{"data":{"id":1722048985374720,"id_str":"1722048985374720","order_type":0,"datetime":"1709257090","microtimestamp":"1709257090227000","amount":0.00040756,"amount_str":"0.00040756","amount_traded":"0","amount_at_create":"0.00040756","price":61317,"price_str":"61317"},"channel":"live_orders_btcusd","event":"order_created"}
{"data":{"id":1722048985374720,"id_str":"1722048985374720","order_type":0,"datetime":"1709257090","microtimestamp":"1709257090310000","amount":0.00040756,"amount_str":"0.00040756","amount_traded":"0","amount_at_create":"0.00040756","price":61317,"price_str":"61317"},"channel":"live_orders_btcusd","event":"order_deleted"}
{"data":{"id":1722048985993216,"id_str":"1722048985993216","order_type":0,"datetime":"1709257090","microtimestamp":"1709257090378000","amount":0.00040756,"amount_str":"0.00040756","amount_traded":"0","amount_at_create":"0.00040756","price":61316,"price_str":"61316"},"channel":"live_orders_btcusd","event":"order_created"}
{"data":{"id":1722048986202112,"id_str":"1722048986202112","order_type":1,"datetime":"1709257090","microtimestamp":"1709257090429000","amount":0.4890693,"amount_str":"0.48906930","amount_traded":"0","amount_at_create":"0.48906930","price":61341,"price_str":"61341"},"channel":"live_orders_btcusd","event":"order_created"}
{"data":{"id":1722048986202113,"id_str":"1722048986202113","order_type":0,"datetime":"1709257090","microtimestamp":"1709257090430000","amount":0.48927725,"amount_str":"0.48927725","amount_traded":"0","amount_at_create":"0.48927725","price":61314,"price_str":"61314"},"channel":"live_orders_btcusd","event":"order_created"}
{"data":{"id":1722048986206209,"id_str":"1722048986206209","order_type":0,"datetime":"1709257090","microtimestamp":"1709257090430000","amount":0.48933635,"amount_str":"0.48933635","amount_traded":"0","amount_at_create":"0.48933635","price":61307,"price_str":"61307"},"channel":"live_orders_btcusd","event":"order_created"}
{"data":{"id":1722048986206210,"id_str":"1722048986206210","order_type":1,"datetime":"1709257090","microtimestamp":"1709257090430000","amount":0.48912514,"amount_str":"0.48912514","amount_traded":"0","amount_at_create":"0.48912514","price":61334,"price_str":"61334"},"channel":"live_orders_btcusd","event":"order_created"}
{"data":{"id":1722048986206212,"id_str":"1722048986206212","order_type":1,"datetime":"1709257090","microtimestamp":"1709257090430000","amount":0.48897383,"amount_str":"0.48897383","amount_traded":"0","amount_at_create":"0.48897383","price":61353,"price_str":"61353"},"channel":"live_orders_btcusd","event":"order_created"}
{"data":{"id":1722048986206213,"id_str":"1722048986206213","order_type":0,"datetime":"1709257090","microtimestamp":"1709257090431000","amount":0.48947019,"amount_str":"0.48947019","amount_traded":"0","amount_at_create":"0.48947019","price":61290,"price_str":"61290"},"channel":"live_orders_btcusd","event":"order_created"}
